
#######################################################################
# +-----------------------------------------------------------------+ #
# |                            BO3 object                           | #
# +-----------------------------------------------------------------+ #
#######################################################################

Author: NLBlackEagle

Description: No description given

Version: 3

SettingsMode: WriteWithoutComments


#######################################################################
# +-----------------------------------------------------------------+ #
# |                          Main settings                          | #
# +-----------------------------------------------------------------+ #
#######################################################################

Tree: true

Frequency: 150

Rarity: 100.0

RotateRandomly: true

SpawnHeight: randomY

SpawnHeightOffset: 0

SpawnHeightVariance: 0

##############################
# Height Limits for the BO3. #
##############################

MinHeight: 20

MaxHeight: 90

######################
# Extrusion settings #
######################

ExtrudeMode: None

ExtrudeThroughBlocks: AIR

MaxBranchDepth: 10

ExcludedBiomes: All


#######################################################################
# +-----------------------------------------------------------------+ #
# |                      Source block settings                      | #
# +-----------------------------------------------------------------+ #
#######################################################################

SourceBlocks: Solid

MaxPercentageOutsideSourceBlock: 5

OutsideSourceBlock: placeAnyway

DoReplaceBlocks: false

IsOTGPlus: false


#######################################################################
# +-----------------------------------------------------------------+ #
# |                              Blocks                             | #
# +-----------------------------------------------------------------+ #
#######################################################################

Block(-12,4,2,STONE:0)
Block(-12,4,3,STONE:0)
Block(-12,4,4,STONE:0)
Block(-12,5,2,STONE:0)
Block(-12,5,3,STONE:0)
Block(-12,5,4,STONE:0)
Block(-12,6,2,iceandfire:frozen_stone:0)
Block(-12,6,3,iceandfire:frozen_stone:0)
Block(-12,6,4,STONE:0)
Block(-11,3,2,iceandfire:frozen_stone:0)
Block(-11,3,3,iceandfire:frozen_stone:0)
Block(-11,3,4,iceandfire:frozen_stone:0)
Block(-11,4,1,STONE:0)
Block(-11,4,2,iceandfire:frozen_stone:0)
Block(-11,4,3,iceandfire:frozen_stone:0)
Block(-11,4,4,iceandfire:frozen_stone:0)
Block(-11,4,5,STONE:0)
Block(-11,5,1,iceandfire:frozen_stone:0)
Block(-11,5,2,iceandfire:frozen_stone:0)
Block(-11,5,3,iceandfire:frozen_stone:0)
Block(-11,5,4,iceandfire:frozen_stone:0)
Block(-11,5,5,STONE:0)
Block(-11,6,1,iceandfire:frozen_stone:0)
Block(-11,6,2,iceandfire:frozen_stone:0)
Block(-11,6,3,iceandfire:frozen_stone:0)
Block(-11,6,4,iceandfire:frozen_stone:0)
Block(-11,6,5,iceandfire:frozen_stone:0)
Block(-11,7,2,iceandfire:frozen_stone:0)
Block(-11,7,3,iceandfire:frozen_stone:0)
Block(-11,7,4,iceandfire:frozen_stone:0)
Block(-11,8,2,iceandfire:frozen_stone:0)
Block(-11,8,3,iceandfire:frozen_stone:0)
Block(-11,8,4,iceandfire:frozen_stone:0)
Block(-11,9,2,iceandfire:frozen_stone:0)
Block(-11,9,3,iceandfire:frozen_stone:0)
Block(-11,9,4,STONE:0)
Block(-10,3,2,iceandfire:frozen_stone:0)
Block(-10,3,3,iceandfire:frozen_stone:0)
Block(-10,3,4,iceandfire:frozen_stone:0)
Block(-10,3,5,iceandfire:frozen_stone:0)
Block(-10,3,6,STONE:0)
Block(-10,3,7,STONE:0)
Block(-10,3,8,STONE:0)
Block(-10,4,-2,STONE:0)
Block(-10,4,-1,STONE:0)
Block(-10,4,0,STONE:0)
Block(-10,4,1,iceandfire:frozen_stone:0)
Block(-10,4,2,iceandfire:frozen_stone:0)
Block(-10,4,3,iceandfire:frozen_stone:0)
Block(-10,4,4,iceandfire:frozen_stone:0)
Block(-10,4,5,iceandfire:frozen_stone:0)
Block(-10,4,6,iceandfire:frozen_stone:0)
Block(-10,4,7,iceandfire:frozen_stone:0)
Block(-10,4,8,iceandfire:frozen_stone:0)
Block(-10,5,-2,STONE:0)
Block(-10,5,-1,iceandfire:frozen_stone:0)
Block(-10,5,0,iceandfire:frozen_stone:0)
Block(-10,5,1,iceandfire:frozen_stone:0)
Block(-10,5,2,AIR:0)
Block(-10,5,3,iceandfire:frozen_stone:0)
Block(-10,5,4,iceandfire:frozen_stone:0)
Block(-10,5,5,iceandfire:frozen_stone:0)
Block(-10,5,6,iceandfire:frozen_stone:0)
Block(-10,5,7,iceandfire:frozen_stone:0)
Block(-10,5,8,iceandfire:frozen_stone:0)
Block(-10,6,-2,STONE:0)
Block(-10,6,-1,iceandfire:frozen_stone:0)
Block(-10,6,0,iceandfire:frozen_stone:0)
Block(-10,6,1,iceandfire:frozen_stone:0)
Block(-10,6,2,iceandfire:frozen_stone:0)
Block(-10,6,3,iceandfire:frozen_stone:0)
Block(-10,6,4,iceandfire:frozen_stone:0)
Block(-10,6,5,iceandfire:frozen_stone:0)
Block(-10,6,6,iceandfire:frozen_stone:0)
Block(-10,6,7,iceandfire:frozen_stone:0)
Block(-10,6,8,iceandfire:frozen_stone:0)
Block(-10,6,9,STONE:0)
Block(-10,7,-1,iceandfire:frozen_stone:0)
Block(-10,7,0,iceandfire:frozen_stone:0)
Block(-10,7,1,iceandfire:frozen_stone:0)
Block(-10,7,2,iceandfire:frozen_stone:0)
Block(-10,7,3,iceandfire:frozen_stone:0)
Block(-10,7,4,iceandfire:frozen_stone:0)
Block(-10,7,5,iceandfire:frozen_stone:0)
Block(-10,7,6,iceandfire:frozen_stone:0)
Block(-10,7,7,STONE:0)
Block(-10,7,8,STONE:0)
Block(-10,7,9,STONE:0)
Block(-10,8,1,iceandfire:frozen_stone:0)
Block(-10,8,2,iceandfire:frozen_stone:0)
Block(-10,8,3,iceandfire:frozen_stone:0)
Block(-10,8,4,iceandfire:frozen_stone:0)
Block(-10,8,5,iceandfire:frozen_stone:0)
Block(-10,8,6,iceandfire:frozen_stone:0)
Block(-10,8,7,STONE:0)
Block(-10,8,8,STONE:0)
Block(-10,8,9,STONE:0)
Block(-10,9,1,iceandfire:frozen_stone:0)
Block(-10,9,2,iceandfire:frozen_stone:0)
Block(-10,9,3,iceandfire:frozen_stone:0)
Block(-10,9,4,iceandfire:frozen_stone:0)
Block(-10,9,5,iceandfire:frozen_stone:0)
Block(-10,9,6,STONE:0)
Block(-10,9,7,STONE:0)
Block(-10,9,8,STONE:0)
Block(-10,10,2,STONE:0)
Block(-10,10,3,STONE:0)
Block(-10,10,4,STONE:0)
Block(-9,1,7,STONE:0)
Block(-9,1,8,STONE:0)
Block(-9,1,9,STONE:0)
Block(-9,2,0,STONE:0)
Block(-9,2,1,STONE:0)
Block(-9,2,2,iceandfire:frozen_stone:0)
Block(-9,2,5,STONE:0)
Block(-9,2,6,STONE:0)
Block(-9,2,7,STONE:0)
Block(-9,2,8,iceandfire:frozen_stone:0)
Block(-9,2,9,iceandfire:frozen_stone:0)
Block(-9,3,-2,STONE:0)
Block(-9,3,-1,STONE:0)
Block(-9,3,0,STONE:0)
Block(-9,3,1,iceandfire:frozen_stone:0)
Block(-9,3,2,iceandfire:frozen_stone:0)
Block(-9,3,3,iceandfire:frozen_stone:0)
Block(-9,3,4,iceandfire:frozen_stone:0)
Block(-9,3,5,iceandfire:frozen_stone:0)
Block(-9,3,6,iceandfire:frozen_stone:0)
Block(-9,3,7,iceandfire:frozen_stone:0)
Block(-9,3,8,iceandfire:frozen_stone:0)
Block(-9,3,9,iceandfire:frozen_stone:0)
Block(-9,3,10,iceandfire:frozen_stone:0)
Block(-9,3,11,STONE:0)
Block(-9,4,-3,STONE:0)
Block(-9,4,-2,iceandfire:frozen_stone:0)
Block(-9,4,-1,iceandfire:frozen_stone:0)
Block(-9,4,0,iceandfire:frozen_stone:0)
Block(-9,4,1,iceandfire:frozen_stone:0)
Block(-9,4,2,biomesoplenty:grass:1)
Block(-9,4,3,quark:stone_stairs:1)
Block(-9,4,4,biomesoplenty:grass:1)
Block(-9,4,5,iceandfire:frozen_stone:0)
Block(-9,4,6,iceandfire:frozen_stone:0)
Block(-9,4,7,iceandfire:frozen_stone:0)
Block(-9,4,8,iceandfire:frozen_stone:0)
Block(-9,4,9,iceandfire:frozen_stone:0)
Block(-9,4,10,iceandfire:frozen_stone:0)
Block(-9,4,11,STONE:0)
Block(-9,5,-3,STONE:0)
Block(-9,5,-2,iceandfire:frozen_stone:0)
Block(-9,5,-1,iceandfire:frozen_stone:0)
Block(-9,5,0,iceandfire:frozen_stone:0)
Block(-9,5,1,iceandfire:frozen_stone:0)
Block(-9,5,2,SNOW:0)
Block(-9,5,3,AIR:0)
Block(-9,5,4,AIR:0)
Block(-9,5,5,iceandfire:frozen_stone:0)
Block(-9,5,6,iceandfire:frozen_stone:0)
Block(-9,5,7,iceandfire:frozen_stone:0)
Block(-9,5,8,iceandfire:frozen_stone:0)
Block(-9,5,9,iceandfire:frozen_stone:0)
Block(-9,5,10,STONE:0)
Block(-9,5,11,STONE:0)
Block(-9,6,-3,STONE:0)
Block(-9,6,-2,iceandfire:frozen_stone:0)
Block(-9,6,-1,iceandfire:frozen_stone:0)
Block(-9,6,0,iceandfire:frozen_stone:0)
Block(-9,6,1,rustic:mooncap_mushroom:0)
Block(-9,6,2,AIR:0)
Block(-9,6,3,AIR:0)
Block(-9,6,4,AIR:0)
Block(-9,6,5,iceandfire:frozen_stone:0)
Block(-9,6,6,iceandfire:frozen_stone:0)
Block(-9,6,7,iceandfire:frozen_stone:0)
Block(-9,6,8,iceandfire:frozen_stone:0)
Block(-9,6,9,iceandfire:frozen_stone:0)
Block(-9,6,10,STONE:0)
Block(-9,6,11,STONE:0)
Block(-9,6,12,STONE:0)
Block(-9,7,-2,iceandfire:frozen_stone:0)
Block(-9,7,-1,iceandfire:frozen_stone:0)
Block(-9,7,0,iceandfire:frozen_stone:0)
Block(-9,7,1,iceandfire:frozen_stone:0)
Block(-9,7,2,AIR:0)
Block(-9,7,3,iceandfire:frozen_stone:0)
Block(-9,7,4,iceandfire:frozen_stone:0)
Block(-9,7,5,iceandfire:frozen_stone:0)
Block(-9,7,6,iceandfire:frozen_stone:0)
Block(-9,7,7,iceandfire:frozen_stone:0)
Block(-9,7,8,iceandfire:frozen_stone:0)
Block(-9,7,9,STONE:0)
Block(-9,7,10,STONE:0)
Block(-9,7,11,STONE:0)
Block(-9,7,12,STONE:0)
Block(-9,8,-2,STONE:0)
Block(-9,8,-1,iceandfire:frozen_stone:0)
Block(-9,8,0,iceandfire:frozen_stone:0)
Block(-9,8,1,iceandfire:frozen_stone:0)
Block(-9,8,2,iceandfire:frozen_stone:0)
Block(-9,8,3,iceandfire:frozen_stone:0)
Block(-9,8,4,iceandfire:frozen_stone:0)
Block(-9,8,5,iceandfire:frozen_stone:0)
Block(-9,8,6,iceandfire:frozen_stone:0)
Block(-9,8,7,STONE:0)
Block(-9,8,8,STONE:0)
Block(-9,8,9,STONE:0)
Block(-9,8,10,STONE:0)
Block(-9,8,11,STONE:0)
Block(-9,8,12,STONE:0)
Block(-9,9,-2,STONE:0)
Block(-9,9,-1,STONE:0)
Block(-9,9,0,STONE:0)
Block(-9,9,1,iceandfire:frozen_stone:0)
Block(-9,9,2,iceandfire:frozen_stone:0)
Block(-9,9,3,iceandfire:frozen_stone:0)
Block(-9,9,4,iceandfire:frozen_stone:0)
Block(-9,9,5,iceandfire:frozen_stone:0)
Block(-9,9,6,iceandfire:frozen_stone:0)
Block(-9,9,7,STONE:0)
Block(-9,9,8,STONE:0)
Block(-9,9,9,STONE:0)
Block(-9,9,10,STONE:0)
Block(-9,10,2,STONE:0)
Block(-9,10,3,STONE:0)
Block(-9,10,4,iceandfire:frozen_stone:0)
Block(-9,10,6,iceandfire:frozen_stone:0)
Block(-9,10,7,STONE:0)
Block(-9,10,8,STONE:0)
Block(-8,0,7,STONE:0)
Block(-8,0,8,STONE:0)
Block(-8,0,9,STONE:0)
Block(-8,1,0,STONE:0)
Block(-8,1,1,STONE:0)
Block(-8,1,2,STONE:0)
Block(-8,1,6,STONE:0)
Block(-8,1,7,STONE:0)
Block(-8,1,8,iceandfire:frozen_stone:0)
Block(-8,1,9,iceandfire:frozen_stone:0)
Block(-8,1,10,iceandfire:frozen_stone:0)
Block(-8,2,-1,STONE:0)
Block(-8,2,0,STONE:0)
Block(-8,2,1,STONE:0)
Block(-8,2,2,iceandfire:frozen_stone:0)
Block(-8,2,3,iceandfire:frozen_stone:0)
Block(-8,2,5,iceandfire:frozen_stone:0)
Block(-8,2,6,iceandfire:frozen_stone:0)
Block(-8,2,7,iceandfire:frozen_stone:0)
Block(-8,2,8,iceandfire:frozen_stone:0)
Block(-8,2,9,iceandfire:frozen_stone:0)
Block(-8,2,10,iceandfire:frozen_stone:0)
Block(-8,2,11,iceandfire:frozen_stone:0)
Block(-8,3,-2,iceandfire:frozen_stone:0)
Block(-8,3,-1,iceandfire:frozen_stone:0)
Block(-8,3,0,iceandfire:frozen_stone:0)
Block(-8,3,1,iceandfire:frozen_stone:0)
Block(-8,3,2,iceandfire:frozen_stone:0)
Block(-8,3,3,iceandfire:frozen_stone:0)
Block(-8,3,4,biomesoplenty:grass:1)
Block(-8,3,5,iceandfire:frozen_stone:0)
Block(-8,3,6,iceandfire:frozen_stone:0)
Block(-8,3,7,iceandfire:frozen_stone:0)
Block(-8,3,8,rustic:mooncap_mushroom:0)
Block(-8,3,9,BROWN_MUSHROOM:0)
Block(-8,3,10,iceandfire:frozen_stone:0)
Block(-8,3,11,iceandfire:frozen_stone:0)
Block(-8,3,12,iceandfire:frozen_stone:0)
Block(-8,4,-3,iceandfire:frozen_stone:0)
Block(-8,4,-2,iceandfire:frozen_stone:0)
Block(-8,4,-1,iceandfire:frozen_stone:0)
Block(-8,4,0,SNOW:0)
Block(-8,4,1,biomesoplenty:grass:1)
Block(-8,4,2,AIR:0)
Block(-8,4,3,SNOW:0)
Block(-8,4,4,SNOW:0)
Block(-8,4,5,biomesoplenty:grass:1)
Block(-8,4,6,quark:stone_stairs:1)
Block(-8,4,7,quark:stone_speleothem:2)
Block(-8,4,8,AIR:0)
Block(-8,4,9,AIR:0)
Block(-8,4,10,iceandfire:frozen_stone:0)
Block(-8,4,11,AIR:0)
Block(-8,4,12,iceandfire:frozen_stone:0)
Block(-8,5,-3,iceandfire:frozen_stone:0)
Block(-8,5,-2,iceandfire:frozen_stone:0)
Block(-8,5,-1,iceandfire:frozen_stone:0)
Block(-8,5,0,AIR:0)
Block(-8,5,1,rustic:deathstalk_mushroom:0)
Block(-8,5,2,AIR:0)
Block(-8,5,3,AIR:0)
Block(-8,5,4,AIR:0)
Block(-8,5,5,SNOW:0)
Block(-8,5,6,AIR:0)
Block(-8,5,7,quark:stone_speleothem:1)
Block(-8,5,8,AIR:0)
Block(-8,5,9,AIR:0)
Block(-8,5,10,iceandfire:frozen_stone:0)
Block(-8,5,11,iceandfire:frozen_stone:0)
Block(-8,5,12,iceandfire:frozen_stone:0)
Block(-8,6,-3,iceandfire:frozen_stone:0)
Block(-8,6,-2,iceandfire:frozen_stone:0)
Block(-8,6,-1,iceandfire:frozen_stone:0)
Block(-8,6,0,iceandfire:frozen_stone:0)
Block(-8,6,1,AIR:0)
Block(-8,6,2,AIR:0)
Block(-8,6,3,AIR:0)
Block(-8,6,4,AIR:0)
Block(-8,6,5,AIR:0)
Block(-8,6,6,AIR:0)
Block(-8,6,7,quark:stone_speleothem:0)
Block(-8,6,8,iceandfire:frozen_stone:0)
Block(-8,6,9,AIR:0)
Block(-8,6,10,iceandfire:frozen_stone:0)
Block(-8,6,11,iceandfire:frozen_stone:0)
Block(-8,6,12,iceandfire:frozen_stone:0)
Block(-8,6,13,STONE:0)
Block(-8,7,-3,iceandfire:frozen_stone:0)
Block(-8,7,-2,iceandfire:frozen_stone:0)
Block(-8,7,-1,iceandfire:frozen_stone:0)
Block(-8,7,0,iceandfire:frozen_stone:0)
Block(-8,7,1,iceandfire:frozen_stone:0)
Block(-8,7,2,AIR:0)
Block(-8,7,3,AIR:0)
Block(-8,7,4,AIR:0)
Block(-8,7,5,iceandfire:frozen_stone:0)
Block(-8,7,6,AIR:0)
Block(-8,7,7,AIR:0)
Block(-8,7,8,iceandfire:frozen_stone:0)
Block(-8,7,9,STONE:0)
Block(-8,7,10,iceandfire:frozen_stone:0)
Block(-8,7,11,iceandfire:frozen_stone:0)
Block(-8,7,12,iceandfire:frozen_stone:0)
Block(-8,7,13,STONE:0)
Block(-8,8,-3,STONE:0)
Block(-8,8,-2,STONE:0)
Block(-8,8,-1,iceandfire:frozen_stone:0)
Block(-8,8,0,iceandfire:frozen_stone:0)
Block(-8,8,1,iceandfire:frozen_stone:0)
Block(-8,8,2,AIR:0)
Block(-8,8,3,AIR:0)
Block(-8,8,4,iceandfire:frozen_stone:0)
Block(-8,8,5,iceandfire:frozen_stone:0)
Block(-8,8,6,iceandfire:frozen_stone:0)
Block(-8,8,7,STONE:0)
Block(-8,8,8,STONE:0)
Block(-8,8,9,STONE:0)
Block(-8,8,10,STONE:0)
Block(-8,8,11,STONE:0)
Block(-8,8,12,STONE:0)
Block(-8,8,13,STONE:0)
Block(-8,9,-3,STONE:0)
Block(-8,9,-2,STONE:0)
Block(-8,9,-1,STONE:0)
Block(-8,9,0,STONE:0)
Block(-8,9,1,STONE:0)
Block(-8,9,2,iceandfire:frozen_stone:0)
Block(-8,9,3,iceandfire:frozen_stone:0)
Block(-8,9,4,iceandfire:frozen_stone:0)
Block(-8,9,5,iceandfire:frozen_stone:0)
Block(-8,9,6,iceandfire:frozen_stone:0)
Block(-8,9,7,iceandfire:frozen_stone:0)
Block(-8,9,8,STONE:0)
Block(-8,9,9,STONE:0)
Block(-8,9,10,STONE:0)
Block(-8,9,11,STONE:0)
Block(-8,9,12,STONE:0)
Block(-8,10,-2,STONE:0)
Block(-8,10,-1,STONE:0)
Block(-8,10,0,STONE:0)
Block(-8,10,1,STONE:0)
Block(-8,10,2,STONE:0)
Block(-8,10,3,iceandfire:frozen_stone:0)
Block(-8,10,4,iceandfire:frozen_stone:0)
Block(-8,10,5,iceandfire:frozen_stone:0)
Block(-8,10,6,iceandfire:frozen_stone:0)
Block(-8,10,7,iceandfire:frozen_stone:0)
Block(-8,10,8,STONE:0)
Block(-8,10,9,STONE:0)
Block(-8,10,10,STONE:0)
Block(-8,11,0,STONE:0)
Block(-8,11,1,STONE:0)
Block(-8,11,2,STONE:0)
Block(-8,11,3,iceandfire:frozen_stone:0)
Block(-8,11,4,iceandfire:frozen_stone:0)
Block(-8,11,5,iceandfire:frozen_stone:0)
Block(-8,11,6,iceandfire:frozen_stone:0)
Block(-7,0,7,STONE:0)
Block(-7,0,8,STONE:0)
Block(-7,0,9,STONE:0)
Block(-7,1,0,STONE:0)
Block(-7,1,1,STONE:0)
Block(-7,1,2,iceandfire:frozen_stone:0)
Block(-7,1,6,iceandfire:frozen_stone:0)
Block(-7,1,7,iceandfire:frozen_stone:0)
Block(-7,1,8,iceandfire:frozen_stone:0)
Block(-7,1,9,iceandfire:frozen_stone:0)
Block(-7,1,10,iceandfire:frozen_stone:0)
Block(-7,2,-1,STONE:0)
Block(-7,2,0,STONE:0)
Block(-7,2,1,iceandfire:frozen_stone:0)
Block(-7,2,2,iceandfire:frozen_stone:0)
Block(-7,2,3,iceandfire:frozen_stone:0)
Block(-7,2,4,iceandfire:frozen_stone:0)
Block(-7,2,5,iceandfire:frozen_stone:0)
Block(-7,2,6,iceandfire:frozen_stone:0)
Block(-7,2,7,iceandfire:frozen_stone:0)
Block(-7,2,8,iceandfire:frozen_stone:0)
Block(-7,2,9,iceandfire:frozen_stone:0)
Block(-7,2,10,iceandfire:frozen_stone:0)
Block(-7,2,11,iceandfire:frozen_stone:0)
Block(-7,3,-2,iceandfire:frozen_stone:0)
Block(-7,3,-1,iceandfire:frozen_stone:0)
Block(-7,3,0,iceandfire:frozen_stone:0)
Block(-7,3,1,biomesoplenty:grass:1)
Block(-7,3,2,iceandfire:frozen_stone:0)
Block(-7,3,3,iceandfire:frozen_stone:0)
Block(-7,3,4,iceandfire:frozen_stone:0)
Block(-7,3,5,iceandfire:frozen_stone:0)
Block(-7,3,6,iceandfire:frozen_stone:0)
Block(-7,3,7,AIR:0)
Block(-7,3,8,AIR:0)
Block(-7,3,9,rustic:mooncap_mushroom:0)
Block(-7,3,10,quark:stone_speleothem:2)
Block(-7,3,11,iceandfire:frozen_stone:0)
Block(-7,3,12,iceandfire:frozen_stone:0)
Block(-7,4,-3,iceandfire:frozen_stone:0)
Block(-7,4,-2,iceandfire:frozen_stone:0)
Block(-7,4,-1,iceandfire:frozen_stone:0)
Block(-7,4,0,rustic:mooncap_mushroom:0)
Block(-7,4,1,AIR:0)
Block(-7,4,2,SNOW:0)
Block(-7,4,3,AIR:0)
Block(-7,4,4,AIR:0)
Block(-7,4,5,rustic:mooncap_mushroom:0)
Block(-7,4,6,AIR:0)
Block(-7,4,7,AIR:0)
Block(-7,4,8,AIR:0)
Block(-7,4,9,AIR:0)
Block(-7,4,10,quark:stone_speleothem:1)
Block(-7,4,11,AIR:0)
Block(-7,4,12,iceandfire:frozen_stone:0)
Block(-7,5,-3,iceandfire:frozen_stone:0)
Block(-7,5,-2,AIR:0)
Block(-7,5,-1,iceandfire:dragon_ice_spikes:0)
Block(-7,5,0,AIR:0)
Block(-7,5,1,AIR:0)
Block(-7,5,2,AIR:0)
Block(-7,5,3,AIR:0)
Block(-7,5,4,AIR:0)
Block(-7,5,5,AIR:0)
Block(-7,5,6,AIR:0)
Block(-7,5,7,AIR:0)
Block(-7,5,8,AIR:0)
Block(-7,5,9,quark:stone_speleothem:0)
Block(-7,5,10,quark:stone_speleothem:0)
Block(-7,5,11,AIR:0)
Block(-7,5,12,iceandfire:frozen_stone:0)
Block(-7,6,-6,iceandfire:frozen_stone:0)
Block(-7,6,-5,iceandfire:frozen_stone:0)
Block(-7,6,-4,iceandfire:frozen_stone:0)
Block(-7,6,-3,iceandfire:frozen_stone:0)
Block(-7,6,-2,iceandfire:frozen_stone:0)
Block(-7,6,-1,iceandfire:frozen_stone:0)
Block(-7,6,0,AIR:0)
Block(-7,6,1,AIR:0)
Block(-7,6,2,AIR:0)
Block(-7,6,3,AIR:0)
Block(-7,6,4,AIR:0)
Block(-7,6,5,AIR:0)
Block(-7,6,6,AIR:0)
Block(-7,6,7,AIR:0)
Block(-7,6,8,AIR:0)
Block(-7,6,9,quark:stone_speleothem:1)
Block(-7,6,10,AIR:0)
Block(-7,6,11,iceandfire:frozen_stone:0)
Block(-7,6,12,iceandfire:frozen_stone:0)
Block(-7,6,13,iceandfire:frozen_stone:0)
Block(-7,7,-6,iceandfire:frozen_stone:0)
Block(-7,7,-5,iceandfire:frozen_stone:0)
Block(-7,7,-4,iceandfire:frozen_stone:0)
Block(-7,7,-3,iceandfire:frozen_stone:0)
Block(-7,7,-2,iceandfire:frozen_stone:0)
Block(-7,7,-1,iceandfire:frozen_stone:0)
Block(-7,7,0,iceandfire:frozen_stone:0)
Block(-7,7,1,AIR:0)
Block(-7,7,2,AIR:0)
Block(-7,7,3,AIR:0)
Block(-7,7,4,AIR:0)
Block(-7,7,5,AIR:0)
Block(-7,7,6,AIR:0)
Block(-7,7,7,AIR:0)
Block(-7,7,8,quark:stone_speleothem:2)
Block(-7,7,9,quark:stone_speleothem:2)
Block(-7,7,10,AIR:0)
Block(-7,7,11,iceandfire:frozen_stone:0)
Block(-7,7,12,iceandfire:frozen_stone:0)
Block(-7,7,13,iceandfire:frozen_stone:0)
Block(-7,8,-6,iceandfire:frozen_stone:0)
Block(-7,8,-5,iceandfire:frozen_stone:0)
Block(-7,8,-4,iceandfire:frozen_stone:0)
Block(-7,8,-3,iceandfire:frozen_stone:0)
Block(-7,8,-2,iceandfire:frozen_stone:0)
Block(-7,8,-1,iceandfire:frozen_stone:0)
Block(-7,8,0,AIR:0)
Block(-7,8,1,AIR:0)
Block(-7,8,2,AIR:0)
Block(-7,8,3,AIR:0)
Block(-7,8,4,AIR:0)
Block(-7,8,5,AIR:0)
Block(-7,8,6,AIR:0)
Block(-7,8,7,AIR:0)
Block(-7,8,8,STONE:0)
Block(-7,8,9,STONE:0)
Block(-7,8,10,iceandfire:frozen_stone:0)
Block(-7,8,11,iceandfire:frozen_stone:0)
Block(-7,8,12,iceandfire:frozen_stone:0)
Block(-7,8,13,STONE:0)
Block(-7,9,-3,iceandfire:frozen_stone:0)
Block(-7,9,-2,iceandfire:frozen_stone:0)
Block(-7,9,-1,iceandfire:frozen_stone:0)
Block(-7,9,0,iceandfire:frozen_stone:0)
Block(-7,9,1,iceandfire:frozen_stone:0)
Block(-7,9,2,quark:stone_stairs:5)
Block(-7,9,3,quark:stone_stairs:7)
Block(-7,9,4,AIR:0)
Block(-7,9,5,iceandfire:frozen_stone:0)
Block(-7,9,6,AIR:0)
Block(-7,9,7,iceandfire:frozen_stone:0)
Block(-7,9,8,STONE:0)
Block(-7,9,9,STONE:0)
Block(-7,9,10,STONE:0)
Block(-7,9,11,STONE:0)
Block(-7,9,12,STONE:0)
Block(-7,10,-2,iceandfire:frozen_stone:0)
Block(-7,10,-1,iceandfire:frozen_stone:0)
Block(-7,10,0,iceandfire:frozen_stone:0)
Block(-7,10,1,iceandfire:frozen_stone:0)
Block(-7,10,2,iceandfire:frozen_stone:0)
Block(-7,10,3,iceandfire:frozen_stone:0)
Block(-7,10,4,iceandfire:frozen_stone:0)
Block(-7,10,5,iceandfire:frozen_stone:0)
Block(-7,10,6,iceandfire:frozen_stone:0)
Block(-7,10,7,iceandfire:frozen_stone:0)
Block(-7,10,8,STONE:0)
Block(-7,10,9,STONE:0)
Block(-7,10,10,STONE:0)
Block(-7,11,-1,iceandfire:frozen_stone:0)
Block(-7,11,0,iceandfire:frozen_stone:0)
Block(-7,11,1,iceandfire:frozen_stone:0)
Block(-7,11,2,STONE:0)
Block(-7,11,3,iceandfire:frozen_stone:0)
Block(-7,11,4,iceandfire:frozen_stone:0)
Block(-7,11,5,iceandfire:frozen_stone:0)
Block(-7,11,6,iceandfire:frozen_stone:0)
Block(-7,11,7,iceandfire:frozen_stone:0)
Block(-7,11,8,STONE:0)
Block(-7,11,9,STONE:0)
Block(-7,12,0,STONE:0)
Block(-7,12,1,STONE:0)
Block(-7,12,2,STONE:0)
Block(-7,12,3,STONE:0)
Block(-7,12,4,iceandfire:frozen_stone:0)
Block(-7,12,5,iceandfire:frozen_stone:0)
Block(-7,12,6,iceandfire:frozen_stone:0)
Block(-6,0,7,STONE:0)
Block(-6,0,8,STONE:0)
Block(-6,0,9,STONE:0)
Block(-6,1,0,STONE:0)
Block(-6,1,1,ICE:0)
Block(-6,1,2,iceandfire:frozen_stone:0)
Block(-6,1,4,iceandfire:frozen_stone:0)
Block(-6,1,5,iceandfire:frozen_stone:0)
Block(-6,1,6,iceandfire:frozen_stone:0)
Block(-6,1,7,iceandfire:frozen_stone:0)
Block(-6,1,8,iceandfire:frozen_stone:0)
Block(-6,1,9,iceandfire:frozen_stone:0)
Block(-6,1,10,iceandfire:frozen_stone:0)
Block(-6,2,-1,STONE:0)
Block(-6,2,0,ICE:0)
Block(-6,2,1,ICE:0)
Block(-6,2,2,ICE:0)
Block(-6,2,3,iceandfire:frozen_stone:0)
Block(-6,2,4,iceandfire:frozen_stone:0)
Block(-6,2,5,iceandfire:frozen_stone:0)
Block(-6,2,6,iceandfire:frozen_stone:0)
Block(-6,2,7,iceandfire:frozen_stone:0)
Block(-6,2,8,iceandfire:frozen_stone:0)
Block(-6,2,9,iceandfire:frozen_stone:0)
Block(-6,2,10,iceandfire:frozen_stone:0)
Block(-6,2,11,iceandfire:frozen_stone:0)
Block(-6,3,-8,STONE:0)
Block(-6,3,-7,STONE:0)
Block(-6,3,-6,STONE:0)
Block(-6,3,-2,iceandfire:frozen_stone:0)
Block(-6,3,-1,iceandfire:frozen_stone:0)
Block(-6,3,0,iceandfire:dragon_ice_spikes:0)
Block(-6,3,1,SNOW:0)
Block(-6,3,2,AIR:0)
Block(-6,3,3,SNOW:0)
Block(-6,3,4,SNOW:0)
Block(-6,3,5,biomesoplenty:grass:1)
Block(-6,3,6,SNOW:0)
Block(-6,3,7,AIR:0)
Block(-6,3,8,AIR:0)
Block(-6,3,9,AIR:0)
Block(-6,3,10,AIR:0)
Block(-6,3,11,AIR:0)
Block(-6,3,12,iceandfire:frozen_stone:0)
Block(-6,4,-8,STONE:0)
Block(-6,4,-7,STONE:0)
Block(-6,4,-6,STONE:0)
Block(-6,4,-3,iceandfire:frozen_stone:0)
Block(-6,4,-2,iceandfire:dragon_ice_spikes:0)
Block(-6,4,-1,quark:stone_speleothem:2)
Block(-6,4,0,AIR:0)
Block(-6,4,1,AIR:0)
Block(-6,4,2,AIR:0)
Block(-6,4,3,AIR:0)
Block(-6,4,4,AIR:0)
Block(-6,4,5,SNOW:0)
Block(-6,4,6,AIR:0)
Block(-6,4,7,AIR:0)
Block(-6,4,8,AIR:0)
Block(-6,4,9,AIR:0)
Block(-6,4,10,AIR:0)
Block(-6,4,11,AIR:0)
Block(-6,4,12,quark:stone_speleothem:2)
Block(-6,4,13,iceandfire:frozen_stone:0)
Block(-6,4,14,iceandfire:frozen_stone:0)
Block(-6,5,-8,STONE:0)
Block(-6,5,-7,iceandfire:frozen_stone:0)
Block(-6,5,-6,iceandfire:frozen_stone:0)
Block(-6,5,-5,iceandfire:frozen_stone:0)
Block(-6,5,-4,iceandfire:frozen_stone:0)
Block(-6,5,-3,AIR:0)
Block(-6,5,-2,AIR:0)
Block(-6,5,-1,quark:stone_speleothem:1)
Block(-6,5,0,AIR:0)
Block(-6,5,1,AIR:0)
Block(-6,5,2,AIR:0)
Block(-6,5,3,AIR:0)
Block(-6,5,4,AIR:0)
Block(-6,5,5,AIR:0)
Block(-6,5,6,AIR:0)
Block(-6,5,7,AIR:0)
Block(-6,5,8,AIR:0)
Block(-6,5,9,AIR:0)
Block(-6,5,10,AIR:0)
Block(-6,5,11,quark:stone_speleothem:0)
Block(-6,5,12,quark:stone_speleothem:2)
Block(-6,5,13,iceandfire:frozen_stone:0)
Block(-6,5,14,STONE:0)
Block(-6,6,-8,STONE:0)
Block(-6,6,-7,iceandfire:frozen_stone:0)
Block(-6,6,-6,iceandfire:frozen_stone:0)
Block(-6,6,-5,iceandfire:frozen_stone:0)
Block(-6,6,-4,iceandfire:frozen_stone:0)
Block(-6,6,-3,iceandfire:frozen_stone:0)
Block(-6,6,-2,quark:stone_speleothem:0)
Block(-6,6,-1,quark:stone_speleothem:0)
Block(-6,6,0,AIR:0)
Block(-6,6,1,AIR:0)
Block(-6,6,2,AIR:0)
Block(-6,6,3,AIR:0)
Block(-6,6,4,AIR:0)
Block(-6,6,5,AIR:0)
Block(-6,6,6,AIR:0)
Block(-6,6,7,AIR:0)
Block(-6,6,8,AIR:0)
Block(-6,6,9,AIR:0)
Block(-6,6,10,AIR:0)
Block(-6,6,11,quark:stone_speleothem:1)
Block(-6,6,12,iceandfire:frozen_stone:0)
Block(-6,6,13,iceandfire:frozen_stone:0)
Block(-6,6,14,STONE:0)
Block(-6,7,-8,STONE:0)
Block(-6,7,-7,iceandfire:frozen_stone:0)
Block(-6,7,-6,iceandfire:frozen_stone:0)
Block(-6,7,-5,iceandfire:frozen_stone:0)
Block(-6,7,-4,iceandfire:frozen_stone:0)
Block(-6,7,-3,iceandfire:frozen_stone:0)
Block(-6,7,-2,quark:stone_speleothem:1)
Block(-6,7,-1,quark:stone_speleothem:0)
Block(-6,7,0,AIR:0)
Block(-6,7,1,AIR:0)
Block(-6,7,2,AIR:0)
Block(-6,7,3,AIR:0)
Block(-6,7,4,AIR:0)
Block(-6,7,5,AIR:0)
Block(-6,7,6,AIR:0)
Block(-6,7,7,AIR:0)
Block(-6,7,8,AIR:0)
Block(-6,7,9,AIR:0)
Block(-6,7,10,AIR:0)
Block(-6,7,11,quark:stone_speleothem:2)
Block(-6,7,12,iceandfire:frozen_stone:0)
Block(-6,7,13,iceandfire:frozen_stone:0)
Block(-6,8,-8,STONE:0)
Block(-6,8,-7,iceandfire:frozen_stone:0)
Block(-6,8,-6,iceandfire:frozen_stone:0)
Block(-6,8,-5,iceandfire:frozen_stone:0)
Block(-6,8,-4,iceandfire:frozen_stone:0)
Block(-6,8,-3,iceandfire:frozen_stone:0)
Block(-6,8,-2,quark:stone_speleothem:2)
Block(-6,8,-1,quark:stone_speleothem:1)
Block(-6,8,0,AIR:0)
Block(-6,8,1,AIR:0)
Block(-6,8,2,AIR:0)
Block(-6,8,3,AIR:0)
Block(-6,8,4,AIR:0)
Block(-6,8,5,AIR:0)
Block(-6,8,6,AIR:0)
Block(-6,8,7,AIR:0)
Block(-6,8,8,AIR:0)
Block(-6,8,9,AIR:0)
Block(-6,8,10,iceandfire:frozen_stone:0)
Block(-6,8,11,iceandfire:frozen_stone:0)
Block(-6,8,12,iceandfire:frozen_stone:0)
Block(-6,8,13,STONE:0)
Block(-6,9,-8,STONE:0)
Block(-6,9,-7,STONE:0)
Block(-6,9,-6,iceandfire:frozen_stone:0)
Block(-6,9,-5,iceandfire:frozen_stone:0)
Block(-6,9,-4,iceandfire:frozen_stone:0)
Block(-6,9,-3,iceandfire:frozen_stone:0)
Block(-6,9,-2,iceandfire:frozen_stone:0)
Block(-6,9,-1,quark:stone_speleothem:2)
Block(-6,9,0,AIR:0)
Block(-6,9,1,AIR:0)
Block(-6,9,2,AIR:0)
Block(-6,9,3,AIR:0)
Block(-6,9,4,AIR:0)
Block(-6,9,5,AIR:0)
Block(-6,9,6,AIR:0)
Block(-6,9,7,AIR:0)
Block(-6,9,8,iceandfire:frozen_stone:0)
Block(-6,9,9,iceandfire:frozen_stone:0)
Block(-6,9,10,STONE:0)
Block(-6,9,11,STONE:0)
Block(-6,9,12,STONE:0)
Block(-6,10,-5,STONE:0)
Block(-6,10,-4,iceandfire:frozen_stone:0)
Block(-6,10,-3,iceandfire:frozen_stone:0)
Block(-6,10,-2,iceandfire:frozen_stone:0)
Block(-6,10,-1,iceandfire:frozen_stone:0)
Block(-6,10,0,iceandfire:frozen_stone:0)
Block(-6,10,1,iceandfire:frozen_stone:0)
Block(-6,10,2,iceandfire:frozen_stone:0)
Block(-6,10,3,iceandfire:frozen_stone:0)
Block(-6,10,4,iceandfire:frozen_stone:0)
Block(-6,10,5,iceandfire:frozen_stone:0)
Block(-6,10,6,iceandfire:frozen_stone:0)
Block(-6,10,7,iceandfire:frozen_stone:0)
Block(-6,10,8,iceandfire:frozen_stone:0)
Block(-6,10,9,iceandfire:frozen_stone:0)
Block(-6,10,10,STONE:0)
Block(-6,11,-2,iceandfire:frozen_stone:0)
Block(-6,11,-1,iceandfire:frozen_stone:0)
Block(-6,11,0,iceandfire:frozen_stone:0)
Block(-6,11,1,iceandfire:frozen_stone:0)
Block(-6,11,2,iceandfire:frozen_stone:0)
Block(-6,11,3,iceandfire:frozen_stone:0)
Block(-6,11,4,iceandfire:frozen_stone:0)
Block(-6,11,5,iceandfire:frozen_stone:0)
Block(-6,11,6,iceandfire:frozen_stone:0)
Block(-6,11,7,iceandfire:frozen_stone:0)
Block(-6,11,8,iceandfire:frozen_stone:0)
Block(-6,11,9,STONE:0)
Block(-6,12,-1,iceandfire:frozen_stone:0)
Block(-6,12,0,iceandfire:frozen_stone:0)
Block(-6,12,1,iceandfire:frozen_stone:0)
Block(-6,12,2,iceandfire:frozen_stone:0)
Block(-6,12,3,STONE:0)
Block(-6,12,4,iceandfire:frozen_stone:0)
Block(-6,12,5,iceandfire:frozen_stone:0)
Block(-6,12,6,iceandfire:frozen_stone:0)
Block(-5,0,0,STONE:0)
Block(-5,0,1,STONE:0)
Block(-5,0,2,STONE:0)
Block(-5,0,7,STONE:0)
Block(-5,0,8,STONE:0)
Block(-5,0,9,STONE:0)
Block(-5,1,-1,STONE:0)
Block(-5,1,0,ICE:0)
Block(-5,1,1,ICE:0)
Block(-5,1,2,ICE:0)
Block(-5,1,3,iceandfire:frozen_stone:0)
Block(-5,1,4,iceandfire:frozen_stone:0)
Block(-5,1,5,iceandfire:frozen_stone:0)
Block(-5,1,6,iceandfire:frozen_stone:0)
Block(-5,1,7,iceandfire:frozen_stone:0)
Block(-5,1,8,iceandfire:frozen_stone:0)
Block(-5,1,9,STONE:0)
Block(-5,1,10,STONE:0)
Block(-5,1,11,iceandfire:frozen_stone:0)
Block(-5,1,12,iceandfire:frozen_stone:0)
Block(-5,1,13,iceandfire:frozen_stone:0)
Block(-5,2,-8,STONE:0)
Block(-5,2,-7,STONE:0)
Block(-5,2,-6,STONE:0)
Block(-5,2,-4,iceandfire:frozen_stone:0)
Block(-5,2,-3,iceandfire:frozen_stone:0)
Block(-5,2,-2,STONE:0)
Block(-5,2,-1,STONE:0)
Block(-5,2,0,ICE:0)
Block(-5,2,1,ICE:0)
Block(-5,2,2,ICE:0)
Block(-5,2,3,iceandfire:frozen_stone:0)
Block(-5,2,4,iceandfire:frozen_stone:0)
Block(-5,2,5,iceandfire:frozen_stone:0)
Block(-5,2,6,iceandfire:frozen_stone:0)
Block(-5,2,7,iceandfire:frozen_stone:0)
Block(-5,2,8,iceandfire:frozen_stone:0)
Block(-5,2,9,iceandfire:frozen_stone:0)
Block(-5,2,10,iceandfire:frozen_stone:0)
Block(-5,2,11,iceandfire:frozen_stone:0)
Block(-5,2,12,iceandfire:frozen_stone:0)
Block(-5,2,13,iceandfire:frozen_stone:0)
Block(-5,3,-9,STONE:0)
Block(-5,3,-8,STONE:0)
Block(-5,3,-7,STONE:0)
Block(-5,3,-6,STONE:0)
Block(-5,3,-5,iceandfire:frozen_stone:0)
Block(-5,3,-4,iceandfire:frozen_stone:0)
Block(-5,3,-3,iceandfire:frozen_stone:0)
Block(-5,3,-2,iceandfire:frozen_stone:0)
Block(-5,3,-1,biomesoplenty:grass:1)
Block(-5,3,0,iceandfire:dragon_ice_spikes:0)
Block(-5,3,1,AIR:0)
Block(-5,3,2,SNOW:0)
Block(-5,3,3,AIR:0)
Block(-5,3,4,AIR:0)
Block(-5,3,5,betternether:bone_button:5)
Block(-5,3,6,BROWN_MUSHROOM:0)
Block(-5,3,7,AIR:0)
Block(-5,3,8,AIR:0)
Block(-5,3,9,AIR:0)
Block(-5,3,10,AIR:0)
Block(-5,3,11,AIR:0)
Block(-5,3,12,rustic:mooncap_mushroom:0)
Block(-5,3,13,iceandfire:frozen_stone:0)
Block(-5,3,14,iceandfire:frozen_stone:0)
Block(-5,4,-9,STONE:0)
Block(-5,4,-8,STONE:0)
Block(-5,4,-7,iceandfire:frozen_stone:0)
Block(-5,4,-6,iceandfire:frozen_stone:0)
Block(-5,4,-5,iceandfire:frozen_stone:0)
Block(-5,4,-4,iceandfire:frozen_stone:0)
Block(-5,4,-3,AIR:0)
Block(-5,4,-2,quark:stone_speleothem:2)
Block(-5,4,-1,SNOW:0)
Block(-5,4,0,AIR:0)
Block(-5,4,1,AIR:0)
Block(-5,4,2,AIR:0)
Block(-5,4,3,AIR:0)
Block(-5,4,4,AIR:0)
Block(-5,4,5,AIR:0)
Block(-5,4,6,AIR:0)
Block(-5,4,7,AIR:0)
Block(-5,4,8,AIR:0)
Block(-5,4,9,AIR:0)
Block(-5,4,10,AIR:0)
Block(-5,4,11,AIR:0)
Block(-5,4,12,AIR:0)
Block(-5,4,13,iceandfire:frozen_stone:0)
Block(-5,4,14,iceandfire:frozen_stone:0)
Block(-5,4,15,STONE:0)
Block(-5,5,-9,STONE:0)
Block(-5,5,-8,iceandfire:frozen_stone:0)
Block(-5,5,-7,iceandfire:frozen_stone:0)
Block(-5,5,-6,iceandfire:frozen_stone:0)
Block(-5,5,-5,quark:stone_speleothem:2)
Block(-5,5,-4,iceandfire:frozen_stone:0)
Block(-5,5,-3,AIR:0)
Block(-5,5,-2,quark:stone_speleothem:1)
Block(-5,5,-1,AIR:0)
Block(-5,5,0,AIR:0)
Block(-5,5,1,AIR:0)
Block(-5,5,2,AIR:0)
Block(-5,5,3,AIR:0)
Block(-5,5,4,AIR:0)
Block(-5,5,5,AIR:0)
Block(-5,5,6,AIR:0)
Block(-5,5,7,AIR:0)
Block(-5,5,8,AIR:0)
Block(-5,5,9,AIR:0)
Block(-5,5,10,AIR:0)
Block(-5,5,11,AIR:0)
Block(-5,5,12,AIR:0)
Block(-5,5,13,iceandfire:frozen_stone:0)
Block(-5,5,14,STONE:0)
Block(-5,5,15,STONE:0)
Block(-5,6,-10,STONE:0)
Block(-5,6,-9,STONE:0)
Block(-5,6,-8,iceandfire:frozen_stone:0)
Block(-5,6,-7,iceandfire:frozen_stone:0)
Block(-5,6,-6,iceandfire:frozen_stone:0)
Block(-5,6,-5,quark:stone_speleothem:1)
Block(-5,6,-4,AIR:0)
Block(-5,6,-3,quark:stone_speleothem:0)
Block(-5,6,-2,quark:stone_speleothem:0)
Block(-5,6,-1,AIR:0)
Block(-5,6,0,AIR:0)
Block(-5,6,1,AIR:0)
Block(-5,6,2,AIR:0)
Block(-5,6,3,AIR:0)
Block(-5,6,4,AIR:0)
Block(-5,6,5,AIR:0)
Block(-5,6,6,AIR:0)
Block(-5,6,7,AIR:0)
Block(-5,6,8,AIR:0)
Block(-5,6,9,AIR:0)
Block(-5,6,10,AIR:0)
Block(-5,6,11,AIR:0)
Block(-5,6,12,AIR:0)
Block(-5,6,13,iceandfire:frozen_stone:0)
Block(-5,6,14,STONE:0)
Block(-5,6,15,STONE:0)
Block(-5,7,-10,STONE:0)
Block(-5,7,-9,STONE:0)
Block(-5,7,-8,iceandfire:frozen_stone:0)
Block(-5,7,-7,iceandfire:frozen_stone:0)
Block(-5,7,-6,iceandfire:frozen_stone:0)
Block(-5,7,-5,quark:stone_speleothem:2)
Block(-5,7,-4,iceandfire:frozen_stone:0)
Block(-5,7,-3,quark:stone_speleothem:1)
Block(-5,7,-2,quark:stone_speleothem:0)
Block(-5,7,-1,AIR:0)
Block(-5,7,0,AIR:0)
Block(-5,7,1,AIR:0)
Block(-5,7,2,quark:slate_speleothem:0)
Block(-5,7,3,AIR:0)
Block(-5,7,4,AIR:0)
Block(-5,7,5,AIR:0)
Block(-5,7,6,quark:slate_speleothem:0)
Block(-5,7,7,AIR:0)
Block(-5,7,8,AIR:0)
Block(-5,7,9,AIR:0)
Block(-5,7,10,AIR:0)
Block(-5,7,11,AIR:0)
Block(-5,7,12,AIR:0)
Block(-5,7,13,iceandfire:frozen_stone:0)
Block(-5,7,14,STONE:0)
Block(-5,8,-10,STONE:0)
Block(-5,8,-9,STONE:0)
Block(-5,8,-8,STONE:0)
Block(-5,8,-7,iceandfire:frozen_stone:0)
Block(-5,8,-6,iceandfire:frozen_stone:0)
Block(-5,8,-5,iceandfire:frozen_stone:0)
Block(-5,8,-4,iceandfire:frozen_stone:0)
Block(-5,8,-3,quark:stone_speleothem:2)
Block(-5,8,-2,quark:stone_speleothem:1)
Block(-5,8,-1,AIR:0)
Block(-5,8,0,AIR:0)
Block(-5,8,1,AIR:0)
Block(-5,8,2,quark:slate_speleothem:1)
Block(-5,8,3,AIR:0)
Block(-5,8,4,AIR:0)
Block(-5,8,5,AIR:0)
Block(-5,8,6,quark:slate_speleothem:1)
Block(-5,8,7,AIR:0)
Block(-5,8,8,AIR:0)
Block(-5,8,9,AIR:0)
Block(-5,8,10,AIR:0)
Block(-5,8,11,iceandfire:frozen_stone:0)
Block(-5,8,12,iceandfire:frozen_stone:0)
Block(-5,8,13,STONE:0)
Block(-5,8,14,STONE:0)
Block(-5,9,-10,STONE:0)
Block(-5,9,-9,STONE:0)
Block(-5,9,-8,STONE:0)
Block(-5,9,-7,STONE:0)
Block(-5,9,-6,iceandfire:frozen_stone:0)
Block(-5,9,-5,iceandfire:frozen_stone:0)
Block(-5,9,-4,iceandfire:frozen_stone:0)
Block(-5,9,-3,iceandfire:frozen_stone:0)
Block(-5,9,-2,quark:stone_speleothem:2)
Block(-5,9,-1,AIR:0)
Block(-5,9,0,AIR:0)
Block(-5,9,1,AIR:0)
Block(-5,9,2,quark:slate_speleothem:2)
Block(-5,9,3,AIR:0)
Block(-5,9,4,AIR:0)
Block(-5,9,5,AIR:0)
Block(-5,9,6,quark:slate_speleothem:2)
Block(-5,9,7,AIR:0)
Block(-5,9,8,AIR:0)
Block(-5,9,9,AIR:0)
Block(-5,9,10,iceandfire:frozen_stone:0)
Block(-5,9,11,STONE:0)
Block(-5,9,12,STONE:0)
Block(-5,9,13,STONE:0)
Block(-5,10,-10,STONE:0)
Block(-5,10,-9,STONE:0)
Block(-5,10,-8,STONE:0)
Block(-5,10,-7,STONE:0)
Block(-5,10,-6,STONE:0)
Block(-5,10,-5,STONE:0)
Block(-5,10,-4,iceandfire:frozen_stone:0)
Block(-5,10,-3,iceandfire:frozen_stone:0)
Block(-5,10,-2,iceandfire:frozen_stone:0)
Block(-5,10,-1,iceandfire:frozen_stone:0)
Block(-5,10,0,iceandfire:frozen_stone:0)
Block(-5,10,1,iceandfire:frozen_stone:0)
Block(-5,10,2,iceandfire:frozen_stone:0)
Block(-5,10,3,iceandfire:frozen_stone:0)
Block(-5,10,4,iceandfire:frozen_stone:0)
Block(-5,10,5,iceandfire:frozen_stone:0)
Block(-5,10,6,iceandfire:frozen_stone:0)
Block(-5,10,7,iceandfire:frozen_stone:0)
Block(-5,10,8,iceandfire:frozen_stone:0)
Block(-5,10,9,iceandfire:frozen_stone:0)
Block(-5,10,10,iceandfire:frozen_stone:0)
Block(-5,10,11,STONE:0)
Block(-5,11,-10,STONE:0)
Block(-5,11,-9,STONE:0)
Block(-5,11,-8,STONE:0)
Block(-5,11,-5,STONE:0)
Block(-5,11,-4,STONE:0)
Block(-5,11,-3,iceandfire:frozen_stone:0)
Block(-5,11,-2,iceandfire:frozen_stone:0)
Block(-5,11,-1,iceandfire:frozen_stone:0)
Block(-5,11,0,iceandfire:frozen_stone:0)
Block(-5,11,1,iceandfire:frozen_stone:0)
Block(-5,11,2,iceandfire:frozen_stone:0)
Block(-5,11,3,iceandfire:frozen_stone:0)
Block(-5,11,4,iceandfire:frozen_stone:0)
Block(-5,11,5,iceandfire:frozen_stone:0)
Block(-5,11,6,iceandfire:frozen_stone:0)
Block(-5,11,7,iceandfire:frozen_stone:0)
Block(-5,11,8,iceandfire:frozen_stone:0)
Block(-5,11,9,iceandfire:frozen_stone:0)
Block(-5,12,-2,STONE:0)
Block(-5,12,-1,iceandfire:frozen_stone:0)
Block(-5,12,0,iceandfire:frozen_stone:0)
Block(-5,12,1,iceandfire:frozen_stone:0)
Block(-5,12,2,iceandfire:frozen_stone:0)
Block(-5,12,3,iceandfire:frozen_stone:0)
Block(-5,12,4,STONE:0)
Block(-5,12,5,STONE:0)
Block(-5,12,6,iceandfire:frozen_stone:0)
Block(-5,12,7,iceandfire:frozen_stone:0)
Block(-5,12,8,iceandfire:frozen_stone:0)
Block(-4,0,0,STONE:0)
Block(-4,0,1,STONE:0)
Block(-4,0,2,STONE:0)
Block(-4,0,3,STONE:0)
Block(-4,0,4,STONE:0)
Block(-4,0,5,STONE:0)
Block(-4,0,11,STONE:0)
Block(-4,0,12,STONE:0)
Block(-4,0,13,STONE:0)
Block(-4,1,-4,iceandfire:frozen_stone:0)
Block(-4,1,-3,iceandfire:frozen_stone:0)
Block(-4,1,-2,STONE:0)
Block(-4,1,-1,STONE:0)
Block(-4,1,0,STONE:0)
Block(-4,1,1,ICE:0)
Block(-4,1,2,ICE:0)
Block(-4,1,3,ICE:0)
Block(-4,1,4,STONE:0)
Block(-4,1,5,STONE:0)
Block(-4,1,6,iceandfire:frozen_stone:0)
Block(-4,1,7,iceandfire:frozen_stone:0)
Block(-4,1,8,iceandfire:frozen_stone:0)
Block(-4,1,9,STONE:0)
Block(-4,1,10,STONE:0)
Block(-4,1,11,STONE:0)
Block(-4,1,12,STONE:0)
Block(-4,1,13,STONE:0)
Block(-4,1,14,STONE:0)
Block(-4,2,-9,STONE:0)
Block(-4,2,-8,STONE:0)
Block(-4,2,-7,iceandfire:frozen_stone:0)
Block(-4,2,-6,iceandfire:frozen_stone:0)
Block(-4,2,-5,iceandfire:frozen_stone:0)
Block(-4,2,-4,iceandfire:frozen_stone:0)
Block(-4,2,-3,iceandfire:frozen_stone:0)
Block(-4,2,-2,iceandfire:frozen_stone:0)
Block(-4,2,-1,ICE:0)
Block(-4,2,0,ICE:0)
Block(-4,2,1,ICE:0)
Block(-4,2,2,iceandfire:frozen_stone:0)
Block(-4,2,3,iceandfire:frozen_stone:0)
Block(-4,2,4,iceandfire:frozen_stone:0)
Block(-4,2,5,iceandfire:frozen_stone:0)
Block(-4,2,6,STATIONARY_WATER:0)
Block(-4,2,7,iceandfire:frozen_stone:0)
Block(-4,2,8,iceandfire:frozen_stone:0)
Block(-4,2,9,iceandfire:frozen_stone:0)
Block(-4,2,10,STONE:0)
Block(-4,2,11,iceandfire:frozen_stone:0)
Block(-4,2,12,iceandfire:frozen_stone:0)
Block(-4,2,13,iceandfire:frozen_stone:0)
Block(-4,2,14,STONE:0)
Block(-4,3,-10,STONE:0)
Block(-4,3,-9,STONE:0)
Block(-4,3,-8,STONE:0)
Block(-4,3,-7,iceandfire:frozen_stone:0)
Block(-4,3,-6,iceandfire:frozen_stone:0)
Block(-4,3,-5,iceandfire:frozen_stone:0)
Block(-4,3,-4,iceandfire:frozen_stone:0)
Block(-4,3,-3,iceandfire:frozen_stone:0)
Block(-4,3,-2,iceandfire:frozen_stone:0)
Block(-4,3,-1,iceandfire:dragon_ice_spikes:0)
Block(-4,3,0,AIR:0)
Block(-4,3,1,AIR:0)
Block(-4,3,2,AIR:0)
Block(-4,3,3,AIR:0)
Block(-4,3,4,AIR:0)
Block(-4,3,5,AIR:0)
Block(-4,3,6,AIR:0)
Block(-4,3,7,betternether:bone_button:5)
Block(-4,3,8,quark:stone_speleothem:2)
Block(-4,3,9,iceandfire:frozen_stone:0)
Block(-4,3,10,AIR:0)
RandomBlock(-4,3,11,SKULL:1,null,6,AIR:0,9,SKULL:1,null,12,AIR:0,15,SKULL:1,null,18,AIR:0,21,SKULL:1,null,24,AIR:0,27,SKULL:1,null,30,AIR:0,33,SKULL:1,null,36,AIR:0,39,SKULL:1,null,42,AIR:0,45,SKULL:1,null,48,AIR:0,51,SKULL:1,null,54,AIR:0,57,SKULL:1,null,60,AIR:0,63,SKULL:1,null,66,AIR:0,69,SKULL:1,null,72,AIR:0,75,SKULL:1,null,78,AIR:0,81,SKULL:1,null,84,AIR:0,87,SKULL:1,null,90,AIR:0,93,SKULL:1,null,96,AIR:0,100)
Block(-4,3,12,contenttweaker:bone_pile:0)
Block(-4,3,13,rustic:mooncap_mushroom:0)
Block(-4,3,14,STONE:0)
Block(-4,3,15,STONE:0)
Block(-4,4,-11,STONE:0)
Block(-4,4,-10,STONE:0)
Block(-4,4,-9,STONE:0)
Block(-4,4,-8,STONE:0)
Block(-4,4,-7,iceandfire:frozen_stone:0)
Block(-4,4,-6,quark:stone_stairs:1)
Block(-4,4,-5,AIR:0)
Block(-4,4,-4,AIR:0)
Block(-4,4,-3,quark:stone_speleothem:2)
Block(-4,4,-2,quark:stone_speleothem:2)
Block(-4,4,-1,AIR:0)
Block(-4,4,0,AIR:0)
Block(-4,4,1,AIR:0)
Block(-4,4,2,AIR:0)
Block(-4,4,3,AIR:0)
Block(-4,4,4,AIR:0)
Block(-4,4,5,AIR:0)
Block(-4,4,6,AIR:0)
Block(-4,4,7,AIR:0)
Block(-4,4,8,quark:stone_speleothem:1)
Block(-4,4,9,quark:stone_speleothem:2)
Block(-4,4,10,AIR:0)
Block(-4,4,11,AIR:0)
Block(-4,4,12,quark:stone_speleothem:0)
Block(-4,4,13,AIR:0)
Block(-4,4,14,STONE:0)
Block(-4,4,15,STONE:0)
Block(-4,4,16,STONE:0)
Block(-4,5,-11,STONE:0)
Block(-4,5,-10,STONE:0)
Block(-4,5,-9,STONE:0)
Block(-4,5,-8,iceandfire:frozen_stone:0)
Block(-4,5,-7,quark:stone_speleothem:2)
Block(-4,5,-6,AIR:0)
Block(-4,5,-5,AIR:0)
Block(-4,5,-4,AIR:0)
Block(-4,5,-3,quark:stone_speleothem:1)
Block(-4,5,-2,quark:stone_speleothem:1)
Block(-4,5,-1,AIR:0)
Block(-4,5,0,AIR:0)
Block(-4,5,1,AIR:0)
Block(-4,5,2,AIR:0)
Block(-4,5,3,AIR:0)
Block(-4,5,4,AIR:0)
Block(-4,5,5,AIR:0)
Block(-4,5,6,AIR:0)
Block(-4,5,7,AIR:0)
Block(-4,5,8,quark:stone_speleothem:0)
Block(-4,5,9,quark:stone_speleothem:1)
Block(-4,5,10,AIR:0)
Block(-4,5,11,AIR:0)
Block(-4,5,12,quark:stone_speleothem:1)
Block(-4,5,13,quark:stone_stairs:6)
Block(-4,5,14,STONE:0)
Block(-4,5,15,STONE:0)
Block(-4,5,16,STONE:0)
Block(-4,6,-11,STONE:0)
Block(-4,6,-10,STONE:0)
Block(-4,6,-9,STONE:0)
Block(-4,6,-8,AIR:0)
Block(-4,6,-7,quark:stone_speleothem:1)
Block(-4,6,-6,quark:stone_speleothem:0)
Block(-4,6,-5,AIR:0)
Block(-4,6,-4,AIR:0)
Block(-4,6,-3,AIR:0)
Block(-4,6,-2,quark:stone_speleothem:0)
Block(-4,6,-1,AIR:0)
Block(-4,6,0,AIR:0)
Block(-4,6,1,AIR:0)
Block(-4,6,2,AIR:0)
Block(-4,6,3,AIR:0)
Block(-4,6,4,AIR:0)
Block(-4,6,5,AIR:0)
Block(-4,6,6,AIR:0)
Block(-4,6,7,AIR:0)
Block(-4,6,8,AIR:0)
Block(-4,6,9,quark:stone_speleothem:0)
Block(-4,6,10,AIR:0)
Block(-4,6,11,AIR:0)
Block(-4,6,12,quark:stone_speleothem:2)
Block(-4,6,13,STONE:0)
Block(-4,6,14,STONE:0)
Block(-4,6,15,STONE:0)
Block(-4,6,16,STONE:0)
Block(-4,7,-11,STONE:0)
Block(-4,7,-10,STONE:0)
Block(-4,7,-9,STONE:0)
Block(-4,7,-8,iceandfire:frozen_stone:0)
Block(-4,7,-7,quark:stone_speleothem:2)
Block(-4,7,-6,quark:stone_speleothem:1)
Block(-4,7,-5,AIR:0)
Block(-4,7,-4,AIR:0)
Block(-4,7,-3,AIR:0)
Block(-4,7,-2,AIR:0)
Block(-4,7,-1,AIR:0)
Block(-4,7,0,AIR:0)
Block(-4,7,1,AIR:0)
Block(-4,7,2,AIR:0)
Block(-4,7,3,AIR:0)
Block(-4,7,4,AIR:0)
Block(-4,7,5,AIR:0)
Block(-4,7,6,AIR:0)
Block(-4,7,7,AIR:0)
Block(-4,7,8,AIR:0)
Block(-4,7,9,AIR:0)
Block(-4,7,10,AIR:0)
Block(-4,7,11,AIR:0)
Block(-4,7,12,iceandfire:frozen_stone:0)
Block(-4,7,13,STONE:0)
Block(-4,7,14,STONE:0)
Block(-4,7,15,STONE:0)
Block(-4,8,-11,STONE:0)
Block(-4,8,-10,STONE:0)
Block(-4,8,-9,STONE:0)
Block(-4,8,-8,STONE:0)
Block(-4,8,-7,iceandfire:frozen_stone:0)
Block(-4,8,-6,quark:stone_speleothem:2)
Block(-4,8,-5,AIR:0)
Block(-4,8,-4,AIR:0)
Block(-4,8,-3,AIR:0)
Block(-4,8,-2,AIR:0)
Block(-4,8,-1,AIR:0)
Block(-4,8,0,AIR:0)
Block(-4,8,1,AIR:0)
Block(-4,8,2,AIR:0)
Block(-4,8,3,AIR:0)
Block(-4,8,4,AIR:0)
Block(-4,8,5,AIR:0)
Block(-4,8,6,AIR:0)
Block(-4,8,7,AIR:0)
Block(-4,8,8,quark:stone_speleothem:1)
Block(-4,8,9,AIR:0)
Block(-4,8,10,AIR:0)
Block(-4,8,11,AIR:0)
Block(-4,8,12,STONE:0)
Block(-4,8,13,STONE:0)
Block(-4,8,14,STONE:0)
Block(-4,8,15,STONE:0)
Block(-4,9,-11,STONE:0)
Block(-4,9,-10,STONE:0)
Block(-4,9,-9,STONE:0)
Block(-4,9,-8,STONE:0)
Block(-4,9,-7,STONE:0)
Block(-4,9,-6,iceandfire:frozen_stone:0)
Block(-4,9,-5,quark:stone_stairs:7)
Block(-4,9,-4,quark:stone_stairs:5)
Block(-4,9,-3,quark:stone_stairs:7)
Block(-4,9,-2,AIR:0)
Block(-4,9,-1,AIR:0)
Block(-4,9,0,AIR:0)
Block(-4,9,1,AIR:0)
Block(-4,9,2,AIR:0)
Block(-4,9,3,AIR:0)
Block(-4,9,4,AIR:0)
Block(-4,9,5,AIR:0)
Block(-4,9,6,AIR:0)
Block(-4,9,7,AIR:0)
Block(-4,9,8,quark:stone_speleothem:2)
Block(-4,9,9,AIR:0)
Block(-4,9,10,iceandfire:frozen_stone:0)
Block(-4,9,11,STONE:0)
Block(-4,9,12,STONE:0)
Block(-4,9,13,STONE:0)
Block(-4,9,14,STONE:0)
Block(-4,10,-11,STONE:0)
Block(-4,10,-10,STONE:0)
Block(-4,10,-9,STONE:0)
Block(-4,10,-8,STONE:0)
Block(-4,10,-7,STONE:0)
Block(-4,10,-6,STONE:0)
Block(-4,10,-5,STONE:0)
Block(-4,10,-4,iceandfire:frozen_stone:0)
Block(-4,10,-3,iceandfire:frozen_stone:0)
Block(-4,10,-2,iceandfire:frozen_stone:0)
Block(-4,10,-1,iceandfire:frozen_stone:0)
Block(-4,10,0,AIR:0)
Block(-4,10,1,AIR:0)
Block(-4,10,2,AIR:0)
Block(-4,10,3,iceandfire:frozen_stone:0)
Block(-4,10,4,iceandfire:frozen_stone:0)
Block(-4,10,5,iceandfire:frozen_stone:0)
Block(-4,10,6,AIR:0)
Block(-4,10,7,iceandfire:frozen_stone:0)
Block(-4,10,8,iceandfire:frozen_stone:0)
Block(-4,10,9,iceandfire:frozen_stone:0)
Block(-4,10,10,iceandfire:frozen_stone:0)
Block(-4,10,11,STONE:0)
Block(-4,10,12,STONE:0)
Block(-4,11,-11,STONE:0)
Block(-4,11,-10,STONE:0)
Block(-4,11,-9,STONE:0)
Block(-4,11,-8,STONE:0)
Block(-4,11,-7,STONE:0)
Block(-4,11,-6,STONE:0)
Block(-4,11,-5,STONE:0)
Block(-4,11,-4,STONE:0)
Block(-4,11,-3,iceandfire:frozen_stone:0)
Block(-4,11,-2,iceandfire:frozen_stone:0)
Block(-4,11,-1,iceandfire:frozen_stone:0)
Block(-4,11,0,iceandfire:frozen_stone:0)
Block(-4,11,1,ICE:0)
Block(-4,11,2,ICE:0)
Block(-4,11,3,ICE:0)
Block(-4,11,4,STONE:0)
Block(-4,11,5,iceandfire:frozen_stone:0)
Block(-4,11,6,iceandfire:frozen_stone:0)
Block(-4,11,7,iceandfire:frozen_stone:0)
Block(-4,11,8,iceandfire:frozen_stone:0)
Block(-4,11,9,iceandfire:frozen_stone:0)
Block(-4,11,10,STONE:0)
Block(-4,11,11,STONE:0)
Block(-4,12,-10,STONE:0)
Block(-4,12,-9,STONE:0)
Block(-4,12,-8,STONE:0)
Block(-4,12,-3,STONE:0)
Block(-4,12,-2,STONE:0)
Block(-4,12,-1,iceandfire:frozen_stone:0)
Block(-4,12,0,iceandfire:frozen_stone:0)
Block(-4,12,1,iceandfire:frozen_stone:0)
Block(-4,12,2,ICE:0)
Block(-4,12,3,iceandfire:frozen_stone:0)
Block(-4,12,4,STONE:0)
Block(-4,12,5,STONE:0)
Block(-4,12,6,iceandfire:frozen_stone:0)
Block(-4,12,7,iceandfire:frozen_stone:0)
Block(-4,12,8,iceandfire:frozen_stone:0)
Block(-3,0,-4,STONE:0)
Block(-3,0,-3,STONE:0)
Block(-3,0,-2,STONE:0)
Block(-3,0,-1,STONE:0)
Block(-3,0,0,STONE:0)
Block(-3,0,1,STONE:0)
Block(-3,0,2,STONE:0)
Block(-3,0,3,STONE:0)
Block(-3,0,4,STONE:0)
Block(-3,0,5,STONE:0)
Block(-3,0,6,STONE:0)
Block(-3,0,7,STONE:0)
Block(-3,0,9,STONE:0)
Block(-3,0,10,STONE:0)
Block(-3,0,11,STONE:0)
Block(-3,0,12,STONE:0)
Block(-3,0,13,STONE:0)
Block(-3,1,-6,iceandfire:frozen_stone:0)
Block(-3,1,-5,iceandfire:frozen_stone:0)
Block(-3,1,-4,iceandfire:frozen_stone:0)
Block(-3,1,-3,iceandfire:frozen_stone:0)
Block(-3,1,-2,STONE:0)
Block(-3,1,-1,STONE:0)
Block(-3,1,0,ICE:0)
Block(-3,1,1,STONE:0)
Block(-3,1,2,ICE:0)
Block(-3,1,3,STONE:0)
Block(-3,1,4,STONE:0)
Block(-3,1,5,STONE:0)
Block(-3,1,6,iceandfire:frozen_stone:0)
Block(-3,1,7,iceandfire:frozen_stone:0)
Block(-3,1,8,iceandfire:frozen_stone:0)
Block(-3,1,9,STONE:0)
Block(-3,1,10,STONE:0)
Block(-3,1,11,STONE:0)
Block(-3,1,12,STONE:0)
Block(-3,1,13,STONE:0)
Block(-3,1,14,STONE:0)
Block(-3,2,-9,STONE:0)
Block(-3,2,-8,iceandfire:frozen_stone:0)
Block(-3,2,-7,iceandfire:frozen_stone:0)
Block(-3,2,-6,iceandfire:frozen_stone:0)
Block(-3,2,-5,iceandfire:frozen_stone:0)
Block(-3,2,-4,iceandfire:frozen_stone:0)
Block(-3,2,-3,BONE_BLOCK:0)
Block(-3,2,-2,iceandfire:frozen_stone:0)
Block(-3,2,-1,ICE:0)
Block(-3,2,0,ICE:0)
Block(-3,2,1,ICE:0)
Block(-3,2,2,ICE:0)
Block(-3,2,3,ICE:0)
Block(-3,2,4,STATIONARY_WATER:0)
Block(-3,2,5,STATIONARY_WATER:0)
Block(-3,2,6,STATIONARY_WATER:0)
Block(-3,2,7,iceandfire:frozen_stone:0)
Block(-3,2,8,iceandfire:frozen_stone:0)
Block(-3,2,9,iceandfire:frozen_stone:0)
Block(-3,2,10,STONE:0)
Block(-3,2,11,STONE:0)
Block(-3,2,12,STONE:0)
Block(-3,2,13,STONE:0)
Block(-3,2,14,STONE:0)
Block(-3,2,15,STONE:0)
Block(-3,3,-11,iceandfire:frozen_stone:0)
Block(-3,3,-10,iceandfire:frozen_stone:0)
Block(-3,3,-9,iceandfire:frozen_stone:0)
Block(-3,3,-8,iceandfire:frozen_stone:0)
Block(-3,3,-7,iceandfire:frozen_stone:0)
Block(-3,3,-6,iceandfire:frozen_stone:0)
Block(-3,3,-5,iceandfire:frozen_stone:0)
Block(-3,3,-4,quark:stone_speleothem:2)
Block(-3,3,-3,betternether:bone_button:5)
Block(-3,3,-2,rustic:mooncap_mushroom:0)
Block(-3,3,-1,AIR:0)
Block(-3,3,0,AIR:0)
Block(-3,3,1,AIR:0)
Block(-3,3,2,AIR:0)
Block(-3,3,3,AIR:0)
Block(-3,3,4,AIR:0)
Block(-3,3,5,AIR:0)
Block(-3,3,6,AIR:0)
Block(-3,3,7,iceandfire:frozen_stone:0)
Block(-3,3,8,iceandfire:frozen_stone:0)
Block(-3,3,9,quark:stone_stairs:1)
Block(-3,3,10,rustic:mooncap_mushroom:0)
Block(-3,3,11,AIR:0)
Block(-3,3,12,contenttweaker:bone_pile:0)
Block(-3,3,13,STONE:0)
Block(-3,3,14,STONE:0)
Block(-3,3,15,STONE:0)
Block(-3,3,16,STONE:0)
Block(-3,4,-14,STONE:0)
Block(-3,4,-13,STONE:0)
Block(-3,4,-12,STONE:0)
Block(-3,4,-11,iceandfire:frozen_stone:0)
Block(-3,4,-10,iceandfire:frozen_stone:0)
Block(-3,4,-9,iceandfire:frozen_stone:0)
Block(-3,4,-8,iceandfire:frozen_stone:0)
Block(-3,4,-7,quark:stone_stairs:3)
Block(-3,4,-6,AIR:0)
Block(-3,4,-5,AIR:0)
Block(-3,4,-4,quark:stone_speleothem:1)
Block(-3,4,-3,AIR:0)
Block(-3,4,-2,AIR:0)
Block(-3,4,-1,AIR:0)
Block(-3,4,0,AIR:0)
Block(-3,4,1,AIR:0)
Block(-3,4,2,AIR:0)
Block(-3,4,3,AIR:0)
Block(-3,4,4,AIR:0)
Block(-3,4,5,AIR:0)
Block(-3,4,6,AIR:0)
Block(-3,4,7,AIR:0)
Block(-3,4,8,iceandfire:frozen_stone:0)
Block(-3,4,9,AIR:0)
Block(-3,4,10,AIR:0)
Block(-3,4,11,AIR:0)
Block(-3,4,12,AIR:0)
Block(-3,4,13,rustic:mooncap_mushroom:0)
Block(-3,4,14,STONE:0)
Block(-3,4,15,STONE:0)
Block(-3,4,16,STONE:0)
Block(-3,5,-14,STONE:0)
Block(-3,5,-13,STONE:0)
Block(-3,5,-12,STONE:0)
Block(-3,5,-11,iceandfire:frozen_stone:0)
Block(-3,5,-10,iceandfire:frozen_stone:0)
Block(-3,5,-9,iceandfire:dragon_ice_spikes:0)
Block(-3,5,-8,AIR:0)
Block(-3,5,-7,AIR:0)
Block(-3,5,-6,AIR:0)
Block(-3,5,-5,AIR:0)
Block(-3,5,-4,quark:stone_speleothem:0)
Block(-3,5,-3,AIR:0)
Block(-3,5,-2,AIR:0)
Block(-3,5,-1,AIR:0)
Block(-3,5,0,AIR:0)
Block(-3,5,1,AIR:0)
Block(-3,5,2,AIR:0)
Block(-3,5,3,AIR:0)
Block(-3,5,4,AIR:0)
Block(-3,5,5,AIR:0)
Block(-3,5,6,AIR:0)
Block(-3,5,7,AIR:0)
Block(-3,5,8,quark:stone_speleothem:2)
Block(-3,5,9,AIR:0)
Block(-3,5,10,AIR:0)
Block(-3,5,11,AIR:0)
Block(-3,5,12,AIR:0)
Block(-3,5,13,AIR:0)
Block(-3,5,14,iceandfire:frozen_stone:0)
Block(-3,5,15,STONE:0)
Block(-3,5,16,STONE:0)
Block(-3,6,-14,STONE:0)
Block(-3,6,-13,STONE:0)
Block(-3,6,-12,STONE:0)
Block(-3,6,-11,STONE:0)
Block(-3,6,-10,STONE:0)
Block(-3,6,-9,quark:stone_speleothem:0)
Block(-3,6,-8,AIR:0)
Block(-3,6,-7,AIR:0)
Block(-3,6,-6,AIR:0)
Block(-3,6,-5,AIR:0)
Block(-3,6,-4,AIR:0)
Block(-3,6,-3,AIR:0)
Block(-3,6,-2,AIR:0)
Block(-3,6,-1,AIR:0)
Block(-3,6,0,AIR:0)
Block(-3,6,1,AIR:0)
Block(-3,6,2,AIR:0)
Block(-3,6,3,AIR:0)
Block(-3,6,4,AIR:0)
Block(-3,6,5,AIR:0)
Block(-3,6,6,AIR:0)
Block(-3,6,7,AIR:0)
Block(-3,6,8,quark:stone_speleothem:1)
Block(-3,6,9,AIR:0)
Block(-3,6,10,AIR:0)
Block(-3,6,11,AIR:0)
Block(-3,6,12,AIR:0)
Block(-3,6,13,iceandfire:frozen_stone:0)
Block(-3,6,14,iceandfire:frozen_stone:0)
Block(-3,6,15,STONE:0)
Block(-3,6,16,STONE:0)
Block(-3,7,-14,STONE:0)
Block(-3,7,-13,STONE:0)
Block(-3,7,-12,STONE:0)
Block(-3,7,-11,STONE:0)
Block(-3,7,-10,STONE:0)
Block(-3,7,-9,quark:stone_speleothem:1)
Block(-3,7,-8,AIR:0)
Block(-3,7,-7,AIR:0)
Block(-3,7,-6,AIR:0)
Block(-3,7,-5,AIR:0)
Block(-3,7,-4,AIR:0)
Block(-3,7,-3,AIR:0)
Block(-3,7,-2,AIR:0)
Block(-3,7,-1,AIR:0)
Block(-3,7,0,AIR:0)
Block(-3,7,1,AIR:0)
Block(-3,7,2,AIR:0)
Block(-3,7,3,AIR:0)
Block(-3,7,4,AIR:0)
Block(-3,7,5,AIR:0)
Block(-3,7,6,AIR:0)
Block(-3,7,7,quark:stone_speleothem:0)
Block(-3,7,8,quark:stone_speleothem:0)
Block(-3,7,9,AIR:0)
Block(-3,7,10,AIR:0)
Block(-3,7,11,AIR:0)
Block(-3,7,12,AIR:0)
Block(-3,7,13,iceandfire:frozen_stone:0)
Block(-3,7,14,iceandfire:frozen_stone:0)
Block(-3,7,15,STONE:0)
Block(-3,8,-14,STONE:0)
Block(-3,8,-13,STONE:0)
Block(-3,8,-12,STONE:0)
Block(-3,8,-11,STONE:0)
Block(-3,8,-10,STONE:0)
Block(-3,8,-9,quark:stone_speleothem:2)
Block(-3,8,-8,AIR:0)
Block(-3,8,-7,AIR:0)
Block(-3,8,-6,AIR:0)
Block(-3,8,-5,AIR:0)
Block(-3,8,-4,AIR:0)
Block(-3,8,-3,AIR:0)
Block(-3,8,-2,AIR:0)
Block(-3,8,-1,AIR:0)
Block(-3,8,0,AIR:0)
Block(-3,8,1,AIR:0)
Block(-3,8,2,AIR:0)
Block(-3,8,3,AIR:0)
Block(-3,8,4,AIR:0)
Block(-3,8,5,AIR:0)
Block(-3,8,6,AIR:0)
Block(-3,8,7,quark:stone_speleothem:1)
Block(-3,8,8,quark:stone_speleothem:0)
Block(-3,8,9,AIR:0)
Block(-3,8,10,AIR:0)
Block(-3,8,11,AIR:0)
Block(-3,8,12,STONE:0)
Block(-3,8,13,STONE:0)
Block(-3,8,14,STONE:0)
Block(-3,8,15,STONE:0)
Block(-3,9,-14,STONE:0)
Block(-3,9,-13,STONE:0)
Block(-3,9,-12,STONE:0)
Block(-3,9,-11,STONE:0)
Block(-3,9,-10,STONE:0)
Block(-3,9,-9,STONE:0)
Block(-3,9,-8,AIR:0)
Block(-3,9,-7,AIR:0)
Block(-3,9,-6,STONE:0)
Block(-3,9,-5,quark:stone_stairs:5)
Block(-3,9,-4,AIR:0)
Block(-3,9,-3,AIR:0)
Block(-3,9,-2,AIR:0)
Block(-3,9,-1,AIR:0)
Block(-3,9,0,AIR:0)
Block(-3,9,1,AIR:0)
Block(-3,9,2,AIR:0)
Block(-3,9,3,AIR:0)
Block(-3,9,4,AIR:0)
Block(-3,9,5,AIR:0)
Block(-3,9,6,AIR:0)
Block(-3,9,7,quark:stone_speleothem:2)
Block(-3,9,8,quark:stone_speleothem:1)
Block(-3,9,9,AIR:0)
Block(-3,9,10,iceandfire:frozen_stone:0)
Block(-3,9,11,STONE:0)
Block(-3,9,12,STONE:0)
Block(-3,9,13,STONE:0)
Block(-3,9,14,STONE:0)
Block(-3,10,-11,STONE:0)
Block(-3,10,-10,STONE:0)
Block(-3,10,-9,STONE:0)
Block(-3,10,-8,STONE:0)
Block(-3,10,-7,STONE:0)
Block(-3,10,-6,STONE:0)
Block(-3,10,-5,STONE:0)
Block(-3,10,-4,STONE:0)
Block(-3,10,-3,iceandfire:frozen_stone:0)
Block(-3,10,-2,iceandfire:frozen_stone:0)
Block(-3,10,-1,AIR:0)
Block(-3,10,0,AIR:0)
Block(-3,10,1,AIR:0)
Block(-3,10,2,AIR:0)
Block(-3,10,3,AIR:0)
Block(-3,10,4,AIR:0)
Block(-3,10,5,iceandfire:frozen_stone:0)
Block(-3,10,6,AIR:0)
Block(-3,10,7,iceandfire:frozen_stone:0)
Block(-3,10,8,quark:stone_speleothem:2)
Block(-3,10,9,iceandfire:frozen_stone:0)
Block(-3,10,10,iceandfire:frozen_stone:0)
Block(-3,10,11,STONE:0)
Block(-3,10,12,STONE:0)
Block(-3,11,-11,STONE:0)
Block(-3,11,-10,STONE:0)
Block(-3,11,-9,STONE:0)
Block(-3,11,-8,STONE:0)
Block(-3,11,-7,STONE:0)
Block(-3,11,-6,STONE:0)
Block(-3,11,-5,STONE:0)
Block(-3,11,-4,STONE:0)
Block(-3,11,-3,STONE:0)
Block(-3,11,-2,STONE:0)
Block(-3,11,-1,iceandfire:frozen_stone:0)
Block(-3,11,0,iceandfire:frozen_stone:0)
Block(-3,11,1,ICE:0)
Block(-3,11,2,ICE:0)
Block(-3,11,3,ICE:0)
Block(-3,11,4,ICE:0)
Block(-3,11,5,iceandfire:frozen_stone:0)
Block(-3,11,6,iceandfire:frozen_stone:0)
Block(-3,11,7,iceandfire:frozen_stone:0)
Block(-3,11,8,iceandfire:frozen_stone:0)
Block(-3,11,9,iceandfire:frozen_stone:0)
Block(-3,11,10,STONE:0)
Block(-3,11,11,STONE:0)
Block(-3,12,-10,STONE:0)
Block(-3,12,-9,STONE:0)
Block(-3,12,-8,STONE:0)
Block(-3,12,-7,STONE:0)
Block(-3,12,-6,STONE:0)
Block(-3,12,-3,STONE:0)
Block(-3,12,-2,STONE:0)
Block(-3,12,-1,iceandfire:frozen_stone:0)
Block(-3,12,0,iceandfire:frozen_stone:0)
Block(-3,12,1,ICE:0)
Block(-3,12,2,ICE:0)
Block(-3,12,3,ICE:0)
Block(-3,12,4,ICE:0)
Block(-3,12,5,ICE:0)
Block(-3,12,6,iceandfire:frozen_stone:0)
Block(-3,12,7,iceandfire:frozen_stone:0)
Block(-3,12,8,iceandfire:frozen_stone:0)
Block(-2,0,-4,STONE:0)
Block(-2,0,-3,STONE:0)
Block(-2,0,-2,STONE:0)
Block(-2,0,-1,STONE:0)
Block(-2,0,0,STONE:0)
Block(-2,0,1,STONE:0)
Block(-2,0,2,STONE:0)
Block(-2,0,3,STONE:0)
Block(-2,0,4,STONE:0)
Block(-2,0,5,STONE:0)
Block(-2,0,6,STONE:0)
Block(-2,0,7,STONE:0)
Block(-2,0,9,STONE:0)
Block(-2,0,10,STONE:0)
Block(-2,0,11,STONE:0)
Block(-2,0,12,STONE:0)
Block(-2,0,13,STONE:0)
Block(-2,1,-9,STONE:0)
Block(-2,1,-8,STONE:0)
Block(-2,1,-7,iceandfire:frozen_stone:0)
Block(-2,1,-6,iceandfire:frozen_stone:0)
Block(-2,1,-5,iceandfire:frozen_stone:0)
Block(-2,1,-4,iceandfire:frozen_stone:0)
Block(-2,1,-3,iceandfire:frozen_stone:0)
Block(-2,1,-2,STONE:0)
Block(-2,1,-1,ICE:0)
Block(-2,1,0,ICE:0)
Block(-2,1,1,ICE:0)
Block(-2,1,2,STONE:0)
Block(-2,1,3,STONE:0)
Block(-2,1,4,STONE:0)
Block(-2,1,5,STATIONARY_WATER:8)
Block(-2,1,6,STATIONARY_WATER:8)
Block(-2,1,7,STONE:0)
Block(-2,1,8,STONE:0)
Block(-2,1,9,STONE:0)
Block(-2,1,10,STONE:0)
Block(-2,1,11,STONE:0)
Block(-2,1,12,STONE:0)
Block(-2,1,13,STONE:0)
Block(-2,1,14,STONE:0)
Block(-2,2,-10,iceandfire:frozen_stone:0)
Block(-2,2,-9,ICE:0)
Block(-2,2,-8,iceandfire:frozen_stone:0)
Block(-2,2,-7,iceandfire:frozen_stone:0)
Block(-2,2,-6,ICE:0)
Block(-2,2,-5,iceandfire:frozen_stone:0)
Block(-2,2,-4,BONE_BLOCK:0)
Block(-2,2,-3,iceandfire:frozen_stone:0)
Block(-2,2,-2,BONE_BLOCK:0)
Block(-2,2,-1,ICE:0)
Block(-2,2,0,ICE:0)
Block(-2,2,1,BONE_BLOCK:0)
Block(-2,2,2,BONE_BLOCK:8)
Block(-2,2,3,STATIONARY_WATER:0)
Block(-2,2,4,STATIONARY_WATER:0)
Block(-2,2,5,STATIONARY_WATER:0)
Block(-2,2,6,STATIONARY_WATER:0)
Block(-2,2,7,iceandfire:frozen_stone:0)
Block(-2,2,8,iceandfire:frozen_stone:0)
Block(-2,2,9,STONE:0)
Block(-2,2,10,STONE:0)
Block(-2,2,11,STONE:0)
Block(-2,2,12,STONE:0)
Block(-2,2,13,STONE:0)
Block(-2,2,14,STONE:0)
Block(-2,2,15,STONE:0)
Block(-2,3,-14,STONE:0)
Block(-2,3,-13,STONE:0)
Block(-2,3,-12,iceandfire:frozen_stone:0)
Block(-2,3,-11,iceandfire:frozen_stone:0)
Block(-2,3,-10,ICE:0)
Block(-2,3,-9,ICE:0)
Block(-2,3,-8,ICE:0)
Block(-2,3,-7,ICE:0)
Block(-2,3,-6,ICE:0)
Block(-2,3,-5,quark:stone_stairs:3)
Block(-2,3,-4,betternether:bone_slab_half:1)
Block(-2,3,-3,BROWN_MUSHROOM:0)
Block(-2,3,-2,rustic:mooncap_mushroom:0)
Block(-2,3,-1,betternether:bone_slab_half:1)
Block(-2,3,0,AIR:0)
Block(-2,3,1,AIR:0)
Block(-2,3,2,AIR:0)
Block(-2,3,3,AIR:0)
Block(-2,3,4,AIR:0)
Block(-2,3,5,AIR:0)
Block(-2,3,6,AIR:0)
Block(-2,3,7,quark:stone_speleothem:2)
Block(-2,3,8,iceandfire:frozen_stone:0)
Block(-2,3,9,rustic:mooncap_mushroom:0)
Block(-2,3,10,AIR:0)
Block(-2,3,11,AIR:0)
Block(-2,3,12,AIR:0)
Block(-2,3,13,rustic:deathstalk_mushroom:0)
Block(-2,3,14,STONE:0)
Block(-2,3,15,STONE:0)
Block(-2,3,16,STONE:0)
Block(-2,4,-14,STONE:0)
Block(-2,4,-13,STONE:0)
Block(-2,4,-12,iceandfire:frozen_stone:0)
Block(-2,4,-11,iceandfire:frozen_stone:0)
Block(-2,4,-10,iceandfire:frozen_stone:0)
Block(-2,4,-9,ICE:0)
Block(-2,4,-8,AIR:0)
Block(-2,4,-7,AIR:0)
Block(-2,4,-6,AIR:0)
Block(-2,4,-5,AIR:0)
Block(-2,4,-4,AIR:0)
Block(-2,4,-3,AIR:0)
Block(-2,4,-2,AIR:0)
Block(-2,4,-1,AIR:0)
Block(-2,4,0,AIR:0)
Block(-2,4,1,AIR:0)
Block(-2,4,2,AIR:0)
Block(-2,4,3,AIR:0)
Block(-2,4,4,AIR:0)
Block(-2,4,5,AIR:0)
Block(-2,4,6,AIR:0)
Block(-2,4,7,quark:stone_speleothem:1)
Block(-2,4,8,quark:stone_speleothem:2)
Block(-2,4,9,AIR:0)
Block(-2,4,10,AIR:0)
Block(-2,4,11,AIR:0)
Block(-2,4,12,AIR:0)
Block(-2,4,13,AIR:0)
Block(-2,4,14,iceandfire:frozen_stone:0)
Block(-2,4,15,STONE:0)
Block(-2,4,16,STONE:0)
Block(-2,5,-14,STONE:0)
Block(-2,5,-13,STONE:0)
Block(-2,5,-12,iceandfire:frozen_stone:0)
Block(-2,5,-11,iceandfire:frozen_stone:0)
Block(-2,5,-10,quark:stone_speleothem:2)
Block(-2,5,-9,AIR:0)
Block(-2,5,-8,AIR:0)
Block(-2,5,-7,AIR:0)
Block(-2,5,-6,AIR:0)
Block(-2,5,-5,AIR:0)
Block(-2,5,-4,AIR:0)
Block(-2,5,-3,AIR:0)
Block(-2,5,-2,AIR:0)
Block(-2,5,-1,AIR:0)
Block(-2,5,0,AIR:0)
Block(-2,5,1,AIR:0)
Block(-2,5,2,AIR:0)
Block(-2,5,3,AIR:0)
Block(-2,5,4,AIR:0)
Block(-2,5,5,AIR:0)
Block(-2,5,6,AIR:0)
Block(-2,5,7,AIR:0)
Block(-2,5,8,quark:stone_speleothem:1)
Block(-2,5,9,AIR:0)
Block(-2,5,10,AIR:0)
Block(-2,5,11,AIR:0)
Block(-2,5,12,AIR:0)
Block(-2,5,13,AIR:0)
Block(-2,5,14,iceandfire:frozen_stone:0)
Block(-2,5,15,iceandfire:frozen_stone:0)
Block(-2,5,16,STONE:0)
Block(-2,6,-14,STONE:0)
Block(-2,6,-13,STONE:0)
Block(-2,6,-12,STONE:0)
Block(-2,6,-11,iceandfire:frozen_stone:0)
Block(-2,6,-10,quark:stone_speleothem:1)
Block(-2,6,-9,AIR:0)
Block(-2,6,-8,AIR:0)
Block(-2,6,-7,AIR:0)
Block(-2,6,-6,AIR:0)
Block(-2,6,-5,AIR:0)
Block(-2,6,-4,AIR:0)
Block(-2,6,-3,AIR:0)
Block(-2,6,-2,AIR:0)
Block(-2,6,-1,AIR:0)
Block(-2,6,0,AIR:0)
Block(-2,6,1,AIR:0)
Block(-2,6,2,AIR:0)
Block(-2,6,3,AIR:0)
Block(-2,6,4,AIR:0)
Block(-2,6,5,AIR:0)
Block(-2,6,6,AIR:0)
Block(-2,6,7,AIR:0)
Block(-2,6,8,quark:stone_speleothem:0)
Block(-2,6,9,AIR:0)
Block(-2,6,10,AIR:0)
Block(-2,6,11,AIR:0)
Block(-2,6,12,AIR:0)
Block(-2,6,13,AIR:0)
Block(-2,6,14,iceandfire:frozen_stone:0)
Block(-2,6,15,iceandfire:frozen_stone:0)
Block(-2,6,16,STONE:0)
Block(-2,7,-15,STONE:0)
Block(-2,7,-14,STONE:0)
Block(-2,7,-13,STONE:0)
Block(-2,7,-12,STONE:0)
Block(-2,7,-11,STONE:0)
Block(-2,7,-10,quark:stone_speleothem:2)
Block(-2,7,-9,AIR:0)
Block(-2,7,-8,AIR:0)
Block(-2,7,-7,AIR:0)
Block(-2,7,-6,AIR:0)
Block(-2,7,-5,AIR:0)
Block(-2,7,-4,AIR:0)
Block(-2,7,-3,AIR:0)
Block(-2,7,-2,AIR:0)
Block(-2,7,-1,AIR:0)
Block(-2,7,0,AIR:0)
Block(-2,7,1,AIR:0)
Block(-2,7,2,AIR:0)
Block(-2,7,3,AIR:0)
Block(-2,7,4,AIR:0)
Block(-2,7,5,AIR:0)
Block(-2,7,6,AIR:0)
Block(-2,7,7,AIR:0)
Block(-2,7,8,AIR:0)
Block(-2,7,9,quark:slate_speleothem:0)
Block(-2,7,10,AIR:0)
Block(-2,7,11,AIR:0)
Block(-2,7,12,AIR:0)
Block(-2,7,13,iceandfire:frozen_stone:0)
Block(-2,7,14,iceandfire:frozen_stone:0)
Block(-2,7,15,iceandfire:frozen_stone:0)
Block(-2,8,-14,STONE:0)
Block(-2,8,-13,STONE:0)
Block(-2,8,-12,STONE:0)
Block(-2,8,-11,STONE:0)
Block(-2,8,-10,STONE:0)
Block(-2,8,-9,AIR:0)
Block(-2,8,-8,AIR:0)
Block(-2,8,-7,AIR:0)
Block(-2,8,-6,AIR:0)
Block(-2,8,-5,AIR:0)
Block(-2,8,-4,AIR:0)
Block(-2,8,-3,AIR:0)
Block(-2,8,-2,AIR:0)
Block(-2,8,-1,AIR:0)
Block(-2,8,0,quark:slate_speleothem:0)
Block(-2,8,1,AIR:0)
Block(-2,8,2,AIR:0)
Block(-2,8,3,AIR:0)
Block(-2,8,4,AIR:0)
Block(-2,8,5,AIR:0)
Block(-2,8,6,AIR:0)
Block(-2,8,7,quark:stone_speleothem:0)
Block(-2,8,8,AIR:0)
Block(-2,8,9,quark:slate_speleothem:1)
Block(-2,8,10,AIR:0)
Block(-2,8,11,iceandfire:frozen_stone:0)
Block(-2,8,12,iceandfire:frozen_stone:0)
Block(-2,8,13,iceandfire:frozen_stone:0)
Block(-2,8,14,iceandfire:frozen_stone:0)
Block(-2,8,15,STONE:0)
Block(-2,9,-14,STONE:0)
Block(-2,9,-13,STONE:0)
Block(-2,9,-12,STONE:0)
Block(-2,9,-11,STONE:0)
Block(-2,9,-10,STONE:0)
Block(-2,9,-9,AIR:0)
Block(-2,9,-8,AIR:0)
Block(-2,9,-7,AIR:0)
Block(-2,9,-6,AIR:0)
Block(-2,9,-5,AIR:0)
Block(-2,9,-4,quark:slate:0)
Block(-2,9,-3,AIR:0)
Block(-2,9,-2,AIR:0)
Block(-2,9,-1,AIR:0)
Block(-2,9,0,quark:slate_speleothem:1)
Block(-2,9,1,AIR:0)
Block(-2,9,2,AIR:0)
Block(-2,9,3,AIR:0)
Block(-2,9,4,AIR:0)
Block(-2,9,5,AIR:0)
Block(-2,9,6,AIR:0)
Block(-2,9,7,quark:stone_speleothem:1)
Block(-2,9,8,AIR:0)
Block(-2,9,9,quark:slate_speleothem:2)
Block(-2,9,10,iceandfire:frozen_stone:0)
Block(-2,9,11,STONE:0)
Block(-2,9,12,STONE:0)
Block(-2,9,13,STONE:0)
Block(-2,9,14,STONE:0)
Block(-2,10,-14,STONE:0)
Block(-2,10,-13,STONE:0)
Block(-2,10,-12,STONE:0)
Block(-2,10,-11,STONE:0)
Block(-2,10,-10,STONE:0)
Block(-2,10,-9,STONE:0)
Block(-2,10,-8,STONE:0)
Block(-2,10,-7,STONE:0)
Block(-2,10,-6,STONE:0)
Block(-2,10,-5,quark:slate:0)
Block(-2,10,-4,quark:slate:0)
Block(-2,10,-3,quark:slate:0)
Block(-2,10,-2,STONE:0)
Block(-2,10,-1,quark:stone_stairs:4)
Block(-2,10,0,quark:slate_speleothem:2)
Block(-2,10,1,AIR:0)
Block(-2,10,2,AIR:0)
Block(-2,10,3,AIR:0)
Block(-2,10,4,AIR:0)
Block(-2,10,5,AIR:0)
Block(-2,10,6,AIR:0)
Block(-2,10,7,quark:stone_speleothem:2)
Block(-2,10,8,AIR:0)
Block(-2,10,9,iceandfire:frozen_stone:0)
Block(-2,10,10,iceandfire:frozen_stone:0)
Block(-2,10,11,STONE:0)
Block(-2,10,12,STONE:0)
Block(-2,11,-11,STONE:0)
Block(-2,11,-10,STONE:0)
Block(-2,11,-9,STONE:0)
Block(-2,11,-8,STONE:0)
Block(-2,11,-7,STONE:0)
Block(-2,11,-6,STONE:0)
Block(-2,11,-5,STONE:0)
Block(-2,11,-4,STONE:0)
Block(-2,11,-3,STONE:0)
Block(-2,11,-2,STONE:0)
Block(-2,11,-1,STONE:0)
Block(-2,11,0,iceandfire:frozen_stone:0)
Block(-2,11,1,ICE:0)
Block(-2,11,2,ICE:0)
Block(-2,11,3,AIR:0)
Block(-2,11,4,AIR:0)
Block(-2,11,5,AIR:0)
Block(-2,11,6,iceandfire:frozen_stone:0)
Block(-2,11,7,iceandfire:frozen_stone:0)
Block(-2,11,8,iceandfire:frozen_stone:0)
Block(-2,11,9,iceandfire:frozen_stone:0)
Block(-2,11,10,iceandfire:frozen_stone:0)
Block(-2,11,11,STONE:0)
Block(-2,12,-10,STONE:0)
Block(-2,12,-9,STONE:0)
Block(-2,12,-8,STONE:0)
Block(-2,12,-7,STONE:0)
Block(-2,12,-6,STONE:0)
Block(-2,12,-3,STONE:0)
Block(-2,12,-2,STONE:0)
Block(-2,12,-1,STONE:0)
Block(-2,12,0,iceandfire:frozen_stone:0)
Block(-2,12,1,ICE:0)
Block(-2,12,2,ICE:0)
Block(-2,12,3,ICE:0)
Block(-2,12,4,ICE:0)
Block(-2,12,5,ICE:0)
Block(-2,12,6,iceandfire:frozen_stone:0)
Block(-2,12,7,iceandfire:frozen_stone:0)
Block(-2,12,8,iceandfire:frozen_stone:0)
Block(-1,0,-4,STONE:0)
Block(-1,0,-3,STONE:0)
Block(-1,0,-2,STONE:0)
Block(-1,0,-1,STONE:0)
Block(-1,0,0,STONE:0)
Block(-1,0,1,STONE:0)
Block(-1,0,2,STONE:0)
Block(-1,0,3,STONE:0)
Block(-1,0,4,STONE:0)
Block(-1,0,5,STONE:0)
Block(-1,0,6,STONE:0)
Block(-1,0,7,STONE:0)
Block(-1,0,9,STONE:0)
Block(-1,0,10,STONE:0)
Block(-1,0,11,STONE:0)
Block(-1,1,-9,STONE:0)
Block(-1,1,-8,STONE:0)
Block(-1,1,-7,iceandfire:frozen_stone:0)
Block(-1,1,-6,iceandfire:frozen_stone:0)
Block(-1,1,-5,iceandfire:frozen_stone:0)
Block(-1,1,-4,STONE:0)
Block(-1,1,-3,STONE:0)
Block(-1,1,-2,STONE:0)
Block(-1,1,-1,STONE:0)
Block(-1,1,0,ICE:0)
Block(-1,1,1,STONE:0)
Block(-1,1,2,STONE:0)
Block(-1,1,3,STONE:0)
Block(-1,1,4,STATIONARY_WATER:8)
Block(-1,1,5,STATIONARY_WATER:8)
Block(-1,1,6,STONE:0)
Block(-1,1,7,STONE:0)
Block(-1,1,8,STONE:0)
Block(-1,1,9,STONE:0)
Block(-1,1,10,STONE:0)
Block(-1,1,11,STONE:0)
Block(-1,1,12,STONE:0)
Block(-1,1,13,STONE:0)
Block(-1,1,14,STONE:0)
Block(-1,2,-12,STONE:0)
Block(-1,2,-11,iceandfire:frozen_stone:0)
Block(-1,2,-10,ICE:0)
Block(-1,2,-9,ICE:0)
Block(-1,2,-8,ICE:0)
Block(-1,2,-7,ICE:0)
Block(-1,2,-6,ICE:0)
Block(-1,2,-5,ICE:0)
Block(-1,2,-4,iceandfire:frozen_stone:0)
Block(-1,2,-3,iceandfire:frozen_stone:0)
Block(-1,2,-2,STONE:0)
Block(-1,2,-1,BONE_BLOCK:4)
Block(-1,2,0,BONE_BLOCK:8)
Block(-1,2,1,BONE_BLOCK:4)
Block(-1,2,2,STATIONARY_WATER:0)
Block(-1,2,3,STATIONARY_WATER:0)
Block(-1,2,4,STATIONARY_WATER:0)
Block(-1,2,5,STATIONARY_WATER:0)
Block(-1,2,6,STATIONARY_WATER:0)
Block(-1,2,7,STATIONARY_WATER:0)
Block(-1,2,8,STONE:0)
Block(-1,2,9,STATIONARY_WATER:0)
Block(-1,2,10,STATIONARY_WATER:0)
Block(-1,2,11,biomesoplenty:grass:1)
Block(-1,2,12,STONE:0)
Block(-1,2,13,ICE:0)
Block(-1,2,14,STONE:0)
Block(-1,2,15,STONE:0)
Block(-1,3,-14,STONE:0)
Block(-1,3,-13,STONE:0)
Block(-1,3,-12,iceandfire:frozen_stone:0)
Block(-1,3,-11,iceandfire:frozen_stone:0)
Block(-1,3,-10,ICE:0)
Block(-1,3,-9,ICE:0)
Block(-1,3,-8,ICE:0)
Block(-1,3,-7,ICE:0)
Block(-1,3,-6,ICE:0)
Block(-1,3,-5,ICE:0)
Block(-1,3,-4,BONE_BLOCK:0)
Block(-1,3,-3,iceandfire:frozen_stone:0)
Block(-1,3,-2,STONE:0)
Block(-1,3,-1,betternether:bone_slab_half:1)
Block(-1,3,0,contenttweaker:bone_pile:0)
RandomBlock(-1,3,1,SKULL:1,null,6,AIR:0,9,SKULL:1,null,12,AIR:0,15,SKULL:1,null,18,AIR:0,21,SKULL:1,null,24,AIR:0,27,SKULL:1,null,30,AIR:0,33,SKULL:1,null,36,AIR:0,39,SKULL:1,null,42,AIR:0,45,SKULL:1,null,48,AIR:0,51,SKULL:1,null,54,AIR:0,57,SKULL:1,null,60,AIR:0,63,SKULL:1,null,66,AIR:0,69,SKULL:1,null,72,AIR:0,75,SKULL:1,null,78,AIR:0,81,SKULL:1,null,84,AIR:0,87,SKULL:1,null,90,AIR:0,93,SKULL:1,null,96,AIR:0,100)
Block(-1,3,2,AIR:0)
Block(-1,3,3,AIR:0)
Block(-1,3,4,AIR:0)
Block(-1,3,5,AIR:0)
Block(-1,3,6,AIR:0)
Block(-1,3,7,AIR:0)
Block(-1,3,8,quark:stone_speleothem:2)
Block(-1,3,9,AIR:0)
Block(-1,3,10,AIR:0)
Block(-1,3,11,SNOW:0)
Block(-1,3,12,AIR:0)
Block(-1,3,13,ICE:0)
Block(-1,3,14,ICE:0)
Block(-1,3,15,STONE:0)
Block(-1,3,16,STONE:0)
Block(-1,4,-14,STONE:0)
Block(-1,4,-13,STONE:0)
Block(-1,4,-12,iceandfire:frozen_stone:0)
Block(-1,4,-11,iceandfire:frozen_stone:0)
Block(-1,4,-10,quark:stone_stairs:3)
Block(-1,4,-9,AIR:0)
Block(-1,4,-8,AIR:0)
Block(-1,4,-7,AIR:0)
Block(-1,4,-6,AIR:0)
Block(-1,4,-5,AIR:0)
Block(-1,4,-4,betternether:bone_button:5)
Block(-1,4,-3,AIR:0)
Block(-1,4,-2,rustic:mooncap_mushroom:0)
Block(-1,4,-1,AIR:0)
Block(-1,4,0,AIR:0)
Block(-1,4,1,AIR:0)
Block(-1,4,2,AIR:0)
Block(-1,4,3,AIR:0)
Block(-1,4,4,AIR:0)
Block(-1,4,5,AIR:0)
Block(-1,4,6,AIR:0)
Block(-1,4,7,AIR:0)
Block(-1,4,8,AIR:0)
Block(-1,4,9,AIR:0)
Block(-1,4,10,AIR:0)
Block(-1,4,11,AIR:0)
Block(-1,4,12,AIR:0)
Block(-1,4,13,iceandfire:dragon_ice_spikes:0)
Block(-1,4,14,iceandfire:frozen_stone:0)
Block(-1,4,15,STONE:0)
Block(-1,4,16,STONE:0)
Block(-1,5,-14,STONE:0)
Block(-1,5,-13,quark:stone_stairs:3)
Block(-1,5,-12,AIR:0)
Block(-1,5,-11,AIR:0)
Block(-1,5,-10,AIR:0)
Block(-1,5,-9,AIR:0)
Block(-1,5,-8,AIR:0)
Block(-1,5,-7,AIR:0)
Block(-1,5,-6,AIR:0)
Block(-1,5,-5,AIR:0)
Block(-1,5,-4,AIR:0)
Block(-1,5,-3,AIR:0)
Block(-1,5,-2,AIR:0)
Block(-1,5,-1,AIR:0)
Block(-1,5,0,AIR:0)
Block(-1,5,1,AIR:0)
Block(-1,5,2,AIR:0)
Block(-1,5,3,AIR:0)
Block(-1,5,4,AIR:0)
Block(-1,5,5,AIR:0)
Block(-1,5,6,AIR:0)
Block(-1,5,7,AIR:0)
Block(-1,5,8,AIR:0)
Block(-1,5,9,AIR:0)
Block(-1,5,10,AIR:0)
Block(-1,5,11,AIR:0)
Block(-1,5,12,AIR:0)
Block(-1,5,13,quark:stone_speleothem:2)
Block(-1,5,14,iceandfire:frozen_stone:0)
Block(-1,5,15,iceandfire:frozen_stone:0)
Block(-1,5,16,STONE:0)
Block(-1,6,-15,STONE:0)
Block(-1,6,-14,AIR:0)
Block(-1,6,-13,AIR:0)
Block(-1,6,-12,AIR:0)
Block(-1,6,-11,AIR:0)
Block(-1,6,-10,AIR:0)
Block(-1,6,-9,AIR:0)
Block(-1,6,-8,AIR:0)
Block(-1,6,-7,AIR:0)
Block(-1,6,-6,AIR:0)
Block(-1,6,-5,quark:stone_speleothem:0)
Block(-1,6,-4,AIR:0)
Block(-1,6,-3,AIR:0)
Block(-1,6,-2,AIR:0)
Block(-1,6,-1,AIR:0)
Block(-1,6,0,AIR:0)
Block(-1,6,1,AIR:0)
Block(-1,6,2,AIR:0)
Block(-1,6,3,AIR:0)
Block(-1,6,4,AIR:0)
Block(-1,6,5,AIR:0)
Block(-1,6,6,AIR:0)
Block(-1,6,7,AIR:0)
Block(-1,6,8,AIR:0)
Block(-1,6,9,AIR:0)
Block(-1,6,10,AIR:0)
Block(-1,6,11,AIR:0)
Block(-1,6,12,AIR:0)
Block(-1,6,13,iceandfire:frozen_stone:0)
Block(-1,6,14,iceandfire:frozen_stone:0)
Block(-1,6,15,iceandfire:frozen_stone:0)
Block(-1,7,-15,STONE:0)
Block(-1,7,-14,STONE:0)
Block(-1,7,-13,STONE:0)
Block(-1,7,-12,AIR:0)
Block(-1,7,-11,AIR:0)
Block(-1,7,-10,AIR:0)
Block(-1,7,-9,AIR:0)
Block(-1,7,-8,AIR:0)
Block(-1,7,-7,AIR:0)
Block(-1,7,-6,AIR:0)
Block(-1,7,-5,quark:stone_speleothem:1)
Block(-1,7,-4,AIR:0)
Block(-1,7,-3,AIR:0)
Block(-1,7,-2,AIR:0)
Block(-1,7,-1,AIR:0)
Block(-1,7,0,AIR:0)
Block(-1,7,1,AIR:0)
Block(-1,7,2,AIR:0)
Block(-1,7,3,AIR:0)
Block(-1,7,4,AIR:0)
Block(-1,7,5,AIR:0)
Block(-1,7,6,AIR:0)
Block(-1,7,7,AIR:0)
Block(-1,7,8,AIR:0)
Block(-1,7,9,AIR:0)
Block(-1,7,10,AIR:0)
Block(-1,7,11,AIR:0)
Block(-1,7,12,AIR:0)
Block(-1,7,13,iceandfire:frozen_stone:0)
Block(-1,7,14,iceandfire:frozen_stone:0)
Block(-1,8,-15,STONE:0)
Block(-1,8,-14,STONE:0)
Block(-1,8,-13,STONE:0)
Block(-1,8,-12,STONE:0)
Block(-1,8,-11,STONE:0)
Block(-1,8,-10,AIR:0)
Block(-1,8,-9,AIR:0)
Block(-1,8,-8,AIR:0)
Block(-1,8,-7,AIR:0)
Block(-1,8,-6,AIR:0)
Block(-1,8,-5,quark:stone_speleothem:2)
Block(-1,8,-4,AIR:0)
Block(-1,8,-3,AIR:0)
Block(-1,8,-2,AIR:0)
Block(-1,8,-1,AIR:0)
Block(-1,8,0,AIR:0)
Block(-1,8,1,AIR:0)
Block(-1,8,2,AIR:0)
Block(-1,8,3,AIR:0)
Block(-1,8,4,AIR:0)
Block(-1,8,5,AIR:0)
Block(-1,8,6,AIR:0)
Block(-1,8,7,AIR:0)
Block(-1,8,8,AIR:0)
Block(-1,8,9,AIR:0)
Block(-1,8,10,AIR:0)
Block(-1,8,11,AIR:0)
Block(-1,8,12,iceandfire:frozen_stone:0)
Block(-1,8,13,iceandfire:frozen_stone:0)
Block(-1,8,14,iceandfire:frozen_stone:0)
Block(-1,9,-14,STONE:0)
Block(-1,9,-13,STONE:0)
Block(-1,9,-12,STONE:0)
Block(-1,9,-11,STONE:0)
Block(-1,9,-10,STONE:0)
Block(-1,9,-9,AIR:0)
Block(-1,9,-8,AIR:0)
Block(-1,9,-7,AIR:0)
Block(-1,9,-6,quark:slate:0)
Block(-1,9,-5,quark:slate:0)
Block(-1,9,-4,quark:slate:0)
Block(-1,9,-3,quark:slate:0)
Block(-1,9,-2,AIR:0)
Block(-1,9,-1,AIR:0)
Block(-1,9,0,AIR:0)
Block(-1,9,1,AIR:0)
Block(-1,9,2,AIR:0)
Block(-1,9,3,AIR:0)
Block(-1,9,4,AIR:0)
Block(-1,9,5,AIR:0)
Block(-1,9,6,AIR:0)
Block(-1,9,7,AIR:0)
Block(-1,9,8,AIR:0)
Block(-1,9,9,AIR:0)
Block(-1,9,10,iceandfire:frozen_stone:0)
Block(-1,9,11,iceandfire:frozen_stone:0)
Block(-1,9,12,iceandfire:frozen_stone:0)
Block(-1,10,-14,STONE:0)
Block(-1,10,-13,STONE:0)
Block(-1,10,-12,STONE:0)
Block(-1,10,-11,STONE:0)
Block(-1,10,-10,STONE:0)
Block(-1,10,-9,STONE:0)
Block(-1,10,-8,STONE:0)
Block(-1,10,-7,STONE:0)
Block(-1,10,-6,quark:slate:0)
Block(-1,10,-5,quark:slate:0)
Block(-1,10,-4,quark:slate:0)
Block(-1,10,-3,quark:slate:0)
Block(-1,10,-2,quark:slate:0)
Block(-1,10,-1,quark:stone_stairs:7)
Block(-1,10,0,AIR:0)
Block(-1,10,1,AIR:0)
Block(-1,10,2,AIR:0)
Block(-1,10,3,AIR:0)
Block(-1,10,4,AIR:0)
Block(-1,10,5,AIR:0)
Block(-1,10,6,AIR:0)
Block(-1,10,7,AIR:0)
Block(-1,10,8,AIR:0)
Block(-1,10,9,iceandfire:frozen_stone:0)
Block(-1,10,10,iceandfire:frozen_stone:0)
Block(-1,10,11,iceandfire:frozen_stone:0)
Block(-1,10,12,STONE:0)
Block(-1,11,-11,STONE:0)
Block(-1,11,-10,STONE:0)
Block(-1,11,-9,STONE:0)
Block(-1,11,-8,STONE:0)
Block(-1,11,-7,STONE:0)
Block(-1,11,-6,STONE:0)
Block(-1,11,-5,quark:slate:0)
Block(-1,11,-4,quark:slate:0)
Block(-1,11,-3,quark:slate:0)
Block(-1,11,-2,STONE:0)
Block(-1,11,-1,STONE:0)
Block(-1,11,0,STONE:0)
Block(-1,11,1,ICE:0)
Block(-1,11,2,AIR:0)
Block(-1,11,3,AIR:0)
Block(-1,11,4,AIR:0)
Block(-1,11,5,AIR:0)
Block(-1,11,6,AIR:0)
Block(-1,11,7,iceandfire:frozen_stone:0)
Block(-1,11,8,iceandfire:frozen_stone:0)
Block(-1,11,9,iceandfire:frozen_stone:0)
Block(-1,11,10,iceandfire:frozen_stone:0)
Block(-1,11,11,iceandfire:frozen_stone:0)
Block(-1,12,-10,STONE:0)
Block(-1,12,-9,STONE:0)
Block(-1,12,-8,STONE:0)
Block(-1,12,-7,STONE:0)
Block(-1,12,-6,STONE:0)
Block(-1,12,-2,STONE:0)
Block(-1,12,-1,STONE:0)
Block(-1,12,0,STONE:0)
Block(-1,12,1,ICE:0)
Block(-1,12,2,ICE:0)
Block(-1,12,3,ICE:0)
Block(-1,12,4,ICE:0)
Block(-1,12,5,ICE:0)
Block(-1,12,6,ICE:0)
Block(-1,12,7,iceandfire:frozen_stone:0)
Block(-1,12,8,iceandfire:frozen_stone:0)
Block(-1,12,9,iceandfire:frozen_stone:0)
Block(-1,12,10,iceandfire:frozen_stone:0)
Block(0,0,1,STONE:0)
Block(0,0,2,STONE:0)
Block(0,0,3,STONE:0)
Block(0,0,4,STONE:0)
Block(0,0,5,STONE:0)
Block(0,0,6,STONE:0)
Block(0,0,7,STONE:0)
Block(0,1,-9,STONE:0)
Block(0,1,-8,STONE:0)
Block(0,1,-7,STONE:0)
Block(0,1,-6,STONE:0)
Block(0,1,-5,STONE:0)
Block(0,1,-4,STONE:0)
Block(0,1,-3,STONE:0)
Block(0,1,-2,STONE:0)
Block(0,1,-1,STONE:0)
Block(0,1,0,STONE:0)
Block(0,1,1,STONE:0)
Block(0,1,2,STONE:0)
Block(0,1,3,STONE:0)
Block(0,1,4,STATIONARY_WATER:8)
Block(0,1,5,STATIONARY_WATER:8)
Block(0,1,6,STATIONARY_WATER:8)
Block(0,1,7,STATIONARY_WATER:8)
Block(0,1,8,ICE:0)
Block(0,1,9,STONE:0)
Block(0,1,10,STONE:0)
Block(0,1,11,STONE:0)
Block(0,1,12,STONE:0)
Block(0,1,13,STONE:0)
Block(0,1,14,STONE:0)
Block(0,2,-12,STONE:0)
Block(0,2,-11,iceandfire:frozen_stone:0)
Block(0,2,-10,iceandfire:frozen_stone:0)
Block(0,2,-9,ICE:0)
Block(0,2,-8,STONE:0)
Block(0,2,-7,iceandfire:frozen_stone:0)
Block(0,2,-6,ICE:0)
Block(0,2,-5,iceandfire:frozen_stone:0)
Block(0,2,-4,STONE:0)
Block(0,2,-3,STONE:0)
Block(0,2,-2,STONE:0)
Block(0,2,-1,STONE:0)
Block(0,2,0,STONE:0)
Block(0,2,1,BONE_BLOCK:0)
Block(0,2,2,STONE:0)
Block(0,2,3,STATIONARY_WATER:0)
Block(0,2,4,STATIONARY_WATER:0)
Block(0,2,5,STATIONARY_WATER:0)
Block(0,2,6,STATIONARY_WATER:0)
Block(0,2,7,STATIONARY_WATER:0)
Block(0,2,8,STATIONARY_WATER:0)
Block(0,2,9,STATIONARY_WATER:0)
Block(0,2,10,biomesoplenty:grass:1)
Block(0,2,11,biomesoplenty:grass:1)
Block(0,2,12,ICE:0)
Block(0,2,13,ICE:0)
Block(0,2,14,ICE:0)
Block(0,2,15,STONE:0)
Block(0,3,-14,STONE:0)
Block(0,3,-13,STONE:0)
Block(0,3,-12,iceandfire:frozen_stone:0)
Block(0,3,-11,iceandfire:frozen_stone:0)
Block(0,3,-10,ICE:0)
Block(0,3,-9,ICE:0)
Block(0,3,-8,ICE:0)
Block(0,3,-7,ICE:0)
Block(0,3,-6,ICE:0)
Block(0,3,-5,ICE:0)
Block(0,3,-4,STONE:0)
Block(0,3,-3,STONE:0)
Block(0,3,-2,STONE:0)
Block(0,3,-1,quark:slate:0)
Block(0,3,0,quark:slate:0)
Block(0,3,1,betternether:bone_slab_half:1)
Block(0,3,2,contenttweaker:bone_pile:0)
Block(0,3,3,AIR:0)
Block(0,3,4,AIR:0)
Block(0,3,5,AIR:0)
Block(0,3,6,AIR:0)
Block(0,3,7,AIR:0)
Block(0,3,8,AIR:0)
Block(0,3,9,AIR:0)
Block(0,3,10,SNOW:0)
Block(0,3,11,AIR:0)
Block(0,3,12,iceandfire:dragon_ice_spikes:0)
Block(0,3,13,ICE:0)
Block(0,3,14,ICE:0)
Block(0,3,15,STONE:0)
Block(0,4,-14,STONE:0)
Block(0,4,-13,STONE:0)
Block(0,4,-12,iceandfire:frozen_stone:0)
Block(0,4,-11,ICE:0)
Block(0,4,-10,ICE:0)
Block(0,4,-9,ICE:0)
Block(0,4,-8,quark:stone_stairs:3)
Block(0,4,-7,quark:stone_stairs:0)
Block(0,4,-6,ICE:0)
Block(0,4,-5,iceandfire:frozen_stone:0)
Block(0,4,-4,quark:slate:0)
Block(0,4,-3,BONE_BLOCK:0)
Block(0,4,-2,BONE_BLOCK:4)
Block(0,4,-1,betternether:bone_slab_half:1)
Block(0,4,0,AIR:0)
Block(0,4,1,AIR:0)
Block(0,4,2,AIR:0)
Block(0,4,3,AIR:0)
Block(0,4,4,AIR:0)
Block(0,4,5,AIR:0)
Block(0,4,6,AIR:0)
Block(0,4,7,AIR:0)
Block(0,4,8,AIR:0)
Block(0,4,9,AIR:0)
Block(0,4,10,AIR:0)
Block(0,4,11,AIR:0)
Block(0,4,12,AIR:0)
Block(0,4,13,AIR:0)
Block(0,4,14,ICE:0)
Block(0,4,15,STONE:0)
Block(0,5,-15,STONE:0)
Block(0,5,-14,quark:stone_speleothem:2)
Block(0,5,-13,AIR:0)
Block(0,5,-12,AIR:0)
Block(0,5,-11,AIR:0)
Block(0,5,-10,AIR:0)
Block(0,5,-9,AIR:0)
Block(0,5,-8,AIR:0)
Block(0,5,-7,AIR:0)
Block(0,5,-6,AIR:0)
Block(0,5,-5,AIR:0)
Block(0,5,-4,rustic:mooncap_mushroom:0)
Block(0,5,-3,AIR:0)
Block(0,5,-2,betternether:bone_button:5)
Block(0,5,-1,AIR:0)
Block(0,5,0,AIR:0)
Block(0,5,1,AIR:0)
Block(0,5,2,AIR:0)
Block(0,5,3,AIR:0)
Block(0,5,4,AIR:0)
Block(0,5,5,AIR:0)
Block(0,5,6,AIR:0)
Block(0,5,7,AIR:0)
Block(0,5,8,AIR:0)
Block(0,5,9,AIR:0)
Block(0,5,10,AIR:0)
Block(0,5,11,AIR:0)
Block(0,5,12,quark:stone_speleothem:0)
Block(0,5,13,iceandfire:frozen_stone:0)
Block(0,5,14,iceandfire:frozen_stone:0)
Block(0,5,15,iceandfire:frozen_stone:0)
Block(0,6,-14,quark:stone_speleothem:1)
Block(0,6,-13,AIR:0)
Block(0,6,-12,AIR:0)
Block(0,6,-11,AIR:0)
Block(0,6,-10,AIR:0)
Block(0,6,-9,AIR:0)
Block(0,6,-8,AIR:0)
Block(0,6,-7,AIR:0)
Block(0,6,-6,AIR:0)
Block(0,6,-5,AIR:0)
Block(0,6,-4,AIR:0)
Block(0,6,-3,AIR:0)
Block(0,6,-2,AIR:0)
Block(0,6,-1,AIR:0)
Block(0,6,0,AIR:0)
Block(0,6,1,AIR:0)
Block(0,6,2,AIR:0)
Block(0,6,3,AIR:0)
Block(0,6,4,AIR:0)
Block(0,6,5,AIR:0)
Block(0,6,6,AIR:0)
Block(0,6,7,AIR:0)
Block(0,6,8,AIR:0)
Block(0,6,9,AIR:0)
Block(0,6,10,AIR:0)
Block(0,6,11,AIR:0)
Block(0,6,12,quark:stone_speleothem:1)
Block(0,6,13,iceandfire:frozen_stone:0)
Block(0,6,14,iceandfire:frozen_stone:0)
Block(0,6,15,iceandfire:frozen_stone:0)
Block(0,7,-14,quark:stone_speleothem:2)
Block(0,7,-13,AIR:0)
Block(0,7,-12,AIR:0)
Block(0,7,-11,AIR:0)
Block(0,7,-10,AIR:0)
Block(0,7,-9,AIR:0)
Block(0,7,-8,AIR:0)
Block(0,7,-7,AIR:0)
Block(0,7,-6,AIR:0)
Block(0,7,-5,AIR:0)
Block(0,7,-4,AIR:0)
Block(0,7,-3,AIR:0)
Block(0,7,-2,AIR:0)
Block(0,7,-1,AIR:0)
Block(0,7,0,AIR:0)
Block(0,7,1,AIR:0)
Block(0,7,2,AIR:0)
Block(0,7,3,AIR:0)
Block(0,7,4,AIR:0)
Block(0,7,5,AIR:0)
Block(0,7,6,AIR:0)
Block(0,7,7,AIR:0)
Block(0,7,8,AIR:0)
Block(0,7,9,AIR:0)
Block(0,7,10,AIR:0)
Block(0,7,11,AIR:0)
Block(0,7,12,quark:stone_speleothem:2)
Block(0,7,13,iceandfire:frozen_stone:0)
Block(0,7,14,iceandfire:frozen_stone:0)
Block(0,8,-15,STONE:0)
Block(0,8,-14,STONE:0)
Block(0,8,-13,STONE:0)
Block(0,8,-12,STONE:0)
Block(0,8,-11,AIR:0)
Block(0,8,-10,AIR:0)
Block(0,8,-9,AIR:0)
Block(0,8,-8,AIR:0)
Block(0,8,-7,AIR:0)
Block(0,8,-6,AIR:0)
Block(0,8,-5,AIR:0)
Block(0,8,-4,AIR:0)
Block(0,8,-3,AIR:0)
Block(0,8,-2,AIR:0)
Block(0,8,-1,AIR:0)
Block(0,8,0,quark:stone_speleothem:0)
Block(0,8,1,AIR:0)
Block(0,8,2,AIR:0)
Block(0,8,3,AIR:0)
Block(0,8,4,AIR:0)
Block(0,8,5,AIR:0)
Block(0,8,6,AIR:0)
Block(0,8,7,AIR:0)
Block(0,8,8,AIR:0)
Block(0,8,9,AIR:0)
Block(0,8,10,AIR:0)
Block(0,8,11,iceandfire:frozen_stone:0)
Block(0,8,12,iceandfire:frozen_stone:0)
Block(0,8,13,iceandfire:frozen_stone:0)
Block(0,8,14,iceandfire:frozen_stone:0)
Block(0,9,-15,STONE:0)
Block(0,9,-14,STONE:0)
Block(0,9,-13,STONE:0)
Block(0,9,-12,STONE:0)
Block(0,9,-11,STONE:0)
Block(0,9,-10,AIR:0)
Block(0,9,-9,AIR:0)
Block(0,9,-8,AIR:0)
Block(0,9,-7,STONE:0)
Block(0,9,-6,quark:slate:0)
Block(0,9,-5,quark:slate:0)
Block(0,9,-4,quark:slate:0)
Block(0,9,-3,quark:slate:0)
Block(0,9,-2,AIR:0)
Block(0,9,-1,AIR:0)
Block(0,9,0,quark:stone_speleothem:1)
Block(0,9,1,AIR:0)
Block(0,9,2,AIR:0)
Block(0,9,3,AIR:0)
Block(0,9,4,AIR:0)
Block(0,9,5,AIR:0)
Block(0,9,6,AIR:0)
Block(0,9,7,AIR:0)
Block(0,9,8,AIR:0)
Block(0,9,9,AIR:0)
Block(0,9,10,iceandfire:frozen_stone:0)
Block(0,9,11,iceandfire:frozen_stone:0)
Block(0,9,12,iceandfire:frozen_stone:0)
Block(0,10,-14,STONE:0)
Block(0,10,-13,STONE:0)
Block(0,10,-12,STONE:0)
Block(0,10,-11,STONE:0)
Block(0,10,-10,STONE:0)
Block(0,10,-9,STONE:0)
Block(0,10,-8,STONE:0)
Block(0,10,-7,STONE:0)
Block(0,10,-6,quark:slate:0)
Block(0,10,-5,quark:slate:0)
Block(0,10,-4,quark:slate:0)
Block(0,10,-3,quark:slate:0)
Block(0,10,-2,quark:slate:0)
Block(0,10,-1,quark:slate:0)
Block(0,10,0,quark:stone_speleothem:2)
Block(0,10,1,AIR:0)
Block(0,10,2,AIR:0)
Block(0,10,3,AIR:0)
Block(0,10,4,AIR:0)
Block(0,10,5,AIR:0)
Block(0,10,6,AIR:0)
Block(0,10,7,AIR:0)
Block(0,10,8,AIR:0)
Block(0,10,9,iceandfire:frozen_stone:0)
Block(0,10,10,iceandfire:frozen_stone:0)
Block(0,10,11,iceandfire:frozen_stone:0)
Block(0,10,12,STONE:0)
Block(0,11,-14,STONE:0)
Block(0,11,-13,STONE:0)
Block(0,11,-12,STONE:0)
Block(0,11,-11,STONE:0)
Block(0,11,-10,STONE:0)
Block(0,11,-9,STONE:0)
Block(0,11,-8,STONE:0)
Block(0,11,-7,STONE:0)
Block(0,11,-6,STONE:0)
Block(0,11,-2,STONE:0)
Block(0,11,-1,STONE:0)
Block(0,11,0,STONE:0)
Block(0,11,1,AIR:0)
Block(0,11,2,AIR:0)
Block(0,11,3,AIR:0)
Block(0,11,4,AIR:0)
Block(0,11,5,AIR:0)
Block(0,11,6,AIR:0)
Block(0,11,7,AIR:0)
Block(0,11,8,AIR:0)
Block(0,11,9,iceandfire:frozen_stone:0)
Block(0,11,10,iceandfire:frozen_stone:0)
Block(0,11,11,iceandfire:frozen_stone:0)
Block(0,11,12,STONE:0)
Block(0,12,-10,STONE:0)
Block(0,12,-9,STONE:0)
Block(0,12,-8,STONE:0)
Block(0,12,-2,STONE:0)
Block(0,12,-1,STONE:0)
Block(0,12,0,STONE:0)
Block(0,12,1,ICE:0)
Block(0,12,2,ICE:0)
Block(0,12,3,ICE:0)
Block(0,12,4,ICE:0)
Block(0,12,5,ICE:0)
Block(0,12,6,ICE:0)
Block(0,12,7,ICE:0)
Block(0,12,8,ICE:0)
Block(0,12,9,iceandfire:frozen_stone:0)
Block(0,12,10,iceandfire:frozen_stone:0)
Block(0,12,11,STONE:0)
Block(1,0,1,STONE:0)
Block(1,0,2,STONE:0)
Block(1,0,3,STONE:0)
Block(1,0,4,STONE:0)
Block(1,0,5,STONE:0)
Block(1,0,6,STONE:0)
Block(1,0,7,STONE:0)
Block(1,1,0,STONE:0)
Block(1,1,1,STONE:0)
Block(1,1,2,STONE:0)
Block(1,1,3,STATIONARY_WATER:8)
Block(1,1,4,STATIONARY_WATER:8)
Block(1,1,5,STATIONARY_WATER:8)
Block(1,1,6,STATIONARY_WATER:8)
Block(1,1,7,STATIONARY_WATER:8)
Block(1,1,8,ICE:0)
Block(1,1,9,ICE:0)
Block(1,1,10,STONE:0)
Block(1,1,11,STONE:0)
Block(1,1,12,STONE:0)
Block(1,1,13,STONE:0)
Block(1,1,14,STONE:0)
Block(1,2,-14,STONE:0)
Block(1,2,-13,STONE:0)
Block(1,2,-12,STONE:0)
Block(1,2,-11,STONE:0)
Block(1,2,-10,STONE:0)
Block(1,2,-9,STONE:0)
Block(1,2,-8,STONE:0)
Block(1,2,-7,STONE:0)
Block(1,2,-6,STONE:0)
Block(1,2,-5,STONE:0)
Block(1,2,-4,STONE:0)
Block(1,2,-2,STONE:0)
Block(1,2,-1,STONE:0)
Block(1,2,0,STONE:0)
Block(1,2,1,STONE:0)
Block(1,2,2,STONE:0)
Block(1,2,3,STATIONARY_WATER:0)
Block(1,2,4,STATIONARY_WATER:0)
Block(1,2,5,STATIONARY_WATER:0)
Block(1,2,6,STATIONARY_WATER:0)
Block(1,2,7,STATIONARY_WATER:0)
Block(1,2,8,STATIONARY_WATER:0)
Block(1,2,9,STATIONARY_WATER:0)
Block(1,2,10,STONE:0)
Block(1,2,11,STONE:0)
Block(1,2,12,STONE:0)
Block(1,2,13,ICE:0)
Block(1,2,14,STONE:0)
Block(1,2,15,STONE:0)
Block(1,3,-14,STONE:0)
Block(1,3,-13,STONE:0)
Block(1,3,-12,STONE:0)
Block(1,3,-11,ICE:0)
Block(1,3,-10,ICE:0)
Block(1,3,-9,ICE:0)
Block(1,3,-8,ICE:0)
Block(1,3,-7,ICE:0)
Block(1,3,-6,STONE:0)
Block(1,3,-5,STONE:0)
Block(1,3,-4,STONE:0)
Block(1,3,-3,STONE:0)
Block(1,3,-2,STONE:0)
Block(1,3,-1,quark:slate:0)
Block(1,3,0,quark:slate:0)
Block(1,3,1,quark:stone_stairs:0)
Block(1,3,2,quark:stone_speleothem:2)
Block(1,3,3,AIR:0)
Block(1,3,4,AIR:0)
Block(1,3,5,AIR:0)
Block(1,3,6,AIR:0)
Block(1,3,7,AIR:0)
Block(1,3,8,AIR:0)
Block(1,3,9,AIR:0)
Block(1,3,10,BROWN_MUSHROOM:0)
Block(1,3,11,rustic:iron_lattice:0)
Block(1,3,12,AIR:0)
Block(1,3,13,quark:stone_stairs:2)
Block(1,3,14,ICE:0)
Block(1,3,15,STONE:0)
Block(1,3,16,STONE:0)
Block(1,4,-15,STONE:0)
Block(1,4,-14,STONE:0)
Block(1,4,-13,STONE:0)
Block(1,4,-12,STONE:0)
Block(1,4,-11,ICE:0)
Block(1,4,-10,ICE:0)
Block(1,4,-9,ICE:0)
Block(1,4,-8,ICE:0)
Block(1,4,-7,ICE:0)
Block(1,4,-6,ICE:0)
Block(1,4,-5,quark:slate:0)
Block(1,4,-4,quark:slate:0)
Block(1,4,-3,quark:slate:0)
Block(1,4,-2,quark:slate:0)
Block(1,4,-1,BONE_BLOCK:0)
Block(1,4,0,quark:slate:0)
Block(1,4,1,AIR:0)
Block(1,4,2,quark:stone_speleothem:1)
Block(1,4,3,AIR:0)
Block(1,4,4,AIR:0)
Block(1,4,5,AIR:0)
Block(1,4,6,AIR:0)
Block(1,4,7,AIR:0)
Block(1,4,8,AIR:0)
Block(1,4,9,AIR:0)
Block(1,4,10,AIR:0)
Block(1,4,11,rustic:iron_lattice:0)
Block(1,4,12,AIR:0)
Block(1,4,13,quark:stone_speleothem:0)
Block(1,4,14,ICE:0)
Block(1,4,15,STONE:0)
Block(1,4,16,STONE:0)
Block(1,5,-14,AIR:0)
Block(1,5,-13,AIR:0)
Block(1,5,-12,AIR:0)
Block(1,5,-11,AIR:0)
Block(1,5,-10,AIR:0)
Block(1,5,-9,AIR:0)
Block(1,5,-8,AIR:0)
Block(1,5,-7,AIR:0)
Block(1,5,-6,quark:stone_stairs:2)
Block(1,5,-5,quark:slate:0)
Block(1,5,-4,quark:slate:0)
Block(1,5,-3,quark:slate:0)
Block(1,5,-2,quark:stone_speleothem:2)
Block(1,5,-1,rustic:mooncap_mushroom:0)
Block(1,5,0,BROWN_MUSHROOM:0)
Block(1,5,1,AIR:0)
Block(1,5,2,quark:stone_speleothem:0)
Block(1,5,3,AIR:0)
Block(1,5,4,AIR:0)
Block(1,5,5,AIR:0)
Block(1,5,6,AIR:0)
Block(1,5,7,AIR:0)
Block(1,5,8,AIR:0)
Block(1,5,9,AIR:0)
Block(1,5,10,AIR:0)
Block(1,5,11,AIR:0)
Block(1,5,12,AIR:0)
Block(1,5,13,quark:stone_speleothem:1)
Block(1,5,14,ICE:0)
Block(1,5,15,ICE:0)
Block(1,5,16,STONE:0)
Block(1,6,-14,AIR:0)
Block(1,6,-13,AIR:0)
Block(1,6,-12,AIR:0)
Block(1,6,-11,AIR:0)
Block(1,6,-10,AIR:0)
Block(1,6,-9,AIR:0)
Block(1,6,-8,AIR:0)
Block(1,6,-7,AIR:0)
Block(1,6,-6,AIR:0)
Block(1,6,-5,AIR:0)
Block(1,6,-4,quark:stone_speleothem:2)
Block(1,6,-3,AIR:0)
Block(1,6,-2,quark:stone_speleothem:1)
Block(1,6,-1,AIR:0)
Block(1,6,0,AIR:0)
Block(1,6,1,AIR:0)
Block(1,6,2,AIR:0)
Block(1,6,3,AIR:0)
Block(1,6,4,AIR:0)
Block(1,6,5,AIR:0)
Block(1,6,6,AIR:0)
Block(1,6,7,AIR:0)
Block(1,6,8,AIR:0)
Block(1,6,9,AIR:0)
Block(1,6,10,AIR:0)
Block(1,6,11,AIR:0)
Block(1,6,12,AIR:0)
Block(1,6,13,quark:stone_speleothem:2)
Block(1,6,14,ICE:0)
Block(1,6,15,STONE:0)
Block(1,6,16,STONE:0)
Block(1,7,-14,AIR:0)
Block(1,7,-13,AIR:0)
Block(1,7,-12,AIR:0)
Block(1,7,-11,AIR:0)
Block(1,7,-10,quark:stone_speleothem:0)
Block(1,7,-9,AIR:0)
Block(1,7,-8,AIR:0)
Block(1,7,-7,AIR:0)
Block(1,7,-6,AIR:0)
Block(1,7,-5,AIR:0)
Block(1,7,-4,quark:stone_speleothem:1)
Block(1,7,-3,AIR:0)
Block(1,7,-2,quark:stone_speleothem:0)
Block(1,7,-1,AIR:0)
Block(1,7,0,AIR:0)
Block(1,7,1,AIR:0)
Block(1,7,2,AIR:0)
Block(1,7,3,AIR:0)
Block(1,7,4,AIR:0)
Block(1,7,5,AIR:0)
Block(1,7,6,AIR:0)
Block(1,7,7,AIR:0)
Block(1,7,8,AIR:0)
Block(1,7,9,AIR:0)
Block(1,7,10,AIR:0)
Block(1,7,11,AIR:0)
Block(1,7,12,AIR:0)
Block(1,7,13,iceandfire:frozen_stone:0)
Block(1,7,14,iceandfire:frozen_stone:0)
Block(1,7,15,STONE:0)
Block(1,8,-14,AIR:0)
Block(1,8,-13,AIR:0)
Block(1,8,-12,AIR:0)
Block(1,8,-11,AIR:0)
Block(1,8,-10,quark:stone_speleothem:1)
Block(1,8,-9,AIR:0)
Block(1,8,-8,STONE:0)
Block(1,8,-7,AIR:0)
Block(1,8,-6,quark:slate:0)
Block(1,8,-5,quark:slate:0)
Block(1,8,-4,quark:stone_speleothem:2)
Block(1,8,-3,AIR:0)
Block(1,8,-2,AIR:0)
Block(1,8,-1,AIR:0)
Block(1,8,0,AIR:0)
Block(1,8,1,quark:slate_speleothem:0)
Block(1,8,2,AIR:0)
Block(1,8,3,AIR:0)
Block(1,8,4,AIR:0)
Block(1,8,5,AIR:0)
Block(1,8,6,AIR:0)
Block(1,8,7,AIR:0)
Block(1,8,8,AIR:0)
Block(1,8,9,AIR:0)
Block(1,8,10,AIR:0)
Block(1,8,11,iceandfire:frozen_stone:0)
Block(1,8,12,iceandfire:frozen_stone:0)
Block(1,8,13,iceandfire:frozen_stone:0)
Block(1,8,14,iceandfire:frozen_stone:0)
Block(1,8,15,STONE:0)
Block(1,9,-15,STONE:0)
Block(1,9,-14,STONE:0)
Block(1,9,-13,STONE:0)
Block(1,9,-12,STONE:0)
Block(1,9,-11,quark:stone_stairs:7)
Block(1,9,-10,quark:stone_speleothem:2)
Block(1,9,-9,STONE:0)
Block(1,9,-8,STONE:0)
Block(1,9,-7,STONE:0)
Block(1,9,-6,quark:slate:0)
Block(1,9,-5,quark:slate:0)
Block(1,9,-4,quark:slate:0)
Block(1,9,-3,quark:slate:0)
Block(1,9,-2,quark:slate:0)
Block(1,9,-1,AIR:0)
Block(1,9,0,AIR:0)
Block(1,9,1,quark:slate_speleothem:1)
Block(1,9,2,AIR:0)
Block(1,9,3,AIR:0)
Block(1,9,4,AIR:0)
Block(1,9,5,AIR:0)
Block(1,9,6,AIR:0)
Block(1,9,7,AIR:0)
Block(1,9,8,AIR:0)
Block(1,9,9,AIR:0)
Block(1,9,10,AIR:0)
Block(1,9,11,iceandfire:frozen_stone:0)
Block(1,9,12,iceandfire:frozen_stone:0)
Block(1,9,13,iceandfire:frozen_stone:0)
Block(1,9,14,STONE:0)
Block(1,10,-14,STONE:0)
Block(1,10,-13,STONE:0)
Block(1,10,-12,STONE:0)
Block(1,10,-11,STONE:0)
Block(1,10,-10,STONE:0)
Block(1,10,-9,STONE:0)
Block(1,10,-8,STONE:0)
Block(1,10,-7,STONE:0)
Block(1,10,-6,quark:slate:0)
Block(1,10,-5,quark:slate:0)
Block(1,10,-2,quark:slate:0)
Block(1,10,-1,quark:slate:0)
Block(1,10,0,AIR:0)
Block(1,10,1,quark:slate_speleothem:2)
Block(1,10,2,AIR:0)
Block(1,10,3,AIR:0)
Block(1,10,4,AIR:0)
Block(1,10,5,AIR:0)
Block(1,10,6,AIR:0)
Block(1,10,7,AIR:0)
Block(1,10,8,AIR:0)
Block(1,10,9,AIR:0)
Block(1,10,10,iceandfire:frozen_stone:0)
Block(1,10,11,iceandfire:frozen_stone:0)
Block(1,10,12,STONE:0)
Block(1,11,-14,STONE:0)
Block(1,11,-13,STONE:0)
Block(1,11,-12,STONE:0)
Block(1,11,-11,STONE:0)
Block(1,11,-10,STONE:0)
Block(1,11,-9,STONE:0)
Block(1,11,-8,STONE:0)
Block(1,11,-7,STONE:0)
Block(1,11,-6,STONE:0)
Block(1,11,-2,quark:slate:0)
Block(1,11,-1,quark:slate:0)
Block(1,11,0,quark:slate:0)
Block(1,11,1,quark:slate:0)
Block(1,11,2,ICE:0)
Block(1,11,3,AIR:0)
Block(1,11,4,AIR:0)
Block(1,11,5,AIR:0)
Block(1,11,6,AIR:0)
Block(1,11,7,AIR:0)
Block(1,11,8,AIR:0)
Block(1,11,9,iceandfire:frozen_stone:0)
Block(1,11,10,iceandfire:frozen_stone:0)
Block(1,11,11,iceandfire:frozen_stone:0)
Block(1,11,12,STONE:0)
Block(1,12,-10,STONE:0)
Block(1,12,-9,STONE:0)
Block(1,12,-8,STONE:0)
Block(1,12,-2,STONE:0)
Block(1,12,-1,STONE:0)
Block(1,12,0,STONE:0)
Block(1,12,1,STONE:0)
Block(1,12,2,ICE:0)
Block(1,12,3,ICE:0)
Block(1,12,4,ICE:0)
Block(1,12,5,ICE:0)
Block(1,12,6,ICE:0)
Block(1,12,7,ICE:0)
Block(1,12,8,ICE:0)
Block(1,12,9,iceandfire:frozen_stone:0)
Block(1,12,10,iceandfire:frozen_stone:0)
Block(1,12,11,STONE:0)
Block(2,0,1,STONE:0)
Block(2,0,2,STONE:0)
Block(2,0,3,STONE:0)
Block(2,0,4,STONE:0)
Block(2,0,5,STONE:0)
Block(2,0,6,STONE:0)
Block(2,0,7,STONE:0)
Block(2,1,0,STONE:0)
Block(2,1,1,STONE:0)
Block(2,1,2,STONE:0)
Block(2,1,3,STATIONARY_WATER:8)
Block(2,1,4,STONE:0)
Block(2,1,5,STATIONARY_WATER:8)
Block(2,1,6,STATIONARY_WATER:8)
Block(2,1,7,STATIONARY_WATER:8)
Block(2,1,8,ICE:0)
Block(2,1,9,STONE:0)
Block(2,1,10,STONE:0)
Block(2,1,11,STONE:0)
Block(2,2,-14,STONE:0)
Block(2,2,-13,STONE:0)
Block(2,2,-11,STONE:0)
Block(2,2,-10,STONE:0)
Block(2,2,-9,STONE:0)
Block(2,2,0,STONE:0)
Block(2,2,1,STONE:0)
Block(2,2,2,STATIONARY_WATER:0)
Block(2,2,3,STATIONARY_WATER:0)
Block(2,2,4,STATIONARY_WATER:0)
Block(2,2,5,STATIONARY_WATER:0)
Block(2,2,6,STATIONARY_WATER:0)
Block(2,2,7,STATIONARY_WATER:0)
Block(2,2,8,STATIONARY_WATER:0)
Block(2,2,9,biomesoplenty:grass:1)
Block(2,2,10,STONE:0)
Block(2,2,11,STONE:0)
Block(2,2,12,STONE:0)
Block(2,2,13,STONE:0)
Block(2,2,14,STONE:0)
Block(2,2,15,STONE:0)
Block(2,3,-14,STONE:0)
Block(2,3,-13,STONE:0)
Block(2,3,-12,STONE:0)
Block(2,3,-11,STONE:0)
Block(2,3,-10,ICE:0)
Block(2,3,-9,ICE:0)
Block(2,3,-8,STONE:0)
Block(2,3,-7,STONE:0)
Block(2,3,-6,STONE:0)
Block(2,3,-1,quark:slate:0)
Block(2,3,0,quark:slate:0)
Block(2,3,1,quark:slate:0)
Block(2,3,2,AIR:0)
Block(2,3,3,AIR:0)
Block(2,3,4,AIR:0)
Block(2,3,5,AIR:0)
Block(2,3,6,AIR:0)
Block(2,3,7,AIR:0)
Block(2,3,8,AIR:0)
Block(2,3,9,SNOW:0)
Block(2,3,10,betternether:bone_button:5)
Block(2,3,11,simpledifficulty:campfire:0)
Block(2,3,12,AIR:0)
Block(2,3,13,rustic:deathstalk_mushroom:0)
Block(2,3,14,STONE:0)
Block(2,3,15,STONE:0)
Block(2,3,16,STONE:0)
Block(2,4,-15,STONE:0)
Block(2,4,-14,STONE:0)
Block(2,4,-13,STONE:0)
Block(2,4,-12,STONE:0)
Block(2,4,-11,ICE:0)
Block(2,4,-10,ICE:0)
Block(2,4,-9,ICE:0)
Block(2,4,-8,ICE:0)
Block(2,4,-7,STONE:0)
Block(2,4,-6,STONE:0)
Block(2,4,-5,quark:slate:0)
Block(2,4,-2,quark:slate:0)
Block(2,4,-1,iceandfire:frozen_stone:0)
Block(2,4,0,iceandfire:frozen_stone:0)
Block(2,4,1,iceandfire:dragon_ice_spikes:0)
Block(2,4,2,AIR:0)
Block(2,4,3,AIR:0)
Block(2,4,4,AIR:0)
Block(2,4,5,AIR:0)
Block(2,4,6,AIR:0)
Block(2,4,7,AIR:0)
Block(2,4,8,AIR:0)
Block(2,4,9,AIR:0)
Block(2,4,10,AIR:0)
Block(2,4,11,biomesoplenty:flesh:0)
Block(2,4,12,AIR:0)
Block(2,4,13,AIR:0)
Block(2,4,14,ICE:0)
Block(2,4,15,ICE:0)
Block(2,4,16,STONE:0)
Block(2,5,-14,AIR:0)
Block(2,5,-13,AIR:0)
Block(2,5,-12,AIR:0)
Block(2,5,-11,AIR:0)
Block(2,5,-10,AIR:0)
Block(2,5,-9,iceandfire:dragon_ice_spikes:0)
Block(2,5,-8,iceandfire:dragon_ice_spikes:0)
Block(2,5,-7,quark:stone_speleothem:2)
Block(2,5,-6,quark:slate:0)
Block(2,5,-5,quark:slate:0)
Block(2,5,-3,quark:slate:0)
Block(2,5,-2,iceandfire:frozen_stone:0)
Block(2,5,-1,iceandfire:frozen_stone:0)
Block(2,5,0,rustic:mooncap_mushroom:0)
Block(2,5,1,AIR:0)
Block(2,5,2,AIR:0)
Block(2,5,3,AIR:0)
Block(2,5,4,AIR:0)
Block(2,5,5,AIR:0)
Block(2,5,6,AIR:0)
Block(2,5,7,AIR:0)
Block(2,5,8,AIR:0)
Block(2,5,9,AIR:0)
Block(2,5,10,AIR:0)
Block(2,5,11,AIR:0)
Block(2,5,12,AIR:0)
Block(2,5,13,AIR:0)
Block(2,5,14,ICE:0)
Block(2,5,15,ICE:0)
Block(2,5,16,STONE:0)
Block(2,6,-14,AIR:0)
Block(2,6,-13,AIR:0)
Block(2,6,-12,AIR:0)
Block(2,6,-11,AIR:0)
Block(2,6,-10,AIR:0)
Block(2,6,-9,AIR:0)
Block(2,6,-8,AIR:0)
Block(2,6,-7,quark:stone_speleothem:1)
Block(2,6,-6,quark:slate:0)
Block(2,6,-5,quark:slate:0)
Block(2,6,-4,quark:slate:0)
Block(2,6,-3,quark:slate:0)
Block(2,6,-2,AIR:0)
Block(2,6,-1,quark:stone_speleothem:2)
Block(2,6,0,AIR:0)
Block(2,6,1,AIR:0)
Block(2,6,2,AIR:0)
Block(2,6,3,AIR:0)
Block(2,6,4,AIR:0)
Block(2,6,5,AIR:0)
Block(2,6,6,AIR:0)
Block(2,6,7,AIR:0)
Block(2,6,8,AIR:0)
Block(2,6,9,AIR:0)
Block(2,6,10,AIR:0)
Block(2,6,11,AIR:0)
Block(2,6,12,AIR:0)
Block(2,6,13,AIR:0)
Block(2,6,14,ICE:0)
Block(2,6,15,ICE:0)
Block(2,6,16,STONE:0)
Block(2,7,-14,AIR:0)
Block(2,7,-13,AIR:0)
Block(2,7,-12,AIR:0)
Block(2,7,-11,AIR:0)
Block(2,7,-10,AIR:0)
Block(2,7,-9,AIR:0)
Block(2,7,-8,AIR:0)
Block(2,7,-7,quark:stone_speleothem:2)
Block(2,7,-6,quark:slate:0)
Block(2,7,-5,quark:slate:0)
Block(2,7,-4,quark:slate:0)
Block(2,7,-3,AIR:0)
Block(2,7,-2,AIR:0)
Block(2,7,-1,quark:stone_speleothem:1)
Block(2,7,0,AIR:0)
Block(2,7,1,AIR:0)
Block(2,7,2,AIR:0)
Block(2,7,3,AIR:0)
Block(2,7,4,AIR:0)
Block(2,7,5,AIR:0)
Block(2,7,6,AIR:0)
Block(2,7,7,AIR:0)
Block(2,7,8,AIR:0)
Block(2,7,9,AIR:0)
Block(2,7,10,AIR:0)
Block(2,7,11,AIR:0)
Block(2,7,12,iceandfire:frozen_stone:0)
Block(2,7,13,iceandfire:frozen_stone:0)
Block(2,7,14,iceandfire:frozen_stone:0)
Block(2,7,15,STONE:0)
Block(2,8,-14,AIR:0)
Block(2,8,-13,AIR:0)
Block(2,8,-12,AIR:0)
Block(2,8,-11,AIR:0)
Block(2,8,-10,AIR:0)
Block(2,8,-9,STONE:0)
Block(2,8,-8,STONE:0)
Block(2,8,-7,STONE:0)
Block(2,8,-6,STONE:0)
Block(2,8,-5,quark:slate:0)
Block(2,8,-4,quark:slate:0)
Block(2,8,-3,AIR:0)
Block(2,8,-2,AIR:0)
Block(2,8,-1,quark:stone_speleothem:2)
Block(2,8,0,AIR:0)
Block(2,8,1,AIR:0)
Block(2,8,2,AIR:0)
Block(2,8,3,AIR:0)
Block(2,8,4,AIR:0)
Block(2,8,5,AIR:0)
Block(2,8,6,AIR:0)
Block(2,8,7,AIR:0)
Block(2,8,8,AIR:0)
Block(2,8,9,AIR:0)
Block(2,8,10,AIR:0)
Block(2,8,11,iceandfire:frozen_stone:0)
Block(2,8,12,iceandfire:frozen_stone:0)
Block(2,8,13,iceandfire:frozen_stone:0)
Block(2,8,14,iceandfire:frozen_stone:0)
Block(2,8,15,STONE:0)
Block(2,9,-15,STONE:0)
Block(2,9,-14,STONE:0)
Block(2,9,-13,STONE:0)
Block(2,9,-12,STONE:0)
Block(2,9,-11,STONE:0)
Block(2,9,-10,STONE:0)
Block(2,9,-9,STONE:0)
Block(2,9,-8,STONE:0)
Block(2,9,-7,STONE:0)
Block(2,9,-6,STONE:0)
Block(2,9,-5,quark:slate:0)
Block(2,9,-4,quark:slate:0)
Block(2,9,-3,quark:slate:0)
Block(2,9,-2,quark:slate:0)
Block(2,9,-1,quark:slate:0)
Block(2,9,0,AIR:0)
Block(2,9,1,AIR:0)
Block(2,9,2,AIR:0)
Block(2,9,3,AIR:0)
Block(2,9,4,AIR:0)
Block(2,9,5,AIR:0)
Block(2,9,6,AIR:0)
Block(2,9,7,AIR:0)
Block(2,9,8,AIR:0)
Block(2,9,9,AIR:0)
Block(2,9,10,iceandfire:frozen_stone:0)
Block(2,9,11,iceandfire:frozen_stone:0)
Block(2,9,12,iceandfire:frozen_stone:0)
Block(2,9,13,iceandfire:frozen_stone:0)
Block(2,9,14,iceandfire:frozen_stone:0)
Block(2,10,-14,STONE:0)
Block(2,10,-13,STONE:0)
Block(2,10,-12,STONE:0)
Block(2,10,-11,STONE:0)
Block(2,10,-10,STONE:0)
Block(2,10,-9,STONE:0)
Block(2,10,-8,STONE:0)
Block(2,10,-7,STONE:0)
Block(2,10,-6,STONE:0)
Block(2,10,-5,quark:slate:0)
Block(2,10,-3,quark:slate:0)
Block(2,10,-2,quark:slate:0)
Block(2,10,-1,quark:slate:0)
Block(2,10,0,quark:slate:0)
Block(2,10,1,AIR:0)
Block(2,10,2,AIR:0)
Block(2,10,3,AIR:0)
Block(2,10,4,AIR:0)
Block(2,10,5,AIR:0)
Block(2,10,6,AIR:0)
Block(2,10,7,AIR:0)
Block(2,10,8,AIR:0)
Block(2,10,9,AIR:0)
Block(2,10,10,iceandfire:frozen_stone:0)
Block(2,10,11,iceandfire:frozen_stone:0)
Block(2,10,12,iceandfire:frozen_stone:0)
Block(2,10,13,iceandfire:frozen_stone:0)
Block(2,11,-14,STONE:0)
Block(2,11,-13,STONE:0)
Block(2,11,-12,STONE:0)
Block(2,11,-11,STONE:0)
Block(2,11,-10,STONE:0)
Block(2,11,-9,STONE:0)
Block(2,11,-8,STONE:0)
Block(2,11,-2,quark:slate:0)
Block(2,11,-1,quark:slate:0)
Block(2,11,0,quark:slate:0)
Block(2,11,1,quark:slate:0)
Block(2,11,2,ICE:0)
Block(2,11,3,ICE:0)
Block(2,11,4,ICE:0)
Block(2,11,5,AIR:0)
Block(2,11,6,AIR:0)
Block(2,11,7,AIR:0)
Block(2,11,8,AIR:0)
Block(2,11,9,ICE:0)
Block(2,11,10,ICE:0)
Block(2,11,11,STONE:0)
Block(2,11,12,STONE:0)
Block(2,11,13,STONE:0)
Block(2,12,-1,STONE:0)
Block(2,12,0,STONE:0)
Block(2,12,1,quark:slate:0)
Block(2,12,2,ICE:0)
Block(2,12,3,ICE:0)
Block(2,12,4,ICE:0)
Block(2,12,5,STONE:0)
Block(2,12,6,ICE:0)
Block(2,12,7,ICE:0)
Block(2,12,8,ICE:0)
Block(2,12,9,ICE:0)
Block(2,12,10,STONE:0)
Block(2,12,11,STONE:0)
Block(2,12,12,STONE:0)
Block(3,0,1,STONE:0)
Block(3,0,2,STONE:0)
Block(3,0,3,STONE:0)
Block(3,0,4,STONE:0)
Block(3,0,5,STONE:0)
Block(3,0,6,STONE:0)
Block(3,1,0,STONE:0)
Block(3,1,1,STONE:0)
Block(3,1,2,STONE:0)
Block(3,1,3,STONE:0)
Block(3,1,4,STONE:0)
Block(3,1,5,STONE:0)
Block(3,1,6,STATIONARY_WATER:8)
Block(3,1,7,STONE:0)
Block(3,1,8,STONE:0)
Block(3,1,9,STONE:0)
Block(3,1,10,STONE:0)
Block(3,1,11,STONE:0)
Block(3,2,-14,STONE:0)
Block(3,2,-13,STONE:0)
Block(3,2,0,STONE:0)
Block(3,2,1,STONE:0)
Block(3,2,2,STATIONARY_WATER:0)
Block(3,2,3,STATIONARY_WATER:0)
Block(3,2,4,biomesoplenty:grass:1)
Block(3,2,5,STATIONARY_WATER:0)
Block(3,2,6,STATIONARY_WATER:0)
Block(3,2,7,STATIONARY_WATER:0)
Block(3,2,8,STATIONARY_WATER:0)
Block(3,2,9,STONE:0)
Block(3,2,10,STONE:0)
Block(3,2,11,STONE:0)
Block(3,2,12,STONE:0)
Block(3,2,13,STONE:0)
Block(3,2,14,STONE:0)
Block(3,2,15,STONE:0)
Block(3,3,-14,STONE:0)
Block(3,3,-13,STONE:0)
Block(3,3,-12,STONE:0)
Block(3,3,-11,STONE:0)
Block(3,3,-10,STONE:0)
Block(3,3,-9,STONE:0)
Block(3,3,-8,STONE:0)
Block(3,3,-7,STONE:0)
Block(3,3,-6,STONE:0)
Block(3,3,0,STONE:0)
Block(3,3,1,STATIONARY_WATER:9)
Block(3,3,2,STATIONARY_WATER:1)
Block(3,3,3,AIR:0)
Block(3,3,4,SNOW:0)
Block(3,3,5,AIR:0)
Block(3,3,6,AIR:0)
Block(3,3,7,AIR:0)
Block(3,3,8,AIR:0)
Block(3,3,9,SNOW:0)
Block(3,3,10,SNOW:0)
Block(3,3,11,rustic:iron_lattice:0)
Block(3,3,12,AIR:0)
Block(3,3,13,STONE:0)
Block(3,3,14,STONE:0)
Block(3,3,15,STONE:0)
Block(3,3,16,STONE:0)
Block(3,4,-15,STONE:0)
Block(3,4,-14,STONE:0)
Block(3,4,-13,STONE:0)
Block(3,4,-12,STONE:0)
Block(3,4,-11,STONE:0)
Block(3,4,-10,STONE:0)
Block(3,4,-9,STONE:0)
Block(3,4,-8,STONE:0)
Block(3,4,-7,STONE:0)
Block(3,4,-6,STONE:0)
Block(3,4,-5,STONE:0)
Block(3,4,-2,STONE:0)
Block(3,4,-1,iceandfire:frozen_stone:0)
Block(3,4,0,iceandfire:frozen_stone:0)
Block(3,4,1,STATIONARY_WATER:1)
Block(3,4,2,AIR:0)
Block(3,4,3,AIR:0)
Block(3,4,4,AIR:0)
Block(3,4,5,AIR:0)
Block(3,4,6,AIR:0)
Block(3,4,7,AIR:0)
Block(3,4,8,AIR:0)
Block(3,4,9,AIR:0)
Block(3,4,10,AIR:0)
Block(3,4,11,rustic:iron_lattice:0)
Block(3,4,12,AIR:0)
Block(3,4,13,BROWN_MUSHROOM:0)
Block(3,4,14,ICE:0)
Block(3,4,15,STONE:0)
Block(3,4,16,STONE:0)
Block(3,5,-15,STONE:0)
Block(3,5,-14,STONE:0)
Block(3,5,-13,quark:stone_stairs:0)
Block(3,5,-12,AIR:0)
Block(3,5,-11,STONE:0)
Block(3,5,-10,STONE:0)
Block(3,5,-9,STONE:0)
Block(3,5,-8,STONE:0)
Block(3,5,-7,STONE:0)
Block(3,5,-6,STONE:0)
Block(3,5,-5,quark:slate:0)
Block(3,5,-3,quark:slate:0)
Block(3,5,-2,iceandfire:frozen_stone:0)
Block(3,5,-1,iceandfire:frozen_stone:0)
Block(3,5,0,quark:stone_speleothem:2)
Block(3,5,1,AIR:0)
Block(3,5,2,AIR:0)
Block(3,5,3,AIR:0)
Block(3,5,4,AIR:0)
Block(3,5,5,AIR:0)
Block(3,5,6,AIR:0)
Block(3,5,7,AIR:0)
Block(3,5,8,AIR:0)
Block(3,5,9,AIR:0)
Block(3,5,10,AIR:0)
Block(3,5,11,AIR:0)
Block(3,5,12,AIR:0)
Block(3,5,13,quark:stone_speleothem:0)
Block(3,5,14,ICE:0)
Block(3,5,15,ICE:0)
Block(3,5,16,STONE:0)
Block(3,6,-15,quark:stone_speleothem:2)
Block(3,6,-14,AIR:0)
Block(3,6,-13,AIR:0)
Block(3,6,-12,AIR:0)
Block(3,6,-11,quark:stone_speleothem:2)
Block(3,6,-10,iceandfire:dragon_ice_spikes:0)
Block(3,6,-9,STONE:0)
Block(3,6,-8,STONE:0)
Block(3,6,-7,STONE:0)
Block(3,6,-6,STONE:0)
Block(3,6,-5,quark:slate:0)
Block(3,6,-4,quark:slate:0)
Block(3,6,-3,quark:slate:0)
Block(3,6,-2,iceandfire:frozen_stone:0)
Block(3,6,-1,quark:stone_stairs:0)
Block(3,6,0,quark:stone_speleothem:1)
Block(3,6,1,AIR:0)
Block(3,6,2,AIR:0)
Block(3,6,3,AIR:0)
Block(3,6,4,AIR:0)
Block(3,6,5,AIR:0)
Block(3,6,6,AIR:0)
Block(3,6,7,AIR:0)
Block(3,6,8,AIR:0)
Block(3,6,9,AIR:0)
Block(3,6,10,AIR:0)
Block(3,6,11,AIR:0)
Block(3,6,12,AIR:0)
Block(3,6,13,quark:stone_speleothem:1)
Block(3,6,14,ICE:0)
Block(3,6,15,STONE:0)
Block(3,6,16,STONE:0)
Block(3,7,-15,STONE:0)
Block(3,7,-14,STONE:0)
Block(3,7,-13,STONE:0)
Block(3,7,-12,AIR:0)
Block(3,7,-11,quark:stone_speleothem:1)
Block(3,7,-10,AIR:0)
Block(3,7,-9,AIR:0)
Block(3,7,-8,STONE:0)
Block(3,7,-7,STONE:0)
Block(3,7,-6,STONE:0)
Block(3,7,-5,quark:slate:0)
Block(3,7,-4,quark:slate:0)
Block(3,7,-3,quark:slate:0)
Block(3,7,-2,iceandfire:frozen_stone:0)
Block(3,7,-1,AIR:0)
Block(3,7,0,quark:stone_speleothem:0)
Block(3,7,1,AIR:0)
Block(3,7,2,AIR:0)
Block(3,7,3,AIR:0)
Block(3,7,4,quark:slate_speleothem:0)
Block(3,7,5,AIR:0)
Block(3,7,6,AIR:0)
Block(3,7,7,AIR:0)
Block(3,7,8,AIR:0)
Block(3,7,9,AIR:0)
Block(3,7,10,AIR:0)
Block(3,7,11,AIR:0)
Block(3,7,12,AIR:0)
Block(3,7,13,quark:stone_speleothem:2)
Block(3,7,14,iceandfire:frozen_stone:0)
Block(3,7,15,STONE:0)
Block(3,8,-15,STONE:0)
Block(3,8,-14,STONE:0)
Block(3,8,-13,STONE:0)
Block(3,8,-12,STONE:0)
Block(3,8,-11,quark:stone_speleothem:2)
Block(3,8,-10,STONE:0)
Block(3,8,-9,STONE:0)
Block(3,8,-8,STONE:0)
Block(3,8,-7,STONE:0)
Block(3,8,-6,STONE:0)
Block(3,8,-5,STONE:0)
Block(3,8,-4,quark:slate:0)
Block(3,8,-3,quark:slate:0)
Block(3,8,-2,AIR:0)
Block(3,8,-1,AIR:0)
Block(3,8,0,AIR:0)
Block(3,8,1,AIR:0)
Block(3,8,2,AIR:0)
Block(3,8,3,AIR:0)
Block(3,8,4,quark:slate_speleothem:1)
Block(3,8,5,AIR:0)
Block(3,8,6,AIR:0)
Block(3,8,7,AIR:0)
Block(3,8,8,AIR:0)
Block(3,8,9,AIR:0)
Block(3,8,10,AIR:0)
Block(3,8,11,AIR:0)
Block(3,8,12,iceandfire:frozen_stone:0)
Block(3,8,13,iceandfire:frozen_stone:0)
Block(3,8,14,iceandfire:frozen_stone:0)
Block(3,8,15,STONE:0)
Block(3,9,-14,STONE:0)
Block(3,9,-13,STONE:0)
Block(3,9,-12,STONE:0)
Block(3,9,-11,STONE:0)
Block(3,9,-10,STONE:0)
Block(3,9,-9,STONE:0)
Block(3,9,-8,STONE:0)
Block(3,9,-7,STONE:0)
Block(3,9,-6,STONE:0)
Block(3,9,-5,STONE:0)
Block(3,9,-3,quark:slate:0)
Block(3,9,-2,quark:slate:0)
