
#######################################################################
# +-----------------------------------------------------------------+ #
# |                            BO3 object                           | #
# +-----------------------------------------------------------------+ #
#######################################################################

Author: NLBlackEagle

Description: No description given

Version: 3

SettingsMode: WriteWithoutComments


#######################################################################
# +-----------------------------------------------------------------+ #
# |                          Main settings                          | #
# +-----------------------------------------------------------------+ #
#######################################################################

Tree: true

Frequency: 180

Rarity: 100.0

RotateRandomly: true

SpawnHeight: randomY

SpawnHeightOffset: 0

SpawnHeightVariance: 0

##############################
# Height Limits for the BO3. #
##############################

MinHeight: 20

MaxHeight: 90

######################
# Extrusion settings #
######################

ExtrudeMode: None

ExtrudeThroughBlocks: AIR

MaxBranchDepth: 10

ExcludedBiomes: All


#######################################################################
# +-----------------------------------------------------------------+ #
# |                      Source block settings                      | #
# +-----------------------------------------------------------------+ #
#######################################################################

SourceBlocks: Solid

MaxPercentageOutsideSourceBlock: 5

OutsideSourceBlock: placeAnyway

DoReplaceBlocks: false

IsOTGPlus: false


#######################################################################
# +-----------------------------------------------------------------+ #
# |                              Blocks                             | #
# +-----------------------------------------------------------------+ #
#######################################################################

Block(-15,2,-2,STONE:0)
Block(-15,2,-1,STONE:0)
Block(-15,2,0,STONE:0)
Block(-15,2,1,STONE:0)
Block(-15,2,2,STONE:0)
Block(-15,2,3,STONE:0)
Block(-15,2,4,STONE:0)
Block(-15,3,-3,STONE:0)
Block(-15,3,-2,STONE:0)
Block(-15,3,-1,STONE:0)
Block(-15,3,0,STONE:0)
Block(-15,3,1,STONE:0)
Block(-15,3,2,STONE:0)
Block(-15,3,3,iceandfire:chared_cobblestone:0)
Block(-15,3,4,iceandfire:chared_stone:0)
Block(-15,3,5,iceandfire:chared_stone:0)
Block(-15,4,-4,STONE:0)
Block(-15,4,-3,STONE:0)
Block(-15,4,-2,quark:slate:0)
Block(-15,4,-1,quark:slate:0)
Block(-15,4,0,quark:slate:0)
Block(-15,4,1,STONE:0)
Block(-15,4,2,STONE:0)
Block(-15,4,3,iceandfire:chared_cobblestone:0)
Block(-15,4,4,iceandfire:chared_stone:0)
Block(-15,4,5,iceandfire:chared_cobblestone:0)
Block(-15,4,6,iceandfire:chared_stone:0)
Block(-15,5,-4,STONE:0)
Block(-15,5,-3,quark:slate:0)
Block(-15,5,-2,quark:slate:0)
Block(-15,5,-1,quark:slate:0)
Block(-15,5,0,quark:slate:0)
Block(-15,5,1,quark:slate:0)
Block(-15,5,2,STONE:0)
Block(-15,5,3,iceandfire:chared_stone:0)
Block(-15,5,4,iceandfire:chared_cobblestone:0)
Block(-15,5,5,MAGMA:0)
Block(-15,6,-4,STONE:0)
Block(-15,6,-3,quark:slate:0)
Block(-15,6,-2,quark:slate:0)
Block(-15,6,-1,quark:slate:0)
Block(-15,6,0,quark:slate:0)
Block(-15,6,1,quark:slate:0)
Block(-15,6,2,STONE:0)
Block(-15,6,3,iceandfire:chared_cobblestone:0)
Block(-15,6,4,iceandfire:chared_stone:0)
Block(-15,7,-3,quark:slate:0)
Block(-15,7,-2,quark:slate:0)
Block(-15,7,-1,quark:slate:0)
Block(-15,7,0,quark:slate:0)
Block(-15,7,1,quark:slate:0)
Block(-15,7,2,STONE:0)
Block(-15,7,3,iceandfire:chared_stone:0)
Block(-15,7,4,iceandfire:chared_stone:0)
Block(-15,7,5,STONE:0)
Block(-15,8,-3,STONE:0)
Block(-15,8,-2,quark:slate:0)
Block(-15,8,-1,quark:slate:0)
Block(-15,8,0,quark:slate:0)
Block(-15,8,1,STONE:0)
Block(-15,8,2,STONE:0)
Block(-15,8,3,STONE:0)
Block(-15,8,4,iceandfire:chared_stone:0)
Block(-15,8,5,STONE:0)
Block(-15,9,-3,STONE:0)
Block(-15,9,-2,STONE:0)
Block(-15,9,-1,STONE:0)
Block(-15,9,0,STONE:0)
Block(-15,9,1,STONE:0)
Block(-15,9,2,STONE:0)
Block(-15,9,3,STONE:0)
Block(-15,10,-3,STONE:0)
Block(-15,10,-2,STONE:0)
Block(-15,10,-1,STONE:0)
Block(-14,1,-2,STONE:0)
Block(-14,1,-1,STONE:0)
Block(-14,1,0,STONE:0)
Block(-14,1,1,STONE:0)
Block(-14,1,6,quark:basalt:0)
Block(-14,1,7,quark:basalt:0)
Block(-14,2,-3,STONE:0)
Block(-14,2,-2,STONE:0)
Block(-14,2,-1,STONE:0)
Block(-14,2,0,STONE:0)
Block(-14,2,1,STONE:0)
Block(-14,2,2,STONE:0)
Block(-14,2,3,iceandfire:chared_stone:0)
Block(-14,2,4,notreepunching:cobblestone/basalt:0)
Block(-14,2,5,quark:basalt:0)
Block(-14,2,6,quark:basalt:0)
Block(-14,2,7,quark:basalt:0)
Block(-14,2,8,quark:basalt:0)
Block(-14,3,-4,STONE:0)
Block(-14,3,-3,STONE:0)
Block(-14,3,-2,STONE:0)
Block(-14,3,-1,STONE:0)
Block(-14,3,0,STONE:0)
Block(-14,3,1,STONE:0)
Block(-14,3,2,iceandfire:chared_cobblestone:0)
Block(-14,3,3,iceandfire:chared_stone:0)
Block(-14,3,4,quark:stone_basalt_stairs:2)
Block(-14,3,5,quark:stone_basalt_stairs:1)
Block(-14,3,6,quark:basalt:0)
Block(-14,3,7,quark:basalt:0)
Block(-14,3,8,quark:basalt:0)
Block(-14,4,-5,STONE:0)
Block(-14,4,-4,STONE:0)
Block(-14,4,-3,STONE:0)
Block(-14,4,-2,quark:slate:0)
Block(-14,4,-1,biomesoplenty:grass:1)
Block(-14,4,0,AIR:0)
Block(-14,4,1,biomesoplenty:grass:1)
Block(-14,4,2,STONE:0)
Block(-14,4,3,contenttweaker:bone_pile:0)
Block(-14,4,4,AIR:0)
Block(-14,4,5,AIR:0)
Block(-14,4,6,AIR:0)
Block(-14,4,7,quark:basalt:0)
Block(-14,4,8,quark:basalt:0)
Block(-14,4,9,quark:basalt:0)
Block(-14,5,-5,STONE:0)
Block(-14,5,-4,STONE:0)
Block(-14,5,-3,quark:slate:0)
Block(-14,5,-2,biomesoplenty:grass:1)
Block(-14,5,-1,biomesoplenty:plant_0:11)
Block(-14,5,0,AIR:0)
Block(-14,5,1,BROWN_MUSHROOM:0)
RandomBlock(-14,5,2,SKULL:1,../../../Skulls/dungeon_skull_01.nbt,6,AIR,9,SKULL:1,../../../Skulls/dungeon_skull_02.nbt,12,AIR,15,SKULL:1,../../../Skulls/dungeon_skull_03.nbt,18,AIR,21,SKULL:1,../../../Skulls/dungeon_skull_04.nbt,24,AIR,27,SKULL:1,../../../Skulls/dungeon_skull_05.nbt,30,AIR,33,SKULL:1,../../../Skulls/dungeon_skull_06.nbt,36,AIR,39,SKULL:1,../../../Skulls/dungeon_skull_07.nbt,42,AIR,45,SKULL:1,../../../Skulls/dungeon_skull_08.nbt,48,AIR,51,SKULL:1,../../../Skulls/dungeon_skull_09.nbt,54,AIR,57,SKULL:1,../../../Skulls/dungeon_skull_10.nbt,60,AIR,63,SKULL:1,../../../Skulls/dungeon_skull_11.nbt,66,AIR,69,SKULL:1,../../../Skulls/dungeon_skull_12.nbt,72,AIR,75,SKULL:1,../../../Skulls/dungeon_skull_13.nbt,78,AIR,81,SKULL:1,../../../Skulls/dungeon_skull_14.nbt,84,AIR,87,SKULL:1,../../../Skulls/dungeon_skull_15.nbt,90,AIR,93,SKULL:1,../../../Skulls/dungeon_skull_16.nbt,96,AIR,100)
Block(-14,5,3,AIR:0)
Block(-14,5,4,AIR:0)
Block(-14,5,5,AIR:0)
Block(-14,5,6,quark:basalt:0)
Block(-14,5,7,notreepunching:cobblestone/basalt:0)
Block(-14,5,8,quark:basalt:0)
Block(-14,6,-5,STONE:0)
Block(-14,6,-4,STONE:0)
Block(-14,6,-3,quark:slate:0)
Block(-14,6,-2,AIR:0)
Block(-14,6,-1,quark:stone_speleothem:1)
Block(-14,6,0,AIR:0)
Block(-14,6,1,AIR:0)
Block(-14,6,2,iceandfire:chared_stone:0)
Block(-14,6,3,AIR:0)
Block(-14,6,4,AIR:0)
Block(-14,6,5,quark:basalt:0)
Block(-14,6,6,notreepunching:cobblestone/basalt:0)
Block(-14,7,-4,STONE:0)
Block(-14,7,-3,quark:slate:0)
Block(-14,7,-2,quark:slate:0)
Block(-14,7,-1,quark:stone_speleothem:2)
Block(-14,7,0,AIR:0)
Block(-14,7,1,quark:slate:0)
Block(-14,7,2,iceandfire:chared_stone:0)
Block(-14,7,3,AIR:0)
Block(-14,7,4,iceandfire:chared_stone:0)
Block(-14,8,-4,STONE:0)
Block(-14,8,-3,STONE:0)
Block(-14,8,-2,quark:slate:0)
Block(-14,8,-1,quark:slate:0)
Block(-14,8,0,quark:slate:0)
Block(-14,8,1,iceandfire:chared_stone:0)
Block(-14,8,2,iceandfire:chared_stone:0)
Block(-14,8,3,iceandfire:chared_stone:0)
Block(-14,8,4,STONE:0)
Block(-14,9,-4,STONE:0)
Block(-14,9,-3,STONE:0)
Block(-14,9,-2,STONE:0)
Block(-14,9,-1,STONE:0)
Block(-14,9,0,STONE:0)
Block(-14,9,1,STONE:0)
Block(-14,9,2,STONE:0)
Block(-14,9,3,STONE:0)
Block(-14,9,4,STONE:0)
Block(-14,10,-4,STONE:0)
Block(-14,10,-3,STONE:0)
Block(-14,10,-2,STONE:0)
Block(-14,10,-1,STONE:0)
Block(-14,10,0,STONE:0)
Block(-14,10,1,STONE:0)
Block(-14,10,2,STONE:0)
Block(-14,10,3,STONE:0)
Block(-14,11,-3,STONE:0)
Block(-14,11,-2,STONE:0)
Block(-14,11,-1,STONE:0)
Block(-13,1,-2,STONE:0)
Block(-13,1,-1,STONE:0)
Block(-13,1,0,STONE:0)
Block(-13,1,1,STONE:0)
Block(-13,1,2,STONE:0)
Block(-13,1,3,STONE:0)
Block(-13,1,4,STONE:0)
Block(-13,1,6,quark:basalt:0)
Block(-13,1,7,quark:basalt:0)
Block(-13,1,8,quark:basalt:0)
Block(-13,2,-3,STONE:0)
Block(-13,2,-2,STONE:0)
Block(-13,2,-1,biomesoplenty:grass:1)
Block(-13,2,0,biomesoplenty:grass:1)
Block(-13,2,1,STONE:0)
Block(-13,2,2,biomesoplenty:ash_block:0)
Block(-13,2,3,quark:stone_basalt_stairs:2)
Block(-13,2,4,notreepunching:cobblestone/basalt:0)
Block(-13,2,5,quark:stone_basalt_slab_double:0)
Block(-13,2,6,quark:basalt:0)
Block(-13,2,7,quark:basalt:0)
Block(-13,2,8,STATIONARY_LAVA:0)
Block(-13,2,9,quark:basalt:0)
Block(-13,3,-6,STONE:0)
Block(-13,3,-5,quark:slate:0)
Block(-13,3,-4,quark:slate:0)
Block(-13,3,-3,quark:slate:0)
Block(-13,3,-2,biomesoplenty:grass:1)
Block(-13,3,-1,biomesoplenty:plant_0:11)
Block(-13,3,0,AIR:0)
Block(-13,3,1,biomesoplenty:grass:1)
Block(-13,3,2,contenttweaker:bone_pile:0)
Block(-13,3,3,AIR:0)
Block(-13,3,4,quark:basalt_speleothem:2)
Block(-13,3,5,rustic:iron_lattice:0)
Block(-13,3,6,quark:basalt_wall:0)
Block(-13,3,7,quark:basalt_speleothem:2)
Block(-13,3,8,AIR:0)
Block(-13,3,9,quark:basalt:0)
Block(-13,4,-6,STONE:0)
Block(-13,4,-5,quark:slate:0)
Block(-13,4,-4,quark:slate:0)
Block(-13,4,-3,biomesoplenty:grass:1)
Block(-13,4,-2,biomesoplenty:plant_0:11)
Block(-13,4,-1,AIR:0)
Block(-13,4,0,AIR:0)
Block(-13,4,1,BROWN_MUSHROOM:0)
Block(-13,4,2,AIR:0)
Block(-13,4,3,AIR:0)
Block(-13,4,4,quark:basalt_speleothem:1)
Block(-13,4,5,rustic:iron_lattice:0)
Block(-13,4,6,AIR:0)
Block(-13,4,7,quark:basalt_speleothem:1)
Block(-13,4,8,AIR:0)
Block(-13,4,9,AIR:0)
Block(-13,4,10,quark:basalt:0)
Block(-13,5,-6,STONE:0)
Block(-13,5,-5,quark:slate:0)
Block(-13,5,-4,quark:slate:0)
Block(-13,5,-3,quark:stone_speleothem:2)
Block(-13,5,-2,AIR:0)
Block(-13,5,-1,AIR:0)
Block(-13,5,0,AIR:0)
Block(-13,5,1,AIR:0)
Block(-13,5,2,AIR:0)
Block(-13,5,3,CAULDRON:0)
Block(-13,5,4,quark:basalt_speleothem:0)
Block(-13,5,5,AIR:0)
Block(-13,5,6,AIR:0)
Block(-13,5,7,quark:basalt_speleothem:2)
Block(-13,5,8,AIR:0)
Block(-13,5,9,quark:basalt:0)
Block(-13,5,10,quark:basalt:0)
Block(-13,6,-5,STONE:0)
Block(-13,6,-4,STONE:0)
Block(-13,6,-3,quark:stone_speleothem:2)
Block(-13,6,-2,AIR:0)
Block(-13,6,-1,AIR:0)
Block(-13,6,0,AIR:0)
Block(-13,6,1,quark:stone_speleothem:0)
Block(-13,6,2,AIR:0)
Block(-13,6,3,rustic:chandelier:0)
Block(-13,6,4,AIR:0)
Block(-13,6,5,AIR:0)
Block(-13,6,6,AIR:0)
Block(-13,6,7,quark:basalt:0)
Block(-13,6,8,quark:basalt:0)
Block(-13,6,9,quark:basalt:0)
Block(-13,7,-4,STONE:0)
Block(-13,7,-3,quark:slate:0)
Block(-13,7,-2,AIR:0)
Block(-13,7,-1,AIR:0)
Block(-13,7,0,AIR:0)
Block(-13,7,1,quark:stone_speleothem:1)
Block(-13,7,2,AIR:0)
Block(-13,7,3,inspirations:rope:1)
Block(-13,7,4,AIR:0)
Block(-13,7,5,quark:basalt:0)
Block(-13,7,6,notreepunching:cobblestone/basalt:0)
Block(-13,8,-4,STONE:0)
Block(-13,8,-3,STONE:0)
Block(-13,8,-2,quark:slate:0)
Block(-13,8,-1,AIR:0)
Block(-13,8,0,quark:slate:0)
Block(-13,8,1,quark:stone_speleothem:2)
Block(-13,8,2,AIR:0)
Block(-13,8,3,inspirations:rope:1)
Block(-13,8,4,iceandfire:chared_stone:0)
Block(-13,9,-4,STONE:0)
Block(-13,9,-3,STONE:0)
Block(-13,9,-2,STONE:0)
Block(-13,9,-1,STONE:0)
Block(-13,9,0,STONE:0)
Block(-13,9,1,STONE:0)
Block(-13,9,2,iceandfire:chared_stone:0)
Block(-13,9,3,iceandfire:chared_stone:0)
Block(-13,9,4,STONE:0)
Block(-13,10,-4,STONE:0)
Block(-13,10,-3,STONE:0)
Block(-13,10,-2,STONE:0)
Block(-13,10,-1,STONE:0)
Block(-13,10,0,STONE:0)
Block(-13,10,1,STONE:0)
Block(-13,10,2,STONE:0)
Block(-13,10,3,STONE:0)
Block(-13,11,-3,STONE:0)
Block(-13,11,-2,STONE:0)
Block(-13,11,-1,STONE:0)
Block(-13,11,0,STONE:0)
Block(-13,11,1,STONE:0)
Block(-13,11,2,STONE:0)
Block(-12,0,2,STONE:0)
Block(-12,0,3,STONE:0)
Block(-12,0,4,STONE:0)
Block(-12,1,-3,STONE:0)
Block(-12,1,-2,STONE:0)
Block(-12,1,-1,STONE:0)
Block(-12,1,0,STONE:0)
Block(-12,1,1,STONE:0)
Block(-12,1,2,STONE:0)
Block(-12,1,3,STONE:0)
Block(-12,1,4,STONE:0)
Block(-12,1,5,quark:basalt:0)
Block(-12,1,6,quark:basalt:0)
Block(-12,1,7,quark:basalt:0)
Block(-12,1,8,quark:basalt:0)
Block(-12,2,-6,STONE:0)
Block(-12,2,-5,quark:slate:0)
Block(-12,2,-4,quark:slate:0)
Block(-12,2,-3,quark:slate:0)
Block(-12,2,-2,STONE:0)
Block(-12,2,-1,STONE:0)
Block(-12,2,0,iceandfire:chared_stone:0)
Block(-12,2,1,iceandfire:chared_stone:0)
Block(-12,2,2,iceandfire:chared_stone:0)
Block(-12,2,3,iceandfire:chared_stone:0)
Block(-12,2,4,quark:stone_basalt_slab_double:0)
Block(-12,2,5,MAGMA:0)
Block(-12,2,6,quark:basalt:0)
Block(-12,2,7,STATIONARY_LAVA:0)
Block(-12,2,8,STATIONARY_LAVA:12)
Block(-12,2,9,quark:basalt:0)
Block(-12,3,-7,STONE:0)
Block(-12,3,-6,quark:slate:0)
Block(-12,3,-5,quark:slate:0)
Block(-12,3,-4,quark:slate:0)
Block(-12,3,-3,biomesoplenty:grass:1)
Block(-12,3,-2,quark:leaf_carpet:1)
Block(-12,3,-1,biomesoplenty:plant_0:11)
Block(-12,3,0,biomesoplenty:plant_0:11)
Block(-12,3,1,AIR:0)
Block(-12,3,2,AIR:0)
Block(-12,3,3,AIR:0)
Block(-12,3,4,quark:stone_basalt_slab:0)
Block(-12,3,5,FIRE:15)
Block(-12,3,6,quark:stone_basalt_slab:0)
Block(-12,3,7,AIR:0)
Block(-12,3,8,STATIONARY_LAVA:12)
Block(-12,3,9,quark:basalt:0)
Block(-12,4,-7,STONE:0)
Block(-12,4,-6,quark:slate:0)
Block(-12,4,-5,quark:slate:0)
Block(-12,4,-4,quark:slate:0)
Block(-12,4,-3,biomesoplenty:plant_0:11)
Block(-12,4,-2,AIR:0)
Block(-12,4,-1,AIR:0)
Block(-12,4,0,AIR:0)
Block(-12,4,1,AIR:0)
Block(-12,4,2,AIR:0)
Block(-12,4,3,AIR:0)
Block(-12,4,4,AIR:0)
Block(-12,4,5,biomesoplenty:flesh:0)
Block(-12,4,6,AIR:0)
Block(-12,4,7,AIR:0)
Block(-12,4,8,STATIONARY_LAVA:12)
Block(-12,4,9,quark:basalt:0)
Block(-12,4,10,quark:basalt:0)
Block(-12,5,-7,STONE:0)
Block(-12,5,-6,quark:slate:0)
Block(-12,5,-5,quark:stone_speleothem:2)
Block(-12,5,-4,rustic:mooncap_mushroom:0)
Block(-12,5,-3,AIR:0)
Block(-12,5,-2,AIR:0)
Block(-12,5,-1,AIR:0)
Block(-12,5,0,AIR:0)
Block(-12,5,1,AIR:0)
Block(-12,5,2,AIR:0)
Block(-12,5,3,AIR:0)
Block(-12,5,4,quark:basalt_speleothem:0)
Block(-12,5,5,BROWN_MUSHROOM:0)
Block(-12,5,6,AIR:0)
Block(-12,5,7,AIR:0)
Block(-12,5,8,STATIONARY_LAVA:4)
Block(-12,5,9,STATIONARY_LAVA:2)
Block(-12,5,10,STATIONARY_LAVA:0)
Block(-12,5,11,quark:basalt:0)
Block(-12,6,-6,STONE:0)
Block(-12,6,-5,quark:slate:0)
Block(-12,6,-4,AIR:0)
Block(-12,6,-3,AIR:0)
Block(-12,6,-2,AIR:0)
Block(-12,6,-1,AIR:0)
Block(-12,6,0,AIR:0)
Block(-12,6,1,AIR:0)
Block(-12,6,2,AIR:0)
Block(-12,6,3,AIR:0)
Block(-12,6,4,quark:basalt_speleothem:1)
Block(-12,6,5,AIR:0)
Block(-12,6,6,AIR:0)
Block(-12,6,7,AIR:0)
Block(-12,6,8,AIR:0)
Block(-12,6,9,quark:basalt:0)
Block(-12,6,10,quark:basalt:0)
Block(-12,7,-4,STONE:0)
Block(-12,7,-3,AIR:0)
Block(-12,7,-2,AIR:0)
Block(-12,7,-1,AIR:0)
Block(-12,7,0,AIR:0)
Block(-12,7,1,AIR:0)
Block(-12,7,2,AIR:0)
Block(-12,7,3,AIR:0)
Block(-12,7,4,quark:basalt_speleothem:2)
Block(-12,7,5,AIR:0)
Block(-12,7,6,AIR:0)
Block(-12,7,7,quark:basalt:0)
Block(-12,7,8,quark:basalt:0)
Block(-12,8,-4,STONE:0)
Block(-12,8,-3,STONE:0)
Block(-12,8,-2,AIR:0)
Block(-12,8,-1,AIR:0)
Block(-12,8,0,AIR:0)
Block(-12,8,1,AIR:0)
Block(-12,8,2,AIR:0)
Block(-12,8,3,AIR:0)
Block(-12,8,4,quark:basalt:0)
Block(-12,8,5,quark:basalt:0)
Block(-12,8,6,notreepunching:cobblestone/basalt:0)
Block(-12,9,-4,STONE:0)
Block(-12,9,-3,STONE:0)
Block(-12,9,-2,STONE:0)
Block(-12,9,-1,STONE:0)
Block(-12,9,0,STONE:0)
Block(-12,9,1,STONE:0)
Block(-12,9,2,iceandfire:chared_cobblestone:0)
Block(-12,9,3,iceandfire:chared_cobblestone:0)
Block(-12,9,4,STONE:0)
Block(-12,10,-4,STONE:0)
Block(-12,10,-3,STONE:0)
Block(-12,10,-2,STONE:0)
Block(-12,10,-1,STONE:0)
Block(-12,10,0,STONE:0)
Block(-12,10,1,STONE:0)
Block(-12,10,2,STONE:0)
Block(-12,10,3,STONE:0)
Block(-12,11,-3,STONE:0)
Block(-12,11,-2,STONE:0)
Block(-12,11,-1,STONE:0)
Block(-12,11,0,STONE:0)
Block(-12,11,1,STONE:0)
Block(-12,11,2,STONE:0)
Block(-11,0,2,STONE:0)
Block(-11,0,3,STONE:0)
Block(-11,0,4,STONE:0)
Block(-11,1,-4,STONE:0)
Block(-11,1,-3,STONE:0)
Block(-11,1,-2,STONE:0)
Block(-11,1,-1,STONE:0)
Block(-11,1,0,STONE:0)
Block(-11,1,1,iceandfire:chared_stone:0)
Block(-11,1,2,iceandfire:chared_stone:0)
Block(-11,1,3,iceandfire:chared_stone:0)
Block(-11,1,4,quark:basalt:0)
Block(-11,1,5,quark:basalt:0)
Block(-11,1,7,quark:basalt:0)
Block(-11,2,-6,STONE:0)
Block(-11,2,-5,quark:slate:0)
Block(-11,2,-4,quark:slate:0)
Block(-11,2,-3,biomesoplenty:grass:1)
Block(-11,2,-2,STONE:0)
Block(-11,2,-1,biomesoplenty:grass:1)
Block(-11,2,0,biomesoplenty:grass:1)
Block(-11,2,1,iceandfire:chared_stone:0)
Block(-11,2,2,iceandfire:chared_stone:0)
Block(-11,2,3,quark:stone_basalt_slab:0)
Block(-11,2,4,quark:stone_basalt_slab:0)
Block(-11,2,5,MAGMA:0)
Block(-11,2,6,quark:basalt:0)
Block(-11,2,7,STATIONARY_LAVA:0)
Block(-11,2,8,quark:basalt:0)
Block(-11,3,-7,STONE:0)
Block(-11,3,-6,quark:slate:0)
Block(-11,3,-5,quark:slate:0)
Block(-11,3,-4,quark:slate:0)
Block(-11,3,-3,quark:leaf_carpet:1)
Block(-11,3,-2,quark:leaf_carpet:1)
Block(-11,3,-1,quark:leaf_carpet:1)
Block(-11,3,0,AIR:0)
Block(-11,3,1,AIR:0)
Block(-11,3,2,biomesoplenty:plant_0:11)
Block(-11,3,3,AIR:0)
Block(-11,3,4,AIR:0)
Block(-11,3,5,FIRE:15)
Block(-11,3,6,quark:basalt_speleothem:2)
Block(-11,3,7,AIR:0)
Block(-11,3,8,quark:basalt:0)
Block(-11,4,-7,STONE:0)
Block(-11,4,-6,quark:slate:0)
Block(-11,4,-5,biomesoplenty:grass:1)
Block(-11,4,-4,rustic:mooncap_mushroom:0)
Block(-11,4,-3,AIR:0)
Block(-11,4,-2,AIR:0)
Block(-11,4,-1,AIR:0)
Block(-11,4,0,AIR:0)
Block(-11,4,1,AIR:0)
Block(-11,4,2,AIR:0)
Block(-11,4,3,AIR:0)
Block(-11,4,4,AIR:0)
Block(-11,4,5,biomesoplenty:flesh:0)
Block(-11,4,6,quark:basalt_speleothem:1)
Block(-11,4,7,AIR:0)
Block(-11,4,8,quark:basalt_speleothem:2)
Block(-11,4,9,quark:basalt:0)
Block(-11,5,-7,STONE:0)
Block(-11,5,-6,quark:slate:0)
Block(-11,5,-5,rustic:mooncap_mushroom:0)
Block(-11,5,-4,AIR:0)
Block(-11,5,-3,AIR:0)
Block(-11,5,-2,AIR:0)
Block(-11,5,-1,AIR:0)
Block(-11,5,0,AIR:0)
Block(-11,5,1,AIR:0)
Block(-11,5,2,AIR:0)
Block(-11,5,3,AIR:0)
Block(-11,5,4,AIR:0)
Block(-11,5,5,BROWN_MUSHROOM:0)
Block(-11,5,6,quark:basalt_speleothem:1)
Block(-11,5,7,AIR:0)
Block(-11,5,8,AIR:0)
Block(-11,5,9,quark:basalt:0)
Block(-11,5,10,quark:basalt:0)
Block(-11,6,-7,STONE:0)
Block(-11,6,-6,STONE:0)
Block(-11,6,-5,AIR:0)
Block(-11,6,-4,AIR:0)
Block(-11,6,-3,AIR:0)
Block(-11,6,-2,AIR:0)
Block(-11,6,-1,AIR:0)
Block(-11,6,0,AIR:0)
Block(-11,6,1,AIR:0)
Block(-11,6,2,AIR:0)
Block(-11,6,3,AIR:0)
Block(-11,6,4,AIR:0)
Block(-11,6,5,AIR:0)
Block(-11,6,6,quark:basalt_speleothem:2)
Block(-11,6,7,AIR:0)
Block(-11,6,8,quark:basalt:0)
Block(-11,7,-6,STONE:0)
Block(-11,7,-5,STONE:0)
Block(-11,7,-4,AIR:0)
Block(-11,7,-3,AIR:0)
Block(-11,7,-2,AIR:0)
Block(-11,7,-1,AIR:0)
Block(-11,7,0,AIR:0)
Block(-11,7,1,AIR:0)
Block(-11,7,2,AIR:0)
Block(-11,7,3,AIR:0)
Block(-11,7,4,AIR:0)
Block(-11,7,5,AIR:0)
Block(-11,7,6,quark:basalt:0)
Block(-11,7,7,quark:basalt:0)
Block(-11,8,-4,STONE:0)
Block(-11,8,-3,quark:slate:0)
Block(-11,8,-2,AIR:0)
Block(-11,8,-1,AIR:0)
Block(-11,8,0,AIR:0)
Block(-11,8,1,AIR:0)
Block(-11,8,2,AIR:0)
Block(-11,8,3,AIR:0)
Block(-11,8,4,AIR:0)
Block(-11,8,5,notreepunching:cobblestone/basalt:0)
Block(-11,9,-3,STONE:0)
Block(-11,9,-2,STONE:0)
Block(-11,9,-1,STONE:0)
Block(-11,9,0,STONE:0)
Block(-11,9,1,iceandfire:chared_cobblestone:0)
Block(-11,9,2,AIR:0)
Block(-11,9,3,iceandfire:chared_stone:0)
Block(-11,9,4,iceandfire:chared_stone:0)
Block(-11,10,-3,STONE:0)
Block(-11,10,-2,STONE:0)
Block(-11,10,-1,STONE:0)
Block(-11,10,0,STONE:0)
Block(-11,10,1,STONE:0)
Block(-11,10,2,iceandfire:chared_cobblestone:0)
Block(-11,10,3,STONE:0)
Block(-11,11,-1,STONE:0)
Block(-11,11,0,STONE:0)
Block(-11,11,1,STONE:0)
Block(-11,11,2,STONE:0)
Block(-10,0,2,iceandfire:chared_stone:0)
Block(-10,0,3,iceandfire:chared_stone:0)
Block(-10,0,4,STONE:0)
Block(-10,1,-4,STONE:0)
Block(-10,1,-3,STONE:0)
Block(-10,1,-2,STONE:0)
Block(-10,1,-1,STONE:0)
Block(-10,1,0,iceandfire:chared_stone:0)
Block(-10,1,1,iceandfire:chared_stone:0)
Block(-10,1,2,iceandfire:chared_stone:0)
Block(-10,1,3,iceandfire:chared_stone:0)
Block(-10,1,4,iceandfire:chared_stone:0)
Block(-10,1,5,STONE:0)
Block(-10,2,-6,STONE:0)
Block(-10,2,-5,quark:slate:0)
Block(-10,2,-4,quark:slate:0)
Block(-10,2,-3,quark:slate:0)
Block(-10,2,-2,biomesoplenty:grass:1)
Block(-10,2,-1,STONE:0)
Block(-10,2,0,biomesoplenty:grass:1)
Block(-10,2,1,biomesoplenty:grass:1)
Block(-10,2,2,iceandfire:chared_stone:0)
Block(-10,2,3,quark:stone_basalt_slab:0)
Block(-10,2,4,quark:stone_basalt_stairs:2)
Block(-10,2,5,quark:basalt:0)
Block(-10,2,6,notreepunching:cobblestone/basalt:0)
Block(-10,2,7,quark:basalt:0)
Block(-10,3,-7,STONE:0)
Block(-10,3,-6,quark:slate:0)
Block(-10,3,-5,quark:slate:0)
Block(-10,3,-4,biomesoplenty:grass:1)
Block(-10,3,-3,quark:leaf_carpet:1)
Block(-10,3,-2,quark:leaf_carpet:1)
Block(-10,3,-1,quark:leaf_carpet:1)
Block(-10,3,0,quark:leaf_carpet:1)
Block(-10,3,1,AIR:0)
Block(-10,3,2,biomesoplenty:plant_0:11)
Block(-10,3,3,AIR:0)
Block(-10,3,4,AIR:0)
Block(-10,3,5,rustic:iron_lattice:0)
Block(-10,3,6,AIR:0)
Block(-10,3,7,quark:basalt:0)
Block(-10,4,-7,STONE:0)
Block(-10,4,-6,quark:slate:0)
Block(-10,4,-5,quark:slate:0)
Block(-10,4,-4,quark:leaf_carpet:1)
Block(-10,4,-3,AIR:0)
Block(-10,4,-2,AIR:0)
Block(-10,4,-1,AIR:0)
Block(-10,4,0,AIR:0)
Block(-10,4,1,AIR:0)
Block(-10,4,2,AIR:0)
Block(-10,4,3,AIR:0)
Block(-10,4,4,AIR:0)
Block(-10,4,5,rustic:iron_lattice:0)
Block(-10,4,6,AIR:0)
Block(-10,4,7,quark:basalt_speleothem:2)
Block(-10,4,8,quark:basalt:0)
Block(-10,5,-7,STONE:0)
Block(-10,5,-6,quark:slate:0)
Block(-10,5,-5,quark:slate:0)
Block(-10,5,-4,AIR:0)
Block(-10,5,-3,AIR:0)
Block(-10,5,-2,AIR:0)
Block(-10,5,-1,AIR:0)
Block(-10,5,0,AIR:0)
Block(-10,5,1,AIR:0)
Block(-10,5,2,AIR:0)
Block(-10,5,3,AIR:0)
Block(-10,5,4,AIR:0)
Block(-10,5,5,AIR:0)
Block(-10,5,6,AIR:0)
Block(-10,5,7,quark:basalt:0)
Block(-10,5,8,quark:basalt:0)
Block(-10,6,-7,STONE:0)
Block(-10,6,-6,STONE:0)
Block(-10,6,-5,quark:slate:0)
Block(-10,6,-4,AIR:0)
Block(-10,6,-3,AIR:0)
Block(-10,6,-2,quark:stone_speleothem:0)
Block(-10,6,-1,AIR:0)
Block(-10,6,0,AIR:0)
Block(-10,6,1,AIR:0)
Block(-10,6,2,AIR:0)
Block(-10,6,3,AIR:0)
Block(-10,6,4,AIR:0)
Block(-10,6,5,AIR:0)
Block(-10,6,6,AIR:0)
Block(-10,6,7,quark:basalt:0)
Block(-10,7,-6,STONE:0)
Block(-10,7,-5,STONE:0)
Block(-10,7,-4,quark:slate:0)
Block(-10,7,-3,quark:slate:0)
Block(-10,7,-2,quark:stone_speleothem:1)
Block(-10,7,-1,AIR:0)
Block(-10,7,0,AIR:0)
Block(-10,7,1,AIR:0)
Block(-10,7,2,quark:stone_speleothem:0)
Block(-10,7,3,AIR:0)
Block(-10,7,4,AIR:0)
Block(-10,7,5,AIR:0)
Block(-10,7,6,notreepunching:cobblestone/basalt:0)
Block(-10,8,-3,quark:slate:0)
Block(-10,8,-2,quark:stone_speleothem:2)
Block(-10,8,-1,quark:slate:0)
Block(-10,8,0,STONE:0)
Block(-10,8,1,AIR:0)
Block(-10,8,2,quark:stone_speleothem:1)
Block(-10,8,3,AIR:0)
Block(-10,8,4,AIR:0)
Block(-10,8,5,MAGMA:0)
Block(-10,9,-2,STONE:0)
Block(-10,9,-1,STONE:0)
Block(-10,9,0,STONE:0)
Block(-10,9,1,iceandfire:chared_stone:0)
Block(-10,9,2,quark:stone_speleothem:2)
Block(-10,9,3,AIR:0)
Block(-10,9,4,iceandfire:chared_stone:0)
Block(-10,9,5,iceandfire:chared_stone:0)
Block(-10,9,6,iceandfire:chared_stone:0)
Block(-10,9,7,STONE:0)
Block(-10,10,-2,STONE:0)
Block(-10,10,-1,STONE:0)
Block(-10,10,0,STONE:0)
Block(-10,10,1,STONE:0)
Block(-10,10,2,STONE:0)
Block(-10,10,3,iceandfire:chared_stone:0)
Block(-10,10,5,iceandfire:chared_stone:0)
Block(-10,10,6,STONE:0)
Block(-10,10,7,STONE:0)
Block(-10,11,-1,STONE:0)
Block(-10,11,0,STONE:0)
Block(-10,11,1,STONE:0)
Block(-10,11,5,iceandfire:chared_stone:0)
Block(-10,11,6,STONE:0)
Block(-10,11,7,STONE:0)
Block(-10,13,3,STONE:0)
Block(-10,13,4,STONE:0)
Block(-10,13,5,STONE:0)
Block(-10,14,3,STONE:0)
Block(-10,14,4,STONE:0)
Block(-10,14,5,STONE:0)
Block(-10,15,3,STONE:0)
Block(-10,15,4,STONE:0)
Block(-10,15,5,STONE:0)
Block(-9,0,1,iceandfire:chared_stone:0)
Block(-9,0,2,iceandfire:chared_stone:0)
Block(-9,0,3,iceandfire:chared_stone:0)
Block(-9,0,4,STONE:0)
Block(-9,0,5,STONE:0)
Block(-9,1,-4,STONE:0)
Block(-9,1,-3,STONE:0)
Block(-9,1,-2,STONE:0)
Block(-9,1,-1,STONE:0)
Block(-9,1,0,iceandfire:chared_stone:0)
Block(-9,1,1,iceandfire:chared_stone:0)
Block(-9,1,2,iceandfire:chared_stone:0)
Block(-9,1,3,iceandfire:chared_stone:0)
Block(-9,1,4,iceandfire:chared_stone:0)
Block(-9,1,5,STONE:0)
Block(-9,1,6,STONE:0)
Block(-9,2,-6,STONE:0)
Block(-9,2,-5,STONE:0)
Block(-9,2,-4,STONE:0)
Block(-9,2,-3,STONE:0)
Block(-9,2,-2,STONE:0)
Block(-9,2,-1,STONE:0)
Block(-9,2,0,iceandfire:chared_stone:0)
Block(-9,2,1,iceandfire:chared_stone:0)
Block(-9,2,2,iceandfire:chared_stone:0)
Block(-9,2,3,quark:stone_basalt_slab:0)
Block(-9,2,4,biomesoplenty:ash_block:0)
Block(-9,2,5,quark:basalt:0)
Block(-9,2,6,iceandfire:chared_stone:0)
Block(-9,2,7,iceandfire:chared_stone:0)
Block(-9,2,8,STONE:0)
Block(-9,2,9,STONE:0)
Block(-9,2,10,STONE:0)
Block(-9,3,-7,STONE:0)
Block(-9,3,-6,STONE:0)
Block(-9,3,-5,quark:slate:0)
Block(-9,3,-4,quark:slate:0)
Block(-9,3,-3,quark:slate:0)
Block(-9,3,-2,biomesoplenty:grass:1)
Block(-9,3,-1,STONE:0)
Block(-9,3,0,biomesoplenty:grass:1)
Block(-9,3,1,biomesoplenty:plant_0:11)
Block(-9,3,2,AIR:0)
Block(-9,3,3,AIR:0)
Block(-9,3,4,AIR:0)
Block(-9,3,5,quark:stone_basalt_stairs:0)
Block(-9,3,6,iceandfire:chared_stone:0)
Block(-9,3,7,iceandfire:chared_stone:0)
Block(-9,3,8,STONE:0)
Block(-9,3,9,STONE:0)
Block(-9,3,10,STONE:0)
Block(-9,4,-7,STONE:0)
Block(-9,4,-6,STONE:0)
Block(-9,4,-5,quark:slate:0)
Block(-9,4,-4,quark:slate:0)
Block(-9,4,-3,quark:slate:0)
Block(-9,4,-2,rustic:mooncap_mushroom:0)
Block(-9,4,-1,biomesoplenty:grass:1)
Block(-9,4,0,biomesoplenty:plant_0:11)
Block(-9,4,1,AIR:0)
Block(-9,4,2,AIR:0)
Block(-9,4,3,AIR:0)
Block(-9,4,4,AIR:0)
Block(-9,4,5,AIR:0)
Block(-9,4,6,iceandfire:chared_stone:0)
Block(-9,4,7,notreepunching:cobblestone/basalt:0)
Block(-9,4,8,STONE:0)
Block(-9,4,9,STONE:0)
Block(-9,4,10,STONE:0)
Block(-9,5,-7,STONE:0)
Block(-9,5,-6,STONE:0)
Block(-9,5,-5,quark:slate:0)
Block(-9,5,-4,quark:slate:0)
Block(-9,5,-3,AIR:0)
Block(-9,5,-2,AIR:0)
Block(-9,5,-1,quark:leaf_carpet:1)
Block(-9,5,0,AIR:0)
Block(-9,5,1,AIR:0)
Block(-9,5,2,AIR:0)
Block(-9,5,3,AIR:0)
Block(-9,5,4,AIR:0)
Block(-9,5,5,AIR:0)
Block(-9,5,6,AIR:0)
Block(-9,5,7,quark:basalt_speleothem:2)
Block(-9,5,8,iceandfire:chared_cobblestone:0)
Block(-9,5,9,STONE:0)
Block(-9,5,10,STONE:0)
Block(-9,6,-7,STONE:0)
Block(-9,6,-6,STONE:0)
Block(-9,6,-5,STONE:0)
Block(-9,6,-4,quark:slate:0)
Block(-9,6,-3,quark:slate:0)
Block(-9,6,-2,quark:slate:0)
Block(-9,6,-1,quark:slate:0)
Block(-9,6,0,AIR:0)
Block(-9,6,1,AIR:0)
Block(-9,6,2,AIR:0)
Block(-9,6,3,AIR:0)
Block(-9,6,4,AIR:0)
Block(-9,6,5,AIR:0)
Block(-9,6,6,AIR:0)
Block(-9,6,7,iceandfire:chared_stone:0)
Block(-9,6,8,STONE:0)
Block(-9,7,-6,STONE:0)
Block(-9,7,-5,STONE:0)
Block(-9,7,-4,quark:slate:0)
Block(-9,7,-3,quark:slate:0)
Block(-9,7,-2,quark:slate:0)
Block(-9,7,-1,quark:slate:0)
Block(-9,7,0,quark:slate:0)
Block(-9,7,1,AIR:0)
Block(-9,7,2,AIR:0)
Block(-9,7,3,AIR:0)
Block(-9,7,4,AIR:0)
Block(-9,7,5,iceandfire:chared_stone:0)
Block(-9,7,6,iceandfire:chared_stone:0)
Block(-9,7,7,iceandfire:chared_stone:0)
Block(-9,7,8,iceandfire:chared_stone:0)
Block(-9,8,-2,quark:slate:0)
Block(-9,8,-1,quark:slate:0)
Block(-9,8,0,quark:slate:0)
Block(-9,8,1,AIR:0)
Block(-9,8,2,AIR:0)
Block(-9,8,3,AIR:0)
Block(-9,8,4,AIR:0)
Block(-9,8,5,iceandfire:chared_cobblestone:0)
Block(-9,8,6,iceandfire:chared_stone:0)
Block(-9,8,7,iceandfire:chared_stone:0)
Block(-9,8,8,iceandfire:chared_stone:0)
Block(-9,9,-1,STONE:0)
Block(-9,9,0,STONE:0)
Block(-9,9,1,iceandfire:chared_stone:0)
Block(-9,9,2,iceandfire:chared_stone:0)
Block(-9,9,3,AIR:0)
Block(-9,9,4,iceandfire:chared_stone:0)
Block(-9,9,5,iceandfire:chared_stone:0)
Block(-9,9,6,iceandfire:chared_stone:0)
Block(-9,9,7,iceandfire:chared_stone:0)
Block(-9,9,8,iceandfire:chared_stone:0)
Block(-9,10,-1,STONE:0)
Block(-9,10,0,STONE:0)
Block(-9,10,1,STONE:0)
Block(-9,10,2,iceandfire:chared_stone:0)
Block(-9,10,3,iceandfire:chared_stone:0)
Block(-9,10,4,iceandfire:chared_stone:0)
Block(-9,10,5,iceandfire:chared_stone:0)
Block(-9,10,6,iceandfire:chared_stone:0)
Block(-9,10,7,iceandfire:chared_stone:0)
Block(-9,10,8,STONE:0)
Block(-9,10,9,STONE:0)
Block(-9,11,0,STONE:0)
Block(-9,11,1,STONE:0)
Block(-9,11,2,iceandfire:chared_stone:0)
Block(-9,11,3,iceandfire:chared_stone:0)
Block(-9,11,4,iceandfire:chared_stone:0)
Block(-9,11,5,iceandfire:chared_stone:0)
Block(-9,11,6,iceandfire:chared_stone:0)
Block(-9,11,7,iceandfire:chared_stone:0)
Block(-9,11,8,STONE:0)
Block(-9,11,9,STONE:0)
Block(-9,12,0,STONE:0)
Block(-9,12,1,STONE:0)
Block(-9,12,2,STONE:0)
Block(-9,12,3,iceandfire:chared_stone:0)
Block(-9,12,4,iceandfire:chared_stone:0)
Block(-9,12,5,iceandfire:chared_stone:0)
Block(-9,12,6,iceandfire:chared_stone:0)
Block(-9,12,7,iceandfire:chared_stone:0)
Block(-9,12,8,iceandfire:chared_stone:0)
Block(-9,12,9,STONE:0)
Block(-9,13,0,STONE:0)
Block(-9,13,1,STONE:0)
Block(-9,13,2,STONE:0)
Block(-9,13,3,STONE:0)
Block(-9,13,4,STONE:0)
Block(-9,13,5,STONE:0)
Block(-9,13,6,iceandfire:chared_stone:0)
Block(-9,14,2,STONE:0)
Block(-9,14,3,STONE:0)
Block(-9,14,4,STONE:0)
Block(-9,14,5,STONE:0)
Block(-9,14,6,iceandfire:chared_stone:0)
Block(-9,15,2,STONE:0)
Block(-9,15,3,STONE:0)
Block(-9,15,4,STONE:0)
Block(-9,15,5,STONE:0)
Block(-9,15,6,STONE:0)
Block(-9,16,3,STONE:0)
Block(-9,16,4,STONE:0)
Block(-9,16,5,STONE:0)
Block(-8,0,1,iceandfire:chared_stone:0)
Block(-8,0,2,iceandfire:chared_stone:0)
Block(-8,0,3,iceandfire:chared_stone:0)
Block(-8,0,4,STONE:0)
Block(-8,0,5,STONE:0)
Block(-8,1,-1,STONE:0)
Block(-8,1,0,iceandfire:chared_stone:0)
Block(-8,1,1,iceandfire:chared_stone:0)
Block(-8,1,2,iceandfire:chared_stone:0)
Block(-8,1,3,iceandfire:chared_stone:0)
Block(-8,1,4,iceandfire:chared_stone:0)
Block(-8,1,5,iceandfire:chared_stone:0)
Block(-8,1,6,iceandfire:chared_stone:0)
Block(-8,1,7,iceandfire:chared_stone:0)
Block(-8,1,8,STONE:0)
Block(-8,1,9,STONE:0)
Block(-8,1,10,STONE:0)
Block(-8,2,-4,STONE:0)
Block(-8,2,-3,STONE:0)
Block(-8,2,-2,STONE:0)
Block(-8,2,-1,STONE:0)
Block(-8,2,0,iceandfire:chared_stone:0)
Block(-8,2,1,iceandfire:chared_stone:0)
Block(-8,2,2,iceandfire:chared_stone:0)
Block(-8,2,3,iceandfire:chared_cobblestone:0)
Block(-8,2,4,iceandfire:chared_cobblestone:0)
Block(-8,2,5,iceandfire:chared_stone:0)
Block(-8,2,6,iceandfire:chared_stone:0)
Block(-8,2,7,iceandfire:chared_stone:0)
Block(-8,2,8,iceandfire:chared_stone:0)
Block(-8,2,9,STONE:0)
Block(-8,2,10,STONE:0)
Block(-8,2,11,STONE:0)
Block(-8,3,-6,STONE:0)
Block(-8,3,-5,STONE:0)
Block(-8,3,-4,STONE:0)
Block(-8,3,-3,STONE:0)
Block(-8,3,-2,STONE:0)
Block(-8,3,-1,STONE:0)
Block(-8,3,0,iceandfire:chared_stone:0)
Block(-8,3,1,AIR:0)
Block(-8,3,2,AIR:0)
Block(-8,3,3,AIR:0)
Block(-8,3,4,contenttweaker:bone_pile:0)
Block(-8,3,5,iceandfire:chared_stone:0)
Block(-8,3,6,iceandfire:chared_cobblestone:0)
Block(-8,3,7,iceandfire:chared_stone:0)
Block(-8,3,8,iceandfire:chared_stone:0)
Block(-8,3,9,STONE:0)
Block(-8,3,10,STONE:0)
Block(-8,3,11,STONE:0)
Block(-8,4,-6,STONE:0)
Block(-8,4,-5,STONE:0)
Block(-8,4,-4,STONE:0)
Block(-8,4,-3,STONE:0)
Block(-8,4,-2,STONE:0)
Block(-8,4,-1,STONE:0)
Block(-8,4,0,iceandfire:chared_stone:0)
Block(-8,4,1,AIR:0)
Block(-8,4,2,AIR:0)
Block(-8,4,3,AIR:0)
Block(-8,4,4,AIR:0)
Block(-8,4,5,AIR:0)
Block(-8,4,6,contenttweaker:bone_pile:0)
Block(-8,4,7,iceandfire:chared_cobblestone:0)
Block(-8,4,8,iceandfire:chared_stone:0)
Block(-8,4,9,STONE:0)
Block(-8,4,10,STONE:0)
Block(-8,4,11,STONE:0)
Block(-8,5,-6,STONE:0)
Block(-8,5,-5,STONE:0)
Block(-8,5,-4,STONE:0)
Block(-8,5,-3,quark:slate:0)
Block(-8,5,-2,quark:slate:0)
Block(-8,5,-1,quark:slate:0)
Block(-8,5,0,quark:stone_speleothem:2)
Block(-8,5,1,quark:stone_speleothem:0)
Block(-8,5,2,AIR:0)
Block(-8,5,3,AIR:0)
Block(-8,5,4,AIR:0)
Block(-8,5,5,AIR:0)
Block(-8,5,6,AIR:0)
Block(-8,5,7,AIR:0)
Block(-8,5,8,iceandfire:chared_stone:0)
Block(-8,5,9,STONE:0)
Block(-8,5,10,STONE:0)
Block(-8,5,11,STONE:0)
Block(-8,6,-6,STONE:0)
Block(-8,6,-5,STONE:0)
Block(-8,6,-4,quark:slate:0)
Block(-8,6,-3,quark:slate:0)
Block(-8,6,-2,quark:slate:0)
Block(-8,6,-1,quark:slate:0)
Block(-8,6,0,quark:stone_speleothem:2)
Block(-8,6,1,quark:stone_speleothem:1)
Block(-8,6,2,AIR:0)
Block(-8,6,3,AIR:0)
Block(-8,6,4,AIR:0)
Block(-8,6,5,AIR:0)
Block(-8,6,6,AIR:0)
Block(-8,6,7,iceandfire:chared_stone:0)
Block(-8,6,8,iceandfire:chared_stone:0)
Block(-8,6,9,iceandfire:chared_stone:0)
Block(-8,6,10,iceandfire:chared_stone:0)
Block(-8,7,-6,STONE:0)
Block(-8,7,-5,STONE:0)
Block(-8,7,-4,quark:slate:0)
Block(-8,7,-3,quark:slate:0)
Block(-8,7,-2,quark:slate:0)
Block(-8,7,-1,quark:slate:0)
Block(-8,7,0,quark:slate:0)
Block(-8,7,1,quark:stone_speleothem:2)
Block(-8,7,2,AIR:0)
Block(-8,7,3,AIR:0)
Block(-8,7,4,AIR:0)
Block(-8,7,5,AIR:0)
Block(-8,7,6,iceandfire:chared_stone:0)
Block(-8,7,7,iceandfire:chared_stone:0)
Block(-8,7,8,iceandfire:chared_stone:0)
Block(-8,7,9,iceandfire:chared_stone:0)
Block(-8,8,-6,STONE:0)
Block(-8,8,-5,STONE:0)
Block(-8,8,-4,quark:slate:0)
Block(-8,8,-2,quark:slate:0)
Block(-8,8,-1,STONE:0)
Block(-8,8,0,iceandfire:chared_stone:0)
Block(-8,8,1,quark:slate:0)
Block(-8,8,2,AIR:0)
Block(-8,8,3,AIR:0)
Block(-8,8,4,AIR:0)
Block(-8,8,5,iceandfire:chared_stone:0)
Block(-8,8,6,iceandfire:chared_stone:0)
Block(-8,8,7,iceandfire:chared_stone:0)
Block(-8,8,8,iceandfire:chared_stone:0)
Block(-8,8,9,iceandfire:chared_stone:0)
Block(-8,9,-6,STONE:0)
Block(-8,9,-5,STONE:0)
Block(-8,9,-4,STONE:0)
Block(-8,9,-3,STONE:0)
Block(-8,9,-2,STONE:0)
Block(-8,9,-1,STONE:0)
Block(-8,9,0,iceandfire:chared_stone:0)
Block(-8,9,1,STONE:0)
Block(-8,9,2,iceandfire:chared_stone:0)
Block(-8,9,3,quark:stone_speleothem:0)
Block(-8,9,4,AIR:0)
Block(-8,9,5,iceandfire:chared_stone:0)
Block(-8,9,6,iceandfire:chared_stone:0)
Block(-8,9,7,iceandfire:chared_stone:0)
Block(-8,9,8,iceandfire:chared_stone:0)
Block(-8,9,9,iceandfire:chared_stone:0)
Block(-8,10,-4,STONE:0)
Block(-8,10,-3,STONE:0)
Block(-8,10,-2,STONE:0)
Block(-8,10,-1,iceandfire:chared_stone:0)
Block(-8,10,0,iceandfire:chared_stone:0)
Block(-8,10,1,iceandfire:chared_stone:0)
Block(-8,10,2,iceandfire:chared_stone:0)
Block(-8,10,3,quark:stone_speleothem:1)
Block(-8,10,4,iceandfire:chared_stone:0)
Block(-8,10,5,iceandfire:chared_stone:0)
Block(-8,10,6,iceandfire:chared_stone:0)
Block(-8,10,7,iceandfire:chared_stone:0)
Block(-8,10,8,iceandfire:chared_stone:0)
Block(-8,10,9,iceandfire:chared_stone:0)
Block(-8,10,10,iceandfire:chared_stone:0)
Block(-8,11,-4,STONE:0)
Block(-8,11,-3,STONE:0)
Block(-8,11,-2,STONE:0)
Block(-8,11,-1,iceandfire:chared_stone:0)
Block(-8,11,0,iceandfire:chared_stone:0)
Block(-8,11,1,iceandfire:chared_stone:0)
Block(-8,11,2,iceandfire:chared_stone:0)
Block(-8,11,3,quark:stone_speleothem:2)
Block(-8,11,4,iceandfire:chared_stone:0)
Block(-8,11,5,iceandfire:chared_stone:0)
Block(-8,11,6,iceandfire:chared_stone:0)
Block(-8,11,7,iceandfire:chared_stone:0)
Block(-8,11,8,iceandfire:chared_stone:0)
Block(-8,11,9,iceandfire:chared_stone:0)
Block(-8,11,10,iceandfire:chared_stone:0)
Block(-8,12,-1,iceandfire:chared_stone:0)
Block(-8,12,0,iceandfire:chared_stone:0)
Block(-8,12,1,iceandfire:chared_stone:0)
Block(-8,12,2,STONE:0)
Block(-8,12,3,iceandfire:chared_stone:0)
Block(-8,12,4,iceandfire:chared_stone:0)
Block(-8,12,5,iceandfire:chared_stone:0)
Block(-8,12,6,iceandfire:chared_stone:0)
Block(-8,12,7,iceandfire:chared_stone:0)
Block(-8,12,8,iceandfire:chared_stone:0)
Block(-8,12,9,iceandfire:chared_stone:0)
Block(-8,12,10,STONE:0)
Block(-8,13,-1,STONE:0)
Block(-8,13,0,STONE:0)
Block(-8,13,1,STONE:0)
Block(-8,13,2,STONE:0)
Block(-8,13,3,STONE:0)
Block(-8,13,4,iceandfire:chared_stone:0)
Block(-8,13,5,iceandfire:chared_stone:0)
Block(-8,13,6,iceandfire:chared_stone:0)
Block(-8,13,7,iceandfire:chared_stone:0)
Block(-8,13,8,iceandfire:chared_stone:0)
Block(-8,13,9,iceandfire:chared_stone:0)
Block(-8,14,0,STONE:0)
Block(-8,14,1,STONE:0)
Block(-8,14,2,STONE:0)
Block(-8,14,3,quark:slate:0)
Block(-8,14,4,quark:slate:0)
Block(-8,14,5,iceandfire:chared_stone:0)
Block(-8,14,6,iceandfire:chared_stone:0)
Block(-8,14,7,iceandfire:chared_stone:0)
Block(-8,14,8,iceandfire:chared_stone:0)
Block(-8,14,9,iceandfire:chared_stone:0)
Block(-8,15,2,STONE:0)
Block(-8,15,3,quark:slate:0)
Block(-8,15,4,quark:slate:0)
Block(-8,15,5,quark:slate:0)
Block(-8,15,6,iceandfire:chared_stone:0)
Block(-8,15,7,iceandfire:chared_stone:0)
Block(-8,16,3,quark:slate:0)
Block(-8,16,4,quark:slate:0)
Block(-8,16,5,quark:slate:0)
Block(-8,16,6,STONE:0)
Block(-7,0,1,iceandfire:chared_stone:0)
Block(-7,0,2,iceandfire:chared_stone:0)
Block(-7,0,3,iceandfire:chared_stone:0)
Block(-7,0,4,STONE:0)
Block(-7,0,5,STONE:0)
Block(-7,1,-1,STONE:0)
Block(-7,1,0,iceandfire:chared_stone:0)
Block(-7,1,1,iceandfire:chared_stone:0)
Block(-7,1,2,iceandfire:chared_stone:0)
Block(-7,1,3,iceandfire:chared_stone:0)
Block(-7,1,4,iceandfire:chared_stone:0)
Block(-7,1,5,iceandfire:chared_stone:0)
Block(-7,1,6,iceandfire:chared_stone:0)
Block(-7,1,7,iceandfire:chared_stone:0)
Block(-7,1,8,STONE:0)
Block(-7,1,9,STONE:0)
Block(-7,1,10,STONE:0)
Block(-7,2,-3,iceandfire:chared_stone:0)
Block(-7,2,-2,iceandfire:chared_stone:0)
Block(-7,2,-1,iceandfire:chared_stone:0)
Block(-7,2,0,iceandfire:chared_stone:0)
Block(-7,2,1,iceandfire:chared_cobblestone:0)
Block(-7,2,2,AIR:0)
Block(-7,2,3,iceandfire:chared_stone:0)
Block(-7,2,4,iceandfire:chared_stone:0)
Block(-7,2,5,iceandfire:chared_stone:0)
Block(-7,2,6,iceandfire:chared_stone:0)
Block(-7,2,7,iceandfire:chared_stone:0)
Block(-7,2,8,iceandfire:chared_stone:0)
Block(-7,2,9,STONE:0)
Block(-7,2,10,STONE:0)
Block(-7,2,11,STONE:0)
Block(-7,3,-4,STONE:0)
Block(-7,3,-3,iceandfire:chared_stone:0)
Block(-7,3,-2,iceandfire:chared_stone:0)
Block(-7,3,-1,iceandfire:chared_stone:0)
Block(-7,3,0,iceandfire:chared_stone:0)
Block(-7,3,1,AIR:0)
Block(-7,3,2,AIR:0)
Block(-7,3,3,biomesoplenty:plant_0:11)
Block(-7,3,4,AIR:0)
Block(-7,3,5,iceandfire:chared_stone:0)
Block(-7,3,6,iceandfire:chared_stone:0)
Block(-7,3,7,iceandfire:chared_stone:0)
Block(-7,3,8,iceandfire:chared_stone:0)
Block(-7,3,9,iceandfire:chared_stone:0)
Block(-7,3,10,iceandfire:chared_stone:0)
Block(-7,3,11,iceandfire:chared_stone:0)
Block(-7,4,-5,STONE:0)
Block(-7,4,-4,STONE:0)
Block(-7,4,-3,iceandfire:chared_stone:0)
Block(-7,4,-2,iceandfire:chared_stone:0)
Block(-7,4,-1,AIR:0)
Block(-7,4,0,BROWN_MUSHROOM:0)
Block(-7,4,1,AIR:0)
Block(-7,4,2,AIR:0)
Block(-7,4,3,AIR:0)
Block(-7,4,4,AIR:0)
Block(-7,4,5,AIR:0)
Block(-7,4,6,quark:stone_speleothem:2)
Block(-7,4,7,AIR:0)
Block(-7,4,8,AIR:0)
Block(-7,4,9,iceandfire:chared_stone:0)
Block(-7,4,10,iceandfire:chared_stone:0)
Block(-7,4,11,iceandfire:chared_stone:0)
Block(-7,5,-5,STONE:0)
Block(-7,5,-4,quark:slate:0)
Block(-7,5,-3,quark:slate:0)
Block(-7,5,-2,AIR:0)
Block(-7,5,-1,AIR:0)
Block(-7,5,0,AIR:0)
Block(-7,5,1,AIR:0)
Block(-7,5,2,AIR:0)
Block(-7,5,3,AIR:0)
Block(-7,5,4,AIR:0)
Block(-7,5,5,AIR:0)
Block(-7,5,6,quark:stone_speleothem:1)
Block(-7,5,7,AIR:0)
Block(-7,5,8,AIR:0)
Block(-7,5,9,iceandfire:chared_stone:0)
Block(-7,5,10,iceandfire:chared_stone:0)
Block(-7,5,11,iceandfire:chared_stone:0)
Block(-7,6,-6,STONE:0)
Block(-7,6,-5,quark:slate:0)
Block(-7,6,-4,quark:slate:0)
Block(-7,6,-3,quark:slate:0)
Block(-7,6,-2,quark:slate:0)
Block(-7,6,-1,quark:stone_speleothem:0)
Block(-7,6,0,AIR:0)
Block(-7,6,1,AIR:0)
Block(-7,6,2,AIR:0)
Block(-7,6,3,AIR:0)
Block(-7,6,4,AIR:0)
Block(-7,6,5,AIR:0)
Block(-7,6,6,quark:stone_speleothem:0)
Block(-7,6,7,AIR:0)
Block(-7,6,8,iceandfire:chared_stone:0)
Block(-7,6,9,iceandfire:chared_stone:0)
Block(-7,6,10,iceandfire:chared_stone:0)
Block(-7,6,11,STONE:0)
Block(-7,7,-7,STONE:0)
Block(-7,7,-6,STONE:0)
Block(-7,7,-5,quark:slate:0)
Block(-7,7,-4,quark:slate:0)
Block(-7,7,-3,quark:slate:0)
Block(-7,7,-2,quark:slate:0)
Block(-7,7,-1,quark:stone_speleothem:1)
Block(-7,7,0,AIR:0)
Block(-7,7,1,AIR:0)
Block(-7,7,2,AIR:0)
Block(-7,7,3,AIR:0)
Block(-7,7,4,AIR:0)
Block(-7,7,5,AIR:0)
Block(-7,7,6,quark:stone_speleothem:0)
Block(-7,7,7,iceandfire:chared_stone:0)
Block(-7,7,8,iceandfire:chared_stone:0)
Block(-7,7,9,iceandfire:chared_stone:0)
Block(-7,7,10,iceandfire:chared_stone:0)
Block(-7,7,11,iceandfire:chared_stone:0)
Block(-7,8,-7,STONE:0)
Block(-7,8,-6,STONE:0)
Block(-7,8,-5,quark:slate:0)
Block(-7,8,-4,quark:slate:0)
Block(-7,8,-3,quark:slate:0)
Block(-7,8,-2,quark:slate:0)
Block(-7,8,-1,quark:stone_speleothem:2)
Block(-7,8,0,AIR:0)
Block(-7,8,1,AIR:0)
Block(-7,8,2,AIR:0)
Block(-7,8,3,AIR:0)
Block(-7,8,4,AIR:0)
Block(-7,8,5,AIR:0)
Block(-7,8,6,quark:stone_speleothem:1)
Block(-7,8,7,AIR:0)
Block(-7,8,8,iceandfire:chared_stone:0)
Block(-7,8,9,iceandfire:chared_stone:0)
Block(-7,8,10,iceandfire:chared_stone:0)
Block(-7,8,11,iceandfire:chared_stone:0)
Block(-7,9,-7,STONE:0)
Block(-7,9,-6,STONE:0)
Block(-7,9,-5,STONE:0)
Block(-7,9,-4,quark:slate:0)
Block(-7,9,-3,quark:slate:0)
Block(-7,9,-2,quark:slate:0)
Block(-7,9,-1,iceandfire:chared_stone:0)
Block(-7,9,0,AIR:0)
Block(-7,9,1,quark:stone_speleothem:0)
Block(-7,9,2,AIR:0)
Block(-7,9,3,AIR:0)
Block(-7,9,4,AIR:0)
Block(-7,9,5,AIR:0)
Block(-7,9,6,quark:stone_speleothem:2)
Block(-7,9,7,iceandfire:chared_stone:0)
Block(-7,9,8,iceandfire:chared_stone:0)
Block(-7,9,9,iceandfire:chared_stone:0)
Block(-7,9,10,iceandfire:chared_stone:0)
Block(-7,9,11,iceandfire:chared_stone:0)
Block(-7,10,-6,STONE:0)
Block(-7,10,-5,STONE:0)
Block(-7,10,-4,STONE:0)
Block(-7,10,-3,STONE:0)
Block(-7,10,-2,iceandfire:chared_stone:0)
Block(-7,10,-1,iceandfire:chared_stone:0)
Block(-7,10,0,AIR:0)
Block(-7,10,1,quark:stone_speleothem:1)
Block(-7,10,2,AIR:0)
Block(-7,10,3,AIR:0)
Block(-7,10,4,AIR:0)
Block(-7,10,5,AIR:0)
Block(-7,10,6,iceandfire:chared_stone:0)
Block(-7,10,7,iceandfire:chared_stone:0)
Block(-7,10,8,iceandfire:chared_stone:0)
Block(-7,10,9,iceandfire:chared_stone:0)
Block(-7,10,10,iceandfire:chared_stone:0)
Block(-7,11,-7,STONE:0)
Block(-7,11,-6,STONE:0)
Block(-7,11,-5,STONE:0)
Block(-7,11,-4,STONE:0)
Block(-7,11,-3,STONE:0)
Block(-7,11,-2,iceandfire:chared_stone:0)
Block(-7,11,-1,iceandfire:chared_stone:0)
Block(-7,11,0,iceandfire:chared_stone:0)
Block(-7,11,1,quark:stone_speleothem:2)
Block(-7,11,2,quark:stone_speleothem:0)
Block(-7,11,3,AIR:0)
Block(-7,11,4,AIR:0)
Block(-7,11,5,quark:stone_speleothem:0)
Block(-7,11,6,iceandfire:chared_stone:0)
Block(-7,11,7,AIR:0)
Block(-7,11,8,iceandfire:chared_stone:0)
Block(-7,11,9,iceandfire:chared_stone:0)
Block(-7,11,10,iceandfire:chared_stone:0)
Block(-7,12,-7,STONE:0)
Block(-7,12,-6,STONE:0)
Block(-7,12,-5,STONE:0)
Block(-7,12,-4,STONE:0)
Block(-7,12,-3,STONE:0)
Block(-7,12,-2,iceandfire:chared_stone:0)
Block(-7,12,-1,iceandfire:chared_stone:0)
Block(-7,12,0,iceandfire:chared_stone:0)
Block(-7,12,1,iceandfire:chared_stone:0)
Block(-7,12,2,quark:stone_speleothem:1)
Block(-7,12,3,AIR:0)
Block(-7,12,4,AIR:0)
Block(-7,12,5,quark:stone_speleothem:1)
Block(-7,12,6,AIR:0)
Block(-7,12,7,AIR:0)
Block(-7,12,8,iceandfire:chared_stone:0)
Block(-7,12,9,iceandfire:chared_stone:0)
Block(-7,12,10,iceandfire:chared_stone:0)
Block(-7,13,-7,STONE:0)
Block(-7,13,-6,STONE:0)
Block(-7,13,-5,STONE:0)
Block(-7,13,-2,STONE:0)
Block(-7,13,-1,iceandfire:chared_stone:0)
Block(-7,13,0,iceandfire:chared_stone:0)
Block(-7,13,1,iceandfire:chared_stone:0)
Block(-7,13,2,quark:stone_speleothem:2)
Block(-7,13,3,AIR:0)
Block(-7,13,4,AIR:0)
Block(-7,13,5,quark:stone_speleothem:2)
Block(-7,13,6,AIR:0)
Block(-7,13,7,iceandfire:chared_stone:0)
Block(-7,13,8,iceandfire:chared_stone:0)
Block(-7,13,9,iceandfire:chared_stone:0)
Block(-7,13,10,STONE:0)
Block(-7,14,-7,STONE:0)
Block(-7,14,-6,STONE:0)
Block(-7,14,-5,STONE:0)
Block(-7,14,0,STONE:0)
Block(-7,14,1,STONE:0)
Block(-7,14,2,quark:slate:0)
Block(-7,14,3,quark:stone_stairs:5)
Block(-7,14,4,AIR:0)
Block(-7,14,5,iceandfire:chared_stone:0)
Block(-7,14,6,iceandfire:chared_stone:0)
Block(-7,14,7,iceandfire:chared_stone:0)
Block(-7,14,8,iceandfire:chared_stone:0)
Block(-7,14,9,iceandfire:chared_stone:0)
Block(-7,14,10,STONE:0)
Block(-7,15,-7,STONE:0)
Block(-7,15,-6,STONE:0)
Block(-7,15,-5,STONE:0)
Block(-7,15,2,quark:slate:0)
Block(-7,15,3,quark:slate:0)
Block(-7,15,4,quark:slate:0)
Block(-7,15,5,quark:slate:0)
Block(-7,15,6,iceandfire:chared_stone:0)
Block(-7,15,7,iceandfire:chared_stone:0)
Block(-7,15,8,iceandfire:chared_stone:0)
Block(-7,15,9,STONE:0)
Block(-7,16,3,quark:slate:0)
Block(-7,16,4,quark:slate:0)
Block(-7,16,5,quark:slate:0)
Block(-7,16,6,quark:slate:0)
Block(-6,0,0,STONE:0)
Block(-6,0,1,iceandfire:chared_stone:0)
Block(-6,0,2,iceandfire:chared_stone:0)
Block(-6,0,3,iceandfire:chared_stone:0)
Block(-6,0,4,STONE:0)
Block(-6,0,5,STONE:0)
Block(-6,0,7,STONE:0)
Block(-6,0,8,STONE:0)
Block(-6,0,9,STONE:0)
Block(-6,1,-1,iceandfire:chared_stone:0)
Block(-6,1,0,iceandfire:chared_stone:0)
Block(-6,1,1,iceandfire:chared_stone:0)
Block(-6,1,2,biomesoplenty:flesh:0)
Block(-6,1,3,iceandfire:chared_stone:0)
Block(-6,1,4,iceandfire:chared_stone:0)
Block(-6,1,5,iceandfire:chared_stone:0)
Block(-6,1,6,iceandfire:chared_stone:0)
Block(-6,1,7,iceandfire:chared_stone:0)
Block(-6,1,8,iceandfire:chared_stone:0)
Block(-6,1,9,iceandfire:chared_stone:0)
Block(-6,1,10,iceandfire:chared_stone:0)
Block(-6,2,-4,iceandfire:chared_stone:0)
Block(-6,2,-3,iceandfire:chared_stone:0)
Block(-6,2,-2,iceandfire:chared_stone:0)
Block(-6,2,-1,iceandfire:chared_stone:0)
Block(-6,2,0,iceandfire:chared_stone:0)
Block(-6,2,1,iceandfire:chared_cobblestone:0)
Block(-6,2,2,AIR:0)
Block(-6,2,3,BROWN_MUSHROOM:0)
Block(-6,2,4,iceandfire:chared_stone:0)
Block(-6,2,5,iceandfire:chared_stone:0)
Block(-6,2,6,iceandfire:chared_stone:0)
Block(-6,2,7,iceandfire:chared_stone:0)
Block(-6,2,8,iceandfire:chared_stone:0)
Block(-6,2,9,iceandfire:chared_stone:0)
Block(-6,2,10,iceandfire:chared_stone:0)
Block(-6,2,11,iceandfire:chared_stone:0)
Block(-6,3,-5,STONE:0)
Block(-6,3,-4,iceandfire:chared_stone:0)
Block(-6,3,-3,iceandfire:chared_stone:0)
Block(-6,3,-2,iceandfire:chared_cobblestone:0)
Block(-6,3,-1,AIR:0)
Block(-6,3,0,AIR:0)
Block(-6,3,1,AIR:0)
Block(-6,3,2,AIR:0)
Block(-6,3,3,AIR:0)
Block(-6,3,4,biomesoplenty:plant_0:11)
Block(-6,3,5,AIR:0)
Block(-6,3,6,AIR:0)
Block(-6,3,7,iceandfire:chared_stone:0)
Block(-6,3,8,iceandfire:chared_stone:0)
Block(-6,3,9,iceandfire:chared_stone:0)
Block(-6,3,10,iceandfire:chared_stone:0)
Block(-6,3,11,iceandfire:chared_stone:0)
Block(-6,3,12,iceandfire:chared_stone:0)
Block(-6,4,-6,STONE:0)
Block(-6,4,-5,STONE:0)
Block(-6,4,-4,iceandfire:chared_stone:0)
Block(-6,4,-3,iceandfire:chared_stone:0)
Block(-6,4,-2,AIR:0)
Block(-6,4,-1,AIR:0)
Block(-6,4,0,AIR:0)
Block(-6,4,1,AIR:0)
Block(-6,4,2,AIR:0)
Block(-6,4,3,AIR:0)
Block(-6,4,4,AIR:0)
Block(-6,4,5,AIR:0)
Block(-6,4,6,AIR:0)
Block(-6,4,7,AIR:0)
Block(-6,4,8,AIR:0)
Block(-6,4,9,iceandfire:chared_stone:0)
Block(-6,4,10,iceandfire:chared_stone:0)
Block(-6,4,11,iceandfire:chared_stone:0)
Block(-6,4,12,iceandfire:chared_stone:0)
Block(-6,5,-6,STONE:0)
Block(-6,5,-5,STONE:0)
Block(-6,5,-4,quark:slate:0)
Block(-6,5,-3,quark:stone_speleothem:2)
Block(-6,5,-2,AIR:0)
Block(-6,5,-1,AIR:0)
Block(-6,5,0,AIR:0)
Block(-6,5,1,AIR:0)
Block(-6,5,2,AIR:0)
Block(-6,5,3,AIR:0)
Block(-6,5,4,AIR:0)
Block(-6,5,5,AIR:0)
Block(-6,5,6,AIR:0)
Block(-6,5,7,AIR:0)
Block(-6,5,8,AIR:0)
Block(-6,5,9,iceandfire:chared_stone:0)
Block(-6,5,10,iceandfire:chared_stone:0)
Block(-6,5,11,iceandfire:chared_stone:0)
Block(-6,5,12,iceandfire:chared_stone:0)
Block(-6,6,-8,STONE:0)
Block(-6,6,-7,STONE:0)
Block(-6,6,-6,STONE:0)
Block(-6,6,-5,quark:slate:0)
Block(-6,6,-4,quark:slate:0)
Block(-6,6,-3,quark:stone_speleothem:1)
Block(-6,6,-2,AIR:0)
Block(-6,6,-1,AIR:0)
Block(-6,6,0,AIR:0)
Block(-6,6,1,AIR:0)
Block(-6,6,2,AIR:0)
Block(-6,6,3,AIR:0)
Block(-6,6,4,AIR:0)
Block(-6,6,5,AIR:0)
Block(-6,6,6,AIR:0)
Block(-6,6,7,AIR:0)
Block(-6,6,8,AIR:0)
Block(-6,6,9,AIR:0)
Block(-6,6,10,iceandfire:chared_stone:0)
Block(-6,6,11,iceandfire:chared_stone:0)
Block(-6,6,12,iceandfire:chared_stone:0)
Block(-6,7,-8,STONE:0)
Block(-6,7,-7,STONE:0)
Block(-6,7,-6,STONE:0)
Block(-6,7,-5,quark:slate:0)
Block(-6,7,-4,quark:slate:0)
Block(-6,7,-3,quark:stone_speleothem:0)
Block(-6,7,-2,AIR:0)
Block(-6,7,-1,AIR:0)
Block(-6,7,0,AIR:0)
Block(-6,7,1,AIR:0)
Block(-6,7,2,AIR:0)
Block(-6,7,3,AIR:0)
Block(-6,7,4,AIR:0)
Block(-6,7,5,AIR:0)
Block(-6,7,6,AIR:0)
Block(-6,7,7,AIR:0)
Block(-6,7,8,AIR:0)
Block(-6,7,9,AIR:0)
Block(-6,7,10,iceandfire:chared_stone:0)
Block(-6,7,11,iceandfire:chared_stone:0)
Block(-6,7,12,STONE:0)
Block(-6,8,-8,STONE:0)
Block(-6,8,-7,STONE:0)
Block(-6,8,-6,STONE:0)
Block(-6,8,-5,quark:slate:0)
Block(-6,8,-4,quark:slate:0)
Block(-6,8,-3,AIR:0)
Block(-6,8,-2,AIR:0)
Block(-6,8,-1,AIR:0)
Block(-6,8,0,AIR:0)
Block(-6,8,1,AIR:0)
Block(-6,8,2,AIR:0)
Block(-6,8,3,AIR:0)
Block(-6,8,4,AIR:0)
Block(-6,8,5,AIR:0)
Block(-6,8,6,AIR:0)
Block(-6,8,7,AIR:0)
Block(-6,8,8,AIR:0)
Block(-6,8,9,AIR:0)
Block(-6,8,10,iceandfire:chared_cobblestone:0)
Block(-6,8,11,iceandfire:chared_stone:0)
Block(-6,8,12,STONE:0)
Block(-6,9,-9,STONE:0)
Block(-6,9,-8,STONE:0)
Block(-6,9,-7,STONE:0)
Block(-6,9,-6,STONE:0)
Block(-6,9,-5,STONE:0)
Block(-6,9,-4,quark:slate:0)
Block(-6,9,-3,quark:slate:0)
Block(-6,9,-2,AIR:0)
Block(-6,9,-1,AIR:0)
Block(-6,9,0,AIR:0)
Block(-6,9,1,AIR:0)
Block(-6,9,2,AIR:0)
Block(-6,9,3,AIR:0)
Block(-6,9,4,AIR:0)
Block(-6,9,5,AIR:0)
Block(-6,9,6,AIR:0)
Block(-6,9,7,AIR:0)
Block(-6,9,8,AIR:0)
Block(-6,9,9,quark:stone_speleothem:0)
Block(-6,9,10,iceandfire:chared_stone:0)
Block(-6,9,11,iceandfire:chared_stone:0)
Block(-6,9,12,iceandfire:chared_stone:0)
Block(-6,10,-9,STONE:0)
Block(-6,10,-8,STONE:0)
Block(-6,10,-7,STONE:0)
Block(-6,10,-6,STONE:0)
Block(-6,10,-5,STONE:0)
Block(-6,10,-4,STONE:0)
Block(-6,10,-3,STONE:0)
Block(-6,10,-2,AIR:0)
Block(-6,10,-1,AIR:0)
Block(-6,10,0,AIR:0)
Block(-6,10,1,AIR:0)
Block(-6,10,2,AIR:0)
Block(-6,10,3,AIR:0)
Block(-6,10,4,AIR:0)
Block(-6,10,5,AIR:0)
Block(-6,10,6,AIR:0)
Block(-6,10,7,AIR:0)
Block(-6,10,8,AIR:0)
Block(-6,10,9,quark:stone_speleothem:1)
Block(-6,10,10,iceandfire:chared_stone:0)
Block(-6,10,11,iceandfire:chared_stone:0)
Block(-6,11,-10,STONE:0)
Block(-6,11,-9,STONE:0)
Block(-6,11,-8,STONE:0)
Block(-6,11,-7,quark:slate:0)
Block(-6,11,-6,quark:slate:0)
Block(-6,11,-5,quark:slate:0)
Block(-6,11,-4,STONE:0)
Block(-6,11,-3,STONE:0)
Block(-6,11,-2,iceandfire:chared_stone:0)
Block(-6,11,-1,AIR:0)
Block(-6,11,0,quark:stone_speleothem:0)
Block(-6,11,1,AIR:0)
Block(-6,11,2,AIR:0)
Block(-6,11,3,AIR:0)
Block(-6,11,4,AIR:0)
Block(-6,11,5,AIR:0)
Block(-6,11,6,AIR:0)
Block(-6,11,7,AIR:0)
Block(-6,11,8,AIR:0)
Block(-6,11,9,quark:stone_speleothem:2)
Block(-6,11,10,iceandfire:chared_stone:0)
Block(-6,12,-10,STONE:0)
Block(-6,12,-9,STONE:0)
Block(-6,12,-8,STONE:0)
Block(-6,12,-7,quark:slate:0)
Block(-6,12,-6,quark:slate:0)
Block(-6,12,-5,quark:slate:0)
Block(-6,12,-4,STONE:0)
Block(-6,12,-3,STONE:0)
Block(-6,12,-2,iceandfire:chared_stone:0)
Block(-6,12,-1,iceandfire:chared_stone:0)
Block(-6,12,0,quark:stone_speleothem:1)
Block(-6,12,1,AIR:0)
Block(-6,12,2,AIR:0)
Block(-6,12,3,AIR:0)
Block(-6,12,4,AIR:0)
Block(-6,12,5,AIR:0)
Block(-6,12,6,AIR:0)
Block(-6,12,7,AIR:0)
Block(-6,12,8,AIR:0)
Block(-6,12,9,iceandfire:chared_stone:0)
Block(-6,12,10,iceandfire:chared_stone:0)
Block(-6,13,-10,STONE:0)
Block(-6,13,-9,STONE:0)
Block(-6,13,-8,STONE:0)
Block(-6,13,-7,quark:slate:0)
Block(-6,13,-6,quark:slate:0)
Block(-6,13,-5,quark:slate:0)
Block(-6,13,-4,STONE:0)
Block(-6,13,-3,STONE:0)
Block(-6,13,-2,STONE:0)
Block(-6,13,-1,iceandfire:chared_stone:0)
Block(-6,13,0,quark:stone_speleothem:2)
Block(-6,13,1,AIR:0)
Block(-6,13,2,AIR:0)
Block(-6,13,3,AIR:0)
Block(-6,13,4,AIR:0)
Block(-6,13,5,AIR:0)
Block(-6,13,6,AIR:0)
Block(-6,13,7,AIR:0)
Block(-6,13,8,iceandfire:chared_stone:0)
Block(-6,13,9,iceandfire:chared_stone:0)
Block(-6,13,10,STONE:0)
Block(-6,14,-10,STONE:0)
Block(-6,14,-9,STONE:0)
Block(-6,14,-8,STONE:0)
Block(-6,14,-7,STONE:0)
Block(-6,14,-6,STONE:0)
Block(-6,14,-5,STONE:0)
Block(-6,14,-4,STONE:0)
Block(-6,14,-3,STONE:0)
Block(-6,14,-2,STONE:0)
Block(-6,14,-1,STONE:0)
Block(-6,14,0,STONE:0)
Block(-6,14,1,quark:stone_stairs:7)
Block(-6,14,2,AIR:0)
Block(-6,14,3,AIR:0)
Block(-6,14,4,AIR:0)
Block(-6,14,5,AIR:0)
Block(-6,14,6,AIR:0)
Block(-6,14,7,iceandfire:chared_stone:0)
Block(-6,14,8,iceandfire:chared_stone:0)
Block(-6,14,9,iceandfire:chared_stone:0)
Block(-6,14,10,STONE:0)
Block(-6,15,-10,STONE:0)
Block(-6,15,-9,STONE:0)
Block(-6,15,-8,STONE:0)
Block(-6,15,-7,STONE:0)
Block(-6,15,-6,STONE:0)
Block(-6,15,-5,STONE:0)
Block(-6,15,-4,STONE:0)
Block(-6,15,-3,STONE:0)
Block(-6,15,-2,STONE:0)
Block(-6,15,0,quark:slate:0)
Block(-6,15,1,quark:slate:0)
Block(-6,15,2,quark:slate:0)
Block(-6,15,3,quark:slate:0)
Block(-6,15,4,quark:slate:0)
Block(-6,15,5,quark:slate:0)
Block(-6,15,6,iceandfire:chared_stone:0)
Block(-6,15,7,iceandfire:chared_stone:0)
Block(-6,15,8,iceandfire:chared_stone:0)
Block(-6,15,9,STONE:0)
Block(-6,16,-10,STONE:0)
Block(-6,16,-9,STONE:0)
Block(-6,16,-8,STONE:0)
Block(-6,16,-7,STONE:0)
Block(-6,16,-6,STONE:0)
Block(-6,16,-5,STONE:0)
Block(-6,16,-4,STONE:0)
Block(-6,16,-3,STONE:0)
Block(-6,16,-2,STONE:0)
Block(-6,16,0,quark:slate:0)
Block(-6,16,1,quark:slate:0)
Block(-6,16,2,quark:slate:0)
Block(-6,16,4,quark:slate:0)
Block(-6,16,5,quark:slate:0)
Block(-6,16,6,quark:slate:0)
Block(-6,17,0,quark:slate:0)
Block(-6,17,1,quark:slate:0)
Block(-6,17,2,STONE:0)
Block(-5,0,0,iceandfire:chared_stone:0)
Block(-5,0,1,iceandfire:chared_stone:0)
Block(-5,0,2,iceandfire:chared_stone:0)
Block(-5,0,3,iceandfire:chared_stone:0)
Block(-5,0,4,STONE:0)
Block(-5,0,5,STONE:0)
Block(-5,0,6,STONE:0)
Block(-5,0,7,STONE:0)
Block(-5,0,8,iceandfire:chared_stone:0)
Block(-5,0,9,iceandfire:chared_stone:0)
Block(-5,0,10,iceandfire:chared_stone:0)
Block(-5,1,-1,iceandfire:chared_stone:0)
Block(-5,1,0,iceandfire:chared_stone:0)
Block(-5,1,1,iceandfire:chared_stone:0)
Block(-5,1,2,iceandfire:chared_stone:0)
Block(-5,1,3,biomesoplenty:flesh:0)
Block(-5,1,4,charm:rotten_flesh_block:0)
Block(-5,1,5,iceandfire:chared_stone:0)
Block(-5,1,6,iceandfire:chared_stone:0)
Block(-5,1,7,iceandfire:chared_stone:0)
Block(-5,1,8,iceandfire:chared_stone:0)
Block(-5,1,9,iceandfire:chared_stone:0)
Block(-5,1,10,iceandfire:chared_stone:0)
Block(-5,1,11,iceandfire:chared_stone:0)
Block(-5,2,-4,iceandfire:chared_stone:0)
Block(-5,2,-3,iceandfire:chared_stone:0)
Block(-5,2,-2,iceandfire:chared_stone:0)
Block(-5,2,-1,iceandfire:chared_stone:0)
Block(-5,2,0,iceandfire:chared_stone:0)
Block(-5,2,1,iceandfire:chared_stone:0)
Block(-5,2,2,BROWN_MUSHROOM:0)
Block(-5,2,3,AIR:0)
Block(-5,2,4,AIR:0)
Block(-5,2,5,AIR:0)
Block(-5,2,6,AIR:0)
Block(-5,2,7,iceandfire:chared_stone:0)
Block(-5,2,8,iceandfire:chared_stone:0)
Block(-5,2,9,iceandfire:chared_stone:0)
Block(-5,2,10,iceandfire:chared_stone:0)
Block(-5,2,11,iceandfire:chared_stone:0)
Block(-5,3,-5,STONE:0)
Block(-5,3,-4,iceandfire:chared_stone:0)
Block(-5,3,-3,iceandfire:chared_stone:0)
Block(-5,3,-2,biomesoplenty:plant_0:11)
Block(-5,3,-1,AIR:0)
Block(-5,3,0,AIR:0)
Block(-5,3,1,BROWN_MUSHROOM:0)
Block(-5,3,2,AIR:0)
Block(-5,3,3,AIR:0)
Block(-5,3,4,AIR:0)
Block(-5,3,5,AIR:0)
Block(-5,3,6,AIR:0)
Block(-5,3,7,AIR:0)
Block(-5,3,8,AIR:0)
Block(-5,3,9,iceandfire:chared_cobblestone:0)
Block(-5,3,10,iceandfire:chared_stone:0)
Block(-5,3,11,iceandfire:chared_stone:0)
Block(-5,3,12,iceandfire:chared_stone:0)
Block(-5,4,-6,STONE:0)
Block(-5,4,-5,STONE:0)
Block(-5,4,-4,iceandfire:chared_stone:0)
Block(-5,4,-3,quark:stone_speleothem:2)
Block(-5,4,-2,AIR:0)
Block(-5,4,-1,AIR:0)
Block(-5,4,0,AIR:0)
Block(-5,4,1,AIR:0)
Block(-5,4,2,AIR:0)
Block(-5,4,3,AIR:0)
Block(-5,4,4,AIR:0)
Block(-5,4,5,AIR:0)
Block(-5,4,6,AIR:0)
Block(-5,4,7,AIR:0)
Block(-5,4,8,AIR:0)
Block(-5,4,9,rustic:mooncap_mushroom:0)
Block(-5,4,10,iceandfire:chared_stone:0)
Block(-5,4,11,iceandfire:chared_stone:0)
Block(-5,4,12,iceandfire:chared_stone:0)
Block(-5,4,13,iceandfire:chared_stone:0)
Block(-5,5,-8,STONE:0)
Block(-5,5,-7,STONE:0)
Block(-5,5,-6,STONE:0)
Block(-5,5,-5,STONE:0)
Block(-5,5,-4,quark:slate:0)
Block(-5,5,-3,quark:stone_speleothem:1)
Block(-5,5,-2,AIR:0)
Block(-5,5,-1,AIR:0)
Block(-5,5,0,AIR:0)
Block(-5,5,1,AIR:0)
Block(-5,5,2,AIR:0)
Block(-5,5,3,AIR:0)
Block(-5,5,4,AIR:0)
Block(-5,5,5,AIR:0)
Block(-5,5,6,AIR:0)
Block(-5,5,7,AIR:0)
Block(-5,5,8,AIR:0)
Block(-5,5,9,AIR:0)
Block(-5,5,10,iceandfire:chared_stone:0)
Block(-5,5,11,iceandfire:chared_stone:0)
Block(-5,5,12,iceandfire:chared_stone:0)
Block(-5,5,13,iceandfire:chared_stone:0)
Block(-5,6,-9,STONE:0)
Block(-5,6,-8,STONE:0)
Block(-5,6,-7,STONE:0)
Block(-5,6,-6,STONE:0)
Block(-5,6,-5,quark:slate:0)
Block(-5,6,-4,quark:slate:0)
Block(-5,6,-3,quark:stone_speleothem:0)
Block(-5,6,-2,AIR:0)
Block(-5,6,-1,AIR:0)
Block(-5,6,0,AIR:0)
Block(-5,6,1,AIR:0)
Block(-5,6,2,AIR:0)
Block(-5,6,3,AIR:0)
Block(-5,6,4,AIR:0)
Block(-5,6,5,AIR:0)
Block(-5,6,6,AIR:0)
Block(-5,6,7,AIR:0)
Block(-5,6,8,AIR:0)
Block(-5,6,9,AIR:0)
Block(-5,6,10,iceandfire:chared_stone:0)
Block(-5,6,11,iceandfire:chared_stone:0)
Block(-5,6,12,iceandfire:chared_stone:0)
Block(-5,6,13,iceandfire:chared_stone:0)
Block(-5,7,-10,STONE:0)
Block(-5,7,-9,STONE:0)
Block(-5,7,-8,STONE:0)
Block(-5,7,-7,STONE:0)
Block(-5,7,-6,STONE:0)
Block(-5,7,-5,quark:stone_speleothem:2)
Block(-5,7,-4,quark:slate:0)
Block(-5,7,-3,AIR:0)
Block(-5,7,-2,AIR:0)
Block(-5,7,-1,AIR:0)
Block(-5,7,0,AIR:0)
Block(-5,7,1,AIR:0)
Block(-5,7,2,AIR:0)
Block(-5,7,3,AIR:0)
Block(-5,7,4,AIR:0)
Block(-5,7,5,AIR:0)
Block(-5,7,6,AIR:0)
Block(-5,7,7,AIR:0)
Block(-5,7,8,AIR:0)
Block(-5,7,9,AIR:0)
Block(-5,7,10,AIR:0)
Block(-5,7,11,iceandfire:chared_stone:0)
Block(-5,7,12,iceandfire:chared_stone:0)
Block(-5,7,13,STONE:0)
Block(-5,8,-10,STONE:0)
Block(-5,8,-9,STONE:0)
Block(-5,8,-8,STONE:0)
Block(-5,8,-7,STONE:0)
Block(-5,8,-6,STONE:0)
Block(-5,8,-5,quark:stone_speleothem:1)
Block(-5,8,-4,quark:stone_speleothem:2)
Block(-5,8,-3,AIR:0)
Block(-5,8,-2,AIR:0)
Block(-5,8,-1,AIR:0)
Block(-5,8,0,AIR:0)
Block(-5,8,1,AIR:0)
Block(-5,8,2,AIR:0)
Block(-5,8,3,AIR:0)
Block(-5,8,4,AIR:0)
Block(-5,8,5,AIR:0)
Block(-5,8,6,AIR:0)
Block(-5,8,7,AIR:0)
Block(-5,8,8,AIR:0)
Block(-5,8,9,AIR:0)
Block(-5,8,10,quark:stone_speleothem:1)
Block(-5,8,11,iceandfire:chared_stone:0)
Block(-5,8,12,iceandfire:chared_stone:0)
Block(-5,8,13,STONE:0)
Block(-5,9,-10,STONE:0)
Block(-5,9,-9,STONE:0)
Block(-5,9,-8,STONE:0)
Block(-5,9,-7,STONE:0)
Block(-5,9,-6,quark:stone_speleothem:2)
Block(-5,9,-5,quark:stone_speleothem:0)
Block(-5,9,-4,quark:stone_speleothem:1)
Block(-5,9,-3,AIR:0)
Block(-5,9,-2,AIR:0)
Block(-5,9,-1,AIR:0)
Block(-5,9,0,AIR:0)
Block(-5,9,1,AIR:0)
Block(-5,9,2,AIR:0)
Block(-5,9,3,AIR:0)
Block(-5,9,4,AIR:0)
Block(-5,9,5,AIR:0)
Block(-5,9,6,AIR:0)
Block(-5,9,7,AIR:0)
Block(-5,9,8,AIR:0)
Block(-5,9,9,AIR:0)
Block(-5,9,10,quark:stone_speleothem:2)
Block(-5,9,11,iceandfire:chared_stone:0)
Block(-5,9,12,iceandfire:chared_stone:0)
Block(-5,9,13,iceandfire:chared_stone:0)
Block(-5,10,-10,STONE:0)
Block(-5,10,-9,STONE:0)
Block(-5,10,-8,STONE:0)
Block(-5,10,-7,quark:slate:0)
Block(-5,10,-6,quark:stone_speleothem:2)
Block(-5,10,-5,AIR:0)
Block(-5,10,-4,quark:stone_speleothem:1)
Block(-5,10,-3,AIR:0)
Block(-5,10,-2,AIR:0)
Block(-5,10,-1,AIR:0)
Block(-5,10,0,AIR:0)
Block(-5,10,1,AIR:0)
Block(-5,10,2,AIR:0)
Block(-5,10,3,AIR:0)
Block(-5,10,4,AIR:0)
Block(-5,10,5,AIR:0)
Block(-5,10,6,AIR:0)
Block(-5,10,7,AIR:0)
Block(-5,10,8,AIR:0)
Block(-5,10,9,AIR:0)
Block(-5,10,10,iceandfire:chared_stone:0)
Block(-5,10,11,iceandfire:chared_stone:0)
Block(-5,10,12,iceandfire:chared_stone:0)
Block(-5,11,-11,STONE:0)
Block(-5,11,-10,STONE:0)
Block(-5,11,-9,STONE:0)
Block(-5,11,-8,quark:slate:0)
Block(-5,11,-7,quark:slate:0)
Block(-5,11,-6,quark:slate:0)
Block(-5,11,-5,AIR:0)
Block(-5,11,-4,quark:stone_speleothem:2)
Block(-5,11,-3,quark:stone_speleothem:0)
Block(-5,11,-2,AIR:0)
Block(-5,11,-1,AIR:0)
Block(-5,11,0,AIR:0)
Block(-5,11,1,AIR:0)
Block(-5,11,2,AIR:0)
Block(-5,11,3,AIR:0)
Block(-5,11,4,AIR:0)
Block(-5,11,5,AIR:0)
Block(-5,11,6,AIR:0)
Block(-5,11,7,AIR:0)
Block(-5,11,8,AIR:0)
Block(-5,11,9,AIR:0)
Block(-5,11,10,iceandfire:chared_cobblestone:0)
Block(-5,11,11,iceandfire:chared_stone:0)
Block(-5,12,-11,STONE:0)
Block(-5,12,-10,iceandfire:frozen_stone:0)
Block(-5,12,-9,iceandfire:frozen_stone:0)
Block(-5,12,-8,iceandfire:frozen_stone:0)
Block(-5,12,-7,quark:slate:0)
Block(-5,12,-6,quark:slate:0)
Block(-5,12,-5,AIR:0)
Block(-5,12,-4,quark:slate:0)
Block(-5,12,-3,quark:stone_speleothem:1)
Block(-5,12,-2,AIR:0)
Block(-5,12,-1,quark:stone_speleothem:0)
Block(-5,12,0,AIR:0)
Block(-5,12,1,AIR:0)
Block(-5,12,2,AIR:0)
Block(-5,12,3,AIR:0)
Block(-5,12,4,quark:stone_speleothem:0)
Block(-5,12,5,AIR:0)
Block(-5,12,6,AIR:0)
Block(-5,12,7,AIR:0)
Block(-5,12,8,AIR:0)
Block(-5,12,9,AIR:0)
Block(-5,12,10,iceandfire:chared_stone:0)
Block(-5,12,11,iceandfire:chared_stone:0)
Block(-5,13,-11,STONE:0)
Block(-5,13,-10,iceandfire:frozen_stone:0)
Block(-5,13,-9,iceandfire:frozen_stone:0)
Block(-5,13,-8,iceandfire:frozen_stone:0)
Block(-5,13,-7,quark:slate:0)
Block(-5,13,-6,quark:slate:0)
Block(-5,13,-5,quark:slate:0)
Block(-5,13,-4,quark:slate:0)
Block(-5,13,-3,quark:stone_speleothem:2)
Block(-5,13,-2,AIR:0)
Block(-5,13,-1,quark:stone_speleothem:1)
Block(-5,13,0,AIR:0)
Block(-5,13,1,AIR:0)
Block(-5,13,2,quark:stone_speleothem:0)
Block(-5,13,3,AIR:0)
Block(-5,13,4,quark:stone_speleothem:1)
Block(-5,13,5,AIR:0)
Block(-5,13,6,AIR:0)
Block(-5,13,7,AIR:0)
Block(-5,13,8,AIR:0)
Block(-5,13,9,STONE:0)
Block(-5,13,10,STONE:0)
Block(-5,13,11,STONE:0)
Block(-5,14,-11,STONE:0)
Block(-5,14,-10,iceandfire:frozen_stone:0)
Block(-5,14,-9,iceandfire:frozen_stone:0)
Block(-5,14,-8,iceandfire:frozen_stone:0)
Block(-5,14,-7,quark:slate:0)
Block(-5,14,-6,quark:slate:0)
Block(-5,14,-5,quark:slate:0)
Block(-5,14,-4,STONE:0)
Block(-5,14,-3,STONE:0)
Block(-5,14,-2,STONE:0)
Block(-5,14,-1,quark:stone_speleothem:2)
Block(-5,14,0,AIR:0)
Block(-5,14,1,AIR:0)
Block(-5,14,2,quark:stone_speleothem:1)
Block(-5,14,3,AIR:0)
Block(-5,14,4,quark:stone_speleothem:2)
Block(-5,14,5,AIR:0)
Block(-5,14,6,AIR:0)
Block(-5,14,7,iceandfire:chared_stone:0)
Block(-5,14,8,iceandfire:chared_stone:0)
Block(-5,14,9,STONE:0)
Block(-5,14,10,STONE:0)
Block(-5,14,11,STONE:0)
Block(-5,15,-11,STONE:0)
Block(-5,15,-10,STONE:0)
Block(-5,15,-9,STONE:0)
Block(-5,15,-8,STONE:0)
Block(-5,15,-7,STONE:0)
Block(-5,15,-6,STONE:0)
Block(-5,15,-5,STONE:0)
Block(-5,15,-4,STONE:0)
Block(-5,15,-3,STONE:0)
Block(-5,15,-2,quark:slate:0)
Block(-5,15,-1,quark:slate:0)
Block(-5,15,0,quark:slate:0)
Block(-5,15,1,AIR:0)
Block(-5,15,2,quark:stone_speleothem:2)
Block(-5,15,3,AIR:0)
Block(-5,15,4,quark:slate:0)
Block(-5,15,5,quark:slate:0)
Block(-5,15,6,quark:slate:0)
Block(-5,15,7,STONE:0)
Block(-5,15,8,STONE:0)
Block(-5,15,9,STONE:0)
Block(-5,16,-11,STONE:0)
Block(-5,16,-10,STONE:0)
Block(-5,16,-9,STONE:0)
Block(-5,16,-8,STONE:0)
Block(-5,16,-7,STONE:0)
Block(-5,16,-6,STONE:0)
Block(-5,16,-5,STONE:0)
Block(-5,16,-4,STONE:0)
Block(-5,16,-3,STONE:0)
Block(-5,16,-2,quark:slate:0)
Block(-5,16,-1,quark:slate:0)
Block(-5,16,0,quark:slate:0)
Block(-5,16,1,quark:slate:0)
Block(-5,16,2,quark:slate:0)
Block(-5,16,3,quark:slate:0)
Block(-5,16,4,quark:slate:0)
Block(-5,16,5,quark:slate:0)
Block(-5,16,6,quark:slate:0)
Block(-5,16,7,STONE:0)
Block(-5,17,-10,STONE:0)
Block(-5,17,-9,STONE:0)
Block(-5,17,-8,STONE:0)
Block(-5,17,-4,STONE:0)
Block(-5,17,-3,STONE:0)
Block(-5,17,-2,quark:slate:0)
Block(-5,17,-1,quark:slate:0)
Block(-5,17,0,quark:slate:0)
Block(-5,17,1,quark:slate:0)
Block(-5,17,2,quark:slate:0)
Block(-5,17,3,quark:slate:0)
Block(-5,17,4,quark:slate:0)
Block(-5,17,5,quark:slate:0)
Block(-5,17,6,STONE:0)
Block(-5,18,0,quark:slate:0)
Block(-5,18,1,quark:slate:0)
Block(-5,18,2,STONE:0)
Block(-4,0,-1,STONE:0)
Block(-4,0,0,iceandfire:chared_stone:0)
Block(-4,0,1,iceandfire:chared_stone:0)
Block(-4,0,2,iceandfire:chared_stone:0)
Block(-4,0,3,STONE:0)
Block(-4,0,4,STONE:0)
Block(-4,0,5,STONE:0)
Block(-4,0,6,STONE:0)
Block(-4,0,7,STONE:0)
Block(-4,0,8,iceandfire:chared_stone:0)
Block(-4,0,9,iceandfire:chared_stone:0)
Block(-4,0,10,iceandfire:chared_stone:0)
Block(-4,1,-1,iceandfire:chared_stone:0)
Block(-4,1,0,biomesoplenty:flesh:0)
Block(-4,1,1,biomesoplenty:flesh:0)
Block(-4,1,2,BONE_BLOCK:0)
Block(-4,1,3,charm:rotten_flesh_block:0)
Block(-4,1,4,BONE_BLOCK:0)
Block(-4,1,5,betternether:bone_stairs:0)
Block(-4,1,6,STONE:0)
Block(-4,1,7,iceandfire:chared_stone:0)
Block(-4,1,8,iceandfire:chared_stone:0)
Block(-4,1,9,iceandfire:chared_stone:0)
Block(-4,1,10,iceandfire:chared_stone:0)
Block(-4,1,11,iceandfire:chared_stone:0)
Block(-4,2,-4,iceandfire:chared_stone:0)
Block(-4,2,-3,iceandfire:chared_stone:0)
Block(-4,2,-2,iceandfire:chared_stone:0)
Block(-4,2,-1,iceandfire:chared_stone:0)
Block(-4,2,0,rustic:mooncap_mushroom:0)
Block(-4,2,1,rustic:mooncap_mushroom:0)
Block(-4,2,2,AIR:0)
Block(-4,2,3,AIR:0)
Block(-4,2,4,contenttweaker:bone_pile:0)
Block(-4,2,5,AIR:0)
Block(-4,2,6,quark:stone_speleothem:2)
Block(-4,2,7,rustic:mooncap_mushroom:0)
Block(-4,2,8,biomesoplenty:flesh:0)
Block(-4,2,9,iceandfire:chared_stone:0)
Block(-4,2,10,iceandfire:chared_stone:0)
Block(-4,2,11,iceandfire:chared_stone:0)
Block(-4,3,-5,STONE:0)
Block(-4,3,-4,iceandfire:chared_stone:0)
Block(-4,3,-3,AIR:0)
Block(-4,3,-2,BROWN_MUSHROOM:0)
Block(-4,3,-1,AIR:0)
Block(-4,3,0,AIR:0)
Block(-4,3,1,AIR:0)
Block(-4,3,2,AIR:0)
Block(-4,3,3,AIR:0)
Block(-4,3,4,AIR:0)
Block(-4,3,5,AIR:0)
Block(-4,3,6,quark:stone_speleothem:1)
Block(-4,3,7,AIR:0)
Block(-4,3,8,AIR:0)
Block(-4,3,9,charm:rotten_flesh_block:0)
Block(-4,3,10,iceandfire:chared_stone:0)
Block(-4,3,11,iceandfire:chared_stone:0)
Block(-4,3,12,iceandfire:chared_stone:0)
Block(-4,4,-6,quark:slate:0)
Block(-4,4,-5,quark:slate:0)
Block(-4,4,-4,AIR:0)
Block(-4,4,-3,AIR:0)
Block(-4,4,-2,AIR:0)
Block(-4,4,-1,AIR:0)
Block(-4,4,0,AIR:0)
Block(-4,4,1,AIR:0)
Block(-4,4,2,AIR:0)
Block(-4,4,3,AIR:0)
Block(-4,4,4,AIR:0)
Block(-4,4,5,AIR:0)
Block(-4,4,6,quark:stone_speleothem:0)
Block(-4,4,7,AIR:0)
Block(-4,4,8,AIR:0)
Block(-4,4,9,AIR:0)
Block(-4,4,10,biomesoplenty:flesh:0)
Block(-4,4,11,iceandfire:chared_stone:0)
Block(-4,4,12,iceandfire:chared_stone:0)
Block(-4,4,13,iceandfire:chared_stone:0)
Block(-4,5,-8,STONE:0)
Block(-4,5,-7,quark:slate:0)
Block(-4,5,-6,quark:slate:0)
Block(-4,5,-5,AIR:0)
Block(-4,5,-4,AIR:0)
Block(-4,5,-3,AIR:0)
Block(-4,5,-2,AIR:0)
Block(-4,5,-1,AIR:0)
Block(-4,5,0,AIR:0)
Block(-4,5,1,AIR:0)
Block(-4,5,2,AIR:0)
Block(-4,5,3,AIR:0)
Block(-4,5,4,AIR:0)
Block(-4,5,5,AIR:0)
Block(-4,5,6,AIR:0)
Block(-4,5,7,AIR:0)
Block(-4,5,8,AIR:0)
Block(-4,5,9,AIR:0)
Block(-4,5,10,rustic:mooncap_mushroom:0)
Block(-4,5,11,iceandfire:chared_stone:0)
Block(-4,5,12,iceandfire:chared_stone:0)
Block(-4,5,13,iceandfire:chared_stone:0)
Block(-4,6,-10,STONE:0)
Block(-4,6,-9,STONE:0)
Block(-4,6,-8,STONE:0)
Block(-4,6,-7,quark:slate:0)
Block(-4,6,-6,quark:stone_stairs:3)
Block(-4,6,-5,AIR:0)
Block(-4,6,-4,AIR:0)
Block(-4,6,-3,AIR:0)
Block(-4,6,-2,AIR:0)
Block(-4,6,-1,AIR:0)
Block(-4,6,0,AIR:0)
Block(-4,6,1,AIR:0)
Block(-4,6,2,AIR:0)
Block(-4,6,3,AIR:0)
Block(-4,6,4,AIR:0)
Block(-4,6,5,AIR:0)
Block(-4,6,6,AIR:0)
Block(-4,6,7,AIR:0)
Block(-4,6,8,AIR:0)
Block(-4,6,9,AIR:0)
Block(-4,6,10,AIR:0)
Block(-4,6,11,iceandfire:chared_cobblestone:0)
Block(-4,6,12,iceandfire:chared_stone:0)
Block(-4,6,13,iceandfire:chared_stone:0)
Block(-4,7,-11,STONE:0)
Block(-4,7,-10,iceandfire:frozen_stone:0)
Block(-4,7,-9,iceandfire:frozen_stone:0)
Block(-4,7,-8,iceandfire:frozen_stone:0)
Block(-4,7,-7,STONE:0)
Block(-4,7,-6,AIR:0)
Block(-4,7,-5,AIR:0)
Block(-4,7,-4,AIR:0)
Block(-4,7,-3,AIR:0)
Block(-4,7,-2,AIR:0)
Block(-4,7,-1,AIR:0)
Block(-4,7,0,AIR:0)
Block(-4,7,1,AIR:0)
Block(-4,7,2,AIR:0)
Block(-4,7,3,AIR:0)
Block(-4,7,4,AIR:0)
Block(-4,7,5,AIR:0)
Block(-4,7,6,AIR:0)
Block(-4,7,7,AIR:0)
Block(-4,7,8,AIR:0)
Block(-4,7,9,AIR:0)
Block(-4,7,10,AIR:0)
Block(-4,7,11,iceandfire:chared_stone:0)
Block(-4,7,12,iceandfire:chared_stone:0)
Block(-4,7,13,iceandfire:chared_stone:0)
Block(-4,8,-11,STONE:0)
Block(-4,8,-10,iceandfire:frozen_stone:0)
Block(-4,8,-9,iceandfire:frozen_stone:0)
Block(-4,8,-8,iceandfire:frozen_stone:0)
Block(-4,8,-7,BROWN_MUSHROOM:0)
Block(-4,8,-6,AIR:0)
Block(-4,8,-5,AIR:0)
Block(-4,8,-4,AIR:0)
Block(-4,8,-3,AIR:0)
Block(-4,8,-2,AIR:0)
Block(-4,8,-1,AIR:0)
Block(-4,8,0,AIR:0)
Block(-4,8,1,AIR:0)
Block(-4,8,2,AIR:0)
Block(-4,8,3,AIR:0)
Block(-4,8,4,AIR:0)
Block(-4,8,5,inspirations:rope:1)
Block(-4,8,6,AIR:0)
Block(-4,8,7,AIR:0)
Block(-4,8,8,AIR:0)
Block(-4,8,9,AIR:0)
Block(-4,8,10,AIR:0)
Block(-4,8,11,iceandfire:chared_stone:0)
Block(-4,8,12,iceandfire:chared_stone:0)
Block(-4,8,13,iceandfire:chared_stone:0)
Block(-4,9,-12,STONE:0)
Block(-4,9,-11,STONE:0)
Block(-4,9,-10,iceandfire:frozen_stone:0)
Block(-4,9,-9,iceandfire:frozen_stone:0)
Block(-4,9,-8,iceandfire:frozen_stone:0)
Block(-4,9,-7,AIR:0)
Block(-4,9,-6,AIR:0)
Block(-4,9,-5,AIR:0)
Block(-4,9,-4,AIR:0)
Block(-4,9,-3,AIR:0)
Block(-4,9,-2,AIR:0)
Block(-4,9,-1,AIR:0)
Block(-4,9,0,AIR:0)
Block(-4,9,1,AIR:0)
Block(-4,9,2,AIR:0)
Block(-4,9,3,AIR:0)
Block(-4,9,4,AIR:0)
Block(-4,9,5,inspirations:rope:1)
Block(-4,9,6,AIR:0)
Block(-4,9,7,AIR:0)
Block(-4,9,8,AIR:0)
Block(-4,9,9,AIR:0)
Block(-4,9,10,AIR:0)
Block(-4,9,11,iceandfire:chared_stone:0)
Block(-4,9,12,iceandfire:chared_stone:0)
Block(-4,9,13,iceandfire:chared_stone:0)
Block(-4,10,-12,quark:slate:0)
Block(-4,10,-11,quark:slate:0)
Block(-4,10,-10,quark:slate:0)
Block(-4,10,-9,STONE:0)
Block(-4,10,-8,STONE:0)
Block(-4,10,-7,AIR:0)
Block(-4,10,-6,AIR:0)
Block(-4,10,-5,AIR:0)
Block(-4,10,-4,AIR:0)
Block(-4,10,-3,AIR:0)
Block(-4,10,-2,AIR:0)
Block(-4,10,-1,AIR:0)
Block(-4,10,0,AIR:0)
Block(-4,10,1,AIR:0)
Block(-4,10,2,AIR:0)
Block(-4,10,3,AIR:0)
Block(-4,10,4,AIR:0)
Block(-4,10,5,inspirations:rope:1)
Block(-4,10,6,AIR:0)
Block(-4,10,7,AIR:0)
Block(-4,10,8,AIR:0)
Block(-4,10,9,AIR:0)
Block(-4,10,10,AIR:0)
Block(-4,10,11,iceandfire:chared_cobblestone:0)
Block(-4,10,12,iceandfire:chared_stone:0)
Block(-4,11,-13,STONE:0)
Block(-4,11,-12,quark:slate:0)
Block(-4,11,-11,quark:slate:0)
Block(-4,11,-10,iceandfire:frozen_stone:0)
Block(-4,11,-9,iceandfire:frozen_stone:0)
Block(-4,11,-8,iceandfire:frozen_stone:0)
Block(-4,11,-7,quark:stone_speleothem:0)
Block(-4,11,-6,AIR:0)
Block(-4,11,-5,AIR:0)
Block(-4,11,-4,AIR:0)
Block(-4,11,-3,AIR:0)
Block(-4,11,-2,AIR:0)
Block(-4,11,-1,AIR:0)
Block(-4,11,0,AIR:0)
Block(-4,11,1,AIR:0)
Block(-4,11,2,AIR:0)
Block(-4,11,3,AIR:0)
Block(-4,11,4,AIR:0)
Block(-4,11,5,inspirations:rope:1)
Block(-4,11,6,AIR:0)
Block(-4,11,7,AIR:0)
Block(-4,11,8,quark:stone_speleothem:0)
Block(-4,11,9,AIR:0)
Block(-4,11,10,AIR:0)
Block(-4,11,11,iceandfire:chared_cobblestone:0)
Block(-4,11,12,iceandfire:chared_stone:0)
Block(-4,12,-13,STONE:0)
Block(-4,12,-12,quark:slate:0)
Block(-4,12,-11,iceandfire:frozen_stone:0)
Block(-4,12,-10,iceandfire:frozen_stone:0)
Block(-4,12,-9,iceandfire:frozen_stone:0)
Block(-4,12,-8,iceandfire:frozen_stone:0)
Block(-4,12,-7,quark:stone_speleothem:1)
Block(-4,12,-6,quark:stone_speleothem:0)
Block(-4,12,-5,AIR:0)
Block(-4,12,-4,AIR:0)
Block(-4,12,-3,AIR:0)
Block(-4,12,-2,quark:stone_speleothem:0)
Block(-4,12,-1,AIR:0)
Block(-4,12,0,AIR:0)
Block(-4,12,1,AIR:0)
Block(-4,12,2,AIR:0)
Block(-4,12,3,AIR:0)
Block(-4,12,4,AIR:0)
Block(-4,12,5,inspirations:rope:1)
Block(-4,12,6,AIR:0)
Block(-4,12,7,AIR:0)
Block(-4,12,8,quark:stone_speleothem:1)
Block(-4,12,9,AIR:0)
Block(-4,12,10,iceandfire:chared_stone:0)
Block(-4,12,11,iceandfire:chared_stone:0)
Block(-4,12,12,iceandfire:chared_stone:0)
Block(-4,13,-13,STONE:0)
Block(-4,13,-12,STONE:0)
Block(-4,13,-11,iceandfire:frozen_stone:0)
Block(-4,13,-10,iceandfire:frozen_stone:0)
Block(-4,13,-9,iceandfire:frozen_stone:0)
Block(-4,13,-8,iceandfire:dragon_ice_spikes:0)
Block(-4,13,-7,quark:stone_speleothem:2)
Block(-4,13,-6,quark:stone_speleothem:1)
Block(-4,13,-5,AIR:0)
Block(-4,13,-4,AIR:0)
Block(-4,13,-3,AIR:0)
Block(-4,13,-2,quark:stone_speleothem:1)
Block(-4,13,-1,quark:stone_speleothem:0)
Block(-4,13,0,AIR:0)
Block(-4,13,1,quark:stone_speleothem:0)
Block(-4,13,2,AIR:0)
Block(-4,13,3,AIR:0)
Block(-4,13,4,AIR:0)
Block(-4,13,5,inspirations:rope:1)
Block(-4,13,6,AIR:0)
Block(-4,13,7,AIR:0)
Block(-4,13,8,quark:stone_speleothem:2)
Block(-4,13,9,AIR:0)
Block(-4,13,10,quark:slate:0)
Block(-4,13,11,quark:slate:0)
Block(-4,13,12,quark:slate:0)
Block(-4,14,-14,STONE:0)
Block(-4,14,-13,STONE:0)
Block(-4,14,-12,STONE:0)
Block(-4,14,-11,iceandfire:frozen_stone:0)
Block(-4,14,-10,iceandfire:frozen_stone:0)
Block(-4,14,-9,iceandfire:frozen_stone:0)
Block(-4,14,-8,AIR:0)
Block(-4,14,-7,iceandfire:frozen_stone:0)
Block(-4,14,-6,quark:stone_speleothem:2)
Block(-4,14,-5,AIR:0)
Block(-4,14,-4,AIR:0)
Block(-4,14,-3,quark:stone_speleothem:1)
Block(-4,14,-2,quark:stone_speleothem:2)
Block(-4,14,-1,quark:stone_speleothem:1)
Block(-4,14,0,AIR:0)
Block(-4,14,1,quark:stone_speleothem:1)
Block(-4,14,2,quark:stone_speleothem:0)
Block(-4,14,3,AIR:0)
Block(-4,14,4,AIR:0)
Block(-4,14,5,inspirations:rope:1)
Block(-4,14,6,AIR:0)
Block(-4,14,7,quark:slate:0)
Block(-4,14,8,quark:slate:0)
Block(-4,14,9,STONE:0)
Block(-4,14,10,quark:slate:0)
Block(-4,14,11,quark:slate:0)
Block(-4,14,12,quark:slate:0)
Block(-4,15,-14,STONE:0)
Block(-4,15,-13,STONE:0)
Block(-4,15,-12,STONE:0)
Block(-4,15,-11,STONE:0)
Block(-4,15,-10,iceandfire:frozen_stone:0)
Block(-4,15,-9,iceandfire:frozen_stone:0)
Block(-4,15,-8,quark:stone_stairs:5)
Block(-4,15,-7,STONE:0)
Block(-4,15,-6,STONE:0)
Block(-4,15,-5,quark:stone_stairs:5)
Block(-4,15,-4,STONE:0)
Block(-4,15,-3,quark:stone_speleothem:2)
Block(-4,15,-2,quark:slate:0)
Block(-4,15,-1,quark:stone_speleothem:2)
Block(-4,15,0,AIR:0)
Block(-4,15,1,quark:stone_speleothem:2)
Block(-4,15,2,quark:stone_speleothem:1)
Block(-4,15,3,AIR:0)
Block(-4,15,4,AIR:0)
Block(-4,15,5,inspirations:rope:1)
Block(-4,15,6,quark:slate:0)
Block(-4,15,7,quark:slate:0)
Block(-4,15,8,STONE:0)
Block(-4,15,9,STONE:0)
Block(-4,15,10,STONE:0)
Block(-4,15,11,STONE:0)
Block(-4,16,-14,STONE:0)
Block(-4,16,-13,STONE:0)
Block(-4,16,-12,STONE:0)
Block(-4,16,-11,STONE:0)
Block(-4,16,-10,STONE:0)
Block(-4,16,-9,STONE:0)
Block(-4,16,-8,STONE:0)
Block(-4,16,-7,STONE:0)
Block(-4,16,-6,STONE:0)
Block(-4,16,-5,STONE:0)
Block(-4,16,-4,quark:slate:0)
Block(-4,16,-3,quark:slate:0)
Block(-4,16,-2,quark:slate:0)
Block(-4,16,-1,quark:slate:0)
Block(-4,16,0,quark:slate:0)
Block(-4,16,1,quark:slate:0)
Block(-4,16,2,quark:stone_speleothem:2)
Block(-4,16,3,quark:slate:0)
Block(-4,16,4,quark:slate:0)
Block(-4,16,5,quark:slate:0)
Block(-4,16,6,STONE:0)
Block(-4,16,7,STONE:0)
Block(-4,16,8,STONE:0)
Block(-4,16,9,STONE:0)
Block(-4,17,-11,STONE:0)
Block(-4,17,-10,STONE:0)
Block(-4,17,-9,STONE:0)
Block(-4,17,-8,STONE:0)
Block(-4,17,-7,STONE:0)
Block(-4,17,-6,STONE:0)
Block(-4,17,-5,STONE:0)
Block(-4,17,-4,quark:slate:0)
Block(-4,17,-3,quark:slate:0)
Block(-4,17,-2,quark:slate:0)
Block(-4,17,-1,quark:slate:0)
Block(-4,17,0,quark:slate:0)
Block(-4,17,1,quark:slate:0)
Block(-4,17,2,quark:slate:0)
Block(-4,17,3,STONE:0)
Block(-4,17,4,STONE:0)
Block(-4,17,5,STONE:0)
Block(-4,17,6,STONE:0)
Block(-4,18,-10,STONE:0)
Block(-4,18,-9,STONE:0)
Block(-4,18,-8,STONE:0)
Block(-4,18,-7,STONE:0)
Block(-4,18,-6,STONE:0)
Block(-4,18,-5,STONE:0)
Block(-4,18,-3,quark:slate:0)
Block(-4,18,-2,quark:slate:0)
Block(-4,18,-1,quark:slate:0)
Block(-4,18,0,quark:slate:0)
Block(-4,18,1,quark:slate:0)
Block(-4,18,2,STONE:0)
Block(-4,18,3,STONE:0)
Block(-4,18,4,STONE:0)
Block(-3,0,-2,STONE:0)
Block(-3,0,-1,iceandfire:chared_stone:0)
Block(-3,0,0,iceandfire:chared_stone:0)
Block(-3,0,1,iceandfire:chared_stone:0)
Block(-3,0,2,iceandfire:chared_stone:0)
Block(-3,0,3,iceandfire:chared_stone:0)
Block(-3,0,4,BONE_BLOCK:4)
Block(-3,0,5,STONE:0)
Block(-3,0,6,STONE:0)
Block(-3,0,7,iceandfire:chared_stone:0)
Block(-3,0,8,iceandfire:chared_stone:0)
Block(-3,0,9,iceandfire:chared_stone:0)
Block(-3,0,10,iceandfire:chared_stone:0)
Block(-3,1,-2,STONE:0)
Block(-3,1,-1,iceandfire:chared_stone:0)
Block(-3,1,0,biomesoplenty:blood:0)
Block(-3,1,1,charm:rotten_flesh_block:0)
Block(-3,1,2,betternether:bone_stairs:1)
Block(-3,1,3,betternether:bone_slab_half:1)
Block(-3,1,4,contenttweaker:bone_pile:0)
Block(-3,1,5,betternether:bone_slab_double:0)
Block(-3,1,6,biomesoplenty:blood:0)
Block(-3,1,7,biomesoplenty:flesh:0)
Block(-3,1,8,iceandfire:chared_stone:0)
Block(-3,1,9,iceandfire:chared_stone:0)
Block(-3,1,10,iceandfire:chared_stone:0)
Block(-3,1,11,iceandfire:chared_stone:0)
Block(-3,2,-4,STONE:0)
Block(-3,2,-3,iceandfire:chared_stone:0)
Block(-3,2,-2,iceandfire:chared_stone:0)
Block(-3,2,-1,BROWN_MUSHROOM:0)
Block(-3,2,0,AIR:0)
Block(-3,2,1,AIR:0)
Block(-3,2,2,AIR:0)
Block(-3,2,3,AIR:0)
Block(-3,2,4,AIR:0)
Block(-3,2,5,AIR:0)
Block(-3,2,6,AIR:0)
Block(-3,2,7,rustic:mooncap_mushroom:0)
Block(-3,2,8,biomesoplenty:flesh:0)
Block(-3,2,9,iceandfire:chared_stone:0)
Block(-3,2,10,iceandfire:chared_stone:0)
Block(-3,2,11,iceandfire:chared_stone:0)
Block(-3,3,-5,quark:slate:0)
Block(-3,3,-4,STONE:0)
Block(-3,3,-3,AIR:0)
Block(-3,3,-2,AIR:0)
Block(-3,3,-1,AIR:0)
Block(-3,3,0,AIR:0)
Block(-3,3,1,AIR:0)
Block(-3,3,2,AIR:0)
Block(-3,3,3,AIR:0)
Block(-3,3,4,AIR:0)
Block(-3,3,5,AIR:0)
Block(-3,3,6,AIR:0)
Block(-3,3,7,AIR:0)
Block(-3,3,8,AIR:0)
Block(-3,3,9,charm:rotten_flesh_block:0)
Block(-3,3,10,biomesoplenty:flesh:0)
Block(-3,3,11,iceandfire:chared_stone:0)
Block(-3,3,12,iceandfire:chared_stone:0)
Block(-3,4,-6,quark:slate:0)
Block(-3,4,-5,quark:stone_stairs:0)
Block(-3,4,-4,AIR:0)
Block(-3,4,-3,AIR:0)
Block(-3,4,-2,AIR:0)
Block(-3,4,-1,AIR:0)
Block(-3,4,0,AIR:0)
Block(-3,4,1,AIR:0)
Block(-3,4,2,AIR:0)
Block(-3,4,3,AIR:0)
Block(-3,4,4,AIR:0)
Block(-3,4,5,AIR:0)
Block(-3,4,6,AIR:0)
Block(-3,4,7,AIR:0)
Block(-3,4,8,AIR:0)
Block(-3,4,9,rustic:mooncap_mushroom:0)
Block(-3,4,10,charm:rotten_flesh_block:0)
Block(-3,4,11,iceandfire:chared_stone:0)
Block(-3,4,12,iceandfire:chared_stone:0)
Block(-3,4,13,iceandfire:chared_stone:0)
Block(-3,5,-9,STONE:0)
Block(-3,5,-8,quark:slate:0)
Block(-3,5,-7,quark:slate:0)
Block(-3,5,-6,quark:stone_stairs:3)
Block(-3,5,-5,AIR:0)
Block(-3,5,-4,AIR:0)
Block(-3,5,-3,AIR:0)
Block(-3,5,-2,AIR:0)
Block(-3,5,-1,AIR:0)
Block(-3,5,0,AIR:0)
Block(-3,5,1,AIR:0)
Block(-3,5,2,AIR:0)
Block(-3,5,3,AIR:0)
Block(-3,5,4,AIR:0)
Block(-3,5,5,AIR:0)
Block(-3,5,6,AIR:0)
Block(-3,5,7,AIR:0)
Block(-3,5,8,AIR:0)
Block(-3,5,9,AIR:0)
Block(-3,5,10,BROWN_MUSHROOM:0)
Block(-3,5,11,iceandfire:chared_stone:0)
Block(-3,5,12,iceandfire:chared_stone:0)
Block(-3,5,13,iceandfire:chared_stone:0)
Block(-3,6,-10,iceandfire:frozen_stone:0)
Block(-3,6,-9,iceandfire:frozen_stone:0)
Block(-3,6,-8,iceandfire:frozen_stone:0)
Block(-3,6,-7,quark:slate:0)
Block(-3,6,-6,AIR:0)
Block(-3,6,-5,AIR:0)
Block(-3,6,-4,AIR:0)
Block(-3,6,-3,AIR:0)
Block(-3,6,-2,AIR:0)
Block(-3,6,-1,AIR:0)
Block(-3,6,0,AIR:0)
Block(-3,6,1,AIR:0)
Block(-3,6,2,AIR:0)
Block(-3,6,3,AIR:0)
Block(-3,6,4,AIR:0)
Block(-3,6,5,AIR:0)
Block(-3,6,6,AIR:0)
Block(-3,6,7,AIR:0)
Block(-3,6,8,AIR:0)
Block(-3,6,9,AIR:0)
Block(-3,6,10,AIR:0)
Block(-3,6,11,AIR:0)
Block(-3,6,12,iceandfire:chared_stone:0)
Block(-3,6,13,iceandfire:chared_stone:0)
Block(-3,7,-11,iceandfire:frozen_stone:0)
Block(-3,7,-10,iceandfire:frozen_stone:0)
Block(-3,7,-9,iceandfire:frozen_stone:0)
Block(-3,7,-8,BROWN_MUSHROOM:0)
Block(-3,7,-7,BROWN_MUSHROOM:0)
Block(-3,7,-6,AIR:0)
Block(-3,7,-5,AIR:0)
Block(-3,7,-4,AIR:0)
Block(-3,7,-3,AIR:0)
Block(-3,7,-2,AIR:0)
Block(-3,7,-1,AIR:0)
Block(-3,7,0,AIR:0)
Block(-3,7,1,AIR:0)
Block(-3,7,2,AIR:0)
Block(-3,7,3,AIR:0)
Block(-3,7,4,AIR:0)
Block(-3,7,5,AIR:0)
Block(-3,7,6,AIR:0)
Block(-3,7,7,AIR:0)
Block(-3,7,8,AIR:0)
Block(-3,7,9,AIR:0)
Block(-3,7,10,AIR:0)
Block(-3,7,11,quark:stone_speleothem:0)
Block(-3,7,12,iceandfire:chared_stone:0)
Block(-3,7,13,iceandfire:chared_stone:0)
Block(-3,7,14,STONE:0)
Block(-3,8,-12,STONE:0)
Block(-3,8,-11,iceandfire:frozen_stone:0)
Block(-3,8,-10,iceandfire:frozen_stone:0)
Block(-3,8,-9,iceandfire:frozen_stone:0)
Block(-3,8,-8,AIR:0)
Block(-3,8,-7,AIR:0)
Block(-3,8,-6,AIR:0)
Block(-3,8,-5,AIR:0)
Block(-3,8,-4,AIR:0)
Block(-3,8,-3,AIR:0)
Block(-3,8,-2,AIR:0)
Block(-3,8,-1,AIR:0)
Block(-3,8,0,AIR:0)
Block(-3,8,1,AIR:0)
Block(-3,8,2,AIR:0)
Block(-3,8,3,AIR:0)
Block(-3,8,4,AIR:0)
Block(-3,8,5,AIR:0)
Block(-3,8,6,AIR:0)
Block(-3,8,7,AIR:0)
Block(-3,8,8,AIR:0)
Block(-3,8,9,AIR:0)
Block(-3,8,10,AIR:0)
Block(-3,8,11,quark:stone_speleothem:1)
Block(-3,8,12,iceandfire:chared_stone:0)
Block(-3,8,13,iceandfire:chared_stone:0)
Block(-3,8,14,STONE:0)
Block(-3,9,-13,STONE:0)
Block(-3,9,-12,quark:slate:0)
Block(-3,9,-11,iceandfire:frozen_stone:0)
Block(-3,9,-10,iceandfire:frozen_stone:0)
Block(-3,9,-9,iceandfire:frozen_stone:0)
Block(-3,9,-8,AIR:0)
Block(-3,9,-7,AIR:0)
Block(-3,9,-6,AIR:0)
Block(-3,9,-5,AIR:0)
Block(-3,9,-4,AIR:0)
Block(-3,9,-3,AIR:0)
Block(-3,9,-2,AIR:0)
Block(-3,9,-1,AIR:0)
Block(-3,9,0,AIR:0)
Block(-3,9,1,AIR:0)
Block(-3,9,2,AIR:0)
Block(-3,9,3,AIR:0)
Block(-3,9,4,AIR:0)
Block(-3,9,5,AIR:0)
Block(-3,9,6,AIR:0)
Block(-3,9,7,AIR:0)
Block(-3,9,8,AIR:0)
Block(-3,9,9,AIR:0)
Block(-3,9,10,AIR:0)
Block(-3,9,11,quark:stone_speleothem:2)
Block(-3,9,12,iceandfire:chared_stone:0)
Block(-3,9,13,iceandfire:chared_stone:0)
Block(-3,9,14,quark:slate:0)
Block(-3,10,-13,quark:slate:0)
Block(-3,10,-12,quark:slate:0)
Block(-3,10,-11,quark:slate:0)
Block(-3,10,-10,iceandfire:frozen_stone:0)
Block(-3,10,-9,iceandfire:frozen_stone:0)
Block(-3,10,-8,AIR:0)
Block(-3,10,-7,AIR:0)
Block(-3,10,-6,AIR:0)
Block(-3,10,-5,AIR:0)
Block(-3,10,-4,AIR:0)
Block(-3,10,-3,AIR:0)
Block(-3,10,-2,AIR:0)
Block(-3,10,-1,AIR:0)
Block(-3,10,0,AIR:0)
Block(-3,10,1,AIR:0)
Block(-3,10,2,AIR:0)
Block(-3,10,3,AIR:0)
Block(-3,10,4,AIR:0)
Block(-3,10,5,AIR:0)
Block(-3,10,6,AIR:0)
Block(-3,10,7,AIR:0)
Block(-3,10,8,AIR:0)
Block(-3,10,9,AIR:0)
Block(-3,10,10,AIR:0)
Block(-3,10,11,iceandfire:chared_stone:0)
Block(-3,10,12,iceandfire:chared_stone:0)
Block(-3,10,13,iceandfire:chared_stone:0)
Block(-3,11,-14,STONE:0)
Block(-3,11,-13,quark:slate:0)
Block(-3,11,-12,quark:slate:0)
Block(-3,11,-11,quark:slate:0)
Block(-3,11,-10,iceandfire:frozen_stone:0)
Block(-3,11,-9,rustic:mooncap_mushroom:0)
Block(-3,11,-8,AIR:0)
Block(-3,11,-7,AIR:0)
Block(-3,11,-6,AIR:0)
Block(-3,11,-5,AIR:0)
Block(-3,11,-4,AIR:0)
Block(-3,11,-3,AIR:0)
Block(-3,11,-2,AIR:0)
Block(-3,11,-1,AIR:0)
Block(-3,11,0,AIR:0)
Block(-3,11,1,AIR:0)
Block(-3,11,2,AIR:0)
Block(-3,11,3,AIR:0)
Block(-3,11,4,AIR:0)
Block(-3,11,5,AIR:0)
Block(-3,11,6,AIR:0)
Block(-3,11,7,AIR:0)
Block(-3,11,8,AIR:0)
Block(-3,11,9,AIR:0)
Block(-3,11,10,quark:stone_speleothem:0)
Block(-3,11,11,iceandfire:chared_stone:0)
Block(-3,11,12,iceandfire:chared_stone:0)
Block(-3,12,-14,STONE:0)
Block(-3,12,-13,quark:slate:0)
Block(-3,12,-12,quark:slate:0)
Block(-3,12,-11,iceandfire:frozen_stone:0)
Block(-3,12,-10,iceandfire:frozen_stone:0)
Block(-3,12,-9,AIR:0)
Block(-3,12,-8,AIR:0)
Block(-3,12,-7,AIR:0)
Block(-3,12,-6,AIR:0)
Block(-3,12,-5,AIR:0)
Block(-3,12,-4,AIR:0)
Block(-3,12,-3,AIR:0)
Block(-3,12,-2,AIR:0)
Block(-3,12,-1,AIR:0)
Block(-3,12,0,AIR:0)
Block(-3,12,1,AIR:0)
Block(-3,12,2,AIR:0)
Block(-3,12,3,AIR:0)
Block(-3,12,4,AIR:0)
Block(-3,12,5,AIR:0)
Block(-3,12,6,AIR:0)
Block(-3,12,7,AIR:0)
Block(-3,12,8,AIR:0)
Block(-3,12,9,AIR:0)
Block(-3,12,10,quark:stone_speleothem:1)
Block(-3,12,11,iceandfire:chared_stone:0)
Block(-3,12,12,iceandfire:chared_stone:0)
Block(-3,13,-14,STONE:0)
Block(-3,13,-13,STONE:0)
Block(-3,13,-12,quark:slate:0)
Block(-3,13,-11,iceandfire:frozen_stone:0)
Block(-3,13,-10,iceandfire:dragon_ice_spikes:0)
Block(-3,13,-9,quark:stone_speleothem:0)
Block(-3,13,-8,AIR:0)
Block(-3,13,-7,AIR:0)
Block(-3,13,-6,AIR:0)
Block(-3,13,-5,AIR:0)
Block(-3,13,-4,AIR:0)
Block(-3,13,-3,AIR:0)
Block(-3,13,-2,AIR:0)
Block(-3,13,-1,AIR:0)
Block(-3,13,0,AIR:0)
Block(-3,13,1,AIR:0)
Block(-3,13,2,AIR:0)
Block(-3,13,3,AIR:0)
Block(-3,13,4,AIR:0)
Block(-3,13,5,AIR:0)
Block(-3,13,6,quark:stone_speleothem:0)
Block(-3,13,7,AIR:0)
Block(-3,13,8,AIR:0)
Block(-3,13,9,AIR:0)
Block(-3,13,10,quark:stone_speleothem:2)
Block(-3,13,11,quark:slate:0)
Block(-3,13,12,quark:slate:0)
Block(-3,14,-14,STONE:0)
Block(-3,14,-13,STONE:0)
Block(-3,14,-12,STONE:0)
Block(-3,14,-11,iceandfire:frozen_stone:0)
Block(-3,14,-10,AIR:0)
Block(-3,14,-9,quark:stone_speleothem:1)
Block(-3,14,-8,AIR:0)
Block(-3,14,-7,AIR:0)
Block(-3,14,-6,AIR:0)
Block(-3,14,-5,AIR:0)
Block(-3,14,-4,AIR:0)
Block(-3,14,-3,AIR:0)
Block(-3,14,-2,AIR:0)
Block(-3,14,-1,AIR:0)
Block(-3,14,0,AIR:0)
Block(-3,14,1,AIR:0)
Block(-3,14,2,AIR:0)
Block(-3,14,3,AIR:0)
Block(-3,14,4,AIR:0)
Block(-3,14,5,AIR:0)
Block(-3,14,6,quark:stone_speleothem:1)
Block(-3,14,7,AIR:0)
Block(-3,14,8,quark:slate:0)
Block(-3,14,9,quark:slate:0)
Block(-3,14,10,quark:slate:0)
Block(-3,14,11,quark:slate:0)
Block(-3,14,12,quark:slate:0)
Block(-3,15,-14,STONE:0)
Block(-3,15,-13,STONE:0)
Block(-3,15,-12,STONE:0)
Block(-3,15,-11,STONE:0)
Block(-3,15,-10,iceandfire:frozen_stone:0)
Block(-3,15,-9,quark:stone_speleothem:2)
Block(-3,15,-8,AIR:0)
Block(-3,15,-7,AIR:0)
Block(-3,15,-6,AIR:0)
Block(-3,15,-5,AIR:0)
Block(-3,15,-4,AIR:0)
Block(-3,15,-3,AIR:0)
Block(-3,15,-2,AIR:0)
Block(-3,15,-1,AIR:0)
Block(-3,15,0,AIR:0)
Block(-3,15,1,AIR:0)
Block(-3,15,2,AIR:0)
Block(-3,15,3,AIR:0)
Block(-3,15,4,AIR:0)
Block(-3,15,5,AIR:0)
Block(-3,15,6,quark:stone_speleothem:2)
Block(-3,15,7,quark:slate:0)
Block(-3,15,8,STONE:0)
Block(-3,15,9,STONE:0)
Block(-3,15,10,quark:slate:0)
Block(-3,15,11,quark:slate:0)
Block(-3,16,-14,STONE:0)
Block(-3,16,-13,STONE:0)
Block(-3,16,-12,STONE:0)
Block(-3,16,-11,STONE:0)
Block(-3,16,-10,iceandfire:frozen_stone:0)
Block(-3,16,-9,iceandfire:frozen_stone:0)
Block(-3,16,-8,iceandfire:frozen_stone:0)
Block(-3,16,-7,quark:stone_stairs:5)
Block(-3,16,-6,STONE:0)
Block(-3,16,-5,quark:slate:0)
Block(-3,16,-4,quark:slate:0)
Block(-3,16,-3,quark:slate:0)
Block(-3,16,-2,quark:stone_stairs:7)
Block(-3,16,-1,AIR:0)
Block(-3,16,0,AIR:0)
Block(-3,16,1,AIR:0)
Block(-3,16,2,AIR:0)
Block(-3,16,3,quark:slate:0)
Block(-3,16,4,quark:slate:0)
Block(-3,16,5,quark:slate:0)
Block(-3,16,6,STONE:0)
Block(-3,16,7,STONE:0)
Block(-3,16,8,STONE:0)
Block(-3,16,9,STONE:0)
Block(-3,17,-14,STONE:0)
Block(-3,17,-13,STONE:0)
Block(-3,17,-12,STONE:0)
Block(-3,17,-11,STONE:0)
Block(-3,17,-10,iceandfire:frozen_stone:0)
Block(-3,17,-9,iceandfire:frozen_stone:0)
Block(-3,17,-8,iceandfire:frozen_stone:0)
Block(-3,17,-7,STONE:0)
Block(-3,17,-6,STONE:0)
Block(-3,17,-5,quark:slate:0)
Block(-3,17,-4,quark:slate:0)
Block(-3,17,-3,quark:slate:0)
Block(-3,17,-2,quark:slate:0)
Block(-3,17,-1,quark:slate:0)
Block(-3,17,0,quark:slate:0)
Block(-3,17,1,quark:slate:0)
Block(-3,17,2,quark:slate:0)
Block(-3,17,3,quark:slate:0)
Block(-3,17,4,quark:slate:0)
Block(-3,17,5,quark:slate:0)
Block(-3,17,6,STONE:0)
Block(-3,18,-14,STONE:0)
Block(-3,18,-13,STONE:0)
Block(-3,18,-12,STONE:0)
Block(-3,18,-11,STONE:0)
Block(-3,18,-10,iceandfire:frozen_stone:0)
Block(-3,18,-9,iceandfire:frozen_stone:0)
Block(-3,18,-8,iceandfire:frozen_stone:0)
Block(-3,18,-7,STONE:0)
Block(-3,18,-6,STONE:0)
Block(-3,18,-5,quark:slate:0)
Block(-3,18,-4,quark:slate:0)
Block(-3,18,-3,quark:slate:0)
Block(-3,18,-2,quark:slate:0)
Block(-3,18,-1,quark:slate:0)
Block(-3,18,0,quark:slate:0)
Block(-3,18,1,quark:slate:0)
Block(-3,18,2,STONE:0)
Block(-3,18,3,quark:slate:0)
Block(-3,18,4,quark:slate:0)
Block(-3,18,5,quark:slate:0)
Block(-2,0,-2,STONE:0)
Block(-2,0,-1,iceandfire:chared_stone:0)
Block(-2,0,0,iceandfire:chared_stone:0)
Block(-2,0,1,iceandfire:chared_stone:0)
Block(-2,0,2,BONE_BLOCK:8)
Block(-2,0,3,iceandfire:chared_stone:0)
Block(-2,0,4,STONE:0)
Block(-2,0,5,STONE:0)
Block(-2,0,6,STONE:0)
Block(-2,0,7,iceandfire:chared_stone:0)
Block(-2,0,8,iceandfire:chared_stone:0)
Block(-2,0,9,iceandfire:chared_stone:0)
Block(-2,0,10,iceandfire:chared_stone:0)
Block(-2,0,11,STONE:0)
Block(-2,1,-4,STONE:0)
Block(-2,1,-3,STONE:0)
Block(-2,1,-2,STONE:0)
Block(-2,1,-1,biomesoplenty:blood:0)
Block(-2,1,0,biomesoplenty:blood:0)
Block(-2,1,1,betternether:bone_stairs:3)
Block(-2,1,2,AIR:0)
Block(-2,1,3,BONE_BLOCK:0)
Block(-2,1,4,BONE_BLOCK:0)
Block(-2,1,5,BONE_BLOCK:0)
Block(-2,1,6,BONE_BLOCK:0)
Block(-2,1,7,BONE_BLOCK:0)
Block(-2,1,8,iceandfire:chared_stone:0)
Block(-2,1,9,iceandfire:chared_stone:0)
Block(-2,1,10,iceandfire:chared_stone:0)
Block(-2,1,11,iceandfire:chared_stone:0)
Block(-2,2,-5,STONE:0)
Block(-2,2,-4,STONE:0)
Block(-2,2,-3,STONE:0)
Block(-2,2,-2,STONE:0)
Block(-2,2,-1,AIR:0)
Block(-2,2,0,AIR:0)
Block(-2,2,1,AIR:0)
Block(-2,2,2,AIR:0)
Block(-2,2,3,AIR:0)
Block(-2,2,4,AIR:0)
Block(-2,2,5,contenttweaker:bone_pile:0)
Block(-2,2,6,AIR:0)
Block(-2,2,7,AIR:0)
Block(-2,2,8,biomesoplenty:flesh:0)
Block(-2,2,9,iceandfire:chared_stone:0)
Block(-2,2,10,iceandfire:chared_stone:0)
Block(-2,2,11,iceandfire:chared_stone:0)
Block(-2,3,-6,quark:slate:0)
Block(-2,3,-5,quark:slate:0)
Block(-2,3,-4,STONE:0)
Block(-2,3,-3,STONE:0)
Block(-2,3,-2,biomesoplenty:plant_0:11)
Block(-2,3,-1,AIR:0)
Block(-2,3,0,AIR:0)
Block(-2,3,1,AIR:0)
Block(-2,3,2,AIR:0)
Block(-2,3,3,AIR:0)
Block(-2,3,4,AIR:0)
Block(-2,3,5,AIR:0)
Block(-2,3,6,AIR:0)
Block(-2,3,7,AIR:0)
Block(-2,3,8,rustic:mooncap_mushroom:0)
RandomBlock(-2,3,9,SKULL:1,../../../Skulls/dungeon_skull_01.nbt,6,AIR,9,SKULL:1,../../../Skulls/dungeon_skull_02.nbt,12,AIR,15,SKULL:1,../../../Skulls/dungeon_skull_03.nbt,18,AIR,21,SKULL:1,../../../Skulls/dungeon_skull_04.nbt,24,AIR,27,SKULL:1,../../../Skulls/dungeon_skull_05.nbt,30,AIR,33,SKULL:1,../../../Skulls/dungeon_skull_06.nbt,36,AIR,39,SKULL:1,../../../Skulls/dungeon_skull_07.nbt,42,AIR,45,SKULL:1,../../../Skulls/dungeon_skull_08.nbt,48,AIR,51,SKULL:1,../../../Skulls/dungeon_skull_09.nbt,54,AIR,57,SKULL:1,../../../Skulls/dungeon_skull_10.nbt,60,AIR,63,SKULL:1,../../../Skulls/dungeon_skull_11.nbt,66,AIR,69,SKULL:1,../../../Skulls/dungeon_skull_12.nbt,72,AIR,75,SKULL:1,../../../Skulls/dungeon_skull_13.nbt,78,AIR,81,SKULL:1,../../../Skulls/dungeon_skull_14.nbt,84,AIR,87,SKULL:1,../../../Skulls/dungeon_skull_15.nbt,90,AIR,93,SKULL:1,../../../Skulls/dungeon_skull_16.nbt,96,AIR,100)
Block(-2,3,10,biomesoplenty:flesh:0)
Block(-2,3,11,biomesoplenty:flesh:0)
Block(-2,3,12,iceandfire:chared_stone:0)
Block(-2,3,13,iceandfire:chared_stone:0)
Block(-2,4,-6,quark:slate:0)
Block(-2,4,-5,quark:slate:0)
Block(-2,4,-4,quark:stone_stairs:3)
Block(-2,4,-3,AIR:0)
Block(-2,4,-2,AIR:0)
Block(-2,4,-1,AIR:0)
Block(-2,4,0,AIR:0)
Block(-2,4,1,AIR:0)
Block(-2,4,2,AIR:0)
Block(-2,4,3,AIR:0)
Block(-2,4,4,AIR:0)
Block(-2,4,5,AIR:0)
Block(-2,4,6,AIR:0)
Block(-2,4,7,AIR:0)
Block(-2,4,8,AIR:0)
Block(-2,4,9,AIR:0)
Block(-2,4,10,BROWN_MUSHROOM:0)
Block(-2,4,11,biomesoplenty:flesh:0)
Block(-2,4,12,iceandfire:chared_stone:0)
Block(-2,4,13,iceandfire:chared_stone:0)
Block(-2,4,14,iceandfire:chared_stone:0)
Block(-2,5,-9,STONE:0)
Block(-2,5,-8,quark:slate:0)
Block(-2,5,-7,quark:slate:0)
Block(-2,5,-6,quark:slate:0)
Block(-2,5,-5,AIR:0)
Block(-2,5,-4,AIR:0)
Block(-2,5,-3,AIR:0)
Block(-2,5,-2,AIR:0)
Block(-2,5,-1,AIR:0)
Block(-2,5,0,AIR:0)
Block(-2,5,1,AIR:0)
Block(-2,5,2,AIR:0)
Block(-2,5,3,AIR:0)
Block(-2,5,4,AIR:0)
Block(-2,5,5,AIR:0)
Block(-2,5,6,AIR:0)
Block(-2,5,7,AIR:0)
Block(-2,5,8,AIR:0)
Block(-2,5,9,AIR:0)
Block(-2,5,10,AIR:0)
Block(-2,5,11,rustic:mooncap_mushroom:0)
Block(-2,5,12,iceandfire:chared_cobblestone:0)
Block(-2,5,13,iceandfire:chared_stone:0)
Block(-2,5,14,iceandfire:chared_stone:0)
Block(-2,6,-10,iceandfire:frozen_stone:0)
Block(-2,6,-9,iceandfire:frozen_stone:0)
Block(-2,6,-8,iceandfire:frozen_stone:0)
Block(-2,6,-7,quark:stone_stairs:3)
Block(-2,6,-6,AIR:0)
Block(-2,6,-5,AIR:0)
Block(-2,6,-4,AIR:0)
Block(-2,6,-3,AIR:0)
Block(-2,6,-2,AIR:0)
Block(-2,6,-1,AIR:0)
Block(-2,6,0,AIR:0)
Block(-2,6,1,AIR:0)
Block(-2,6,2,AIR:0)
Block(-2,6,3,AIR:0)
Block(-2,6,4,AIR:0)
Block(-2,6,5,AIR:0)
Block(-2,6,6,AIR:0)
Block(-2,6,7,AIR:0)
Block(-2,6,8,AIR:0)
Block(-2,6,9,AIR:0)
Block(-2,6,10,AIR:0)
Block(-2,6,11,AIR:0)
Block(-2,6,12,iceandfire:chared_stone:0)
Block(-2,6,13,iceandfire:chared_stone:0)
Block(-2,6,14,iceandfire:chared_stone:0)
Block(-2,7,-12,STONE:0)
Block(-2,7,-11,iceandfire:frozen_stone:0)
Block(-2,7,-10,iceandfire:frozen_stone:0)
Block(-2,7,-9,iceandfire:frozen_stone:0)
Block(-2,7,-8,quark:stone_stairs:0)
Block(-2,7,-7,AIR:0)
Block(-2,7,-6,AIR:0)
Block(-2,7,-5,AIR:0)
Block(-2,7,-4,AIR:0)
Block(-2,7,-3,AIR:0)
Block(-2,7,-2,AIR:0)
Block(-2,7,-1,AIR:0)
Block(-2,7,0,AIR:0)
Block(-2,7,1,AIR:0)
Block(-2,7,2,AIR:0)
Block(-2,7,3,AIR:0)
Block(-2,7,4,AIR:0)
Block(-2,7,5,AIR:0)
Block(-2,7,6,AIR:0)
Block(-2,7,7,AIR:0)
Block(-2,7,8,AIR:0)
Block(-2,7,9,AIR:0)
Block(-2,7,10,AIR:0)
Block(-2,7,11,AIR:0)
Block(-2,7,12,iceandfire:chared_cobblestone:0)
Block(-2,7,13,iceandfire:chared_stone:0)
Block(-2,7,14,iceandfire:chared_stone:0)
Block(-2,8,-13,STONE:0)
Block(-2,8,-12,STONE:0)
Block(-2,8,-11,iceandfire:frozen_stone:0)
Block(-2,8,-10,iceandfire:frozen_stone:0)
Block(-2,8,-9,quark:stone_speleothem:2)
Block(-2,8,-8,AIR:0)
Block(-2,8,-7,AIR:0)
Block(-2,8,-6,AIR:0)
Block(-2,8,-5,AIR:0)
Block(-2,8,-4,AIR:0)
Block(-2,8,-3,AIR:0)
Block(-2,8,-2,AIR:0)
Block(-2,8,-1,AIR:0)
Block(-2,8,0,AIR:0)
Block(-2,8,1,AIR:0)
Block(-2,8,2,AIR:0)
Block(-2,8,3,AIR:0)
Block(-2,8,4,AIR:0)
Block(-2,8,5,AIR:0)
Block(-2,8,6,AIR:0)
Block(-2,8,7,AIR:0)
Block(-2,8,8,AIR:0)
Block(-2,8,9,AIR:0)
Block(-2,8,10,AIR:0)
Block(-2,8,11,AIR:0)
Block(-2,8,12,iceandfire:chared_cobblestone:0)
Block(-2,8,13,iceandfire:chared_stone:0)
Block(-2,8,14,quark:slate:0)
Block(-2,9,-13,STONE:0)
Block(-2,9,-12,quark:slate:0)
Block(-2,9,-11,iceandfire:frozen_stone:0)
Block(-2,9,-10,iceandfire:frozen_stone:0)
Block(-2,9,-9,quark:stone_speleothem:1)
Block(-2,9,-8,AIR:0)
Block(-2,9,-7,AIR:0)
Block(-2,9,-6,AIR:0)
Block(-2,9,-5,AIR:0)
Block(-2,9,-4,AIR:0)
Block(-2,9,-3,AIR:0)
Block(-2,9,-2,AIR:0)
Block(-2,9,-1,AIR:0)
Block(-2,9,0,AIR:0)
Block(-2,9,1,AIR:0)
Block(-2,9,2,AIR:0)
Block(-2,9,3,AIR:0)
Block(-2,9,4,AIR:0)
Block(-2,9,5,AIR:0)
Block(-2,9,6,AIR:0)
Block(-2,9,7,AIR:0)
Block(-2,9,8,AIR:0)
Block(-2,9,9,AIR:0)
Block(-2,9,10,AIR:0)
Block(-2,9,11,AIR:0)
Block(-2,9,12,iceandfire:chared_stone:0)
Block(-2,9,13,quark:slate:0)
Block(-2,9,14,quark:slate:0)
Block(-2,10,-14,STONE:0)
Block(-2,10,-13,quark:slate:0)
Block(-2,10,-12,quark:slate:0)
Block(-2,10,-11,iceandfire:frozen_stone:0)
Block(-2,10,-10,rustic:mooncap_mushroom:0)
Block(-2,10,-9,quark:stone_speleothem:0)
Block(-2,10,-8,AIR:0)
Block(-2,10,-7,AIR:0)
Block(-2,10,-6,AIR:0)
Block(-2,10,-5,AIR:0)
Block(-2,10,-4,AIR:0)
Block(-2,10,-3,AIR:0)
Block(-2,10,-2,AIR:0)
Block(-2,10,-1,AIR:0)
Block(-2,10,0,AIR:0)
Block(-2,10,1,AIR:0)
Block(-2,10,2,AIR:0)
Block(-2,10,3,AIR:0)
Block(-2,10,4,AIR:0)
Block(-2,10,5,AIR:0)
Block(-2,10,6,AIR:0)
Block(-2,10,7,AIR:0)
Block(-2,10,8,AIR:0)
Block(-2,10,9,AIR:0)
Block(-2,10,10,AIR:0)
Block(-2,10,11,AIR:0)
Block(-2,10,12,iceandfire:chared_stone:0)
Block(-2,10,13,quark:slate:0)
Block(-2,11,-14,STONE:0)
Block(-2,11,-13,quark:slate:0)
Block(-2,11,-12,quark:slate:0)
Block(-2,11,-11,quark:stone_stairs:1)
Block(-2,11,-10,AIR:0)
Block(-2,11,-9,AIR:0)
Block(-2,11,-8,AIR:0)
Block(-2,11,-7,AIR:0)
Block(-2,11,-6,AIR:0)
Block(-2,11,-5,AIR:0)
Block(-2,11,-4,AIR:0)
Block(-2,11,-3,AIR:0)
Block(-2,11,-2,AIR:0)
Block(-2,11,-1,AIR:0)
Block(-2,11,0,AIR:0)
Block(-2,11,1,AIR:0)
Block(-2,11,2,AIR:0)
Block(-2,11,3,AIR:0)
Block(-2,11,4,AIR:0)
Block(-2,11,5,AIR:0)
Block(-2,11,6,AIR:0)
Block(-2,11,7,AIR:0)
Block(-2,11,8,AIR:0)
Block(-2,11,9,AIR:0)
Block(-2,11,10,AIR:0)
Block(-2,11,11,AIR:0)
Block(-2,11,12,AIR:0)
Block(-2,11,13,quark:slate:0)
Block(-2,12,-14,STONE:0)
Block(-2,12,-13,quark:slate:0)
Block(-2,12,-12,quark:slate:0)
Block(-2,12,-11,AIR:0)
Block(-2,12,-10,AIR:0)
Block(-2,12,-9,AIR:0)
Block(-2,12,-8,AIR:0)
Block(-2,12,-7,AIR:0)
Block(-2,12,-6,AIR:0)
Block(-2,12,-5,AIR:0)
Block(-2,12,-4,AIR:0)
Block(-2,12,-3,AIR:0)
Block(-2,12,-2,AIR:0)
Block(-2,12,-1,AIR:0)
Block(-2,12,0,AIR:0)
Block(-2,12,1,AIR:0)
Block(-2,12,2,AIR:0)
Block(-2,12,3,AIR:0)
Block(-2,12,4,AIR:0)
Block(-2,12,5,AIR:0)
Block(-2,12,6,AIR:0)
Block(-2,12,7,AIR:0)
Block(-2,12,8,AIR:0)
Block(-2,12,9,AIR:0)
Block(-2,12,10,AIR:0)
Block(-2,12,11,AIR:0)
Block(-2,12,12,quark:slate:0)
Block(-2,12,13,quark:slate:0)
Block(-2,13,-14,STONE:0)
Block(-2,13,-13,STONE:0)
Block(-2,13,-12,quark:slate:0)
Block(-2,13,-11,quark:stone_speleothem:0)
Block(-2,13,-10,AIR:0)
Block(-2,13,-9,AIR:0)
Block(-2,13,-8,AIR:0)
Block(-2,13,-7,AIR:0)
Block(-2,13,-6,AIR:0)
Block(-2,13,-5,AIR:0)
Block(-2,13,-4,AIR:0)
Block(-2,13,-3,AIR:0)
Block(-2,13,-2,AIR:0)
Block(-2,13,-1,AIR:0)
Block(-2,13,0,AIR:0)
Block(-2,13,1,AIR:0)
Block(-2,13,2,AIR:0)
Block(-2,13,3,AIR:0)
Block(-2,13,4,AIR:0)
Block(-2,13,5,AIR:0)
Block(-2,13,6,AIR:0)
Block(-2,13,7,AIR:0)
Block(-2,13,8,AIR:0)
Block(-2,13,9,AIR:0)
Block(-2,13,10,AIR:0)
Block(-2,13,11,quark:stone_stairs:6)
Block(-2,13,12,quark:slate:0)
Block(-2,13,13,quark:slate:0)
Block(-2,14,-14,STONE:0)
Block(-2,14,-13,iceandfire:dragon_ice_spikes:0)
Block(-2,14,-12,STONE:0)
Block(-2,14,-11,quark:stone_speleothem:1)
Block(-2,14,-10,AIR:0)
Block(-2,14,-9,AIR:0)
Block(-2,14,-8,AIR:0)
Block(-2,14,-7,AIR:0)
Block(-2,14,-6,AIR:0)
Block(-2,14,-5,quark:stone_speleothem:0)
Block(-2,14,-4,AIR:0)
Block(-2,14,-3,AIR:0)
Block(-2,14,-2,AIR:0)
Block(-2,14,-1,inspirations:rope:1)
Block(-2,14,0,AIR:0)
Block(-2,14,1,AIR:0)
Block(-2,14,2,AIR:0)
Block(-2,14,3,AIR:0)
Block(-2,14,4,AIR:0)
Block(-2,14,5,AIR:0)
Block(-2,14,6,AIR:0)
Block(-2,14,7,AIR:0)
Block(-2,14,8,AIR:0)
Block(-2,14,9,quark:slate:0)
Block(-2,14,10,quark:slate:0)
Block(-2,14,11,quark:slate:0)
Block(-2,14,12,quark:slate:0)
Block(-2,14,13,quark:slate:0)
Block(-2,15,-14,STONE:0)
Block(-2,15,-13,STONE:0)
Block(-2,15,-12,STONE:0)
Block(-2,15,-11,quark:stone_speleothem:2)
Block(-2,15,-10,AIR:0)
Block(-2,15,-9,AIR:0)
Block(-2,15,-8,AIR:0)
Block(-2,15,-7,AIR:0)
Block(-2,15,-6,AIR:0)
Block(-2,15,-5,quark:stone_speleothem:1)
Block(-2,15,-4,AIR:0)
Block(-2,15,-3,AIR:0)
Block(-2,15,-2,AIR:0)
Block(-2,15,-1,inspirations:rope:1)
Block(-2,15,0,AIR:0)
Block(-2,15,1,quark:stone_speleothem:0)
Block(-2,15,2,AIR:0)
Block(-2,15,3,AIR:0)
Block(-2,15,4,AIR:0)
Block(-2,15,5,AIR:0)
Block(-2,15,6,AIR:0)
Block(-2,15,7,quark:slate:0)
Block(-2,15,8,STONE:0)
Block(-2,15,9,STONE:0)
Block(-2,15,10,quark:slate:0)
Block(-2,15,11,quark:slate:0)
Block(-2,15,12,quark:slate:0)
Block(-2,16,-14,STONE:0)
Block(-2,16,-13,STONE:0)
Block(-2,16,-12,STONE:0)
Block(-2,16,-11,iceandfire:frozen_stone:0)
Block(-2,16,-10,AIR:0)
Block(-2,16,-9,AIR:0)
Block(-2,16,-8,AIR:0)
Block(-2,16,-7,AIR:0)
Block(-2,16,-6,AIR:0)
Block(-2,16,-5,quark:stone_speleothem:2)
Block(-2,16,-4,AIR:0)
Block(-2,16,-3,AIR:0)
Block(-2,16,-2,AIR:0)
Block(-2,16,-1,inspirations:rope:1)
Block(-2,16,0,AIR:0)
Block(-2,16,1,quark:stone_speleothem:1)
Block(-2,16,2,AIR:0)
Block(-2,16,3,quark:stone_stairs:6)
Block(-2,16,4,quark:slate:0)
Block(-2,16,5,quark:slate:0)
Block(-2,16,6,quark:slate:0)
Block(-2,16,7,STONE:0)
Block(-2,16,8,STONE:0)
Block(-2,16,9,STONE:0)
Block(-2,16,10,STONE:0)
Block(-2,17,-14,STONE:0)
Block(-2,17,-13,STONE:0)
Block(-2,17,-12,STONE:0)
Block(-2,17,-11,iceandfire:frozen_stone:0)
Block(-2,17,-10,iceandfire:frozen_stone:0)
Block(-2,17,-9,iceandfire:frozen_stone:0)
Block(-2,17,-8,iceandfire:frozen_stone:0)
Block(-2,17,-7,iceandfire:frozen_stone:0)
Block(-2,17,-6,STONE:0)
Block(-2,17,-5,quark:slate:0)
Block(-2,17,-4,quark:slate:0)
Block(-2,17,-3,quark:slate:0)
Block(-2,17,-2,quark:stone_stairs:7)
Block(-2,17,-1,inspirations:rope:1)
Block(-2,17,0,AIR:0)
Block(-2,17,1,quark:stone_speleothem:2)
Block(-2,17,2,quark:slate:0)
Block(-2,17,3,quark:slate:0)
Block(-2,17,4,quark:slate:0)
Block(-2,17,5,quark:slate:0)
Block(-2,17,7,STONE:0)
Block(-2,17,8,STONE:0)
Block(-2,17,9,STONE:0)
Block(-2,18,-14,STONE:0)
Block(-2,18,-13,STONE:0)
Block(-2,18,-12,STONE:0)
Block(-2,18,-11,iceandfire:frozen_stone:0)
Block(-2,18,-10,iceandfire:frozen_stone:0)
Block(-2,18,-9,iceandfire:frozen_stone:0)
Block(-2,18,-8,iceandfire:frozen_stone:0)
Block(-2,18,-7,iceandfire:frozen_stone:0)
Block(-2,18,-6,STONE:0)
Block(-2,18,-5,quark:slate:0)
Block(-2,18,-4,quark:slate:0)
Block(-2,18,-3,quark:slate:0)
Block(-2,18,-2,quark:slate:0)
Block(-2,18,-1,quark:slate:0)
Block(-2,18,0,STONE:0)
Block(-2,18,1,STONE:0)
Block(-2,18,2,quark:slate:0)
Block(-2,18,3,quark:slate:0)
Block(-2,18,4,quark:slate:0)
Block(-2,18,5,quark:slate:0)
Block(-2,18,7,STONE:0)
Block(-2,18,8,STONE:0)
Block(-2,18,9,STONE:0)
Block(-1,0,-2,STONE:0)
