
#######################################################################
# +-----------------------------------------------------------------+ #
# |                            BO3 object                           | #
# +-----------------------------------------------------------------+ #
#######################################################################

Author: NLBlackEagle

Description: No description given

Version: 3

SettingsMode: WriteWithoutComments


#######################################################################
# +-----------------------------------------------------------------+ #
# |                          Main settings                          | #
# +-----------------------------------------------------------------+ #
#######################################################################

Tree: true

Frequency: 180

Rarity: 100.0

RotateRandomly: true

SpawnHeight: randomY

SpawnHeightOffset: 0

SpawnHeightVariance: 0

##############################
# Height Limits for the BO3. #
##############################

MinHeight: 20

MaxHeight: 90

######################
# Extrusion settings #
######################

ExtrudeMode: None

ExtrudeThroughBlocks: AIR

MaxBranchDepth: 10

ExcludedBiomes: All


#######################################################################
# +-----------------------------------------------------------------+ #
# |                      Source block settings                      | #
# +-----------------------------------------------------------------+ #
#######################################################################

SourceBlocks: Solid

MaxPercentageOutsideSourceBlock: 5

OutsideSourceBlock: placeAnyway

DoReplaceBlocks: false

IsOTGPlus: false


#######################################################################
# +-----------------------------------------------------------------+ #
# |                              Blocks                             | #
# +-----------------------------------------------------------------+ #
#######################################################################

Block(-11,12,-7,STONE:0)
Block(-11,12,-6,STONE:0)
Block(-11,12,-5,STONE:0)
Block(-11,13,-7,STONE:0)
Block(-11,13,-6,STONE:0)
Block(-11,13,-5,STONE:0)
Block(-11,14,-7,STONE:0)
Block(-11,14,-6,STONE:0)
Block(-11,14,-5,quark:slate:0)
Block(-11,15,-5,quark:slate:0)
Block(-11,15,-4,quark:slate:0)
Block(-11,15,-3,quark:slate:0)
Block(-11,15,-2,STONE:0)
Block(-11,16,-5,iceandfire:frozen_stone:0)
Block(-11,16,-4,iceandfire:frozen_stone:0)
Block(-11,16,-3,iceandfire:frozen_stone:0)
Block(-11,16,-2,STONE:0)
Block(-11,17,-5,iceandfire:frozen_stone:0)
Block(-11,17,-4,iceandfire:frozen_stone:0)
Block(-11,17,-3,iceandfire:frozen_stone:0)
Block(-11,17,-2,STONE:0)
Block(-11,17,-1,STONE:0)
Block(-11,17,0,STONE:0)
Block(-11,18,-2,STONE:0)
Block(-11,18,-1,STONE:0)
Block(-11,18,0,STONE:0)
Block(-11,19,-2,STONE:0)
Block(-11,19,-1,STONE:0)
Block(-11,19,0,STONE:0)
Block(-10,11,-7,quark:slate:0)
Block(-10,11,-6,quark:slate:0)
Block(-10,11,-5,STONE:0)
Block(-10,12,-8,quark:slate:0)
Block(-10,12,-7,quark:slate:0)
Block(-10,12,-6,quark:slate:0)
Block(-10,12,-5,STONE:0)
Block(-10,12,-4,STONE:0)
Block(-10,12,-3,STONE:0)
Block(-10,12,-2,STONE:0)
Block(-10,12,1,STONE:0)
Block(-10,12,2,STONE:0)
Block(-10,12,3,STONE:0)
Block(-10,13,-8,quark:slate:0)
Block(-10,13,-7,quark:slate:0)
Block(-10,13,-6,quark:slate:0)
Block(-10,13,-5,quark:slate:0)
Block(-10,13,-4,quark:slate:0)
Block(-10,13,-3,quark:slate:0)
Block(-10,13,-2,STONE:0)
Block(-10,13,1,STONE:0)
Block(-10,13,2,STONE:0)
Block(-10,13,3,STONE:0)
Block(-10,13,4,STONE:0)
Block(-10,14,-8,STONE:0)
Block(-10,14,-7,STONE:0)
Block(-10,14,-6,quark:slate:0)
Block(-10,14,-5,quark:slate:0)
Block(-10,14,-4,quark:slate:0)
Block(-10,14,-3,quark:slate:0)
Block(-10,14,-2,quark:slate:0)
Block(-10,14,1,STONE:0)
Block(-10,14,2,STONE:0)
Block(-10,14,3,STONE:0)
Block(-10,14,4,STONE:0)
Block(-10,15,-7,STONE:0)
Block(-10,15,-6,quark:slate:0)
Block(-10,15,-5,iceandfire:frozen_stone:0)
Block(-10,15,-4,iceandfire:frozen_stone:0)
Block(-10,15,-3,iceandfire:frozen_stone:0)
Block(-10,15,-2,quark:slate:0)
Block(-10,15,-1,STONE:0)
Block(-10,15,0,STONE:0)
Block(-10,15,1,STONE:0)
Block(-10,15,2,STONE:0)
Block(-10,15,3,STONE:0)
Block(-10,15,4,STONE:0)
Block(-10,16,-6,iceandfire:frozen_stone:0)
Block(-10,16,-5,iceandfire:frozen_stone:0)
Block(-10,16,-4,iceandfire:frozen_stone:0)
Block(-10,16,-3,iceandfire:frozen_stone:0)
Block(-10,16,-2,iceandfire:frozen_stone:0)
Block(-10,16,-1,STONE:0)
Block(-10,16,0,STONE:0)
Block(-10,16,1,STONE:0)
Block(-10,16,2,STONE:0)
Block(-10,16,3,STONE:0)
Block(-10,17,-6,iceandfire:frozen_stone:0)
Block(-10,17,-5,iceandfire:frozen_stone:0)
Block(-10,17,-4,iceandfire:frozen_stone:0)
Block(-10,17,-3,iceandfire:frozen_stone:0)
Block(-10,17,-2,iceandfire:frozen_stone:0)
Block(-10,17,-1,STONE:0)
Block(-10,17,0,STONE:0)
Block(-10,17,1,STONE:0)
Block(-10,17,2,STONE:0)
Block(-10,17,3,STONE:0)
Block(-10,18,-5,iceandfire:frozen_stone:0)
Block(-10,18,-4,iceandfire:frozen_stone:0)
Block(-10,18,-3,iceandfire:frozen_stone:0)
Block(-10,18,-2,iceandfire:frozen_stone:0)
Block(-10,18,-1,STONE:0)
Block(-10,18,0,STONE:0)
Block(-10,18,1,STONE:0)
Block(-10,18,2,STONE:0)
Block(-10,18,3,STONE:0)
Block(-10,19,-3,iceandfire:frozen_stone:0)
Block(-10,19,-2,STONE:0)
Block(-10,19,-1,STONE:0)
Block(-10,19,0,STONE:0)
Block(-10,19,1,STONE:0)
Block(-10,20,-2,STONE:0)
Block(-10,20,-1,STONE:0)
Block(-10,20,0,STONE:0)
Block(-10,20,1,STONE:0)
Block(-9,9,-7,STONE:0)
Block(-9,9,-6,STONE:0)
Block(-9,9,-5,STONE:0)
Block(-9,9,-3,STONE:0)
Block(-9,9,-2,STONE:0)
Block(-9,9,-1,STONE:0)
Block(-9,10,-8,quark:slate:0)
Block(-9,10,-7,quark:slate:0)
Block(-9,10,-6,quark:slate:0)
Block(-9,10,-5,STONE:0)
Block(-9,10,-4,STONE:0)
Block(-9,10,-3,STONE:0)
Block(-9,10,-2,STONE:0)
Block(-9,10,-1,STONE:0)
Block(-9,11,-9,quark:slate:0)
Block(-9,11,-8,quark:slate:0)
Block(-9,11,-7,quark:slate:0)
Block(-9,11,-6,quark:slate:0)
Block(-9,11,-5,quark:slate:0)
Block(-9,11,-4,STONE:0)
Block(-9,11,-3,STONE:0)
Block(-9,11,-2,STONE:0)
Block(-9,11,-1,STONE:0)
Block(-9,11,1,STONE:0)
Block(-9,11,2,STONE:0)
Block(-9,11,3,STONE:0)
Block(-9,12,-9,PACKED_ICE:0)
Block(-9,12,-8,PACKED_ICE:0)
Block(-9,12,-7,PACKED_ICE:0)
Block(-9,12,-6,quark:slate:0)
Block(-9,12,-5,quark:slate:0)
Block(-9,12,-4,STONE:0)
Block(-9,12,-3,STONE:0)
Block(-9,12,-2,STONE:0)
Block(-9,12,-1,quark:slate:0)
Block(-9,12,0,quark:slate:0)
Block(-9,12,1,quark:slate:0)
Block(-9,12,2,STONE:0)
Block(-9,12,3,STONE:0)
Block(-9,12,4,STONE:0)
Block(-9,13,-9,PACKED_ICE:0)
Block(-9,13,-8,PACKED_ICE:0)
Block(-9,13,-7,PACKED_ICE:0)
Block(-9,13,-6,quark:slate:0)
Block(-9,13,-5,quark:slate:0)
Block(-9,13,-4,quark:slate:0)
Block(-9,13,-3,quark:slate:0)
Block(-9,13,-2,STONE:0)
Block(-9,13,-1,quark:slate:0)
Block(-9,13,0,quark:slate:0)
Block(-9,13,1,quark:slate:0)
Block(-9,13,2,STONE:0)
Block(-9,13,3,STONE:0)
Block(-9,13,4,STONE:0)
Block(-9,13,5,STONE:0)
Block(-9,14,-8,PACKED_ICE:0)
Block(-9,14,-7,PACKED_ICE:0)
Block(-9,14,-6,quark:slate:0)
Block(-9,14,-5,quark:slate:0)
Block(-9,14,-4,quark:slate:0)
Block(-9,14,-3,quark:slate:0)
Block(-9,14,-2,quark:slate:0)
Block(-9,14,-1,quark:slate:0)
Block(-9,14,0,quark:slate:0)
Block(-9,14,1,quark:slate:0)
Block(-9,14,2,STONE:0)
Block(-9,14,3,STONE:0)
Block(-9,14,4,STONE:0)
Block(-9,14,5,STONE:0)
Block(-9,15,-7,STONE:0)
Block(-9,15,-6,quark:slate:0)
Block(-9,15,-5,iceandfire:frozen_stone:0)
Block(-9,15,-4,iceandfire:frozen_stone:0)
Block(-9,15,-3,iceandfire:frozen_stone:0)
Block(-9,15,-2,quark:slate:0)
Block(-9,15,-1,STONE:0)
Block(-9,15,0,AIR:0)
Block(-9,15,1,AIR:0)
Block(-9,15,2,AIR:0)
Block(-9,15,3,STONE:0)
Block(-9,15,4,STONE:0)
Block(-9,15,5,STONE:0)
Block(-9,16,-7,STONE:0)
Block(-9,16,-6,iceandfire:frozen_stone:0)
Block(-9,16,-5,iceandfire:frozen_stone:0)
Block(-9,16,-4,iceandfire:frozen_stone:0)
Block(-9,16,-3,iceandfire:frozen_stone:0)
Block(-9,16,-2,iceandfire:frozen_stone:0)
Block(-9,16,-1,AIR:0)
Block(-9,16,0,AIR:0)
Block(-9,16,1,AIR:0)
Block(-9,16,2,STONE:0)
Block(-9,16,3,STONE:0)
Block(-9,16,4,STONE:0)
Block(-9,17,-7,STONE:0)
Block(-9,17,-6,iceandfire:frozen_stone:0)
Block(-9,17,-5,iceandfire:frozen_stone:0)
Block(-9,17,-4,iceandfire:frozen_stone:0)
Block(-9,17,-3,iceandfire:frozen_stone:0)
Block(-9,17,-2,iceandfire:frozen_stone:0)
Block(-9,17,-1,AIR:0)
Block(-9,17,0,AIR:0)
Block(-9,17,1,STONE:0)
Block(-9,17,2,STONE:0)
Block(-9,17,3,STONE:0)
Block(-9,17,4,STONE:0)
Block(-9,18,-6,iceandfire:frozen_stone:0)
Block(-9,18,-5,iceandfire:frozen_stone:0)
Block(-9,18,-4,iceandfire:frozen_stone:0)
Block(-9,18,-3,iceandfire:frozen_stone:0)
Block(-9,18,-2,iceandfire:frozen_stone:0)
Block(-9,18,-1,iceandfire:frozen_stone:0)
Block(-9,18,0,AIR:0)
Block(-9,18,1,STONE:0)
Block(-9,18,2,STONE:0)
Block(-9,18,3,STONE:0)
Block(-9,18,4,STONE:0)
Block(-9,19,-3,iceandfire:frozen_stone:0)
Block(-9,19,-2,iceandfire:frozen_stone:0)
Block(-9,19,-1,iceandfire:frozen_stone:0)
Block(-9,19,0,STONE:0)
Block(-9,19,1,STONE:0)
Block(-9,19,2,STONE:0)
Block(-9,19,3,STONE:0)
Block(-9,19,4,STONE:0)
Block(-9,20,-2,STONE:0)
Block(-9,20,-1,STONE:0)
Block(-9,20,0,STONE:0)
Block(-9,20,1,STONE:0)
Block(-9,20,2,STONE:0)
Block(-9,20,3,STONE:0)
Block(-9,21,-1,STONE:0)
Block(-9,21,0,STONE:0)
Block(-9,21,1,STONE:0)
Block(-8,8,-7,STONE:0)
Block(-8,8,-6,STONE:0)
Block(-8,8,-5,STONE:0)
Block(-8,8,-3,STONE:0)
Block(-8,8,-2,STONE:0)
Block(-8,8,-1,STONE:0)
Block(-8,9,-8,STONE:0)
Block(-8,9,-7,STONE:0)
Block(-8,9,-6,STONE:0)
Block(-8,9,-5,STONE:0)
Block(-8,9,-4,biomesoplenty:flesh:0)
Block(-8,9,-3,STONE:0)
Block(-8,9,-2,STONE:0)
Block(-8,9,-1,STONE:0)
Block(-8,9,0,STONE:0)
Block(-8,9,2,STONE:0)
Block(-8,9,3,STONE:0)
Block(-8,9,4,STONE:0)
Block(-8,10,-9,STONE:0)
Block(-8,10,-8,quark:slate:0)
Block(-8,10,-7,quark:slate:0)
Block(-8,10,-6,biomesoplenty:flesh:0)
Block(-8,10,-5,biomesoplenty:flesh:0)
Block(-8,10,-4,PACKED_ICE:0)
Block(-8,10,-3,STONE:0)
Block(-8,10,-2,STONE:0)
Block(-8,10,-1,STONE:0)
Block(-8,10,0,STONE:0)
Block(-8,10,2,STONE:0)
Block(-8,10,3,STONE:0)
Block(-8,10,4,STONE:0)
Block(-8,11,-10,STONE:0)
Block(-8,11,-9,PACKED_ICE:0)
Block(-8,11,-8,PACKED_ICE:0)
Block(-8,11,-7,PACKED_ICE:0)
Block(-8,11,-6,biomesoplenty:flesh:0)
Block(-8,11,-5,AIR:0)
Block(-8,11,-4,PACKED_ICE:0)
Block(-8,11,-3,STONE:0)
Block(-8,11,-2,STONE:0)
Block(-8,11,-1,quark:slate:0)
Block(-8,11,0,quark:slate:0)
Block(-8,11,1,quark:slate:0)
Block(-8,11,2,STONE:0)
Block(-8,11,3,STONE:0)
Block(-8,11,4,STONE:0)
Block(-8,12,-10,PACKED_ICE:0)
Block(-8,12,-9,PACKED_ICE:0)
Block(-8,12,-8,PACKED_ICE:0)
Block(-8,12,-7,PACKED_ICE:0)
Block(-8,12,-6,BROWN_MUSHROOM:0)
Block(-8,12,-5,AIR:0)
Block(-8,12,-4,PACKED_ICE:0)
Block(-8,12,-3,STONE:0)
Block(-8,12,-2,quark:slate:0)
Block(-8,12,-1,quark:slate:0)
Block(-8,12,0,quark:slate:0)
Block(-8,12,1,quark:slate:0)
Block(-8,12,2,quark:slate:0)
Block(-8,12,3,STONE:0)
Block(-8,12,4,STONE:0)
Block(-8,13,-10,PACKED_ICE:0)
Block(-8,13,-9,iceandfire:frozen_stone:0)
Block(-8,13,-8,iceandfire:frozen_stone:0)
Block(-8,13,-7,iceandfire:frozen_stone:0)
Block(-8,13,-6,AIR:0)
Block(-8,13,-5,AIR:0)
Block(-8,13,-4,quark:slate:0)
Block(-8,13,-3,quark:slate:0)
Block(-8,13,-2,quark:slate:0)
Block(-8,13,-1,quark:slate:0)
Block(-8,13,0,quark:slate:0)
Block(-8,13,1,quark:slate:0)
Block(-8,13,2,quark:slate:0)
Block(-8,13,3,STONE:0)
Block(-8,13,4,STONE:0)
Block(-8,13,5,STONE:0)
Block(-8,14,-9,iceandfire:frozen_stone:0)
Block(-8,14,-8,iceandfire:frozen_stone:0)
Block(-8,14,-7,iceandfire:frozen_stone:0)
Block(-8,14,-6,AIR:0)
Block(-8,14,-5,quark:stone_speleothem:0)
Block(-8,14,-4,AIR:0)
Block(-8,14,-3,quark:slate:0)
Block(-8,14,-2,quark:slate:0)
Block(-8,14,-1,quark:slate:0)
Block(-8,14,0,quark:stone_speleothem:2)
Block(-8,14,1,AIR:0)
Block(-8,14,2,AIR:0)
Block(-8,14,3,STONE:0)
Block(-8,14,4,STONE:0)
Block(-8,14,5,STONE:0)
Block(-8,15,-9,iceandfire:frozen_stone:0)
Block(-8,15,-8,iceandfire:frozen_stone:0)
Block(-8,15,-7,iceandfire:frozen_stone:0)
Block(-8,15,-6,AIR:0)
Block(-8,15,-5,quark:stone_speleothem:1)
Block(-8,15,-4,AIR:0)
Block(-8,15,-3,quark:slate_speleothem:2)
Block(-8,15,-2,AIR:0)
Block(-8,15,-1,AIR:0)
Block(-8,15,0,quark:stone_speleothem:1)
Block(-8,15,1,AIR:0)
Block(-8,15,2,quark:stone_speleothem:0)
Block(-8,15,3,STONE:0)
Block(-8,15,4,STONE:0)
Block(-8,15,5,STONE:0)
Block(-8,16,-7,STONE:0)
Block(-8,16,-6,iceandfire:frozen_stone:0)
Block(-8,16,-5,quark:stone_speleothem:2)
Block(-8,16,-4,AIR:0)
Block(-8,16,-3,quark:slate_speleothem:1)
Block(-8,16,-2,AIR:0)
Block(-8,16,-1,AIR:0)
Block(-8,16,0,quark:stone_speleothem:0)
Block(-8,16,1,quark:stone_speleothem:0)
Block(-8,16,2,quark:stone_speleothem:1)
Block(-8,16,3,AIR:0)
Block(-8,16,4,STONE:0)
Block(-8,16,5,STONE:0)
Block(-8,17,-7,STONE:0)
Block(-8,17,-6,iceandfire:frozen_stone:0)
Block(-8,17,-5,iceandfire:frozen_stone:0)
Block(-8,17,-4,AIR:0)
Block(-8,17,-3,quark:slate_speleothem:2)
Block(-8,17,-2,AIR:0)
Block(-8,17,-1,AIR:0)
Block(-8,17,0,AIR:0)
Block(-8,17,1,quark:stone_speleothem:1)
Block(-8,17,2,quark:stone_speleothem:2)
Block(-8,17,3,STONE:0)
Block(-8,17,4,STONE:0)
Block(-8,17,5,STONE:0)
Block(-8,18,-7,STONE:0)
Block(-8,18,-6,iceandfire:frozen_stone:0)
Block(-8,18,-5,iceandfire:frozen_stone:0)
Block(-8,18,-4,iceandfire:frozen_stone:0)
Block(-8,18,-3,iceandfire:frozen_stone:0)
Block(-8,18,-2,iceandfire:frozen_stone:0)
Block(-8,18,-1,iceandfire:frozen_stone:0)
Block(-8,18,0,AIR:0)
Block(-8,18,1,quark:stone_speleothem:2)
Block(-8,18,2,STONE:0)
Block(-8,18,3,STONE:0)
Block(-8,18,4,STONE:0)
Block(-8,18,5,STONE:0)
Block(-8,19,-4,iceandfire:frozen_stone:0)
Block(-8,19,-3,iceandfire:frozen_stone:0)
Block(-8,19,-2,iceandfire:frozen_stone:0)
Block(-8,19,-1,iceandfire:frozen_stone:0)
Block(-8,19,0,iceandfire:frozen_stone:0)
Block(-8,19,1,STONE:0)
Block(-8,19,2,STONE:0)
Block(-8,19,3,STONE:0)
Block(-8,19,4,STONE:0)
Block(-8,19,5,STONE:0)
Block(-8,20,-4,STONE:0)
Block(-8,20,-3,iceandfire:frozen_stone:0)
Block(-8,20,-2,iceandfire:frozen_stone:0)
Block(-8,20,-1,iceandfire:frozen_stone:0)
Block(-8,20,0,STONE:0)
Block(-8,20,1,STONE:0)
Block(-8,20,2,STONE:0)
Block(-8,20,3,STONE:0)
Block(-8,20,4,STONE:0)
Block(-8,21,-1,STONE:0)
Block(-8,21,0,STONE:0)
Block(-8,21,1,STONE:0)
Block(-8,21,2,STONE:0)
Block(-8,21,3,STONE:0)
Block(-7,7,0,STONE:0)
Block(-7,7,1,STONE:0)
Block(-7,7,2,STONE:0)
Block(-7,8,-8,STONE:0)
Block(-7,8,-7,STONE:0)
Block(-7,8,-6,STONE:0)
Block(-7,8,-5,STONE:0)
Block(-7,8,-3,STONE:0)
Block(-7,8,-2,PACKED_ICE:0)
Block(-7,8,-1,PACKED_ICE:0)
Block(-7,8,0,PACKED_ICE:0)
Block(-7,8,1,PACKED_ICE:0)
Block(-7,8,2,PACKED_ICE:0)
Block(-7,8,3,PACKED_ICE:0)
Block(-7,8,4,STONE:0)
Block(-7,9,-9,STONE:0)
Block(-7,9,-8,STONE:0)
Block(-7,9,-7,STONE:0)
Block(-7,9,-6,PACKED_ICE:0)
Block(-7,9,-5,biomesoplenty:flesh:0)
Block(-7,9,-4,BONE_BLOCK:0)
Block(-7,9,-3,BONE_BLOCK:4)
Block(-7,9,-2,PACKED_ICE:0)
Block(-7,9,-1,PACKED_ICE:0)
Block(-7,9,0,PACKED_ICE:0)
Block(-7,9,1,PACKED_ICE:0)
Block(-7,9,2,PACKED_ICE:0)
Block(-7,9,3,PACKED_ICE:0)
Block(-7,9,4,STONE:0)
Block(-7,9,5,STONE:0)
Block(-7,10,-9,STONE:0)
Block(-7,10,-8,quark:slate:0)
Block(-7,10,-7,biomesoplenty:flesh:0)
Block(-7,10,-6,iceandfire:dragon_ice_spikes:0)
Block(-7,10,-5,contenttweaker:bone_pile:0)
Block(-7,10,-4,contenttweaker:bone_pile:0)
Block(-7,10,-3,BONE_BLOCK:0)
Block(-7,10,-2,PACKED_ICE:0)
Block(-7,10,-1,PACKED_ICE:0)
Block(-7,10,0,PACKED_ICE:0)
Block(-7,10,1,PACKED_ICE:0)
Block(-7,10,2,PACKED_ICE:0)
Block(-7,10,3,PACKED_ICE:0)
Block(-7,10,4,STONE:0)
Block(-7,10,5,STONE:0)
Block(-7,11,-10,STONE:0)
Block(-7,11,-9,PACKED_ICE:0)
Block(-7,11,-8,PACKED_ICE:0)
Block(-7,11,-7,BROWN_MUSHROOM:0)
Block(-7,11,-6,AIR:0)
Block(-7,11,-5,AIR:0)
Block(-7,11,-4,AIR:0)
Block(-7,11,-3,PACKED_ICE:0)
Block(-7,11,-2,quark:slate:0)
Block(-7,11,-1,quark:slate:0)
Block(-7,11,0,quark:slate:0)
Block(-7,11,1,quark:slate:0)
Block(-7,11,2,quark:slate:0)
Block(-7,11,3,STONE:0)
Block(-7,11,4,STONE:0)
Block(-7,11,5,STONE:0)
Block(-7,12,-10,PACKED_ICE:0)
Block(-7,12,-9,iceandfire:frozen_stone:0)
Block(-7,12,-8,iceandfire:frozen_stone:0)
Block(-7,12,-7,AIR:0)
Block(-7,12,-6,AIR:0)
Block(-7,12,-5,AIR:0)
Block(-7,12,-4,AIR:0)
Block(-7,12,-3,PACKED_ICE:0)
Block(-7,12,-2,quark:stone_speleothem:2)
Block(-7,12,-1,quark:slate:0)
Block(-7,12,0,quark:slate:0)
Block(-7,12,1,quark:slate:0)
Block(-7,12,2,quark:slate:0)
Block(-7,12,3,STONE:0)
Block(-7,12,4,STONE:0)
Block(-7,12,5,STONE:0)
Block(-7,13,-10,iceandfire:frozen_stone:0)
Block(-7,13,-9,iceandfire:frozen_stone:0)
Block(-7,13,-8,iceandfire:frozen_stone:0)
Block(-7,13,-7,AIR:0)
Block(-7,13,-6,AIR:0)
Block(-7,13,-5,AIR:0)
Block(-7,13,-4,AIR:0)
Block(-7,13,-3,iceandfire:dragon_ice_spikes:0)
Block(-7,13,-2,quark:stone_speleothem:1)
Block(-7,13,-1,AIR:0)
Block(-7,13,0,quark:slate:0)
Block(-7,13,1,AIR:0)
Block(-7,13,2,AIR:0)
Block(-7,13,3,STONE:0)
Block(-7,13,4,STONE:0)
Block(-7,13,5,STONE:0)
Block(-7,14,-10,iceandfire:frozen_stone:0)
Block(-7,14,-9,iceandfire:frozen_stone:0)
Block(-7,14,-8,iceandfire:frozen_stone:0)
Block(-7,14,-7,iceandfire:frozen_stone:0)
Block(-7,14,-6,AIR:0)
Block(-7,14,-5,AIR:0)
Block(-7,14,-4,AIR:0)
Block(-7,14,-3,AIR:0)
Block(-7,14,-2,quark:stone_speleothem:0)
Block(-7,14,-1,AIR:0)
Block(-7,14,0,AIR:0)
Block(-7,14,1,AIR:0)
Block(-7,14,2,AIR:0)
Block(-7,14,3,quark:stone_speleothem:2)
Block(-7,14,4,AIR:0)
Block(-7,14,5,STONE:0)
Block(-7,15,-10,iceandfire:frozen_stone:0)
Block(-7,15,-9,iceandfire:frozen_stone:0)
Block(-7,15,-8,iceandfire:frozen_stone:0)
Block(-7,15,-7,iceandfire:frozen_stone:0)
Block(-7,15,-6,AIR:0)
Block(-7,15,-5,AIR:0)
Block(-7,15,-4,AIR:0)
Block(-7,15,-3,AIR:0)
Block(-7,15,-2,AIR:0)
Block(-7,15,-1,AIR:0)
Block(-7,15,0,AIR:0)
Block(-7,15,1,AIR:0)
Block(-7,15,2,AIR:0)
Block(-7,15,3,quark:stone_speleothem:1)
Block(-7,15,4,AIR:0)
Block(-7,15,5,STONE:0)
Block(-7,15,6,STONE:0)
Block(-7,16,-9,iceandfire:frozen_stone:0)
Block(-7,16,-8,iceandfire:frozen_stone:0)
Block(-7,16,-7,iceandfire:frozen_stone:0)
Block(-7,16,-6,AIR:0)
Block(-7,16,-5,AIR:0)
Block(-7,16,-4,AIR:0)
Block(-7,16,-3,AIR:0)
Block(-7,16,-2,AIR:0)
Block(-7,16,-1,AIR:0)
Block(-7,16,0,AIR:0)
Block(-7,16,1,AIR:0)
Block(-7,16,2,AIR:0)
Block(-7,16,3,quark:stone_speleothem:0)
Block(-7,16,4,AIR:0)
Block(-7,16,5,STONE:0)
Block(-7,16,6,STONE:0)
Block(-7,17,-9,STONE:0)
Block(-7,17,-8,STONE:0)
Block(-7,17,-7,STONE:0)
Block(-7,17,-6,AIR:0)
Block(-7,17,-5,AIR:0)
Block(-7,17,-4,AIR:0)
Block(-7,17,-3,AIR:0)
Block(-7,17,-2,AIR:0)
Block(-7,17,-1,AIR:0)
Block(-7,17,0,AIR:0)
Block(-7,17,1,AIR:0)
Block(-7,17,2,AIR:0)
Block(-7,17,3,AIR:0)
Block(-7,17,4,AIR:0)
Block(-7,17,5,STONE:0)
Block(-7,17,6,STONE:0)
Block(-7,18,-8,STONE:0)
Block(-7,18,-7,STONE:0)
Block(-7,18,-6,STONE:0)
Block(-7,18,-5,iceandfire:frozen_stone:0)
Block(-7,18,-4,iceandfire:frozen_stone:0)
Block(-7,18,-3,iceandfire:frozen_stone:0)
Block(-7,18,-2,iceandfire:frozen_stone:0)
Block(-7,18,-1,iceandfire:frozen_stone:0)
Block(-7,18,0,AIR:0)
Block(-7,18,1,AIR:0)
Block(-7,18,2,AIR:0)
Block(-7,18,3,STONE:0)
Block(-7,18,4,STONE:0)
Block(-7,18,5,STONE:0)
Block(-7,18,6,STONE:0)
Block(-7,19,-7,STONE:0)
Block(-7,19,-6,STONE:0)
Block(-7,19,-5,STONE:0)
Block(-7,19,-4,iceandfire:frozen_stone:0)
Block(-7,19,-3,iceandfire:frozen_stone:0)
Block(-7,19,-2,iceandfire:frozen_stone:0)
Block(-7,19,-1,iceandfire:frozen_stone:0)
Block(-7,19,0,iceandfire:frozen_stone:0)
Block(-7,19,1,iceandfire:frozen_stone:0)
Block(-7,19,2,STONE:0)
Block(-7,19,3,STONE:0)
Block(-7,19,4,STONE:0)
Block(-7,19,5,STONE:0)
Block(-7,19,6,STONE:0)
Block(-7,20,-5,STONE:0)
Block(-7,20,-4,STONE:0)
Block(-7,20,-3,iceandfire:frozen_stone:0)
Block(-7,20,-2,iceandfire:frozen_stone:0)
Block(-7,20,-1,iceandfire:frozen_stone:0)
Block(-7,20,0,iceandfire:frozen_stone:0)
Block(-7,20,1,STONE:0)
Block(-7,20,2,STONE:0)
Block(-7,20,3,STONE:0)
Block(-7,20,4,STONE:0)
Block(-7,20,5,STONE:0)
Block(-7,21,-4,STONE:0)
Block(-7,21,-3,STONE:0)
Block(-7,21,-2,STONE:0)
Block(-7,21,-1,STONE:0)
Block(-7,21,0,STONE:0)
Block(-7,21,1,STONE:0)
Block(-7,21,2,STONE:0)
Block(-7,21,3,STONE:0)
Block(-6,6,0,STONE:0)
Block(-6,6,1,STONE:0)
Block(-6,6,2,STONE:0)
Block(-6,7,-8,STONE:0)
Block(-6,7,-7,STONE:0)
Block(-6,7,-6,STONE:0)
Block(-6,7,-5,STONE:0)
Block(-6,7,-4,STONE:0)
Block(-6,7,-1,PACKED_ICE:0)
Block(-6,7,0,PACKED_ICE:0)
Block(-6,7,1,PACKED_ICE:0)
Block(-6,7,2,PACKED_ICE:0)
Block(-6,7,3,PACKED_ICE:0)
Block(-6,8,-8,STONE:0)
Block(-6,8,-7,quark:slate:0)
Block(-6,8,-6,quark:slate:0)
Block(-6,8,-5,quark:slate:0)
Block(-6,8,-4,STONE:0)
Block(-6,8,-3,PACKED_ICE:0)
Block(-6,8,-2,PACKED_ICE:0)
Block(-6,8,-1,PACKED_ICE:0)
Block(-6,8,0,PACKED_ICE:0)
Block(-6,8,1,PACKED_ICE:0)
Block(-6,8,2,PACKED_ICE:0)
Block(-6,8,3,PACKED_ICE:0)
Block(-6,8,4,PACKED_ICE:0)
Block(-6,9,-9,STONE:0)
Block(-6,9,-8,STONE:0)
Block(-6,9,-7,quark:slate:0)
Block(-6,9,-6,PACKED_ICE:0)
Block(-6,9,-5,quark:stone_speleothem:2)
Block(-6,9,-4,SNOW:0)
Block(-6,9,-3,SNOW:0)
Block(-6,9,-2,contenttweaker:bone_pile:0)
Block(-6,9,-1,PACKED_ICE:0)
Block(-6,9,0,PACKED_ICE:0)
Block(-6,9,1,SNOW:0)
Block(-6,9,2,quark:stone_speleothem:2)
Block(-6,9,3,PACKED_ICE:0)
Block(-6,9,4,PACKED_ICE:0)
Block(-6,9,5,STONE:0)
Block(-6,10,-9,STONE:0)
Block(-6,10,-8,STONE:0)
Block(-6,10,-7,biomesoplenty:flesh:0)
Block(-6,10,-6,iceandfire:dragon_ice_spikes:0)
Block(-6,10,-5,quark:stone_speleothem:1)
Block(-6,10,-4,AIR:0)
Block(-6,10,-3,AIR:0)
Block(-6,10,-2,AIR:0)
Block(-6,10,-1,quark:stone_speleothem:2)
Block(-6,10,0,quark:stone_speleothem:2)
Block(-6,10,1,AIR:0)
Block(-6,10,2,quark:stone_speleothem:1)
Block(-6,10,3,PACKED_ICE:0)
Block(-6,10,4,PACKED_ICE:0)
Block(-6,10,5,STONE:0)
Block(-6,11,-10,STONE:0)
Block(-6,11,-9,PACKED_ICE:0)
Block(-6,11,-8,PACKED_ICE:0)
Block(-6,11,-7,BROWN_MUSHROOM:0)
Block(-6,11,-6,AIR:0)
Block(-6,11,-5,quark:stone_speleothem:0)
Block(-6,11,-4,AIR:0)
Block(-6,11,-3,AIR:0)
Block(-6,11,-2,AIR:0)
Block(-6,11,-1,quark:stone_speleothem:1)
Block(-6,11,0,quark:stone_speleothem:1)
Block(-6,11,1,AIR:0)
Block(-6,11,2,quark:stone_speleothem:0)
Block(-6,11,3,PACKED_ICE:0)
Block(-6,11,4,PACKED_ICE:0)
Block(-6,11,5,STONE:0)
Block(-6,12,-10,PACKED_ICE:0)
Block(-6,12,-9,iceandfire:frozen_stone:0)
Block(-6,12,-8,SNOW:0)
Block(-6,12,-7,AIR:0)
Block(-6,12,-6,AIR:0)
Block(-6,12,-5,AIR:0)
Block(-6,12,-4,AIR:0)
Block(-6,12,-3,AIR:0)
Block(-6,12,-2,AIR:0)
Block(-6,12,-1,AIR:0)
Block(-6,12,0,quark:stone_speleothem:0)
Block(-6,12,1,AIR:0)
Block(-6,12,2,AIR:0)
Block(-6,12,3,PACKED_ICE:0)
Block(-6,12,4,PACKED_ICE:0)
Block(-6,12,5,STONE:0)
Block(-6,12,6,STONE:0)
Block(-6,13,-10,iceandfire:frozen_stone:0)
Block(-6,13,-9,iceandfire:frozen_stone:0)
Block(-6,13,-8,iceandfire:frozen_stone:0)
Block(-6,13,-7,AIR:0)
Block(-6,13,-6,AIR:0)
Block(-6,13,-5,AIR:0)
Block(-6,13,-4,AIR:0)
Block(-6,13,-3,AIR:0)
Block(-6,13,-2,AIR:0)
Block(-6,13,-1,AIR:0)
Block(-6,13,0,AIR:0)
Block(-6,13,1,AIR:0)
Block(-6,13,2,AIR:0)
Block(-6,13,3,iceandfire:dragon_ice_spikes:0)
Block(-6,13,4,iceandfire:dragon_ice_spikes:0)
Block(-6,13,5,STONE:0)
Block(-6,13,6,STONE:0)
Block(-6,14,-10,iceandfire:frozen_stone:0)
Block(-6,14,-9,iceandfire:frozen_stone:0)
Block(-6,14,-8,iceandfire:frozen_stone:0)
Block(-6,14,-7,AIR:0)
Block(-6,14,-6,AIR:0)
Block(-6,14,-5,AIR:0)
Block(-6,14,-4,AIR:0)
Block(-6,14,-3,AIR:0)
Block(-6,14,-2,AIR:0)
Block(-6,14,-1,AIR:0)
Block(-6,14,0,AIR:0)
Block(-6,14,1,AIR:0)
Block(-6,14,2,AIR:0)
Block(-6,14,3,AIR:0)
Block(-6,14,4,AIR:0)
Block(-6,14,5,STONE:0)
Block(-6,14,6,STONE:0)
Block(-6,15,-10,iceandfire:frozen_stone:0)
Block(-6,15,-9,iceandfire:frozen_stone:0)
Block(-6,15,-8,iceandfire:frozen_stone:0)
Block(-6,15,-7,iceandfire:frozen_stone:0)
Block(-6,15,-6,AIR:0)
Block(-6,15,-5,AIR:0)
Block(-6,15,-4,AIR:0)
Block(-6,15,-3,AIR:0)
Block(-6,15,-2,AIR:0)
Block(-6,15,-1,AIR:0)
Block(-6,15,0,AIR:0)
Block(-6,15,1,AIR:0)
Block(-6,15,2,AIR:0)
Block(-6,15,3,AIR:0)
Block(-6,15,4,AIR:0)
Block(-6,15,5,STONE:0)
Block(-6,15,6,STONE:0)
Block(-6,16,-10,STONE:0)
Block(-6,16,-9,iceandfire:frozen_stone:0)
Block(-6,16,-8,iceandfire:frozen_stone:0)
Block(-6,16,-7,iceandfire:frozen_stone:0)
Block(-6,16,-6,AIR:0)
Block(-6,16,-5,AIR:0)
Block(-6,16,-4,quark:stone_speleothem:0)
Block(-6,16,-3,quark:slate_speleothem:0)
Block(-6,16,-2,AIR:0)
Block(-6,16,-1,quark:stone_speleothem:0)
Block(-6,16,0,AIR:0)
Block(-6,16,1,AIR:0)
Block(-6,16,2,AIR:0)
Block(-6,16,3,AIR:0)
Block(-6,16,4,STONE:0)
Block(-6,16,5,STONE:0)
Block(-6,16,6,STONE:0)
Block(-6,17,-10,STONE:0)
Block(-6,17,-9,STONE:0)
Block(-6,17,-8,PACKED_ICE:0)
Block(-6,17,-7,PACKED_ICE:0)
Block(-6,17,-6,PACKED_ICE:0)
Block(-6,17,-5,AIR:0)
Block(-6,17,-4,quark:stone_speleothem:1)
Block(-6,17,-3,quark:slate_speleothem:1)
Block(-6,17,-2,AIR:0)
Block(-6,17,-1,quark:stone_speleothem:1)
Block(-6,17,0,AIR:0)
Block(-6,17,1,AIR:0)
Block(-6,17,2,AIR:0)
Block(-6,17,3,AIR:0)
Block(-6,17,4,STONE:0)
Block(-6,17,5,STONE:0)
Block(-6,17,6,STONE:0)
Block(-6,18,-9,STONE:0)
Block(-6,18,-8,STONE:0)
Block(-6,18,-7,STONE:0)
Block(-6,18,-6,STONE:0)
Block(-6,18,-5,STONE:0)
Block(-6,18,-4,quark:stone_speleothem:2)
Block(-6,18,-3,quark:slate_speleothem:2)
Block(-6,18,-2,AIR:0)
Block(-6,18,-1,quark:stone_speleothem:2)
Block(-6,18,0,AIR:0)
Block(-6,18,1,AIR:0)
Block(-6,18,2,AIR:0)
Block(-6,18,3,AIR:0)
Block(-6,18,4,STONE:0)
Block(-6,18,5,STONE:0)
Block(-6,18,6,STONE:0)
Block(-6,19,-7,STONE:0)
Block(-6,19,-6,STONE:0)
Block(-6,19,-5,STONE:0)
Block(-6,19,-4,iceandfire:frozen_stone:0)
Block(-6,19,-3,iceandfire:frozen_stone:0)
Block(-6,19,-2,iceandfire:frozen_stone:0)
Block(-6,19,-1,iceandfire:frozen_stone:0)
Block(-6,19,0,iceandfire:frozen_stone:0)
Block(-6,19,1,AIR:0)
Block(-6,19,2,iceandfire:frozen_stone:0)
Block(-6,19,3,STONE:0)
Block(-6,19,4,STONE:0)
Block(-6,19,5,STONE:0)
Block(-6,19,6,STONE:0)
Block(-6,20,-5,STONE:0)
Block(-6,20,-4,STONE:0)
Block(-6,20,-3,iceandfire:frozen_stone:0)
Block(-6,20,-2,iceandfire:frozen_stone:0)
Block(-6,20,-1,iceandfire:frozen_stone:0)
Block(-6,20,0,iceandfire:frozen_stone:0)
Block(-6,20,1,iceandfire:frozen_stone:0)
Block(-6,20,2,STONE:0)
Block(-6,20,3,STONE:0)
Block(-6,20,4,STONE:0)
Block(-6,20,5,STONE:0)
Block(-6,21,-4,STONE:0)
Block(-6,21,-3,STONE:0)
Block(-6,21,-2,iceandfire:frozen_stone:0)
Block(-6,21,-1,iceandfire:frozen_stone:0)
Block(-6,21,0,iceandfire:frozen_stone:0)
Block(-6,21,1,STONE:0)
Block(-6,21,2,STONE:0)
Block(-6,21,3,STONE:0)
Block(-5,6,-8,STONE:0)
Block(-5,6,-7,STONE:0)
Block(-5,6,-6,STONE:0)
Block(-5,6,-5,STONE:0)
Block(-5,6,-4,STONE:0)
Block(-5,6,0,STONE:0)
Block(-5,6,1,STONE:0)
Block(-5,6,2,STONE:0)
Block(-5,7,-9,STONE:0)
Block(-5,7,-8,STONE:0)
Block(-5,7,-7,quark:slate:0)
Block(-5,7,-6,quark:slate:0)
Block(-5,7,-5,quark:slate:0)
Block(-5,7,-4,STONE:0)
Block(-5,7,-3,STONE:0)
Block(-5,7,-2,PACKED_ICE:0)
Block(-5,7,-1,PACKED_ICE:0)
Block(-5,7,0,PACKED_ICE:0)
Block(-5,7,1,PACKED_ICE:0)
Block(-5,7,2,PACKED_ICE:0)
Block(-5,7,3,PACKED_ICE:0)
Block(-5,8,-9,STONE:0)
Block(-5,8,-8,quark:slate:0)
Block(-5,8,-7,quark:slate:0)
Block(-5,8,-6,quark:slate:0)
Block(-5,8,-5,quark:slate:0)
Block(-5,8,-4,quark:slate:0)
Block(-5,8,-3,biomesoplenty:flesh:0)
Block(-5,8,-2,biomesoplenty:flesh:0)
Block(-5,8,-1,biomesoplenty:flesh:0)
Block(-5,8,0,charm:rotten_flesh_block:0)
Block(-5,8,1,PACKED_ICE:0)
Block(-5,8,2,PACKED_ICE:0)
Block(-5,8,3,PACKED_ICE:0)
Block(-5,8,4,PACKED_ICE:0)
Block(-5,9,-10,quark:slate:0)
Block(-5,9,-9,quark:slate:0)
Block(-5,9,-8,quark:slate:0)
Block(-5,9,-7,quark:slate:0)
Block(-5,9,-6,biomesoplenty:flesh:0)
Block(-5,9,-5,AIR:0)
Block(-5,9,-4,AIR:0)
Block(-5,9,-3,AIR:0)
Block(-5,9,-2,rustic:mooncap_mushroom:0)
Block(-5,9,-1,BROWN_MUSHROOM:0)
Block(-5,9,0,BROWN_MUSHROOM:0)
Block(-5,9,1,SNOW:0)
Block(-5,9,2,contenttweaker:bone_pile:0)
Block(-5,9,3,PACKED_ICE:0)
Block(-5,9,4,PACKED_ICE:0)
Block(-5,9,5,STONE:0)
Block(-5,10,-11,quark:slate:0)
Block(-5,10,-10,quark:slate:0)
Block(-5,10,-9,quark:slate:0)
Block(-5,10,-8,quark:slate:0)
Block(-5,10,-7,iceandfire:dragon_ice_spikes:0)
Block(-5,10,-6,AIR:0)
Block(-5,10,-5,AIR:0)
Block(-5,10,-4,AIR:0)
Block(-5,10,-3,AIR:0)
Block(-5,10,-2,AIR:0)
Block(-5,10,-1,AIR:0)
Block(-5,10,0,AIR:0)
Block(-5,10,1,AIR:0)
Block(-5,10,2,AIR:0)
Block(-5,10,3,PACKED_ICE:0)
Block(-5,10,4,PACKED_ICE:0)
Block(-5,10,5,PACKED_ICE:0)
Block(-5,11,-11,quark:slate:0)
Block(-5,11,-10,quark:slate:0)
Block(-5,11,-9,quark:slate:0)
Block(-5,11,-8,quark:stone_speleothem:2)
Block(-5,11,-7,AIR:0)
Block(-5,11,-6,AIR:0)
Block(-5,11,-5,AIR:0)
Block(-5,11,-4,AIR:0)
Block(-5,11,-3,AIR:0)
Block(-5,11,-2,AIR:0)
Block(-5,11,-1,AIR:0)
Block(-5,11,0,AIR:0)
Block(-5,11,1,AIR:0)
Block(-5,11,2,AIR:0)
Block(-5,11,3,PACKED_ICE:0)
Block(-5,11,4,PACKED_ICE:0)
Block(-5,11,5,PACKED_ICE:0)
Block(-5,12,-11,STONE:0)
Block(-5,12,-10,STONE:0)
Block(-5,12,-9,iceandfire:frozen_stone:0)
Block(-5,12,-8,quark:stone_speleothem:1)
Block(-5,12,-7,AIR:0)
Block(-5,12,-6,AIR:0)
Block(-5,12,-5,AIR:0)
Block(-5,12,-4,AIR:0)
Block(-5,12,-3,AIR:0)
Block(-5,12,-2,AIR:0)
Block(-5,12,-1,AIR:0)
Block(-5,12,0,AIR:0)
Block(-5,12,1,AIR:0)
Block(-5,12,2,AIR:0)
Block(-5,12,3,PACKED_ICE:0)
Block(-5,12,4,PACKED_ICE:0)
Block(-5,12,5,PACKED_ICE:0)
Block(-5,12,6,STONE:0)
Block(-5,13,-10,iceandfire:frozen_stone:0)
Block(-5,13,-9,iceandfire:frozen_stone:0)
Block(-5,13,-8,quark:stone_speleothem:0)
Block(-5,13,-7,AIR:0)
Block(-5,13,-6,AIR:0)
Block(-5,13,-5,AIR:0)
Block(-5,13,-4,AIR:0)
Block(-5,13,-3,AIR:0)
Block(-5,13,-2,AIR:0)
Block(-5,13,-1,AIR:0)
Block(-5,13,0,AIR:0)
Block(-5,13,1,AIR:0)
Block(-5,13,2,AIR:0)
Block(-5,13,3,iceandfire:dragon_ice_spikes:0)
Block(-5,13,4,PACKED_ICE:0)
Block(-5,13,5,STONE:0)
Block(-5,13,6,STONE:0)
Block(-5,13,7,STONE:0)
Block(-5,13,8,STONE:0)
Block(-5,13,9,STONE:0)
Block(-5,14,-10,iceandfire:frozen_stone:0)
Block(-5,14,-9,iceandfire:frozen_stone:0)
Block(-5,14,-8,AIR:0)
Block(-5,14,-7,AIR:0)
Block(-5,14,-6,AIR:0)
Block(-5,14,-5,AIR:0)
Block(-5,14,-4,inspirations:rope:1)
Block(-5,14,-3,AIR:0)
Block(-5,14,-2,AIR:0)
Block(-5,14,-1,AIR:0)
Block(-5,14,0,AIR:0)
Block(-5,14,1,AIR:0)
Block(-5,14,2,AIR:0)
Block(-5,14,3,AIR:0)
Block(-5,14,4,PACKED_ICE:0)
Block(-5,14,5,STONE:0)
Block(-5,14,6,STONE:0)
Block(-5,14,7,STONE:0)
Block(-5,14,8,STONE:0)
Block(-5,14,9,STONE:0)
Block(-5,15,-10,iceandfire:frozen_stone:0)
Block(-5,15,-9,iceandfire:frozen_stone:0)
Block(-5,15,-8,iceandfire:frozen_stone:0)
Block(-5,15,-7,AIR:0)
Block(-5,15,-6,AIR:0)
Block(-5,15,-5,AIR:0)
Block(-5,15,-4,inspirations:rope:1)
Block(-5,15,-3,AIR:0)
Block(-5,15,-2,AIR:0)
Block(-5,15,-1,AIR:0)
Block(-5,15,0,AIR:0)
Block(-5,15,1,AIR:0)
Block(-5,15,2,AIR:0)
Block(-5,15,3,quark:stone_speleothem:0)
Block(-5,15,4,STONE:0)
Block(-5,15,5,STONE:0)
Block(-5,15,6,STONE:0)
Block(-5,15,7,STONE:0)
Block(-5,15,8,STONE:0)
Block(-5,15,9,STONE:0)
Block(-5,15,10,STONE:0)
Block(-5,16,-10,STONE:0)
Block(-5,16,-9,iceandfire:frozen_stone:0)
Block(-5,16,-8,iceandfire:frozen_stone:0)
Block(-5,16,-7,iceandfire:frozen_stone:0)
Block(-5,16,-6,AIR:0)
Block(-5,16,-5,AIR:0)
Block(-5,16,-4,inspirations:rope:1)
Block(-5,16,-3,AIR:0)
Block(-5,16,-2,AIR:0)
Block(-5,16,-1,AIR:0)
Block(-5,16,0,AIR:0)
Block(-5,16,1,AIR:0)
Block(-5,16,2,AIR:0)
Block(-5,16,3,quark:stone_speleothem:1)
Block(-5,16,4,STONE:0)
Block(-5,16,5,STONE:0)
Block(-5,16,6,STONE:0)
Block(-5,16,8,STONE:0)
Block(-5,16,9,STONE:0)
Block(-5,16,10,STONE:0)
Block(-5,17,-10,STONE:0)
Block(-5,17,-9,PACKED_ICE:0)
Block(-5,17,-8,PACKED_ICE:0)
Block(-5,17,-7,PACKED_ICE:0)
Block(-5,17,-6,PACKED_ICE:0)
Block(-5,17,-5,AIR:0)
Block(-5,17,-4,inspirations:rope:1)
Block(-5,17,-3,AIR:0)
Block(-5,17,-2,AIR:0)
Block(-5,17,-1,AIR:0)
Block(-5,17,0,AIR:0)
Block(-5,17,1,quark:stone_speleothem:0)
Block(-5,17,2,AIR:0)
Block(-5,17,3,quark:stone_speleothem:2)
Block(-5,17,4,STONE:0)
Block(-5,17,5,STONE:0)
Block(-5,17,6,STONE:0)
Block(-5,17,8,STONE:0)
Block(-5,17,9,STONE:0)
Block(-5,17,10,STONE:0)
Block(-5,18,-9,STONE:0)
Block(-5,18,-8,PACKED_ICE:0)
Block(-5,18,-7,PACKED_ICE:0)
Block(-5,18,-6,PACKED_ICE:0)
Block(-5,18,-5,STONE:0)
Block(-5,18,-4,STONE:0)
Block(-5,18,-3,AIR:0)
Block(-5,18,-2,AIR:0)
Block(-5,18,-1,AIR:0)
Block(-5,18,0,AIR:0)
Block(-5,18,1,quark:stone_speleothem:1)
Block(-5,18,2,AIR:0)
Block(-5,18,3,iceandfire:frozen_stone:0)
Block(-5,18,4,STONE:0)
Block(-5,18,5,STONE:0)
Block(-5,18,6,STONE:0)
Block(-5,19,-7,STONE:0)
Block(-5,19,-6,STONE:0)
Block(-5,19,-5,STONE:0)
Block(-5,19,-4,STONE:0)
Block(-5,19,-3,iceandfire:frozen_stone:0)
Block(-5,19,-2,iceandfire:frozen_stone:0)
Block(-5,19,-1,iceandfire:frozen_stone:0)
Block(-5,19,0,AIR:0)
Block(-5,19,1,quark:stone_speleothem:2)
Block(-5,19,2,iceandfire:frozen_stone:0)
Block(-5,19,3,STONE:0)
Block(-5,19,4,STONE:0)
Block(-5,19,5,STONE:0)
Block(-5,19,6,STONE:0)
Block(-5,20,-5,STONE:0)
Block(-5,20,-4,STONE:0)
Block(-5,20,-3,iceandfire:frozen_stone:0)
Block(-5,20,-2,iceandfire:frozen_stone:0)
Block(-5,20,-1,iceandfire:frozen_stone:0)
Block(-5,20,0,iceandfire:frozen_stone:0)
Block(-5,20,1,iceandfire:frozen_stone:0)
Block(-5,20,2,STONE:0)
Block(-5,20,3,STONE:0)
Block(-5,20,4,STONE:0)
Block(-5,20,5,STONE:0)
Block(-5,21,-4,STONE:0)
Block(-5,21,-3,STONE:0)
Block(-5,21,-2,iceandfire:frozen_stone:0)
Block(-5,21,-1,iceandfire:frozen_stone:0)
Block(-5,21,0,iceandfire:frozen_stone:0)
Block(-4,5,-6,STONE:0)
Block(-4,5,-5,STONE:0)
Block(-4,5,-4,STONE:0)
Block(-4,6,-8,STONE:0)
Block(-4,6,-7,STONE:0)
Block(-4,6,-6,STONE:0)
Block(-4,6,-5,STONE:0)
Block(-4,6,-4,STONE:0)
Block(-4,6,-3,STONE:0)
Block(-4,6,-2,STONE:0)
Block(-4,6,-1,quark:slate:0)
Block(-4,6,0,quark:slate:0)
Block(-4,6,1,quark:slate:0)
Block(-4,6,2,STONE:0)
Block(-4,7,-9,STONE:0)
Block(-4,7,-8,STONE:0)
Block(-4,7,-7,quark:slate:0)
Block(-4,7,-6,quark:slate:0)
Block(-4,7,-5,quark:slate:0)
Block(-4,7,-4,STONE:0)
Block(-4,7,-3,STONE:0)
Block(-4,7,-2,PACKED_ICE:0)
Block(-4,7,-1,PACKED_ICE:0)
Block(-4,7,0,PACKED_ICE:0)
Block(-4,7,1,PACKED_ICE:0)
Block(-4,7,2,PACKED_ICE:0)
Block(-4,7,3,PACKED_ICE:0)
Block(-4,8,-10,quark:slate:0)
Block(-4,8,-9,quark:slate:0)
Block(-4,8,-8,quark:slate:0)
Block(-4,8,-7,quark:slate:0)
Block(-4,8,-6,quark:slate:0)
Block(-4,8,-5,quark:slate:0)
Block(-4,8,-4,biomesoplenty:flesh:0)
Block(-4,8,-3,charm:rotten_flesh_block:0)
Block(-4,8,-2,BROWN_MUSHROOM:0)
Block(-4,8,-1,biomesoplenty:flesh:0)
Block(-4,8,0,charm:rotten_flesh_block:0)
Block(-4,8,1,charm:rotten_flesh_block:0)
Block(-4,8,2,PACKED_ICE:0)
Block(-4,8,3,PACKED_ICE:0)
Block(-4,9,-11,quark:slate:0)
Block(-4,9,-10,quark:slate:0)
Block(-4,9,-9,quark:slate:0)
Block(-4,9,-8,quark:slate:0)
Block(-4,9,-7,biomesoplenty:flesh:0)
Block(-4,9,-6,rustic:mooncap_mushroom:0)
Block(-4,9,-5,SNOW:0)
Block(-4,9,-4,AIR:0)
Block(-4,9,-3,AIR:0)
Block(-4,9,-2,AIR:0)
Block(-4,9,-1,AIR:0)
Block(-4,9,0,AIR:0)
Block(-4,9,1,AIR:0)
Block(-4,9,2,SNOW:0)
Block(-4,9,3,PACKED_ICE:0)
Block(-4,9,4,PACKED_ICE:0)
Block(-4,10,-12,quark:slate:0)
Block(-4,10,-11,quark:slate:0)
Block(-4,10,-10,quark:slate:0)
Block(-4,10,-9,quark:slate:0)
Block(-4,10,-8,contenttweaker:bone_pile:0)
Block(-4,10,-7,rustic:mooncap_mushroom:0)
Block(-4,10,-6,AIR:0)
Block(-4,10,-5,AIR:0)
Block(-4,10,-4,AIR:0)
Block(-4,10,-3,AIR:0)
Block(-4,10,-2,AIR:0)
Block(-4,10,-1,AIR:0)
Block(-4,10,0,AIR:0)
Block(-4,10,1,AIR:0)
Block(-4,10,2,AIR:0)
Block(-4,10,3,PACKED_ICE:0)
Block(-4,10,4,PACKED_ICE:0)
Block(-4,11,-12,quark:slate:0)
Block(-4,11,-11,quark:slate:0)
Block(-4,11,-10,quark:slate:0)
Block(-4,11,-9,quark:slate:0)
Block(-4,11,-8,AIR:0)
Block(-4,11,-7,AIR:0)
Block(-4,11,-6,AIR:0)
Block(-4,11,-5,AIR:0)
Block(-4,11,-4,AIR:0)
Block(-4,11,-3,AIR:0)
Block(-4,11,-2,AIR:0)
Block(-4,11,-1,AIR:0)
Block(-4,11,0,AIR:0)
Block(-4,11,1,AIR:0)
Block(-4,11,2,AIR:0)
Block(-4,11,3,PACKED_ICE:0)
Block(-4,11,4,PACKED_ICE:0)
Block(-4,11,5,PACKED_ICE:0)
Block(-4,11,7,STONE:0)
Block(-4,11,8,STONE:0)
Block(-4,11,9,STONE:0)
Block(-4,12,-12,STONE:0)
Block(-4,12,-11,quark:slate:0)
Block(-4,12,-10,quark:slate:0)
Block(-4,12,-9,quark:slate:0)
Block(-4,12,-8,AIR:0)
Block(-4,12,-7,AIR:0)
Block(-4,12,-6,AIR:0)
Block(-4,12,-5,AIR:0)
Block(-4,12,-4,AIR:0)
Block(-4,12,-3,AIR:0)
Block(-4,12,-2,AIR:0)
Block(-4,12,-1,AIR:0)
Block(-4,12,0,AIR:0)
Block(-4,12,1,AIR:0)
Block(-4,12,2,AIR:0)
Block(-4,12,3,iceandfire:dragon_ice_spikes:0)
Block(-4,12,4,PACKED_ICE:0)
Block(-4,12,5,PACKED_ICE:0)
Block(-4,12,6,STONE:0)
Block(-4,12,7,STONE:0)
Block(-4,12,8,STONE:0)
Block(-4,12,9,STONE:0)
Block(-4,13,-11,STONE:0)
Block(-4,13,-10,STONE:0)
Block(-4,13,-9,iceandfire:frozen_stone:0)
Block(-4,13,-8,AIR:0)
Block(-4,13,-7,AIR:0)
Block(-4,13,-6,AIR:0)
Block(-4,13,-5,AIR:0)
Block(-4,13,-4,AIR:0)
Block(-4,13,-3,AIR:0)
Block(-4,13,-2,AIR:0)
Block(-4,13,-1,AIR:0)
Block(-4,13,0,AIR:0)
Block(-4,13,1,AIR:0)
Block(-4,13,2,AIR:0)
Block(-4,13,3,quark:stone_speleothem:0)
Block(-4,13,4,PACKED_ICE:0)
Block(-4,13,5,PACKED_ICE:0)
Block(-4,13,6,STONE:0)
Block(-4,13,7,STONE:0)
Block(-4,13,8,STONE:0)
Block(-4,13,9,STONE:0)
Block(-4,13,10,STONE:0)
Block(-4,14,-10,STONE:0)
Block(-4,14,-9,iceandfire:frozen_stone:0)
Block(-4,14,-8,AIR:0)
Block(-4,14,-7,AIR:0)
Block(-4,14,-6,AIR:0)
Block(-4,14,-5,AIR:0)
Block(-4,14,-4,AIR:0)
Block(-4,14,-3,AIR:0)
Block(-4,14,-2,AIR:0)
Block(-4,14,-1,AIR:0)
Block(-4,14,0,AIR:0)
Block(-4,14,1,AIR:0)
Block(-4,14,2,AIR:0)
Block(-4,14,3,quark:stone_speleothem:1)
Block(-4,14,4,PACKED_ICE:0)
Block(-4,14,5,PACKED_ICE:0)
Block(-4,14,6,STONE:0)
Block(-4,14,7,STONE:0)
Block(-4,14,8,STONE:0)
Block(-4,14,9,quark:slate:0)
Block(-4,14,10,quark:slate:0)
Block(-4,15,-10,STONE:0)
Block(-4,15,-9,iceandfire:frozen_stone:0)
Block(-4,15,-8,iceandfire:frozen_stone:0)
Block(-4,15,-7,AIR:0)
Block(-4,15,-6,AIR:0)
Block(-4,15,-5,AIR:0)
Block(-4,15,-4,AIR:0)
Block(-4,15,-3,AIR:0)
Block(-4,15,-2,AIR:0)
Block(-4,15,-1,AIR:0)
Block(-4,15,0,AIR:0)
Block(-4,15,1,AIR:0)
Block(-4,15,2,AIR:0)
Block(-4,15,3,quark:stone_speleothem:2)
Block(-4,15,4,PACKED_ICE:0)
Block(-4,15,5,PACKED_ICE:0)
Block(-4,15,6,STONE:0)
Block(-4,15,7,STONE:0)
Block(-4,15,8,STONE:0)
Block(-4,15,9,quark:slate:0)
Block(-4,15,10,quark:slate:0)
Block(-4,15,11,quark:slate:0)
Block(-4,16,-10,STONE:0)
Block(-4,16,-9,PACKED_ICE:0)
Block(-4,16,-8,PACKED_ICE:0)
Block(-4,16,-7,PACKED_ICE:0)
Block(-4,16,-6,AIR:0)
Block(-4,16,-5,AIR:0)
Block(-4,16,-4,AIR:0)
Block(-4,16,-3,AIR:0)
Block(-4,16,-2,AIR:0)
Block(-4,16,-1,AIR:0)
Block(-4,16,0,AIR:0)
Block(-4,16,1,AIR:0)
Block(-4,16,2,AIR:0)
Block(-4,16,3,iceandfire:frozen_stone:0)
Block(-4,16,4,PACKED_ICE:0)
Block(-4,16,5,PACKED_ICE:0)
Block(-4,16,7,STONE:0)
Block(-4,16,8,STONE:0)
Block(-4,16,9,quark:slate:0)
Block(-4,16,10,quark:slate:0)
Block(-4,16,11,quark:slate:0)
Block(-4,17,-10,STONE:0)
Block(-4,17,-9,PACKED_ICE:0)
Block(-4,17,-8,PACKED_ICE:0)
Block(-4,17,-7,PACKED_ICE:0)
Block(-4,17,-6,PACKED_ICE:0)
Block(-4,17,-5,PACKED_ICE:0)
Block(-4,17,-4,AIR:0)
Block(-4,17,-3,AIR:0)
Block(-4,17,-2,AIR:0)
Block(-4,17,-1,AIR:0)
Block(-4,17,0,AIR:0)
Block(-4,17,1,AIR:0)
Block(-4,17,2,iceandfire:frozen_stone:0)
Block(-4,17,3,iceandfire:frozen_stone:0)
Block(-4,17,4,PACKED_ICE:0)
Block(-4,17,5,STONE:0)
Block(-4,17,7,STONE:0)
Block(-4,17,8,STONE:0)
Block(-4,17,9,STONE:0)
Block(-4,17,10,STONE:0)
Block(-4,17,11,STONE:0)
Block(-4,18,-9,STONE:0)
Block(-4,18,-8,PACKED_ICE:0)
Block(-4,18,-7,PACKED_ICE:0)
Block(-4,18,-6,PACKED_ICE:0)
Block(-4,18,-5,STONE:0)
Block(-4,18,-4,STONE:0)
Block(-4,18,-3,AIR:0)
Block(-4,18,-2,AIR:0)
Block(-4,18,-1,AIR:0)
Block(-4,18,0,AIR:0)
Block(-4,18,1,AIR:0)
Block(-4,18,2,AIR:0)
Block(-4,18,3,iceandfire:frozen_stone:0)
Block(-4,18,4,STONE:0)
Block(-4,18,5,STONE:0)
Block(-4,18,8,STONE:0)
Block(-4,18,9,STONE:0)
Block(-4,18,10,STONE:0)
Block(-4,19,-7,STONE:0)
Block(-4,19,-6,STONE:0)
Block(-4,19,-5,STONE:0)
Block(-4,19,-4,STONE:0)
Block(-4,19,-3,iceandfire:frozen_stone:0)
Block(-4,19,-2,iceandfire:frozen_stone:0)
Block(-4,19,-1,iceandfire:frozen_stone:0)
Block(-4,19,0,iceandfire:frozen_stone:0)
Block(-4,19,1,iceandfire:frozen_stone:0)
Block(-4,19,2,iceandfire:frozen_stone:0)
Block(-4,19,3,STONE:0)
Block(-4,19,4,STONE:0)
Block(-4,19,5,STONE:0)
Block(-4,20,-5,STONE:0)
Block(-4,20,-4,STONE:0)
Block(-4,20,-3,iceandfire:frozen_stone:0)
Block(-4,20,-2,iceandfire:frozen_stone:0)
Block(-4,20,-1,iceandfire:frozen_stone:0)
Block(-4,20,0,iceandfire:frozen_stone:0)
Block(-4,20,1,iceandfire:frozen_stone:0)
Block(-4,21,-3,STONE:0)
Block(-4,21,-2,iceandfire:frozen_stone:0)
Block(-4,21,-1,iceandfire:frozen_stone:0)
Block(-4,21,0,iceandfire:frozen_stone:0)
Block(-3,5,-6,STONE:0)
Block(-3,5,-5,STONE:0)
Block(-3,5,-4,STONE:0)
Block(-3,6,-10,STONE:0)
Block(-3,6,-9,STONE:0)
Block(-3,6,-8,biomesoplenty:flesh:0)
Block(-3,6,-7,BONE_BLOCK:4)
Block(-3,6,-6,STONE:0)
Block(-3,6,-5,STONE:0)
Block(-3,6,-4,STONE:0)
Block(-3,6,-3,STONE:0)
Block(-3,6,-2,STONE:0)
Block(-3,6,-1,quark:slate:0)
Block(-3,6,0,quark:slate:0)
Block(-3,7,-10,STONE:0)
Block(-3,7,-9,STONE:0)
Block(-3,7,-8,ICE:0)
Block(-3,7,-7,ICE:0)
Block(-3,7,-6,biomesoplenty:flesh:0)
Block(-3,7,-5,biomesoplenty:flesh:0)
Block(-3,7,-4,iceandfire:frozen_stone:0)
Block(-3,7,-3,iceandfire:frozen_stone:0)
Block(-3,7,-2,quark:slate:0)
Block(-3,7,-1,quark:slate:0)
Block(-3,7,0,quark:slate:0)
Block(-3,7,1,PACKED_ICE:0)
Block(-3,7,2,PACKED_ICE:0)
Block(-3,8,-11,quark:slate:0)
Block(-3,8,-10,quark:slate:0)
Block(-3,8,-9,charm:rotten_flesh_block:0)
Block(-3,8,-8,AIR:0)
Block(-3,8,-7,AIR:0)
Block(-3,8,-6,BROWN_MUSHROOM:0)
Block(-3,8,-5,AIR:0)
Block(-3,8,-4,SNOW:0)
Block(-3,8,-3,AIR:0)
Block(-3,8,-2,AIR:0)
Block(-3,8,-1,AIR:0)
Block(-3,8,0,BROWN_MUSHROOM:0)
Block(-3,8,1,contenttweaker:bone_pile:0)
Block(-3,8,2,biomesoplenty:flesh:0)
Block(-3,8,3,PACKED_ICE:0)
Block(-3,8,4,PACKED_ICE:0)
Block(-3,9,-11,quark:slate:0)
Block(-3,9,-10,quark:slate:0)
Block(-3,9,-9,rustic:mooncap_mushroom:0)
Block(-3,9,-8,AIR:0)
Block(-3,9,-7,AIR:0)
Block(-3,9,-6,AIR:0)
Block(-3,9,-5,AIR:0)
Block(-3,9,-4,AIR:0)
Block(-3,9,-3,AIR:0)
Block(-3,9,-2,AIR:0)
Block(-3,9,-1,AIR:0)
Block(-3,9,0,AIR:0)
Block(-3,9,1,AIR:0)
Block(-3,9,2,BROWN_MUSHROOM:0)
Block(-3,9,3,PACKED_ICE:0)
Block(-3,9,4,PACKED_ICE:0)
Block(-3,9,5,STONE:0)
Block(-3,10,-12,quark:slate:0)
Block(-3,10,-11,quark:slate:0)
Block(-3,10,-10,quark:slate:0)
Block(-3,10,-9,AIR:0)
Block(-3,10,-8,AIR:0)
Block(-3,10,-7,AIR:0)
Block(-3,10,-6,AIR:0)
Block(-3,10,-5,AIR:0)
Block(-3,10,-4,AIR:0)
Block(-3,10,-3,AIR:0)
Block(-3,10,-2,AIR:0)
Block(-3,10,-1,AIR:0)
Block(-3,10,0,AIR:0)
Block(-3,10,1,AIR:0)
Block(-3,10,2,AIR:0)
Block(-3,10,3,PACKED_ICE:0)
Block(-3,10,4,PACKED_ICE:0)
Block(-3,10,5,PACKED_ICE:0)
Block(-3,10,7,STONE:0)
Block(-3,10,8,STONE:0)
Block(-3,10,9,STONE:0)
Block(-3,11,-12,quark:slate:0)
Block(-3,11,-11,quark:slate:0)
Block(-3,11,-10,quark:slate:0)
Block(-3,11,-9,AIR:0)
Block(-3,11,-8,quark:stone_speleothem:0)
Block(-3,11,-7,AIR:0)
Block(-3,11,-6,AIR:0)
Block(-3,11,-5,AIR:0)
Block(-3,11,-4,AIR:0)
Block(-3,11,-3,AIR:0)
Block(-3,11,-2,AIR:0)
Block(-3,11,-1,AIR:0)
Block(-3,11,0,AIR:0)
Block(-3,11,1,AIR:0)
Block(-3,11,2,AIR:0)
Block(-3,11,3,PACKED_ICE:0)
Block(-3,11,4,PACKED_ICE:0)
Block(-3,11,5,PACKED_ICE:0)
Block(-3,11,6,STONE:0)
Block(-3,11,7,STONE:0)
Block(-3,11,8,STONE:0)
Block(-3,11,9,STONE:0)
Block(-3,11,10,STONE:0)
Block(-3,12,-12,STONE:0)
Block(-3,12,-11,quark:slate:0)
Block(-3,12,-10,quark:slate:0)
Block(-3,12,-9,quark:slate:0)
Block(-3,12,-8,quark:stone_speleothem:1)
Block(-3,12,-7,AIR:0)
Block(-3,12,-6,AIR:0)
Block(-3,12,-5,AIR:0)
Block(-3,12,-4,AIR:0)
Block(-3,12,-3,AIR:0)
Block(-3,12,-2,AIR:0)
Block(-3,12,-1,AIR:0)
Block(-3,12,0,AIR:0)
Block(-3,12,1,AIR:0)
Block(-3,12,2,AIR:0)
Block(-3,12,3,quark:stone_speleothem:2)
Block(-3,12,4,PACKED_ICE:0)
Block(-3,12,5,PACKED_ICE:0)
Block(-3,12,6,STONE:0)
Block(-3,12,7,STONE:0)
Block(-3,12,8,STONE:0)
Block(-3,12,9,STONE:0)
Block(-3,12,10,STONE:0)
Block(-3,13,-11,STONE:0)
Block(-3,13,-10,STONE:0)
Block(-3,13,-9,quark:slate:0)
Block(-3,13,-8,quark:stone_speleothem:2)
Block(-3,13,-7,AIR:0)
Block(-3,13,-6,AIR:0)
Block(-3,13,-5,AIR:0)
Block(-3,13,-4,AIR:0)
Block(-3,13,-3,AIR:0)
Block(-3,13,-2,AIR:0)
Block(-3,13,-1,AIR:0)
Block(-3,13,0,AIR:0)
Block(-3,13,1,AIR:0)
Block(-3,13,2,AIR:0)
Block(-3,13,3,quark:stone_speleothem:1)
Block(-3,13,4,PACKED_ICE:0)
Block(-3,13,5,PACKED_ICE:0)
Block(-3,13,6,STONE:0)
Block(-3,13,7,STONE:0)
Block(-3,13,8,STONE:0)
Block(-3,13,9,quark:slate:0)
Block(-3,13,10,quark:slate:0)
Block(-3,13,11,quark:slate:0)
Block(-3,13,12,quark:slate:0)
Block(-3,14,-11,STONE:0)
Block(-3,14,-10,STONE:0)
Block(-3,14,-9,quark:slate:0)
Block(-3,14,-8,PACKED_ICE:0)
Block(-3,14,-7,AIR:0)
Block(-3,14,-6,AIR:0)
Block(-3,14,-5,AIR:0)
Block(-3,14,-4,AIR:0)
Block(-3,14,-3,AIR:0)
Block(-3,14,-2,AIR:0)
Block(-3,14,-1,AIR:0)
Block(-3,14,0,AIR:0)
Block(-3,14,1,AIR:0)
Block(-3,14,2,AIR:0)
Block(-3,14,3,quark:stone_speleothem:2)
Block(-3,14,4,iceandfire:frozen_stone:0)
Block(-3,14,5,iceandfire:frozen_stone:0)
Block(-3,14,6,PACKED_ICE:0)
Block(-3,14,7,STONE:0)
Block(-3,14,8,quark:slate:0)
Block(-3,14,9,quark:slate:0)
Block(-3,14,10,quark:slate:0)
Block(-3,14,11,quark:slate:0)
Block(-3,14,12,quark:slate:0)
Block(-3,15,-10,STONE:0)
Block(-3,15,-9,PACKED_ICE:0)
Block(-3,15,-8,PACKED_ICE:0)
Block(-3,15,-7,PACKED_ICE:0)
Block(-3,15,-6,AIR:0)
Block(-3,15,-5,AIR:0)
Block(-3,15,-4,AIR:0)
Block(-3,15,-3,quark:slate_speleothem:0)
Block(-3,15,-2,AIR:0)
Block(-3,15,-1,AIR:0)
Block(-3,15,0,AIR:0)
Block(-3,15,1,AIR:0)
Block(-3,15,2,AIR:0)
Block(-3,15,3,iceandfire:frozen_stone:0)
Block(-3,15,4,iceandfire:frozen_stone:0)
Block(-3,15,5,iceandfire:frozen_stone:0)
Block(-3,15,6,PACKED_ICE:0)
Block(-3,15,7,STONE:0)
Block(-3,15,8,quark:slate:0)
Block(-3,15,9,quark:slate:0)
Block(-3,15,10,quark:slate:0)
Block(-3,15,11,quark:slate:0)
Block(-3,15,12,quark:slate:0)
Block(-3,16,-10,STONE:0)
Block(-3,16,-9,PACKED_ICE:0)
Block(-3,16,-8,PACKED_ICE:0)
Block(-3,16,-7,PACKED_ICE:0)
Block(-3,16,-6,PACKED_ICE:0)
Block(-3,16,-5,AIR:0)
Block(-3,16,-4,AIR:0)
Block(-3,16,-3,quark:slate_speleothem:1)
Block(-3,16,-2,AIR:0)
Block(-3,16,-1,AIR:0)
Block(-3,16,0,AIR:0)
Block(-3,16,1,AIR:0)
Block(-3,16,2,iceandfire:frozen_stone:0)
Block(-3,16,3,iceandfire:frozen_stone:0)
Block(-3,16,4,iceandfire:frozen_stone:0)
Block(-3,16,5,iceandfire:frozen_stone:0)
Block(-3,16,6,PACKED_ICE:0)
Block(-3,16,7,STONE:0)
Block(-3,16,8,quark:slate:0)
Block(-3,16,9,quark:slate:0)
Block(-3,16,10,quark:slate:0)
Block(-3,16,11,quark:slate:0)
Block(-3,16,12,quark:slate:0)
Block(-3,17,-10,STONE:0)
Block(-3,17,-9,PACKED_ICE:0)
Block(-3,17,-8,PACKED_ICE:0)
Block(-3,17,-7,PACKED_ICE:0)
Block(-3,17,-6,PACKED_ICE:0)
Block(-3,17,-5,PACKED_ICE:0)
Block(-3,17,-4,STONE:0)
Block(-3,17,-3,quark:slate_speleothem:2)
Block(-3,17,-2,AIR:0)
Block(-3,17,-1,AIR:0)
Block(-3,17,0,AIR:0)
Block(-3,17,1,AIR:0)
Block(-3,17,2,iceandfire:frozen_stone:0)
Block(-3,17,3,iceandfire:frozen_stone:0)
Block(-3,17,4,iceandfire:frozen_stone:0)
Block(-3,17,5,PACKED_ICE:0)
Block(-3,17,6,STONE:0)
Block(-3,17,7,STONE:0)
Block(-3,17,8,STONE:0)
Block(-3,17,9,quark:slate:0)
Block(-3,17,10,quark:slate:0)
Block(-3,17,11,quark:slate:0)
Block(-3,17,12,quark:slate:0)
Block(-3,18,-10,STONE:0)
Block(-3,18,-9,STONE:0)
Block(-3,18,-8,PACKED_ICE:0)
Block(-3,18,-7,PACKED_ICE:0)
Block(-3,18,-6,PACKED_ICE:0)
Block(-3,18,-5,STONE:0)
Block(-3,18,-4,STONE:0)
Block(-3,18,-3,STONE:0)
Block(-3,18,-2,AIR:0)
Block(-3,18,-1,AIR:0)
Block(-3,18,0,AIR:0)
Block(-3,18,1,AIR:0)
Block(-3,18,2,iceandfire:frozen_stone:0)
Block(-3,18,3,iceandfire:frozen_stone:0)
Block(-3,18,4,iceandfire:frozen_stone:0)
Block(-3,18,8,STONE:0)
Block(-3,18,9,STONE:0)
Block(-3,18,10,STONE:0)
Block(-3,18,11,STONE:0)
Block(-3,19,-10,STONE:0)
Block(-3,19,-9,STONE:0)
Block(-3,19,-8,STONE:0)
Block(-3,19,-7,STONE:0)
Block(-3,19,-6,STONE:0)
Block(-3,19,-5,STONE:0)
Block(-3,19,-4,STONE:0)
Block(-3,19,-3,STONE:0)
Block(-3,19,-2,iceandfire:frozen_stone:0)
Block(-3,19,-1,iceandfire:frozen_stone:0)
Block(-3,19,0,iceandfire:frozen_stone:0)
Block(-3,19,1,STONE:0)
Block(-3,19,2,STONE:0)
Block(-3,19,3,STONE:0)
Block(-3,20,-8,STONE:0)
Block(-3,20,-7,STONE:0)
Block(-3,20,-6,STONE:0)
Block(-3,20,-5,STONE:0)
Block(-3,20,-4,STONE:0)
Block(-3,20,-3,STONE:0)
Block(-3,20,-2,iceandfire:frozen_stone:0)
Block(-3,20,-1,iceandfire:frozen_stone:0)
Block(-3,20,0,iceandfire:frozen_stone:0)
Block(-3,20,1,STONE:0)
Block(-3,21,-8,STONE:0)
Block(-3,21,-7,STONE:0)
Block(-3,21,-6,STONE:0)
Block(-3,21,-3,STONE:0)
Block(-3,21,-2,STONE:0)
Block(-3,21,-1,STONE:0)
Block(-2,5,-10,STONE:0)
Block(-2,5,-9,STONE:0)
Block(-2,5,-8,STONE:0)
Block(-2,5,-7,STONE:0)
Block(-2,5,-6,STONE:0)
Block(-2,5,-5,STONE:0)
Block(-2,5,-4,STONE:0)
Block(-2,5,-2,STONE:0)
Block(-2,5,-1,STONE:0)
Block(-2,5,0,quark:slate:0)
Block(-2,6,-11,STONE:0)
Block(-2,6,-10,STONE:0)
Block(-2,6,-9,STONE:0)
Block(-2,6,-8,BONE_BLOCK:0)
Block(-2,6,-7,BONE_BLOCK:4)
Block(-2,6,-6,iceandfire:frozen_stone:0)
Block(-2,6,-5,iceandfire:frozen_stone:0)
Block(-2,6,-4,iceandfire:frozen_stone:0)
Block(-2,6,-3,BONE_BLOCK:8)
Block(-2,6,-2,STONE:0)
Block(-2,6,-1,quark:slate:0)
Block(-2,6,0,quark:slate:0)
Block(-2,6,1,quark:slate:0)
Block(-2,7,-11,quark:slate:0)
Block(-2,7,-10,quark:slate:0)
Block(-2,7,-9,quark:slate:0)
Block(-2,7,-8,ICE:0)
Block(-2,7,-7,biomesoplenty:flesh:0)
Block(-2,7,-6,ICE:0)
Block(-2,7,-5,ICE:0)
Block(-2,7,-4,ICE:0)
Block(-2,7,-3,ICE:0)
Block(-2,7,-2,iceandfire:frozen_stone:0)
Block(-2,7,-1,quark:slate:0)
Block(-2,7,0,quark:slate:0)
Block(-2,7,1,PACKED_ICE:0)
Block(-2,7,2,PACKED_ICE:0)
Block(-2,7,3,PACKED_ICE:0)
Block(-2,7,4,STONE:0)
Block(-2,8,-12,quark:slate:0)
Block(-2,8,-11,quark:slate:0)
Block(-2,8,-10,quark:slate:0)
Block(-2,8,-9,biomesoplenty:flesh:0)
Block(-2,8,-8,AIR:0)
Block(-2,8,-7,SNOW:0)
Block(-2,8,-6,AIR:0)
Block(-2,8,-5,AIR:0)
Block(-2,8,-4,AIR:0)
Block(-2,8,-3,AIR:0)
Block(-2,8,-2,AIR:0)
Block(-2,8,-1,AIR:0)
Block(-2,8,0,SNOW:0)
Block(-2,8,1,SNOW:0)
Block(-2,8,2,contenttweaker:bone_pile:0)
Block(-2,8,3,PACKED_ICE:0)
Block(-2,8,4,PACKED_ICE:0)
Block(-2,8,5,STONE:0)
Block(-2,9,-12,quark:slate:0)
Block(-2,9,-11,quark:slate:0)
Block(-2,9,-10,biomesoplenty:flesh:0)
Block(-2,9,-9,BROWN_MUSHROOM:0)
Block(-2,9,-8,AIR:0)
Block(-2,9,-7,AIR:0)
Block(-2,9,-6,AIR:0)
Block(-2,9,-5,AIR:0)
Block(-2,9,-4,AIR:0)
Block(-2,9,-3,AIR:0)
Block(-2,9,-2,AIR:0)
Block(-2,9,-1,AIR:0)
Block(-2,9,0,AIR:0)
Block(-2,9,1,AIR:0)
Block(-2,9,2,AIR:0)
Block(-2,9,3,PACKED_ICE:0)
Block(-2,9,4,PACKED_ICE:0)
Block(-2,9,5,STONE:0)
Block(-2,9,6,STONE:0)
Block(-2,9,7,STONE:0)
Block(-2,9,8,STONE:0)
Block(-2,9,9,STONE:0)
Block(-2,10,-13,STONE:0)
Block(-2,10,-12,quark:slate:0)
Block(-2,10,-11,quark:slate:0)
Block(-2,10,-10,contenttweaker:bone_pile:0)
Block(-2,10,-9,AIR:0)
Block(-2,10,-8,AIR:0)
Block(-2,10,-7,AIR:0)
Block(-2,10,-6,AIR:0)
Block(-2,10,-5,AIR:0)
Block(-2,10,-4,AIR:0)
Block(-2,10,-3,AIR:0)
Block(-2,10,-2,AIR:0)
Block(-2,10,-1,AIR:0)
Block(-2,10,0,AIR:0)
Block(-2,10,1,AIR:0)
Block(-2,10,2,AIR:0)
Block(-2,10,3,quark:stone_speleothem:2)
Block(-2,10,4,PACKED_ICE:0)
Block(-2,10,5,quark:slate:0)
Block(-2,10,6,quark:slate:0)
Block(-2,10,7,STONE:0)
Block(-2,10,8,STONE:0)
Block(-2,10,9,STONE:0)
Block(-2,10,10,STONE:0)
Block(-2,11,-13,STONE:0)
Block(-2,11,-12,quark:slate:0)
Block(-2,11,-11,quark:slate:0)
Block(-2,11,-10,AIR:0)
Block(-2,11,-9,AIR:0)
Block(-2,11,-8,AIR:0)
Block(-2,11,-7,AIR:0)
Block(-2,11,-6,AIR:0)
Block(-2,11,-5,AIR:0)
Block(-2,11,-4,AIR:0)
Block(-2,11,-3,AIR:0)
Block(-2,11,-2,AIR:0)
Block(-2,11,-1,AIR:0)
Block(-2,11,0,AIR:0)
Block(-2,11,1,AIR:0)
Block(-2,11,2,AIR:0)
Block(-2,11,3,quark:stone_speleothem:1)
Block(-2,11,4,PACKED_ICE:0)
Block(-2,11,5,quark:slate:0)
Block(-2,11,6,quark:slate:0)
Block(-2,11,7,quark:slate:0)
Block(-2,11,8,STONE:0)
Block(-2,11,9,STONE:0)
Block(-2,11,10,STONE:0)
Block(-2,11,11,STONE:0)
Block(-2,12,-13,STONE:0)
Block(-2,12,-12,STONE:0)
Block(-2,12,-11,quark:slate:0)
Block(-2,12,-10,quark:stone_speleothem:2)
Block(-2,12,-9,AIR:0)
Block(-2,12,-8,AIR:0)
Block(-2,12,-7,AIR:0)
Block(-2,12,-6,AIR:0)
Block(-2,12,-5,AIR:0)
Block(-2,12,-4,AIR:0)
Block(-2,12,-3,AIR:0)
Block(-2,12,-2,AIR:0)
Block(-2,12,-1,AIR:0)
Block(-2,12,0,AIR:0)
Block(-2,12,1,AIR:0)
Block(-2,12,2,AIR:0)
Block(-2,12,3,quark:stone_speleothem:0)
Block(-2,12,4,PACKED_ICE:0)
Block(-2,12,5,PACKED_ICE:0)
Block(-2,12,6,quark:slate:0)
Block(-2,12,7,quark:slate:0)
Block(-2,12,8,STONE:0)
Block(-2,12,9,quark:slate:0)
Block(-2,12,10,quark:slate:0)
Block(-2,12,11,quark:slate:0)
Block(-2,12,12,STONE:0)
Block(-2,13,-12,STONE:0)
Block(-2,13,-11,STONE:0)
Block(-2,13,-10,quark:slate:0)
Block(-2,13,-9,AIR:0)
Block(-2,13,-8,AIR:0)
Block(-2,13,-7,AIR:0)
Block(-2,13,-6,AIR:0)
Block(-2,13,-5,AIR:0)
Block(-2,13,-4,AIR:0)
Block(-2,13,-3,AIR:0)
Block(-2,13,-2,AIR:0)
Block(-2,13,-1,AIR:0)
Block(-2,13,0,AIR:0)
Block(-2,13,1,AIR:0)
Block(-2,13,2,AIR:0)
Block(-2,13,3,AIR:0)
Block(-2,13,4,iceandfire:frozen_stone:0)
Block(-2,13,5,iceandfire:frozen_stone:0)
Block(-2,13,6,quark:slate:0)
Block(-2,13,7,quark:slate:0)
Block(-2,13,8,STONE:0)
Block(-2,13,9,AIR:0)
Block(-2,13,10,quark:slate:0)
Block(-2,13,11,quark:slate:0)
Block(-2,13,12,quark:slate:0)
Block(-2,13,13,STONE:0)
Block(-2,14,-12,STONE:0)
Block(-2,14,-11,STONE:0)
Block(-2,14,-10,quark:slate:0)
Block(-2,14,-9,AIR:0)
Block(-2,14,-8,AIR:0)
Block(-2,14,-7,AIR:0)
Block(-2,14,-6,AIR:0)
Block(-2,14,-5,AIR:0)
Block(-2,14,-4,AIR:0)
Block(-2,14,-3,AIR:0)
Block(-2,14,-2,AIR:0)
Block(-2,14,-1,AIR:0)
Block(-2,14,0,AIR:0)
Block(-2,14,1,AIR:0)
Block(-2,14,2,AIR:0)
Block(-2,14,3,AIR:0)
Block(-2,14,4,iceandfire:frozen_stone:0)
Block(-2,14,5,iceandfire:frozen_stone:0)
Block(-2,14,6,iceandfire:frozen_stone:0)
Block(-2,14,7,STONE:0)
Block(-2,14,8,AIR:0)
Block(-2,14,9,AIR:0)
Block(-2,14,10,quark:slate:0)
Block(-2,14,11,quark:slate:0)
Block(-2,14,12,quark:slate:0)
Block(-2,14,13,quark:slate:0)
Block(-2,15,-11,iceandfire:frozen_stone:0)
Block(-2,15,-10,iceandfire:frozen_stone:0)
Block(-2,15,-9,iceandfire:frozen_stone:0)
Block(-2,15,-8,PACKED_ICE:0)
Block(-2,15,-7,iceandfire:frozen_stone:0)
Block(-2,15,-6,iceandfire:frozen_stone:0)
Block(-2,15,-5,AIR:0)
Block(-2,15,-4,AIR:0)
Block(-2,15,-3,AIR:0)
Block(-2,15,-2,AIR:0)
Block(-2,15,-1,inspirations:rope:1)
Block(-2,15,0,AIR:0)
Block(-2,15,1,AIR:0)
Block(-2,15,2,AIR:0)
Block(-2,15,3,AIR:0)
Block(-2,15,4,iceandfire:frozen_stone:0)
Block(-2,15,5,iceandfire:frozen_stone:0)
Block(-2,15,6,iceandfire:frozen_stone:0)
Block(-2,15,7,STONE:0)
Block(-2,15,8,AIR:0)
Block(-2,15,9,AIR:0)
Block(-2,15,10,quark:slate:0)
Block(-2,15,11,quark:slate:0)
Block(-2,15,12,quark:slate:0)
Block(-2,15,13,quark:slate:0)
Block(-2,16,-11,iceandfire:frozen_stone:0)
Block(-2,16,-10,iceandfire:frozen_stone:0)
Block(-2,16,-9,iceandfire:frozen_stone:0)
Block(-2,16,-8,PACKED_ICE:0)
Block(-2,16,-7,iceandfire:frozen_stone:0)
Block(-2,16,-6,iceandfire:frozen_stone:0)
Block(-2,16,-5,iceandfire:frozen_stone:0)
Block(-2,16,-4,AIR:0)
Block(-2,16,-3,AIR:0)
Block(-2,16,-2,AIR:0)
Block(-2,16,-1,inspirations:rope:1)
Block(-2,16,0,AIR:0)
Block(-2,16,1,AIR:0)
Block(-2,16,2,AIR:0)
Block(-2,16,3,iceandfire:frozen_stone:0)
Block(-2,16,4,iceandfire:frozen_stone:0)
Block(-2,16,5,iceandfire:frozen_stone:0)
Block(-2,16,6,iceandfire:frozen_stone:0)
Block(-2,16,7,STONE:0)
Block(-2,16,8,AIR:0)
Block(-2,16,9,AIR:0)
Block(-2,16,10,quark:slate:0)
Block(-2,16,11,quark:slate:0)
Block(-2,16,12,quark:slate:0)
Block(-2,16,13,quark:slate:0)
Block(-2,17,-10,iceandfire:frozen_stone:0)
Block(-2,17,-9,iceandfire:frozen_stone:0)
Block(-2,17,-8,PACKED_ICE:0)
Block(-2,17,-7,iceandfire:frozen_stone:0)
Block(-2,17,-6,iceandfire:frozen_stone:0)
Block(-2,17,-5,iceandfire:frozen_stone:0)
Block(-2,17,-4,STONE:0)
Block(-2,17,-3,AIR:0)
Block(-2,17,-2,AIR:0)
Block(-2,17,-1,inspirations:rope:1)
Block(-2,17,0,AIR:0)
Block(-2,17,1,AIR:0)
Block(-2,17,2,iceandfire:frozen_stone:0)
Block(-2,17,3,iceandfire:frozen_stone:0)
Block(-2,17,4,iceandfire:frozen_stone:0)
Block(-2,17,5,iceandfire:frozen_stone:0)
Block(-2,17,6,STONE:0)
Block(-2,17,7,STONE:0)
Block(-2,17,8,STONE:0)
Block(-2,17,9,quark:slate:0)
Block(-2,17,10,quark:slate:0)
Block(-2,17,11,quark:slate:0)
Block(-2,17,12,quark:slate:0)
Block(-2,17,13,STONE:0)
Block(-2,18,-10,STONE:0)
Block(-2,18,-9,PACKED_ICE:0)
Block(-2,18,-8,PACKED_ICE:0)
Block(-2,18,-7,PACKED_ICE:0)
Block(-2,18,-6,PACKED_ICE:0)
Block(-2,18,-5,PACKED_ICE:0)
Block(-2,18,-4,STONE:0)
Block(-2,18,-3,STONE:0)
Block(-2,18,-2,STONE:0)
Block(-2,18,-1,inspirations:rope:1)
Block(-2,18,0,STONE:0)
Block(-2,18,1,iceandfire:frozen_stone:0)
Block(-2,18,2,iceandfire:frozen_stone:0)
Block(-2,18,3,iceandfire:frozen_stone:0)
Block(-2,18,4,iceandfire:frozen_stone:0)
Block(-2,18,5,iceandfire:frozen_stone:0)
Block(-2,18,6,STONE:0)
Block(-2,18,7,STONE:0)
Block(-2,18,8,STONE:0)
Block(-2,18,9,STONE:0)
Block(-2,18,10,STONE:0)
Block(-2,18,11,STONE:0)
Block(-2,18,12,STONE:0)
Block(-2,19,-12,STONE:0)
Block(-2,19,-11,STONE:0)
Block(-2,19,-10,REDSTONE_WIRE:0)
Block(-2,19,-9,REDSTONE_WIRE:0)
Block(-2,19,-8,REDSTONE_WIRE:0)
Block(-2,19,-7,REDSTONE_WIRE:0)
Block(-2,19,-6,REDSTONE_WIRE:0)
Block(-2,19,-5,REDSTONE_WIRE:0)
Block(-2,19,-4,REDSTONE_WIRE:0)
Block(-2,19,-3,REDSTONE_WIRE:0)
Block(-2,19,-2,REDSTONE_WIRE:0)
Block(-2,19,-1,STONE:0)
Block(-2,19,0,STONE:0)
Block(-2,19,1,STONE:0)
Block(-2,19,2,iceandfire:frozen_stone:0)
Block(-2,20,-12,STONE:0)
Block(-2,20,-11,STONE:0)
Block(-2,20,-10,STONE:0)
Block(-2,20,-9,STONE:0)
Block(-2,20,-8,STONE:0)
Block(-2,20,-7,STONE:0)
Block(-2,20,-6,STONE:0)
Block(-2,20,-5,STONE:0)
Block(-2,20,-4,STONE:0)
Block(-2,20,-3,STONE:0)
Block(-2,20,-2,STONE:0)
Block(-2,20,-1,STONE:0)
Block(-2,20,0,STONE:0)
Block(-2,20,1,STONE:0)
Block(-2,21,-12,STONE:0)
Block(-2,21,-11,STONE:0)
Block(-2,21,-10,STONE:0)
Block(-2,21,-9,STONE:0)
Block(-2,21,-8,STONE:0)
Block(-2,21,-7,STONE:0)
Block(-2,21,-6,STONE:0)
Block(-2,21,-5,STONE:0)
Block(-2,21,-3,STONE:0)
Block(-2,21,-2,STONE:0)
Block(-2,21,-1,STONE:0)
Block(-2,22,-8,STONE:0)
Block(-2,22,-7,STONE:0)
Block(-2,22,-6,STONE:0)
Block(-1,5,-10,STONE:0)
Block(-1,5,-9,STONE:0)
Block(-1,5,-8,STONE:0)
Block(-1,5,-7,biomesoplenty:flesh:0)
Block(-1,5,-6,biomesoplenty:flesh:0)
Block(-1,5,-5,iceandfire:frozen_stone:0)
Block(-1,5,-2,STONE:0)
Block(-1,5,-1,STONE:0)
Block(-1,5,0,quark:slate:0)
Block(-1,6,-13,STONE:0)
Block(-1,6,-12,STONE:0)
Block(-1,6,-11,STONE:0)
Block(-1,6,-10,STONE:0)
Block(-1,6,-9,STONE:0)
Block(-1,6,-8,biomesoplenty:flesh:0)
Block(-1,6,-7,biomesoplenty:flesh:0)
Block(-1,6,-6,biomesoplenty:flesh:0)
Block(-1,6,-5,biomesoplenty:blood:0)
Block(-1,6,-4,BONE_BLOCK:0)
Block(-1,6,-3,biomesoplenty:flesh:0)
Block(-1,6,-2,BONE_BLOCK:0)
Block(-1,6,-1,quark:slate:0)
Block(-1,6,0,quark:slate:0)
Block(-1,6,1,quark:slate:0)
Block(-1,6,2,quark:slate:0)
Block(-1,6,3,quark:slate:0)
Block(-1,6,4,STONE:0)
Block(-1,7,-13,quark:slate:0)
Block(-1,7,-12,quark:slate:0)
Block(-1,7,-11,quark:slate:0)
Block(-1,7,-10,quark:slate:0)
Block(-1,7,-9,ICE:0)
Block(-1,7,-8,ICE:0)
Block(-1,7,-7,ICE:0)
Block(-1,7,-6,ICE:0)
Block(-1,7,-5,ICE:0)
Block(-1,7,-4,BONE_BLOCK:0)
Block(-1,7,-3,ICE:0)
Block(-1,7,-2,ICE:0)
Block(-1,7,-1,iceandfire:frozen_stone:0)
Block(-1,7,0,iceandfire:frozen_stone:0)
Block(-1,7,1,charm:rotten_flesh_block:0)
Block(-1,7,2,quark:slate:0)
Block(-1,7,3,quark:slate:0)
Block(-1,7,4,STONE:0)
Block(-1,8,-13,quark:slate:0)
Block(-1,8,-12,quark:slate:0)
Block(-1,8,-11,quark:slate:0)
Block(-1,8,-10,biomesoplenty:flesh:0)
Block(-1,8,-9,AIR:0)
Block(-1,8,-8,AIR:0)
Block(-1,8,-7,AIR:0)
Block(-1,8,-6,AIR:0)
Block(-1,8,-5,AIR:0)
Block(-1,8,-4,BONE_BLOCK:0)
Block(-1,8,-3,AIR:0)
Block(-1,8,-2,AIR:0)
Block(-1,8,-1,AIR:0)
Block(-1,8,0,AIR:0)
Block(-1,8,1,AIR:0)
Block(-1,8,2,BROWN_MUSHROOM:0)
Block(-1,8,3,PACKED_ICE:0)
Block(-1,8,4,STONE:0)
Block(-1,8,5,STONE:0)
Block(-1,8,6,STONE:0)
Block(-1,8,7,STONE:0)
Block(-1,9,-13,quark:slate:0)
Block(-1,9,-12,quark:slate:0)
Block(-1,9,-11,quark:slate:0)
Block(-1,9,-10,charm:rotten_flesh_block:0)
Block(-1,9,-9,AIR:0)
Block(-1,9,-8,AIR:0)
Block(-1,9,-7,AIR:0)
Block(-1,9,-6,AIR:0)
Block(-1,9,-5,AIR:0)
Block(-1,9,-4,BONE_BLOCK:0)
Block(-1,9,-3,AIR:0)
Block(-1,9,-2,AIR:0)
Block(-1,9,-1,AIR:0)
Block(-1,9,0,AIR:0)
Block(-1,9,1,AIR:0)
Block(-1,9,2,AIR:0)
Block(-1,9,3,iceandfire:dragon_ice_spikes:0)
Block(-1,9,4,quark:slate:0)
Block(-1,9,5,quark:slate:0)
Block(-1,9,6,quark:slate:0)
Block(-1,9,7,STONE:0)
Block(-1,9,8,STONE:0)
Block(-1,9,9,STONE:0)
Block(-1,9,10,STONE:0)
Block(-1,10,-14,STONE:0)
Block(-1,10,-13,STONE:0)
Block(-1,10,-12,quark:slate:0)
Block(-1,10,-11,biomesoplenty:flesh:0)
Block(-1,10,-10,AIR:0)
Block(-1,10,-9,AIR:0)
Block(-1,10,-8,AIR:0)
Block(-1,10,-7,AIR:0)
Block(-1,10,-6,AIR:0)
Block(-1,10,-5,AIR:0)
Block(-1,10,-4,AIR:0)
Block(-1,10,-3,AIR:0)
Block(-1,10,-2,AIR:0)
Block(-1,10,-1,AIR:0)
Block(-1,10,0,AIR:0)
Block(-1,10,1,AIR:0)
Block(-1,10,2,AIR:0)
Block(-1,10,3,AIR:0)
Block(-1,10,4,quark:slate:0)
Block(-1,10,5,quark:slate:0)
Block(-1,10,6,quark:slate:0)
Block(-1,10,7,quark:slate:0)
Block(-1,10,8,STONE:0)
Block(-1,10,9,STONE:0)
Block(-1,10,10,STONE:0)
Block(-1,10,11,STONE:0)
Block(-1,11,-14,STONE:0)
Block(-1,11,-13,STONE:0)
Block(-1,11,-12,quark:slate:0)
Block(-1,11,-11,contenttweaker:bone_pile:0)
Block(-1,11,-10,quark:stone_speleothem:0)
Block(-1,11,-9,AIR:0)
Block(-1,11,-8,AIR:0)
Block(-1,11,-7,AIR:0)
Block(-1,11,-6,AIR:0)
Block(-1,11,-5,AIR:0)
Block(-1,11,-4,AIR:0)
Block(-1,11,-3,AIR:0)
Block(-1,11,-2,AIR:0)
Block(-1,11,-1,AIR:0)
Block(-1,11,0,AIR:0)
Block(-1,11,1,AIR:0)
Block(-1,11,2,AIR:0)
Block(-1,11,3,AIR:0)
Block(-1,11,4,quark:stone_speleothem:2)
Block(-1,11,5,quark:slate:0)
Block(-1,11,6,quark:slate:0)
Block(-1,11,7,quark:slate:0)
Block(-1,11,8,quark:slate:0)
Block(-1,11,9,BROWN_MUSHROOM:0)
Block(-1,11,10,quark:slate:0)
Block(-1,11,11,quark:slate:0)
Block(-1,11,12,STONE:0)
Block(-1,12,-14,STONE:0)
Block(-1,12,-13,STONE:0)
Block(-1,12,-12,quark:slate:0)
Block(-1,12,-11,quark:slate:0)
Block(-1,12,-10,quark:stone_speleothem:1)
Block(-1,12,-9,AIR:0)
Block(-1,12,-8,AIR:0)
Block(-1,12,-7,AIR:0)
Block(-1,12,-6,AIR:0)
Block(-1,12,-5,AIR:0)
Block(-1,12,-4,AIR:0)
Block(-1,12,-3,AIR:0)
Block(-1,12,-2,AIR:0)
Block(-1,12,-1,AIR:0)
Block(-1,12,0,AIR:0)
Block(-1,12,1,AIR:0)
Block(-1,12,2,AIR:0)
Block(-1,12,3,AIR:0)
Block(-1,12,4,quark:stone_speleothem:1)
Block(-1,12,5,quark:slate:0)
Block(-1,12,6,quark:slate:0)
Block(-1,12,7,quark:slate:0)
Block(-1,12,8,AIR:0)
Block(-1,12,9,AIR:0)
Block(-1,12,10,quark:slate:0)
Block(-1,12,11,quark:slate:0)
Block(-1,12,12,quark:slate:0)
Block(-1,13,-13,STONE:0)
Block(-1,13,-12,quark:slate:0)
Block(-1,13,-11,quark:slate:0)
Block(-1,13,-10,quark:stone_speleothem:2)
Block(-1,13,-9,AIR:0)
Block(-1,13,-8,quark:stone_speleothem:0)
Block(-1,13,-7,AIR:0)
Block(-1,13,-6,AIR:0)
Block(-1,13,-5,AIR:0)
Block(-1,13,-4,AIR:0)
Block(-1,13,-3,AIR:0)
Block(-1,13,-2,AIR:0)
Block(-1,13,-1,AIR:0)
Block(-1,13,0,AIR:0)
Block(-1,13,1,AIR:0)
Block(-1,13,2,AIR:0)
Block(-1,13,3,AIR:0)
Block(-1,13,4,quark:stone_speleothem:2)
Block(-1,13,5,iceandfire:frozen_stone:0)
Block(-1,13,6,quark:slate:0)
Block(-1,13,7,quark:slate:0)
Block(-1,13,8,AIR:0)
Block(-1,13,9,AIR:0)
Block(-1,13,10,quark:slate:0)
Block(-1,13,11,quark:slate:0)
Block(-1,13,12,quark:slate:0)
Block(-1,13,13,STONE:0)
Block(-1,14,-12,STONE:0)
Block(-1,14,-11,iceandfire:frozen_stone:0)
Block(-1,14,-10,iceandfire:frozen_stone:0)
Block(-1,14,-9,AIR:0)
Block(-1,14,-8,quark:stone_speleothem:1)
Block(-1,14,-7,AIR:0)
Block(-1,14,-6,AIR:0)
Block(-1,14,-5,quark:stone_speleothem:0)
Block(-1,14,-4,AIR:0)
Block(-1,14,-3,AIR:0)
Block(-1,14,-2,AIR:0)
Block(-1,14,-1,AIR:0)
Block(-1,14,0,AIR:0)
Block(-1,14,1,AIR:0)
Block(-1,14,2,AIR:0)
Block(-1,14,3,AIR:0)
Block(-1,14,4,iceandfire:frozen_stone:0)
Block(-1,14,5,iceandfire:frozen_stone:0)
Block(-1,14,6,iceandfire:frozen_stone:0)
Block(-1,14,7,quark:slate:0)
Block(-1,14,8,AIR:0)
Block(-1,14,9,AIR:0)
Block(-1,14,10,AIR:0)
Block(-1,14,11,quark:slate:0)
Block(-1,14,12,quark:slate:0)
Block(-1,14,13,quark:slate:0)
Block(-1,15,-12,iceandfire:frozen_stone:0)
Block(-1,15,-11,iceandfire:frozen_stone:0)
Block(-1,15,-10,iceandfire:frozen_stone:0)
Block(-1,15,-9,iceandfire:frozen_stone:0)
Block(-1,15,-8,quark:stone_speleothem:2)
Block(-1,15,-7,AIR:0)
Block(-1,15,-6,AIR:0)
Block(-1,15,-5,quark:stone_speleothem:1)
Block(-1,15,-4,AIR:0)
Block(-1,15,-3,AIR:0)
Block(-1,15,-2,AIR:0)
Block(-1,15,-1,AIR:0)
Block(-1,15,0,AIR:0)
Block(-1,15,1,AIR:0)
Block(-1,15,2,AIR:0)
Block(-1,15,3,AIR:0)
Block(-1,15,4,iceandfire:dragon_ice_spikes:0)
Block(-1,15,5,iceandfire:frozen_stone:0)
Block(-1,15,6,iceandfire:frozen_stone:0)
Block(-1,15,7,STONE:0)
Block(-1,15,8,AIR:0)
Block(-1,15,9,AIR:0)
Block(-1,15,10,AIR:0)
Block(-1,15,11,quark:slate:0)
Block(-1,15,12,quark:slate:0)
Block(-1,15,13,quark:slate:0)
Block(-1,16,-12,iceandfire:frozen_stone:0)
Block(-1,16,-11,iceandfire:frozen_stone:0)
Block(-1,16,-10,iceandfire:frozen_stone:0)
Block(-1,16,-9,iceandfire:frozen_stone:0)
Block(-1,16,-8,iceandfire:frozen_stone:0)
Block(-1,16,-7,iceandfire:frozen_stone:0)
Block(-1,16,-6,iceandfire:frozen_stone:0)
Block(-1,16,-5,quark:stone_speleothem:2)
Block(-1,16,-4,AIR:0)
Block(-1,16,-3,AIR:0)
Block(-1,16,-2,AIR:0)
Block(-1,16,-1,AIR:0)
Block(-1,16,0,AIR:0)
Block(-1,16,1,AIR:0)
Block(-1,16,2,AIR:0)
Block(-1,16,3,AIR:0)
Block(-1,16,4,iceandfire:frozen_stone:0)
Block(-1,16,5,iceandfire:frozen_stone:0)
Block(-1,16,6,iceandfire:frozen_stone:0)
Block(-1,16,7,quark:slate:0)
Block(-1,16,8,AIR:0)
Block(-1,16,9,AIR:0)
Block(-1,16,10,AIR:0)
Block(-1,16,11,quark:slate:0)
Block(-1,16,12,quark:slate:0)
Block(-1,16,13,quark:slate:0)
Block(-1,17,-14,STONE:0)
Block(-1,17,-13,STONE:0)
Block(-1,17,-12,iceandfire:frozen_stone:0)
Block(-1,17,-11,iceandfire:frozen_stone:0)
Block(-1,17,-10,iceandfire:frozen_stone:0)
Block(-1,17,-9,iceandfire:frozen_stone:0)
Block(-1,17,-8,iceandfire:frozen_stone:0)
Block(-1,17,-7,iceandfire:frozen_stone:0)
Block(-1,17,-6,iceandfire:frozen_stone:0)
Block(-1,17,-5,iceandfire:frozen_stone:0)
Block(-1,17,-4,iceandfire:frozen_stone:0)
Block(-1,17,-3,PACKED_ICE:0)
Block(-1,17,-2,iceandfire:frozen_stone:0)
Block(-1,17,-1,AIR:0)
Block(-1,17,0,AIR:0)
Block(-1,17,1,AIR:0)
Block(-1,17,2,iceandfire:frozen_stone:0)
Block(-1,17,3,iceandfire:frozen_stone:0)
Block(-1,17,4,iceandfire:frozen_stone:0)
Block(-1,17,5,iceandfire:frozen_stone:0)
Block(-1,17,6,quark:slate:0)
Block(-1,17,7,quark:slate:0)
Block(-1,17,8,quark:slate:0)
Block(-1,17,9,AIR:0)
Block(-1,17,10,quark:slate:0)
Block(-1,17,11,quark:slate:0)
Block(-1,17,12,quark:slate:0)
Block(-1,17,13,STONE:0)
Block(-1,18,-14,STONE:0)
Block(-1,18,-13,STONE:0)
Block(-1,18,-12,STONE:0)
Block(-1,18,-11,iceandfire:frozen_stone:0)
Block(-1,18,-10,PISTON_STICKY_BASE:5)
Block(-1,18,-9,PISTON_STICKY_BASE:5)
Block(-1,18,-8,PISTON_STICKY_BASE:5)
Block(-1,18,-7,PISTON_STICKY_BASE:5)
Block(-1,18,-6,PISTON_STICKY_BASE:5)
Block(-1,18,-5,PISTON_STICKY_BASE:5)
Block(-1,18,-4,PISTON_STICKY_BASE:5)
Block(-1,18,-3,PACKED_ICE:0)
Block(-1,18,-2,PACKED_ICE:0)
Block(-1,18,-1,PACKED_ICE:0)
Block(-1,18,0,AIR:0)
Block(-1,18,1,iceandfire:frozen_stone:0)
Block(-1,18,2,iceandfire:frozen_stone:0)
Block(-1,18,3,iceandfire:frozen_stone:0)
Block(-1,18,4,iceandfire:frozen_stone:0)
Block(-1,18,5,iceandfire:frozen_stone:0)
Block(-1,18,6,quark:slate:0)
Block(-1,18,7,quark:slate:0)
Block(-1,18,8,quark:slate:0)
Block(-1,18,9,quark:slate:0)
Block(-1,18,10,STONE:0)
Block(-1,18,11,STONE:0)
Block(-1,18,12,STONE:0)
Block(-1,19,-14,STONE:0)
Block(-1,19,-13,STONE:0)
Block(-1,19,-12,STONE:0)
Block(-1,19,-11,STONE:0)
Block(-1,19,-10,STONE:0)
Block(-1,19,-9,STONE:0)
Block(-1,19,-8,PACKED_ICE:0)
Block(-1,19,-7,PACKED_ICE:0)
Block(-1,19,-6,PACKED_ICE:0)
Block(-1,19,-5,PACKED_ICE:0)
Block(-1,19,-4,AIR:0)
Block(-1,19,-3,AIR:0)
Block(-1,19,-2,REDSTONE_WIRE:0)
Block(-1,19,-1,STONE:0)
Block(-1,19,0,STONE:0)
Block(-1,19,1,STONE:0)
Block(-1,19,2,iceandfire:frozen_stone:0)
Block(-1,19,3,iceandfire:frozen_stone:0)
Block(-1,20,-15,STONE:0)
Block(-1,20,-13,STONE:0)
Block(-1,20,-12,STONE:0)
Block(-1,20,-11,STONE:0)
Block(-1,20,-10,STONE:0)
Block(-1,20,-9,STONE:0)
Block(-1,20,-8,STONE:0)
Block(-1,20,-7,STONE:0)
Block(-1,20,-6,STONE:0)
Block(-1,20,-5,STONE:0)
Block(-1,20,-4,STONE:0)
Block(-1,20,-3,STONE:0)
Block(-1,20,-2,STONE:0)
Block(-1,20,-1,STONE:0)
Block(-1,20,0,STONE:0)
Block(-1,20,1,STONE:0)
Block(-1,21,-13,STONE:0)
Block(-1,21,-12,STONE:0)
Block(-1,21,-11,STONE:0)
Block(-1,21,-10,STONE:0)
Block(-1,21,-9,STONE:0)
Block(-1,21,-8,STONE:0)
Block(-1,21,-7,STONE:0)
Block(-1,21,-6,STONE:0)
Block(-1,21,-5,STONE:0)
Block(-1,21,-4,STONE:0)
Block(-1,21,-3,STONE:0)
Block(-1,21,-2,STONE:0)
Block(-1,22,-12,STONE:0)
Block(-1,22,-11,STONE:0)
Block(-1,22,-10,STONE:0)
Block(-1,22,-9,STONE:0)
Block(-1,22,-8,STONE:0)
Block(-1,22,-7,STONE:0)
Block(-1,22,-6,STONE:0)
Block(0,5,-13,STONE:0)
Block(0,5,-12,STONE:0)
Block(0,5,-11,STONE:0)
Block(0,5,-10,STONE:0)
Block(0,5,-9,STONE:0)
Block(0,5,-8,STONE:0)
Block(0,5,-7,STONE:0)
Block(0,5,-6,BONE_BLOCK:0)
Block(0,5,-5,biomesoplenty:flesh:0)
Block(0,5,-4,biomesoplenty:flesh:0)
Block(0,5,-3,STONE:0)
Block(0,5,-2,STONE:0)
Block(0,5,-1,STONE:0)
Block(0,5,0,quark:slate:0)
Block(0,5,1,quark:slate:0)
Block(0,5,2,quark:slate:0)
Block(0,5,3,STONE:0)
Block(0,5,4,STONE:0)
Block(0,6,-14,STONE:0)
Block(0,6,-13,quark:slate:0)
Block(0,6,-12,quark:slate:0)
Block(0,6,-11,quark:slate:0)
Block(0,6,-10,STONE:0)
Block(0,6,-9,biomesoplenty:blood:0)
Block(0,6,-8,biomesoplenty:blood:0)
Block(0,6,-7,biomesoplenty:blood:0)
Block(0,6,-6,biomesoplenty:blood:0)
Block(0,6,-5,biomesoplenty:blood:0)
Block(0,6,-4,biomesoplenty:blood:0)
Block(0,6,-3,biomesoplenty:blood:0)
Block(0,6,-2,biomesoplenty:blood:0)
Block(0,6,-1,quark:slate:0)
Block(0,6,0,quark:slate:0)
Block(0,6,1,quark:slate:0)
Block(0,6,2,quark:slate:0)
Block(0,6,3,quark:slate:0)
Block(0,6,4,STONE:0)
Block(0,6,5,STONE:0)
Block(0,7,-14,quark:slate:0)
Block(0,7,-13,quark:slate:0)
Block(0,7,-12,quark:slate:0)
Block(0,7,-11,ICE:0)
Block(0,7,-10,ICE:0)
Block(0,7,-9,ICE:0)
Block(0,7,-8,ICE:0)
Block(0,7,-7,ICE:0)
Block(0,7,-6,ICE:0)
Block(0,7,-5,ICE:0)
Block(0,7,-4,ICE:0)
Block(0,7,-3,ICE:0)
Block(0,7,-2,ICE:0)
Block(0,7,-1,ICE:0)
Block(0,7,0,iceandfire:frozen_stone:0)
Block(0,7,1,charm:rotten_flesh_block:0)
Block(0,7,2,biomesoplenty:flesh:0)
Block(0,7,3,quark:slate:0)
Block(0,7,4,STONE:0)
Block(0,7,5,STONE:0)
Block(0,7,6,STONE:0)
Block(0,8,-14,quark:slate:0)
Block(0,8,-13,quark:slate:0)
Block(0,8,-12,quark:slate:0)
Block(0,8,-11,AIR:0)
Block(0,8,-10,AIR:0)
Block(0,8,-9,AIR:0)
Block(0,8,-8,AIR:0)
Block(0,8,-7,AIR:0)
Block(0,8,-6,AIR:0)
Block(0,8,-5,AIR:0)
Block(0,8,-4,AIR:0)
Block(0,8,-3,AIR:0)
Block(0,8,-2,AIR:0)
Block(0,8,-1,AIR:0)
Block(0,8,0,quark:stone_speleothem:2)
Block(0,8,1,AIR:0)
Block(0,8,2,AIR:0)
Block(0,8,3,contenttweaker:bone_pile:0)
Block(0,8,4,quark:slate:0)
Block(0,8,5,quark:slate:0)
Block(0,8,6,STONE:0)
Block(0,8,7,STONE:0)
Block(0,8,8,STONE:0)
Block(0,8,9,STONE:0)
Block(0,8,10,STONE:0)
Block(0,9,-14,quark:slate:0)
Block(0,9,-13,quark:slate:0)
Block(0,9,-12,quark:slate:0)
Block(0,9,-11,AIR:0)
Block(0,9,-10,AIR:0)
Block(0,9,-9,AIR:0)
Block(0,9,-8,AIR:0)
Block(0,9,-7,AIR:0)
Block(0,9,-6,AIR:0)
Block(0,9,-5,AIR:0)
Block(0,9,-4,AIR:0)
Block(0,9,-3,AIR:0)
Block(0,9,-2,AIR:0)
Block(0,9,-1,AIR:0)
Block(0,9,0,quark:stone_speleothem:1)
Block(0,9,1,AIR:0)
Block(0,9,2,AIR:0)
Block(0,9,3,AIR:0)
Block(0,9,4,SNOW:0)
Block(0,9,5,quark:slate:0)
Block(0,9,6,quark:slate:0)
Block(0,9,7,STONE:0)
Block(0,9,8,STONE:0)
Block(0,9,9,STONE:0)
Block(0,9,10,STONE:0)
Block(0,9,11,STONE:0)
Block(0,10,-14,STONE:0)
Block(0,10,-13,quark:slate:0)
Block(0,10,-12,quark:slate:0)
Block(0,10,-11,AIR:0)
Block(0,10,-10,AIR:0)
Block(0,10,-9,AIR:0)
Block(0,10,-8,AIR:0)
Block(0,10,-7,AIR:0)
Block(0,10,-6,AIR:0)
Block(0,10,-5,AIR:0)
Block(0,10,-4,AIR:0)
Block(0,10,-3,AIR:0)
Block(0,10,-2,AIR:0)
Block(0,10,-1,AIR:0)
Block(0,10,0,quark:stone_speleothem:0)
Block(0,10,1,AIR:0)
Block(0,10,2,AIR:0)
Block(0,10,3,AIR:0)
Block(0,10,4,AIR:0)
Block(0,10,5,quark:stone_speleothem:2)
Block(0,10,6,quark:slate:0)
Block(0,10,7,quark:slate:0)
Block(0,10,8,rustic:mooncap_mushroom:0)
Block(0,10,9,quark:slate:0)
Block(0,10,10,quark:slate:0)
Block(0,10,11,quark:slate:0)
Block(0,10,12,STONE:0)
Block(0,11,-14,STONE:0)
Block(0,11,-13,quark:slate:0)
Block(0,11,-12,quark:slate:0)
Block(0,11,-11,AIR:0)
Block(0,11,-10,AIR:0)
Block(0,11,-9,AIR:0)
Block(0,11,-8,AIR:0)
Block(0,11,-7,AIR:0)
Block(0,11,-6,AIR:0)
Block(0,11,-5,AIR:0)
Block(0,11,-4,AIR:0)
Block(0,11,-3,AIR:0)
Block(0,11,-2,AIR:0)
Block(0,11,-1,AIR:0)
Block(0,11,0,AIR:0)
Block(0,11,1,AIR:0)
Block(0,11,2,AIR:0)
Block(0,11,3,AIR:0)
Block(0,11,4,AIR:0)
Block(0,11,5,quark:stone_speleothem:1)
Block(0,11,6,quark:stone_speleothem:2)
Block(0,11,7,rustic:mooncap_mushroom:0)
Block(0,11,8,AIR:0)
Block(0,11,9,biomesoplenty:flesh:0)
Block(0,11,10,quark:slate:0)
Block(0,11,11,quark:slate:0)
Block(0,11,12,STONE:0)
Block(0,12,-14,STONE:0)
Block(0,12,-13,quark:slate:0)
Block(0,12,-12,quark:slate:0)
Block(0,12,-11,AIR:0)
Block(0,12,-10,AIR:0)
Block(0,12,-9,AIR:0)
Block(0,12,-8,AIR:0)
Block(0,12,-7,AIR:0)
Block(0,12,-6,AIR:0)
Block(0,12,-5,AIR:0)
Block(0,12,-4,AIR:0)
Block(0,12,-3,AIR:0)
Block(0,12,-2,AIR:0)
Block(0,12,-1,AIR:0)
Block(0,12,0,AIR:0)
Block(0,12,1,AIR:0)
Block(0,12,2,AIR:0)
Block(0,12,3,AIR:0)
Block(0,12,4,AIR:0)
Block(0,12,5,quark:stone_speleothem:0)
Block(0,12,6,quark:stone_speleothem:1)
Block(0,12,7,AIR:0)
Block(0,12,8,AIR:0)
Block(0,12,9,AIR:0)
Block(0,12,10,quark:slate:0)
Block(0,12,11,quark:slate:0)
Block(0,12,12,quark:slate:0)
Block(0,13,-13,quark:slate:0)
Block(0,13,-12,quark:slate:0)
Block(0,13,-11,quark:slate:0)
Block(0,13,-10,AIR:0)
Block(0,13,-9,AIR:0)
Block(0,13,-8,AIR:0)
Block(0,13,-7,AIR:0)
Block(0,13,-6,AIR:0)
Block(0,13,-5,AIR:0)
Block(0,13,-4,AIR:0)
Block(0,13,-3,AIR:0)
Block(0,13,-2,AIR:0)
Block(0,13,-1,AIR:0)
Block(0,13,0,AIR:0)
Block(0,13,1,AIR:0)
Block(0,13,2,AIR:0)
Block(0,13,3,AIR:0)
Block(0,13,4,AIR:0)
Block(0,13,5,quark:slate_speleothem:0)
Block(0,13,6,quark:stone_speleothem:0)
Block(0,13,7,AIR:0)
Block(0,13,8,AIR:0)
Block(0,13,9,AIR:0)
Block(0,13,10,quark:stone_speleothem:2)
Block(0,13,11,quark:slate:0)
Block(0,13,12,quark:slate:0)
Block(0,13,13,STONE:0)
Block(0,14,-13,STONE:0)
Block(0,14,-12,iceandfire:frozen_stone:0)
Block(0,14,-11,iceandfire:frozen_stone:0)
Block(0,14,-10,quark:stone_speleothem:0)
Block(0,14,-9,AIR:0)
Block(0,14,-8,AIR:0)
Block(0,14,-7,AIR:0)
Block(0,14,-6,quark:slate_speleothem:0)
Block(0,14,-5,AIR:0)
Block(0,14,-4,AIR:0)
Block(0,14,-3,AIR:0)
Block(0,14,-2,quark:slate_speleothem:0)
Block(0,14,-1,AIR:0)
Block(0,14,0,AIR:0)
Block(0,14,1,AIR:0)
Block(0,14,2,AIR:0)
Block(0,14,3,AIR:0)
Block(0,14,4,AIR:0)
Block(0,14,5,quark:slate_speleothem:1)
Block(0,14,6,AIR:0)
Block(0,14,7,AIR:0)
Block(0,14,8,AIR:0)
Block(0,14,9,AIR:0)
Block(0,14,10,quark:stone_speleothem:1)
Block(0,14,11,quark:slate:0)
Block(0,14,12,quark:slate:0)
Block(0,14,13,quark:slate:0)
Block(0,15,-13,STONE:0)
Block(0,15,-12,iceandfire:frozen_stone:0)
Block(0,15,-11,iceandfire:frozen_stone:0)
Block(0,15,-10,quark:stone_speleothem:1)
Block(0,15,-9,AIR:0)
Block(0,15,-8,AIR:0)
Block(0,15,-7,AIR:0)
Block(0,15,-6,quark:slate_speleothem:1)
Block(0,15,-5,AIR:0)
Block(0,15,-4,AIR:0)
Block(0,15,-3,AIR:0)
Block(0,15,-2,quark:slate_speleothem:1)
Block(0,15,-1,AIR:0)
Block(0,15,0,AIR:0)
Block(0,15,1,quark:stone_speleothem:0)
Block(0,15,2,AIR:0)
Block(0,15,3,AIR:0)
Block(0,15,4,AIR:0)
Block(0,15,5,quark:slate_speleothem:2)
Block(0,15,6,AIR:0)
Block(0,15,7,AIR:0)
Block(0,15,8,AIR:0)
Block(0,15,9,AIR:0)
Block(0,15,10,quark:stone_speleothem:0)
Block(0,15,11,quark:slate:0)
Block(0,15,12,quark:slate:0)
Block(0,15,13,quark:slate:0)
Block(0,16,-14,STONE:0)
Block(0,16,-13,STONE:0)
Block(0,16,-12,iceandfire:frozen_stone:0)
Block(0,16,-11,iceandfire:frozen_stone:0)
Block(0,16,-10,quark:stone_speleothem:2)
Block(0,16,-9,AIR:0)
Block(0,16,-8,AIR:0)
Block(0,16,-7,AIR:0)
Block(0,16,-6,quark:slate_speleothem:2)
Block(0,16,-5,AIR:0)
Block(0,16,-4,AIR:0)
Block(0,16,-3,AIR:0)
Block(0,16,-2,quark:slate_speleothem:2)
Block(0,16,-1,AIR:0)
Block(0,16,0,AIR:0)
Block(0,16,1,quark:stone_speleothem:1)
Block(0,16,2,quark:stone_speleothem:1)
Block(0,16,3,AIR:0)
Block(0,16,4,AIR:0)
Block(0,16,5,iceandfire:frozen_stone:0)
Block(0,16,6,AIR:0)
Block(0,16,7,AIR:0)
Block(0,16,8,AIR:0)
Block(0,16,9,AIR:0)
Block(0,16,10,AIR:0)
Block(0,16,11,quark:slate:0)
Block(0,16,12,quark:slate:0)
Block(0,16,13,quark:slate:0)
Block(0,17,-14,STONE:0)
Block(0,17,-13,STONE:0)
Block(0,17,-12,iceandfire:frozen_stone:0)
Block(0,17,-11,iceandfire:frozen_stone:0)
Block(0,17,-10,iceandfire:frozen_stone:0)
Block(0,17,-9,iceandfire:frozen_stone:0)
Block(0,17,-8,iceandfire:frozen_stone:0)
Block(0,17,-7,iceandfire:frozen_stone:0)
Block(0,17,-6,iceandfire:frozen_stone:0)
Block(0,17,-5,iceandfire:frozen_stone:0)
Block(0,17,-4,iceandfire:frozen_stone:0)
Block(0,17,-3,PACKED_ICE:0)
Block(0,17,-2,PACKED_ICE:0)
Block(0,17,-1,PACKED_ICE:0)
Block(0,17,0,PACKED_ICE:0)
Block(0,17,1,quark:stone_speleothem:2)
Block(0,17,2,quark:stone_speleothem:2)
Block(0,17,3,iceandfire:frozen_stone:0)
Block(0,17,4,iceandfire:frozen_stone:0)
Block(0,17,5,iceandfire:frozen_stone:0)
Block(0,17,6,quark:slate:0)
Block(0,17,7,quark:slate:0)
Block(0,17,8,quark:slate:0)
Block(0,17,9,quark:slate:0)
Block(0,17,10,quark:slate:0)
Block(0,17,11,quark:slate:0)
Block(0,17,12,quark:slate:0)
Block(0,17,13,STONE:0)
Block(0,18,-15,STONE:0)
Block(0,18,-14,STONE:0)
Block(0,18,-13,STONE:0)
Block(0,18,-12,STONE:0)
Block(0,18,-11,iceandfire:frozen_stone:0)
Block(0,18,-10,AIR:0)
Block(0,18,-9,AIR:0)
Block(0,18,-8,AIR:0)
Block(0,18,-7,AIR:0)
Block(0,18,-6,AIR:0)
Block(0,18,-5,AIR:0)
Block(0,18,-4,AIR:0)
Block(0,18,-3,STONE:0)
Block(0,18,-2,PACKED_ICE:0)
Block(0,18,-1,PACKED_ICE:0)
Block(0,18,0,PACKED_ICE:0)
Block(0,18,1,iceandfire:frozen_stone:0)
Block(0,18,2,iceandfire:frozen_stone:0)
Block(0,18,3,iceandfire:frozen_stone:0)
Block(0,18,4,iceandfire:frozen_stone:0)
Block(0,18,5,iceandfire:frozen_stone:0)
Block(0,18,6,quark:slate:0)
Block(0,18,7,quark:slate:0)
Block(0,18,8,quark:slate:0)
Block(0,18,10,quark:slate:0)
Block(0,18,11,STONE:0)
Block(0,18,12,STONE:0)
Block(0,19,-15,STONE:0)
Block(0,19,-14,STONE:0)
Block(0,19,-13,AIR:0)
Block(0,19,-12,AIR:0)
Block(0,19,-11,STONE:0)
Block(0,19,-10,STONE:0)
Block(0,19,-9,STONE:0)
Block(0,19,-8,STONE:0)
Block(0,19,-7,STONE:0)
Block(0,19,-6,STONE:0)
Block(0,19,-5,STONE:0)
Block(0,19,-4,STONE:0)
Block(0,19,-3,PACKED_ICE:0)
Block(0,19,-2,REDSTONE_WIRE:0)
Block(0,19,-1,PACKED_ICE:0)
Block(0,19,0,STONE:0)
Block(0,19,1,STONE:0)
Block(0,19,2,iceandfire:frozen_stone:0)
Block(0,19,3,iceandfire:frozen_stone:0)
Block(0,19,4,iceandfire:frozen_stone:0)
Block(0,19,5,quark:slate:0)
Block(0,19,6,quark:slate:0)
Block(0,19,7,quark:slate:0)
Block(0,20,-14,STONE:0)
Block(0,20,-13,STONE:0)
Block(0,20,-12,AIR:0)
Block(0,20,-11,STONE:0)
Block(0,20,-10,STONE:0)
Block(0,20,-9,STONE:0)
Block(0,20,-8,AIR:0)
Block(0,20,-7,AIR:0)
Block(0,20,-6,STONE:0)
Block(0,20,-5,STONE:0)
Block(0,20,-4,STONE:0)
Block(0,20,-3,STONE:0)
Block(0,20,-2,STONE:0)
Block(0,20,-1,STONE:0)
Block(0,20,3,STONE:0)
Block(0,20,4,STONE:0)
Block(0,20,5,STONE:0)
Block(0,21,-15,STONE:0)
Block(0,21,-14,STONE:0)
Block(0,21,-13,STONE:0)
Block(0,21,-12,STONE:0)
Block(0,21,-11,STONE:0)
Block(0,21,-10,STONE:0)
Block(0,21,-9,AIR:0)
Block(0,21,-8,AIR:0)
Block(0,21,-7,AIR:0)
Block(0,21,-6,AIR:0)
Block(0,21,-5,STONE:0)
Block(0,21,-4,STONE:0)
Block(0,21,-3,STONE:0)
Block(0,21,-2,STONE:0)
Block(0,21,-1,STONE:0)
Block(0,22,-14,STONE:0)
Block(0,22,-13,STONE:0)
Block(0,22,-12,STONE:0)
Block(0,22,-11,STONE:0)
Block(0,22,-10,STONE:0)
Block(0,22,-9,STONE:0)
Block(0,22,-8,STONE:0)
Block(0,22,-7,STONE:0)
Block(0,22,-6,STONE:0)
Block(0,22,-4,STONE:0)
Block(0,22,-3,STONE:0)
Block(0,22,-2,STONE:0)
Block(1,5,-13,STONE:0)
Block(1,5,-12,STONE:0)
Block(1,5,-11,STONE:0)
Block(1,5,-10,STONE:0)
Block(1,5,-9,STONE:0)
Block(1,5,-8,BONE_BLOCK:0)
Block(1,5,-7,BONE_BLOCK:0)
Block(1,5,-6,biomesoplenty:flesh:0)
Block(1,5,-5,biomesoplenty:flesh:0)
Block(1,5,-4,biomesoplenty:flesh:0)
Block(1,5,-3,iceandfire:frozen_stone:0)
Block(1,5,-2,BONE_BLOCK:0)
Block(1,5,-1,STONE:0)
Block(1,5,0,STONE:0)
Block(1,5,1,STONE:0)
Block(1,5,2,STONE:0)
Block(1,5,3,STONE:0)
Block(1,5,4,STONE:0)
Block(1,6,-14,STONE:0)
Block(1,6,-13,quark:slate:0)
Block(1,6,-12,quark:slate:0)
Block(1,6,-11,quark:slate:0)
Block(1,6,-10,biomesoplenty:blood:0)
Block(1,6,-9,biomesoplenty:blood:0)
Block(1,6,-8,biomesoplenty:blood:0)
Block(1,6,-7,biomesoplenty:blood:0)
Block(1,6,-6,biomesoplenty:blood:0)
Block(1,6,-5,biomesoplenty:flesh:0)
Block(1,6,-4,biomesoplenty:flesh:0)
Block(1,6,-3,biomesoplenty:blood:0)
Block(1,6,-2,biomesoplenty:blood:0)
Block(1,6,-1,biomesoplenty:flesh:0)
Block(1,6,0,quark:slate:0)
Block(1,6,1,quark:slate:0)
Block(1,6,2,quark:slate:0)
Block(1,6,3,STONE:0)
Block(1,6,4,STONE:0)
Block(1,6,5,STONE:0)
Block(1,7,-14,quark:slate:0)
Block(1,7,-13,quark:slate:0)
Block(1,7,-12,quark:slate:0)
Block(1,7,-11,ICE:0)
Block(1,7,-10,ICE:0)
Block(1,7,-9,ICE:0)
Block(1,7,-8,ICE:0)
Block(1,7,-7,ICE:0)
Block(1,7,-6,ICE:0)
Block(1,7,-5,biomesoplenty:flesh:0)
Block(1,7,-4,biomesoplenty:blood:0)
Block(1,7,-3,ICE:0)
Block(1,7,-2,ICE:0)
Block(1,7,-1,ICE:0)
Block(1,7,0,iceandfire:frozen_stone:0)
Block(1,7,1,iceandfire:frozen_stone:0)
Block(1,7,2,biomesoplenty:flesh:0)
Block(1,7,3,biomesoplenty:flesh:0)
Block(1,7,4,quark:slate:0)
Block(1,7,5,quark:slate:0)
Block(1,7,6,STONE:0)
Block(1,8,-14,quark:slate:0)
Block(1,8,-13,quark:slate:0)
Block(1,8,-12,quark:slate:0)
Block(1,8,-11,AIR:0)
Block(1,8,-10,AIR:0)
Block(1,8,-9,AIR:0)
Block(1,8,-8,AIR:0)
Block(1,8,-7,AIR:0)
Block(1,8,-6,AIR:0)
Block(1,8,-5,AIR:0)
Block(1,8,-4,AIR:0)
Block(1,8,-3,AIR:0)
Block(1,8,-2,AIR:0)
Block(1,8,-1,AIR:0)
Block(1,8,0,AIR:0)
Block(1,8,1,SNOW:0)
Block(1,8,2,AIR:0)
Block(1,8,3,AIR:0)
Block(1,8,4,BONE_BLOCK:0)
Block(1,8,5,quark:slate:0)
Block(1,8,6,biomesoplenty:grass:1)
Block(1,8,7,STONE:0)
Block(1,8,8,STONE:0)
Block(1,8,9,STONE:0)
Block(1,8,10,STONE:0)
Block(1,9,-14,quark:slate:0)
Block(1,9,-13,quark:slate:0)
Block(1,9,-12,quark:slate:0)
Block(1,9,-11,AIR:0)
Block(1,9,-10,AIR:0)
Block(1,9,-9,AIR:0)
Block(1,9,-8,AIR:0)
Block(1,9,-7,AIR:0)
Block(1,9,-6,AIR:0)
Block(1,9,-5,AIR:0)
Block(1,9,-4,AIR:0)
Block(1,9,-3,AIR:0)
Block(1,9,-2,AIR:0)
Block(1,9,-1,AIR:0)
Block(1,9,0,AIR:0)
Block(1,9,1,AIR:0)
Block(1,9,2,AIR:0)
Block(1,9,3,AIR:0)
Block(1,9,4,SNOW:0)
Block(1,9,5,SNOW:0)
Block(1,9,6,contenttweaker:bone_pile:0)
Block(1,9,7,biomesoplenty:flesh:0)
Block(1,9,8,biomesoplenty:grass:1)
Block(1,9,9,quark:slate:0)
Block(1,9,10,quark:slate:0)
Block(1,9,11,quark:slate:0)
Block(1,10,-14,STONE:0)
Block(1,10,-13,quark:slate:0)
Block(1,10,-12,quark:slate:0)
Block(1,10,-11,AIR:0)
Block(1,10,-10,AIR:0)
Block(1,10,-9,AIR:0)
Block(1,10,-8,AIR:0)
Block(1,10,-7,AIR:0)
Block(1,10,-6,AIR:0)
Block(1,10,-5,AIR:0)
Block(1,10,-4,AIR:0)
Block(1,10,-3,AIR:0)
Block(1,10,-2,AIR:0)
Block(1,10,-1,AIR:0)
Block(1,10,0,AIR:0)
Block(1,10,1,AIR:0)
Block(1,10,2,AIR:0)
Block(1,10,3,AIR:0)
Block(1,10,4,AIR:0)
Block(1,10,5,AIR:0)
Block(1,10,6,AIR:0)
Block(1,10,7,AIR:0)
Block(1,10,8,BROWN_MUSHROOM:0)
Block(1,10,9,biomesoplenty:flesh:0)
Block(1,10,10,quark:slate:0)
Block(1,10,11,quark:slate:0)
Block(1,10,12,quark:slate:0)
Block(1,11,-14,STONE:0)
Block(1,11,-13,quark:slate:0)
Block(1,11,-12,quark:slate:0)
Block(1,11,-11,quark:stone_speleothem:0)
Block(1,11,-10,AIR:0)
Block(1,11,-9,AIR:0)
Block(1,11,-8,AIR:0)
Block(1,11,-7,AIR:0)
Block(1,11,-6,AIR:0)
Block(1,11,-5,AIR:0)
Block(1,11,-4,AIR:0)
Block(1,11,-3,AIR:0)
Block(1,11,-2,AIR:0)
Block(1,11,-1,AIR:0)
Block(1,11,0,AIR:0)
Block(1,11,1,AIR:0)
Block(1,11,2,AIR:0)
Block(1,11,3,AIR:0)
Block(1,11,4,AIR:0)
Block(1,11,5,AIR:0)
Block(1,11,6,AIR:0)
Block(1,11,7,AIR:0)
Block(1,11,8,AIR:0)
Block(1,11,9,AIR:0)
Block(1,11,10,quark:slate:0)
Block(1,11,11,quark:slate:0)
Block(1,11,12,quark:slate:0)
Block(1,12,-14,STONE:0)
Block(1,12,-13,quark:slate:0)
Block(1,12,-12,quark:slate:0)
Block(1,12,-11,quark:stone_speleothem:1)
Block(1,12,-10,AIR:0)
Block(1,12,-9,AIR:0)
Block(1,12,-8,AIR:0)
Block(1,12,-7,AIR:0)
Block(1,12,-6,AIR:0)
Block(1,12,-5,AIR:0)
Block(1,12,-4,AIR:0)
Block(1,12,-3,AIR:0)
Block(1,12,-2,AIR:0)
Block(1,12,-1,AIR:0)
Block(1,12,0,AIR:0)
Block(1,12,1,AIR:0)
Block(1,12,2,AIR:0)
Block(1,12,3,AIR:0)
Block(1,12,4,AIR:0)
Block(1,12,5,AIR:0)
Block(1,12,6,AIR:0)
Block(1,12,7,AIR:0)
Block(1,12,8,AIR:0)
Block(1,12,9,AIR:0)
Block(1,12,10,quark:stone_speleothem:2)
Block(1,12,11,quark:slate:0)
Block(1,12,12,quark:slate:0)
Block(1,12,13,quark:slate:0)
Block(1,13,-13,quark:slate:0)
Block(1,13,-12,iceandfire:frozen_stone:0)
Block(1,13,-11,quark:stone_speleothem:2)
Block(1,13,-10,AIR:0)
Block(1,13,-9,AIR:0)
Block(1,13,-8,AIR:0)
Block(1,13,-7,AIR:0)
Block(1,13,-6,AIR:0)
Block(1,13,-5,AIR:0)
Block(1,13,-4,AIR:0)
Block(1,13,-3,AIR:0)
Block(1,13,-2,AIR:0)
Block(1,13,-1,AIR:0)
Block(1,13,0,AIR:0)
Block(1,13,1,AIR:0)
Block(1,13,2,AIR:0)
Block(1,13,3,AIR:0)
Block(1,13,4,AIR:0)
Block(1,13,5,AIR:0)
Block(1,13,6,AIR:0)
Block(1,13,7,AIR:0)
Block(1,13,8,AIR:0)
Block(1,13,9,AIR:0)
Block(1,13,10,quark:stone_speleothem:1)
Block(1,13,11,quark:slate:0)
Block(1,13,12,quark:slate:0)
Block(1,13,13,quark:slate:0)
Block(1,14,-13,iceandfire:frozen_stone:0)
Block(1,14,-12,iceandfire:frozen_stone:0)
Block(1,14,-11,iceandfire:frozen_stone:0)
Block(1,14,-10,AIR:0)
Block(1,14,-9,AIR:0)
Block(1,14,-8,AIR:0)
Block(1,14,-7,AIR:0)
Block(1,14,-6,AIR:0)
Block(1,14,-5,AIR:0)
Block(1,14,-4,AIR:0)
Block(1,14,-3,AIR:0)
Block(1,14,-2,AIR:0)
Block(1,14,-1,AIR:0)
Block(1,14,0,quark:stone_speleothem:0)
Block(1,14,1,AIR:0)
Block(1,14,2,AIR:0)
Block(1,14,3,AIR:0)
Block(1,14,4,AIR:0)
Block(1,14,5,AIR:0)
Block(1,14,6,AIR:0)
Block(1,14,7,AIR:0)
Block(1,14,8,AIR:0)
Block(1,14,9,AIR:0)
Block(1,14,10,quark:stone_speleothem:0)
Block(1,14,11,quark:slate:0)
Block(1,14,12,quark:slate:0)
Block(1,14,13,quark:slate:0)
Block(1,15,-13,iceandfire:frozen_stone:0)
Block(1,15,-12,iceandfire:frozen_stone:0)
Block(1,15,-11,iceandfire:frozen_stone:0)
Block(1,15,-10,AIR:0)
Block(1,15,-9,AIR:0)
Block(1,15,-8,AIR:0)
Block(1,15,-7,AIR:0)
Block(1,15,-6,AIR:0)
Block(1,15,-5,AIR:0)
Block(1,15,-4,AIR:0)
Block(1,15,-3,AIR:0)
Block(1,15,-2,AIR:0)
Block(1,15,-1,AIR:0)
Block(1,15,0,quark:stone_speleothem:1)
Block(1,15,1,AIR:0)
Block(1,15,2,AIR:0)
Block(1,15,3,AIR:0)
Block(1,15,4,quark:slate_speleothem:0)
Block(1,15,5,AIR:0)
Block(1,15,6,AIR:0)
Block(1,15,7,AIR:0)
Block(1,15,8,AIR:0)
Block(1,15,9,AIR:0)
Block(1,15,10,AIR:0)
Block(1,15,11,quark:slate:0)
Block(1,15,12,quark:slate:0)
Block(1,15,13,quark:slate:0)
Block(1,16,-14,STONE:0)
Block(1,16,-13,iceandfire:frozen_stone:0)
Block(1,16,-12,iceandfire:frozen_stone:0)
Block(1,16,-11,iceandfire:frozen_stone:0)
Block(1,16,-10,AIR:0)
Block(1,16,-9,AIR:0)
Block(1,16,-8,AIR:0)
Block(1,16,-7,AIR:0)
Block(1,16,-6,AIR:0)
Block(1,16,-5,AIR:0)
Block(1,16,-4,AIR:0)
Block(1,16,-3,AIR:0)
Block(1,16,-2,AIR:0)
Block(1,16,-1,AIR:0)
Block(1,16,0,quark:stone_speleothem:2)
Block(1,16,1,AIR:0)
Block(1,16,2,AIR:0)
Block(1,16,3,AIR:0)
Block(1,16,4,quark:slate_speleothem:1)
Block(1,16,5,AIR:0)
Block(1,16,6,AIR:0)
Block(1,16,7,AIR:0)
Block(1,16,8,AIR:0)
Block(1,16,9,AIR:0)
Block(1,16,10,AIR:0)
Block(1,16,11,quark:slate:0)
Block(1,16,12,quark:slate:0)
Block(1,16,13,quark:slate:0)
Block(1,17,-15,STONE:0)
Block(1,17,-14,STONE:0)
Block(1,17,-13,STONE:0)
Block(1,17,-12,iceandfire:frozen_stone:0)
Block(1,17,-11,iceandfire:frozen_stone:0)
Block(1,17,-10,AIR:0)
Block(1,17,-9,AIR:0)
Block(1,17,-8,AIR:0)
Block(1,17,-7,AIR:0)
Block(1,17,-6,AIR:0)
Block(1,17,-5,AIR:0)
Block(1,17,-4,AIR:0)
Block(1,17,-3,PACKED_ICE:0)
Block(1,17,-2,PACKED_ICE:0)
Block(1,17,-1,PACKED_ICE:0)
Block(1,17,0,PACKED_ICE:0)
Block(1,17,1,AIR:0)
Block(1,17,2,AIR:0)
Block(1,17,3,AIR:0)
Block(1,17,4,quark:slate_speleothem:2)
Block(1,17,5,AIR:0)
Block(1,17,6,iceandfire:frozen_stone:0)
Block(1,17,7,quark:slate:0)
Block(1,17,8,quark:slate:0)
Block(1,17,9,quark:slate:0)
Block(1,17,10,quark:slate:0)
Block(1,17,11,quark:slate:0)
Block(1,17,12,quark:slate:0)
Block(1,17,13,STONE:0)
Block(1,18,-14,STONE:0)
Block(1,18,-13,STONE:0)
Block(1,18,-12,STONE:0)
Block(1,18,-11,STONE:0)
Block(1,18,-10,STONE:0)
Block(1,18,-9,STONE:0)
Block(1,18,-8,STONE:0)
Block(1,18,-7,STONE:0)
Block(1,18,-6,STONE:0)
Block(1,18,-5,STONE:0)
Block(1,18,-4,STONE:0)
Block(1,18,-3,PACKED_ICE:0)
Block(1,18,-2,PACKED_ICE:0)
Block(1,18,-1,PACKED_ICE:0)
Block(1,18,0,PACKED_ICE:0)
Block(1,18,1,PACKED_ICE:0)
Block(1,18,2,iceandfire:frozen_stone:0)
Block(1,18,3,iceandfire:frozen_stone:0)
Block(1,18,4,iceandfire:frozen_stone:0)
Block(1,18,5,quark:slate:0)
Block(1,18,6,quark:slate:0)
Block(1,18,7,quark:slate:0)
Block(1,18,8,quark:slate:0)
Block(1,18,10,quark:slate:0)
Block(1,18,11,STONE:0)
Block(1,18,12,STONE:0)
Block(1,19,-14,AIR:0)
Block(1,19,-13,AIR:0)
Block(1,19,-12,AIR:0)
Block(1,19,-11,AIR:0)
Block(1,19,-10,AIR:0)
Block(1,19,-9,AIR:0)
Block(1,19,-8,AIR:0)
Block(1,19,-7,AIR:0)
Block(1,19,-6,AIR:0)
Block(1,19,-5,AIR:0)
Block(1,19,-4,AIR:0)
Block(1,19,-3,STONE:0)
Block(1,19,-2,REDSTONE_WIRE:0)
Block(1,19,-1,PACKED_ICE:0)
Block(1,19,0,PACKED_ICE:0)
Block(1,19,1,PACKED_ICE:0)
Block(1,19,2,PACKED_ICE:0)
Block(1,19,3,PACKED_ICE:0)
Block(1,19,4,PACKED_ICE:0)
Block(1,19,5,quark:slate:0)
Block(1,19,6,quark:slate:0)
Block(1,19,7,quark:slate:0)
Block(1,20,-14,AIR:0)
Block(1,20,-13,AIR:0)
Block(1,20,-12,AIR:0)
Block(1,20,-11,AIR:0)
Block(1,20,-10,AIR:0)
Block(1,20,-9,AIR:0)
Block(1,20,-8,AIR:0)
Block(1,20,-7,AIR:0)
Block(1,20,-6,AIR:0)
Block(1,20,-5,AIR:0)
Block(1,20,-4,AIR:0)
Block(1,20,-3,STONE:0)
Block(1,20,-2,STONE:0)
Block(1,20,-1,STONE:0)
Block(1,20,2,PACKED_ICE:0)
Block(1,20,3,PACKED_ICE:0)
Block(1,20,4,PACKED_ICE:0)
Block(1,20,5,quark:slate:0)
Block(1,20,6,quark:slate:0)
Block(1,21,-14,STONE:0)
Block(1,21,-13,AIR:0)
Block(1,21,-12,AIR:0)
Block(1,21,-11,AIR:0)
Block(1,21,-10,AIR:0)
Block(1,21,-9,AIR:0)
Block(1,21,-8,AIR:0)
Block(1,21,-7,AIR:0)
Block(1,21,-6,STONE:0)
Block(1,21,-5,STONE:0)
Block(1,21,-4,STONE:0)
Block(1,21,-3,STONE:0)
Block(1,21,-2,STONE:0)
Block(1,21,-1,STONE:0)
Block(1,21,3,STONE:0)
Block(1,21,4,STONE:0)
Block(1,21,5,STONE:0)
Block(1,22,-15,STONE:0)
Block(1,22,-14,STONE:0)
Block(1,22,-13,STONE:0)
Block(1,22,-12,STONE:0)
Block(1,22,-11,STONE:0)
Block(1,22,-10,STONE:0)
Block(1,22,-9,STONE:0)
Block(1,22,-8,STONE:0)
Block(1,22,-7,STONE:0)
Block(1,22,-6,STONE:0)
Block(1,22,-5,STONE:0)
Block(1,22,-4,STONE:0)
Block(1,22,-3,STONE:0)
Block(1,22,-2,STONE:0)
Block(2,5,-13,STONE:0)
Block(2,5,-12,STONE:0)
Block(2,5,-11,STONE:0)
Block(2,5,-10,STONE:0)
Block(2,5,-9,STONE:0)
Block(2,5,-8,biomesoplenty:flesh:0)
Block(2,5,-7,biomesoplenty:flesh:0)
Block(2,5,-6,biomesoplenty:flesh:0)
Block(2,5,-5,biomesoplenty:flesh:0)
Block(2,5,-4,iceandfire:frozen_stone:0)
Block(2,5,-3,BONE_BLOCK:0)
Block(2,5,-2,BONE_BLOCK:8)
Block(2,5,-1,STONE:0)
Block(2,5,0,STONE:0)
Block(2,5,1,STONE:0)
Block(2,5,2,STONE:0)
Block(2,5,3,STONE:0)
Block(2,5,4,STONE:0)
Block(2,6,-14,STONE:0)
Block(2,6,-13,quark:slate:0)
Block(2,6,-12,quark:slate:0)
Block(2,6,-11,quark:slate:0)
Block(2,6,-10,biomesoplenty:blood:0)
Block(2,6,-9,biomesoplenty:flesh:0)
Block(2,6,-8,biomesoplenty:blood:0)
Block(2,6,-7,biomesoplenty:blood:0)
Block(2,6,-6,biomesoplenty:blood:1)
Block(2,6,-5,biomesoplenty:flesh:0)
Block(2,6,-4,biomesoplenty:flesh:0)
Block(2,6,-3,biomesoplenty:blood:0)
Block(2,6,-2,biomesoplenty:blood:0)
Block(2,6,-1,biomesoplenty:flesh:0)
Block(2,6,0,STONE:0)
Block(2,6,1,STONE:0)
Block(2,6,2,quark:slate:0)
Block(2,6,3,quark:slate:0)
Block(2,6,4,quark:slate:0)
Block(2,6,5,STONE:0)
Block(2,7,-14,quark:slate:0)
Block(2,7,-13,quark:slate:0)
Block(2,7,-12,quark:slate:0)
Block(2,7,-11,ICE:0)
Block(2,7,-10,ICE:0)
Block(2,7,-9,biomesoplenty:flesh:0)
Block(2,7,-8,ICE:0)
Block(2,7,-7,ICE:0)
Block(2,7,-6,ICE:0)
Block(2,7,-5,biomesoplenty:flesh:0)
Block(2,7,-4,biomesoplenty:blood:0)
Block(2,7,-3,ICE:0)
Block(2,7,-2,ICE:0)
Block(2,7,-1,ICE:0)
Block(2,7,0,quark:slate:0)
Block(2,7,1,quark:slate:0)
Block(2,7,2,quark:slate:0)
Block(2,7,3,biomesoplenty:flesh:0)
Block(2,7,4,quark:slate:0)
Block(2,7,5,quark:slate:0)
Block(2,7,6,STONE:0)
Block(2,8,-14,quark:slate:0)
Block(2,8,-13,quark:slate:0)
Block(2,8,-12,quark:slate:0)
Block(2,8,-11,AIR:0)
Block(2,8,-10,AIR:0)
Block(2,8,-9,BROWN_MUSHROOM:0)
Block(2,8,-8,AIR:0)
Block(2,8,-7,AIR:0)
Block(2,8,-6,AIR:0)
Block(2,8,-5,contenttweaker:bone_pile:0)
Block(2,8,-4,AIR:0)
Block(2,8,-3,AIR:0)
Block(2,8,-2,AIR:0)
Block(2,8,-1,AIR:0)
Block(2,8,0,AIR:0)
Block(2,8,1,SNOW:0)
Block(2,8,2,SNOW:0)
Block(2,8,3,AIR:0)
Block(2,8,4,quark:slate:0)
Block(2,8,5,quark:slate:0)
Block(2,8,6,quark:slate:0)
Block(2,8,7,STONE:0)
Block(2,8,8,STONE:0)
Block(2,8,9,STONE:0)
Block(2,8,10,STONE:0)
Block(2,9,-14,quark:slate:0)
Block(2,9,-13,quark:slate:0)
Block(2,9,-12,quark:slate:0)
Block(2,9,-11,AIR:0)
Block(2,9,-10,AIR:0)
Block(2,9,-9,AIR:0)
Block(2,9,-8,AIR:0)
Block(2,9,-7,AIR:0)
Block(2,9,-6,AIR:0)
Block(2,9,-5,AIR:0)
Block(2,9,-4,AIR:0)
Block(2,9,-3,AIR:0)
Block(2,9,-2,AIR:0)
Block(2,9,-1,AIR:0)
Block(2,9,0,AIR:0)
Block(2,9,1,AIR:0)
Block(2,9,2,AIR:0)
Block(2,9,3,AIR:0)
Block(2,9,4,rustic:mooncap_mushroom:0)
Block(2,9,5,AIR:0)
Block(2,9,6,SNOW:0)
Block(2,9,7,quark:stone_speleothem:2)
Block(2,9,8,BROWN_MUSHROOM:0)
Block(2,9,9,biomesoplenty:grass:1)
Block(2,9,10,quark:slate:0)
Block(2,9,11,quark:slate:0)
Block(2,10,-14,STONE:0)
Block(2,10,-13,quark:slate:0)
Block(2,10,-12,quark:slate:0)
Block(2,10,-11,AIR:0)
Block(2,10,-10,AIR:0)
Block(2,10,-9,AIR:0)
Block(2,10,-8,AIR:0)
Block(2,10,-7,AIR:0)
Block(2,10,-6,AIR:0)
Block(2,10,-5,AIR:0)
Block(2,10,-4,AIR:0)
Block(2,10,-3,AIR:0)
Block(2,10,-2,AIR:0)
Block(2,10,-1,AIR:0)
Block(2,10,0,AIR:0)
Block(2,10,1,AIR:0)
Block(2,10,2,AIR:0)
Block(2,10,3,AIR:0)
Block(2,10,4,AIR:0)
Block(2,10,5,AIR:0)
Block(2,10,6,AIR:0)
Block(2,10,7,quark:stone_speleothem:1)
Block(2,10,8,AIR:0)
Block(2,10,9,contenttweaker:bone_pile:0)
Block(2,10,10,quark:slate:0)
Block(2,10,11,quark:slate:0)
Block(2,10,12,quark:slate:0)
Block(2,11,-14,STONE:0)
Block(2,11,-13,quark:slate:0)
Block(2,11,-12,quark:slate:0)
Block(2,11,-11,AIR:0)
Block(2,11,-10,AIR:0)
Block(2,11,-9,AIR:0)
Block(2,11,-8,AIR:0)
Block(2,11,-7,AIR:0)
Block(2,11,-6,AIR:0)
Block(2,11,-5,AIR:0)
Block(2,11,-4,AIR:0)
Block(2,11,-3,AIR:0)
Block(2,11,-2,AIR:0)
Block(2,11,-1,AIR:0)
Block(2,11,0,AIR:0)
Block(2,11,1,AIR:0)
Block(2,11,2,AIR:0)
Block(2,11,3,AIR:0)
Block(2,11,4,AIR:0)
Block(2,11,5,AIR:0)
Block(2,11,6,AIR:0)
Block(2,11,7,quark:stone_speleothem:0)
Block(2,11,8,AIR:0)
Block(2,11,9,AIR:0)
Block(2,11,10,quark:slate:0)
Block(2,11,11,quark:slate:0)
Block(2,11,12,quark:slate:0)
Block(2,12,-13,quark:slate:0)
Block(2,12,-12,quark:slate:0)
Block(2,12,-11,quark:stone_speleothem:0)
Block(2,12,-10,AIR:0)
Block(2,12,-9,AIR:0)
Block(2,12,-8,AIR:0)
Block(2,12,-7,AIR:0)
Block(2,12,-6,AIR:0)
Block(2,12,-5,AIR:0)
Block(2,12,-4,AIR:0)
Block(2,12,-3,AIR:0)
Block(2,12,-2,AIR:0)
Block(2,12,-1,AIR:0)
Block(2,12,0,AIR:0)
Block(2,12,1,AIR:0)
Block(2,12,2,AIR:0)
Block(2,12,3,AIR:0)
Block(2,12,4,AIR:0)
Block(2,12,5,AIR:0)
Block(2,12,6,AIR:0)
Block(2,12,7,AIR:0)
Block(2,12,8,AIR:0)
Block(2,12,9,AIR:0)
Block(2,12,10,AIR:0)
Block(2,12,11,quark:slate:0)
Block(2,12,12,quark:slate:0)
Block(2,12,13,quark:slate:0)
Block(2,13,-13,quark:slate:0)
Block(2,13,-12,iceandfire:frozen_stone:0)
Block(2,13,-11,quark:stone_speleothem:1)
Block(2,13,-10,AIR:0)
Block(2,13,-9,AIR:0)
Block(2,13,-8,AIR:0)
Block(2,13,-7,AIR:0)
Block(2,13,-6,AIR:0)
Block(2,13,-5,AIR:0)
Block(2,13,-4,AIR:0)
Block(2,13,-3,AIR:0)
Block(2,13,-2,AIR:0)
Block(2,13,-1,AIR:0)
Block(2,13,0,AIR:0)
Block(2,13,1,AIR:0)
Block(2,13,2,AIR:0)
Block(2,13,3,AIR:0)
Block(2,13,4,AIR:0)
Block(2,13,5,AIR:0)
Block(2,13,6,AIR:0)
Block(2,13,7,AIR:0)
Block(2,13,8,AIR:0)
Block(2,13,9,AIR:0)
Block(2,13,10,AIR:0)
Block(2,13,11,quark:slate:0)
Block(2,13,12,quark:slate:0)
Block(2,13,13,quark:slate:0)
Block(2,14,-13,iceandfire:frozen_stone:0)
Block(2,14,-12,iceandfire:frozen_stone:0)
Block(2,14,-11,quark:stone_speleothem:2)
Block(2,14,-10,AIR:0)
Block(2,14,-9,AIR:0)
Block(2,14,-8,AIR:0)
Block(2,14,-7,AIR:0)
Block(2,14,-6,AIR:0)
Block(2,14,-5,AIR:0)
Block(2,14,-4,AIR:0)
Block(2,14,-3,AIR:0)
Block(2,14,-2,AIR:0)
Block(2,14,-1,AIR:0)
Block(2,14,0,AIR:0)
Block(2,14,1,AIR:0)
Block(2,14,2,AIR:0)
Block(2,14,3,AIR:0)
Block(2,14,4,AIR:0)
Block(2,14,5,AIR:0)
Block(2,14,6,AIR:0)
Block(2,14,7,AIR:0)
Block(2,14,8,AIR:0)
Block(2,14,9,AIR:0)
Block(2,14,10,AIR:0)
Block(2,14,11,quark:slate:0)
Block(2,14,12,quark:slate:0)
Block(2,14,13,quark:slate:0)
Block(2,15,-13,iceandfire:frozen_stone:0)
Block(2,15,-12,iceandfire:frozen_stone:0)
Block(2,15,-11,iceandfire:frozen_stone:0)
Block(2,15,-10,AIR:0)
Block(2,15,-9,AIR:0)
Block(2,15,-8,AIR:0)
Block(2,15,-7,AIR:0)
Block(2,15,-6,AIR:0)
Block(2,15,-5,AIR:0)
Block(2,15,-4,AIR:0)
Block(2,15,-3,AIR:0)
Block(2,15,-2,AIR:0)
Block(2,15,-1,AIR:0)
Block(2,15,0,AIR:0)
Block(2,15,1,AIR:0)
Block(2,15,2,AIR:0)
Block(2,15,3,AIR:0)
Block(2,15,4,AIR:0)
Block(2,15,5,AIR:0)
Block(2,15,6,AIR:0)
Block(2,15,7,AIR:0)
Block(2,15,8,AIR:0)
Block(2,15,9,AIR:0)
Block(2,15,10,AIR:0)
Block(2,15,11,quark:slate:0)
Block(2,15,12,quark:slate:0)
Block(2,15,13,quark:slate:0)
Block(2,16,-14,STONE:0)
Block(2,16,-13,iceandfire:frozen_stone:0)
Block(2,16,-12,iceandfire:frozen_stone:0)
Block(2,16,-11,iceandfire:frozen_stone:0)
Block(2,16,-10,AIR:0)
Block(2,16,-9,AIR:0)
Block(2,16,-8,AIR:0)
Block(2,16,-7,AIR:0)
Block(2,16,-6,AIR:0)
Block(2,16,-5,AIR:0)
Block(2,16,-4,AIR:0)
Block(2,16,-3,AIR:0)
Block(2,16,-2,AIR:0)
Block(2,16,-1,AIR:0)
Block(2,16,0,AIR:0)
Block(2,16,1,AIR:0)
Block(2,16,2,AIR:0)
Block(2,16,3,AIR:0)
Block(2,16,4,AIR:0)
Block(2,16,5,quark:slate_speleothem:1)
Block(2,16,6,AIR:0)
Block(2,16,7,AIR:0)
Block(2,16,8,AIR:0)
Block(2,16,9,AIR:0)
Block(2,16,10,AIR:0)
Block(2,16,11,quark:slate:0)
Block(2,16,12,quark:slate:0)
Block(2,16,13,quark:slate:0)
Block(2,17,-15,STONE:0)
Block(2,17,-14,STONE:0)
Block(2,17,-13,STONE:0)
Block(2,17,-12,iceandfire:frozen_stone:0)
Block(2,17,-11,iceandfire:frozen_stone:0)
Block(2,17,-10,AIR:0)
Block(2,17,-9,AIR:0)
Block(2,17,-8,AIR:0)
Block(2,17,-7,AIR:0)
Block(2,17,-6,AIR:0)
Block(2,17,-5,iceandfire:frozen_stone:0)
Block(2,17,-4,PACKED_ICE:0)
Block(2,17,-3,PACKED_ICE:0)
Block(2,17,-2,PACKED_ICE:0)
Block(2,17,-1,PACKED_ICE:0)
Block(2,17,0,PACKED_ICE:0)
Block(2,17,1,AIR:0)
Block(2,17,2,AIR:0)
Block(2,17,3,AIR:0)
Block(2,17,4,AIR:0)
Block(2,17,5,quark:slate_speleothem:2)
Block(2,17,6,AIR:0)
Block(2,17,7,AIR:0)
Block(2,17,8,AIR:0)
Block(2,17,9,quark:slate:0)
Block(2,17,10,quark:slate:0)
Block(2,17,11,quark:slate:0)
Block(2,17,12,quark:slate:0)
Block(2,17,13,STONE:0)
Block(2,18,-15,STONE:0)
Block(2,18,-14,STONE:0)
Block(2,18,-13,STONE:0)
Block(2,18,-12,STONE:0)
Block(2,18,-11,STONE:0)
Block(2,18,-10,STONE:0)
Block(2,18,-9,STONE:0)
Block(2,18,-8,STONE:0)
Block(2,18,-7,STONE:0)
Block(2,18,-6,STONE:0)
Block(2,18,-5,STONE:0)
Block(2,18,-4,PACKED_ICE:0)
Block(2,18,-3,PACKED_ICE:0)
Block(2,18,-2,PACKED_ICE:0)
Block(2,18,-1,PACKED_ICE:0)
Block(2,18,0,PACKED_ICE:0)
Block(2,18,1,PACKED_ICE:0)
Block(2,18,2,PACKED_ICE:0)
Block(2,18,3,AIR:0)
Block(2,18,4,AIR:0)
Block(2,18,5,iceandfire:frozen_stone:0)
Block(2,18,6,iceandfire:frozen_stone:0)
Block(2,18,7,quark:slate:0)
Block(2,18,8,quark:slate:0)
Block(2,18,9,quark:slate:0)
Block(2,18,10,quark:slate:0)
Block(2,18,11,STONE:0)
Block(2,18,12,STONE:0)
Block(2,19,-14,AIR:0)
Block(2,19,-13,AIR:0)
Block(2,19,-12,AIR:0)
Block(2,19,-11,AIR:0)
Block(2,19,-10,AIR:0)
Block(2,19,-9,AIR:0)
Block(2,19,-8,AIR:0)
Block(2,19,-7,AIR:0)
Block(2,19,-6,AIR:0)
Block(2,19,-5,STONE:0)
Block(2,19,-4,STONE:0)
Block(2,19,-3,PACKED_ICE:0)
Block(2,19,-2,REDSTONE_WIRE:0)
Block(2,19,-1,PACKED_ICE:0)
Block(2,19,0,PACKED_ICE:0)
Block(2,19,1,PACKED_ICE:0)
Block(2,19,2,PACKED_ICE:0)
Block(2,19,3,PACKED_ICE:0)
Block(2,19,4,PACKED_ICE:0)
Block(2,19,5,PACKED_ICE:0)
Block(2,19,6,quark:slate:0)
Block(2,19,7,quark:slate:0)
Block(2,20,-14,AIR:0)
Block(2,20,-13,AIR:0)
Block(2,20,-12,AIR:0)
Block(2,20,-11,AIR:0)
Block(2,20,-10,AIR:0)
Block(2,20,-9,AIR:0)
Block(2,20,-8,AIR:0)
Block(2,20,-7,AIR:0)
Block(2,20,-6,AIR:0)
RandomBlock(2,20,-5,DIAMOND_ORE:0,35,EMERALD_ORE:0,100)
Block(2,20,-4,STONE:0)
Block(2,20,-3,STONE:0)
Block(2,20,-2,STONE:0)
Block(2,20,-1,STONE:0)
Block(2,20,1,PACKED_ICE:0)
Block(2,20,2,PACKED_ICE:0)
Block(2,20,3,PACKED_ICE:0)
Block(2,20,4,PACKED_ICE:0)
Block(2,20,5,PACKED_ICE:0)
Block(2,20,6,quark:slate:0)
Block(2,21,-15,STONE:0)
Block(2,21,-14,AIR:0)
Block(2,21,-13,AIR:0)
Block(2,21,-12,AIR:0)
Block(2,21,-11,AIR:0)
Block(2,21,-10,AIR:0)
Block(2,21,-9,AIR:0)
Block(2,21,-8,STONE:0)
Block(2,21,-7,STONE:0)
Block(2,21,-6,STONE:0)
Block(2,21,-5,STONE:0)
Block(2,21,-4,STONE:0)
Block(2,21,-3,STONE:0)
Block(2,21,-2,STONE:0)
Block(2,21,-1,STONE:0)
Block(2,21,2,PACKED_ICE:0)
Block(2,21,3,PACKED_ICE:0)
Block(2,21,4,PACKED_ICE:0)
Block(2,21,5,STONE:0)
Block(2,22,-15,STONE:0)
Block(2,22,-14,STONE:0)
Block(2,22,-13,STONE:0)
Block(2,22,-12,STONE:0)
Block(2,22,-11,STONE:0)
Block(2,22,-10,STONE:0)
Block(2,22,-9,STONE:0)
Block(2,22,-8,STONE:0)
Block(2,22,-7,STONE:0)
Block(2,22,-6,STONE:0)
Block(2,22,-5,STONE:0)
Block(2,22,-4,STONE:0)
Block(2,22,-3,STONE:0)
