
#######################################################################
# +-----------------------------------------------------------------+ #
# |                            BO3 object                           | #
# +-----------------------------------------------------------------+ #
#######################################################################

Author: NLBlackHeavenNL

Description: No description given

Version: 3

SettingsMode: WriteWithoutComments


#######################################################################
# +-----------------------------------------------------------------+ #
# |                          Main settings                          | #
# +-----------------------------------------------------------------+ #
#######################################################################

Tree: true

Frequency: 1

Rarity: 100.0

RotateRandomly: false

SpawnHeight: highestSolidBlock

SpawnHeightOffset: -1

SpawnHeightVariance: 0

##############################
# Height Limits for the BO3. #
##############################

MinHeight: 0

MaxHeight: 255

######################
# Extrusion settings #
######################

ExtrudeMode: None

ExtrudeThroughBlocks: AIR

MaxBranchDepth: 10

ExcludedBiomes: All


#######################################################################
# +-----------------------------------------------------------------+ #
# |                      Source block settings                      | #
# +-----------------------------------------------------------------+ #
#######################################################################

SourceBlocks: AIR,GRASS,DIRT,biomesoplenty:dirt

MaxPercentageOutsideSourceBlock: 0

OutsideSourceBlock: placeAnyway

DoReplaceBlocks: true

IsOTGPlus: false


#######################################################################
# +-----------------------------------------------------------------+ #
# |                              Blocks                             | #
# +-----------------------------------------------------------------+ #
#######################################################################

Block(-5,3,-1,dynamictreesquark:leaves0:0)
Block(-5,3,0,dynamictreesquark:leaves0:0)
Block(-5,3,1,dynamictreesquark:leaves0:0)
Block(-5,3,2,dynamictreesquark:leaves0:0)
Block(-5,4,0,dynamictreesquark:leaves0:0)
Block(-5,4,1,dynamictreesquark:leaves0:0)
Block(-5,4,2,dynamictreesquark:leaves0:0)
Block(-5,5,1,dynamictreesquark:leaves0:0)
Block(-4,2,-1,dynamictreesquark:leaves0:0)
Block(-4,2,0,dynamictreesquark:leaves0:0)
Block(-4,2,2,dynamictreesquark:leaves0:0)
Block(-4,3,-2,dynamictreesquark:leaves0:0)
Block(-4,3,-1,dynamictreesquark:leaves0:1)
Block(-4,3,0,dynamictreesquark:leaves0:2)
Block(-4,3,1,dynamictreesquark:leaves0:3)
Block(-4,3,2,dynamictreesquark:leaves0:2)
Block(-4,3,3,dynamictreesquark:leaves0:0)
Block(-4,4,-1,dynamictreesquark:leaves0:0)
Block(-4,4,0,dynamictreesquark:leaves0:1)
Block(-4,4,1,dynamictreesquark:leaves0:2)
Block(-4,4,2,dynamictreesquark:leaves0:1)
Block(-4,4,3,dynamictreesquark:leaves0:0)
Block(-4,5,0,dynamictreesquark:leaves0:0)
Block(-4,5,1,dynamictreesquark:leaves0:1)
Block(-4,5,2,dynamictreesquark:leaves0:0)
Block(-4,6,1,dynamictreesquark:leaves0:0)
Block(-3,2,-1,dynamictreesquark:leaves0:0)
Block(-3,3,-2,dynamictreesquark:leaves0:0)
Block(-3,3,-1,dynamictreesquark:leaves0:2)
Block(-3,3,0,dynamictreesquark:leaves0:3)
Block(-3,3,1,dynamictreesquark:blossomingbranch:0)
Block(-3,3,2,dynamictreesquark:leaves0:3)
Block(-3,3,3,dynamictreesquark:leaves0:0)
Block(-3,4,-2,dynamictreesquark:leaves0:0)
Block(-3,4,-1,dynamictreesquark:leaves0:1)
Block(-3,4,0,dynamictreesquark:leaves0:2)
Block(-3,4,1,dynamictreesquark:leaves0:3)
Block(-3,4,2,dynamictreesquark:leaves0:2)
Block(-3,4,3,dynamictreesquark:leaves0:0)
Block(-3,5,-1,dynamictreesquark:leaves0:0)
Block(-3,5,0,dynamictreesquark:leaves0:1)
Block(-3,5,1,dynamictreesquark:leaves0:2)
Block(-3,5,2,dynamictreesquark:leaves0:1)
Block(-3,5,3,dynamictreesquark:leaves0:0)
Block(-3,6,0,dynamictreesquark:leaves0:0)
Block(-3,6,1,dynamictreesquark:leaves0:1)
Block(-3,6,2,dynamictreesquark:leaves0:0)
Block(-3,7,1,dynamictreesquark:leaves0:0)
Block(-2,3,-2,dynamictreesquark:leaves0:0)
Block(-2,3,-1,dynamictreesquark:leaves0:3)
Block(-2,3,0,dynamictreesquark:blossomingbranch:0)
Block(-2,3,1,dynamictreesquark:blossomingbranch:1)
Block(-2,4,-2,dynamictreesquark:leaves0:0)
Block(-2,4,-1,dynamictreesquark:leaves0:2)
Block(-2,4,0,dynamictreesquark:leaves0:3)
Block(-2,4,1,dynamictreesquark:blossomingbranch:0)
Block(-2,4,2,dynamictreesquark:leaves0:3)
Block(-2,4,3,dynamictreesquark:leaves0:0)
Block(-2,4,4,dynamictreesquark:leaves0:0)
Block(-2,4,5,dynamictreesquark:leaves0:0)
Block(-2,5,-2,dynamictreesquark:leaves0:0)
Block(-2,5,-1,dynamictreesquark:leaves0:1)
Block(-2,5,0,dynamictreesquark:leaves0:2)
Block(-2,5,1,dynamictreesquark:leaves0:3)
Block(-2,5,2,dynamictreesquark:leaves0:2)
Block(-2,5,3,dynamictreesquark:leaves0:0)
Block(-2,5,4,dynamictreesquark:leaves0:0)
Block(-2,5,5,dynamictreesquark:leaves0:0)
Block(-2,6,-1,dynamictreesquark:leaves0:0)
Block(-2,6,0,dynamictreesquark:leaves0:1)
Block(-2,6,1,dynamictreesquark:leaves0:2)
Block(-2,6,2,dynamictreesquark:leaves0:1)
Block(-2,6,3,dynamictreesquark:leaves0:0)
Block(-2,6,4,dynamictreesquark:leaves0:0)
Block(-2,6,5,dynamictreesquark:leaves0:0)
Block(-2,7,0,dynamictreesquark:leaves0:0)
Block(-2,7,1,dynamictreesquark:leaves0:1)
Block(-2,7,2,dynamictreesquark:leaves0:0)
Block(-2,8,1,dynamictreesquark:leaves0:0)
Block(-1,3,1,dynamictreesquark:blossomingbranch:2)
Block(-1,4,-1,dynamictreesquark:leaves0:0)
Block(-1,4,4,dynamictreesquark:leaves0:2)
Block(-1,4,5,dynamictreesquark:leaves0:1)
Block(-1,4,6,dynamictreesquark:leaves0:0)
Block(-1,5,-1,dynamictreesquark:leaves0:0)
Block(-1,5,0,dynamictreesquark:leaves0:1)
Block(-1,5,1,dynamictreesquark:leaves0:2)
Block(-1,5,2,dynamictreesquark:leaves0:1)
Block(-1,5,3,dynamictreesquark:leaves0:0)
Block(-1,5,4,dynamictreesquark:leaves0:3)
Block(-1,5,5,dynamictreesquark:leaves0:2)
Block(-1,5,6,dynamictreesquark:leaves0:0)
Block(-1,6,-1,dynamictreesquark:leaves0:0)
Block(-1,6,0,dynamictreesquark:leaves0:2)
Block(-1,6,1,dynamictreesquark:leaves0:3)
Block(-1,6,2,dynamictreesquark:leaves0:2)
Block(-1,6,3,dynamictreesquark:leaves0:1)
Block(-1,6,4,dynamictreesquark:leaves0:2)
Block(-1,6,5,dynamictreesquark:leaves0:1)
Block(-1,6,6,dynamictreesquark:leaves0:0)
Block(-1,7,-1,dynamictreesquark:leaves0:0)
Block(-1,7,0,dynamictreesquark:leaves0:1)
Block(-1,7,1,dynamictreesquark:leaves0:2)
Block(-1,7,2,dynamictreesquark:leaves0:1)
Block(-1,7,3,dynamictreesquark:leaves0:0)
Block(-1,7,4,dynamictreesquark:leaves0:0)
Block(-1,7,5,dynamictreesquark:leaves0:0)
Block(-1,8,0,dynamictreesquark:leaves0:0)
Block(-1,8,1,dynamictreesquark:leaves0:0)
Block(-1,8,2,dynamictreesquark:leaves0:0)
Block(0,0,1,dynamictrees:rootydirt:14)
Block(0,1,1,dynamictreesquark:blossomingbranch:6)
Block(0,2,1,dynamictreesquark:blossomingbranch:6)
Block(0,3,0,dynamictreesquark:blossomingbranch:0)
Block(0,3,1,dynamictreesquark:blossomingbranch:5)
Block(0,3,2,dynamictreesquark:blossomingbranch:2)
Block(0,3,3,dynamictreesquark:blossomingbranch:2)
Block(0,3,4,dynamictreesquark:blossomingbranch:0)
Block(0,4,-1,dynamictreesquark:leaves0:0)
Block(0,4,0,dynamictreesquark:leaves0:3)
Block(0,4,1,dynamictreesquark:blossomingbranch:2)
Block(0,4,3,dynamictreesquark:blossomingbranch:1)
Block(0,4,4,dynamictreesquark:leaves0:3)
Block(0,4,5,dynamictreesquark:leaves0:2)
Block(0,4,6,dynamictreesquark:leaves0:0)
Block(0,5,-1,dynamictreesquark:leaves0:0)
Block(0,5,0,dynamictreesquark:leaves0:2)
Block(0,5,1,dynamictreesquark:blossomingbranch:1)
Block(0,5,2,dynamictreesquark:leaves0:3)
Block(0,5,3,dynamictreesquark:blossomingbranch:1)
Block(0,5,4,dynamictreesquark:blossomingbranch:0)
Block(0,5,5,dynamictreesquark:leaves0:3)
Block(0,5,6,dynamictreesquark:leaves0:0)
Block(0,6,-1,dynamictreesquark:leaves0:0)
Block(0,6,0,dynamictreesquark:leaves0:3)
Block(0,6,1,dynamictreesquark:blossomingbranch:0)
Block(0,6,2,dynamictreesquark:leaves0:3)
Block(0,6,3,dynamictreesquark:leaves0:2)
Block(0,6,4,dynamictreesquark:leaves0:3)
Block(0,6,5,dynamictreesquark:leaves0:2)
Block(0,6,6,dynamictreesquark:leaves0:0)
Block(0,7,-1,dynamictreesquark:leaves0:0)
Block(0,7,0,dynamictreesquark:leaves0:2)
Block(0,7,1,dynamictreesquark:leaves0:3)
Block(0,7,2,dynamictreesquark:leaves0:2)
Block(0,7,3,dynamictreesquark:leaves0:1)
Block(0,7,4,dynamictreesquark:leaves0:0)
Block(0,7,5,dynamictreesquark:leaves0:0)
Block(0,8,0,dynamictreesquark:leaves0:0)
Block(0,8,1,dynamictreesquark:leaves0:0)
Block(0,8,2,dynamictreesquark:leaves0:0)
Block(0,8,3,dynamictreesquark:leaves0:0)
Block(1,3,1,dynamictreesquark:blossomingbranch:1)
Block(1,4,-1,dynamictreesquark:leaves0:0)
Block(1,4,3,dynamictreesquark:leaves0:1)
Block(1,4,4,dynamictreesquark:leaves0:2)
Block(1,4,5,dynamictreesquark:leaves0:1)
Block(1,4,6,dynamictreesquark:leaves0:0)
Block(1,5,-1,dynamictreesquark:leaves0:0)
Block(1,5,0,dynamictreesquark:leaves0:1)
Block(1,5,1,dynamictreesquark:blossomingbranch:1)
Block(1,5,2,dynamictreesquark:blossomingbranch:0)
Block(1,5,3,dynamictreesquark:leaves0:3)
Block(1,5,4,dynamictreesquark:leaves0:3)
Block(1,5,5,dynamictreesquark:leaves0:2)
Block(1,5,6,dynamictreesquark:leaves0:0)
Block(1,6,-1,dynamictreesquark:leaves0:0)
Block(1,6,0,dynamictreesquark:leaves0:2)
Block(1,6,1,dynamictreesquark:leaves0:3)
Block(1,6,2,dynamictreesquark:leaves0:3)
Block(1,6,3,dynamictreesquark:leaves0:2)
Block(1,6,4,dynamictreesquark:leaves0:2)
Block(1,6,5,dynamictreesquark:leaves0:1)
Block(1,6,6,dynamictreesquark:leaves0:0)
Block(1,7,-1,dynamictreesquark:leaves0:0)
Block(1,7,0,dynamictreesquark:leaves0:1)
Block(1,7,1,dynamictreesquark:leaves0:2)
Block(1,7,2,dynamictreesquark:leaves0:1)
Block(1,7,3,dynamictreesquark:leaves0:0)
Block(1,7,4,dynamictreesquark:leaves0:0)
Block(1,7,5,dynamictreesquark:leaves0:0)
Block(1,8,0,dynamictreesquark:leaves0:0)
Block(1,8,1,dynamictreesquark:leaves0:0)
Block(1,8,2,dynamictreesquark:leaves0:0)
Block(2,3,-2,dynamictreesquark:leaves0:0)
Block(2,3,-1,dynamictreesquark:leaves0:3)
Block(2,3,0,dynamictreesquark:blossomingbranch:0)
Block(2,3,1,dynamictreesquark:blossomingbranch:1)
Block(2,4,-2,dynamictreesquark:leaves0:0)
Block(2,4,-1,dynamictreesquark:leaves0:2)
Block(2,4,0,dynamictreesquark:leaves0:3)
Block(2,4,3,dynamictreesquark:leaves0:0)
Block(2,4,4,dynamictreesquark:leaves0:0)
Block(2,5,-2,dynamictreesquark:leaves0:0)
Block(2,5,-1,dynamictreesquark:leaves0:1)
Block(2,5,0,dynamictreesquark:leaves0:2)
Block(2,5,1,dynamictreesquark:leaves0:1)
Block(2,5,2,dynamictreesquark:leaves0:3)
Block(2,5,3,dynamictreesquark:leaves0:2)
Block(2,5,4,dynamictreesquark:leaves0:0)
Block(2,5,5,dynamictreesquark:leaves0:0)
Block(2,6,-1,dynamictreesquark:leaves0:0)
Block(2,6,0,dynamictreesquark:leaves0:1)
Block(2,6,1,dynamictreesquark:leaves0:0)
Block(2,6,2,dynamictreesquark:leaves0:2)
Block(2,6,3,dynamictreesquark:leaves0:1)
Block(2,6,4,dynamictreesquark:leaves0:0)
Block(2,6,5,dynamictreesquark:leaves0:0)
Block(2,7,0,dynamictreesquark:leaves0:0)
Block(2,7,1,dynamictreesquark:leaves0:0)
Block(2,7,2,dynamictreesquark:leaves0:0)
Block(2,7,3,dynamictreesquark:leaves0:0)
Block(3,2,-2,dynamictreesquark:leaves0:0)
Block(3,2,-1,dynamictreesquark:leaves0:0)
Block(3,3,-2,dynamictreesquark:leaves0:0)
Block(3,3,-1,dynamictreesquark:leaves0:2)
Block(3,3,0,dynamictreesquark:leaves0:3)
Block(3,3,1,dynamictreesquark:blossomingbranch:0)
Block(3,3,2,dynamictreesquark:leaves0:3)
Block(3,3,3,dynamictreesquark:leaves0:0)
Block(3,4,-2,dynamictreesquark:leaves0:0)
Block(3,4,-1,dynamictreesquark:leaves0:1)
Block(3,4,0,dynamictreesquark:leaves0:2)
Block(3,4,1,dynamictreesquark:leaves0:3)
Block(3,4,2,dynamictreesquark:leaves0:2)
Block(3,4,3,dynamictreesquark:leaves0:0)
Block(3,5,-1,dynamictreesquark:leaves0:0)
Block(3,5,0,dynamictreesquark:leaves0:1)
Block(3,5,1,dynamictreesquark:leaves0:0)
Block(3,5,2,dynamictreesquark:leaves0:0)
Block(3,5,3,dynamictreesquark:leaves0:0)
Block(3,6,0,dynamictreesquark:leaves0:0)
Block(3,6,2,dynamictreesquark:leaves0:0)
Block(3,6,3,dynamictreesquark:leaves0:0)
Block(4,2,-1,dynamictreesquark:leaves0:0)
Block(4,2,0,dynamictreesquark:leaves0:0)
Block(4,2,2,dynamictreesquark:leaves0:0)
Block(4,3,-2,dynamictreesquark:leaves0:0)
Block(4,3,-1,dynamictreesquark:leaves0:1)
Block(4,3,0,dynamictreesquark:leaves0:2)
Block(4,3,1,dynamictreesquark:leaves0:3)
Block(4,3,2,dynamictreesquark:leaves0:2)
Block(4,3,3,dynamictreesquark:leaves0:0)
Block(4,4,-1,dynamictreesquark:leaves0:0)
Block(4,4,0,dynamictreesquark:leaves0:1)
Block(4,4,1,dynamictreesquark:leaves0:2)
Block(4,4,2,dynamictreesquark:leaves0:1)
Block(4,4,3,dynamictreesquark:leaves0:0)
Block(4,5,0,dynamictreesquark:leaves0:0)
Block(4,5,1,dynamictreesquark:leaves0:0)
Block(4,5,2,dynamictreesquark:leaves0:0)
Block(5,3,-1,dynamictreesquark:leaves0:0)
Block(5,3,0,dynamictreesquark:leaves0:0)
Block(5,3,1,dynamictreesquark:leaves0:0)
Block(5,3,2,dynamictreesquark:leaves0:0)
Block(5,4,0,dynamictreesquark:leaves0:0)
Block(5,4,1,dynamictreesquark:leaves0:0)
Block(5,4,2,dynamictreesquark:leaves0:0)

#######################################################################
# +-----------------------------------------------------------------+ #
# |                            BO3 checks                           | #
# +-----------------------------------------------------------------+ #
#######################################################################

BlockCheck(0,-1,1,GRASS,DIRT,biomesoplenty:grass,biomesoplenty:dirt)

#######################################################################
# +-----------------------------------------------------------------+ #
# |                             Branches                            | #
# +-----------------------------------------------------------------+ #
#######################################################################


#######################################################################
# +-----------------------------------------------------------------+ #
# |                             Entities                            | #
# +-----------------------------------------------------------------+ #
#######################################################################


#######################################################################
# +-----------------------------------------------------------------+ #
# |                            Particles                            | #
# +-----------------------------------------------------------------+ #
#######################################################################


#######################################################################
# +-----------------------------------------------------------------+ #
# |                             Spawners                            | #
# +-----------------------------------------------------------------+ #
#######################################################################


#######################################################################
# +-----------------------------------------------------------------+ #
# |                             ModData                             | #
# +-----------------------------------------------------------------+ #
#######################################################################

