
#######################################################################
# +-----------------------------------------------------------------+ #
# |                            BO4 object                           | #
# +-----------------------------------------------------------------+ #
#######################################################################

Author: NLBlackEagle

Description: No description given

SettingsMode: WriteWithoutComments


#######################################################################
# +-----------------------------------------------------------------+ #
# |                          Main settings                          | #
# +-----------------------------------------------------------------+ #
#######################################################################

FixedRotation: 

Frequency: 0

SpawnHeight: highestBlock

UseCenterForHighestBlock: true

##############################
# Height Limits for the BO4. #
##############################

MinHeight: 0

MaxHeight: 255

InheritBO3: 

InheritBO3Rotation: NORTH

OverrideChildSettings: true

OverrideParentHeight: false

CanOverride: true

BranchFrequency: 0

BranchFrequencyGroup: 

MustBeBelowOther: false

MustBeInside: 

CannotBeInside: 

ReplacesBO3: 

MustBeInsideWorldBorders: false

CanSpawnOnWater: true

SpawnOnWaterOnly: false

SpawnUnderWater: false

SpawnAtWaterLevel: false

HeightOffset: 0

RemoveAir: false

ReplaceAbove: 

ReplaceBelow: 

ReplaceWithBiomeBlocks: true

ReplaceWithSurfaceBlock: GRASS

ReplaceWithGroundBlock: DIRT

ReplaceWithStoneBlock: STONE

SmoothRadius: 0

SmoothHeightOffset: 0

SmoothStartTop: false

SmoothStartWood: false

SmoothingSurfaceBlock: 

SmoothingGroundBlock: 

BO3Group: 

IsSpawnPoint: false

DoReplaceBlocks: false


#######################################################################
# +-----------------------------------------------------------------+ #
# |                              Blocks                             | #
# +-----------------------------------------------------------------+ #
#######################################################################

Block(-8,9,-6,COBBLESTONE_STAIRS:6)
RandomBlock(-8,9,-5,quark:iron_plate:1,null,70,STAINED_CLAY:15,null,30,STAINED_CLAY:7,null,30,quark:iron_plate:1,null,100)
Block(-8,9,-4,COBBLESTONE_STAIRS:7)
RandomBlock(-8,10,-6,quark:iron_plate:1,null,70,STAINED_CLAY:15,null,30,STAINED_CLAY:7,null,30,quark:iron_plate:1,null,100)
Block(-8,10,-5,srparasites:deadblood:0)
RandomBlock(-8,10,-4,quark:iron_plate:1,null,70,STAINED_CLAY:15,null,30,STAINED_CLAY:7,null,30,quark:iron_plate:1,null,100)
Block(-8,11,-6,COBBLESTONE_STAIRS:2)
RandomBlock(-8,11,-5,rustic:iron_lattice:1,null,30,rustic:iron_lattice:1,null,30,biomesoplenty:leaves_2:7,null,30,quark:iron_plate_stairs:6,null,10,quark:iron_plate_stairs:0,null,10,quark:iron_plate_stairs:5,null,10,quark:iron_plate_stairs:3,null,10,quark:iron_plate_slab:8,null,10,quark:iron_plate_stairs:7,null,10,quark:iron_plate_stairs:1,null,10,quark:iron_plate_slab:0,null,10,quark:iron_plate_stairs:4,null,10,quark:iron_plate_stairs:2,null,10,rustic:iron_lattice:1,null,50,rustic:iron_lattice:1,null,50,biomesoplenty:leaves_2:7,null,100)
Block(-8,11,-4,COBBLESTONE_STAIRS:3)
Block(-8,13,-5,quark:basalt_wall:0)
Block(-7,9,-6,COBBLESTONE_STAIRS:6)
RandomBlock(-7,9,-5,quark:iron_plate:1,null,70,STAINED_CLAY:15,null,30,STAINED_CLAY:7,null,30,quark:iron_plate:1,null,100)
Block(-7,9,-4,COBBLESTONE_STAIRS:7)
RandomBlock(-7,10,-6,quark:iron_plate:1,null,70,STAINED_CLAY:15,null,30,STAINED_CLAY:7,null,30,quark:iron_plate:1,null,100)
Block(-7,10,-5,srparasites:deadblood:0)
RandomBlock(-7,10,-4,quark:iron_plate:1,null,70,STAINED_CLAY:15,null,30,STAINED_CLAY:7,null,30,quark:iron_plate:1,null,100)
Block(-7,11,-6,COBBLESTONE_STAIRS:2)
RandomBlock(-7,11,-5,rustic:iron_lattice:1,null,30,rustic:iron_lattice:1,null,30,biomesoplenty:leaves_2:7,null,30,quark:iron_plate_stairs:6,null,10,quark:iron_plate_stairs:0,null,10,quark:iron_plate_stairs:5,null,10,quark:iron_plate_stairs:3,null,10,quark:iron_plate_slab:8,null,10,quark:iron_plate_stairs:7,null,10,quark:iron_plate_stairs:1,null,10,quark:iron_plate_slab:0,null,10,quark:iron_plate_stairs:4,null,10,quark:iron_plate_stairs:2,null,10,rustic:iron_lattice:1,null,50,rustic:iron_lattice:1,null,50,biomesoplenty:leaves_2:7,null,100)
Block(-7,11,-4,COBBLESTONE_STAIRS:3)
Block(-7,13,-5,quark:basalt_wall:0)
Block(-6,9,-6,COBBLESTONE_STAIRS:6)
RandomBlock(-6,9,-5,quark:iron_plate:1,null,70,STAINED_CLAY:15,null,30,STAINED_CLAY:7,null,30,quark:iron_plate:1,null,100)
Block(-6,9,-4,COBBLESTONE_STAIRS:7)
RandomBlock(-6,10,-6,quark:iron_plate:1,null,70,STAINED_CLAY:15,null,30,STAINED_CLAY:7,null,30,quark:iron_plate:1,null,100)
Block(-6,10,-5,srparasites:deadblood:0)
RandomBlock(-6,10,-4,quark:iron_plate:1,null,70,STAINED_CLAY:15,null,30,STAINED_CLAY:7,null,30,quark:iron_plate:1,null,100)
Block(-6,11,-6,COBBLESTONE_STAIRS:2)
RandomBlock(-6,11,-5,rustic:iron_lattice:1,null,30,rustic:iron_lattice:1,null,30,biomesoplenty:leaves_2:7,null,30,quark:iron_plate_stairs:6,null,10,quark:iron_plate_stairs:0,null,10,quark:iron_plate_stairs:5,null,10,quark:iron_plate_stairs:3,null,10,quark:iron_plate_slab:8,null,10,quark:iron_plate_stairs:7,null,10,quark:iron_plate_stairs:1,null,10,quark:iron_plate_slab:0,null,10,quark:iron_plate_stairs:4,null,10,quark:iron_plate_stairs:2,null,10,rustic:iron_lattice:1,null,50,rustic:iron_lattice:1,null,50,biomesoplenty:leaves_2:7,null,100)
Block(-6,11,-4,COBBLESTONE_STAIRS:3)
Block(-6,13,-5,quark:basalt_wall:0)
Block(-5,9,-6,COBBLESTONE_STAIRS:6)
RandomBlock(-5,9,-5,quark:iron_plate:1,null,70,STAINED_CLAY:15,null,30,STAINED_CLAY:7,null,30,quark:iron_plate:1,null,100)
Block(-5,9,-4,COBBLESTONE_STAIRS:7)
RandomBlock(-5,10,-6,quark:iron_plate:1,null,70,STAINED_CLAY:15,null,30,STAINED_CLAY:7,null,30,quark:iron_plate:1,null,100)
Block(-5,10,-5,srparasites:deadblood:0)
RandomBlock(-5,10,-4,quark:iron_plate:1,null,70,STAINED_CLAY:15,null,30,STAINED_CLAY:7,null,30,quark:iron_plate:1,null,100)
Block(-5,11,-6,COBBLESTONE_STAIRS:2)
RandomBlock(-5,11,-5,rustic:iron_lattice:1,null,30,rustic:iron_lattice:1,null,30,biomesoplenty:leaves_2:7,null,30,quark:iron_plate_stairs:6,null,10,quark:iron_plate_stairs:0,null,10,quark:iron_plate_stairs:5,null,10,quark:iron_plate_stairs:3,null,10,quark:iron_plate_slab:8,null,10,quark:iron_plate_stairs:7,null,10,quark:iron_plate_stairs:1,null,10,quark:iron_plate_slab:0,null,10,quark:iron_plate_stairs:4,null,10,quark:iron_plate_stairs:2,null,10,rustic:iron_lattice:1,null,50,rustic:iron_lattice:1,null,50,biomesoplenty:leaves_2:7,null,100)
Block(-5,11,-4,COBBLESTONE_STAIRS:3)
Block(-5,13,-5,quark:basalt_wall:0)
Block(-4,9,-6,COBBLESTONE_STAIRS:6)
RandomBlock(-4,9,-5,quark:iron_plate:1,null,70,STAINED_CLAY:15,null,30,STAINED_CLAY:7,null,30,quark:iron_plate:1,null,100)
Block(-4,9,-4,COBBLESTONE_STAIRS:7)
RandomBlock(-4,10,-6,quark:iron_plate:1,null,70,STAINED_CLAY:15,null,30,STAINED_CLAY:7,null,30,quark:iron_plate:1,null,100)
Block(-4,10,-5,srparasites:deadblood:0)
RandomBlock(-4,10,-4,quark:iron_plate:1,null,70,STAINED_CLAY:15,null,30,STAINED_CLAY:7,null,30,quark:iron_plate:1,null,100)
Block(-4,11,-6,COBBLESTONE_STAIRS:2)
RandomBlock(-4,11,-5,rustic:iron_lattice:1,null,30,rustic:iron_lattice:1,null,30,biomesoplenty:leaves_2:7,null,30,quark:iron_plate_stairs:6,null,10,quark:iron_plate_stairs:0,null,10,quark:iron_plate_stairs:5,null,10,quark:iron_plate_stairs:3,null,10,quark:iron_plate_slab:8,null,10,quark:iron_plate_stairs:7,null,10,quark:iron_plate_stairs:1,null,10,quark:iron_plate_slab:0,null,10,quark:iron_plate_stairs:4,null,10,quark:iron_plate_stairs:2,null,10,rustic:iron_lattice:1,null,50,rustic:iron_lattice:1,null,50,biomesoplenty:leaves_2:7,null,100)
Block(-4,11,-4,COBBLESTONE_STAIRS:3)
Block(-4,13,-5,quark:basalt_wall:0)
Block(-3,9,-6,COBBLESTONE_STAIRS:6)
RandomBlock(-3,9,-5,quark:iron_plate:1,null,70,STAINED_CLAY:15,null,30,STAINED_CLAY:7,null,30,quark:iron_plate:1,null,100)
Block(-3,9,-4,COBBLESTONE_STAIRS:7)
RandomBlock(-3,10,-6,quark:iron_plate:1,null,70,STAINED_CLAY:15,null,30,STAINED_CLAY:7,null,30,quark:iron_plate:1,null,100)
Block(-3,10,-5,srparasites:deadblood:0)
RandomBlock(-3,10,-4,quark:iron_plate:1,null,70,STAINED_CLAY:15,null,30,STAINED_CLAY:7,null,30,quark:iron_plate:1,null,100)
Block(-3,11,-6,COBBLESTONE_STAIRS:2)
RandomBlock(-3,11,-5,quark:iron_plate:1,null,70,STAINED_CLAY:15,null,30,STAINED_CLAY:7,null,30,quark:iron_plate:1,null,100)
Block(-3,11,-4,COBBLESTONE_STAIRS:3)
Block(-3,13,-5,quark:basalt_wall:0)
Block(-2,9,-6,COBBLESTONE_STAIRS:6)
RandomBlock(-2,9,-5,quark:iron_plate:1,null,70,STAINED_CLAY:15,null,30,STAINED_CLAY:7,null,30,quark:iron_plate:1,null,100)
Block(-2,9,-4,COBBLESTONE_STAIRS:7)
RandomBlock(-2,10,-6,quark:iron_plate:1,null,70,STAINED_CLAY:15,null,30,STAINED_CLAY:7,null,30,quark:iron_plate:1,null,100)
Block(-2,10,-5,srparasites:deadblood:0)
RandomBlock(-2,10,-4,quark:iron_plate:1,null,70,STAINED_CLAY:15,null,30,STAINED_CLAY:7,null,30,quark:iron_plate:1,null,100)
Block(-2,11,-6,COBBLESTONE_STAIRS:2)
RandomBlock(-2,11,-5,quark:iron_plate:1,null,70,STAINED_CLAY:15,null,30,STAINED_CLAY:7,null,30,quark:iron_plate:1,null,100)
Block(-2,11,-4,COBBLESTONE_STAIRS:3)
Block(-2,13,-5,quark:basalt_wall:0)
Block(-1,0,-5,quark:world_stone_pavement:2)
Block(-1,1,-5,quark:world_stone_pavement:2)
Block(-1,2,-5,quark:world_stone_pavement:2)
Block(-1,3,-5,quark:world_stone_pavement:2)
Block(-1,4,-5,quark:world_stone_pavement:2)
Block(-1,5,-5,quark:basalt_wall:0)
Block(-1,6,-5,quark:basalt_wall:0)
Block(-1,7,-5,quark:basalt_wall:0)
Block(-1,8,-5,quark:basalt_wall:0)
Block(-1,9,-6,COBBLESTONE_STAIRS:6)
RandomBlock(-1,9,-5,quark:iron_plate:1,null,70,STAINED_CLAY:15,null,30,STAINED_CLAY:7,null,30,quark:iron_plate:1,null,100)
Block(-1,9,-4,COBBLESTONE_STAIRS:7)
RandomBlock(-1,10,-6,quark:iron_plate:1,null,70,STAINED_CLAY:15,null,30,STAINED_CLAY:7,null,30,quark:iron_plate:1,null,100)
Block(-1,10,-5,srparasites:deadblood:0)
RandomBlock(-1,10,-4,quark:iron_plate:1,null,70,STAINED_CLAY:15,null,30,STAINED_CLAY:7,null,30,quark:iron_plate:1,null,100)
Block(-1,11,-6,COBBLESTONE_STAIRS:2)
RandomBlock(-1,11,-5,quark:iron_plate:1,null,70,STAINED_CLAY:15,null,30,STAINED_CLAY:7,null,30,quark:iron_plate:1,null,100)
Block(-1,11,-4,COBBLESTONE_STAIRS:3)
Block(-1,12,-5,quark:basalt_wall:0)
Block(-1,13,-5,quark:basalt_wall:0)
Block(0,9,-6,COBBLESTONE_STAIRS:6)
RandomBlock(0,9,-5,quark:iron_plate:1,null,70,STAINED_CLAY:15,null,30,STAINED_CLAY:7,null,30,quark:iron_plate:1,null,100)
Block(0,9,-4,COBBLESTONE_STAIRS:7)
RandomBlock(0,10,-6,quark:iron_plate:1,null,70,STAINED_CLAY:15,null,30,STAINED_CLAY:7,null,30,quark:iron_plate:1,null,100)
Block(0,10,-5,srparasites:deadblood:0)
RandomBlock(0,10,-4,quark:iron_plate:1,null,70,STAINED_CLAY:15,null,30,STAINED_CLAY:7,null,30,quark:iron_plate:1,null,100)
Block(0,11,-6,COBBLESTONE_STAIRS:2)
RandomBlock(0,11,-5,quark:iron_plate:1,null,70,STAINED_CLAY:15,null,30,STAINED_CLAY:7,null,30,quark:iron_plate:1,null,100)
Block(0,11,-4,COBBLESTONE_STAIRS:3)
Block(0,13,-5,quark:basalt_wall:0)
Block(1,9,-6,COBBLESTONE_STAIRS:6)
RandomBlock(1,9,-5,quark:iron_plate:1,null,70,STAINED_CLAY:15,null,30,STAINED_CLAY:7,null,30,quark:iron_plate:1,null,100)
Block(1,9,-4,COBBLESTONE_STAIRS:7)
RandomBlock(1,10,-6,quark:iron_plate:1,null,70,STAINED_CLAY:15,null,30,STAINED_CLAY:7,null,30,quark:iron_plate:1,null,100)
Block(1,10,-5,srparasites:deadblood:0)
RandomBlock(1,10,-4,quark:iron_plate:1,null,70,STAINED_CLAY:15,null,30,STAINED_CLAY:7,null,30,quark:iron_plate:1,null,100)
Block(1,11,-6,COBBLESTONE_STAIRS:2)
RandomBlock(1,11,-5,quark:iron_plate:1,null,70,STAINED_CLAY:15,null,30,STAINED_CLAY:7,null,30,quark:iron_plate:1,null,100)
Block(1,11,-4,COBBLESTONE_STAIRS:3)
Block(1,13,-5,quark:basalt_wall:0)
Block(2,9,-6,COBBLESTONE_STAIRS:6)
RandomBlock(2,9,-5,quark:iron_plate:1,null,70,STAINED_CLAY:15,null,30,STAINED_CLAY:7,null,30,quark:iron_plate:1,null,100)
Block(2,9,-4,COBBLESTONE_STAIRS:7)
RandomBlock(2,10,-6,quark:iron_plate:1,null,70,STAINED_CLAY:15,null,30,STAINED_CLAY:7,null,30,quark:iron_plate:1,null,100)
Block(2,10,-5,srparasites:deadblood:0)
RandomBlock(2,10,-4,quark:iron_plate:1,null,70,STAINED_CLAY:15,null,30,STAINED_CLAY:7,null,30,quark:iron_plate:1,null,100)
Block(2,11,-6,COBBLESTONE_STAIRS:2)
RandomBlock(2,11,-5,quark:iron_plate:1,null,70,STAINED_CLAY:15,null,30,STAINED_CLAY:7,null,30,quark:iron_plate:1,null,100)
Block(2,11,-4,COBBLESTONE_STAIRS:3)
Block(2,13,-5,quark:basalt_wall:0)
Block(3,9,-6,COBBLESTONE_STAIRS:6)
RandomBlock(3,9,-5,quark:iron_plate:1,null,70,STAINED_CLAY:15,null,30,STAINED_CLAY:7,null,30,quark:iron_plate:1,null,100)
Block(3,9,-4,COBBLESTONE_STAIRS:7)
RandomBlock(3,10,-6,quark:iron_plate:1,null,70,STAINED_CLAY:15,null,30,STAINED_CLAY:7,null,30,quark:iron_plate:1,null,100)
Block(3,10,-5,srparasites:deadblood:0)
RandomBlock(3,10,-4,quark:iron_plate:1,null,70,STAINED_CLAY:15,null,30,STAINED_CLAY:7,null,30,quark:iron_plate:1,null,100)
Block(3,11,-6,COBBLESTONE_STAIRS:2)
RandomBlock(3,11,-5,rustic:iron_lattice:1,null,30,rustic:iron_lattice:1,null,30,biomesoplenty:leaves_2:7,null,30,quark:iron_plate_stairs:6,null,10,quark:iron_plate_stairs:0,null,10,quark:iron_plate_stairs:5,null,10,quark:iron_plate_stairs:3,null,10,quark:iron_plate_slab:8,null,10,quark:iron_plate_stairs:7,null,10,quark:iron_plate_stairs:1,null,10,quark:iron_plate_slab:0,null,10,quark:iron_plate_stairs:4,null,10,quark:iron_plate_stairs:2,null,10,rustic:iron_lattice:1,null,50,rustic:iron_lattice:1,null,50,biomesoplenty:leaves_2:7,null,100)
Block(3,11,-4,COBBLESTONE_STAIRS:3)
Block(3,13,-5,quark:basalt_wall:0)
Block(4,9,-6,COBBLESTONE_STAIRS:6)
RandomBlock(4,9,-5,quark:iron_plate:1,null,70,STAINED_CLAY:15,null,30,STAINED_CLAY:7,null,30,quark:iron_plate:1,null,100)
Block(4,9,-4,COBBLESTONE_STAIRS:7)
RandomBlock(4,10,-6,quark:iron_plate:1,null,70,STAINED_CLAY:15,null,30,STAINED_CLAY:7,null,30,quark:iron_plate:1,null,100)
Block(4,10,-5,srparasites:deadblood:0)
RandomBlock(4,10,-4,quark:iron_plate:1,null,70,STAINED_CLAY:15,null,30,STAINED_CLAY:7,null,30,quark:iron_plate:1,null,100)
Block(4,11,-6,COBBLESTONE_STAIRS:2)
RandomBlock(4,11,-5,rustic:iron_lattice:1,null,30,rustic:iron_lattice:1,null,30,biomesoplenty:leaves_2:7,null,30,quark:iron_plate_stairs:6,null,10,quark:iron_plate_stairs:0,null,10,quark:iron_plate_stairs:5,null,10,quark:iron_plate_stairs:3,null,10,quark:iron_plate_slab:8,null,10,quark:iron_plate_stairs:7,null,10,quark:iron_plate_stairs:1,null,10,quark:iron_plate_slab:0,null,10,quark:iron_plate_stairs:4,null,10,quark:iron_plate_stairs:2,null,10,rustic:iron_lattice:1,null,50,rustic:iron_lattice:1,null,50,biomesoplenty:leaves_2:7,null,100)
Block(4,11,-4,COBBLESTONE_STAIRS:3)
Block(4,13,-5,quark:basalt_wall:0)
Block(5,9,-6,COBBLESTONE_STAIRS:6)
RandomBlock(5,9,-5,quark:iron_plate:1,null,70,STAINED_CLAY:15,null,30,STAINED_CLAY:7,null,30,quark:iron_plate:1,null,100)
Block(5,9,-4,COBBLESTONE_STAIRS:7)
RandomBlock(5,10,-6,quark:iron_plate:1,null,70,STAINED_CLAY:15,null,30,STAINED_CLAY:7,null,30,quark:iron_plate:1,null,100)
Block(5,10,-5,srparasites:deadblood:0)
RandomBlock(5,10,-4,quark:iron_plate:1,null,70,STAINED_CLAY:15,null,30,STAINED_CLAY:7,null,30,quark:iron_plate:1,null,100)
Block(5,11,-6,COBBLESTONE_STAIRS:2)
RandomBlock(5,11,-5,rustic:iron_lattice:1,null,30,rustic:iron_lattice:1,null,30,biomesoplenty:leaves_2:7,null,30,quark:iron_plate_stairs:6,null,10,quark:iron_plate_stairs:0,null,10,quark:iron_plate_stairs:5,null,10,quark:iron_plate_stairs:3,null,10,quark:iron_plate_slab:8,null,10,quark:iron_plate_stairs:7,null,10,quark:iron_plate_stairs:1,null,10,quark:iron_plate_slab:0,null,10,quark:iron_plate_stairs:4,null,10,quark:iron_plate_stairs:2,null,10,rustic:iron_lattice:1,null,50,rustic:iron_lattice:1,null,50,biomesoplenty:leaves_2:7,null,100)
Block(5,11,-4,COBBLESTONE_STAIRS:3)
Block(5,13,-5,quark:basalt_wall:0)
Block(6,9,-6,COBBLESTONE_STAIRS:6)
RandomBlock(6,9,-5,quark:iron_plate:1,null,70,STAINED_CLAY:15,null,30,STAINED_CLAY:7,null,30,quark:iron_plate:1,null,100)
Block(6,9,-4,COBBLESTONE_STAIRS:7)
RandomBlock(6,10,-6,quark:iron_plate:1,null,70,STAINED_CLAY:15,null,30,STAINED_CLAY:7,null,30,quark:iron_plate:1,null,100)
Block(6,10,-5,srparasites:deadblood:0)
RandomBlock(6,10,-4,quark:iron_plate:1,null,70,STAINED_CLAY:15,null,30,STAINED_CLAY:7,null,30,quark:iron_plate:1,null,100)
Block(6,11,-6,COBBLESTONE_STAIRS:2)
RandomBlock(6,11,-5,quark:iron_plate:1,null,70,STAINED_CLAY:15,null,30,STAINED_CLAY:7,null,30,quark:iron_plate:1,null,100)
Block(6,11,-4,COBBLESTONE_STAIRS:3)
Block(6,13,-5,quark:basalt_wall:0)
Block(7,9,-6,COBBLESTONE_STAIRS:6)
RandomBlock(7,9,-5,quark:iron_plate:1,null,70,STAINED_CLAY:15,null,30,STAINED_CLAY:7,null,30,quark:iron_plate:1,null,100)
Block(7,9,-4,COBBLESTONE_STAIRS:7)
RandomBlock(7,10,-6,quark:iron_plate:1,null,70,STAINED_CLAY:15,null,30,STAINED_CLAY:7,null,30,quark:iron_plate:1,null,100)
Block(7,10,-5,srparasites:deadblood:0)
RandomBlock(7,10,-4,quark:iron_plate:1,null,70,STAINED_CLAY:15,null,30,STAINED_CLAY:7,null,30,quark:iron_plate:1,null,100)
Block(7,11,-6,COBBLESTONE_STAIRS:2)
RandomBlock(7,11,-5,quark:iron_plate:1,null,70,STAINED_CLAY:15,null,30,STAINED_CLAY:7,null,30,quark:iron_plate:1,null,100)
Block(7,11,-4,COBBLESTONE_STAIRS:3)
Block(7,13,-5,quark:basalt_wall:0)

#######################################################################
# +-----------------------------------------------------------------+ #
# |                             Branches                            | #
# +-----------------------------------------------------------------+ #
#######################################################################

Branch(16,0,0,true,brutal_pipesmall_05C2R0,NORTH,100.0,0)

#######################################################################
# +-----------------------------------------------------------------+ #
# |                             Entities                            | #
# +-----------------------------------------------------------------+ #
#######################################################################


#######################################################################
# +-----------------------------------------------------------------+ #
# |                            Particles                            | #
# +-----------------------------------------------------------------+ #
#######################################################################


#######################################################################
# +-----------------------------------------------------------------+ #
# |                             Spawners                            | #
# +-----------------------------------------------------------------+ #
#######################################################################


#######################################################################
# +-----------------------------------------------------------------+ #
# |                             ModData                             | #
# +-----------------------------------------------------------------+ #
#######################################################################

