
#######################################################################
# +-----------------------------------------------------------------+ #
# |                            BO4 object                           | #
# +-----------------------------------------------------------------+ #
#######################################################################

Author: NLBlackEagle

Description: No description given

SettingsMode: WriteWithoutComments


#######################################################################
# +-----------------------------------------------------------------+ #
# |                          Main settings                          | #
# +-----------------------------------------------------------------+ #
#######################################################################

FixedRotation: 

Frequency: 0

SpawnHeight: highestBlock

UseCenterForHighestBlock: true

##############################
# Height Limits for the BO4. #
##############################

MinHeight: 0

MaxHeight: 255

InheritBO3: 

InheritBO3Rotation: NORTH

OverrideChildSettings: true

OverrideParentHeight: false

CanOverride: true

BranchFrequency: 0

BranchFrequencyGroup: 

MustBeBelowOther: false

MustBeInside: 

CannotBeInside: 

ReplacesBO3: 

MustBeInsideWorldBorders: false

CanSpawnOnWater: true

SpawnOnWaterOnly: false

SpawnUnderWater: false

SpawnAtWaterLevel: false

HeightOffset: 0

RemoveAir: false

ReplaceAbove: 

ReplaceBelow: 

ReplaceWithBiomeBlocks: true

ReplaceWithSurfaceBlock: GRASS

ReplaceWithGroundBlock: DIRT

ReplaceWithStoneBlock: STONE

SmoothRadius: 0

SmoothHeightOffset: 0

SmoothStartTop: false

SmoothStartWood: false

SmoothingSurfaceBlock: 

SmoothingGroundBlock: 

BO3Group: 

IsSpawnPoint: false

DoReplaceBlocks: false


#######################################################################
# +-----------------------------------------------------------------+ #
# |                              Blocks                             | #
# +-----------------------------------------------------------------+ #
#######################################################################

Block(-8,9,-6,COBBLESTONE_STAIRS:6)
RandomBlock(-8,9,-5,quark:iron_plate:1,null,70,STAINED_CLAY:15,null,30,STAINED_CLAY:7,null,30,quark:iron_plate:1,null,100)
Block(-8,9,-4,COBBLESTONE_STAIRS:7)
RandomBlock(-8,10,-6,quark:iron_plate:1,null,70,STAINED_CLAY:15,null,30,STAINED_CLAY:7,null,30,quark:iron_plate:1,null,100)
Block(-8,10,-5,srparasites:deadblood:0)
RandomBlock(-8,10,-4,quark:iron_plate:1,null,70,STAINED_CLAY:15,null,30,STAINED_CLAY:7,null,30,quark:iron_plate:1,null,100)
Block(-8,11,-6,COBBLESTONE_STAIRS:2)
RandomBlock(-8,11,-5,rustic:iron_lattice:1,null,30,rustic:iron_lattice:1,null,30,biomesoplenty:leaves_2:7,null,30,quark:iron_plate_stairs:6,null,10,quark:iron_plate_stairs:0,null,10,quark:iron_plate_stairs:5,null,10,quark:iron_plate_stairs:3,null,10,quark:iron_plate_slab:8,null,10,quark:iron_plate_stairs:7,null,10,quark:iron_plate_stairs:1,null,10,quark:iron_plate_slab:0,null,10,quark:iron_plate_stairs:4,null,10,quark:iron_plate_stairs:2,null,10,rustic:iron_lattice:1,null,50,rustic:iron_lattice:1,null,50,biomesoplenty:leaves_2:7,null,100)
Block(-8,11,-4,COBBLESTONE_STAIRS:3)
Block(-8,13,-5,quark:basalt_wall:0)
Block(-7,9,-6,COBBLESTONE_STAIRS:6)
RandomBlock(-7,9,-5,quark:iron_plate:1,null,70,STAINED_CLAY:15,null,30,STAINED_CLAY:7,null,30,quark:iron_plate:1,null,100)
Block(-7,9,-4,COBBLESTONE_STAIRS:7)
RandomBlock(-7,10,-6,quark:iron_plate:1,null,70,STAINED_CLAY:15,null,30,STAINED_CLAY:7,null,30,quark:iron_plate:1,null,100)
Block(-7,10,-5,srparasites:deadblood:0)
RandomBlock(-7,10,-4,quark:iron_plate:1,null,70,STAINED_CLAY:15,null,30,STAINED_CLAY:7,null,30,quark:iron_plate:1,null,100)
Block(-7,11,-6,COBBLESTONE_STAIRS:2)
RandomBlock(-7,11,-5,rustic:iron_lattice:1,null,30,rustic:iron_lattice:1,null,30,biomesoplenty:leaves_2:7,null,30,quark:iron_plate_stairs:6,null,10,quark:iron_plate_stairs:0,null,10,quark:iron_plate_stairs:5,null,10,quark:iron_plate_stairs:3,null,10,quark:iron_plate_slab:8,null,10,quark:iron_plate_stairs:7,null,10,quark:iron_plate_stairs:1,null,10,quark:iron_plate_slab:0,null,10,quark:iron_plate_stairs:4,null,10,quark:iron_plate_stairs:2,null,10,rustic:iron_lattice:1,null,50,rustic:iron_lattice:1,null,50,biomesoplenty:leaves_2:7,null,100)
Block(-7,11,-4,COBBLESTONE_STAIRS:3)
Block(-7,13,-5,quark:basalt_wall:0)
Block(-6,9,-6,COBBLESTONE_STAIRS:6)
RandomBlock(-6,9,-5,quark:iron_plate:1,null,70,STAINED_CLAY:15,null,30,STAINED_CLAY:7,null,30,quark:iron_plate:1,null,100)
Block(-6,9,-4,COBBLESTONE_STAIRS:7)
RandomBlock(-6,10,-6,quark:iron_plate:1,null,70,STAINED_CLAY:15,null,30,STAINED_CLAY:7,null,30,quark:iron_plate:1,null,100)
Block(-6,10,-5,srparasites:deadblood:0)
RandomBlock(-6,10,-4,quark:iron_plate:1,null,70,STAINED_CLAY:15,null,30,STAINED_CLAY:7,null,30,quark:iron_plate:1,null,100)
Block(-6,11,-6,COBBLESTONE_STAIRS:2)
RandomBlock(-6,11,-5,rustic:iron_lattice:1,null,30,rustic:iron_lattice:1,null,30,biomesoplenty:leaves_2:7,null,30,quark:iron_plate_stairs:6,null,10,quark:iron_plate_stairs:0,null,10,quark:iron_plate_stairs:5,null,10,quark:iron_plate_stairs:3,null,10,quark:iron_plate_slab:8,null,10,quark:iron_plate_stairs:7,null,10,quark:iron_plate_stairs:1,null,10,quark:iron_plate_slab:0,null,10,quark:iron_plate_stairs:4,null,10,quark:iron_plate_stairs:2,null,10,rustic:iron_lattice:1,null,50,rustic:iron_lattice:1,null,50,biomesoplenty:leaves_2:7,null,100)
Block(-6,11,-4,COBBLESTONE_STAIRS:3)
Block(-6,13,-5,quark:basalt_wall:0)
Block(-5,9,-6,COBBLESTONE_STAIRS:6)
RandomBlock(-5,9,-5,quark:iron_plate:1,null,70,STAINED_CLAY:15,null,30,STAINED_CLAY:7,null,30,quark:iron_plate:1,null,100)
Block(-5,9,-4,COBBLESTONE_STAIRS:7)
RandomBlock(-5,10,-6,quark:iron_plate:1,null,70,STAINED_CLAY:15,null,30,STAINED_CLAY:7,null,30,quark:iron_plate:1,null,100)
Block(-5,10,-5,srparasites:deadblood:0)
RandomBlock(-5,10,-4,quark:iron_plate:1,null,70,STAINED_CLAY:15,null,30,STAINED_CLAY:7,null,30,quark:iron_plate:1,null,100)
Block(-5,11,-6,COBBLESTONE_STAIRS:2)
RandomBlock(-5,11,-5,quark:iron_plate:1,null,70,STAINED_CLAY:15,null,30,STAINED_CLAY:7,null,30,quark:iron_plate:1,null,100)
Block(-5,11,-4,COBBLESTONE_STAIRS:3)
Block(-5,13,-5,quark:basalt_wall:0)
Block(-4,0,-5,quark:world_stone_pavement:2)
Block(-4,1,-5,quark:world_stone_pavement:2)
Block(-4,2,-5,quark:world_stone_pavement:2)
Block(-4,3,-5,quark:world_stone_pavement:2)
Block(-4,4,-5,quark:world_stone_pavement:2)
Block(-4,5,-5,quark:basalt_wall:0)
Block(-4,6,-5,quark:basalt_wall:0)
Block(-4,7,-5,quark:basalt_wall:0)
Block(-4,8,-5,quark:basalt_wall:0)
Block(-4,9,-6,COBBLESTONE_STAIRS:6)
RandomBlock(-4,9,-5,quark:iron_plate:1,null,70,STAINED_CLAY:15,null,30,STAINED_CLAY:7,null,30,quark:iron_plate:1,null,100)
Block(-4,9,-4,COBBLESTONE_STAIRS:7)
RandomBlock(-4,10,-6,quark:iron_plate:1,null,70,STAINED_CLAY:15,null,30,STAINED_CLAY:7,null,30,quark:iron_plate:1,null,100)
Block(-4,10,-5,srparasites:deadblood:0)
RandomBlock(-4,10,-4,quark:iron_plate:1,null,70,STAINED_CLAY:15,null,30,STAINED_CLAY:7,null,30,quark:iron_plate:1,null,100)
Block(-4,11,-6,COBBLESTONE_STAIRS:2)
RandomBlock(-4,11,-5,quark:iron_plate:1,null,70,STAINED_CLAY:15,null,30,STAINED_CLAY:7,null,30,quark:iron_plate:1,null,100)
Block(-4,11,-4,COBBLESTONE_STAIRS:3)
Block(-4,12,-5,quark:basalt_wall:0)
Block(-4,13,-5,quark:basalt_wall:0)
Block(-3,9,-6,COBBLESTONE_STAIRS:6)
RandomBlock(-3,9,-5,quark:iron_plate:1,null,70,STAINED_CLAY:15,null,30,STAINED_CLAY:7,null,30,quark:iron_plate:1,null,100)
Block(-3,9,-4,COBBLESTONE_STAIRS:7)
RandomBlock(-3,10,-6,quark:iron_plate:1,null,70,STAINED_CLAY:15,null,30,STAINED_CLAY:7,null,30,quark:iron_plate:1,null,100)
Block(-3,10,-5,srparasites:deadblood:0)
RandomBlock(-3,10,-4,quark:iron_plate:1,null,70,STAINED_CLAY:15,null,30,STAINED_CLAY:7,null,30,quark:iron_plate:1,null,100)
Block(-3,11,-6,COBBLESTONE_STAIRS:2)
RandomBlock(-3,11,-5,quark:iron_plate:1,null,70,STAINED_CLAY:15,null,30,STAINED_CLAY:7,null,30,quark:iron_plate:1,null,100)
Block(-3,11,-4,COBBLESTONE_STAIRS:3)
Block(-3,13,-5,quark:basalt_wall:0)
Block(-2,9,-6,COBBLESTONE_STAIRS:6)
RandomBlock(-2,9,-5,quark:iron_plate:1,null,70,STAINED_CLAY:15,null,30,STAINED_CLAY:7,null,30,quark:iron_plate:1,null,100)
Block(-2,9,-4,COBBLESTONE_STAIRS:7)
RandomBlock(-2,10,-6,quark:iron_plate:1,null,70,STAINED_CLAY:15,null,30,STAINED_CLAY:7,null,30,quark:iron_plate:1,null,100)
Block(-2,10,-5,srparasites:deadblood:0)
RandomBlock(-2,10,-4,quark:iron_plate:1,null,70,STAINED_CLAY:15,null,30,STAINED_CLAY:7,null,30,quark:iron_plate:1,null,100)
Block(-2,11,-6,COBBLESTONE_STAIRS:2)
RandomBlock(-2,11,-5,quark:iron_plate:1,null,70,STAINED_CLAY:15,null,30,STAINED_CLAY:7,null,30,quark:iron_plate:1,null,100)
Block(-2,11,-4,COBBLESTONE_STAIRS:3)
Block(-2,13,-5,quark:basalt_wall:0)
Block(-1,9,-6,COBBLESTONE_STAIRS:6)
RandomBlock(-1,9,-5,quark:iron_plate:1,null,70,STAINED_CLAY:15,null,30,STAINED_CLAY:7,null,30,quark:iron_plate:1,null,100)
Block(-1,9,-4,COBBLESTONE_STAIRS:7)
RandomBlock(-1,10,-6,quark:iron_plate:1,null,70,STAINED_CLAY:15,null,30,STAINED_CLAY:7,null,30,quark:iron_plate:1,null,100)
Block(-1,10,-5,srparasites:deadblood:0)
RandomBlock(-1,10,-4,quark:iron_plate:1,null,70,STAINED_CLAY:15,null,30,STAINED_CLAY:7,null,30,quark:iron_plate:1,null,100)
Block(-1,11,-6,COBBLESTONE_STAIRS:2)
RandomBlock(-1,11,-5,quark:iron_plate:1,null,70,STAINED_CLAY:15,null,30,STAINED_CLAY:7,null,30,quark:iron_plate:1,null,100)
Block(-1,11,-4,COBBLESTONE_STAIRS:3)
Block(-1,13,-5,quark:basalt_wall:0)
Block(0,9,-6,COBBLESTONE_STAIRS:6)
RandomBlock(0,9,-5,quark:iron_plate:1,null,70,STAINED_CLAY:15,null,30,STAINED_CLAY:7,null,30,quark:iron_plate:1,null,100)
Block(0,9,-4,COBBLESTONE_STAIRS:7)
RandomBlock(0,10,-6,quark:iron_plate:1,null,70,STAINED_CLAY:15,null,30,STAINED_CLAY:7,null,30,quark:iron_plate:1,null,100)
Block(0,10,-5,srparasites:deadblood:0)
RandomBlock(0,10,-4,quark:iron_plate:1,null,70,STAINED_CLAY:15,null,30,STAINED_CLAY:7,null,30,quark:iron_plate:1,null,100)
Block(0,11,-6,COBBLESTONE_STAIRS:2)
RandomBlock(0,11,-5,quark:iron_plate:1,null,70,STAINED_CLAY:15,null,30,STAINED_CLAY:7,null,30,quark:iron_plate:1,null,100)
Block(0,11,-4,COBBLESTONE_STAIRS:3)
Block(0,13,-5,quark:basalt_wall:0)
Block(1,0,-7,quark:limestone:0)
Block(1,0,-6,quark:limestone:0)
Block(1,0,-5,quark:limestone:0)
Block(1,0,-4,quark:limestone:0)
Block(1,0,-3,quark:limestone:0)
Block(1,1,-7,COBBLESTONE_STAIRS:2)
Block(1,1,-6,COBBLESTONE_STAIRS:0)
Block(1,1,-5,COBBLESTONE_STAIRS:0)
Block(1,1,-4,COBBLESTONE_STAIRS:0)
Block(1,1,-3,COBBLESTONE_STAIRS:0)
Block(1,9,-6,COBBLESTONE_STAIRS:6)
RandomBlock(1,9,-5,quark:iron_plate:1,null,70,STAINED_CLAY:15,null,30,STAINED_CLAY:7,null,30,quark:iron_plate:1,null,100)
Block(1,9,-4,COBBLESTONE_STAIRS:7)
RandomBlock(1,10,-6,quark:iron_plate:1,null,70,STAINED_CLAY:15,null,30,STAINED_CLAY:7,null,30,quark:iron_plate:1,null,100)
Block(1,10,-5,srparasites:deadblood:0)
RandomBlock(1,10,-4,quark:iron_plate:1,null,70,STAINED_CLAY:15,null,30,STAINED_CLAY:7,null,30,quark:iron_plate:1,null,100)
Block(1,11,-6,COBBLESTONE_STAIRS:2)
RandomBlock(1,11,-5,quark:iron_plate:1,null,70,STAINED_CLAY:15,null,30,STAINED_CLAY:7,null,30,quark:iron_plate:1,null,100)
Block(1,11,-4,COBBLESTONE_STAIRS:3)
Block(1,13,-5,quark:basalt_wall:0)
Block(2,0,-7,quark:limestone:0)
RandomBlock(2,0,-6,rustic:iron_lattice:1,null,30,rustic:iron_lattice:1,null,30,biomesoplenty:leaves_2:7,null,30,quark:iron_plate_stairs:6,null,10,quark:iron_plate_stairs:0,null,10,quark:iron_plate_stairs:5,null,10,quark:iron_plate_stairs:3,null,10,quark:iron_plate_slab:8,null,10,quark:iron_plate_stairs:7,null,10,quark:iron_plate_stairs:1,null,10,quark:iron_plate_slab:0,null,10,quark:iron_plate_stairs:4,null,10,quark:iron_plate_stairs:2,null,10,rustic:iron_lattice:1,null,50,rustic:iron_lattice:1,null,50,biomesoplenty:leaves_2:7,null,100)
RandomBlock(2,0,-5,quark:iron_plate:1,null,70,STAINED_CLAY:15,null,30,STAINED_CLAY:7,null,30,quark:iron_plate:1,null,100)
RandomBlock(2,0,-4,quark:iron_plate:1,null,70,STAINED_CLAY:15,null,30,STAINED_CLAY:7,null,30,quark:iron_plate:1,null,100)
Block(2,0,-3,quark:limestone:0)
Block(2,1,-7,COBBLESTONE_STAIRS:2)
RandomBlock(2,1,-6,rustic:iron_lattice:1,null,30,rustic:iron_lattice:1,null,30,biomesoplenty:leaves_2:7,null,30,quark:iron_plate_stairs:6,null,10,quark:iron_plate_stairs:0,null,10,quark:iron_plate_stairs:5,null,10,quark:iron_plate_stairs:3,null,10,quark:iron_plate_slab:8,null,10,quark:iron_plate_stairs:7,null,10,quark:iron_plate_stairs:1,null,10,quark:iron_plate_slab:0,null,10,quark:iron_plate_stairs:4,null,10,quark:iron_plate_stairs:2,null,10,rustic:iron_lattice:1,null,50,rustic:iron_lattice:1,null,50,biomesoplenty:leaves_2:7,null,100)
RandomBlock(2,1,-5,quark:iron_plate:1,null,70,STAINED_CLAY:15,null,30,STAINED_CLAY:7,null,30,quark:iron_plate:1,null,100)
RandomBlock(2,1,-4,quark:iron_plate:1,null,70,STAINED_CLAY:15,null,30,STAINED_CLAY:7,null,30,quark:iron_plate:1,null,100)
Block(2,1,-3,COBBLESTONE_STAIRS:3)
RandomBlock(2,2,-6,rustic:iron_lattice:1,null,30,rustic:iron_lattice:1,null,30,biomesoplenty:leaves_2:7,null,30,quark:iron_plate_stairs:6,null,10,quark:iron_plate_stairs:0,null,10,quark:iron_plate_stairs:5,null,10,quark:iron_plate_stairs:3,null,10,quark:iron_plate_slab:8,null,10,quark:iron_plate_stairs:7,null,10,quark:iron_plate_stairs:1,null,10,quark:iron_plate_slab:0,null,10,quark:iron_plate_stairs:4,null,10,quark:iron_plate_stairs:2,null,10,rustic:iron_lattice:1,null,50,rustic:iron_lattice:1,null,50,biomesoplenty:leaves_2:7,null,100)
RandomBlock(2,2,-5,quark:iron_plate:1,null,70,STAINED_CLAY:15,null,30,STAINED_CLAY:7,null,30,quark:iron_plate:1,null,100)
RandomBlock(2,2,-4,quark:iron_plate:1,null,70,STAINED_CLAY:15,null,30,STAINED_CLAY:7,null,30,quark:iron_plate:1,null,100)
RandomBlock(2,3,-6,quark:iron_plate:1,null,70,STAINED_CLAY:15,null,30,STAINED_CLAY:7,null,30,quark:iron_plate:1,null,100)
RandomBlock(2,3,-5,quark:iron_plate:1,null,70,STAINED_CLAY:15,null,30,STAINED_CLAY:7,null,30,quark:iron_plate:1,null,100)
RandomBlock(2,3,-4,quark:iron_plate:1,null,70,STAINED_CLAY:15,null,30,STAINED_CLAY:7,null,30,quark:iron_plate:1,null,100)
RandomBlock(2,4,-6,quark:iron_plate:1,null,70,STAINED_CLAY:15,null,30,STAINED_CLAY:7,null,30,quark:iron_plate:1,null,100)
RandomBlock(2,4,-5,quark:iron_plate:1,null,70,STAINED_CLAY:15,null,30,STAINED_CLAY:7,null,30,quark:iron_plate:1,null,100)
RandomBlock(2,4,-4,rustic:iron_lattice:1,null,30,rustic:iron_lattice:1,null,30,biomesoplenty:leaves_2:7,null,30,quark:iron_plate_stairs:6,null,10,quark:iron_plate_stairs:0,null,10,quark:iron_plate_stairs:5,null,10,quark:iron_plate_stairs:3,null,10,quark:iron_plate_slab:8,null,10,quark:iron_plate_stairs:7,null,10,quark:iron_plate_stairs:1,null,10,quark:iron_plate_slab:0,null,10,quark:iron_plate_stairs:4,null,10,quark:iron_plate_stairs:2,null,10,rustic:iron_lattice:1,null,50,rustic:iron_lattice:1,null,50,biomesoplenty:leaves_2:7,null,100)
RandomBlock(2,5,-6,rustic:iron_lattice:1,null,30,rustic:iron_lattice:1,null,30,biomesoplenty:leaves_2:7,null,30,quark:iron_plate_stairs:6,null,10,quark:iron_plate_stairs:0,null,10,quark:iron_plate_stairs:5,null,10,quark:iron_plate_stairs:3,null,10,quark:iron_plate_slab:8,null,10,quark:iron_plate_stairs:7,null,10,quark:iron_plate_stairs:1,null,10,quark:iron_plate_slab:0,null,10,quark:iron_plate_stairs:4,null,10,quark:iron_plate_stairs:2,null,10,rustic:iron_lattice:1,null,50,rustic:iron_lattice:1,null,50,biomesoplenty:leaves_2:7,null,100)
RandomBlock(2,5,-5,quark:iron_plate:1,null,70,STAINED_CLAY:15,null,30,STAINED_CLAY:7,null,30,quark:iron_plate:1,null,100)
RandomBlock(2,5,-4,rustic:iron_lattice:1,null,30,rustic:iron_lattice:1,null,30,biomesoplenty:leaves_2:7,null,30,quark:iron_plate_stairs:6,null,10,quark:iron_plate_stairs:0,null,10,quark:iron_plate_stairs:5,null,10,quark:iron_plate_stairs:3,null,10,quark:iron_plate_slab:8,null,10,quark:iron_plate_stairs:7,null,10,quark:iron_plate_stairs:1,null,10,quark:iron_plate_slab:0,null,10,quark:iron_plate_stairs:4,null,10,quark:iron_plate_stairs:2,null,10,rustic:iron_lattice:1,null,50,rustic:iron_lattice:1,null,50,biomesoplenty:leaves_2:7,null,100)
RandomBlock(2,6,-6,rustic:iron_lattice:1,null,30,rustic:iron_lattice:1,null,30,biomesoplenty:leaves_2:7,null,30,quark:iron_plate_stairs:6,null,10,quark:iron_plate_stairs:0,null,10,quark:iron_plate_stairs:5,null,10,quark:iron_plate_stairs:3,null,10,quark:iron_plate_slab:8,null,10,quark:iron_plate_stairs:7,null,10,quark:iron_plate_stairs:1,null,10,quark:iron_plate_slab:0,null,10,quark:iron_plate_stairs:4,null,10,quark:iron_plate_stairs:2,null,10,rustic:iron_lattice:1,null,50,rustic:iron_lattice:1,null,50,biomesoplenty:leaves_2:7,null,100)
RandomBlock(2,6,-5,quark:iron_plate:1,null,70,STAINED_CLAY:15,null,30,STAINED_CLAY:7,null,30,quark:iron_plate:1,null,100)
RandomBlock(2,6,-4,rustic:iron_lattice:1,null,30,rustic:iron_lattice:1,null,30,biomesoplenty:leaves_2:7,null,30,quark:iron_plate_stairs:6,null,10,quark:iron_plate_stairs:0,null,10,quark:iron_plate_stairs:5,null,10,quark:iron_plate_stairs:3,null,10,quark:iron_plate_slab:8,null,10,quark:iron_plate_stairs:7,null,10,quark:iron_plate_stairs:1,null,10,quark:iron_plate_slab:0,null,10,quark:iron_plate_stairs:4,null,10,quark:iron_plate_stairs:2,null,10,rustic:iron_lattice:1,null,50,rustic:iron_lattice:1,null,50,biomesoplenty:leaves_2:7,null,100)
RandomBlock(2,7,-6,rustic:iron_lattice:1,null,30,rustic:iron_lattice:1,null,30,biomesoplenty:leaves_2:7,null,30,quark:iron_plate_stairs:6,null,10,quark:iron_plate_stairs:0,null,10,quark:iron_plate_stairs:5,null,10,quark:iron_plate_stairs:3,null,10,quark:iron_plate_slab:8,null,10,quark:iron_plate_stairs:7,null,10,quark:iron_plate_stairs:1,null,10,quark:iron_plate_slab:0,null,10,quark:iron_plate_stairs:4,null,10,quark:iron_plate_stairs:2,null,10,rustic:iron_lattice:1,null,50,rustic:iron_lattice:1,null,50,biomesoplenty:leaves_2:7,null,100)
RandomBlock(2,7,-5,quark:iron_plate:1,null,70,STAINED_CLAY:15,null,30,STAINED_CLAY:7,null,30,quark:iron_plate:1,null,100)
RandomBlock(2,7,-4,quark:iron_plate:1,null,70,STAINED_CLAY:15,null,30,STAINED_CLAY:7,null,30,quark:iron_plate:1,null,100)
RandomBlock(2,8,-6,rustic:iron_lattice:1,null,30,rustic:iron_lattice:1,null,30,biomesoplenty:leaves_2:7,null,30,quark:iron_plate_stairs:6,null,10,quark:iron_plate_stairs:0,null,10,quark:iron_plate_stairs:5,null,10,quark:iron_plate_stairs:3,null,10,quark:iron_plate_slab:8,null,10,quark:iron_plate_stairs:7,null,10,quark:iron_plate_stairs:1,null,10,quark:iron_plate_slab:0,null,10,quark:iron_plate_stairs:4,null,10,quark:iron_plate_stairs:2,null,10,rustic:iron_lattice:1,null,50,rustic:iron_lattice:1,null,50,biomesoplenty:leaves_2:7,null,100)
RandomBlock(2,8,-5,quark:iron_plate:1,null,70,STAINED_CLAY:15,null,30,STAINED_CLAY:7,null,30,quark:iron_plate:1,null,100)
RandomBlock(2,8,-4,quark:iron_plate:1,null,70,STAINED_CLAY:15,null,30,STAINED_CLAY:7,null,30,quark:iron_plate:1,null,100)
RandomBlock(2,9,-6,rustic:iron_lattice:1,null,30,rustic:iron_lattice:1,null,30,biomesoplenty:leaves_2:7,null,30,quark:iron_plate_stairs:6,null,10,quark:iron_plate_stairs:0,null,10,quark:iron_plate_stairs:5,null,10,quark:iron_plate_stairs:3,null,10,quark:iron_plate_slab:8,null,10,quark:iron_plate_stairs:7,null,10,quark:iron_plate_stairs:1,null,10,quark:iron_plate_slab:0,null,10,quark:iron_plate_stairs:4,null,10,quark:iron_plate_stairs:2,null,10,rustic:iron_lattice:1,null,50,rustic:iron_lattice:1,null,50,biomesoplenty:leaves_2:7,null,100)
RandomBlock(2,9,-5,quark:iron_plate:1,null,70,STAINED_CLAY:15,null,30,STAINED_CLAY:7,null,30,quark:iron_plate:1,null,100)
RandomBlock(2,9,-4,quark:iron_plate:1,null,70,STAINED_CLAY:15,null,30,STAINED_CLAY:7,null,30,quark:iron_plate:1,null,100)
RandomBlock(2,10,-6,quark:iron_plate:1,null,70,STAINED_CLAY:15,null,30,STAINED_CLAY:7,null,30,quark:iron_plate:1,null,100)
Block(2,10,-5,srparasites:deadblood:0)
RandomBlock(2,10,-4,quark:iron_plate:1,null,70,STAINED_CLAY:15,null,30,STAINED_CLAY:7,null,30,quark:iron_plate:1,null,100)
RandomBlock(2,11,-6,rustic:iron_lattice:1,null,30,rustic:iron_lattice:1,null,30,biomesoplenty:leaves_2:7,null,30,quark:iron_plate_stairs:6,null,10,quark:iron_plate_stairs:0,null,10,quark:iron_plate_stairs:5,null,10,quark:iron_plate_stairs:3,null,10,quark:iron_plate_slab:8,null,10,quark:iron_plate_stairs:7,null,10,quark:iron_plate_stairs:1,null,10,quark:iron_plate_slab:0,null,10,quark:iron_plate_stairs:4,null,10,quark:iron_plate_stairs:2,null,10,rustic:iron_lattice:1,null,50,rustic:iron_lattice:1,null,50,biomesoplenty:leaves_2:7,null,100)
RandomBlock(2,11,-5,quark:iron_plate:1,null,70,STAINED_CLAY:15,null,30,STAINED_CLAY:7,null,30,quark:iron_plate:1,null,100)
RandomBlock(2,11,-4,rustic:iron_lattice:1,null,30,rustic:iron_lattice:1,null,30,biomesoplenty:leaves_2:7,null,30,quark:iron_plate_stairs:6,null,10,quark:iron_plate_stairs:0,null,10,quark:iron_plate_stairs:5,null,10,quark:iron_plate_stairs:3,null,10,quark:iron_plate_slab:8,null,10,quark:iron_plate_stairs:7,null,10,quark:iron_plate_stairs:1,null,10,quark:iron_plate_slab:0,null,10,quark:iron_plate_stairs:4,null,10,quark:iron_plate_stairs:2,null,10,rustic:iron_lattice:1,null,50,rustic:iron_lattice:1,null,50,biomesoplenty:leaves_2:7,null,100)
RandomBlock(2,12,-6,quark:iron_plate:1,null,70,STAINED_CLAY:15,null,30,STAINED_CLAY:7,null,30,quark:iron_plate:1,null,100)
RandomBlock(2,12,-5,quark:iron_plate:1,null,70,STAINED_CLAY:15,null,30,STAINED_CLAY:7,null,30,quark:iron_plate:1,null,100)
RandomBlock(2,12,-4,rustic:iron_lattice:1,null,30,rustic:iron_lattice:1,null,30,biomesoplenty:leaves_2:7,null,30,quark:iron_plate_stairs:6,null,10,quark:iron_plate_stairs:0,null,10,quark:iron_plate_stairs:5,null,10,quark:iron_plate_stairs:3,null,10,quark:iron_plate_slab:8,null,10,quark:iron_plate_stairs:7,null,10,quark:iron_plate_stairs:1,null,10,quark:iron_plate_slab:0,null,10,quark:iron_plate_stairs:4,null,10,quark:iron_plate_stairs:2,null,10,rustic:iron_lattice:1,null,50,rustic:iron_lattice:1,null,50,biomesoplenty:leaves_2:7,null,100)
RandomBlock(2,13,-6,rustic:iron_lattice:1,null,30,rustic:iron_lattice:1,null,30,biomesoplenty:leaves_2:7,null,30,quark:iron_plate_stairs:6,null,10,quark:iron_plate_stairs:0,null,10,quark:iron_plate_stairs:5,null,10,quark:iron_plate_stairs:3,null,10,quark:iron_plate_slab:8,null,10,quark:iron_plate_stairs:7,null,10,quark:iron_plate_stairs:1,null,10,quark:iron_plate_slab:0,null,10,quark:iron_plate_stairs:4,null,10,quark:iron_plate_stairs:2,null,10,rustic:iron_lattice:1,null,50,rustic:iron_lattice:1,null,50,biomesoplenty:leaves_2:7,null,100)
RandomBlock(2,13,-5,quark:iron_plate:1,null,70,STAINED_CLAY:15,null,30,STAINED_CLAY:7,null,30,quark:iron_plate:1,null,100)
RandomBlock(2,13,-4,rustic:iron_lattice:1,null,30,rustic:iron_lattice:1,null,30,biomesoplenty:leaves_2:7,null,30,quark:iron_plate_stairs:6,null,10,quark:iron_plate_stairs:0,null,10,quark:iron_plate_stairs:5,null,10,quark:iron_plate_stairs:3,null,10,quark:iron_plate_slab:8,null,10,quark:iron_plate_stairs:7,null,10,quark:iron_plate_stairs:1,null,10,quark:iron_plate_slab:0,null,10,quark:iron_plate_stairs:4,null,10,quark:iron_plate_stairs:2,null,10,rustic:iron_lattice:1,null,50,rustic:iron_lattice:1,null,50,biomesoplenty:leaves_2:7,null,100)
RandomBlock(2,14,-6,rustic:iron_lattice:1,null,30,rustic:iron_lattice:1,null,30,biomesoplenty:leaves_2:7,null,30,quark:iron_plate_stairs:6,null,10,quark:iron_plate_stairs:0,null,10,quark:iron_plate_stairs:5,null,10,quark:iron_plate_stairs:3,null,10,quark:iron_plate_slab:8,null,10,quark:iron_plate_stairs:7,null,10,quark:iron_plate_stairs:1,null,10,quark:iron_plate_slab:0,null,10,quark:iron_plate_stairs:4,null,10,quark:iron_plate_stairs:2,null,10,rustic:iron_lattice:1,null,50,rustic:iron_lattice:1,null,50,biomesoplenty:leaves_2:7,null,100)
RandomBlock(2,14,-5,rustic:iron_lattice:1,null,30,rustic:iron_lattice:1,null,30,biomesoplenty:leaves_2:7,null,30,quark:iron_plate_stairs:6,null,10,quark:iron_plate_stairs:0,null,10,quark:iron_plate_stairs:5,null,10,quark:iron_plate_stairs:3,null,10,quark:iron_plate_slab:8,null,10,quark:iron_plate_stairs:7,null,10,quark:iron_plate_stairs:1,null,10,quark:iron_plate_slab:0,null,10,quark:iron_plate_stairs:4,null,10,quark:iron_plate_stairs:2,null,10,rustic:iron_lattice:1,null,50,rustic:iron_lattice:1,null,50,biomesoplenty:leaves_2:7,null,100)
RandomBlock(2,14,-4,quark:iron_plate:1,null,70,STAINED_CLAY:15,null,30,STAINED_CLAY:7,null,30,quark:iron_plate:1,null,100)
Block(2,15,-6,quark:iron_plate_slab:0)
Block(2,15,-5,COBBLESTONE_STAIRS:0)
Block(2,15,-4,quark:iron_plate_slab:0)
Block(2,16,-6,rustic:iron_lattice:0)
Block(2,16,-5,rustic:iron_lattice:0)
Block(2,16,-4,rustic:iron_lattice:0)
Block(3,0,-7,quark:limestone:0)
RandomBlock(3,0,-6,quark:iron_plate:1,null,70,STAINED_CLAY:15,null,30,STAINED_CLAY:7,null,30,quark:iron_plate:1,null,100)
Block(3,0,-5,srparasites:deadblood:0)
RandomBlock(3,0,-4,quark:iron_plate:1,null,70,STAINED_CLAY:15,null,30,STAINED_CLAY:7,null,30,quark:iron_plate:1,null,100)
Block(3,0,-3,quark:limestone:0)
Block(3,1,-7,COBBLESTONE_STAIRS:2)
RandomBlock(3,1,-6,quark:iron_plate:1,null,70,STAINED_CLAY:15,null,30,STAINED_CLAY:7,null,30,quark:iron_plate:1,null,100)
Block(3,1,-5,srparasites:deadblood:0)
RandomBlock(3,1,-4,quark:iron_plate:1,null,70,STAINED_CLAY:15,null,30,STAINED_CLAY:7,null,30,quark:iron_plate:1,null,100)
Block(3,1,-3,COBBLESTONE_STAIRS:3)
RandomBlock(3,2,-6,quark:iron_plate:1,null,70,STAINED_CLAY:15,null,30,STAINED_CLAY:7,null,30,quark:iron_plate:1,null,100)
Block(3,2,-5,srparasites:deadblood:0)
RandomBlock(3,2,-4,quark:iron_plate:1,null,70,STAINED_CLAY:15,null,30,STAINED_CLAY:7,null,30,quark:iron_plate:1,null,100)
RandomBlock(3,3,-6,quark:iron_plate:1,null,70,STAINED_CLAY:15,null,30,STAINED_CLAY:7,null,30,quark:iron_plate:1,null,100)
Block(3,3,-5,srparasites:deadblood:0)
RandomBlock(3,3,-4,quark:iron_plate:1,null,70,STAINED_CLAY:15,null,30,STAINED_CLAY:7,null,30,quark:iron_plate:1,null,100)
RandomBlock(3,4,-6,quark:iron_plate:1,null,70,STAINED_CLAY:15,null,30,STAINED_CLAY:7,null,30,quark:iron_plate:1,null,100)
Block(3,4,-5,srparasites:deadblood:0)
RandomBlock(3,4,-4,quark:iron_plate:1,null,70,STAINED_CLAY:15,null,30,STAINED_CLAY:7,null,30,quark:iron_plate:1,null,100)
RandomBlock(3,5,-6,quark:iron_plate:1,null,70,STAINED_CLAY:15,null,30,STAINED_CLAY:7,null,30,quark:iron_plate:1,null,100)
Block(3,5,-5,srparasites:deadblood:0)
RandomBlock(3,5,-4,quark:iron_plate:1,null,70,STAINED_CLAY:15,null,30,STAINED_CLAY:7,null,30,quark:iron_plate:1,null,100)
RandomBlock(3,6,-6,quark:iron_plate:1,null,70,STAINED_CLAY:15,null,30,STAINED_CLAY:7,null,30,quark:iron_plate:1,null,100)
Block(3,6,-5,srparasites:deadblood:0)
RandomBlock(3,6,-4,quark:iron_plate:1,null,70,STAINED_CLAY:15,null,30,STAINED_CLAY:7,null,30,quark:iron_plate:1,null,100)
RandomBlock(3,7,-6,quark:iron_plate:1,null,70,STAINED_CLAY:15,null,30,STAINED_CLAY:7,null,30,quark:iron_plate:1,null,100)
Block(3,7,-5,srparasites:deadblood:0)
RandomBlock(3,7,-4,quark:iron_plate:1,null,70,STAINED_CLAY:15,null,30,STAINED_CLAY:7,null,30,quark:iron_plate:1,null,100)
RandomBlock(3,8,-6,quark:iron_plate:1,null,70,STAINED_CLAY:15,null,30,STAINED_CLAY:7,null,30,quark:iron_plate:1,null,100)
Block(3,8,-5,srparasites:deadblood:0)
RandomBlock(3,8,-4,quark:iron_plate:1,null,70,STAINED_CLAY:15,null,30,STAINED_CLAY:7,null,30,quark:iron_plate:1,null,100)
RandomBlock(3,9,-6,quark:iron_plate:1,null,70,STAINED_CLAY:15,null,30,STAINED_CLAY:7,null,30,quark:iron_plate:1,null,100)
Block(3,9,-5,srparasites:deadblood:0)
RandomBlock(3,9,-4,quark:iron_plate:1,null,70,STAINED_CLAY:15,null,30,STAINED_CLAY:7,null,30,quark:iron_plate:1,null,100)
RandomBlock(3,10,-6,quark:iron_plate:1,null,70,STAINED_CLAY:15,null,30,STAINED_CLAY:7,null,30,quark:iron_plate:1,null,100)
Block(3,10,-5,srparasites:deadblood:0)
RandomBlock(3,10,-4,quark:iron_plate:1,null,70,STAINED_CLAY:15,null,30,STAINED_CLAY:7,null,30,quark:iron_plate:1,null,100)
RandomBlock(3,11,-6,rustic:iron_lattice:1,null,30,rustic:iron_lattice:1,null,30,biomesoplenty:leaves_2:7,null,30,quark:iron_plate_stairs:6,null,10,quark:iron_plate_stairs:0,null,10,quark:iron_plate_stairs:5,null,10,quark:iron_plate_stairs:3,null,10,quark:iron_plate_slab:8,null,10,quark:iron_plate_stairs:7,null,10,quark:iron_plate_stairs:1,null,10,quark:iron_plate_slab:0,null,10,quark:iron_plate_stairs:4,null,10,quark:iron_plate_stairs:2,null,10,rustic:iron_lattice:1,null,50,rustic:iron_lattice:1,null,50,biomesoplenty:leaves_2:7,null,100)
RandomBlock(3,11,-5,quark:iron_plate:1,null,70,STAINED_CLAY:15,null,30,STAINED_CLAY:7,null,30,quark:iron_plate:1,null,100)
RandomBlock(3,11,-4,rustic:iron_lattice:1,null,30,rustic:iron_lattice:1,null,30,biomesoplenty:leaves_2:7,null,30,quark:iron_plate_stairs:6,null,10,quark:iron_plate_stairs:0,null,10,quark:iron_plate_stairs:5,null,10,quark:iron_plate_stairs:3,null,10,quark:iron_plate_slab:8,null,10,quark:iron_plate_stairs:7,null,10,quark:iron_plate_stairs:1,null,10,quark:iron_plate_slab:0,null,10,quark:iron_plate_stairs:4,null,10,quark:iron_plate_stairs:2,null,10,rustic:iron_lattice:1,null,50,rustic:iron_lattice:1,null,50,biomesoplenty:leaves_2:7,null,100)
RandomBlock(3,12,-6,quark:iron_plate:1,null,70,STAINED_CLAY:15,null,30,STAINED_CLAY:7,null,30,quark:iron_plate:1,null,100)
Block(3,12,-5,quark:basalt_wall:0)
RandomBlock(3,12,-4,quark:iron_plate:1,null,70,STAINED_CLAY:15,null,30,STAINED_CLAY:7,null,30,quark:iron_plate:1,null,100)
RandomBlock(3,13,-6,quark:iron_plate:1,null,70,STAINED_CLAY:15,null,30,STAINED_CLAY:7,null,30,quark:iron_plate:1,null,100)
Block(3,13,-5,quark:basalt_wall:0)
RandomBlock(3,13,-4,quark:iron_plate:1,null,70,STAINED_CLAY:15,null,30,STAINED_CLAY:7,null,30,quark:iron_plate:1,null,100)
RandomBlock(3,14,-6,quark:iron_plate:1,null,70,STAINED_CLAY:15,null,30,STAINED_CLAY:7,null,30,quark:iron_plate:1,null,100)
Block(3,14,-5,quark:basalt_wall:0)
RandomBlock(3,14,-4,quark:iron_plate:1,null,70,STAINED_CLAY:15,null,30,STAINED_CLAY:7,null,30,quark:iron_plate:1,null,100)
Block(3,15,-6,COBBLESTONE_STAIRS:2)
Block(3,15,-5,quark:basalt_wall:0)
Block(3,15,-4,COBBLESTONE_STAIRS:3)
Block(3,16,-6,rustic:iron_lattice:0)
Block(3,16,-5,rustic:iron_lattice:0)
Block(3,16,-4,rustic:iron_lattice:0)
Block(4,0,-7,quark:limestone:0)
RandomBlock(4,0,-6,quark:iron_plate:1,null,70,STAINED_CLAY:15,null,30,STAINED_CLAY:7,null,30,quark:iron_plate:1,null,100)
RandomBlock(4,0,-5,quark:iron_plate:1,null,70,STAINED_CLAY:15,null,30,STAINED_CLAY:7,null,30,quark:iron_plate:1,null,100)
RandomBlock(4,0,-4,quark:iron_plate:1,null,70,STAINED_CLAY:15,null,30,STAINED_CLAY:7,null,30,quark:iron_plate:1,null,100)
Block(4,0,-3,quark:limestone:0)
Block(4,1,-7,COBBLESTONE_STAIRS:2)
RandomBlock(4,1,-6,quark:iron_plate:1,null,70,STAINED_CLAY:15,null,30,STAINED_CLAY:7,null,30,quark:iron_plate:1,null,100)
RandomBlock(4,1,-5,quark:iron_plate:1,null,70,STAINED_CLAY:15,null,30,STAINED_CLAY:7,null,30,quark:iron_plate:1,null,100)
RandomBlock(4,1,-4,quark:iron_plate:1,null,70,STAINED_CLAY:15,null,30,STAINED_CLAY:7,null,30,quark:iron_plate:1,null,100)
Block(4,1,-3,COBBLESTONE_STAIRS:3)
RandomBlock(4,2,-6,rustic:iron_lattice:1,null,30,rustic:iron_lattice:1,null,30,biomesoplenty:leaves_2:7,null,30,quark:iron_plate_stairs:6,null,10,quark:iron_plate_stairs:0,null,10,quark:iron_plate_stairs:5,null,10,quark:iron_plate_stairs:3,null,10,quark:iron_plate_slab:8,null,10,quark:iron_plate_stairs:7,null,10,quark:iron_plate_stairs:1,null,10,quark:iron_plate_slab:0,null,10,quark:iron_plate_stairs:4,null,10,quark:iron_plate_stairs:2,null,10,rustic:iron_lattice:1,null,50,rustic:iron_lattice:1,null,50,biomesoplenty:leaves_2:7,null,100)
RandomBlock(4,2,-5,quark:iron_plate:1,null,70,STAINED_CLAY:15,null,30,STAINED_CLAY:7,null,30,quark:iron_plate:1,null,100)
RandomBlock(4,2,-4,quark:iron_plate:1,null,70,STAINED_CLAY:15,null,30,STAINED_CLAY:7,null,30,quark:iron_plate:1,null,100)
RandomBlock(4,3,-6,rustic:iron_lattice:1,null,30,rustic:iron_lattice:1,null,30,biomesoplenty:leaves_2:7,null,30,quark:iron_plate_stairs:6,null,10,quark:iron_plate_stairs:0,null,10,quark:iron_plate_stairs:5,null,10,quark:iron_plate_stairs:3,null,10,quark:iron_plate_slab:8,null,10,quark:iron_plate_stairs:7,null,10,quark:iron_plate_stairs:1,null,10,quark:iron_plate_slab:0,null,10,quark:iron_plate_stairs:4,null,10,quark:iron_plate_stairs:2,null,10,rustic:iron_lattice:1,null,50,rustic:iron_lattice:1,null,50,biomesoplenty:leaves_2:7,null,100)
RandomBlock(4,3,-5,quark:iron_plate:1,null,70,STAINED_CLAY:15,null,30,STAINED_CLAY:7,null,30,quark:iron_plate:1,null,100)
RandomBlock(4,3,-4,rustic:iron_lattice:1,null,30,rustic:iron_lattice:1,null,30,biomesoplenty:leaves_2:7,null,30,quark:iron_plate_stairs:6,null,10,quark:iron_plate_stairs:0,null,10,quark:iron_plate_stairs:5,null,10,quark:iron_plate_stairs:3,null,10,quark:iron_plate_slab:8,null,10,quark:iron_plate_stairs:7,null,10,quark:iron_plate_stairs:1,null,10,quark:iron_plate_slab:0,null,10,quark:iron_plate_stairs:4,null,10,quark:iron_plate_stairs:2,null,10,rustic:iron_lattice:1,null,50,rustic:iron_lattice:1,null,50,biomesoplenty:leaves_2:7,null,100)
RandomBlock(4,4,-6,rustic:iron_lattice:1,null,30,rustic:iron_lattice:1,null,30,biomesoplenty:leaves_2:7,null,30,quark:iron_plate_stairs:6,null,10,quark:iron_plate_stairs:0,null,10,quark:iron_plate_stairs:5,null,10,quark:iron_plate_stairs:3,null,10,quark:iron_plate_slab:8,null,10,quark:iron_plate_stairs:7,null,10,quark:iron_plate_stairs:1,null,10,quark:iron_plate_slab:0,null,10,quark:iron_plate_stairs:4,null,10,quark:iron_plate_stairs:2,null,10,rustic:iron_lattice:1,null,50,rustic:iron_lattice:1,null,50,biomesoplenty:leaves_2:7,null,100)
RandomBlock(4,4,-5,quark:iron_plate:1,null,70,STAINED_CLAY:15,null,30,STAINED_CLAY:7,null,30,quark:iron_plate:1,null,100)
RandomBlock(4,4,-4,rustic:iron_lattice:1,null,30,rustic:iron_lattice:1,null,30,biomesoplenty:leaves_2:7,null,30,quark:iron_plate_stairs:6,null,10,quark:iron_plate_stairs:0,null,10,quark:iron_plate_stairs:5,null,10,quark:iron_plate_stairs:3,null,10,quark:iron_plate_slab:8,null,10,quark:iron_plate_stairs:7,null,10,quark:iron_plate_stairs:1,null,10,quark:iron_plate_slab:0,null,10,quark:iron_plate_stairs:4,null,10,quark:iron_plate_stairs:2,null,10,rustic:iron_lattice:1,null,50,rustic:iron_lattice:1,null,50,biomesoplenty:leaves_2:7,null,100)
RandomBlock(4,5,-6,rustic:iron_lattice:1,null,30,rustic:iron_lattice:1,null,30,biomesoplenty:leaves_2:7,null,30,quark:iron_plate_stairs:6,null,10,quark:iron_plate_stairs:0,null,10,quark:iron_plate_stairs:5,null,10,quark:iron_plate_stairs:3,null,10,quark:iron_plate_slab:8,null,10,quark:iron_plate_stairs:7,null,10,quark:iron_plate_stairs:1,null,10,quark:iron_plate_slab:0,null,10,quark:iron_plate_stairs:4,null,10,quark:iron_plate_stairs:2,null,10,rustic:iron_lattice:1,null,50,rustic:iron_lattice:1,null,50,biomesoplenty:leaves_2:7,null,100)
RandomBlock(4,5,-5,quark:iron_plate:1,null,70,STAINED_CLAY:15,null,30,STAINED_CLAY:7,null,30,quark:iron_plate:1,null,100)
RandomBlock(4,5,-4,rustic:iron_lattice:1,null,30,rustic:iron_lattice:1,null,30,biomesoplenty:leaves_2:7,null,30,quark:iron_plate_stairs:6,null,10,quark:iron_plate_stairs:0,null,10,quark:iron_plate_stairs:5,null,10,quark:iron_plate_stairs:3,null,10,quark:iron_plate_slab:8,null,10,quark:iron_plate_stairs:7,null,10,quark:iron_plate_stairs:1,null,10,quark:iron_plate_slab:0,null,10,quark:iron_plate_stairs:4,null,10,quark:iron_plate_stairs:2,null,10,rustic:iron_lattice:1,null,50,rustic:iron_lattice:1,null,50,biomesoplenty:leaves_2:7,null,100)
RandomBlock(4,6,-6,rustic:iron_lattice:1,null,30,rustic:iron_lattice:1,null,30,biomesoplenty:leaves_2:7,null,30,quark:iron_plate_stairs:6,null,10,quark:iron_plate_stairs:0,null,10,quark:iron_plate_stairs:5,null,10,quark:iron_plate_stairs:3,null,10,quark:iron_plate_slab:8,null,10,quark:iron_plate_stairs:7,null,10,quark:iron_plate_stairs:1,null,10,quark:iron_plate_slab:0,null,10,quark:iron_plate_stairs:4,null,10,quark:iron_plate_stairs:2,null,10,rustic:iron_lattice:1,null,50,rustic:iron_lattice:1,null,50,biomesoplenty:leaves_2:7,null,100)
RandomBlock(4,6,-5,quark:iron_plate:1,null,70,STAINED_CLAY:15,null,30,STAINED_CLAY:7,null,30,quark:iron_plate:1,null,100)
RandomBlock(4,6,-4,rustic:iron_lattice:1,null,30,rustic:iron_lattice:1,null,30,biomesoplenty:leaves_2:7,null,30,quark:iron_plate_stairs:6,null,10,quark:iron_plate_stairs:0,null,10,quark:iron_plate_stairs:5,null,10,quark:iron_plate_stairs:3,null,10,quark:iron_plate_slab:8,null,10,quark:iron_plate_stairs:7,null,10,quark:iron_plate_stairs:1,null,10,quark:iron_plate_slab:0,null,10,quark:iron_plate_stairs:4,null,10,quark:iron_plate_stairs:2,null,10,rustic:iron_lattice:1,null,50,rustic:iron_lattice:1,null,50,biomesoplenty:leaves_2:7,null,100)
RandomBlock(4,7,-6,quark:iron_plate:1,null,70,STAINED_CLAY:15,null,30,STAINED_CLAY:7,null,30,quark:iron_plate:1,null,100)
RandomBlock(4,7,-5,quark:iron_plate:1,null,70,STAINED_CLAY:15,null,30,STAINED_CLAY:7,null,30,quark:iron_plate:1,null,100)
RandomBlock(4,7,-4,rustic:iron_lattice:1,null,30,rustic:iron_lattice:1,null,30,biomesoplenty:leaves_2:7,null,30,quark:iron_plate_stairs:6,null,10,quark:iron_plate_stairs:0,null,10,quark:iron_plate_stairs:5,null,10,quark:iron_plate_stairs:3,null,10,quark:iron_plate_slab:8,null,10,quark:iron_plate_stairs:7,null,10,quark:iron_plate_stairs:1,null,10,quark:iron_plate_slab:0,null,10,quark:iron_plate_stairs:4,null,10,quark:iron_plate_stairs:2,null,10,rustic:iron_lattice:1,null,50,rustic:iron_lattice:1,null,50,biomesoplenty:leaves_2:7,null,100)
RandomBlock(4,8,-6,quark:iron_plate:1,null,70,STAINED_CLAY:15,null,30,STAINED_CLAY:7,null,30,quark:iron_plate:1,null,100)
RandomBlock(4,8,-5,quark:iron_plate:1,null,70,STAINED_CLAY:15,null,30,STAINED_CLAY:7,null,30,quark:iron_plate:1,null,100)
RandomBlock(4,8,-4,quark:iron_plate:1,null,70,STAINED_CLAY:15,null,30,STAINED_CLAY:7,null,30,quark:iron_plate:1,null,100)
RandomBlock(4,9,-6,rustic:iron_lattice:1,null,30,rustic:iron_lattice:1,null,30,biomesoplenty:leaves_2:7,null,30,quark:iron_plate_stairs:6,null,10,quark:iron_plate_stairs:0,null,10,quark:iron_plate_stairs:5,null,10,quark:iron_plate_stairs:3,null,10,quark:iron_plate_slab:8,null,10,quark:iron_plate_stairs:7,null,10,quark:iron_plate_stairs:1,null,10,quark:iron_plate_slab:0,null,10,quark:iron_plate_stairs:4,null,10,quark:iron_plate_stairs:2,null,10,rustic:iron_lattice:1,null,50,rustic:iron_lattice:1,null,50,biomesoplenty:leaves_2:7,null,100)
RandomBlock(4,9,-5,quark:iron_plate:1,null,70,STAINED_CLAY:15,null,30,STAINED_CLAY:7,null,30,quark:iron_plate:1,null,100)
RandomBlock(4,9,-4,quark:iron_plate:1,null,70,STAINED_CLAY:15,null,30,STAINED_CLAY:7,null,30,quark:iron_plate:1,null,100)
RandomBlock(4,10,-6,rustic:iron_lattice:1,null,30,rustic:iron_lattice:1,null,30,biomesoplenty:leaves_2:7,null,30,quark:iron_plate_stairs:6,null,10,quark:iron_plate_stairs:0,null,10,quark:iron_plate_stairs:5,null,10,quark:iron_plate_stairs:3,null,10,quark:iron_plate_slab:8,null,10,quark:iron_plate_stairs:7,null,10,quark:iron_plate_stairs:1,null,10,quark:iron_plate_slab:0,null,10,quark:iron_plate_stairs:4,null,10,quark:iron_plate_stairs:2,null,10,rustic:iron_lattice:1,null,50,rustic:iron_lattice:1,null,50,biomesoplenty:leaves_2:7,null,100)
RandomBlock(4,10,-5,quark:iron_plate:1,null,70,STAINED_CLAY:15,null,30,STAINED_CLAY:7,null,30,quark:iron_plate:1,null,100)
RandomBlock(4,10,-4,rustic:iron_lattice:1,null,30,rustic:iron_lattice:1,null,30,biomesoplenty:leaves_2:7,null,30,quark:iron_plate_stairs:6,null,10,quark:iron_plate_stairs:0,null,10,quark:iron_plate_stairs:5,null,10,quark:iron_plate_stairs:3,null,10,quark:iron_plate_slab:8,null,10,quark:iron_plate_stairs:7,null,10,quark:iron_plate_stairs:1,null,10,quark:iron_plate_slab:0,null,10,quark:iron_plate_stairs:4,null,10,quark:iron_plate_stairs:2,null,10,rustic:iron_lattice:1,null,50,rustic:iron_lattice:1,null,50,biomesoplenty:leaves_2:7,null,100)
RandomBlock(4,11,-6,rustic:iron_lattice:1,null,30,rustic:iron_lattice:1,null,30,biomesoplenty:leaves_2:7,null,30,quark:iron_plate_stairs:6,null,10,quark:iron_plate_stairs:0,null,10,quark:iron_plate_stairs:5,null,10,quark:iron_plate_stairs:3,null,10,quark:iron_plate_slab:8,null,10,quark:iron_plate_stairs:7,null,10,quark:iron_plate_stairs:1,null,10,quark:iron_plate_slab:0,null,10,quark:iron_plate_stairs:4,null,10,quark:iron_plate_stairs:2,null,10,rustic:iron_lattice:1,null,50,rustic:iron_lattice:1,null,50,biomesoplenty:leaves_2:7,null,100)
RandomBlock(4,11,-5,quark:iron_plate:1,null,70,STAINED_CLAY:15,null,30,STAINED_CLAY:7,null,30,quark:iron_plate:1,null,100)
RandomBlock(4,11,-4,rustic:iron_lattice:1,null,30,rustic:iron_lattice:1,null,30,biomesoplenty:leaves_2:7,null,30,quark:iron_plate_stairs:6,null,10,quark:iron_plate_stairs:0,null,10,quark:iron_plate_stairs:5,null,10,quark:iron_plate_stairs:3,null,10,quark:iron_plate_slab:8,null,10,quark:iron_plate_stairs:7,null,10,quark:iron_plate_stairs:1,null,10,quark:iron_plate_slab:0,null,10,quark:iron_plate_stairs:4,null,10,quark:iron_plate_stairs:2,null,10,rustic:iron_lattice:1,null,50,rustic:iron_lattice:1,null,50,biomesoplenty:leaves_2:7,null,100)
RandomBlock(4,12,-6,quark:iron_plate:1,null,70,STAINED_CLAY:15,null,30,STAINED_CLAY:7,null,30,quark:iron_plate:1,null,100)
RandomBlock(4,12,-5,rustic:iron_lattice:1,null,30,rustic:iron_lattice:1,null,30,biomesoplenty:leaves_2:7,null,30,quark:iron_plate_stairs:6,null,10,quark:iron_plate_stairs:0,null,10,quark:iron_plate_stairs:5,null,10,quark:iron_plate_stairs:3,null,10,quark:iron_plate_slab:8,null,10,quark:iron_plate_stairs:7,null,10,quark:iron_plate_stairs:1,null,10,quark:iron_plate_slab:0,null,10,quark:iron_plate_stairs:4,null,10,quark:iron_plate_stairs:2,null,10,rustic:iron_lattice:1,null,50,rustic:iron_lattice:1,null,50,biomesoplenty:leaves_2:7,null,100)
RandomBlock(4,12,-4,rustic:iron_lattice:1,null,30,rustic:iron_lattice:1,null,30,biomesoplenty:leaves_2:7,null,30,quark:iron_plate_stairs:6,null,10,quark:iron_plate_stairs:0,null,10,quark:iron_plate_stairs:5,null,10,quark:iron_plate_stairs:3,null,10,quark:iron_plate_slab:8,null,10,quark:iron_plate_stairs:7,null,10,quark:iron_plate_stairs:1,null,10,quark:iron_plate_slab:0,null,10,quark:iron_plate_stairs:4,null,10,quark:iron_plate_stairs:2,null,10,rustic:iron_lattice:1,null,50,rustic:iron_lattice:1,null,50,biomesoplenty:leaves_2:7,null,100)
RandomBlock(4,13,-6,quark:iron_plate:1,null,70,STAINED_CLAY:15,null,30,STAINED_CLAY:7,null,30,quark:iron_plate:1,null,100)
RandomBlock(4,13,-5,quark:iron_plate:1,null,70,STAINED_CLAY:15,null,30,STAINED_CLAY:7,null,30,quark:iron_plate:1,null,100)
RandomBlock(4,13,-4,rustic:iron_lattice:1,null,30,rustic:iron_lattice:1,null,30,biomesoplenty:leaves_2:7,null,30,quark:iron_plate_stairs:6,null,10,quark:iron_plate_stairs:0,null,10,quark:iron_plate_stairs:5,null,10,quark:iron_plate_stairs:3,null,10,quark:iron_plate_slab:8,null,10,quark:iron_plate_stairs:7,null,10,quark:iron_plate_stairs:1,null,10,quark:iron_plate_slab:0,null,10,quark:iron_plate_stairs:4,null,10,quark:iron_plate_stairs:2,null,10,rustic:iron_lattice:1,null,50,rustic:iron_lattice:1,null,50,biomesoplenty:leaves_2:7,null,100)
RandomBlock(4,14,-6,rustic:iron_lattice:1,null,30,rustic:iron_lattice:1,null,30,biomesoplenty:leaves_2:7,null,30,quark:iron_plate_stairs:6,null,10,quark:iron_plate_stairs:0,null,10,quark:iron_plate_stairs:5,null,10,quark:iron_plate_stairs:3,null,10,quark:iron_plate_slab:8,null,10,quark:iron_plate_stairs:7,null,10,quark:iron_plate_stairs:1,null,10,quark:iron_plate_slab:0,null,10,quark:iron_plate_stairs:4,null,10,quark:iron_plate_stairs:2,null,10,rustic:iron_lattice:1,null,50,rustic:iron_lattice:1,null,50,biomesoplenty:leaves_2:7,null,100)
RandomBlock(4,14,-5,quark:iron_plate:1,null,70,STAINED_CLAY:15,null,30,STAINED_CLAY:7,null,30,quark:iron_plate:1,null,100)
RandomBlock(4,14,-4,rustic:iron_lattice:1,null,30,rustic:iron_lattice:1,null,30,biomesoplenty:leaves_2:7,null,30,quark:iron_plate_stairs:6,null,10,quark:iron_plate_stairs:0,null,10,quark:iron_plate_stairs:5,null,10,quark:iron_plate_stairs:3,null,10,quark:iron_plate_slab:8,null,10,quark:iron_plate_stairs:7,null,10,quark:iron_plate_stairs:1,null,10,quark:iron_plate_slab:0,null,10,quark:iron_plate_stairs:4,null,10,quark:iron_plate_stairs:2,null,10,rustic:iron_lattice:1,null,50,rustic:iron_lattice:1,null,50,biomesoplenty:leaves_2:7,null,100)
Block(4,15,-6,quark:iron_plate_slab:0)
Block(4,15,-5,COBBLESTONE_STAIRS:1)
Block(4,15,-4,quark:iron_plate_slab:0)
Block(4,16,-6,rustic:iron_lattice:0)
Block(4,16,-5,rustic:iron_lattice:0)
Block(4,16,-4,rustic:iron_lattice:0)
Block(5,0,-7,quark:limestone:0)
Block(5,0,-6,quark:limestone:0)
Block(5,0,-5,quark:limestone:0)
Block(5,0,-4,quark:limestone:0)
Block(5,0,-3,quark:limestone:0)
Block(5,1,-7,COBBLESTONE_STAIRS:2)
Block(5,1,-6,COBBLESTONE_STAIRS:1)
Block(5,1,-5,COBBLESTONE_STAIRS:1)
Block(5,1,-4,COBBLESTONE_STAIRS:1)
Block(5,1,-3,COBBLESTONE_STAIRS:3)

#######################################################################
# +-----------------------------------------------------------------+ #
# |                             Branches                            | #
# +-----------------------------------------------------------------+ #
#######################################################################


#######################################################################
# +-----------------------------------------------------------------+ #
# |                             Entities                            | #
# +-----------------------------------------------------------------+ #
#######################################################################


#######################################################################
# +-----------------------------------------------------------------+ #
# |                            Particles                            | #
# +-----------------------------------------------------------------+ #
#######################################################################


#######################################################################
# +-----------------------------------------------------------------+ #
# |                             Spawners                            | #
# +-----------------------------------------------------------------+ #
#######################################################################


#######################################################################
# +-----------------------------------------------------------------+ #
# |                             ModData                             | #
# +-----------------------------------------------------------------+ #
#######################################################################

