
#######################################################################
# +-----------------------------------------------------------------+ #
# |                            BO4 object                           | #
# +-----------------------------------------------------------------+ #
#######################################################################

Author: NLBlackEagle

Description: No description given

SettingsMode: WriteWithoutComments


#######################################################################
# +-----------------------------------------------------------------+ #
# |                          Main settings                          | #
# +-----------------------------------------------------------------+ #
#######################################################################

FixedRotation: 

Frequency: 0

SpawnHeight: highestBlock

UseCenterForHighestBlock: true

##############################
# Height Limits for the BO4. #
##############################

MinHeight: 0

MaxHeight: 255

InheritBO3: 

InheritBO3Rotation: NORTH

OverrideChildSettings: true

OverrideParentHeight: false

CanOverride: true

BranchFrequency: 0

BranchFrequencyGroup: 

MustBeBelowOther: false

MustBeInside: 

CannotBeInside: 

ReplacesBO3: 

MustBeInsideWorldBorders: false

CanSpawnOnWater: true

SpawnOnWaterOnly: false

SpawnUnderWater: false

SpawnAtWaterLevel: false

HeightOffset: 0

RemoveAir: true

ReplaceAbove: 

ReplaceBelow: 

ReplaceWithBiomeBlocks: false

ReplaceWithSurfaceBlock: GRASS

ReplaceWithGroundBlock: DIRT

ReplaceWithStoneBlock: STONE

SmoothRadius: 0

SmoothHeightOffset: 0

SmoothStartTop: false

SmoothStartWood: false

SmoothingSurfaceBlock: 

SmoothingGroundBlock: 

BO3Group: 

IsSpawnPoint: false

DoReplaceBlocks: true


#######################################################################
# +-----------------------------------------------------------------+ #
# |                              Blocks                             | #
# +-----------------------------------------------------------------+ #
#######################################################################

RandomBlock(-8,0,-7,contenttweaker:reinforced_concrete:0,null,40,SMOOTH_BRICK:1,null,30,SMOOTH_BRICK:2,null,30,SMOOTH_STAIRS:0,null,15,SMOOTH_STAIRS:1,null,15,SMOOTH_STAIRS:2,null,15,SMOOTH_STAIRS:3,null,15,STEP:5,null,15,STEP:13,null,15,COBBLE_WALL:0,null,10,COBBLESTONE_STAIRS:0,null,10,STEP:3,null,10,COBBLE_WALL:1,null,20,COBBLESTONE_STAIRS:2,null,20,COBBLESTONE_STAIRS:3,null,20,MOSSY_COBBLESTONE:0,null,60,COBBLESTONE_STAIRS:1,null,20,STEP:11,null,20,COBBLESTONE:0,null,100)
RandomBlock(-8,0,-6,contenttweaker:reinforced_concrete:0,null,40,SMOOTH_BRICK:1,null,30,SMOOTH_BRICK:2,null,30,SMOOTH_STAIRS:0,null,15,SMOOTH_STAIRS:1,null,15,SMOOTH_STAIRS:2,null,15,SMOOTH_STAIRS:3,null,15,STEP:5,null,15,STEP:13,null,15,COBBLE_WALL:0,null,10,COBBLESTONE_STAIRS:0,null,10,STEP:3,null,10,COBBLE_WALL:1,null,20,COBBLESTONE_STAIRS:2,null,20,COBBLESTONE_STAIRS:3,null,20,MOSSY_COBBLESTONE:0,null,60,COBBLESTONE_STAIRS:1,null,20,STEP:11,null,20,COBBLESTONE:0,null,100)
RandomBlock(-8,0,-5,contenttweaker:reinforced_concrete:0,null,40,SMOOTH_BRICK:1,null,30,SMOOTH_BRICK:2,null,30,SMOOTH_STAIRS:0,null,15,SMOOTH_STAIRS:1,null,15,SMOOTH_STAIRS:2,null,15,SMOOTH_STAIRS:3,null,15,STEP:5,null,15,STEP:13,null,15,COBBLE_WALL:0,null,10,COBBLESTONE_STAIRS:0,null,10,STEP:3,null,10,COBBLE_WALL:1,null,20,COBBLESTONE_STAIRS:2,null,20,COBBLESTONE_STAIRS:3,null,20,MOSSY_COBBLESTONE:0,null,60,COBBLESTONE_STAIRS:1,null,20,STEP:11,null,20,COBBLESTONE:0,null,100)
RandomBlock(-8,0,-4,contenttweaker:reinforced_concrete:0,null,40,SMOOTH_BRICK:1,null,30,SMOOTH_BRICK:2,null,30,SMOOTH_STAIRS:0,null,15,SMOOTH_STAIRS:1,null,15,SMOOTH_STAIRS:2,null,15,SMOOTH_STAIRS:3,null,15,STEP:5,null,15,STEP:13,null,15,COBBLE_WALL:0,null,10,COBBLESTONE_STAIRS:0,null,10,STEP:3,null,10,COBBLE_WALL:1,null,20,COBBLESTONE_STAIRS:2,null,20,COBBLESTONE_STAIRS:3,null,20,MOSSY_COBBLESTONE:0,null,60,COBBLESTONE_STAIRS:1,null,20,STEP:11,null,20,COBBLESTONE:0,null,100)
RandomBlock(-8,0,-3,contenttweaker:reinforced_concrete:0,null,40,SMOOTH_BRICK:1,null,30,SMOOTH_BRICK:2,null,30,SMOOTH_STAIRS:0,null,15,SMOOTH_STAIRS:1,null,15,SMOOTH_STAIRS:2,null,15,SMOOTH_STAIRS:3,null,15,STEP:5,null,15,STEP:13,null,15,COBBLE_WALL:0,null,10,COBBLESTONE_STAIRS:0,null,10,STEP:3,null,10,COBBLE_WALL:1,null,20,COBBLESTONE_STAIRS:2,null,20,COBBLESTONE_STAIRS:3,null,20,MOSSY_COBBLESTONE:0,null,60,COBBLESTONE_STAIRS:1,null,20,STEP:11,null,20,COBBLESTONE:0,null,100)
RandomBlock(-8,0,-2,contenttweaker:reinforced_concrete:0,null,40,SMOOTH_BRICK:1,null,30,SMOOTH_BRICK:2,null,30,SMOOTH_STAIRS:0,null,15,SMOOTH_STAIRS:1,null,15,SMOOTH_STAIRS:2,null,15,SMOOTH_STAIRS:3,null,15,STEP:5,null,15,STEP:13,null,15,COBBLE_WALL:0,null,10,COBBLESTONE_STAIRS:0,null,10,STEP:3,null,10,COBBLE_WALL:1,null,20,COBBLESTONE_STAIRS:2,null,20,COBBLESTONE_STAIRS:3,null,20,MOSSY_COBBLESTONE:0,null,60,COBBLESTONE_STAIRS:1,null,20,STEP:11,null,20,COBBLESTONE:0,null,100)
RandomBlock(-8,1,-7,contenttweaker:reinforced_concrete:0,null,40,SMOOTH_BRICK:1,null,30,SMOOTH_BRICK:2,null,30,SMOOTH_STAIRS:0,null,15,SMOOTH_STAIRS:1,null,15,SMOOTH_STAIRS:2,null,15,SMOOTH_STAIRS:3,null,15,STEP:5,null,15,STEP:13,null,15,COBBLE_WALL:0,null,10,COBBLESTONE_STAIRS:0,null,10,STEP:3,null,10,COBBLE_WALL:1,null,20,COBBLESTONE_STAIRS:2,null,20,COBBLESTONE_STAIRS:3,null,20,MOSSY_COBBLESTONE:0,null,60,COBBLESTONE_STAIRS:1,null,20,STEP:11,null,20,COBBLESTONE:0,null,100)
RandomBlock(-8,1,-6,contenttweaker:reinforced_concrete:0,null,40,SMOOTH_BRICK:1,null,30,SMOOTH_BRICK:2,null,30,SMOOTH_STAIRS:0,null,15,SMOOTH_STAIRS:1,null,15,SMOOTH_STAIRS:2,null,15,SMOOTH_STAIRS:3,null,15,STEP:5,null,15,STEP:13,null,15,COBBLE_WALL:0,null,10,COBBLESTONE_STAIRS:0,null,10,STEP:3,null,10,COBBLE_WALL:1,null,20,COBBLESTONE_STAIRS:2,null,20,COBBLESTONE_STAIRS:3,null,20,MOSSY_COBBLESTONE:0,null,60,COBBLESTONE_STAIRS:1,null,20,STEP:11,null,20,COBBLESTONE:0,null,100)
RandomBlock(-8,1,-5,contenttweaker:reinforced_concrete:0,null,40,SMOOTH_BRICK:1,null,30,SMOOTH_BRICK:2,null,30,SMOOTH_STAIRS:0,null,15,SMOOTH_STAIRS:1,null,15,SMOOTH_STAIRS:2,null,15,SMOOTH_STAIRS:3,null,15,STEP:5,null,15,STEP:13,null,15,COBBLE_WALL:0,null,10,COBBLESTONE_STAIRS:0,null,10,STEP:3,null,10,COBBLE_WALL:1,null,20,COBBLESTONE_STAIRS:2,null,20,COBBLESTONE_STAIRS:3,null,20,MOSSY_COBBLESTONE:0,null,60,COBBLESTONE_STAIRS:1,null,20,STEP:11,null,20,COBBLESTONE:0,null,100)
RandomBlock(-8,1,-4,contenttweaker:reinforced_concrete:0,null,40,SMOOTH_BRICK:1,null,30,SMOOTH_BRICK:2,null,30,SMOOTH_STAIRS:0,null,15,SMOOTH_STAIRS:1,null,15,SMOOTH_STAIRS:2,null,15,SMOOTH_STAIRS:3,null,15,STEP:5,null,15,STEP:13,null,15,COBBLE_WALL:0,null,10,COBBLESTONE_STAIRS:0,null,10,STEP:3,null,10,COBBLE_WALL:1,null,20,COBBLESTONE_STAIRS:2,null,20,COBBLESTONE_STAIRS:3,null,20,MOSSY_COBBLESTONE:0,null,60,COBBLESTONE_STAIRS:1,null,20,STEP:11,null,20,COBBLESTONE:0,null,100)
RandomBlock(-8,1,-3,contenttweaker:reinforced_concrete:0,null,40,SMOOTH_BRICK:1,null,30,SMOOTH_BRICK:2,null,30,SMOOTH_STAIRS:0,null,15,SMOOTH_STAIRS:1,null,15,SMOOTH_STAIRS:2,null,15,SMOOTH_STAIRS:3,null,15,STEP:5,null,15,STEP:13,null,15,COBBLE_WALL:0,null,10,COBBLESTONE_STAIRS:0,null,10,STEP:3,null,10,COBBLE_WALL:1,null,20,COBBLESTONE_STAIRS:2,null,20,COBBLESTONE_STAIRS:3,null,20,MOSSY_COBBLESTONE:0,null,60,COBBLESTONE_STAIRS:1,null,20,STEP:11,null,20,COBBLESTONE:0,null,100)
RandomBlock(-8,1,-2,contenttweaker:reinforced_concrete:0,null,40,SMOOTH_BRICK:1,null,30,SMOOTH_BRICK:2,null,30,SMOOTH_STAIRS:0,null,15,SMOOTH_STAIRS:1,null,15,SMOOTH_STAIRS:2,null,15,SMOOTH_STAIRS:3,null,15,STEP:5,null,15,STEP:13,null,15,COBBLE_WALL:0,null,10,COBBLESTONE_STAIRS:0,null,10,STEP:3,null,10,COBBLE_WALL:1,null,20,COBBLESTONE_STAIRS:2,null,20,COBBLESTONE_STAIRS:3,null,20,MOSSY_COBBLESTONE:0,null,60,COBBLESTONE_STAIRS:1,null,20,STEP:11,null,20,COBBLESTONE:0,null,100)
RandomBlock(-8,2,-7,contenttweaker:reinforced_concrete:0,null,40,SMOOTH_BRICK:1,null,30,SMOOTH_BRICK:2,null,30,SMOOTH_STAIRS:0,null,15,SMOOTH_STAIRS:1,null,15,SMOOTH_STAIRS:2,null,15,SMOOTH_STAIRS:3,null,15,STEP:5,null,15,STEP:13,null,15,COBBLE_WALL:0,null,10,COBBLESTONE_STAIRS:0,null,10,STEP:3,null,10,COBBLE_WALL:1,null,20,COBBLESTONE_STAIRS:2,null,20,COBBLESTONE_STAIRS:3,null,20,MOSSY_COBBLESTONE:0,null,60,COBBLESTONE_STAIRS:1,null,20,STEP:11,null,20,COBBLESTONE:0,null,100)
RandomBlock(-8,2,-6,contenttweaker:reinforced_concrete:0,null,40,SMOOTH_BRICK:1,null,30,SMOOTH_BRICK:2,null,30,SMOOTH_STAIRS:0,null,15,SMOOTH_STAIRS:1,null,15,SMOOTH_STAIRS:2,null,15,SMOOTH_STAIRS:3,null,15,STEP:5,null,15,STEP:13,null,15,COBBLE_WALL:0,null,10,COBBLESTONE_STAIRS:0,null,10,STEP:3,null,10,COBBLE_WALL:1,null,20,COBBLESTONE_STAIRS:2,null,20,COBBLESTONE_STAIRS:3,null,20,MOSSY_COBBLESTONE:0,null,60,COBBLESTONE_STAIRS:1,null,20,STEP:11,null,20,COBBLESTONE:0,null,100)
RandomBlock(-8,2,-5,contenttweaker:reinforced_concrete:0,null,40,SMOOTH_BRICK:1,null,30,SMOOTH_BRICK:2,null,30,SMOOTH_STAIRS:0,null,15,SMOOTH_STAIRS:1,null,15,SMOOTH_STAIRS:2,null,15,SMOOTH_STAIRS:3,null,15,STEP:5,null,15,STEP:13,null,15,COBBLE_WALL:0,null,10,COBBLESTONE_STAIRS:0,null,10,STEP:3,null,10,COBBLE_WALL:1,null,20,COBBLESTONE_STAIRS:2,null,20,COBBLESTONE_STAIRS:3,null,20,MOSSY_COBBLESTONE:0,null,60,COBBLESTONE_STAIRS:1,null,20,STEP:11,null,20,COBBLESTONE:0,null,100)
RandomBlock(-8,2,-4,contenttweaker:reinforced_concrete:0,null,40,SMOOTH_BRICK:1,null,30,SMOOTH_BRICK:2,null,30,SMOOTH_STAIRS:0,null,15,SMOOTH_STAIRS:1,null,15,SMOOTH_STAIRS:2,null,15,SMOOTH_STAIRS:3,null,15,STEP:5,null,15,STEP:13,null,15,COBBLE_WALL:0,null,10,COBBLESTONE_STAIRS:0,null,10,STEP:3,null,10,COBBLE_WALL:1,null,20,COBBLESTONE_STAIRS:2,null,20,COBBLESTONE_STAIRS:3,null,20,MOSSY_COBBLESTONE:0,null,60,COBBLESTONE_STAIRS:1,null,20,STEP:11,null,20,COBBLESTONE:0,null,100)
RandomBlock(-8,2,-3,contenttweaker:reinforced_concrete:0,null,40,SMOOTH_BRICK:1,null,30,SMOOTH_BRICK:2,null,30,SMOOTH_STAIRS:0,null,15,SMOOTH_STAIRS:1,null,15,SMOOTH_STAIRS:2,null,15,SMOOTH_STAIRS:3,null,15,STEP:5,null,15,STEP:13,null,15,COBBLE_WALL:0,null,10,COBBLESTONE_STAIRS:0,null,10,STEP:3,null,10,COBBLE_WALL:1,null,20,COBBLESTONE_STAIRS:2,null,20,COBBLESTONE_STAIRS:3,null,20,MOSSY_COBBLESTONE:0,null,60,COBBLESTONE_STAIRS:1,null,20,STEP:11,null,20,COBBLESTONE:0,null,100)
RandomBlock(-8,2,-2,contenttweaker:reinforced_concrete:0,null,40,SMOOTH_BRICK:1,null,30,SMOOTH_BRICK:2,null,30,SMOOTH_STAIRS:0,null,15,SMOOTH_STAIRS:1,null,15,SMOOTH_STAIRS:2,null,15,SMOOTH_STAIRS:3,null,15,STEP:5,null,15,STEP:13,null,15,COBBLE_WALL:0,null,10,COBBLESTONE_STAIRS:0,null,10,STEP:3,null,10,COBBLE_WALL:1,null,20,COBBLESTONE_STAIRS:2,null,20,COBBLESTONE_STAIRS:3,null,20,MOSSY_COBBLESTONE:0,null,60,COBBLESTONE_STAIRS:1,null,20,STEP:11,null,20,COBBLESTONE:0,null,100)
RandomBlock(-8,3,-7,contenttweaker:reinforced_concrete:0,null,40,SMOOTH_BRICK:1,null,30,SMOOTH_BRICK:2,null,30,SMOOTH_STAIRS:0,null,15,SMOOTH_STAIRS:1,null,15,SMOOTH_STAIRS:2,null,15,SMOOTH_STAIRS:3,null,15,STEP:5,null,15,STEP:13,null,15,COBBLE_WALL:0,null,10,COBBLESTONE_STAIRS:0,null,10,STEP:3,null,10,COBBLE_WALL:1,null,20,COBBLESTONE_STAIRS:2,null,20,COBBLESTONE_STAIRS:3,null,20,MOSSY_COBBLESTONE:0,null,60,COBBLESTONE_STAIRS:1,null,20,STEP:11,null,20,COBBLESTONE:0,null,100)
RandomBlock(-8,3,-6,contenttweaker:reinforced_concrete:0,null,40,SMOOTH_BRICK:1,null,30,SMOOTH_BRICK:2,null,30,SMOOTH_STAIRS:0,null,15,SMOOTH_STAIRS:1,null,15,SMOOTH_STAIRS:2,null,15,SMOOTH_STAIRS:3,null,15,STEP:5,null,15,STEP:13,null,15,COBBLE_WALL:0,null,10,COBBLESTONE_STAIRS:0,null,10,STEP:3,null,10,COBBLE_WALL:1,null,20,COBBLESTONE_STAIRS:2,null,20,COBBLESTONE_STAIRS:3,null,20,MOSSY_COBBLESTONE:0,null,60,COBBLESTONE_STAIRS:1,null,20,STEP:11,null,20,COBBLESTONE:0,null,100)
RandomBlock(-8,3,-5,contenttweaker:reinforced_concrete:0,null,40,SMOOTH_BRICK:1,null,30,SMOOTH_BRICK:2,null,30,SMOOTH_STAIRS:0,null,15,SMOOTH_STAIRS:1,null,15,SMOOTH_STAIRS:2,null,15,SMOOTH_STAIRS:3,null,15,STEP:5,null,15,STEP:13,null,15,COBBLE_WALL:0,null,10,COBBLESTONE_STAIRS:0,null,10,STEP:3,null,10,COBBLE_WALL:1,null,20,COBBLESTONE_STAIRS:2,null,20,COBBLESTONE_STAIRS:3,null,20,MOSSY_COBBLESTONE:0,null,60,COBBLESTONE_STAIRS:1,null,20,STEP:11,null,20,COBBLESTONE:0,null,100)
RandomBlock(-8,3,-4,contenttweaker:reinforced_concrete:0,null,40,SMOOTH_BRICK:1,null,30,SMOOTH_BRICK:2,null,30,SMOOTH_STAIRS:0,null,15,SMOOTH_STAIRS:1,null,15,SMOOTH_STAIRS:2,null,15,SMOOTH_STAIRS:3,null,15,STEP:5,null,15,STEP:13,null,15,COBBLE_WALL:0,null,10,COBBLESTONE_STAIRS:0,null,10,STEP:3,null,10,COBBLE_WALL:1,null,20,COBBLESTONE_STAIRS:2,null,20,COBBLESTONE_STAIRS:3,null,20,MOSSY_COBBLESTONE:0,null,60,COBBLESTONE_STAIRS:1,null,20,STEP:11,null,20,COBBLESTONE:0,null,100)
RandomBlock(-8,3,-3,contenttweaker:reinforced_concrete:0,null,40,SMOOTH_BRICK:1,null,30,SMOOTH_BRICK:2,null,30,SMOOTH_STAIRS:0,null,15,SMOOTH_STAIRS:1,null,15,SMOOTH_STAIRS:2,null,15,SMOOTH_STAIRS:3,null,15,STEP:5,null,15,STEP:13,null,15,COBBLE_WALL:0,null,10,COBBLESTONE_STAIRS:0,null,10,STEP:3,null,10,COBBLE_WALL:1,null,20,COBBLESTONE_STAIRS:2,null,20,COBBLESTONE_STAIRS:3,null,20,MOSSY_COBBLESTONE:0,null,60,COBBLESTONE_STAIRS:1,null,20,STEP:11,null,20,COBBLESTONE:0,null,100)
RandomBlock(-8,3,-2,contenttweaker:reinforced_concrete:0,null,40,SMOOTH_BRICK:1,null,30,SMOOTH_BRICK:2,null,30,SMOOTH_STAIRS:0,null,15,SMOOTH_STAIRS:1,null,15,SMOOTH_STAIRS:2,null,15,SMOOTH_STAIRS:3,null,15,STEP:5,null,15,STEP:13,null,15,COBBLE_WALL:0,null,10,COBBLESTONE_STAIRS:0,null,10,STEP:3,null,10,COBBLE_WALL:1,null,20,COBBLESTONE_STAIRS:2,null,20,COBBLESTONE_STAIRS:3,null,20,MOSSY_COBBLESTONE:0,null,60,COBBLESTONE_STAIRS:1,null,20,STEP:11,null,20,COBBLESTONE:0,null,100)
RandomBlock(-8,4,-7,contenttweaker:reinforced_concrete:0,null,40,SMOOTH_BRICK:1,null,30,SMOOTH_BRICK:2,null,30,SMOOTH_STAIRS:0,null,15,SMOOTH_STAIRS:1,null,15,SMOOTH_STAIRS:2,null,15,SMOOTH_STAIRS:3,null,15,STEP:5,null,15,STEP:13,null,15,COBBLE_WALL:0,null,10,COBBLESTONE_STAIRS:0,null,10,STEP:3,null,10,COBBLE_WALL:1,null,20,COBBLESTONE_STAIRS:2,null,20,COBBLESTONE_STAIRS:3,null,20,MOSSY_COBBLESTONE:0,null,60,COBBLESTONE_STAIRS:1,null,20,STEP:11,null,20,COBBLESTONE:0,null,100)
RandomBlock(-8,4,-6,contenttweaker:reinforced_concrete:0,null,40,SMOOTH_BRICK:1,null,30,SMOOTH_BRICK:2,null,30,SMOOTH_STAIRS:0,null,15,SMOOTH_STAIRS:1,null,15,SMOOTH_STAIRS:2,null,15,SMOOTH_STAIRS:3,null,15,STEP:5,null,15,STEP:13,null,15,COBBLE_WALL:0,null,10,COBBLESTONE_STAIRS:0,null,10,STEP:3,null,10,COBBLE_WALL:1,null,20,COBBLESTONE_STAIRS:2,null,20,COBBLESTONE_STAIRS:3,null,20,MOSSY_COBBLESTONE:0,null,60,COBBLESTONE_STAIRS:1,null,20,STEP:11,null,20,COBBLESTONE:0,null,100)
RandomBlock(-8,4,-5,contenttweaker:reinforced_concrete:0,null,40,SMOOTH_BRICK:1,null,30,SMOOTH_BRICK:2,null,30,SMOOTH_STAIRS:0,null,15,SMOOTH_STAIRS:1,null,15,SMOOTH_STAIRS:2,null,15,SMOOTH_STAIRS:3,null,15,STEP:5,null,15,STEP:13,null,15,COBBLE_WALL:0,null,10,COBBLESTONE_STAIRS:0,null,10,STEP:3,null,10,COBBLE_WALL:1,null,20,COBBLESTONE_STAIRS:2,null,20,COBBLESTONE_STAIRS:3,null,20,MOSSY_COBBLESTONE:0,null,60,COBBLESTONE_STAIRS:1,null,20,STEP:11,null,20,COBBLESTONE:0,null,100)
RandomBlock(-8,4,-4,contenttweaker:reinforced_concrete:0,null,40,SMOOTH_BRICK:1,null,30,SMOOTH_BRICK:2,null,30,SMOOTH_STAIRS:0,null,15,SMOOTH_STAIRS:1,null,15,SMOOTH_STAIRS:2,null,15,SMOOTH_STAIRS:3,null,15,STEP:5,null,15,STEP:13,null,15,COBBLE_WALL:0,null,10,COBBLESTONE_STAIRS:0,null,10,STEP:3,null,10,COBBLE_WALL:1,null,20,COBBLESTONE_STAIRS:2,null,20,COBBLESTONE_STAIRS:3,null,20,MOSSY_COBBLESTONE:0,null,60,COBBLESTONE_STAIRS:1,null,20,STEP:11,null,20,COBBLESTONE:0,null,100)
RandomBlock(-8,4,-3,contenttweaker:reinforced_concrete:0,null,40,SMOOTH_BRICK:1,null,30,SMOOTH_BRICK:2,null,30,SMOOTH_STAIRS:0,null,15,SMOOTH_STAIRS:1,null,15,SMOOTH_STAIRS:2,null,15,SMOOTH_STAIRS:3,null,15,STEP:5,null,15,STEP:13,null,15,COBBLE_WALL:0,null,10,COBBLESTONE_STAIRS:0,null,10,STEP:3,null,10,COBBLE_WALL:1,null,20,COBBLESTONE_STAIRS:2,null,20,COBBLESTONE_STAIRS:3,null,20,MOSSY_COBBLESTONE:0,null,60,COBBLESTONE_STAIRS:1,null,20,STEP:11,null,20,COBBLESTONE:0,null,100)
RandomBlock(-8,4,-2,contenttweaker:reinforced_concrete:0,null,40,SMOOTH_BRICK:1,null,30,SMOOTH_BRICK:2,null,30,SMOOTH_STAIRS:0,null,15,SMOOTH_STAIRS:1,null,15,SMOOTH_STAIRS:2,null,15,SMOOTH_STAIRS:3,null,15,STEP:5,null,15,STEP:13,null,15,COBBLE_WALL:0,null,10,COBBLESTONE_STAIRS:0,null,10,STEP:3,null,10,COBBLE_WALL:1,null,20,COBBLESTONE_STAIRS:2,null,20,COBBLESTONE_STAIRS:3,null,20,MOSSY_COBBLESTONE:0,null,60,COBBLESTONE_STAIRS:1,null,20,STEP:11,null,20,COBBLESTONE:0,null,100)
RandomBlock(-8,5,-7,contenttweaker:reinforced_concrete:0,null,40,SMOOTH_BRICK:1,null,30,SMOOTH_BRICK:2,null,30,SMOOTH_STAIRS:0,null,15,SMOOTH_STAIRS:1,null,15,SMOOTH_STAIRS:2,null,15,SMOOTH_STAIRS:3,null,15,STEP:5,null,15,STEP:13,null,15,COBBLE_WALL:0,null,10,COBBLESTONE_STAIRS:0,null,10,STEP:3,null,10,COBBLE_WALL:1,null,20,COBBLESTONE_STAIRS:2,null,20,COBBLESTONE_STAIRS:3,null,20,MOSSY_COBBLESTONE:0,null,60,COBBLESTONE_STAIRS:1,null,20,STEP:11,null,20,COBBLESTONE:0,null,100)
RandomBlock(-8,5,-6,contenttweaker:reinforced_concrete:0,null,40,SMOOTH_BRICK:1,null,30,SMOOTH_BRICK:2,null,30,SMOOTH_STAIRS:0,null,15,SMOOTH_STAIRS:1,null,15,SMOOTH_STAIRS:2,null,15,SMOOTH_STAIRS:3,null,15,STEP:5,null,15,STEP:13,null,15,COBBLE_WALL:0,null,10,COBBLESTONE_STAIRS:0,null,10,STEP:3,null,10,COBBLE_WALL:1,null,20,COBBLESTONE_STAIRS:2,null,20,COBBLESTONE_STAIRS:3,null,20,MOSSY_COBBLESTONE:0,null,60,COBBLESTONE_STAIRS:1,null,20,STEP:11,null,20,COBBLESTONE:0,null,100)
RandomBlock(-8,5,-5,contenttweaker:reinforced_concrete:0,null,40,SMOOTH_BRICK:1,null,30,SMOOTH_BRICK:2,null,30,SMOOTH_STAIRS:0,null,15,SMOOTH_STAIRS:1,null,15,SMOOTH_STAIRS:2,null,15,SMOOTH_STAIRS:3,null,15,STEP:5,null,15,STEP:13,null,15,COBBLE_WALL:0,null,10,COBBLESTONE_STAIRS:0,null,10,STEP:3,null,10,COBBLE_WALL:1,null,20,COBBLESTONE_STAIRS:2,null,20,COBBLESTONE_STAIRS:3,null,20,MOSSY_COBBLESTONE:0,null,60,COBBLESTONE_STAIRS:1,null,20,STEP:11,null,20,COBBLESTONE:0,null,100)
RandomBlock(-8,5,-4,contenttweaker:reinforced_concrete:0,null,40,SMOOTH_BRICK:1,null,30,SMOOTH_BRICK:2,null,30,SMOOTH_STAIRS:0,null,15,SMOOTH_STAIRS:1,null,15,SMOOTH_STAIRS:2,null,15,SMOOTH_STAIRS:3,null,15,STEP:5,null,15,STEP:13,null,15,COBBLE_WALL:0,null,10,COBBLESTONE_STAIRS:0,null,10,STEP:3,null,10,COBBLE_WALL:1,null,20,COBBLESTONE_STAIRS:2,null,20,COBBLESTONE_STAIRS:3,null,20,MOSSY_COBBLESTONE:0,null,60,COBBLESTONE_STAIRS:1,null,20,STEP:11,null,20,COBBLESTONE:0,null,100)
RandomBlock(-8,5,-3,contenttweaker:reinforced_concrete:0,null,40,SMOOTH_BRICK:1,null,30,SMOOTH_BRICK:2,null,30,SMOOTH_STAIRS:0,null,15,SMOOTH_STAIRS:1,null,15,SMOOTH_STAIRS:2,null,15,SMOOTH_STAIRS:3,null,15,STEP:5,null,15,STEP:13,null,15,COBBLE_WALL:0,null,10,COBBLESTONE_STAIRS:0,null,10,STEP:3,null,10,COBBLE_WALL:1,null,20,COBBLESTONE_STAIRS:2,null,20,COBBLESTONE_STAIRS:3,null,20,MOSSY_COBBLESTONE:0,null,60,COBBLESTONE_STAIRS:1,null,20,STEP:11,null,20,COBBLESTONE:0,null,100)
RandomBlock(-8,5,-2,contenttweaker:reinforced_concrete:0,null,30,quark:limestone_wall:0,null,10,contenttweaker:reinforced_concrete:0,null,100)
RandomBlock(-8,6,-7,contenttweaker:reinforced_concrete:0,null,40,SMOOTH_BRICK:1,null,30,SMOOTH_BRICK:2,null,30,SMOOTH_STAIRS:0,null,15,SMOOTH_STAIRS:1,null,15,SMOOTH_STAIRS:2,null,15,SMOOTH_STAIRS:3,null,15,STEP:5,null,15,STEP:13,null,15,COBBLE_WALL:0,null,10,COBBLESTONE_STAIRS:0,null,10,STEP:3,null,10,COBBLE_WALL:1,null,20,COBBLESTONE_STAIRS:2,null,20,COBBLESTONE_STAIRS:3,null,20,MOSSY_COBBLESTONE:0,null,60,COBBLESTONE_STAIRS:1,null,20,STEP:11,null,20,COBBLESTONE:0,null,100)
RandomBlock(-8,6,-6,contenttweaker:reinforced_concrete:0,null,40,SMOOTH_BRICK:1,null,30,SMOOTH_BRICK:2,null,30,SMOOTH_STAIRS:0,null,15,SMOOTH_STAIRS:1,null,15,SMOOTH_STAIRS:2,null,15,SMOOTH_STAIRS:3,null,15,STEP:5,null,15,STEP:13,null,15,COBBLE_WALL:0,null,10,COBBLESTONE_STAIRS:0,null,10,STEP:3,null,10,COBBLE_WALL:1,null,20,COBBLESTONE_STAIRS:2,null,20,COBBLESTONE_STAIRS:3,null,20,MOSSY_COBBLESTONE:0,null,60,COBBLESTONE_STAIRS:1,null,20,STEP:11,null,20,COBBLESTONE:0,null,100)
RandomBlock(-8,6,-5,contenttweaker:reinforced_concrete:0,null,40,SMOOTH_BRICK:1,null,30,SMOOTH_BRICK:2,null,30,SMOOTH_STAIRS:0,null,15,SMOOTH_STAIRS:1,null,15,SMOOTH_STAIRS:2,null,15,SMOOTH_STAIRS:3,null,15,STEP:5,null,15,STEP:13,null,15,COBBLE_WALL:0,null,10,COBBLESTONE_STAIRS:0,null,10,STEP:3,null,10,COBBLE_WALL:1,null,20,COBBLESTONE_STAIRS:2,null,20,COBBLESTONE_STAIRS:3,null,20,MOSSY_COBBLESTONE:0,null,60,COBBLESTONE_STAIRS:1,null,20,STEP:11,null,20,COBBLESTONE:0,null,100)
RandomBlock(-8,6,-4,contenttweaker:reinforced_concrete:0,null,40,SMOOTH_BRICK:1,null,30,SMOOTH_BRICK:2,null,30,SMOOTH_STAIRS:0,null,15,SMOOTH_STAIRS:1,null,15,SMOOTH_STAIRS:2,null,15,SMOOTH_STAIRS:3,null,15,STEP:5,null,15,STEP:13,null,15,COBBLE_WALL:0,null,10,COBBLESTONE_STAIRS:0,null,10,STEP:3,null,10,COBBLE_WALL:1,null,20,COBBLESTONE_STAIRS:2,null,20,COBBLESTONE_STAIRS:3,null,20,MOSSY_COBBLESTONE:0,null,60,COBBLESTONE_STAIRS:1,null,20,STEP:11,null,20,COBBLESTONE:0,null,100)
RandomBlock(-8,6,-3,contenttweaker:reinforced_concrete:0,null,40,SMOOTH_BRICK:1,null,30,SMOOTH_BRICK:2,null,30,SMOOTH_STAIRS:0,null,15,SMOOTH_STAIRS:1,null,15,SMOOTH_STAIRS:2,null,15,SMOOTH_STAIRS:3,null,15,STEP:5,null,15,STEP:13,null,15,COBBLE_WALL:0,null,10,COBBLESTONE_STAIRS:0,null,10,STEP:3,null,10,COBBLE_WALL:1,null,20,COBBLESTONE_STAIRS:2,null,20,COBBLESTONE_STAIRS:3,null,20,MOSSY_COBBLESTONE:0,null,60,COBBLESTONE_STAIRS:1,null,20,STEP:11,null,20,COBBLESTONE:0,null,100)
RandomBlock(-8,6,-2,contenttweaker:reinforced_concrete:0,null,30,quark:limestone_wall:0,null,10,contenttweaker:reinforced_concrete:0,null,100)
RandomBlock(-8,7,-7,contenttweaker:reinforced_concrete:0,null,40,SMOOTH_BRICK:1,null,30,SMOOTH_BRICK:2,null,30,SMOOTH_STAIRS:0,null,15,SMOOTH_STAIRS:1,null,15,SMOOTH_STAIRS:2,null,15,SMOOTH_STAIRS:3,null,15,STEP:5,null,15,STEP:13,null,15,COBBLE_WALL:0,null,10,COBBLESTONE_STAIRS:0,null,10,STEP:3,null,10,COBBLE_WALL:1,null,20,COBBLESTONE_STAIRS:2,null,20,COBBLESTONE_STAIRS:3,null,20,MOSSY_COBBLESTONE:0,null,60,COBBLESTONE_STAIRS:1,null,20,STEP:11,null,20,COBBLESTONE:0,null,100)
RandomBlock(-8,7,-6,contenttweaker:reinforced_concrete:0,null,40,SMOOTH_BRICK:1,null,30,SMOOTH_BRICK:2,null,30,SMOOTH_STAIRS:0,null,15,SMOOTH_STAIRS:1,null,15,SMOOTH_STAIRS:2,null,15,SMOOTH_STAIRS:3,null,15,STEP:5,null,15,STEP:13,null,15,COBBLE_WALL:0,null,10,COBBLESTONE_STAIRS:0,null,10,STEP:3,null,10,COBBLE_WALL:1,null,20,COBBLESTONE_STAIRS:2,null,20,COBBLESTONE_STAIRS:3,null,20,MOSSY_COBBLESTONE:0,null,60,COBBLESTONE_STAIRS:1,null,20,STEP:11,null,20,COBBLESTONE:0,null,100)
RandomBlock(-8,7,-5,contenttweaker:reinforced_concrete:0,null,40,SMOOTH_BRICK:1,null,30,SMOOTH_BRICK:2,null,30,SMOOTH_STAIRS:0,null,15,SMOOTH_STAIRS:1,null,15,SMOOTH_STAIRS:2,null,15,SMOOTH_STAIRS:3,null,15,STEP:5,null,15,STEP:13,null,15,COBBLE_WALL:0,null,10,COBBLESTONE_STAIRS:0,null,10,STEP:3,null,10,COBBLE_WALL:1,null,20,COBBLESTONE_STAIRS:2,null,20,COBBLESTONE_STAIRS:3,null,20,MOSSY_COBBLESTONE:0,null,60,COBBLESTONE_STAIRS:1,null,20,STEP:11,null,20,COBBLESTONE:0,null,100)
RandomBlock(-8,7,-4,contenttweaker:reinforced_concrete:0,null,40,SMOOTH_BRICK:1,null,30,SMOOTH_BRICK:2,null,30,SMOOTH_STAIRS:0,null,15,SMOOTH_STAIRS:1,null,15,SMOOTH_STAIRS:2,null,15,SMOOTH_STAIRS:3,null,15,STEP:5,null,15,STEP:13,null,15,COBBLE_WALL:0,null,10,COBBLESTONE_STAIRS:0,null,10,STEP:3,null,10,COBBLE_WALL:1,null,20,COBBLESTONE_STAIRS:2,null,20,COBBLESTONE_STAIRS:3,null,20,MOSSY_COBBLESTONE:0,null,60,COBBLESTONE_STAIRS:1,null,20,STEP:11,null,20,COBBLESTONE:0,null,100)
RandomBlock(-8,7,-3,contenttweaker:reinforced_concrete:0,null,40,SMOOTH_BRICK:1,null,30,SMOOTH_BRICK:2,null,30,SMOOTH_STAIRS:0,null,15,SMOOTH_STAIRS:1,null,15,SMOOTH_STAIRS:2,null,15,SMOOTH_STAIRS:3,null,15,STEP:5,null,15,STEP:13,null,15,COBBLE_WALL:0,null,10,COBBLESTONE_STAIRS:0,null,10,STEP:3,null,10,COBBLE_WALL:1,null,20,COBBLESTONE_STAIRS:2,null,20,COBBLESTONE_STAIRS:3,null,20,MOSSY_COBBLESTONE:0,null,60,COBBLESTONE_STAIRS:1,null,20,STEP:11,null,20,COBBLESTONE:0,null,100)
RandomBlock(-8,7,-2,contenttweaker:reinforced_concrete:0,null,30,quark:limestone_wall:0,null,10,contenttweaker:reinforced_concrete:0,null,100)
RandomBlock(-8,8,-7,contenttweaker:reinforced_concrete:0,null,30,quark:limestone_wall:0,null,10,contenttweaker:reinforced_concrete:0,null,100)
RandomBlock(-8,8,-6,contenttweaker:reinforced_concrete:0,null,30,quark:limestone_wall:0,null,10,contenttweaker:reinforced_concrete:0,null,100)
RandomBlock(-8,8,-5,contenttweaker:reinforced_concrete:0,null,30,quark:limestone_wall:0,null,10,contenttweaker:reinforced_concrete:0,null,100)
RandomBlock(-8,8,-4,rustic:iron_lattice:0,null,30,rustic:iron_lattice:1,null,100)
RandomBlock(-8,8,-3,rustic:iron_lattice:0,null,30,rustic:iron_lattice:1,null,100)
Block(-8,8,-2,inspirations:redstone_barrel:0)
RandomBlock(-8,9,-7,contenttweaker:reinforced_concrete:0,null,30,quark:limestone_wall:0,null,10,contenttweaker:reinforced_concrete:0,null,100)
RandomBlock(-8,9,-4,rustic:iron_lattice:0,null,30,rustic:iron_lattice:1,null,100)
RandomBlock(-8,9,-3,rustic:iron_lattice:0,null,30,rustic:iron_lattice:1,null,100)
Block(-8,9,-2,inspirations:redstone_barrel:0)
RandomBlock(-8,10,-7,rustic:iron_lattice:0,null,30,rustic:iron_lattice:1,null,100)
RandomBlock(-8,10,-4,rustic:iron_lattice:0,null,30,rustic:iron_lattice:1,null,100)
RandomBlock(-8,10,-3,rustic:iron_lattice:0,null,30,rustic:iron_lattice:1,null,100)
RandomBlock(-8,10,-2,contenttweaker:reinforced_concrete:0,null,30,quark:limestone_wall:0,null,10,contenttweaker:reinforced_concrete:0,null,100)
RandomBlock(-8,11,-7,rustic:iron_lattice:0,null,30,rustic:iron_lattice:1,null,100)
RandomBlock(-8,11,-2,contenttweaker:reinforced_concrete:0,null,30,quark:limestone_wall:0,null,10,contenttweaker:reinforced_concrete:0,null,100)
Block(-8,12,-4,VINE:8)
RandomBlock(-8,12,-3,contenttweaker:reinforced_concrete:0,null,30,quark:limestone_wall:0,null,10,contenttweaker:reinforced_concrete:0,null,100)
RandomBlock(-8,13,-3,contenttweaker:reinforced_concrete:0,null,30,quark:limestone_wall:0,null,10,contenttweaker:reinforced_concrete:0,null,100)
Block(-8,14,-3,VINE:2)
RandomBlock(-7,0,-7,contenttweaker:reinforced_concrete:0,null,40,SMOOTH_BRICK:1,null,30,SMOOTH_BRICK:2,null,30,SMOOTH_STAIRS:0,null,15,SMOOTH_STAIRS:1,null,15,SMOOTH_STAIRS:2,null,15,SMOOTH_STAIRS:3,null,15,STEP:5,null,15,STEP:13,null,15,COBBLE_WALL:0,null,10,COBBLESTONE_STAIRS:0,null,10,STEP:3,null,10,COBBLE_WALL:1,null,20,COBBLESTONE_STAIRS:2,null,20,COBBLESTONE_STAIRS:3,null,20,MOSSY_COBBLESTONE:0,null,60,COBBLESTONE_STAIRS:1,null,20,STEP:11,null,20,COBBLESTONE:0,null,100)
RandomBlock(-7,0,-6,contenttweaker:reinforced_concrete:0,null,40,SMOOTH_BRICK:1,null,30,SMOOTH_BRICK:2,null,30,SMOOTH_STAIRS:0,null,15,SMOOTH_STAIRS:1,null,15,SMOOTH_STAIRS:2,null,15,SMOOTH_STAIRS:3,null,15,STEP:5,null,15,STEP:13,null,15,COBBLE_WALL:0,null,10,COBBLESTONE_STAIRS:0,null,10,STEP:3,null,10,COBBLE_WALL:1,null,20,COBBLESTONE_STAIRS:2,null,20,COBBLESTONE_STAIRS:3,null,20,MOSSY_COBBLESTONE:0,null,60,COBBLESTONE_STAIRS:1,null,20,STEP:11,null,20,COBBLESTONE:0,null,100)
RandomBlock(-7,0,-5,contenttweaker:reinforced_concrete:0,null,40,SMOOTH_BRICK:1,null,30,SMOOTH_BRICK:2,null,30,SMOOTH_STAIRS:0,null,15,SMOOTH_STAIRS:1,null,15,SMOOTH_STAIRS:2,null,15,SMOOTH_STAIRS:3,null,15,STEP:5,null,15,STEP:13,null,15,COBBLE_WALL:0,null,10,COBBLESTONE_STAIRS:0,null,10,STEP:3,null,10,COBBLE_WALL:1,null,20,COBBLESTONE_STAIRS:2,null,20,COBBLESTONE_STAIRS:3,null,20,MOSSY_COBBLESTONE:0,null,60,COBBLESTONE_STAIRS:1,null,20,STEP:11,null,20,COBBLESTONE:0,null,100)
RandomBlock(-7,0,-4,contenttweaker:reinforced_concrete:0,null,40,SMOOTH_BRICK:1,null,30,SMOOTH_BRICK:2,null,30,SMOOTH_STAIRS:0,null,15,SMOOTH_STAIRS:1,null,15,SMOOTH_STAIRS:2,null,15,SMOOTH_STAIRS:3,null,15,STEP:5,null,15,STEP:13,null,15,COBBLE_WALL:0,null,10,COBBLESTONE_STAIRS:0,null,10,STEP:3,null,10,COBBLE_WALL:1,null,20,COBBLESTONE_STAIRS:2,null,20,COBBLESTONE_STAIRS:3,null,20,MOSSY_COBBLESTONE:0,null,60,COBBLESTONE_STAIRS:1,null,20,STEP:11,null,20,COBBLESTONE:0,null,100)
RandomBlock(-7,0,-3,contenttweaker:reinforced_concrete:0,null,40,SMOOTH_BRICK:1,null,30,SMOOTH_BRICK:2,null,30,SMOOTH_STAIRS:0,null,15,SMOOTH_STAIRS:1,null,15,SMOOTH_STAIRS:2,null,15,SMOOTH_STAIRS:3,null,15,STEP:5,null,15,STEP:13,null,15,COBBLE_WALL:0,null,10,COBBLESTONE_STAIRS:0,null,10,STEP:3,null,10,COBBLE_WALL:1,null,20,COBBLESTONE_STAIRS:2,null,20,COBBLESTONE_STAIRS:3,null,20,MOSSY_COBBLESTONE:0,null,60,COBBLESTONE_STAIRS:1,null,20,STEP:11,null,20,COBBLESTONE:0,null,100)
RandomBlock(-7,1,-7,contenttweaker:reinforced_concrete:0,null,40,SMOOTH_BRICK:1,null,30,SMOOTH_BRICK:2,null,30,SMOOTH_STAIRS:0,null,15,SMOOTH_STAIRS:1,null,15,SMOOTH_STAIRS:2,null,15,SMOOTH_STAIRS:3,null,15,STEP:5,null,15,STEP:13,null,15,COBBLE_WALL:0,null,10,COBBLESTONE_STAIRS:0,null,10,STEP:3,null,10,COBBLE_WALL:1,null,20,COBBLESTONE_STAIRS:2,null,20,COBBLESTONE_STAIRS:3,null,20,MOSSY_COBBLESTONE:0,null,60,COBBLESTONE_STAIRS:1,null,20,STEP:11,null,20,COBBLESTONE:0,null,100)
RandomBlock(-7,1,-6,contenttweaker:reinforced_concrete:0,null,40,SMOOTH_BRICK:1,null,30,SMOOTH_BRICK:2,null,30,SMOOTH_STAIRS:0,null,15,SMOOTH_STAIRS:1,null,15,SMOOTH_STAIRS:2,null,15,SMOOTH_STAIRS:3,null,15,STEP:5,null,15,STEP:13,null,15,COBBLE_WALL:0,null,10,COBBLESTONE_STAIRS:0,null,10,STEP:3,null,10,COBBLE_WALL:1,null,20,COBBLESTONE_STAIRS:2,null,20,COBBLESTONE_STAIRS:3,null,20,MOSSY_COBBLESTONE:0,null,60,COBBLESTONE_STAIRS:1,null,20,STEP:11,null,20,COBBLESTONE:0,null,100)
RandomBlock(-7,1,-5,contenttweaker:reinforced_concrete:0,null,40,SMOOTH_BRICK:1,null,30,SMOOTH_BRICK:2,null,30,SMOOTH_STAIRS:0,null,15,SMOOTH_STAIRS:1,null,15,SMOOTH_STAIRS:2,null,15,SMOOTH_STAIRS:3,null,15,STEP:5,null,15,STEP:13,null,15,COBBLE_WALL:0,null,10,COBBLESTONE_STAIRS:0,null,10,STEP:3,null,10,COBBLE_WALL:1,null,20,COBBLESTONE_STAIRS:2,null,20,COBBLESTONE_STAIRS:3,null,20,MOSSY_COBBLESTONE:0,null,60,COBBLESTONE_STAIRS:1,null,20,STEP:11,null,20,COBBLESTONE:0,null,100)
RandomBlock(-7,1,-4,contenttweaker:reinforced_concrete:0,null,40,SMOOTH_BRICK:1,null,30,SMOOTH_BRICK:2,null,30,SMOOTH_STAIRS:0,null,15,SMOOTH_STAIRS:1,null,15,SMOOTH_STAIRS:2,null,15,SMOOTH_STAIRS:3,null,15,STEP:5,null,15,STEP:13,null,15,COBBLE_WALL:0,null,10,COBBLESTONE_STAIRS:0,null,10,STEP:3,null,10,COBBLE_WALL:1,null,20,COBBLESTONE_STAIRS:2,null,20,COBBLESTONE_STAIRS:3,null,20,MOSSY_COBBLESTONE:0,null,60,COBBLESTONE_STAIRS:1,null,20,STEP:11,null,20,COBBLESTONE:0,null,100)
RandomBlock(-7,1,-3,contenttweaker:reinforced_concrete:0,null,40,SMOOTH_BRICK:1,null,30,SMOOTH_BRICK:2,null,30,SMOOTH_STAIRS:0,null,15,SMOOTH_STAIRS:1,null,15,SMOOTH_STAIRS:2,null,15,SMOOTH_STAIRS:3,null,15,STEP:5,null,15,STEP:13,null,15,COBBLE_WALL:0,null,10,COBBLESTONE_STAIRS:0,null,10,STEP:3,null,10,COBBLE_WALL:1,null,20,COBBLESTONE_STAIRS:2,null,20,COBBLESTONE_STAIRS:3,null,20,MOSSY_COBBLESTONE:0,null,60,COBBLESTONE_STAIRS:1,null,20,STEP:11,null,20,COBBLESTONE:0,null,100)
RandomBlock(-7,2,-7,contenttweaker:reinforced_concrete:0,null,40,SMOOTH_BRICK:1,null,30,SMOOTH_BRICK:2,null,30,SMOOTH_STAIRS:0,null,15,SMOOTH_STAIRS:1,null,15,SMOOTH_STAIRS:2,null,15,SMOOTH_STAIRS:3,null,15,STEP:5,null,15,STEP:13,null,15,COBBLE_WALL:0,null,10,COBBLESTONE_STAIRS:0,null,10,STEP:3,null,10,COBBLE_WALL:1,null,20,COBBLESTONE_STAIRS:2,null,20,COBBLESTONE_STAIRS:3,null,20,MOSSY_COBBLESTONE:0,null,60,COBBLESTONE_STAIRS:1,null,20,STEP:11,null,20,COBBLESTONE:0,null,100)
RandomBlock(-7,2,-6,contenttweaker:reinforced_concrete:0,null,40,SMOOTH_BRICK:1,null,30,SMOOTH_BRICK:2,null,30,SMOOTH_STAIRS:0,null,15,SMOOTH_STAIRS:1,null,15,SMOOTH_STAIRS:2,null,15,SMOOTH_STAIRS:3,null,15,STEP:5,null,15,STEP:13,null,15,COBBLE_WALL:0,null,10,COBBLESTONE_STAIRS:0,null,10,STEP:3,null,10,COBBLE_WALL:1,null,20,COBBLESTONE_STAIRS:2,null,20,COBBLESTONE_STAIRS:3,null,20,MOSSY_COBBLESTONE:0,null,60,COBBLESTONE_STAIRS:1,null,20,STEP:11,null,20,COBBLESTONE:0,null,100)
RandomBlock(-7,2,-5,contenttweaker:reinforced_concrete:0,null,40,SMOOTH_BRICK:1,null,30,SMOOTH_BRICK:2,null,30,SMOOTH_STAIRS:0,null,15,SMOOTH_STAIRS:1,null,15,SMOOTH_STAIRS:2,null,15,SMOOTH_STAIRS:3,null,15,STEP:5,null,15,STEP:13,null,15,COBBLE_WALL:0,null,10,COBBLESTONE_STAIRS:0,null,10,STEP:3,null,10,COBBLE_WALL:1,null,20,COBBLESTONE_STAIRS:2,null,20,COBBLESTONE_STAIRS:3,null,20,MOSSY_COBBLESTONE:0,null,60,COBBLESTONE_STAIRS:1,null,20,STEP:11,null,20,COBBLESTONE:0,null,100)
RandomBlock(-7,2,-4,contenttweaker:reinforced_concrete:0,null,40,SMOOTH_BRICK:1,null,30,SMOOTH_BRICK:2,null,30,SMOOTH_STAIRS:0,null,15,SMOOTH_STAIRS:1,null,15,SMOOTH_STAIRS:2,null,15,SMOOTH_STAIRS:3,null,15,STEP:5,null,15,STEP:13,null,15,COBBLE_WALL:0,null,10,COBBLESTONE_STAIRS:0,null,10,STEP:3,null,10,COBBLE_WALL:1,null,20,COBBLESTONE_STAIRS:2,null,20,COBBLESTONE_STAIRS:3,null,20,MOSSY_COBBLESTONE:0,null,60,COBBLESTONE_STAIRS:1,null,20,STEP:11,null,20,COBBLESTONE:0,null,100)
RandomBlock(-7,2,-3,contenttweaker:reinforced_concrete:0,null,40,SMOOTH_BRICK:1,null,30,SMOOTH_BRICK:2,null,30,SMOOTH_STAIRS:0,null,15,SMOOTH_STAIRS:1,null,15,SMOOTH_STAIRS:2,null,15,SMOOTH_STAIRS:3,null,15,STEP:5,null,15,STEP:13,null,15,COBBLE_WALL:0,null,10,COBBLESTONE_STAIRS:0,null,10,STEP:3,null,10,COBBLE_WALL:1,null,20,COBBLESTONE_STAIRS:2,null,20,COBBLESTONE_STAIRS:3,null,20,MOSSY_COBBLESTONE:0,null,60,COBBLESTONE_STAIRS:1,null,20,STEP:11,null,20,COBBLESTONE:0,null,100)
RandomBlock(-7,3,-7,contenttweaker:reinforced_concrete:0,null,40,SMOOTH_BRICK:1,null,30,SMOOTH_BRICK:2,null,30,SMOOTH_STAIRS:0,null,15,SMOOTH_STAIRS:1,null,15,SMOOTH_STAIRS:2,null,15,SMOOTH_STAIRS:3,null,15,STEP:5,null,15,STEP:13,null,15,COBBLE_WALL:0,null,10,COBBLESTONE_STAIRS:0,null,10,STEP:3,null,10,COBBLE_WALL:1,null,20,COBBLESTONE_STAIRS:2,null,20,COBBLESTONE_STAIRS:3,null,20,MOSSY_COBBLESTONE:0,null,60,COBBLESTONE_STAIRS:1,null,20,STEP:11,null,20,COBBLESTONE:0,null,100)
RandomBlock(-7,3,-6,contenttweaker:reinforced_concrete:0,null,40,SMOOTH_BRICK:1,null,30,SMOOTH_BRICK:2,null,30,SMOOTH_STAIRS:0,null,15,SMOOTH_STAIRS:1,null,15,SMOOTH_STAIRS:2,null,15,SMOOTH_STAIRS:3,null,15,STEP:5,null,15,STEP:13,null,15,COBBLE_WALL:0,null,10,COBBLESTONE_STAIRS:0,null,10,STEP:3,null,10,COBBLE_WALL:1,null,20,COBBLESTONE_STAIRS:2,null,20,COBBLESTONE_STAIRS:3,null,20,MOSSY_COBBLESTONE:0,null,60,COBBLESTONE_STAIRS:1,null,20,STEP:11,null,20,COBBLESTONE:0,null,100)
RandomBlock(-7,3,-5,contenttweaker:reinforced_concrete:0,null,40,SMOOTH_BRICK:1,null,30,SMOOTH_BRICK:2,null,30,SMOOTH_STAIRS:0,null,15,SMOOTH_STAIRS:1,null,15,SMOOTH_STAIRS:2,null,15,SMOOTH_STAIRS:3,null,15,STEP:5,null,15,STEP:13,null,15,COBBLE_WALL:0,null,10,COBBLESTONE_STAIRS:0,null,10,STEP:3,null,10,COBBLE_WALL:1,null,20,COBBLESTONE_STAIRS:2,null,20,COBBLESTONE_STAIRS:3,null,20,MOSSY_COBBLESTONE:0,null,60,COBBLESTONE_STAIRS:1,null,20,STEP:11,null,20,COBBLESTONE:0,null,100)
RandomBlock(-7,3,-4,contenttweaker:reinforced_concrete:0,null,40,SMOOTH_BRICK:1,null,30,SMOOTH_BRICK:2,null,30,SMOOTH_STAIRS:0,null,15,SMOOTH_STAIRS:1,null,15,SMOOTH_STAIRS:2,null,15,SMOOTH_STAIRS:3,null,15,STEP:5,null,15,STEP:13,null,15,COBBLE_WALL:0,null,10,COBBLESTONE_STAIRS:0,null,10,STEP:3,null,10,COBBLE_WALL:1,null,20,COBBLESTONE_STAIRS:2,null,20,COBBLESTONE_STAIRS:3,null,20,MOSSY_COBBLESTONE:0,null,60,COBBLESTONE_STAIRS:1,null,20,STEP:11,null,20,COBBLESTONE:0,null,100)
RandomBlock(-7,3,-3,contenttweaker:reinforced_concrete:0,null,40,SMOOTH_BRICK:1,null,30,SMOOTH_BRICK:2,null,30,SMOOTH_STAIRS:0,null,15,SMOOTH_STAIRS:1,null,15,SMOOTH_STAIRS:2,null,15,SMOOTH_STAIRS:3,null,15,STEP:5,null,15,STEP:13,null,15,COBBLE_WALL:0,null,10,COBBLESTONE_STAIRS:0,null,10,STEP:3,null,10,COBBLE_WALL:1,null,20,COBBLESTONE_STAIRS:2,null,20,COBBLESTONE_STAIRS:3,null,20,MOSSY_COBBLESTONE:0,null,60,COBBLESTONE_STAIRS:1,null,20,STEP:11,null,20,COBBLESTONE:0,null,100)
RandomBlock(-7,4,-7,contenttweaker:reinforced_concrete:0,null,40,SMOOTH_BRICK:1,null,30,SMOOTH_BRICK:2,null,30,SMOOTH_STAIRS:0,null,15,SMOOTH_STAIRS:1,null,15,SMOOTH_STAIRS:2,null,15,SMOOTH_STAIRS:3,null,15,STEP:5,null,15,STEP:13,null,15,COBBLE_WALL:0,null,10,COBBLESTONE_STAIRS:0,null,10,STEP:3,null,10,COBBLE_WALL:1,null,20,COBBLESTONE_STAIRS:2,null,20,COBBLESTONE_STAIRS:3,null,20,MOSSY_COBBLESTONE:0,null,60,COBBLESTONE_STAIRS:1,null,20,STEP:11,null,20,COBBLESTONE:0,null,100)
RandomBlock(-7,4,-6,contenttweaker:reinforced_concrete:0,null,40,SMOOTH_BRICK:1,null,30,SMOOTH_BRICK:2,null,30,SMOOTH_STAIRS:0,null,15,SMOOTH_STAIRS:1,null,15,SMOOTH_STAIRS:2,null,15,SMOOTH_STAIRS:3,null,15,STEP:5,null,15,STEP:13,null,15,COBBLE_WALL:0,null,10,COBBLESTONE_STAIRS:0,null,10,STEP:3,null,10,COBBLE_WALL:1,null,20,COBBLESTONE_STAIRS:2,null,20,COBBLESTONE_STAIRS:3,null,20,MOSSY_COBBLESTONE:0,null,60,COBBLESTONE_STAIRS:1,null,20,STEP:11,null,20,COBBLESTONE:0,null,100)
RandomBlock(-7,4,-5,contenttweaker:reinforced_concrete:0,null,40,SMOOTH_BRICK:1,null,30,SMOOTH_BRICK:2,null,30,SMOOTH_STAIRS:0,null,15,SMOOTH_STAIRS:1,null,15,SMOOTH_STAIRS:2,null,15,SMOOTH_STAIRS:3,null,15,STEP:5,null,15,STEP:13,null,15,COBBLE_WALL:0,null,10,COBBLESTONE_STAIRS:0,null,10,STEP:3,null,10,COBBLE_WALL:1,null,20,COBBLESTONE_STAIRS:2,null,20,COBBLESTONE_STAIRS:3,null,20,MOSSY_COBBLESTONE:0,null,60,COBBLESTONE_STAIRS:1,null,20,STEP:11,null,20,COBBLESTONE:0,null,100)
RandomBlock(-7,4,-4,contenttweaker:reinforced_concrete:0,null,40,SMOOTH_BRICK:1,null,30,SMOOTH_BRICK:2,null,30,SMOOTH_STAIRS:0,null,15,SMOOTH_STAIRS:1,null,15,SMOOTH_STAIRS:2,null,15,SMOOTH_STAIRS:3,null,15,STEP:5,null,15,STEP:13,null,15,COBBLE_WALL:0,null,10,COBBLESTONE_STAIRS:0,null,10,STEP:3,null,10,COBBLE_WALL:1,null,20,COBBLESTONE_STAIRS:2,null,20,COBBLESTONE_STAIRS:3,null,20,MOSSY_COBBLESTONE:0,null,60,COBBLESTONE_STAIRS:1,null,20,STEP:11,null,20,COBBLESTONE:0,null,100)
RandomBlock(-7,4,-3,contenttweaker:reinforced_concrete:0,null,40,SMOOTH_BRICK:1,null,30,SMOOTH_BRICK:2,null,30,SMOOTH_STAIRS:0,null,15,SMOOTH_STAIRS:1,null,15,SMOOTH_STAIRS:2,null,15,SMOOTH_STAIRS:3,null,15,STEP:5,null,15,STEP:13,null,15,COBBLE_WALL:0,null,10,COBBLESTONE_STAIRS:0,null,10,STEP:3,null,10,COBBLE_WALL:1,null,20,COBBLESTONE_STAIRS:2,null,20,COBBLESTONE_STAIRS:3,null,20,MOSSY_COBBLESTONE:0,null,60,COBBLESTONE_STAIRS:1,null,20,STEP:11,null,20,COBBLESTONE:0,null,100)
RandomBlock(-7,5,-7,contenttweaker:reinforced_concrete:0,null,40,SMOOTH_BRICK:1,null,30,SMOOTH_BRICK:2,null,30,SMOOTH_STAIRS:0,null,15,SMOOTH_STAIRS:1,null,15,SMOOTH_STAIRS:2,null,15,SMOOTH_STAIRS:3,null,15,STEP:5,null,15,STEP:13,null,15,COBBLE_WALL:0,null,10,COBBLESTONE_STAIRS:0,null,10,STEP:3,null,10,COBBLE_WALL:1,null,20,COBBLESTONE_STAIRS:2,null,20,COBBLESTONE_STAIRS:3,null,20,MOSSY_COBBLESTONE:0,null,60,COBBLESTONE_STAIRS:1,null,20,STEP:11,null,20,COBBLESTONE:0,null,100)
RandomBlock(-7,5,-6,contenttweaker:reinforced_concrete:0,null,40,SMOOTH_BRICK:1,null,30,SMOOTH_BRICK:2,null,30,SMOOTH_STAIRS:0,null,15,SMOOTH_STAIRS:1,null,15,SMOOTH_STAIRS:2,null,15,SMOOTH_STAIRS:3,null,15,STEP:5,null,15,STEP:13,null,15,COBBLE_WALL:0,null,10,COBBLESTONE_STAIRS:0,null,10,STEP:3,null,10,COBBLE_WALL:1,null,20,COBBLESTONE_STAIRS:2,null,20,COBBLESTONE_STAIRS:3,null,20,MOSSY_COBBLESTONE:0,null,60,COBBLESTONE_STAIRS:1,null,20,STEP:11,null,20,COBBLESTONE:0,null,100)
RandomBlock(-7,5,-5,contenttweaker:reinforced_concrete:0,null,40,SMOOTH_BRICK:1,null,30,SMOOTH_BRICK:2,null,30,SMOOTH_STAIRS:0,null,15,SMOOTH_STAIRS:1,null,15,SMOOTH_STAIRS:2,null,15,SMOOTH_STAIRS:3,null,15,STEP:5,null,15,STEP:13,null,15,COBBLE_WALL:0,null,10,COBBLESTONE_STAIRS:0,null,10,STEP:3,null,10,COBBLE_WALL:1,null,20,COBBLESTONE_STAIRS:2,null,20,COBBLESTONE_STAIRS:3,null,20,MOSSY_COBBLESTONE:0,null,60,COBBLESTONE_STAIRS:1,null,20,STEP:11,null,20,COBBLESTONE:0,null,100)
RandomBlock(-7,5,-4,contenttweaker:reinforced_concrete:0,null,40,SMOOTH_BRICK:1,null,30,SMOOTH_BRICK:2,null,30,SMOOTH_STAIRS:0,null,15,SMOOTH_STAIRS:1,null,15,SMOOTH_STAIRS:2,null,15,SMOOTH_STAIRS:3,null,15,STEP:5,null,15,STEP:13,null,15,COBBLE_WALL:0,null,10,COBBLESTONE_STAIRS:0,null,10,STEP:3,null,10,COBBLE_WALL:1,null,20,COBBLESTONE_STAIRS:2,null,20,COBBLESTONE_STAIRS:3,null,20,MOSSY_COBBLESTONE:0,null,60,COBBLESTONE_STAIRS:1,null,20,STEP:11,null,20,COBBLESTONE:0,null,100)
RandomBlock(-7,5,-3,contenttweaker:reinforced_concrete:0,null,30,quark:limestone_wall:0,null,10,contenttweaker:reinforced_concrete:0,null,100)
RandomBlock(-7,6,-7,contenttweaker:reinforced_concrete:0,null,40,SMOOTH_BRICK:1,null,30,SMOOTH_BRICK:2,null,30,SMOOTH_STAIRS:0,null,15,SMOOTH_STAIRS:1,null,15,SMOOTH_STAIRS:2,null,15,SMOOTH_STAIRS:3,null,15,STEP:5,null,15,STEP:13,null,15,COBBLE_WALL:0,null,10,COBBLESTONE_STAIRS:0,null,10,STEP:3,null,10,COBBLE_WALL:1,null,20,COBBLESTONE_STAIRS:2,null,20,COBBLESTONE_STAIRS:3,null,20,MOSSY_COBBLESTONE:0,null,60,COBBLESTONE_STAIRS:1,null,20,STEP:11,null,20,COBBLESTONE:0,null,100)
RandomBlock(-7,6,-6,contenttweaker:reinforced_concrete:0,null,40,SMOOTH_BRICK:1,null,30,SMOOTH_BRICK:2,null,30,SMOOTH_STAIRS:0,null,15,SMOOTH_STAIRS:1,null,15,SMOOTH_STAIRS:2,null,15,SMOOTH_STAIRS:3,null,15,STEP:5,null,15,STEP:13,null,15,COBBLE_WALL:0,null,10,COBBLESTONE_STAIRS:0,null,10,STEP:3,null,10,COBBLE_WALL:1,null,20,COBBLESTONE_STAIRS:2,null,20,COBBLESTONE_STAIRS:3,null,20,MOSSY_COBBLESTONE:0,null,60,COBBLESTONE_STAIRS:1,null,20,STEP:11,null,20,COBBLESTONE:0,null,100)
RandomBlock(-7,6,-5,contenttweaker:reinforced_concrete:0,null,40,SMOOTH_BRICK:1,null,30,SMOOTH_BRICK:2,null,30,SMOOTH_STAIRS:0,null,15,SMOOTH_STAIRS:1,null,15,SMOOTH_STAIRS:2,null,15,SMOOTH_STAIRS:3,null,15,STEP:5,null,15,STEP:13,null,15,COBBLE_WALL:0,null,10,COBBLESTONE_STAIRS:0,null,10,STEP:3,null,10,COBBLE_WALL:1,null,20,COBBLESTONE_STAIRS:2,null,20,COBBLESTONE_STAIRS:3,null,20,MOSSY_COBBLESTONE:0,null,60,COBBLESTONE_STAIRS:1,null,20,STEP:11,null,20,COBBLESTONE:0,null,100)
RandomBlock(-7,6,-4,contenttweaker:reinforced_concrete:0,null,40,SMOOTH_BRICK:1,null,30,SMOOTH_BRICK:2,null,30,SMOOTH_STAIRS:0,null,15,SMOOTH_STAIRS:1,null,15,SMOOTH_STAIRS:2,null,15,SMOOTH_STAIRS:3,null,15,STEP:5,null,15,STEP:13,null,15,COBBLE_WALL:0,null,10,COBBLESTONE_STAIRS:0,null,10,STEP:3,null,10,COBBLE_WALL:1,null,20,COBBLESTONE_STAIRS:2,null,20,COBBLESTONE_STAIRS:3,null,20,MOSSY_COBBLESTONE:0,null,60,COBBLESTONE_STAIRS:1,null,20,STEP:11,null,20,COBBLESTONE:0,null,100)
RandomBlock(-7,6,-3,contenttweaker:reinforced_concrete:0,null,30,quark:limestone_wall:0,null,10,contenttweaker:reinforced_concrete:0,null,100)
RandomBlock(-7,7,-7,contenttweaker:reinforced_concrete:0,null,40,SMOOTH_BRICK:1,null,30,SMOOTH_BRICK:2,null,30,SMOOTH_STAIRS:0,null,15,SMOOTH_STAIRS:1,null,15,SMOOTH_STAIRS:2,null,15,SMOOTH_STAIRS:3,null,15,STEP:5,null,15,STEP:13,null,15,COBBLE_WALL:0,null,10,COBBLESTONE_STAIRS:0,null,10,STEP:3,null,10,COBBLE_WALL:1,null,20,COBBLESTONE_STAIRS:2,null,20,COBBLESTONE_STAIRS:3,null,20,MOSSY_COBBLESTONE:0,null,60,COBBLESTONE_STAIRS:1,null,20,STEP:11,null,20,COBBLESTONE:0,null,100)
RandomBlock(-7,7,-6,contenttweaker:reinforced_concrete:0,null,40,SMOOTH_BRICK:1,null,30,SMOOTH_BRICK:2,null,30,SMOOTH_STAIRS:0,null,15,SMOOTH_STAIRS:1,null,15,SMOOTH_STAIRS:2,null,15,SMOOTH_STAIRS:3,null,15,STEP:5,null,15,STEP:13,null,15,COBBLE_WALL:0,null,10,COBBLESTONE_STAIRS:0,null,10,STEP:3,null,10,COBBLE_WALL:1,null,20,COBBLESTONE_STAIRS:2,null,20,COBBLESTONE_STAIRS:3,null,20,MOSSY_COBBLESTONE:0,null,60,COBBLESTONE_STAIRS:1,null,20,STEP:11,null,20,COBBLESTONE:0,null,100)
RandomBlock(-7,7,-5,contenttweaker:reinforced_concrete:0,null,40,SMOOTH_BRICK:1,null,30,SMOOTH_BRICK:2,null,30,SMOOTH_STAIRS:0,null,15,SMOOTH_STAIRS:1,null,15,SMOOTH_STAIRS:2,null,15,SMOOTH_STAIRS:3,null,15,STEP:5,null,15,STEP:13,null,15,COBBLE_WALL:0,null,10,COBBLESTONE_STAIRS:0,null,10,STEP:3,null,10,COBBLE_WALL:1,null,20,COBBLESTONE_STAIRS:2,null,20,COBBLESTONE_STAIRS:3,null,20,MOSSY_COBBLESTONE:0,null,60,COBBLESTONE_STAIRS:1,null,20,STEP:11,null,20,COBBLESTONE:0,null,100)
RandomBlock(-7,7,-4,contenttweaker:reinforced_concrete:0,null,40,SMOOTH_BRICK:1,null,30,SMOOTH_BRICK:2,null,30,SMOOTH_STAIRS:0,null,15,SMOOTH_STAIRS:1,null,15,SMOOTH_STAIRS:2,null,15,SMOOTH_STAIRS:3,null,15,STEP:5,null,15,STEP:13,null,15,COBBLE_WALL:0,null,10,COBBLESTONE_STAIRS:0,null,10,STEP:3,null,10,COBBLE_WALL:1,null,20,COBBLESTONE_STAIRS:2,null,20,COBBLESTONE_STAIRS:3,null,20,MOSSY_COBBLESTONE:0,null,60,COBBLESTONE_STAIRS:1,null,20,STEP:11,null,20,COBBLESTONE:0,null,100)
RandomBlock(-7,7,-3,contenttweaker:reinforced_concrete:0,null,30,quark:limestone_wall:0,null,10,contenttweaker:reinforced_concrete:0,null,100)
RandomBlock(-7,8,-7,contenttweaker:reinforced_concrete:0,null,30,quark:limestone_wall:0,null,10,contenttweaker:reinforced_concrete:0,null,100)
RandomBlock(-7,8,-6,contenttweaker:reinforced_concrete:0,null,30,quark:limestone_wall:0,null,10,contenttweaker:reinforced_concrete:0,null,100)
RandomBlock(-7,8,-5,contenttweaker:reinforced_concrete:0,null,30,quark:limestone_wall:0,null,10,contenttweaker:reinforced_concrete:0,null,100)
RandomBlock(-7,8,-4,rustic:iron_lattice:0,null,30,rustic:iron_lattice:1,null,100)
Block(-7,9,-5,VINE:1)
RandomBlock(-7,9,-4,rustic:iron_lattice:0,null,30,rustic:iron_lattice:1,null,100)
Block(-7,10,-5,VINE:1)
RandomBlock(-7,10,-4,rustic:iron_lattice:0,null,30,rustic:iron_lattice:1,null,100)
RandomBlock(-7,10,-3,contenttweaker:reinforced_concrete:0,null,30,quark:limestone_wall:0,null,10,contenttweaker:reinforced_concrete:0,null,100)
Block(-7,11,-5,VINE:1)
RandomBlock(-7,11,-3,contenttweaker:reinforced_concrete:0,null,30,quark:limestone_wall:0,null,10,contenttweaker:reinforced_concrete:0,null,100)
Block(-7,12,-5,VINE:1)
RandomBlock(-7,12,-4,contenttweaker:reinforced_concrete:0,null,30,quark:limestone_wall:0,null,10,contenttweaker:reinforced_concrete:0,null,100)
RandomBlock(-7,13,-4,contenttweaker:reinforced_concrete:0,null,30,quark:limestone_wall:0,null,10,contenttweaker:reinforced_concrete:0,null,100)
RandomBlock(-6,0,-7,contenttweaker:reinforced_concrete:0,null,40,SMOOTH_BRICK:1,null,30,SMOOTH_BRICK:2,null,30,SMOOTH_STAIRS:0,null,15,SMOOTH_STAIRS:1,null,15,SMOOTH_STAIRS:2,null,15,SMOOTH_STAIRS:3,null,15,STEP:5,null,15,STEP:13,null,15,COBBLE_WALL:0,null,10,COBBLESTONE_STAIRS:0,null,10,STEP:3,null,10,COBBLE_WALL:1,null,20,COBBLESTONE_STAIRS:2,null,20,COBBLESTONE_STAIRS:3,null,20,MOSSY_COBBLESTONE:0,null,60,COBBLESTONE_STAIRS:1,null,20,STEP:11,null,20,COBBLESTONE:0,null,100)
RandomBlock(-6,0,-6,contenttweaker:reinforced_concrete:0,null,40,SMOOTH_BRICK:1,null,30,SMOOTH_BRICK:2,null,30,SMOOTH_STAIRS:0,null,15,SMOOTH_STAIRS:1,null,15,SMOOTH_STAIRS:2,null,15,SMOOTH_STAIRS:3,null,15,STEP:5,null,15,STEP:13,null,15,COBBLE_WALL:0,null,10,COBBLESTONE_STAIRS:0,null,10,STEP:3,null,10,COBBLE_WALL:1,null,20,COBBLESTONE_STAIRS:2,null,20,COBBLESTONE_STAIRS:3,null,20,MOSSY_COBBLESTONE:0,null,60,COBBLESTONE_STAIRS:1,null,20,STEP:11,null,20,COBBLESTONE:0,null,100)
RandomBlock(-6,0,-5,contenttweaker:reinforced_concrete:0,null,40,SMOOTH_BRICK:1,null,30,SMOOTH_BRICK:2,null,30,SMOOTH_STAIRS:0,null,15,SMOOTH_STAIRS:1,null,15,SMOOTH_STAIRS:2,null,15,SMOOTH_STAIRS:3,null,15,STEP:5,null,15,STEP:13,null,15,COBBLE_WALL:0,null,10,COBBLESTONE_STAIRS:0,null,10,STEP:3,null,10,COBBLE_WALL:1,null,20,COBBLESTONE_STAIRS:2,null,20,COBBLESTONE_STAIRS:3,null,20,MOSSY_COBBLESTONE:0,null,60,COBBLESTONE_STAIRS:1,null,20,STEP:11,null,20,COBBLESTONE:0,null,100)
RandomBlock(-6,0,-4,contenttweaker:reinforced_concrete:0,null,40,SMOOTH_BRICK:1,null,30,SMOOTH_BRICK:2,null,30,SMOOTH_STAIRS:0,null,15,SMOOTH_STAIRS:1,null,15,SMOOTH_STAIRS:2,null,15,SMOOTH_STAIRS:3,null,15,STEP:5,null,15,STEP:13,null,15,COBBLE_WALL:0,null,10,COBBLESTONE_STAIRS:0,null,10,STEP:3,null,10,COBBLE_WALL:1,null,20,COBBLESTONE_STAIRS:2,null,20,COBBLESTONE_STAIRS:3,null,20,MOSSY_COBBLESTONE:0,null,60,COBBLESTONE_STAIRS:1,null,20,STEP:11,null,20,COBBLESTONE:0,null,100)
RandomBlock(-6,0,-3,contenttweaker:reinforced_concrete:0,null,40,SMOOTH_BRICK:1,null,30,SMOOTH_BRICK:2,null,30,SMOOTH_STAIRS:0,null,15,SMOOTH_STAIRS:1,null,15,SMOOTH_STAIRS:2,null,15,SMOOTH_STAIRS:3,null,15,STEP:5,null,15,STEP:13,null,15,COBBLE_WALL:0,null,10,COBBLESTONE_STAIRS:0,null,10,STEP:3,null,10,COBBLE_WALL:1,null,20,COBBLESTONE_STAIRS:2,null,20,COBBLESTONE_STAIRS:3,null,20,MOSSY_COBBLESTONE:0,null,60,COBBLESTONE_STAIRS:1,null,20,STEP:11,null,20,COBBLESTONE:0,null,100)
RandomBlock(-6,1,-7,contenttweaker:reinforced_concrete:0,null,40,SMOOTH_BRICK:1,null,30,SMOOTH_BRICK:2,null,30,SMOOTH_STAIRS:0,null,15,SMOOTH_STAIRS:1,null,15,SMOOTH_STAIRS:2,null,15,SMOOTH_STAIRS:3,null,15,STEP:5,null,15,STEP:13,null,15,COBBLE_WALL:0,null,10,COBBLESTONE_STAIRS:0,null,10,STEP:3,null,10,COBBLE_WALL:1,null,20,COBBLESTONE_STAIRS:2,null,20,COBBLESTONE_STAIRS:3,null,20,MOSSY_COBBLESTONE:0,null,60,COBBLESTONE_STAIRS:1,null,20,STEP:11,null,20,COBBLESTONE:0,null,100)
RandomBlock(-6,1,-6,contenttweaker:reinforced_concrete:0,null,40,SMOOTH_BRICK:1,null,30,SMOOTH_BRICK:2,null,30,SMOOTH_STAIRS:0,null,15,SMOOTH_STAIRS:1,null,15,SMOOTH_STAIRS:2,null,15,SMOOTH_STAIRS:3,null,15,STEP:5,null,15,STEP:13,null,15,COBBLE_WALL:0,null,10,COBBLESTONE_STAIRS:0,null,10,STEP:3,null,10,COBBLE_WALL:1,null,20,COBBLESTONE_STAIRS:2,null,20,COBBLESTONE_STAIRS:3,null,20,MOSSY_COBBLESTONE:0,null,60,COBBLESTONE_STAIRS:1,null,20,STEP:11,null,20,COBBLESTONE:0,null,100)
RandomBlock(-6,1,-5,contenttweaker:reinforced_concrete:0,null,40,SMOOTH_BRICK:1,null,30,SMOOTH_BRICK:2,null,30,SMOOTH_STAIRS:0,null,15,SMOOTH_STAIRS:1,null,15,SMOOTH_STAIRS:2,null,15,SMOOTH_STAIRS:3,null,15,STEP:5,null,15,STEP:13,null,15,COBBLE_WALL:0,null,10,COBBLESTONE_STAIRS:0,null,10,STEP:3,null,10,COBBLE_WALL:1,null,20,COBBLESTONE_STAIRS:2,null,20,COBBLESTONE_STAIRS:3,null,20,MOSSY_COBBLESTONE:0,null,60,COBBLESTONE_STAIRS:1,null,20,STEP:11,null,20,COBBLESTONE:0,null,100)
RandomBlock(-6,1,-4,contenttweaker:reinforced_concrete:0,null,40,SMOOTH_BRICK:1,null,30,SMOOTH_BRICK:2,null,30,SMOOTH_STAIRS:0,null,15,SMOOTH_STAIRS:1,null,15,SMOOTH_STAIRS:2,null,15,SMOOTH_STAIRS:3,null,15,STEP:5,null,15,STEP:13,null,15,COBBLE_WALL:0,null,10,COBBLESTONE_STAIRS:0,null,10,STEP:3,null,10,COBBLE_WALL:1,null,20,COBBLESTONE_STAIRS:2,null,20,COBBLESTONE_STAIRS:3,null,20,MOSSY_COBBLESTONE:0,null,60,COBBLESTONE_STAIRS:1,null,20,STEP:11,null,20,COBBLESTONE:0,null,100)
RandomBlock(-6,1,-3,contenttweaker:reinforced_concrete:0,null,40,SMOOTH_BRICK:1,null,30,SMOOTH_BRICK:2,null,30,SMOOTH_STAIRS:0,null,15,SMOOTH_STAIRS:1,null,15,SMOOTH_STAIRS:2,null,15,SMOOTH_STAIRS:3,null,15,STEP:5,null,15,STEP:13,null,15,COBBLE_WALL:0,null,10,COBBLESTONE_STAIRS:0,null,10,STEP:3,null,10,COBBLE_WALL:1,null,20,COBBLESTONE_STAIRS:2,null,20,COBBLESTONE_STAIRS:3,null,20,MOSSY_COBBLESTONE:0,null,60,COBBLESTONE_STAIRS:1,null,20,STEP:11,null,20,COBBLESTONE:0,null,100)
RandomBlock(-6,2,-7,contenttweaker:reinforced_concrete:0,null,40,SMOOTH_BRICK:1,null,30,SMOOTH_BRICK:2,null,30,SMOOTH_STAIRS:0,null,15,SMOOTH_STAIRS:1,null,15,SMOOTH_STAIRS:2,null,15,SMOOTH_STAIRS:3,null,15,STEP:5,null,15,STEP:13,null,15,COBBLE_WALL:0,null,10,COBBLESTONE_STAIRS:0,null,10,STEP:3,null,10,COBBLE_WALL:1,null,20,COBBLESTONE_STAIRS:2,null,20,COBBLESTONE_STAIRS:3,null,20,MOSSY_COBBLESTONE:0,null,60,COBBLESTONE_STAIRS:1,null,20,STEP:11,null,20,COBBLESTONE:0,null,100)
RandomBlock(-6,2,-6,contenttweaker:reinforced_concrete:0,null,40,SMOOTH_BRICK:1,null,30,SMOOTH_BRICK:2,null,30,SMOOTH_STAIRS:0,null,15,SMOOTH_STAIRS:1,null,15,SMOOTH_STAIRS:2,null,15,SMOOTH_STAIRS:3,null,15,STEP:5,null,15,STEP:13,null,15,COBBLE_WALL:0,null,10,COBBLESTONE_STAIRS:0,null,10,STEP:3,null,10,COBBLE_WALL:1,null,20,COBBLESTONE_STAIRS:2,null,20,COBBLESTONE_STAIRS:3,null,20,MOSSY_COBBLESTONE:0,null,60,COBBLESTONE_STAIRS:1,null,20,STEP:11,null,20,COBBLESTONE:0,null,100)
RandomBlock(-6,2,-5,contenttweaker:reinforced_concrete:0,null,40,SMOOTH_BRICK:1,null,30,SMOOTH_BRICK:2,null,30,SMOOTH_STAIRS:0,null,15,SMOOTH_STAIRS:1,null,15,SMOOTH_STAIRS:2,null,15,SMOOTH_STAIRS:3,null,15,STEP:5,null,15,STEP:13,null,15,COBBLE_WALL:0,null,10,COBBLESTONE_STAIRS:0,null,10,STEP:3,null,10,COBBLE_WALL:1,null,20,COBBLESTONE_STAIRS:2,null,20,COBBLESTONE_STAIRS:3,null,20,MOSSY_COBBLESTONE:0,null,60,COBBLESTONE_STAIRS:1,null,20,STEP:11,null,20,COBBLESTONE:0,null,100)
RandomBlock(-6,2,-4,contenttweaker:reinforced_concrete:0,null,40,SMOOTH_BRICK:1,null,30,SMOOTH_BRICK:2,null,30,SMOOTH_STAIRS:0,null,15,SMOOTH_STAIRS:1,null,15,SMOOTH_STAIRS:2,null,15,SMOOTH_STAIRS:3,null,15,STEP:5,null,15,STEP:13,null,15,COBBLE_WALL:0,null,10,COBBLESTONE_STAIRS:0,null,10,STEP:3,null,10,COBBLE_WALL:1,null,20,COBBLESTONE_STAIRS:2,null,20,COBBLESTONE_STAIRS:3,null,20,MOSSY_COBBLESTONE:0,null,60,COBBLESTONE_STAIRS:1,null,20,STEP:11,null,20,COBBLESTONE:0,null,100)
RandomBlock(-6,2,-3,contenttweaker:reinforced_concrete:0,null,40,SMOOTH_BRICK:1,null,30,SMOOTH_BRICK:2,null,30,SMOOTH_STAIRS:0,null,15,SMOOTH_STAIRS:1,null,15,SMOOTH_STAIRS:2,null,15,SMOOTH_STAIRS:3,null,15,STEP:5,null,15,STEP:13,null,15,COBBLE_WALL:0,null,10,COBBLESTONE_STAIRS:0,null,10,STEP:3,null,10,COBBLE_WALL:1,null,20,COBBLESTONE_STAIRS:2,null,20,COBBLESTONE_STAIRS:3,null,20,MOSSY_COBBLESTONE:0,null,60,COBBLESTONE_STAIRS:1,null,20,STEP:11,null,20,COBBLESTONE:0,null,100)
RandomBlock(-6,3,-7,contenttweaker:reinforced_concrete:0,null,40,SMOOTH_BRICK:1,null,30,SMOOTH_BRICK:2,null,30,SMOOTH_STAIRS:0,null,15,SMOOTH_STAIRS:1,null,15,SMOOTH_STAIRS:2,null,15,SMOOTH_STAIRS:3,null,15,STEP:5,null,15,STEP:13,null,15,COBBLE_WALL:0,null,10,COBBLESTONE_STAIRS:0,null,10,STEP:3,null,10,COBBLE_WALL:1,null,20,COBBLESTONE_STAIRS:2,null,20,COBBLESTONE_STAIRS:3,null,20,MOSSY_COBBLESTONE:0,null,60,COBBLESTONE_STAIRS:1,null,20,STEP:11,null,20,COBBLESTONE:0,null,100)
RandomBlock(-6,3,-6,contenttweaker:reinforced_concrete:0,null,40,SMOOTH_BRICK:1,null,30,SMOOTH_BRICK:2,null,30,SMOOTH_STAIRS:0,null,15,SMOOTH_STAIRS:1,null,15,SMOOTH_STAIRS:2,null,15,SMOOTH_STAIRS:3,null,15,STEP:5,null,15,STEP:13,null,15,COBBLE_WALL:0,null,10,COBBLESTONE_STAIRS:0,null,10,STEP:3,null,10,COBBLE_WALL:1,null,20,COBBLESTONE_STAIRS:2,null,20,COBBLESTONE_STAIRS:3,null,20,MOSSY_COBBLESTONE:0,null,60,COBBLESTONE_STAIRS:1,null,20,STEP:11,null,20,COBBLESTONE:0,null,100)
RandomBlock(-6,3,-5,contenttweaker:reinforced_concrete:0,null,40,SMOOTH_BRICK:1,null,30,SMOOTH_BRICK:2,null,30,SMOOTH_STAIRS:0,null,15,SMOOTH_STAIRS:1,null,15,SMOOTH_STAIRS:2,null,15,SMOOTH_STAIRS:3,null,15,STEP:5,null,15,STEP:13,null,15,COBBLE_WALL:0,null,10,COBBLESTONE_STAIRS:0,null,10,STEP:3,null,10,COBBLE_WALL:1,null,20,COBBLESTONE_STAIRS:2,null,20,COBBLESTONE_STAIRS:3,null,20,MOSSY_COBBLESTONE:0,null,60,COBBLESTONE_STAIRS:1,null,20,STEP:11,null,20,COBBLESTONE:0,null,100)
RandomBlock(-6,3,-4,contenttweaker:reinforced_concrete:0,null,40,SMOOTH_BRICK:1,null,30,SMOOTH_BRICK:2,null,30,SMOOTH_STAIRS:0,null,15,SMOOTH_STAIRS:1,null,15,SMOOTH_STAIRS:2,null,15,SMOOTH_STAIRS:3,null,15,STEP:5,null,15,STEP:13,null,15,COBBLE_WALL:0,null,10,COBBLESTONE_STAIRS:0,null,10,STEP:3,null,10,COBBLE_WALL:1,null,20,COBBLESTONE_STAIRS:2,null,20,COBBLESTONE_STAIRS:3,null,20,MOSSY_COBBLESTONE:0,null,60,COBBLESTONE_STAIRS:1,null,20,STEP:11,null,20,COBBLESTONE:0,null,100)
RandomBlock(-6,3,-3,contenttweaker:reinforced_concrete:0,null,40,SMOOTH_BRICK:1,null,30,SMOOTH_BRICK:2,null,30,SMOOTH_STAIRS:0,null,15,SMOOTH_STAIRS:1,null,15,SMOOTH_STAIRS:2,null,15,SMOOTH_STAIRS:3,null,15,STEP:5,null,15,STEP:13,null,15,COBBLE_WALL:0,null,10,COBBLESTONE_STAIRS:0,null,10,STEP:3,null,10,COBBLE_WALL:1,null,20,COBBLESTONE_STAIRS:2,null,20,COBBLESTONE_STAIRS:3,null,20,MOSSY_COBBLESTONE:0,null,60,COBBLESTONE_STAIRS:1,null,20,STEP:11,null,20,COBBLESTONE:0,null,100)
RandomBlock(-6,4,-7,contenttweaker:reinforced_concrete:0,null,40,SMOOTH_BRICK:1,null,30,SMOOTH_BRICK:2,null,30,SMOOTH_STAIRS:0,null,15,SMOOTH_STAIRS:1,null,15,SMOOTH_STAIRS:2,null,15,SMOOTH_STAIRS:3,null,15,STEP:5,null,15,STEP:13,null,15,COBBLE_WALL:0,null,10,COBBLESTONE_STAIRS:0,null,10,STEP:3,null,10,COBBLE_WALL:1,null,20,COBBLESTONE_STAIRS:2,null,20,COBBLESTONE_STAIRS:3,null,20,MOSSY_COBBLESTONE:0,null,60,COBBLESTONE_STAIRS:1,null,20,STEP:11,null,20,COBBLESTONE:0,null,100)
RandomBlock(-6,4,-6,contenttweaker:reinforced_concrete:0,null,40,SMOOTH_BRICK:1,null,30,SMOOTH_BRICK:2,null,30,SMOOTH_STAIRS:0,null,15,SMOOTH_STAIRS:1,null,15,SMOOTH_STAIRS:2,null,15,SMOOTH_STAIRS:3,null,15,STEP:5,null,15,STEP:13,null,15,COBBLE_WALL:0,null,10,COBBLESTONE_STAIRS:0,null,10,STEP:3,null,10,COBBLE_WALL:1,null,20,COBBLESTONE_STAIRS:2,null,20,COBBLESTONE_STAIRS:3,null,20,MOSSY_COBBLESTONE:0,null,60,COBBLESTONE_STAIRS:1,null,20,STEP:11,null,20,COBBLESTONE:0,null,100)
RandomBlock(-6,4,-5,contenttweaker:reinforced_concrete:0,null,40,SMOOTH_BRICK:1,null,30,SMOOTH_BRICK:2,null,30,SMOOTH_STAIRS:0,null,15,SMOOTH_STAIRS:1,null,15,SMOOTH_STAIRS:2,null,15,SMOOTH_STAIRS:3,null,15,STEP:5,null,15,STEP:13,null,15,COBBLE_WALL:0,null,10,COBBLESTONE_STAIRS:0,null,10,STEP:3,null,10,COBBLE_WALL:1,null,20,COBBLESTONE_STAIRS:2,null,20,COBBLESTONE_STAIRS:3,null,20,MOSSY_COBBLESTONE:0,null,60,COBBLESTONE_STAIRS:1,null,20,STEP:11,null,20,COBBLESTONE:0,null,100)
RandomBlock(-6,4,-4,contenttweaker:reinforced_concrete:0,null,40,SMOOTH_BRICK:1,null,30,SMOOTH_BRICK:2,null,30,SMOOTH_STAIRS:0,null,15,SMOOTH_STAIRS:1,null,15,SMOOTH_STAIRS:2,null,15,SMOOTH_STAIRS:3,null,15,STEP:5,null,15,STEP:13,null,15,COBBLE_WALL:0,null,10,COBBLESTONE_STAIRS:0,null,10,STEP:3,null,10,COBBLE_WALL:1,null,20,COBBLESTONE_STAIRS:2,null,20,COBBLESTONE_STAIRS:3,null,20,MOSSY_COBBLESTONE:0,null,60,COBBLESTONE_STAIRS:1,null,20,STEP:11,null,20,COBBLESTONE:0,null,100)
RandomBlock(-6,4,-3,contenttweaker:reinforced_concrete:0,null,40,SMOOTH_BRICK:1,null,30,SMOOTH_BRICK:2,null,30,SMOOTH_STAIRS:0,null,15,SMOOTH_STAIRS:1,null,15,SMOOTH_STAIRS:2,null,15,SMOOTH_STAIRS:3,null,15,STEP:5,null,15,STEP:13,null,15,COBBLE_WALL:0,null,10,COBBLESTONE_STAIRS:0,null,10,STEP:3,null,10,COBBLE_WALL:1,null,20,COBBLESTONE_STAIRS:2,null,20,COBBLESTONE_STAIRS:3,null,20,MOSSY_COBBLESTONE:0,null,60,COBBLESTONE_STAIRS:1,null,20,STEP:11,null,20,COBBLESTONE:0,null,100)
RandomBlock(-6,5,-7,contenttweaker:reinforced_concrete:0,null,40,SMOOTH_BRICK:1,null,30,SMOOTH_BRICK:2,null,30,SMOOTH_STAIRS:0,null,15,SMOOTH_STAIRS:1,null,15,SMOOTH_STAIRS:2,null,15,SMOOTH_STAIRS:3,null,15,STEP:5,null,15,STEP:13,null,15,COBBLE_WALL:0,null,10,COBBLESTONE_STAIRS:0,null,10,STEP:3,null,10,COBBLE_WALL:1,null,20,COBBLESTONE_STAIRS:2,null,20,COBBLESTONE_STAIRS:3,null,20,MOSSY_COBBLESTONE:0,null,60,COBBLESTONE_STAIRS:1,null,20,STEP:11,null,20,COBBLESTONE:0,null,100)
RandomBlock(-6,5,-6,contenttweaker:reinforced_concrete:0,null,40,SMOOTH_BRICK:1,null,30,SMOOTH_BRICK:2,null,30,SMOOTH_STAIRS:0,null,15,SMOOTH_STAIRS:1,null,15,SMOOTH_STAIRS:2,null,15,SMOOTH_STAIRS:3,null,15,STEP:5,null,15,STEP:13,null,15,COBBLE_WALL:0,null,10,COBBLESTONE_STAIRS:0,null,10,STEP:3,null,10,COBBLE_WALL:1,null,20,COBBLESTONE_STAIRS:2,null,20,COBBLESTONE_STAIRS:3,null,20,MOSSY_COBBLESTONE:0,null,60,COBBLESTONE_STAIRS:1,null,20,STEP:11,null,20,COBBLESTONE:0,null,100)
RandomBlock(-6,5,-5,contenttweaker:reinforced_concrete:0,null,40,SMOOTH_BRICK:1,null,30,SMOOTH_BRICK:2,null,30,SMOOTH_STAIRS:0,null,15,SMOOTH_STAIRS:1,null,15,SMOOTH_STAIRS:2,null,15,SMOOTH_STAIRS:3,null,15,STEP:5,null,15,STEP:13,null,15,COBBLE_WALL:0,null,10,COBBLESTONE_STAIRS:0,null,10,STEP:3,null,10,COBBLE_WALL:1,null,20,COBBLESTONE_STAIRS:2,null,20,COBBLESTONE_STAIRS:3,null,20,MOSSY_COBBLESTONE:0,null,60,COBBLESTONE_STAIRS:1,null,20,STEP:11,null,20,COBBLESTONE:0,null,100)
RandomBlock(-6,5,-4,contenttweaker:reinforced_concrete:0,null,40,SMOOTH_BRICK:1,null,30,SMOOTH_BRICK:2,null,30,SMOOTH_STAIRS:0,null,15,SMOOTH_STAIRS:1,null,15,SMOOTH_STAIRS:2,null,15,SMOOTH_STAIRS:3,null,15,STEP:5,null,15,STEP:13,null,15,COBBLE_WALL:0,null,10,COBBLESTONE_STAIRS:0,null,10,STEP:3,null,10,COBBLE_WALL:1,null,20,COBBLESTONE_STAIRS:2,null,20,COBBLESTONE_STAIRS:3,null,20,MOSSY_COBBLESTONE:0,null,60,COBBLESTONE_STAIRS:1,null,20,STEP:11,null,20,COBBLESTONE:0,null,100)
RandomBlock(-6,5,-3,contenttweaker:reinforced_concrete:0,null,30,quark:limestone_wall:0,null,10,contenttweaker:reinforced_concrete:0,null,100)
RandomBlock(-6,6,-7,contenttweaker:reinforced_concrete:0,null,40,SMOOTH_BRICK:1,null,30,SMOOTH_BRICK:2,null,30,SMOOTH_STAIRS:0,null,15,SMOOTH_STAIRS:1,null,15,SMOOTH_STAIRS:2,null,15,SMOOTH_STAIRS:3,null,15,STEP:5,null,15,STEP:13,null,15,COBBLE_WALL:0,null,10,COBBLESTONE_STAIRS:0,null,10,STEP:3,null,10,COBBLE_WALL:1,null,20,COBBLESTONE_STAIRS:2,null,20,COBBLESTONE_STAIRS:3,null,20,MOSSY_COBBLESTONE:0,null,60,COBBLESTONE_STAIRS:1,null,20,STEP:11,null,20,COBBLESTONE:0,null,100)
RandomBlock(-6,6,-6,contenttweaker:reinforced_concrete:0,null,40,SMOOTH_BRICK:1,null,30,SMOOTH_BRICK:2,null,30,SMOOTH_STAIRS:0,null,15,SMOOTH_STAIRS:1,null,15,SMOOTH_STAIRS:2,null,15,SMOOTH_STAIRS:3,null,15,STEP:5,null,15,STEP:13,null,15,COBBLE_WALL:0,null,10,COBBLESTONE_STAIRS:0,null,10,STEP:3,null,10,COBBLE_WALL:1,null,20,COBBLESTONE_STAIRS:2,null,20,COBBLESTONE_STAIRS:3,null,20,MOSSY_COBBLESTONE:0,null,60,COBBLESTONE_STAIRS:1,null,20,STEP:11,null,20,COBBLESTONE:0,null,100)
RandomBlock(-6,6,-5,contenttweaker:reinforced_concrete:0,null,40,SMOOTH_BRICK:1,null,30,SMOOTH_BRICK:2,null,30,SMOOTH_STAIRS:0,null,15,SMOOTH_STAIRS:1,null,15,SMOOTH_STAIRS:2,null,15,SMOOTH_STAIRS:3,null,15,STEP:5,null,15,STEP:13,null,15,COBBLE_WALL:0,null,10,COBBLESTONE_STAIRS:0,null,10,STEP:3,null,10,COBBLE_WALL:1,null,20,COBBLESTONE_STAIRS:2,null,20,COBBLESTONE_STAIRS:3,null,20,MOSSY_COBBLESTONE:0,null,60,COBBLESTONE_STAIRS:1,null,20,STEP:11,null,20,COBBLESTONE:0,null,100)
RandomBlock(-6,6,-4,contenttweaker:reinforced_concrete:0,null,40,SMOOTH_BRICK:1,null,30,SMOOTH_BRICK:2,null,30,SMOOTH_STAIRS:0,null,15,SMOOTH_STAIRS:1,null,15,SMOOTH_STAIRS:2,null,15,SMOOTH_STAIRS:3,null,15,STEP:5,null,15,STEP:13,null,15,COBBLE_WALL:0,null,10,COBBLESTONE_STAIRS:0,null,10,STEP:3,null,10,COBBLE_WALL:1,null,20,COBBLESTONE_STAIRS:2,null,20,COBBLESTONE_STAIRS:3,null,20,MOSSY_COBBLESTONE:0,null,60,COBBLESTONE_STAIRS:1,null,20,STEP:11,null,20,COBBLESTONE:0,null,100)
RandomBlock(-6,6,-3,contenttweaker:reinforced_concrete:0,null,30,quark:limestone_wall:0,null,10,contenttweaker:reinforced_concrete:0,null,100)
RandomBlock(-6,7,-7,contenttweaker:reinforced_concrete:0,null,40,SMOOTH_BRICK:1,null,30,SMOOTH_BRICK:2,null,30,SMOOTH_STAIRS:0,null,15,SMOOTH_STAIRS:1,null,15,SMOOTH_STAIRS:2,null,15,SMOOTH_STAIRS:3,null,15,STEP:5,null,15,STEP:13,null,15,COBBLE_WALL:0,null,10,COBBLESTONE_STAIRS:0,null,10,STEP:3,null,10,COBBLE_WALL:1,null,20,COBBLESTONE_STAIRS:2,null,20,COBBLESTONE_STAIRS:3,null,20,MOSSY_COBBLESTONE:0,null,60,COBBLESTONE_STAIRS:1,null,20,STEP:11,null,20,COBBLESTONE:0,null,100)
RandomBlock(-6,7,-6,contenttweaker:reinforced_concrete:0,null,40,SMOOTH_BRICK:1,null,30,SMOOTH_BRICK:2,null,30,SMOOTH_STAIRS:0,null,15,SMOOTH_STAIRS:1,null,15,SMOOTH_STAIRS:2,null,15,SMOOTH_STAIRS:3,null,15,STEP:5,null,15,STEP:13,null,15,COBBLE_WALL:0,null,10,COBBLESTONE_STAIRS:0,null,10,STEP:3,null,10,COBBLE_WALL:1,null,20,COBBLESTONE_STAIRS:2,null,20,COBBLESTONE_STAIRS:3,null,20,MOSSY_COBBLESTONE:0,null,60,COBBLESTONE_STAIRS:1,null,20,STEP:11,null,20,COBBLESTONE:0,null,100)
RandomBlock(-6,7,-5,contenttweaker:reinforced_concrete:0,null,40,SMOOTH_BRICK:1,null,30,SMOOTH_BRICK:2,null,30,SMOOTH_STAIRS:0,null,15,SMOOTH_STAIRS:1,null,15,SMOOTH_STAIRS:2,null,15,SMOOTH_STAIRS:3,null,15,STEP:5,null,15,STEP:13,null,15,COBBLE_WALL:0,null,10,COBBLESTONE_STAIRS:0,null,10,STEP:3,null,10,COBBLE_WALL:1,null,20,COBBLESTONE_STAIRS:2,null,20,COBBLESTONE_STAIRS:3,null,20,MOSSY_COBBLESTONE:0,null,60,COBBLESTONE_STAIRS:1,null,20,STEP:11,null,20,COBBLESTONE:0,null,100)
RandomBlock(-6,7,-4,contenttweaker:reinforced_concrete:0,null,40,SMOOTH_BRICK:1,null,30,SMOOTH_BRICK:2,null,30,SMOOTH_STAIRS:0,null,15,SMOOTH_STAIRS:1,null,15,SMOOTH_STAIRS:2,null,15,SMOOTH_STAIRS:3,null,15,STEP:5,null,15,STEP:13,null,15,COBBLE_WALL:0,null,10,COBBLESTONE_STAIRS:0,null,10,STEP:3,null,10,COBBLE_WALL:1,null,20,COBBLESTONE_STAIRS:2,null,20,COBBLESTONE_STAIRS:3,null,20,MOSSY_COBBLESTONE:0,null,60,COBBLESTONE_STAIRS:1,null,20,STEP:11,null,20,COBBLESTONE:0,null,100)
RandomBlock(-6,7,-3,contenttweaker:reinforced_concrete:0,null,30,quark:limestone_wall:0,null,10,contenttweaker:reinforced_concrete:0,null,100)
RandomBlock(-6,8,-7,contenttweaker:reinforced_concrete:0,null,30,quark:limestone_wall:0,null,10,contenttweaker:reinforced_concrete:0,null,100)
RandomBlock(-6,8,-5,rustic:iron_lattice:0,null,30,rustic:iron_lattice:1,null,100)
RandomBlock(-6,8,-4,rustic:iron_lattice:0,null,30,rustic:iron_lattice:1,null,100)
Block(-6,8,-3,inspirations:redstone_barrel:0)
RandomBlock(-6,9,-7,contenttweaker:reinforced_concrete:0,null,30,quark:limestone_wall:0,null,10,contenttweaker:reinforced_concrete:0,null,100)
RandomBlock(-6,9,-5,rustic:iron_lattice:0,null,30,rustic:iron_lattice:1,null,100)
RandomBlock(-6,9,-4,rustic:iron_lattice:0,null,30,rustic:iron_lattice:1,null,100)
Block(-6,9,-3,inspirations:redstone_barrel:0)
RandomBlock(-6,10,-5,rustic:iron_lattice:0,null,30,rustic:iron_lattice:1,null,100)
RandomBlock(-6,10,-4,rustic:iron_lattice:0,null,30,rustic:iron_lattice:1,null,100)
RandomBlock(-6,10,-3,contenttweaker:reinforced_concrete:0,null,30,quark:limestone_wall:0,null,10,contenttweaker:reinforced_concrete:0,null,100)
Block(-6,11,-5,VINE:9)
RandomBlock(-6,11,-3,contenttweaker:reinforced_concrete:0,null,30,quark:limestone_wall:0,null,10,contenttweaker:reinforced_concrete:0,null,100)
Block(-6,12,-5,VINE:9)
RandomBlock(-6,12,-4,contenttweaker:reinforced_concrete:0,null,30,quark:limestone_wall:0,null,10,contenttweaker:reinforced_concrete:0,null,100)
Block(-6,13,-5,VINE:8)
RandomBlock(-6,13,-4,contenttweaker:reinforced_concrete:0,null,30,quark:limestone_wall:0,null,10,contenttweaker:reinforced_concrete:0,null,100)
RandomBlock(-6,14,-4,rustic:iron_lattice:0,null,30,rustic:iron_lattice:1,null,100)
RandomBlock(-6,15,-5,rustic:iron_lattice:0,null,30,rustic:iron_lattice:1,null,100)
RandomBlock(-6,15,-4,rustic:iron_lattice:0,null,30,rustic:iron_lattice:1,null,100)
RandomBlock(-5,0,-7,contenttweaker:reinforced_concrete:0,null,40,SMOOTH_BRICK:1,null,30,SMOOTH_BRICK:2,null,30,SMOOTH_STAIRS:0,null,15,SMOOTH_STAIRS:1,null,15,SMOOTH_STAIRS:2,null,15,SMOOTH_STAIRS:3,null,15,STEP:5,null,15,STEP:13,null,15,COBBLE_WALL:0,null,10,COBBLESTONE_STAIRS:0,null,10,STEP:3,null,10,COBBLE_WALL:1,null,20,COBBLESTONE_STAIRS:2,null,20,COBBLESTONE_STAIRS:3,null,20,MOSSY_COBBLESTONE:0,null,60,COBBLESTONE_STAIRS:1,null,20,STEP:11,null,20,COBBLESTONE:0,null,100)
RandomBlock(-5,0,-6,contenttweaker:reinforced_concrete:0,null,40,SMOOTH_BRICK:1,null,30,SMOOTH_BRICK:2,null,30,SMOOTH_STAIRS:0,null,15,SMOOTH_STAIRS:1,null,15,SMOOTH_STAIRS:2,null,15,SMOOTH_STAIRS:3,null,15,STEP:5,null,15,STEP:13,null,15,COBBLE_WALL:0,null,10,COBBLESTONE_STAIRS:0,null,10,STEP:3,null,10,COBBLE_WALL:1,null,20,COBBLESTONE_STAIRS:2,null,20,COBBLESTONE_STAIRS:3,null,20,MOSSY_COBBLESTONE:0,null,60,COBBLESTONE_STAIRS:1,null,20,STEP:11,null,20,COBBLESTONE:0,null,100)
RandomBlock(-5,0,-5,contenttweaker:reinforced_concrete:0,null,40,SMOOTH_BRICK:1,null,30,SMOOTH_BRICK:2,null,30,SMOOTH_STAIRS:0,null,15,SMOOTH_STAIRS:1,null,15,SMOOTH_STAIRS:2,null,15,SMOOTH_STAIRS:3,null,15,STEP:5,null,15,STEP:13,null,15,COBBLE_WALL:0,null,10,COBBLESTONE_STAIRS:0,null,10,STEP:3,null,10,COBBLE_WALL:1,null,20,COBBLESTONE_STAIRS:2,null,20,COBBLESTONE_STAIRS:3,null,20,MOSSY_COBBLESTONE:0,null,60,COBBLESTONE_STAIRS:1,null,20,STEP:11,null,20,COBBLESTONE:0,null,100)
RandomBlock(-5,0,-4,contenttweaker:reinforced_concrete:0,null,40,SMOOTH_BRICK:1,null,30,SMOOTH_BRICK:2,null,30,SMOOTH_STAIRS:0,null,15,SMOOTH_STAIRS:1,null,15,SMOOTH_STAIRS:2,null,15,SMOOTH_STAIRS:3,null,15,STEP:5,null,15,STEP:13,null,15,COBBLE_WALL:0,null,10,COBBLESTONE_STAIRS:0,null,10,STEP:3,null,10,COBBLE_WALL:1,null,20,COBBLESTONE_STAIRS:2,null,20,COBBLESTONE_STAIRS:3,null,20,MOSSY_COBBLESTONE:0,null,60,COBBLESTONE_STAIRS:1,null,20,STEP:11,null,20,COBBLESTONE:0,null,100)
RandomBlock(-5,1,-7,contenttweaker:reinforced_concrete:0,null,40,SMOOTH_BRICK:1,null,30,SMOOTH_BRICK:2,null,30,SMOOTH_STAIRS:0,null,15,SMOOTH_STAIRS:1,null,15,SMOOTH_STAIRS:2,null,15,SMOOTH_STAIRS:3,null,15,STEP:5,null,15,STEP:13,null,15,COBBLE_WALL:0,null,10,COBBLESTONE_STAIRS:0,null,10,STEP:3,null,10,COBBLE_WALL:1,null,20,COBBLESTONE_STAIRS:2,null,20,COBBLESTONE_STAIRS:3,null,20,MOSSY_COBBLESTONE:0,null,60,COBBLESTONE_STAIRS:1,null,20,STEP:11,null,20,COBBLESTONE:0,null,100)
RandomBlock(-5,1,-6,contenttweaker:reinforced_concrete:0,null,40,SMOOTH_BRICK:1,null,30,SMOOTH_BRICK:2,null,30,SMOOTH_STAIRS:0,null,15,SMOOTH_STAIRS:1,null,15,SMOOTH_STAIRS:2,null,15,SMOOTH_STAIRS:3,null,15,STEP:5,null,15,STEP:13,null,15,COBBLE_WALL:0,null,10,COBBLESTONE_STAIRS:0,null,10,STEP:3,null,10,COBBLE_WALL:1,null,20,COBBLESTONE_STAIRS:2,null,20,COBBLESTONE_STAIRS:3,null,20,MOSSY_COBBLESTONE:0,null,60,COBBLESTONE_STAIRS:1,null,20,STEP:11,null,20,COBBLESTONE:0,null,100)
RandomBlock(-5,1,-5,contenttweaker:reinforced_concrete:0,null,40,SMOOTH_BRICK:1,null,30,SMOOTH_BRICK:2,null,30,SMOOTH_STAIRS:0,null,15,SMOOTH_STAIRS:1,null,15,SMOOTH_STAIRS:2,null,15,SMOOTH_STAIRS:3,null,15,STEP:5,null,15,STEP:13,null,15,COBBLE_WALL:0,null,10,COBBLESTONE_STAIRS:0,null,10,STEP:3,null,10,COBBLE_WALL:1,null,20,COBBLESTONE_STAIRS:2,null,20,COBBLESTONE_STAIRS:3,null,20,MOSSY_COBBLESTONE:0,null,60,COBBLESTONE_STAIRS:1,null,20,STEP:11,null,20,COBBLESTONE:0,null,100)
RandomBlock(-5,1,-4,contenttweaker:reinforced_concrete:0,null,40,SMOOTH_BRICK:1,null,30,SMOOTH_BRICK:2,null,30,SMOOTH_STAIRS:0,null,15,SMOOTH_STAIRS:1,null,15,SMOOTH_STAIRS:2,null,15,SMOOTH_STAIRS:3,null,15,STEP:5,null,15,STEP:13,null,15,COBBLE_WALL:0,null,10,COBBLESTONE_STAIRS:0,null,10,STEP:3,null,10,COBBLE_WALL:1,null,20,COBBLESTONE_STAIRS:2,null,20,COBBLESTONE_STAIRS:3,null,20,MOSSY_COBBLESTONE:0,null,60,COBBLESTONE_STAIRS:1,null,20,STEP:11,null,20,COBBLESTONE:0,null,100)
RandomBlock(-5,2,-7,contenttweaker:reinforced_concrete:0,null,40,SMOOTH_BRICK:1,null,30,SMOOTH_BRICK:2,null,30,SMOOTH_STAIRS:0,null,15,SMOOTH_STAIRS:1,null,15,SMOOTH_STAIRS:2,null,15,SMOOTH_STAIRS:3,null,15,STEP:5,null,15,STEP:13,null,15,COBBLE_WALL:0,null,10,COBBLESTONE_STAIRS:0,null,10,STEP:3,null,10,COBBLE_WALL:1,null,20,COBBLESTONE_STAIRS:2,null,20,COBBLESTONE_STAIRS:3,null,20,MOSSY_COBBLESTONE:0,null,60,COBBLESTONE_STAIRS:1,null,20,STEP:11,null,20,COBBLESTONE:0,null,100)
RandomBlock(-5,2,-6,contenttweaker:reinforced_concrete:0,null,40,SMOOTH_BRICK:1,null,30,SMOOTH_BRICK:2,null,30,SMOOTH_STAIRS:0,null,15,SMOOTH_STAIRS:1,null,15,SMOOTH_STAIRS:2,null,15,SMOOTH_STAIRS:3,null,15,STEP:5,null,15,STEP:13,null,15,COBBLE_WALL:0,null,10,COBBLESTONE_STAIRS:0,null,10,STEP:3,null,10,COBBLE_WALL:1,null,20,COBBLESTONE_STAIRS:2,null,20,COBBLESTONE_STAIRS:3,null,20,MOSSY_COBBLESTONE:0,null,60,COBBLESTONE_STAIRS:1,null,20,STEP:11,null,20,COBBLESTONE:0,null,100)
RandomBlock(-5,2,-5,contenttweaker:reinforced_concrete:0,null,40,SMOOTH_BRICK:1,null,30,SMOOTH_BRICK:2,null,30,SMOOTH_STAIRS:0,null,15,SMOOTH_STAIRS:1,null,15,SMOOTH_STAIRS:2,null,15,SMOOTH_STAIRS:3,null,15,STEP:5,null,15,STEP:13,null,15,COBBLE_WALL:0,null,10,COBBLESTONE_STAIRS:0,null,10,STEP:3,null,10,COBBLE_WALL:1,null,20,COBBLESTONE_STAIRS:2,null,20,COBBLESTONE_STAIRS:3,null,20,MOSSY_COBBLESTONE:0,null,60,COBBLESTONE_STAIRS:1,null,20,STEP:11,null,20,COBBLESTONE:0,null,100)
RandomBlock(-5,2,-4,contenttweaker:reinforced_concrete:0,null,40,SMOOTH_BRICK:1,null,30,SMOOTH_BRICK:2,null,30,SMOOTH_STAIRS:0,null,15,SMOOTH_STAIRS:1,null,15,SMOOTH_STAIRS:2,null,15,SMOOTH_STAIRS:3,null,15,STEP:5,null,15,STEP:13,null,15,COBBLE_WALL:0,null,10,COBBLESTONE_STAIRS:0,null,10,STEP:3,null,10,COBBLE_WALL:1,null,20,COBBLESTONE_STAIRS:2,null,20,COBBLESTONE_STAIRS:3,null,20,MOSSY_COBBLESTONE:0,null,60,COBBLESTONE_STAIRS:1,null,20,STEP:11,null,20,COBBLESTONE:0,null,100)
RandomBlock(-5,3,-7,contenttweaker:reinforced_concrete:0,null,40,SMOOTH_BRICK:1,null,30,SMOOTH_BRICK:2,null,30,SMOOTH_STAIRS:0,null,15,SMOOTH_STAIRS:1,null,15,SMOOTH_STAIRS:2,null,15,SMOOTH_STAIRS:3,null,15,STEP:5,null,15,STEP:13,null,15,COBBLE_WALL:0,null,10,COBBLESTONE_STAIRS:0,null,10,STEP:3,null,10,COBBLE_WALL:1,null,20,COBBLESTONE_STAIRS:2,null,20,COBBLESTONE_STAIRS:3,null,20,MOSSY_COBBLESTONE:0,null,60,COBBLESTONE_STAIRS:1,null,20,STEP:11,null,20,COBBLESTONE:0,null,100)
RandomBlock(-5,3,-6,contenttweaker:reinforced_concrete:0,null,40,SMOOTH_BRICK:1,null,30,SMOOTH_BRICK:2,null,30,SMOOTH_STAIRS:0,null,15,SMOOTH_STAIRS:1,null,15,SMOOTH_STAIRS:2,null,15,SMOOTH_STAIRS:3,null,15,STEP:5,null,15,STEP:13,null,15,COBBLE_WALL:0,null,10,COBBLESTONE_STAIRS:0,null,10,STEP:3,null,10,COBBLE_WALL:1,null,20,COBBLESTONE_STAIRS:2,null,20,COBBLESTONE_STAIRS:3,null,20,MOSSY_COBBLESTONE:0,null,60,COBBLESTONE_STAIRS:1,null,20,STEP:11,null,20,COBBLESTONE:0,null,100)
RandomBlock(-5,3,-5,contenttweaker:reinforced_concrete:0,null,40,SMOOTH_BRICK:1,null,30,SMOOTH_BRICK:2,null,30,SMOOTH_STAIRS:0,null,15,SMOOTH_STAIRS:1,null,15,SMOOTH_STAIRS:2,null,15,SMOOTH_STAIRS:3,null,15,STEP:5,null,15,STEP:13,null,15,COBBLE_WALL:0,null,10,COBBLESTONE_STAIRS:0,null,10,STEP:3,null,10,COBBLE_WALL:1,null,20,COBBLESTONE_STAIRS:2,null,20,COBBLESTONE_STAIRS:3,null,20,MOSSY_COBBLESTONE:0,null,60,COBBLESTONE_STAIRS:1,null,20,STEP:11,null,20,COBBLESTONE:0,null,100)
RandomBlock(-5,3,-4,contenttweaker:reinforced_concrete:0,null,40,SMOOTH_BRICK:1,null,30,SMOOTH_BRICK:2,null,30,SMOOTH_STAIRS:0,null,15,SMOOTH_STAIRS:1,null,15,SMOOTH_STAIRS:2,null,15,SMOOTH_STAIRS:3,null,15,STEP:5,null,15,STEP:13,null,15,COBBLE_WALL:0,null,10,COBBLESTONE_STAIRS:0,null,10,STEP:3,null,10,COBBLE_WALL:1,null,20,COBBLESTONE_STAIRS:2,null,20,COBBLESTONE_STAIRS:3,null,20,MOSSY_COBBLESTONE:0,null,60,COBBLESTONE_STAIRS:1,null,20,STEP:11,null,20,COBBLESTONE:0,null,100)
RandomBlock(-5,4,-7,contenttweaker:reinforced_concrete:0,null,40,SMOOTH_BRICK:1,null,30,SMOOTH_BRICK:2,null,30,SMOOTH_STAIRS:0,null,15,SMOOTH_STAIRS:1,null,15,SMOOTH_STAIRS:2,null,15,SMOOTH_STAIRS:3,null,15,STEP:5,null,15,STEP:13,null,15,COBBLE_WALL:0,null,10,COBBLESTONE_STAIRS:0,null,10,STEP:3,null,10,COBBLE_WALL:1,null,20,COBBLESTONE_STAIRS:2,null,20,COBBLESTONE_STAIRS:3,null,20,MOSSY_COBBLESTONE:0,null,60,COBBLESTONE_STAIRS:1,null,20,STEP:11,null,20,COBBLESTONE:0,null,100)
RandomBlock(-5,4,-6,contenttweaker:reinforced_concrete:0,null,40,SMOOTH_BRICK:1,null,30,SMOOTH_BRICK:2,null,30,SMOOTH_STAIRS:0,null,15,SMOOTH_STAIRS:1,null,15,SMOOTH_STAIRS:2,null,15,SMOOTH_STAIRS:3,null,15,STEP:5,null,15,STEP:13,null,15,COBBLE_WALL:0,null,10,COBBLESTONE_STAIRS:0,null,10,STEP:3,null,10,COBBLE_WALL:1,null,20,COBBLESTONE_STAIRS:2,null,20,COBBLESTONE_STAIRS:3,null,20,MOSSY_COBBLESTONE:0,null,60,COBBLESTONE_STAIRS:1,null,20,STEP:11,null,20,COBBLESTONE:0,null,100)
RandomBlock(-5,4,-5,contenttweaker:reinforced_concrete:0,null,40,SMOOTH_BRICK:1,null,30,SMOOTH_BRICK:2,null,30,SMOOTH_STAIRS:0,null,15,SMOOTH_STAIRS:1,null,15,SMOOTH_STAIRS:2,null,15,SMOOTH_STAIRS:3,null,15,STEP:5,null,15,STEP:13,null,15,COBBLE_WALL:0,null,10,COBBLESTONE_STAIRS:0,null,10,STEP:3,null,10,COBBLE_WALL:1,null,20,COBBLESTONE_STAIRS:2,null,20,COBBLESTONE_STAIRS:3,null,20,MOSSY_COBBLESTONE:0,null,60,COBBLESTONE_STAIRS:1,null,20,STEP:11,null,20,COBBLESTONE:0,null,100)
RandomBlock(-5,4,-4,contenttweaker:reinforced_concrete:0,null,40,SMOOTH_BRICK:1,null,30,SMOOTH_BRICK:2,null,30,SMOOTH_STAIRS:0,null,15,SMOOTH_STAIRS:1,null,15,SMOOTH_STAIRS:2,null,15,SMOOTH_STAIRS:3,null,15,STEP:5,null,15,STEP:13,null,15,COBBLE_WALL:0,null,10,COBBLESTONE_STAIRS:0,null,10,STEP:3,null,10,COBBLE_WALL:1,null,20,COBBLESTONE_STAIRS:2,null,20,COBBLESTONE_STAIRS:3,null,20,MOSSY_COBBLESTONE:0,null,60,COBBLESTONE_STAIRS:1,null,20,STEP:11,null,20,COBBLESTONE:0,null,100)
RandomBlock(-5,5,-7,contenttweaker:reinforced_concrete:0,null,40,SMOOTH_BRICK:1,null,30,SMOOTH_BRICK:2,null,30,SMOOTH_STAIRS:0,null,15,SMOOTH_STAIRS:1,null,15,SMOOTH_STAIRS:2,null,15,SMOOTH_STAIRS:3,null,15,STEP:5,null,15,STEP:13,null,15,COBBLE_WALL:0,null,10,COBBLESTONE_STAIRS:0,null,10,STEP:3,null,10,COBBLE_WALL:1,null,20,COBBLESTONE_STAIRS:2,null,20,COBBLESTONE_STAIRS:3,null,20,MOSSY_COBBLESTONE:0,null,60,COBBLESTONE_STAIRS:1,null,20,STEP:11,null,20,COBBLESTONE:0,null,100)
RandomBlock(-5,5,-6,contenttweaker:reinforced_concrete:0,null,40,SMOOTH_BRICK:1,null,30,SMOOTH_BRICK:2,null,30,SMOOTH_STAIRS:0,null,15,SMOOTH_STAIRS:1,null,15,SMOOTH_STAIRS:2,null,15,SMOOTH_STAIRS:3,null,15,STEP:5,null,15,STEP:13,null,15,COBBLE_WALL:0,null,10,COBBLESTONE_STAIRS:0,null,10,STEP:3,null,10,COBBLE_WALL:1,null,20,COBBLESTONE_STAIRS:2,null,20,COBBLESTONE_STAIRS:3,null,20,MOSSY_COBBLESTONE:0,null,60,COBBLESTONE_STAIRS:1,null,20,STEP:11,null,20,COBBLESTONE:0,null,100)
RandomBlock(-5,5,-5,contenttweaker:reinforced_concrete:0,null,40,SMOOTH_BRICK:1,null,30,SMOOTH_BRICK:2,null,30,SMOOTH_STAIRS:0,null,15,SMOOTH_STAIRS:1,null,15,SMOOTH_STAIRS:2,null,15,SMOOTH_STAIRS:3,null,15,STEP:5,null,15,STEP:13,null,15,COBBLE_WALL:0,null,10,COBBLESTONE_STAIRS:0,null,10,STEP:3,null,10,COBBLE_WALL:1,null,20,COBBLESTONE_STAIRS:2,null,20,COBBLESTONE_STAIRS:3,null,20,MOSSY_COBBLESTONE:0,null,60,COBBLESTONE_STAIRS:1,null,20,STEP:11,null,20,COBBLESTONE:0,null,100)
RandomBlock(-5,5,-4,contenttweaker:reinforced_concrete:0,null,30,quark:limestone_wall:0,null,10,contenttweaker:reinforced_concrete:0,null,100)
RandomBlock(-5,6,-7,contenttweaker:reinforced_concrete:0,null,40,SMOOTH_BRICK:1,null,30,SMOOTH_BRICK:2,null,30,SMOOTH_STAIRS:0,null,15,SMOOTH_STAIRS:1,null,15,SMOOTH_STAIRS:2,null,15,SMOOTH_STAIRS:3,null,15,STEP:5,null,15,STEP:13,null,15,COBBLE_WALL:0,null,10,COBBLESTONE_STAIRS:0,null,10,STEP:3,null,10,COBBLE_WALL:1,null,20,COBBLESTONE_STAIRS:2,null,20,COBBLESTONE_STAIRS:3,null,20,MOSSY_COBBLESTONE:0,null,60,COBBLESTONE_STAIRS:1,null,20,STEP:11,null,20,COBBLESTONE:0,null,100)
RandomBlock(-5,6,-6,contenttweaker:reinforced_concrete:0,null,40,SMOOTH_BRICK:1,null,30,SMOOTH_BRICK:2,null,30,SMOOTH_STAIRS:0,null,15,SMOOTH_STAIRS:1,null,15,SMOOTH_STAIRS:2,null,15,SMOOTH_STAIRS:3,null,15,STEP:5,null,15,STEP:13,null,15,COBBLE_WALL:0,null,10,COBBLESTONE_STAIRS:0,null,10,STEP:3,null,10,COBBLE_WALL:1,null,20,COBBLESTONE_STAIRS:2,null,20,COBBLESTONE_STAIRS:3,null,20,MOSSY_COBBLESTONE:0,null,60,COBBLESTONE_STAIRS:1,null,20,STEP:11,null,20,COBBLESTONE:0,null,100)
RandomBlock(-5,6,-5,contenttweaker:reinforced_concrete:0,null,40,SMOOTH_BRICK:1,null,30,SMOOTH_BRICK:2,null,30,SMOOTH_STAIRS:0,null,15,SMOOTH_STAIRS:1,null,15,SMOOTH_STAIRS:2,null,15,SMOOTH_STAIRS:3,null,15,STEP:5,null,15,STEP:13,null,15,COBBLE_WALL:0,null,10,COBBLESTONE_STAIRS:0,null,10,STEP:3,null,10,COBBLE_WALL:1,null,20,COBBLESTONE_STAIRS:2,null,20,COBBLESTONE_STAIRS:3,null,20,MOSSY_COBBLESTONE:0,null,60,COBBLESTONE_STAIRS:1,null,20,STEP:11,null,20,COBBLESTONE:0,null,100)
RandomBlock(-5,6,-4,contenttweaker:reinforced_concrete:0,null,30,quark:limestone_wall:0,null,10,contenttweaker:reinforced_concrete:0,null,100)
RandomBlock(-5,7,-7,contenttweaker:reinforced_concrete:0,null,40,SMOOTH_BRICK:1,null,30,SMOOTH_BRICK:2,null,30,SMOOTH_STAIRS:0,null,15,SMOOTH_STAIRS:1,null,15,SMOOTH_STAIRS:2,null,15,SMOOTH_STAIRS:3,null,15,STEP:5,null,15,STEP:13,null,15,COBBLE_WALL:0,null,10,COBBLESTONE_STAIRS:0,null,10,STEP:3,null,10,COBBLE_WALL:1,null,20,COBBLESTONE_STAIRS:2,null,20,COBBLESTONE_STAIRS:3,null,20,MOSSY_COBBLESTONE:0,null,60,COBBLESTONE_STAIRS:1,null,20,STEP:11,null,20,COBBLESTONE:0,null,100)
RandomBlock(-5,7,-6,contenttweaker:reinforced_concrete:0,null,40,SMOOTH_BRICK:1,null,30,SMOOTH_BRICK:2,null,30,SMOOTH_STAIRS:0,null,15,SMOOTH_STAIRS:1,null,15,SMOOTH_STAIRS:2,null,15,SMOOTH_STAIRS:3,null,15,STEP:5,null,15,STEP:13,null,15,COBBLE_WALL:0,null,10,COBBLESTONE_STAIRS:0,null,10,STEP:3,null,10,COBBLE_WALL:1,null,20,COBBLESTONE_STAIRS:2,null,20,COBBLESTONE_STAIRS:3,null,20,MOSSY_COBBLESTONE:0,null,60,COBBLESTONE_STAIRS:1,null,20,STEP:11,null,20,COBBLESTONE:0,null,100)
RandomBlock(-5,7,-5,contenttweaker:reinforced_concrete:0,null,40,SMOOTH_BRICK:1,null,30,SMOOTH_BRICK:2,null,30,SMOOTH_STAIRS:0,null,15,SMOOTH_STAIRS:1,null,15,SMOOTH_STAIRS:2,null,15,SMOOTH_STAIRS:3,null,15,STEP:5,null,15,STEP:13,null,15,COBBLE_WALL:0,null,10,COBBLESTONE_STAIRS:0,null,10,STEP:3,null,10,COBBLE_WALL:1,null,20,COBBLESTONE_STAIRS:2,null,20,COBBLESTONE_STAIRS:3,null,20,MOSSY_COBBLESTONE:0,null,60,COBBLESTONE_STAIRS:1,null,20,STEP:11,null,20,COBBLESTONE:0,null,100)
RandomBlock(-5,7,-4,contenttweaker:reinforced_concrete:0,null,30,quark:limestone_wall:0,null,10,contenttweaker:reinforced_concrete:0,null,100)
RandomBlock(-5,8,-7,rustic:iron_lattice:0,null,30,rustic:iron_lattice:1,null,100)
RandomBlock(-5,8,-6,rustic:iron_lattice:0,null,30,rustic:iron_lattice:1,null,100)
RandomBlock(-5,8,-5,rustic:iron_lattice:0,null,30,rustic:iron_lattice:1,null,100)
RandomBlock(-5,9,-7,rustic:iron_lattice:0,null,30,rustic:iron_lattice:1,null,100)
RandomBlock(-5,9,-6,rustic:iron_lattice:0,null,30,rustic:iron_lattice:1,null,100)
RandomBlock(-5,9,-5,rustic:iron_lattice:0,null,30,rustic:iron_lattice:1,null,100)
RandomBlock(-5,10,-7,rustic:iron_lattice:0,null,30,rustic:iron_lattice:1,null,100)
RandomBlock(-5,10,-6,rustic:iron_lattice:0,null,30,rustic:iron_lattice:1,null,100)
RandomBlock(-5,10,-5,rustic:iron_lattice:0,null,30,rustic:iron_lattice:1,null,100)
RandomBlock(-5,10,-4,contenttweaker:reinforced_concrete:0,null,30,quark:limestone_wall:0,null,10,contenttweaker:reinforced_concrete:0,null,100)
RandomBlock(-5,11,-4,contenttweaker:reinforced_concrete:0,null,30,quark:limestone_wall:0,null,10,contenttweaker:reinforced_concrete:0,null,100)
RandomBlock(-5,12,-6,contenttweaker:reinforced_concrete:0,null,30,quark:limestone_wall:0,null,10,contenttweaker:reinforced_concrete:0,null,100)
RandomBlock(-5,12,-5,contenttweaker:reinforced_concrete:0,null,30,quark:limestone_wall:0,null,10,contenttweaker:reinforced_concrete:0,null,100)
RandomBlock(-5,13,-6,contenttweaker:reinforced_concrete:0,null,30,quark:limestone_wall:0,null,10,contenttweaker:reinforced_concrete:0,null,100)
RandomBlock(-5,13,-5,contenttweaker:reinforced_concrete:0,null,30,quark:limestone_wall:0,null,10,contenttweaker:reinforced_concrete:0,null,100)
RandomBlock(-5,14,-6,rustic:iron_lattice:0,null,30,rustic:iron_lattice:1,null,100)
RandomBlock(-4,0,-7,contenttweaker:reinforced_concrete:0,null,40,SMOOTH_BRICK:1,null,30,SMOOTH_BRICK:2,null,30,SMOOTH_STAIRS:0,null,15,SMOOTH_STAIRS:1,null,15,SMOOTH_STAIRS:2,null,15,SMOOTH_STAIRS:3,null,15,STEP:5,null,15,STEP:13,null,15,COBBLE_WALL:0,null,10,COBBLESTONE_STAIRS:0,null,10,STEP:3,null,10,COBBLE_WALL:1,null,20,COBBLESTONE_STAIRS:2,null,20,COBBLESTONE_STAIRS:3,null,20,MOSSY_COBBLESTONE:0,null,60,COBBLESTONE_STAIRS:1,null,20,STEP:11,null,20,COBBLESTONE:0,null,100)
RandomBlock(-4,0,-6,contenttweaker:reinforced_concrete:0,null,40,SMOOTH_BRICK:1,null,30,SMOOTH_BRICK:2,null,30,SMOOTH_STAIRS:0,null,15,SMOOTH_STAIRS:1,null,15,SMOOTH_STAIRS:2,null,15,SMOOTH_STAIRS:3,null,15,STEP:5,null,15,STEP:13,null,15,COBBLE_WALL:0,null,10,COBBLESTONE_STAIRS:0,null,10,STEP:3,null,10,COBBLE_WALL:1,null,20,COBBLESTONE_STAIRS:2,null,20,COBBLESTONE_STAIRS:3,null,20,MOSSY_COBBLESTONE:0,null,60,COBBLESTONE_STAIRS:1,null,20,STEP:11,null,20,COBBLESTONE:0,null,100)
RandomBlock(-4,0,-5,contenttweaker:reinforced_concrete:0,null,40,SMOOTH_BRICK:1,null,30,SMOOTH_BRICK:2,null,30,SMOOTH_STAIRS:0,null,15,SMOOTH_STAIRS:1,null,15,SMOOTH_STAIRS:2,null,15,SMOOTH_STAIRS:3,null,15,STEP:5,null,15,STEP:13,null,15,COBBLE_WALL:0,null,10,COBBLESTONE_STAIRS:0,null,10,STEP:3,null,10,COBBLE_WALL:1,null,20,COBBLESTONE_STAIRS:2,null,20,COBBLESTONE_STAIRS:3,null,20,MOSSY_COBBLESTONE:0,null,60,COBBLESTONE_STAIRS:1,null,20,STEP:11,null,20,COBBLESTONE:0,null,100)
RandomBlock(-4,1,-7,contenttweaker:reinforced_concrete:0,null,40,SMOOTH_BRICK:1,null,30,SMOOTH_BRICK:2,null,30,SMOOTH_STAIRS:0,null,15,SMOOTH_STAIRS:1,null,15,SMOOTH_STAIRS:2,null,15,SMOOTH_STAIRS:3,null,15,STEP:5,null,15,STEP:13,null,15,COBBLE_WALL:0,null,10,COBBLESTONE_STAIRS:0,null,10,STEP:3,null,10,COBBLE_WALL:1,null,20,COBBLESTONE_STAIRS:2,null,20,COBBLESTONE_STAIRS:3,null,20,MOSSY_COBBLESTONE:0,null,60,COBBLESTONE_STAIRS:1,null,20,STEP:11,null,20,COBBLESTONE:0,null,100)
RandomBlock(-4,1,-6,contenttweaker:reinforced_concrete:0,null,40,SMOOTH_BRICK:1,null,30,SMOOTH_BRICK:2,null,30,SMOOTH_STAIRS:0,null,15,SMOOTH_STAIRS:1,null,15,SMOOTH_STAIRS:2,null,15,SMOOTH_STAIRS:3,null,15,STEP:5,null,15,STEP:13,null,15,COBBLE_WALL:0,null,10,COBBLESTONE_STAIRS:0,null,10,STEP:3,null,10,COBBLE_WALL:1,null,20,COBBLESTONE_STAIRS:2,null,20,COBBLESTONE_STAIRS:3,null,20,MOSSY_COBBLESTONE:0,null,60,COBBLESTONE_STAIRS:1,null,20,STEP:11,null,20,COBBLESTONE:0,null,100)
RandomBlock(-4,1,-5,contenttweaker:reinforced_concrete:0,null,40,SMOOTH_BRICK:1,null,30,SMOOTH_BRICK:2,null,30,SMOOTH_STAIRS:0,null,15,SMOOTH_STAIRS:1,null,15,SMOOTH_STAIRS:2,null,15,SMOOTH_STAIRS:3,null,15,STEP:5,null,15,STEP:13,null,15,COBBLE_WALL:0,null,10,COBBLESTONE_STAIRS:0,null,10,STEP:3,null,10,COBBLE_WALL:1,null,20,COBBLESTONE_STAIRS:2,null,20,COBBLESTONE_STAIRS:3,null,20,MOSSY_COBBLESTONE:0,null,60,COBBLESTONE_STAIRS:1,null,20,STEP:11,null,20,COBBLESTONE:0,null,100)
RandomBlock(-4,2,-7,contenttweaker:reinforced_concrete:0,null,40,SMOOTH_BRICK:1,null,30,SMOOTH_BRICK:2,null,30,SMOOTH_STAIRS:0,null,15,SMOOTH_STAIRS:1,null,15,SMOOTH_STAIRS:2,null,15,SMOOTH_STAIRS:3,null,15,STEP:5,null,15,STEP:13,null,15,COBBLE_WALL:0,null,10,COBBLESTONE_STAIRS:0,null,10,STEP:3,null,10,COBBLE_WALL:1,null,20,COBBLESTONE_STAIRS:2,null,20,COBBLESTONE_STAIRS:3,null,20,MOSSY_COBBLESTONE:0,null,60,COBBLESTONE_STAIRS:1,null,20,STEP:11,null,20,COBBLESTONE:0,null,100)
RandomBlock(-4,2,-6,contenttweaker:reinforced_concrete:0,null,40,SMOOTH_BRICK:1,null,30,SMOOTH_BRICK:2,null,30,SMOOTH_STAIRS:0,null,15,SMOOTH_STAIRS:1,null,15,SMOOTH_STAIRS:2,null,15,SMOOTH_STAIRS:3,null,15,STEP:5,null,15,STEP:13,null,15,COBBLE_WALL:0,null,10,COBBLESTONE_STAIRS:0,null,10,STEP:3,null,10,COBBLE_WALL:1,null,20,COBBLESTONE_STAIRS:2,null,20,COBBLESTONE_STAIRS:3,null,20,MOSSY_COBBLESTONE:0,null,60,COBBLESTONE_STAIRS:1,null,20,STEP:11,null,20,COBBLESTONE:0,null,100)
RandomBlock(-4,2,-5,contenttweaker:reinforced_concrete:0,null,40,SMOOTH_BRICK:1,null,30,SMOOTH_BRICK:2,null,30,SMOOTH_STAIRS:0,null,15,SMOOTH_STAIRS:1,null,15,SMOOTH_STAIRS:2,null,15,SMOOTH_STAIRS:3,null,15,STEP:5,null,15,STEP:13,null,15,COBBLE_WALL:0,null,10,COBBLESTONE_STAIRS:0,null,10,STEP:3,null,10,COBBLE_WALL:1,null,20,COBBLESTONE_STAIRS:2,null,20,COBBLESTONE_STAIRS:3,null,20,MOSSY_COBBLESTONE:0,null,60,COBBLESTONE_STAIRS:1,null,20,STEP:11,null,20,COBBLESTONE:0,null,100)
RandomBlock(-4,3,-7,contenttweaker:reinforced_concrete:0,null,40,SMOOTH_BRICK:1,null,30,SMOOTH_BRICK:2,null,30,SMOOTH_STAIRS:0,null,15,SMOOTH_STAIRS:1,null,15,SMOOTH_STAIRS:2,null,15,SMOOTH_STAIRS:3,null,15,STEP:5,null,15,STEP:13,null,15,COBBLE_WALL:0,null,10,COBBLESTONE_STAIRS:0,null,10,STEP:3,null,10,COBBLE_WALL:1,null,20,COBBLESTONE_STAIRS:2,null,20,COBBLESTONE_STAIRS:3,null,20,MOSSY_COBBLESTONE:0,null,60,COBBLESTONE_STAIRS:1,null,20,STEP:11,null,20,COBBLESTONE:0,null,100)
RandomBlock(-4,3,-6,contenttweaker:reinforced_concrete:0,null,40,SMOOTH_BRICK:1,null,30,SMOOTH_BRICK:2,null,30,SMOOTH_STAIRS:0,null,15,SMOOTH_STAIRS:1,null,15,SMOOTH_STAIRS:2,null,15,SMOOTH_STAIRS:3,null,15,STEP:5,null,15,STEP:13,null,15,COBBLE_WALL:0,null,10,COBBLESTONE_STAIRS:0,null,10,STEP:3,null,10,COBBLE_WALL:1,null,20,COBBLESTONE_STAIRS:2,null,20,COBBLESTONE_STAIRS:3,null,20,MOSSY_COBBLESTONE:0,null,60,COBBLESTONE_STAIRS:1,null,20,STEP:11,null,20,COBBLESTONE:0,null,100)
RandomBlock(-4,3,-5,contenttweaker:reinforced_concrete:0,null,40,SMOOTH_BRICK:1,null,30,SMOOTH_BRICK:2,null,30,SMOOTH_STAIRS:0,null,15,SMOOTH_STAIRS:1,null,15,SMOOTH_STAIRS:2,null,15,SMOOTH_STAIRS:3,null,15,STEP:5,null,15,STEP:13,null,15,COBBLE_WALL:0,null,10,COBBLESTONE_STAIRS:0,null,10,STEP:3,null,10,COBBLE_WALL:1,null,20,COBBLESTONE_STAIRS:2,null,20,COBBLESTONE_STAIRS:3,null,20,MOSSY_COBBLESTONE:0,null,60,COBBLESTONE_STAIRS:1,null,20,STEP:11,null,20,COBBLESTONE:0,null,100)
RandomBlock(-4,4,-7,contenttweaker:reinforced_concrete:0,null,40,SMOOTH_BRICK:1,null,30,SMOOTH_BRICK:2,null,30,SMOOTH_STAIRS:0,null,15,SMOOTH_STAIRS:1,null,15,SMOOTH_STAIRS:2,null,15,SMOOTH_STAIRS:3,null,15,STEP:5,null,15,STEP:13,null,15,COBBLE_WALL:0,null,10,COBBLESTONE_STAIRS:0,null,10,STEP:3,null,10,COBBLE_WALL:1,null,20,COBBLESTONE_STAIRS:2,null,20,COBBLESTONE_STAIRS:3,null,20,MOSSY_COBBLESTONE:0,null,60,COBBLESTONE_STAIRS:1,null,20,STEP:11,null,20,COBBLESTONE:0,null,100)
RandomBlock(-4,4,-6,contenttweaker:reinforced_concrete:0,null,40,SMOOTH_BRICK:1,null,30,SMOOTH_BRICK:2,null,30,SMOOTH_STAIRS:0,null,15,SMOOTH_STAIRS:1,null,15,SMOOTH_STAIRS:2,null,15,SMOOTH_STAIRS:3,null,15,STEP:5,null,15,STEP:13,null,15,COBBLE_WALL:0,null,10,COBBLESTONE_STAIRS:0,null,10,STEP:3,null,10,COBBLE_WALL:1,null,20,COBBLESTONE_STAIRS:2,null,20,COBBLESTONE_STAIRS:3,null,20,MOSSY_COBBLESTONE:0,null,60,COBBLESTONE_STAIRS:1,null,20,STEP:11,null,20,COBBLESTONE:0,null,100)
RandomBlock(-4,4,-5,contenttweaker:reinforced_concrete:0,null,40,SMOOTH_BRICK:1,null,30,SMOOTH_BRICK:2,null,30,SMOOTH_STAIRS:0,null,15,SMOOTH_STAIRS:1,null,15,SMOOTH_STAIRS:2,null,15,SMOOTH_STAIRS:3,null,15,STEP:5,null,15,STEP:13,null,15,COBBLE_WALL:0,null,10,COBBLESTONE_STAIRS:0,null,10,STEP:3,null,10,COBBLE_WALL:1,null,20,COBBLESTONE_STAIRS:2,null,20,COBBLESTONE_STAIRS:3,null,20,MOSSY_COBBLESTONE:0,null,60,COBBLESTONE_STAIRS:1,null,20,STEP:11,null,20,COBBLESTONE:0,null,100)
RandomBlock(-4,5,-7,contenttweaker:reinforced_concrete:0,null,40,SMOOTH_BRICK:1,null,30,SMOOTH_BRICK:2,null,30,SMOOTH_STAIRS:0,null,15,SMOOTH_STAIRS:1,null,15,SMOOTH_STAIRS:2,null,15,SMOOTH_STAIRS:3,null,15,STEP:5,null,15,STEP:13,null,15,COBBLE_WALL:0,null,10,COBBLESTONE_STAIRS:0,null,10,STEP:3,null,10,COBBLE_WALL:1,null,20,COBBLESTONE_STAIRS:2,null,20,COBBLESTONE_STAIRS:3,null,20,MOSSY_COBBLESTONE:0,null,60,COBBLESTONE_STAIRS:1,null,20,STEP:11,null,20,COBBLESTONE:0,null,100)
RandomBlock(-4,5,-6,contenttweaker:reinforced_concrete:0,null,30,quark:limestone_wall:0,null,10,contenttweaker:reinforced_concrete:0,null,100)
RandomBlock(-4,5,-5,contenttweaker:reinforced_concrete:0,null,30,quark:limestone_wall:0,null,10,contenttweaker:reinforced_concrete:0,null,100)
RandomBlock(-4,6,-7,contenttweaker:reinforced_concrete:0,null,40,SMOOTH_BRICK:1,null,30,SMOOTH_BRICK:2,null,30,SMOOTH_STAIRS:0,null,15,SMOOTH_STAIRS:1,null,15,SMOOTH_STAIRS:2,null,15,SMOOTH_STAIRS:3,null,15,STEP:5,null,15,STEP:13,null,15,COBBLE_WALL:0,null,10,COBBLESTONE_STAIRS:0,null,10,STEP:3,null,10,COBBLE_WALL:1,null,20,COBBLESTONE_STAIRS:2,null,20,COBBLESTONE_STAIRS:3,null,20,MOSSY_COBBLESTONE:0,null,60,COBBLESTONE_STAIRS:1,null,20,STEP:11,null,20,COBBLESTONE:0,null,100)
RandomBlock(-4,6,-6,contenttweaker:reinforced_concrete:0,null,30,quark:limestone_wall:0,null,10,contenttweaker:reinforced_concrete:0,null,100)
RandomBlock(-4,6,-5,contenttweaker:reinforced_concrete:0,null,30,quark:limestone_wall:0,null,10,contenttweaker:reinforced_concrete:0,null,100)
RandomBlock(-4,7,-7,contenttweaker:reinforced_concrete:0,null,40,SMOOTH_BRICK:1,null,30,SMOOTH_BRICK:2,null,30,SMOOTH_STAIRS:0,null,15,SMOOTH_STAIRS:1,null,15,SMOOTH_STAIRS:2,null,15,SMOOTH_STAIRS:3,null,15,STEP:5,null,15,STEP:13,null,15,COBBLE_WALL:0,null,10,COBBLESTONE_STAIRS:0,null,10,STEP:3,null,10,COBBLE_WALL:1,null,20,COBBLESTONE_STAIRS:2,null,20,COBBLESTONE_STAIRS:3,null,20,MOSSY_COBBLESTONE:0,null,60,COBBLESTONE_STAIRS:1,null,20,STEP:11,null,20,COBBLESTONE:0,null,100)
RandomBlock(-4,7,-6,contenttweaker:reinforced_concrete:0,null,30,quark:limestone_wall:0,null,10,contenttweaker:reinforced_concrete:0,null,100)
RandomBlock(-4,7,-5,contenttweaker:reinforced_concrete:0,null,30,quark:limestone_wall:0,null,10,contenttweaker:reinforced_concrete:0,null,100)
RandomBlock(-4,8,-7,rustic:iron_lattice:0,null,30,rustic:iron_lattice:1,null,100)
Block(-4,8,-5,inspirations:redstone_barrel:0)
RandomBlock(-4,9,-7,rustic:iron_lattice:0,null,30,rustic:iron_lattice:1,null,100)
Block(-4,9,-5,inspirations:redstone_barrel:0)
RandomBlock(-4,10,-7,rustic:iron_lattice:0,null,30,rustic:iron_lattice:1,null,100)
RandomBlock(-4,10,-6,contenttweaker:reinforced_concrete:0,null,30,quark:limestone_wall:0,null,10,contenttweaker:reinforced_concrete:0,null,100)
RandomBlock(-4,10,-5,contenttweaker:reinforced_concrete:0,null,30,quark:limestone_wall:0,null,10,contenttweaker:reinforced_concrete:0,null,100)
RandomBlock(-4,11,-6,contenttweaker:reinforced_concrete:0,null,30,quark:limestone_wall:0,null,10,contenttweaker:reinforced_concrete:0,null,100)
RandomBlock(-4,11,-5,contenttweaker:reinforced_concrete:0,null,30,quark:limestone_wall:0,null,10,contenttweaker:reinforced_concrete:0,null,100)
RandomBlock(-4,12,-7,contenttweaker:reinforced_concrete:0,null,30,quark:limestone_wall:0,null,10,contenttweaker:reinforced_concrete:0,null,100)
RandomBlock(-4,13,-7,contenttweaker:reinforced_concrete:0,null,30,quark:limestone_wall:0,null,10,contenttweaker:reinforced_concrete:0,null,100)
RandomBlock(-4,14,-6,rustic:iron_lattice:0,null,30,rustic:iron_lattice:1,null,100)
RandomBlock(-3,0,-7,contenttweaker:reinforced_concrete:0,null,40,SMOOTH_BRICK:1,null,30,SMOOTH_BRICK:2,null,30,SMOOTH_STAIRS:0,null,15,SMOOTH_STAIRS:1,null,15,SMOOTH_STAIRS:2,null,15,SMOOTH_STAIRS:3,null,15,STEP:5,null,15,STEP:13,null,15,COBBLE_WALL:0,null,10,COBBLESTONE_STAIRS:0,null,10,STEP:3,null,10,COBBLE_WALL:1,null,20,COBBLESTONE_STAIRS:2,null,20,COBBLESTONE_STAIRS:3,null,20,MOSSY_COBBLESTONE:0,null,60,COBBLESTONE_STAIRS:1,null,20,STEP:11,null,20,COBBLESTONE:0,null,100)
RandomBlock(-3,1,-7,contenttweaker:reinforced_concrete:0,null,40,SMOOTH_BRICK:1,null,30,SMOOTH_BRICK:2,null,30,SMOOTH_STAIRS:0,null,15,SMOOTH_STAIRS:1,null,15,SMOOTH_STAIRS:2,null,15,SMOOTH_STAIRS:3,null,15,STEP:5,null,15,STEP:13,null,15,COBBLE_WALL:0,null,10,COBBLESTONE_STAIRS:0,null,10,STEP:3,null,10,COBBLE_WALL:1,null,20,COBBLESTONE_STAIRS:2,null,20,COBBLESTONE_STAIRS:3,null,20,MOSSY_COBBLESTONE:0,null,60,COBBLESTONE_STAIRS:1,null,20,STEP:11,null,20,COBBLESTONE:0,null,100)
RandomBlock(-3,2,-7,contenttweaker:reinforced_concrete:0,null,40,SMOOTH_BRICK:1,null,30,SMOOTH_BRICK:2,null,30,SMOOTH_STAIRS:0,null,15,SMOOTH_STAIRS:1,null,15,SMOOTH_STAIRS:2,null,15,SMOOTH_STAIRS:3,null,15,STEP:5,null,15,STEP:13,null,15,COBBLE_WALL:0,null,10,COBBLESTONE_STAIRS:0,null,10,STEP:3,null,10,COBBLE_WALL:1,null,20,COBBLESTONE_STAIRS:2,null,20,COBBLESTONE_STAIRS:3,null,20,MOSSY_COBBLESTONE:0,null,60,COBBLESTONE_STAIRS:1,null,20,STEP:11,null,20,COBBLESTONE:0,null,100)
RandomBlock(-3,3,-7,contenttweaker:reinforced_concrete:0,null,40,SMOOTH_BRICK:1,null,30,SMOOTH_BRICK:2,null,30,SMOOTH_STAIRS:0,null,15,SMOOTH_STAIRS:1,null,15,SMOOTH_STAIRS:2,null,15,SMOOTH_STAIRS:3,null,15,STEP:5,null,15,STEP:13,null,15,COBBLE_WALL:0,null,10,COBBLESTONE_STAIRS:0,null,10,STEP:3,null,10,COBBLE_WALL:1,null,20,COBBLESTONE_STAIRS:2,null,20,COBBLESTONE_STAIRS:3,null,20,MOSSY_COBBLESTONE:0,null,60,COBBLESTONE_STAIRS:1,null,20,STEP:11,null,20,COBBLESTONE:0,null,100)
RandomBlock(-3,4,-7,contenttweaker:reinforced_concrete:0,null,40,SMOOTH_BRICK:1,null,30,SMOOTH_BRICK:2,null,30,SMOOTH_STAIRS:0,null,15,SMOOTH_STAIRS:1,null,15,SMOOTH_STAIRS:2,null,15,SMOOTH_STAIRS:3,null,15,STEP:5,null,15,STEP:13,null,15,COBBLE_WALL:0,null,10,COBBLESTONE_STAIRS:0,null,10,STEP:3,null,10,COBBLE_WALL:1,null,20,COBBLESTONE_STAIRS:2,null,20,COBBLESTONE_STAIRS:3,null,20,MOSSY_COBBLESTONE:0,null,60,COBBLESTONE_STAIRS:1,null,20,STEP:11,null,20,COBBLESTONE:0,null,100)
RandomBlock(-3,5,-7,contenttweaker:reinforced_concrete:0,null,30,quark:limestone_wall:0,null,10,contenttweaker:reinforced_concrete:0,null,100)
RandomBlock(-3,6,-7,contenttweaker:reinforced_concrete:0,null,30,quark:limestone_wall:0,null,10,contenttweaker:reinforced_concrete:0,null,100)
RandomBlock(-3,7,-7,contenttweaker:reinforced_concrete:0,null,30,quark:limestone_wall:0,null,10,contenttweaker:reinforced_concrete:0,null,100)
Block(-3,8,-7,inspirations:redstone_barrel:0)
Block(-3,9,-7,inspirations:redstone_barrel:0)
RandomBlock(-3,10,-7,contenttweaker:reinforced_concrete:0,null,30,quark:limestone_wall:0,null,10,contenttweaker:reinforced_concrete:0,null,100)
RandomBlock(-3,11,-7,contenttweaker:reinforced_concrete:0,null,30,quark:limestone_wall:0,null,10,contenttweaker:reinforced_concrete:0,null,100)

#######################################################################
# +-----------------------------------------------------------------+ #
# |                             Branches                            | #
# +-----------------------------------------------------------------+ #
#######################################################################

Branch(-16,0,0,true,CoolingTower3C0R1,NORTH,100.0,0)

#######################################################################
# +-----------------------------------------------------------------+ #
# |                             Entities                            | #
# +-----------------------------------------------------------------+ #
#######################################################################


#######################################################################
# +-----------------------------------------------------------------+ #
# |                            Particles                            | #
# +-----------------------------------------------------------------+ #
#######################################################################


#######################################################################
# +-----------------------------------------------------------------+ #
# |                             Spawners                            | #
# +-----------------------------------------------------------------+ #
#######################################################################


#######################################################################
# +-----------------------------------------------------------------+ #
# |                             ModData                             | #
# +-----------------------------------------------------------------+ #
#######################################################################

