
#######################################################################
# +-----------------------------------------------------------------+ #
# |                            BO4 object                           | #
# +-----------------------------------------------------------------+ #
#######################################################################

Author: NLBlackEagle

Description: No description given

SettingsMode: WriteWithoutComments


#######################################################################
# +-----------------------------------------------------------------+ #
# |                          Main settings                          | #
# +-----------------------------------------------------------------+ #
#######################################################################

FixedRotation: 

Frequency: 0

SpawnHeight: highestBlock

UseCenterForHighestBlock: true

##############################
# Height Limits for the BO4. #
##############################

MinHeight: 0

MaxHeight: 255

InheritBO3: 

InheritBO3Rotation: NORTH

OverrideChildSettings: true

OverrideParentHeight: false

CanOverride: true

BranchFrequency: 0

BranchFrequencyGroup: 

MustBeBelowOther: false

MustBeInside: 

CannotBeInside: 

ReplacesBO3: 

MustBeInsideWorldBorders: false

CanSpawnOnWater: true

SpawnOnWaterOnly: false

SpawnUnderWater: false

SpawnAtWaterLevel: false

HeightOffset: 0

RemoveAir: false

ReplaceAbove: 

ReplaceBelow: 

ReplaceWithBiomeBlocks: false

ReplaceWithSurfaceBlock: GRASS

ReplaceWithGroundBlock: DIRT

ReplaceWithStoneBlock: STONE

SmoothRadius: 0

SmoothHeightOffset: 0

SmoothStartTop: false

SmoothStartWood: false

SmoothingSurfaceBlock: 

SmoothingGroundBlock: 

BO3Group: 

IsSpawnPoint: false

DoReplaceBlocks: true


#######################################################################
# +-----------------------------------------------------------------+ #
# |                              Blocks                             | #
# +-----------------------------------------------------------------+ #
#######################################################################

RandomBlock(-7,0,-7,SMOOTH_BRICK:0,null,40,SMOOTH_BRICK:1,null,20,SMOOTH_BRICK:2,null,30,SMOOTH_BRICK:0,null,100)
RandomBlock(-7,0,-6,SMOOTH_BRICK:0,null,40,SMOOTH_BRICK:1,null,20,SMOOTH_BRICK:2,null,30,SMOOTH_BRICK:0,null,100)
RandomBlock(-7,0,-5,SMOOTH_BRICK:0,null,40,SMOOTH_BRICK:1,null,20,SMOOTH_BRICK:2,null,30,SMOOTH_BRICK:0,null,100)
RandomBlock(-7,0,-4,SMOOTH_BRICK:0,null,40,SMOOTH_BRICK:1,null,20,SMOOTH_BRICK:2,null,30,SMOOTH_BRICK:0,null,100)
Block(-7,1,-7,VINE:8)
Block(-7,1,-6,VINE:8)
Block(-7,1,-5,VINE:8)
RandomBlock(-6,0,-7,SMOOTH_BRICK:0,null,40,SMOOTH_BRICK:1,null,20,SMOOTH_BRICK:2,null,30,SMOOTH_BRICK:0,null,100)
RandomBlock(-6,0,-6,SMOOTH_BRICK:0,null,40,SMOOTH_BRICK:1,null,20,SMOOTH_BRICK:2,null,30,SMOOTH_BRICK:0,null,100)
RandomBlock(-6,0,-5,SMOOTH_BRICK:0,null,40,SMOOTH_BRICK:1,null,20,SMOOTH_BRICK:2,null,30,SMOOTH_BRICK:0,null,100)
RandomBlock(-6,0,-4,SMOOTH_BRICK:0,null,40,SMOOTH_BRICK:1,null,20,SMOOTH_BRICK:2,null,30,SMOOTH_BRICK:0,null,100)
RandomBlock(-6,1,-7,SMOOTH_BRICK:0,null,40,SMOOTH_BRICK:1,null,20,SMOOTH_BRICK:2,null,30,SMOOTH_BRICK:0,null,100)
Block(-6,1,-6,SMOOTH_BRICK:2)
RandomBlock(-6,1,-5,SMOOTH_BRICK:0,null,40,SMOOTH_BRICK:1,null,20,SMOOTH_BRICK:2,null,30,SMOOTH_BRICK:0,null,100)
Block(-6,1,-4,VINE:4)
Block(-6,2,-7,lycanitesmobs:lushstone_slab:0)
Block(-6,2,-6,lycanitesmobs:lushstone_slab:0)
Block(-6,2,-5,lycanitesmobs:lushstone_slab:0)
RandomBlock(-5,0,-7,SMOOTH_BRICK:0,null,40,SMOOTH_BRICK:1,null,20,SMOOTH_BRICK:2,null,30,SMOOTH_BRICK:0,null,100)
RandomBlock(-5,0,-6,SMOOTH_BRICK:0,null,40,SMOOTH_BRICK:1,null,20,SMOOTH_BRICK:2,null,30,SMOOTH_BRICK:0,null,100)
RandomBlock(-5,0,-5,SMOOTH_BRICK:0,null,40,SMOOTH_BRICK:1,null,20,SMOOTH_BRICK:2,null,30,SMOOTH_BRICK:0,null,100)
RandomBlock(-5,0,-4,SMOOTH_BRICK:0,null,40,SMOOTH_BRICK:1,null,20,SMOOTH_BRICK:2,null,30,SMOOTH_BRICK:0,null,100)
RandomBlock(-5,1,-7,SMOOTH_BRICK:0,null,40,SMOOTH_BRICK:1,null,20,SMOOTH_BRICK:2,null,30,SMOOTH_BRICK:0,null,100)
RandomBlock(-5,1,-6,SMOOTH_BRICK:0,null,40,SMOOTH_BRICK:1,null,20,SMOOTH_BRICK:2,null,30,SMOOTH_BRICK:0,null,100)
Block(-5,1,-5,SMOOTH_BRICK:1)
RandomBlock(-5,2,-7,SMOOTH_BRICK:0,null,40,SMOOTH_BRICK:1,null,20,SMOOTH_BRICK:2,null,30,SMOOTH_BRICK:0,null,100)
RandomBlock(-5,2,-6,SMOOTH_BRICK:0,null,40,SMOOTH_BRICK:1,null,20,SMOOTH_BRICK:2,null,30,SMOOTH_BRICK:0,null,100)
Block(-5,2,-5,lycanitesmobs:lushstone_slab:0)
Block(-5,3,-7,VINE:8)
RandomBlock(-4,0,-7,SMOOTH_BRICK:0,null,40,SMOOTH_BRICK:1,null,20,SMOOTH_BRICK:2,null,30,SMOOTH_BRICK:0,null,100)
RandomBlock(-4,0,-6,SMOOTH_BRICK:0,null,40,SMOOTH_BRICK:1,null,20,SMOOTH_BRICK:2,null,30,SMOOTH_BRICK:0,null,100)
RandomBlock(-4,0,-5,SMOOTH_BRICK:0,null,40,SMOOTH_BRICK:1,null,20,SMOOTH_BRICK:2,null,30,SMOOTH_BRICK:0,null,100)
RandomBlock(-4,0,-4,SMOOTH_BRICK:0,null,40,SMOOTH_BRICK:1,null,20,SMOOTH_BRICK:2,null,30,SMOOTH_BRICK:0,null,100)
RandomBlock(-4,1,-7,SMOOTH_BRICK:0,null,40,SMOOTH_BRICK:1,null,20,SMOOTH_BRICK:2,null,30,SMOOTH_BRICK:0,null,100)
RandomBlock(-4,1,-6,SMOOTH_BRICK:0,null,40,SMOOTH_BRICK:1,null,20,SMOOTH_BRICK:2,null,30,SMOOTH_BRICK:0,null,100)
Block(-4,1,-5,SMOOTH_BRICK:1)
Block(-4,2,-7,SMOOTH_BRICK:2)
RandomBlock(-4,2,-6,SMOOTH_BRICK:0,null,40,SMOOTH_BRICK:1,null,20,SMOOTH_BRICK:2,null,30,SMOOTH_BRICK:0,null,100)
Block(-4,2,-5,lycanitesmobs:lushstone_slab:0)
RandomBlock(-4,3,-7,SMOOTH_BRICK:0,null,40,SMOOTH_BRICK:1,null,20,SMOOTH_BRICK:2,null,30,SMOOTH_BRICK:0,null,100)
RandomBlock(-3,0,-7,SMOOTH_BRICK:0,null,40,SMOOTH_BRICK:1,null,20,SMOOTH_BRICK:2,null,30,SMOOTH_BRICK:0,null,100)
RandomBlock(-3,0,-6,SMOOTH_BRICK:0,null,40,SMOOTH_BRICK:1,null,20,SMOOTH_BRICK:2,null,30,SMOOTH_BRICK:0,null,100)
RandomBlock(-3,0,-5,SMOOTH_BRICK:0,null,40,SMOOTH_BRICK:1,null,20,SMOOTH_BRICK:2,null,30,SMOOTH_BRICK:0,null,100)
RandomBlock(-3,0,-4,SMOOTH_BRICK:0,null,40,SMOOTH_BRICK:1,null,20,SMOOTH_BRICK:2,null,30,SMOOTH_BRICK:0,null,100)
RandomBlock(-3,1,-7,SMOOTH_BRICK:0,null,40,SMOOTH_BRICK:1,null,20,SMOOTH_BRICK:2,null,30,SMOOTH_BRICK:0,null,100)
RandomBlock(-3,1,-6,SMOOTH_BRICK:0,null,40,SMOOTH_BRICK:1,null,20,SMOOTH_BRICK:2,null,30,SMOOTH_BRICK:0,null,100)
Block(-3,1,-5,SMOOTH_BRICK:1)
Block(-3,2,-7,SMOOTH_BRICK:2)
Block(-3,2,-6,SMOOTH_BRICK:1)
Block(-3,2,-5,lycanitesmobs:lushstone_slab:0)
RandomBlock(-3,3,-7,SMOOTH_BRICK:0,null,40,SMOOTH_BRICK:1,null,20,SMOOTH_BRICK:2,null,30,SMOOTH_BRICK:0,null,100)
RandomBlock(-2,0,-7,SMOOTH_BRICK:0,null,40,SMOOTH_BRICK:1,null,20,SMOOTH_BRICK:2,null,30,SMOOTH_BRICK:0,null,100)
RandomBlock(-2,0,-6,SMOOTH_BRICK:0,null,40,SMOOTH_BRICK:1,null,20,SMOOTH_BRICK:2,null,30,SMOOTH_BRICK:0,null,100)
RandomBlock(-2,0,-5,SMOOTH_BRICK:0,null,40,SMOOTH_BRICK:1,null,20,SMOOTH_BRICK:2,null,30,SMOOTH_BRICK:0,null,100)
RandomBlock(-2,0,-4,SMOOTH_BRICK:0,null,40,SMOOTH_BRICK:1,null,20,SMOOTH_BRICK:2,null,30,SMOOTH_BRICK:0,null,100)
RandomBlock(-2,1,-7,SMOOTH_BRICK:0,null,40,SMOOTH_BRICK:1,null,20,SMOOTH_BRICK:2,null,30,SMOOTH_BRICK:0,null,100)
RandomBlock(-2,1,-6,SMOOTH_BRICK:0,null,40,SMOOTH_BRICK:1,null,20,SMOOTH_BRICK:2,null,30,SMOOTH_BRICK:0,null,100)
Block(-2,1,-5,SMOOTH_BRICK:2)
Block(-2,2,-7,SMOOTH_BRICK:2)
Block(-2,2,-6,SMOOTH_BRICK:2)
Block(-2,2,-5,lycanitesmobs:lushstone_slab:0)
Block(-2,3,-7,SMOOTH_BRICK:2)
Block(-2,4,-7,VINE:4)
RandomBlock(-1,0,-7,SMOOTH_BRICK:0,null,40,SMOOTH_BRICK:1,null,20,SMOOTH_BRICK:2,null,30,SMOOTH_BRICK:0,null,100)
RandomBlock(-1,0,-6,SMOOTH_BRICK:0,null,40,SMOOTH_BRICK:1,null,20,SMOOTH_BRICK:2,null,30,SMOOTH_BRICK:0,null,100)
RandomBlock(-1,0,-5,SMOOTH_BRICK:0,null,40,SMOOTH_BRICK:1,null,20,SMOOTH_BRICK:2,null,30,SMOOTH_BRICK:0,null,100)
RandomBlock(-1,0,-4,SMOOTH_BRICK:0,null,40,SMOOTH_BRICK:1,null,20,SMOOTH_BRICK:2,null,30,SMOOTH_BRICK:0,null,100)
RandomBlock(-1,1,-7,SMOOTH_BRICK:0,null,40,SMOOTH_BRICK:1,null,20,SMOOTH_BRICK:2,null,30,SMOOTH_BRICK:0,null,100)
RandomBlock(-1,1,-6,SMOOTH_BRICK:0,null,40,SMOOTH_BRICK:1,null,20,SMOOTH_BRICK:2,null,30,SMOOTH_BRICK:0,null,100)
Block(-1,1,-5,SMOOTH_BRICK:2)
Block(-1,2,-7,SMOOTH_BRICK:1)
Block(-1,2,-6,SMOOTH_BRICK:1)
Block(-1,2,-5,lycanitesmobs:lushstone_slab:0)
Block(-1,3,-7,SMOOTH_BRICK:1)
RandomBlock(0,0,-7,SMOOTH_BRICK:0,null,40,SMOOTH_BRICK:1,null,20,SMOOTH_BRICK:2,null,30,SMOOTH_BRICK:0,null,100)
RandomBlock(0,0,-6,SMOOTH_BRICK:0,null,40,SMOOTH_BRICK:1,null,20,SMOOTH_BRICK:2,null,30,SMOOTH_BRICK:0,null,100)
RandomBlock(0,0,-5,SMOOTH_BRICK:0,null,40,SMOOTH_BRICK:1,null,20,SMOOTH_BRICK:2,null,30,SMOOTH_BRICK:0,null,100)
RandomBlock(0,0,-4,SMOOTH_BRICK:0,null,40,SMOOTH_BRICK:1,null,20,SMOOTH_BRICK:2,null,30,SMOOTH_BRICK:0,null,100)
RandomBlock(0,0,-3,SMOOTH_BRICK:0,null,40,SMOOTH_BRICK:1,null,20,SMOOTH_BRICK:2,null,30,SMOOTH_BRICK:0,null,100)
RandomBlock(0,1,-7,SMOOTH_BRICK:0,null,40,SMOOTH_BRICK:1,null,20,SMOOTH_BRICK:2,null,30,SMOOTH_BRICK:0,null,100)
RandomBlock(0,1,-6,SMOOTH_BRICK:0,null,40,SMOOTH_BRICK:1,null,20,SMOOTH_BRICK:2,null,30,SMOOTH_BRICK:0,null,100)
RandomBlock(0,1,-5,SMOOTH_BRICK:0,null,40,SMOOTH_BRICK:1,null,20,SMOOTH_BRICK:2,null,30,SMOOTH_BRICK:0,null,100)
Block(0,1,-4,SMOOTH_BRICK:1)
Block(0,1,-3,lycanitesmobs:lushstonetile_stairs:3)
Block(0,2,-7,SMOOTH_BRICK:1)
RandomBlock(0,2,-6,SMOOTH_BRICK:0,null,40,SMOOTH_BRICK:1,null,20,SMOOTH_BRICK:2,null,30,SMOOTH_BRICK:0,null,100)
Block(0,2,-5,SMOOTH_BRICK:1)
Block(0,2,-4,lycanitesmobs:lushstonetile_stairs:3)
RandomBlock(0,3,-7,SMOOTH_BRICK:0,null,40,SMOOTH_BRICK:1,null,20,SMOOTH_BRICK:2,null,30,SMOOTH_BRICK:0,null,100)
Block(0,3,-6,SMOOTH_BRICK:1)
Block(0,3,-5,lycanitesmobs:lushstonetile_stairs:3)
Block(0,4,-7,SMOOTH_BRICK:1)
Block(0,4,-6,lycanitesmobs:lushstonetile_stairs:3)
Block(0,5,-7,lycanitesmobs:lushstonetile_stairs:3)
RandomBlock(1,0,-7,SMOOTH_BRICK:0,null,40,SMOOTH_BRICK:1,null,20,SMOOTH_BRICK:2,null,30,SMOOTH_BRICK:0,null,100)
RandomBlock(1,0,-6,SMOOTH_BRICK:0,null,40,SMOOTH_BRICK:1,null,20,SMOOTH_BRICK:2,null,30,SMOOTH_BRICK:0,null,100)
RandomBlock(1,0,-5,SMOOTH_BRICK:0,null,40,SMOOTH_BRICK:1,null,20,SMOOTH_BRICK:2,null,30,SMOOTH_BRICK:0,null,100)
RandomBlock(1,0,-4,SMOOTH_BRICK:0,null,40,SMOOTH_BRICK:1,null,20,SMOOTH_BRICK:2,null,30,SMOOTH_BRICK:0,null,100)
RandomBlock(1,0,-3,SMOOTH_BRICK:0,null,40,SMOOTH_BRICK:1,null,20,SMOOTH_BRICK:2,null,30,SMOOTH_BRICK:0,null,100)
RandomBlock(1,1,-7,SMOOTH_BRICK:0,null,40,SMOOTH_BRICK:1,null,20,SMOOTH_BRICK:2,null,30,SMOOTH_BRICK:0,null,100)
RandomBlock(1,1,-6,SMOOTH_BRICK:0,null,40,SMOOTH_BRICK:1,null,20,SMOOTH_BRICK:2,null,30,SMOOTH_BRICK:0,null,100)
RandomBlock(1,1,-5,SMOOTH_BRICK:0,null,40,SMOOTH_BRICK:1,null,20,SMOOTH_BRICK:2,null,30,SMOOTH_BRICK:0,null,100)
Block(1,1,-4,SMOOTH_STAIRS:3)
RandomBlock(1,2,-7,SMOOTH_BRICK:0,null,40,SMOOTH_BRICK:1,null,20,SMOOTH_BRICK:2,null,30,SMOOTH_BRICK:0,null,100)
RandomBlock(1,2,-6,SMOOTH_BRICK:0,null,40,SMOOTH_BRICK:1,null,20,SMOOTH_BRICK:2,null,30,SMOOTH_BRICK:0,null,100)
Block(1,2,-5,SMOOTH_STAIRS:3)
RandomBlock(1,3,-7,SMOOTH_BRICK:0,null,40,SMOOTH_BRICK:1,null,20,SMOOTH_BRICK:2,null,30,SMOOTH_BRICK:0,null,100)
Block(1,3,-6,SMOOTH_STAIRS:3)
Block(1,4,-7,SMOOTH_STAIRS:3)
RandomBlock(2,0,-7,SMOOTH_BRICK:0,null,40,SMOOTH_BRICK:1,null,20,SMOOTH_BRICK:2,null,30,SMOOTH_BRICK:0,null,100)
RandomBlock(2,0,-6,SMOOTH_BRICK:0,null,40,SMOOTH_BRICK:1,null,20,SMOOTH_BRICK:2,null,30,SMOOTH_BRICK:0,null,100)
RandomBlock(2,0,-5,SMOOTH_BRICK:0,null,40,SMOOTH_BRICK:1,null,20,SMOOTH_BRICK:2,null,30,SMOOTH_BRICK:0,null,100)
RandomBlock(2,0,-4,SMOOTH_BRICK:0,null,40,SMOOTH_BRICK:1,null,20,SMOOTH_BRICK:2,null,30,SMOOTH_BRICK:0,null,100)
RandomBlock(2,0,-3,SMOOTH_BRICK:0,null,40,SMOOTH_BRICK:1,null,20,SMOOTH_BRICK:2,null,30,SMOOTH_BRICK:0,null,100)
RandomBlock(2,1,-7,SMOOTH_BRICK:0,null,40,SMOOTH_BRICK:1,null,20,SMOOTH_BRICK:2,null,30,SMOOTH_BRICK:0,null,100)
RandomBlock(2,1,-6,SMOOTH_BRICK:0,null,40,SMOOTH_BRICK:1,null,20,SMOOTH_BRICK:2,null,30,SMOOTH_BRICK:0,null,100)
RandomBlock(2,1,-5,SMOOTH_BRICK:0,null,40,SMOOTH_BRICK:1,null,20,SMOOTH_BRICK:2,null,30,SMOOTH_BRICK:0,null,100)
Block(2,1,-4,SMOOTH_STAIRS:3)
RandomBlock(2,2,-7,SMOOTH_BRICK:0,null,40,SMOOTH_BRICK:1,null,20,SMOOTH_BRICK:2,null,30,SMOOTH_BRICK:0,null,100)
RandomBlock(2,2,-6,SMOOTH_BRICK:0,null,40,SMOOTH_BRICK:1,null,20,SMOOTH_BRICK:2,null,30,SMOOTH_BRICK:0,null,100)
Block(2,2,-5,SMOOTH_STAIRS:3)
RandomBlock(2,3,-7,SMOOTH_BRICK:0,null,40,SMOOTH_BRICK:1,null,20,SMOOTH_BRICK:2,null,30,SMOOTH_BRICK:0,null,100)
Block(2,3,-6,SMOOTH_STAIRS:3)
Block(2,4,-7,SMOOTH_STAIRS:3)
RandomBlock(3,0,-7,SMOOTH_BRICK:0,null,40,SMOOTH_BRICK:1,null,20,SMOOTH_BRICK:2,null,30,SMOOTH_BRICK:0,null,100)
RandomBlock(3,0,-6,SMOOTH_BRICK:0,null,40,SMOOTH_BRICK:1,null,20,SMOOTH_BRICK:2,null,30,SMOOTH_BRICK:0,null,100)
RandomBlock(3,0,-5,SMOOTH_BRICK:0,null,40,SMOOTH_BRICK:1,null,20,SMOOTH_BRICK:2,null,30,SMOOTH_BRICK:0,null,100)
RandomBlock(3,0,-4,SMOOTH_BRICK:0,null,40,SMOOTH_BRICK:1,null,20,SMOOTH_BRICK:2,null,30,SMOOTH_BRICK:0,null,100)
RandomBlock(3,0,-3,SMOOTH_BRICK:0,null,40,SMOOTH_BRICK:1,null,20,SMOOTH_BRICK:2,null,30,SMOOTH_BRICK:0,null,100)
RandomBlock(3,1,-7,SMOOTH_BRICK:0,null,40,SMOOTH_BRICK:1,null,20,SMOOTH_BRICK:2,null,30,SMOOTH_BRICK:0,null,100)
RandomBlock(3,1,-6,SMOOTH_BRICK:0,null,40,SMOOTH_BRICK:1,null,20,SMOOTH_BRICK:2,null,30,SMOOTH_BRICK:0,null,100)
RandomBlock(3,1,-5,SMOOTH_BRICK:0,null,40,SMOOTH_BRICK:1,null,20,SMOOTH_BRICK:2,null,30,SMOOTH_BRICK:0,null,100)
Block(3,1,-4,SMOOTH_STAIRS:3)
RandomBlock(3,2,-7,SMOOTH_BRICK:0,null,40,SMOOTH_BRICK:1,null,20,SMOOTH_BRICK:2,null,30,SMOOTH_BRICK:0,null,100)
RandomBlock(3,2,-6,SMOOTH_BRICK:0,null,40,SMOOTH_BRICK:1,null,20,SMOOTH_BRICK:2,null,30,SMOOTH_BRICK:0,null,100)
Block(3,2,-5,SMOOTH_STAIRS:3)
RandomBlock(3,3,-7,SMOOTH_BRICK:0,null,40,SMOOTH_BRICK:1,null,20,SMOOTH_BRICK:2,null,30,SMOOTH_BRICK:0,null,100)
Block(3,3,-6,SMOOTH_STAIRS:3)
Block(3,4,-7,SMOOTH_STAIRS:3)
RandomBlock(4,0,-7,SMOOTH_BRICK:0,null,40,SMOOTH_BRICK:1,null,20,SMOOTH_BRICK:2,null,30,SMOOTH_BRICK:0,null,100)
RandomBlock(4,0,-6,SMOOTH_BRICK:0,null,40,SMOOTH_BRICK:1,null,20,SMOOTH_BRICK:2,null,30,SMOOTH_BRICK:0,null,100)
RandomBlock(4,0,-5,SMOOTH_BRICK:0,null,40,SMOOTH_BRICK:1,null,20,SMOOTH_BRICK:2,null,30,SMOOTH_BRICK:0,null,100)
RandomBlock(4,0,-4,SMOOTH_BRICK:0,null,40,SMOOTH_BRICK:1,null,20,SMOOTH_BRICK:2,null,30,SMOOTH_BRICK:0,null,100)
RandomBlock(4,0,-3,SMOOTH_BRICK:0,null,40,SMOOTH_BRICK:1,null,20,SMOOTH_BRICK:2,null,30,SMOOTH_BRICK:0,null,100)
RandomBlock(4,1,-7,SMOOTH_BRICK:0,null,40,SMOOTH_BRICK:1,null,20,SMOOTH_BRICK:2,null,30,SMOOTH_BRICK:0,null,100)
RandomBlock(4,1,-6,SMOOTH_BRICK:0,null,40,SMOOTH_BRICK:1,null,20,SMOOTH_BRICK:2,null,30,SMOOTH_BRICK:0,null,100)
RandomBlock(4,1,-5,SMOOTH_BRICK:0,null,40,SMOOTH_BRICK:1,null,20,SMOOTH_BRICK:2,null,30,SMOOTH_BRICK:0,null,100)
RandomBlock(4,1,-4,SMOOTH_BRICK:0,null,40,SMOOTH_BRICK:1,null,20,SMOOTH_BRICK:2,null,30,SMOOTH_BRICK:0,null,100)
Block(4,1,-3,lycanitesmobs:lushstonetile_stairs:3)
RandomBlock(4,2,-7,SMOOTH_BRICK:0,null,40,SMOOTH_BRICK:1,null,20,SMOOTH_BRICK:2,null,30,SMOOTH_BRICK:0,null,100)
RandomBlock(4,2,-6,SMOOTH_BRICK:0,null,40,SMOOTH_BRICK:1,null,20,SMOOTH_BRICK:2,null,30,SMOOTH_BRICK:0,null,100)
Block(4,2,-5,SMOOTH_BRICK:1)
Block(4,2,-4,lycanitesmobs:lushstonetile_stairs:3)
RandomBlock(4,3,-7,SMOOTH_BRICK:0,null,40,SMOOTH_BRICK:1,null,20,SMOOTH_BRICK:2,null,30,SMOOTH_BRICK:0,null,100)
Block(4,3,-6,SMOOTH_BRICK:1)
Block(4,3,-5,lycanitesmobs:lushstonetile_stairs:3)
Block(4,4,-7,SMOOTH_BRICK:1)
Block(4,4,-6,lycanitesmobs:lushstonetile_stairs:3)
Block(4,5,-7,lycanitesmobs:lushstonetile_stairs:3)
RandomBlock(5,0,-7,SMOOTH_BRICK:0,null,40,SMOOTH_BRICK:1,null,20,SMOOTH_BRICK:2,null,30,SMOOTH_BRICK:0,null,100)
RandomBlock(5,0,-6,SMOOTH_BRICK:0,null,40,SMOOTH_BRICK:1,null,20,SMOOTH_BRICK:2,null,30,SMOOTH_BRICK:0,null,100)
RandomBlock(5,0,-5,SMOOTH_BRICK:0,null,40,SMOOTH_BRICK:1,null,20,SMOOTH_BRICK:2,null,30,SMOOTH_BRICK:0,null,100)
RandomBlock(5,0,-4,SMOOTH_BRICK:0,null,40,SMOOTH_BRICK:1,null,20,SMOOTH_BRICK:2,null,30,SMOOTH_BRICK:0,null,100)
RandomBlock(5,1,-7,SMOOTH_BRICK:0,null,40,SMOOTH_BRICK:1,null,20,SMOOTH_BRICK:2,null,30,SMOOTH_BRICK:0,null,100)
RandomBlock(5,1,-6,SMOOTH_BRICK:0,null,40,SMOOTH_BRICK:1,null,20,SMOOTH_BRICK:2,null,30,SMOOTH_BRICK:0,null,100)
Block(5,1,-5,SMOOTH_BRICK:1)
Block(5,1,-4,VINE:6)
RandomBlock(5,2,-7,SMOOTH_BRICK:0,null,40,SMOOTH_BRICK:1,null,20,SMOOTH_BRICK:2,null,30,SMOOTH_BRICK:0,null,100)
Block(5,2,-6,SMOOTH_BRICK:1)
Block(5,2,-5,lycanitesmobs:lushstone_slab:0)
Block(5,3,-7,SMOOTH_BRICK:1)
RandomBlock(6,0,-7,SMOOTH_BRICK:0,null,40,SMOOTH_BRICK:1,null,20,SMOOTH_BRICK:2,null,30,SMOOTH_BRICK:0,null,100)
RandomBlock(6,0,-6,SMOOTH_BRICK:0,null,40,SMOOTH_BRICK:1,null,20,SMOOTH_BRICK:2,null,30,SMOOTH_BRICK:0,null,100)
RandomBlock(6,0,-5,SMOOTH_BRICK:0,null,40,SMOOTH_BRICK:1,null,20,SMOOTH_BRICK:2,null,30,SMOOTH_BRICK:0,null,100)
RandomBlock(6,0,-4,SMOOTH_BRICK:0,null,40,SMOOTH_BRICK:1,null,20,SMOOTH_BRICK:2,null,30,SMOOTH_BRICK:0,null,100)
RandomBlock(6,1,-7,SMOOTH_BRICK:0,null,40,SMOOTH_BRICK:1,null,20,SMOOTH_BRICK:2,null,30,SMOOTH_BRICK:0,null,100)
RandomBlock(6,1,-6,SMOOTH_BRICK:0,null,40,SMOOTH_BRICK:1,null,20,SMOOTH_BRICK:2,null,30,SMOOTH_BRICK:0,null,100)
RandomBlock(6,1,-5,SMOOTH_BRICK:0,null,40,SMOOTH_BRICK:1,null,20,SMOOTH_BRICK:2,null,30,SMOOTH_BRICK:0,null,100)
Block(6,1,-4,VINE:4)
RandomBlock(6,2,-7,SMOOTH_BRICK:0,null,40,SMOOTH_BRICK:1,null,20,SMOOTH_BRICK:2,null,30,SMOOTH_BRICK:0,null,100)
RandomBlock(6,2,-6,SMOOTH_BRICK:0,null,40,SMOOTH_BRICK:1,null,20,SMOOTH_BRICK:2,null,30,SMOOTH_BRICK:0,null,100)
Block(6,2,-5,lycanitesmobs:lushstone_slab:0)
RandomBlock(6,3,-7,SMOOTH_BRICK:0,null,40,SMOOTH_BRICK:1,null,20,SMOOTH_BRICK:2,null,30,SMOOTH_BRICK:0,null,100)
Block(6,3,-6,VINE:4)
RandomBlock(7,0,-7,SMOOTH_BRICK:0,null,40,SMOOTH_BRICK:1,null,20,SMOOTH_BRICK:2,null,30,SMOOTH_BRICK:0,null,100)
RandomBlock(7,0,-6,SMOOTH_BRICK:0,null,40,SMOOTH_BRICK:1,null,20,SMOOTH_BRICK:2,null,30,SMOOTH_BRICK:0,null,100)
RandomBlock(7,0,-5,SMOOTH_BRICK:0,null,40,SMOOTH_BRICK:1,null,20,SMOOTH_BRICK:2,null,30,SMOOTH_BRICK:0,null,100)
RandomBlock(7,0,-4,SMOOTH_BRICK:0,null,40,SMOOTH_BRICK:1,null,20,SMOOTH_BRICK:2,null,30,SMOOTH_BRICK:0,null,100)
RandomBlock(7,1,-7,SMOOTH_BRICK:0,null,40,SMOOTH_BRICK:1,null,20,SMOOTH_BRICK:2,null,30,SMOOTH_BRICK:0,null,100)
RandomBlock(7,1,-6,SMOOTH_BRICK:0,null,40,SMOOTH_BRICK:1,null,20,SMOOTH_BRICK:2,null,30,SMOOTH_BRICK:0,null,100)
RandomBlock(7,1,-5,SMOOTH_BRICK:0,null,40,SMOOTH_BRICK:1,null,20,SMOOTH_BRICK:2,null,30,SMOOTH_BRICK:0,null,100)
Block(7,1,-4,VINE:4)
Block(7,2,-7,SMOOTH_BRICK:2)
RandomBlock(7,2,-6,SMOOTH_BRICK:0,null,40,SMOOTH_BRICK:1,null,20,SMOOTH_BRICK:2,null,30,SMOOTH_BRICK:0,null,100)
Block(7,2,-5,lycanitesmobs:lushstone_slab:0)
RandomBlock(7,3,-7,SMOOTH_BRICK:0,null,40,SMOOTH_BRICK:1,null,20,SMOOTH_BRICK:2,null,30,SMOOTH_BRICK:0,null,100)
Block(7,4,-7,VINE:4)

#######################################################################
# +-----------------------------------------------------------------+ #
# |                             Branches                            | #
# +-----------------------------------------------------------------+ #
#######################################################################


#######################################################################
# +-----------------------------------------------------------------+ #
# |                             Entities                            | #
# +-----------------------------------------------------------------+ #
#######################################################################


#######################################################################
# +-----------------------------------------------------------------+ #
# |                            Particles                            | #
# +-----------------------------------------------------------------+ #
#######################################################################


#######################################################################
# +-----------------------------------------------------------------+ #
# |                             Spawners                            | #
# +-----------------------------------------------------------------+ #
#######################################################################


#######################################################################
# +-----------------------------------------------------------------+ #
# |                             ModData                             | #
# +-----------------------------------------------------------------+ #
#######################################################################

