
#######################################################################
# +-----------------------------------------------------------------+ #
# |                            BO4 object                           | #
# +-----------------------------------------------------------------+ #
#######################################################################

Author: NLBlackEagle

Description: No description given

SettingsMode: WriteWithoutComments


#######################################################################
# +-----------------------------------------------------------------+ #
# |                          Main settings                          | #
# +-----------------------------------------------------------------+ #
#######################################################################

FixedRotation: 

Frequency: 0

SpawnHeight: highestBlock

UseCenterForHighestBlock: true

##############################
# Height Limits for the BO4. #
##############################

MinHeight: 0

MaxHeight: 255

InheritBO3: 

InheritBO3Rotation: NORTH

OverrideChildSettings: true

OverrideParentHeight: false

CanOverride: true

BranchFrequency: 0

BranchFrequencyGroup: 

MustBeBelowOther: false

MustBeInside: 

CannotBeInside: 

ReplacesBO3: 

MustBeInsideWorldBorders: false

CanSpawnOnWater: true

SpawnOnWaterOnly: false

SpawnUnderWater: false

SpawnAtWaterLevel: false

HeightOffset: 0

RemoveAir: false

ReplaceAbove: 

ReplaceBelow: 

ReplaceWithBiomeBlocks: false

ReplaceWithSurfaceBlock: GRASS

ReplaceWithGroundBlock: DIRT

ReplaceWithStoneBlock: STONE

SmoothRadius: 0

SmoothHeightOffset: 0

SmoothStartTop: false

SmoothStartWood: false

SmoothingSurfaceBlock: 

SmoothingGroundBlock: 

BO3Group: 

IsSpawnPoint: false

DoReplaceBlocks: true


#######################################################################
# +-----------------------------------------------------------------+ #
# |                              Blocks                             | #
# +-----------------------------------------------------------------+ #
#######################################################################

RandomBlock(-8,0,1,SMOOTH_BRICK:0,40,SMOOTH_BRICK:1,20,SMOOTH_BRICK:2,30,SMOOTH_BRICK:0,100)
RandomBlock(-8,0,2,SMOOTH_BRICK:0,40,SMOOTH_BRICK:1,20,SMOOTH_BRICK:2,30,SMOOTH_BRICK:0,100)
RandomBlock(-8,0,3,SMOOTH_BRICK:0,40,SMOOTH_BRICK:1,20,SMOOTH_BRICK:2,30,SMOOTH_BRICK:0,100)
RandomBlock(-8,0,4,SMOOTH_BRICK:0,40,SMOOTH_BRICK:1,20,SMOOTH_BRICK:2,30,SMOOTH_BRICK:0,100)
RandomBlock(-8,0,5,SMOOTH_BRICK:0,40,SMOOTH_BRICK:1,20,SMOOTH_BRICK:2,30,SMOOTH_BRICK:0,100)
Block(-8,1,1,lycanitesmobs:lushstonetile_stairs:0)
Block(-8,1,5,lycanitesmobs:lushstonetile_stairs:0)
RandomBlock(-7,0,-6,SMOOTH_BRICK:0,40,SMOOTH_BRICK:1,20,SMOOTH_BRICK:2,30,SMOOTH_BRICK:0,100)
RandomBlock(-7,0,-5,SMOOTH_BRICK:0,40,SMOOTH_BRICK:1,20,SMOOTH_BRICK:2,30,SMOOTH_BRICK:0,100)
RandomBlock(-7,0,-4,SMOOTH_BRICK:0,40,SMOOTH_BRICK:1,20,SMOOTH_BRICK:2,30,SMOOTH_BRICK:0,100)
RandomBlock(-7,0,-3,SMOOTH_BRICK:0,40,SMOOTH_BRICK:1,20,SMOOTH_BRICK:2,30,SMOOTH_BRICK:0,100)
RandomBlock(-7,0,-2,SMOOTH_BRICK:0,40,SMOOTH_BRICK:1,20,SMOOTH_BRICK:2,30,SMOOTH_BRICK:0,100)
RandomBlock(-7,0,-1,SMOOTH_BRICK:0,40,SMOOTH_BRICK:1,20,SMOOTH_BRICK:2,30,SMOOTH_BRICK:0,100)
RandomBlock(-7,0,0,SMOOTH_BRICK:0,40,SMOOTH_BRICK:1,20,SMOOTH_BRICK:2,30,SMOOTH_BRICK:0,100)
RandomBlock(-7,0,1,SMOOTH_BRICK:0,40,SMOOTH_BRICK:1,20,SMOOTH_BRICK:2,30,SMOOTH_BRICK:0,100)
RandomBlock(-7,0,2,SMOOTH_BRICK:0,40,SMOOTH_BRICK:1,20,SMOOTH_BRICK:2,30,SMOOTH_BRICK:0,100)
RandomBlock(-7,0,3,SMOOTH_BRICK:0,40,SMOOTH_BRICK:1,20,SMOOTH_BRICK:2,30,SMOOTH_BRICK:0,100)
RandomBlock(-7,0,4,SMOOTH_BRICK:0,40,SMOOTH_BRICK:1,20,SMOOTH_BRICK:2,30,SMOOTH_BRICK:0,100)
RandomBlock(-7,0,5,SMOOTH_BRICK:0,40,SMOOTH_BRICK:1,20,SMOOTH_BRICK:2,30,SMOOTH_BRICK:0,100)
RandomBlock(-7,0,6,SMOOTH_BRICK:0,40,SMOOTH_BRICK:1,20,SMOOTH_BRICK:2,30,SMOOTH_BRICK:0,100)
RandomBlock(-7,0,7,SMOOTH_BRICK:0,40,SMOOTH_BRICK:1,20,SMOOTH_BRICK:2,30,SMOOTH_BRICK:0,100)
RandomBlock(-7,0,8,SMOOTH_BRICK:0,40,SMOOTH_BRICK:1,20,SMOOTH_BRICK:2,30,SMOOTH_BRICK:0,100)
Block(-7,1,1,SMOOTH_BRICK:2)
Block(-7,1,2,SMOOTH_STAIRS:0)
Block(-7,1,3,STEP:5)
Block(-7,1,4,SMOOTH_STAIRS:0)
Block(-7,1,5,SMOOTH_BRICK:1)
Block(-7,2,1,lycanitesmobs:lushstonetile_stairs:0)
Block(-7,2,5,lycanitesmobs:lushstonetile_stairs:0)
RandomBlock(-6,0,-6,SMOOTH_BRICK:0,40,SMOOTH_BRICK:1,20,SMOOTH_BRICK:2,30,SMOOTH_BRICK:0,100)
RandomBlock(-6,0,-5,SMOOTH_BRICK:0,40,SMOOTH_BRICK:1,20,SMOOTH_BRICK:2,30,SMOOTH_BRICK:0,100)
RandomBlock(-6,0,-4,SMOOTH_BRICK:0,40,SMOOTH_BRICK:1,20,SMOOTH_BRICK:2,30,SMOOTH_BRICK:0,100)
RandomBlock(-6,0,-3,SMOOTH_BRICK:0,40,SMOOTH_BRICK:1,20,SMOOTH_BRICK:2,30,SMOOTH_BRICK:0,100)
RandomBlock(-6,0,-2,SMOOTH_BRICK:0,40,SMOOTH_BRICK:1,20,SMOOTH_BRICK:2,30,SMOOTH_BRICK:0,100)
RandomBlock(-6,0,-1,SMOOTH_BRICK:0,40,SMOOTH_BRICK:1,20,SMOOTH_BRICK:2,30,SMOOTH_BRICK:0,100)
RandomBlock(-6,0,0,SMOOTH_BRICK:0,40,SMOOTH_BRICK:1,20,SMOOTH_BRICK:2,30,SMOOTH_BRICK:0,100)
RandomBlock(-6,0,1,SMOOTH_BRICK:0,40,SMOOTH_BRICK:1,20,SMOOTH_BRICK:2,30,SMOOTH_BRICK:0,100)
RandomBlock(-6,0,2,SMOOTH_BRICK:0,40,SMOOTH_BRICK:1,20,SMOOTH_BRICK:2,30,SMOOTH_BRICK:0,100)
RandomBlock(-6,0,3,SMOOTH_BRICK:0,40,SMOOTH_BRICK:1,20,SMOOTH_BRICK:2,30,SMOOTH_BRICK:0,100)
RandomBlock(-6,0,4,SMOOTH_BRICK:0,40,SMOOTH_BRICK:1,20,SMOOTH_BRICK:2,30,SMOOTH_BRICK:0,100)
RandomBlock(-6,0,5,SMOOTH_BRICK:0,40,SMOOTH_BRICK:1,20,SMOOTH_BRICK:2,30,SMOOTH_BRICK:0,100)
RandomBlock(-6,0,6,SMOOTH_BRICK:0,40,SMOOTH_BRICK:1,20,SMOOTH_BRICK:2,30,SMOOTH_BRICK:0,100)
RandomBlock(-6,0,7,SMOOTH_BRICK:0,40,SMOOTH_BRICK:1,20,SMOOTH_BRICK:2,30,SMOOTH_BRICK:0,100)
RandomBlock(-6,0,8,SMOOTH_BRICK:0,40,SMOOTH_BRICK:1,20,SMOOTH_BRICK:2,30,SMOOTH_BRICK:0,100)
Block(-6,1,-5,SMOOTH_BRICK:2)
Block(-6,1,-4,SMOOTH_BRICK:1)
RandomBlock(-6,1,-3,SMOOTH_BRICK:0,40,SMOOTH_BRICK:1,20,SMOOTH_BRICK:2,30,SMOOTH_BRICK:0,100)
RandomBlock(-6,1,-2,SMOOTH_BRICK:0,40,SMOOTH_BRICK:1,20,SMOOTH_BRICK:2,30,SMOOTH_BRICK:0,100)
RandomBlock(-6,1,-1,SMOOTH_BRICK:0,40,SMOOTH_BRICK:1,20,SMOOTH_BRICK:2,30,SMOOTH_BRICK:0,100)
RandomBlock(-6,1,0,SMOOTH_BRICK:0,40,SMOOTH_BRICK:1,20,SMOOTH_BRICK:2,30,SMOOTH_BRICK:0,100)
RandomBlock(-6,1,1,SMOOTH_BRICK:0,40,SMOOTH_BRICK:1,20,SMOOTH_BRICK:2,30,SMOOTH_BRICK:0,100)
RandomBlock(-6,1,2,SMOOTH_BRICK:0,40,SMOOTH_BRICK:1,20,SMOOTH_BRICK:2,30,SMOOTH_BRICK:0,100)
Block(-6,1,3,SMOOTH_BRICK:1)
RandomBlock(-6,1,4,SMOOTH_BRICK:0,40,SMOOTH_BRICK:1,20,SMOOTH_BRICK:2,30,SMOOTH_BRICK:0,100)
RandomBlock(-6,1,5,SMOOTH_BRICK:0,40,SMOOTH_BRICK:1,20,SMOOTH_BRICK:2,30,SMOOTH_BRICK:0,100)
RandomBlock(-6,1,6,SMOOTH_BRICK:0,40,SMOOTH_BRICK:1,20,SMOOTH_BRICK:2,30,SMOOTH_BRICK:0,100)
Block(-6,1,7,SMOOTH_BRICK:1)
Block(-6,1,8,SMOOTH_BRICK:1)
Block(-6,2,-5,lycanitesmobs:lushstone_slab:0)
Block(-6,2,-4,lycanitesmobs:lushstone_slab:0)
Block(-6,2,-3,lycanitesmobs:lushstone_slab:0)
Block(-6,2,-2,lycanitesmobs:lushstone_slab:0)
Block(-6,2,-1,lycanitesmobs:lushstone_slab:0)
Block(-6,2,0,lycanitesmobs:lushstone_slab:0)
Block(-6,2,1,SMOOTH_BRICK:1)
Block(-6,2,2,SMOOTH_STAIRS:0)
Block(-6,2,3,AIR:0)
Block(-6,2,4,SMOOTH_STAIRS:0)
Block(-6,2,5,SMOOTH_BRICK:1)
Block(-6,2,6,lycanitesmobs:lushstone_slab:0)
Block(-6,2,7,lycanitesmobs:lushstone_slab:0)
Block(-6,2,8,lycanitesmobs:lushstone_slab:0)
Block(-6,3,1,lycanitesmobs:lushstonetile_stairs:0)
Block(-6,3,5,lycanitesmobs:lushstonetile_stairs:0)
RandomBlock(-5,0,-6,SMOOTH_BRICK:0,40,SMOOTH_BRICK:1,20,SMOOTH_BRICK:2,30,SMOOTH_BRICK:0,100)
RandomBlock(-5,0,-5,SMOOTH_BRICK:0,40,SMOOTH_BRICK:1,20,SMOOTH_BRICK:2,30,SMOOTH_BRICK:0,100)
RandomBlock(-5,0,-4,SMOOTH_BRICK:0,40,SMOOTH_BRICK:1,20,SMOOTH_BRICK:2,30,SMOOTH_BRICK:0,100)
RandomBlock(-5,0,-3,SMOOTH_BRICK:0,40,SMOOTH_BRICK:1,20,SMOOTH_BRICK:2,30,SMOOTH_BRICK:0,100)
RandomBlock(-5,0,-2,SMOOTH_BRICK:0,40,SMOOTH_BRICK:1,20,SMOOTH_BRICK:2,30,SMOOTH_BRICK:0,100)
RandomBlock(-5,0,-1,SMOOTH_BRICK:0,40,SMOOTH_BRICK:1,20,SMOOTH_BRICK:2,30,SMOOTH_BRICK:0,100)
RandomBlock(-5,0,0,SMOOTH_BRICK:0,40,SMOOTH_BRICK:1,20,SMOOTH_BRICK:2,30,SMOOTH_BRICK:0,100)
RandomBlock(-5,0,1,SMOOTH_BRICK:0,40,SMOOTH_BRICK:1,20,SMOOTH_BRICK:2,30,SMOOTH_BRICK:0,100)
RandomBlock(-5,0,2,SMOOTH_BRICK:0,40,SMOOTH_BRICK:1,20,SMOOTH_BRICK:2,30,SMOOTH_BRICK:0,100)
RandomBlock(-5,0,3,SMOOTH_BRICK:0,40,SMOOTH_BRICK:1,20,SMOOTH_BRICK:2,30,SMOOTH_BRICK:0,100)
RandomBlock(-5,0,4,SMOOTH_BRICK:0,40,SMOOTH_BRICK:1,20,SMOOTH_BRICK:2,30,SMOOTH_BRICK:0,100)
RandomBlock(-5,0,5,SMOOTH_BRICK:0,40,SMOOTH_BRICK:1,20,SMOOTH_BRICK:2,30,SMOOTH_BRICK:0,100)
RandomBlock(-5,0,6,SMOOTH_BRICK:0,40,SMOOTH_BRICK:1,20,SMOOTH_BRICK:2,30,SMOOTH_BRICK:0,100)
RandomBlock(-5,0,7,SMOOTH_BRICK:0,40,SMOOTH_BRICK:1,20,SMOOTH_BRICK:2,30,SMOOTH_BRICK:0,100)
RandomBlock(-5,0,8,SMOOTH_BRICK:0,40,SMOOTH_BRICK:1,20,SMOOTH_BRICK:2,30,SMOOTH_BRICK:0,100)
RandomBlock(-5,1,-5,SMOOTH_BRICK:0,40,SMOOTH_BRICK:1,20,SMOOTH_BRICK:2,30,SMOOTH_BRICK:0,100)
RandomBlock(-5,1,-4,SMOOTH_BRICK:0,40,SMOOTH_BRICK:1,20,SMOOTH_BRICK:2,30,SMOOTH_BRICK:0,100)
RandomBlock(-5,1,-3,SMOOTH_BRICK:0,40,SMOOTH_BRICK:1,20,SMOOTH_BRICK:2,30,SMOOTH_BRICK:0,100)
RandomBlock(-5,1,-2,SMOOTH_BRICK:0,40,SMOOTH_BRICK:1,20,SMOOTH_BRICK:2,30,SMOOTH_BRICK:0,100)
RandomBlock(-5,1,-1,SMOOTH_BRICK:0,40,SMOOTH_BRICK:1,20,SMOOTH_BRICK:2,30,SMOOTH_BRICK:0,100)
RandomBlock(-5,1,0,SMOOTH_BRICK:0,40,SMOOTH_BRICK:1,20,SMOOTH_BRICK:2,30,SMOOTH_BRICK:0,100)
RandomBlock(-5,1,1,SMOOTH_BRICK:0,40,SMOOTH_BRICK:1,20,SMOOTH_BRICK:2,30,SMOOTH_BRICK:0,100)
RandomBlock(-5,1,2,SMOOTH_BRICK:0,40,SMOOTH_BRICK:1,20,SMOOTH_BRICK:2,30,SMOOTH_BRICK:0,100)
Block(-5,1,3,SMOOTH_BRICK:1)
RandomBlock(-5,1,4,SMOOTH_BRICK:0,40,SMOOTH_BRICK:1,20,SMOOTH_BRICK:2,30,SMOOTH_BRICK:0,100)
RandomBlock(-5,1,5,SMOOTH_BRICK:0,40,SMOOTH_BRICK:1,20,SMOOTH_BRICK:2,30,SMOOTH_BRICK:0,100)
RandomBlock(-5,1,6,SMOOTH_BRICK:0,40,SMOOTH_BRICK:1,20,SMOOTH_BRICK:2,30,SMOOTH_BRICK:0,100)
RandomBlock(-5,1,7,SMOOTH_BRICK:0,40,SMOOTH_BRICK:1,20,SMOOTH_BRICK:2,30,SMOOTH_BRICK:0,100)
RandomBlock(-5,1,8,SMOOTH_BRICK:0,40,SMOOTH_BRICK:1,20,SMOOTH_BRICK:2,30,SMOOTH_BRICK:0,100)
Block(-5,2,-5,lycanitesmobs:lushstone_slab:0)
RandomBlock(-5,2,-4,SMOOTH_BRICK:0,40,SMOOTH_BRICK:1,20,SMOOTH_BRICK:2,30,SMOOTH_BRICK:0,100)
RandomBlock(-5,2,-3,SMOOTH_BRICK:0,40,SMOOTH_BRICK:1,20,SMOOTH_BRICK:2,30,SMOOTH_BRICK:0,100)
RandomBlock(-5,2,-2,SMOOTH_BRICK:0,40,SMOOTH_BRICK:1,20,SMOOTH_BRICK:2,30,SMOOTH_BRICK:0,100)
RandomBlock(-5,2,-1,SMOOTH_BRICK:0,40,SMOOTH_BRICK:1,20,SMOOTH_BRICK:2,30,SMOOTH_BRICK:0,100)
Block(-5,2,0,SMOOTH_BRICK:2)
RandomBlock(-5,2,1,SMOOTH_BRICK:0,40,SMOOTH_BRICK:1,20,SMOOTH_BRICK:2,30,SMOOTH_BRICK:0,100)
RandomBlock(-5,2,2,SMOOTH_BRICK:0,40,SMOOTH_BRICK:1,20,SMOOTH_BRICK:2,30,SMOOTH_BRICK:0,100)
Block(-5,2,3,AIR:0)
RandomBlock(-5,2,4,SMOOTH_BRICK:0,40,SMOOTH_BRICK:1,20,SMOOTH_BRICK:2,30,SMOOTH_BRICK:0,100)
RandomBlock(-5,2,5,SMOOTH_BRICK:0,40,SMOOTH_BRICK:1,20,SMOOTH_BRICK:2,30,SMOOTH_BRICK:0,100)
Block(-5,2,6,SMOOTH_BRICK:1)
RandomBlock(-5,2,7,SMOOTH_BRICK:0,40,SMOOTH_BRICK:1,20,SMOOTH_BRICK:2,30,SMOOTH_BRICK:0,100)
RandomBlock(-5,2,8,SMOOTH_BRICK:0,40,SMOOTH_BRICK:1,20,SMOOTH_BRICK:2,30,SMOOTH_BRICK:0,100)
Block(-5,3,-2,VINE:8)
Block(-5,3,-1,VINE:8)
Block(-5,3,1,SMOOTH_BRICK:1)
Block(-5,3,2,SMOOTH_STAIRS:0)
Block(-5,3,3,AIR:0)
Block(-5,3,4,SMOOTH_STAIRS:0)
Block(-5,3,5,SMOOTH_BRICK:1)
Block(-5,3,7,VINE:8)
Block(-5,4,1,lycanitesmobs:lushstonetile_stairs:0)
Block(-5,4,5,lycanitesmobs:lushstonetile_stairs:0)
RandomBlock(-4,0,-6,SMOOTH_BRICK:0,40,SMOOTH_BRICK:1,20,SMOOTH_BRICK:2,30,SMOOTH_BRICK:0,100)
RandomBlock(-4,0,-5,SMOOTH_BRICK:0,40,SMOOTH_BRICK:1,20,SMOOTH_BRICK:2,30,SMOOTH_BRICK:0,100)
RandomBlock(-4,0,-4,SMOOTH_BRICK:0,40,SMOOTH_BRICK:1,20,SMOOTH_BRICK:2,30,SMOOTH_BRICK:0,100)
RandomBlock(-4,0,-3,SMOOTH_BRICK:0,40,SMOOTH_BRICK:1,20,SMOOTH_BRICK:2,30,SMOOTH_BRICK:0,100)
RandomBlock(-4,0,-2,SMOOTH_BRICK:0,40,SMOOTH_BRICK:1,20,SMOOTH_BRICK:2,30,SMOOTH_BRICK:0,100)
RandomBlock(-4,0,-1,SMOOTH_BRICK:0,40,SMOOTH_BRICK:1,20,SMOOTH_BRICK:2,30,SMOOTH_BRICK:0,100)
RandomBlock(-4,0,0,SMOOTH_BRICK:0,40,SMOOTH_BRICK:1,20,SMOOTH_BRICK:2,30,SMOOTH_BRICK:0,100)
RandomBlock(-4,0,1,SMOOTH_BRICK:0,40,SMOOTH_BRICK:1,20,SMOOTH_BRICK:2,30,SMOOTH_BRICK:0,100)
RandomBlock(-4,0,2,SMOOTH_BRICK:0,40,SMOOTH_BRICK:1,20,SMOOTH_BRICK:2,30,SMOOTH_BRICK:0,100)
RandomBlock(-4,0,3,SMOOTH_BRICK:0,40,SMOOTH_BRICK:1,20,SMOOTH_BRICK:2,30,SMOOTH_BRICK:0,100)
RandomBlock(-4,0,4,SMOOTH_BRICK:0,40,SMOOTH_BRICK:1,20,SMOOTH_BRICK:2,30,SMOOTH_BRICK:0,100)
RandomBlock(-4,0,5,SMOOTH_BRICK:0,40,SMOOTH_BRICK:1,20,SMOOTH_BRICK:2,30,SMOOTH_BRICK:0,100)
RandomBlock(-4,0,6,SMOOTH_BRICK:0,40,SMOOTH_BRICK:1,20,SMOOTH_BRICK:2,30,SMOOTH_BRICK:0,100)
RandomBlock(-4,0,7,SMOOTH_BRICK:0,40,SMOOTH_BRICK:1,20,SMOOTH_BRICK:2,30,SMOOTH_BRICK:0,100)
RandomBlock(-4,0,8,SMOOTH_BRICK:0,40,SMOOTH_BRICK:1,20,SMOOTH_BRICK:2,30,SMOOTH_BRICK:0,100)
Block(-4,1,-5,SMOOTH_BRICK:1)
RandomBlock(-4,1,-4,SMOOTH_BRICK:0,40,SMOOTH_BRICK:1,20,SMOOTH_BRICK:2,30,SMOOTH_BRICK:0,100)
RandomBlock(-4,1,-3,SMOOTH_BRICK:0,40,SMOOTH_BRICK:1,20,SMOOTH_BRICK:2,30,SMOOTH_BRICK:0,100)
RandomBlock(-4,1,-2,SMOOTH_BRICK:0,40,SMOOTH_BRICK:1,20,SMOOTH_BRICK:2,30,SMOOTH_BRICK:0,100)
RandomBlock(-4,1,-1,SMOOTH_BRICK:0,40,SMOOTH_BRICK:1,20,SMOOTH_BRICK:2,30,SMOOTH_BRICK:0,100)
RandomBlock(-4,1,0,SMOOTH_BRICK:0,40,SMOOTH_BRICK:1,20,SMOOTH_BRICK:2,30,SMOOTH_BRICK:0,100)
RandomBlock(-4,1,1,SMOOTH_BRICK:0,40,SMOOTH_BRICK:1,20,SMOOTH_BRICK:2,30,SMOOTH_BRICK:0,100)
RandomBlock(-4,1,2,SMOOTH_BRICK:0,40,SMOOTH_BRICK:1,20,SMOOTH_BRICK:2,30,SMOOTH_BRICK:0,100)
Block(-4,1,3,SMOOTH_BRICK:1)
RandomBlock(-4,1,4,SMOOTH_BRICK:0,40,SMOOTH_BRICK:1,20,SMOOTH_BRICK:2,30,SMOOTH_BRICK:0,100)
RandomBlock(-4,1,5,SMOOTH_BRICK:0,40,SMOOTH_BRICK:1,20,SMOOTH_BRICK:2,30,SMOOTH_BRICK:0,100)
RandomBlock(-4,1,6,SMOOTH_BRICK:0,40,SMOOTH_BRICK:1,20,SMOOTH_BRICK:2,30,SMOOTH_BRICK:0,100)
RandomBlock(-4,1,7,SMOOTH_BRICK:0,40,SMOOTH_BRICK:1,20,SMOOTH_BRICK:2,30,SMOOTH_BRICK:0,100)
RandomBlock(-4,1,8,SMOOTH_BRICK:0,40,SMOOTH_BRICK:1,20,SMOOTH_BRICK:2,30,SMOOTH_BRICK:0,100)
Block(-4,2,-5,lycanitesmobs:lushstone_slab:0)
Block(-4,2,-4,SMOOTH_BRICK:2)
Block(-4,2,-3,SMOOTH_BRICK:1)
RandomBlock(-4,2,-2,SMOOTH_BRICK:0,40,SMOOTH_BRICK:1,20,SMOOTH_BRICK:2,30,SMOOTH_BRICK:0,100)
RandomBlock(-4,2,-1,SMOOTH_BRICK:0,40,SMOOTH_BRICK:1,20,SMOOTH_BRICK:2,30,SMOOTH_BRICK:0,100)
RandomBlock(-4,2,0,SMOOTH_BRICK:0,40,SMOOTH_BRICK:1,20,SMOOTH_BRICK:2,30,SMOOTH_BRICK:0,100)
Block(-4,2,1,SMOOTH_BRICK:1)
Block(-4,2,2,SMOOTH_BRICK:1)
Block(-4,2,3,AIR:0)
Block(-4,2,4,SMOOTH_BRICK:1)
Block(-4,2,5,SMOOTH_BRICK:1)
RandomBlock(-4,2,6,SMOOTH_BRICK:0,40,SMOOTH_BRICK:1,20,SMOOTH_BRICK:2,30,SMOOTH_BRICK:0,100)
Block(-4,2,7,SMOOTH_BRICK:1)
Block(-4,2,8,SMOOTH_BRICK:1)
Block(-4,3,-4,VINE:1)
RandomBlock(-4,3,-3,SMOOTH_BRICK:0,40,SMOOTH_BRICK:1,20,SMOOTH_BRICK:2,30,SMOOTH_BRICK:0,100)
RandomBlock(-4,3,-2,SMOOTH_BRICK:0,40,SMOOTH_BRICK:1,20,SMOOTH_BRICK:2,30,SMOOTH_BRICK:0,100)
RandomBlock(-4,3,-1,SMOOTH_BRICK:0,40,SMOOTH_BRICK:1,20,SMOOTH_BRICK:2,30,SMOOTH_BRICK:0,100)
RandomBlock(-4,3,0,SMOOTH_BRICK:0,40,SMOOTH_BRICK:1,20,SMOOTH_BRICK:2,30,SMOOTH_BRICK:0,100)
RandomBlock(-4,3,1,SMOOTH_BRICK:0,40,SMOOTH_BRICK:1,20,SMOOTH_BRICK:2,30,SMOOTH_BRICK:0,100)
RandomBlock(-4,3,2,SMOOTH_BRICK:0,40,SMOOTH_BRICK:1,20,SMOOTH_BRICK:2,30,SMOOTH_BRICK:0,100)
Block(-4,3,3,AIR:0)
RandomBlock(-4,3,4,SMOOTH_BRICK:0,40,SMOOTH_BRICK:1,20,SMOOTH_BRICK:2,30,SMOOTH_BRICK:0,100)
RandomBlock(-4,3,5,SMOOTH_BRICK:0,40,SMOOTH_BRICK:1,20,SMOOTH_BRICK:2,30,SMOOTH_BRICK:0,100)
Block(-4,3,6,SMOOTH_BRICK:1)
RandomBlock(-4,3,7,SMOOTH_BRICK:0,40,SMOOTH_BRICK:1,20,SMOOTH_BRICK:2,30,SMOOTH_BRICK:0,100)
RandomBlock(-4,3,8,SMOOTH_BRICK:0,40,SMOOTH_BRICK:1,20,SMOOTH_BRICK:2,30,SMOOTH_BRICK:0,100)
Block(-4,4,-2,VINE:8)
Block(-4,4,-1,VINE:8)
Block(-4,4,1,SMOOTH_BRICK:1)
Block(-4,4,2,SMOOTH_STAIRS:0)
Block(-4,4,3,SMOOTH_STAIRS:0)
Block(-4,4,4,SMOOTH_STAIRS:0)
Block(-4,4,5,SMOOTH_BRICK:1)
Block(-4,5,1,lycanitesmobs:lushstonetile_stairs:0)
Block(-4,5,5,lycanitesmobs:lushstonetile_stairs:0)
RandomBlock(-3,0,-6,SMOOTH_BRICK:0,40,SMOOTH_BRICK:1,20,SMOOTH_BRICK:2,30,SMOOTH_BRICK:0,100)
RandomBlock(-3,0,-5,SMOOTH_BRICK:0,40,SMOOTH_BRICK:1,20,SMOOTH_BRICK:2,30,SMOOTH_BRICK:0,100)
RandomBlock(-3,0,-4,SMOOTH_BRICK:0,40,SMOOTH_BRICK:1,20,SMOOTH_BRICK:2,30,SMOOTH_BRICK:0,100)
RandomBlock(-3,0,-3,SMOOTH_BRICK:0,40,SMOOTH_BRICK:1,20,SMOOTH_BRICK:2,30,SMOOTH_BRICK:0,100)
RandomBlock(-3,0,-2,SMOOTH_BRICK:0,40,SMOOTH_BRICK:1,20,SMOOTH_BRICK:2,30,SMOOTH_BRICK:0,100)
RandomBlock(-3,0,-1,SMOOTH_BRICK:0,40,SMOOTH_BRICK:1,20,SMOOTH_BRICK:2,30,SMOOTH_BRICK:0,100)
RandomBlock(-3,0,0,SMOOTH_BRICK:0,40,SMOOTH_BRICK:1,20,SMOOTH_BRICK:2,30,SMOOTH_BRICK:0,100)
RandomBlock(-3,0,1,SMOOTH_BRICK:0,40,SMOOTH_BRICK:1,20,SMOOTH_BRICK:2,30,SMOOTH_BRICK:0,100)
RandomBlock(-3,0,2,SMOOTH_BRICK:0,40,SMOOTH_BRICK:1,20,SMOOTH_BRICK:2,30,SMOOTH_BRICK:0,100)
RandomBlock(-3,0,3,SMOOTH_BRICK:0,40,SMOOTH_BRICK:1,20,SMOOTH_BRICK:2,30,SMOOTH_BRICK:0,100)
RandomBlock(-3,0,4,SMOOTH_BRICK:0,40,SMOOTH_BRICK:1,20,SMOOTH_BRICK:2,30,SMOOTH_BRICK:0,100)
RandomBlock(-3,0,5,SMOOTH_BRICK:0,40,SMOOTH_BRICK:1,20,SMOOTH_BRICK:2,30,SMOOTH_BRICK:0,100)
RandomBlock(-3,0,6,SMOOTH_BRICK:0,40,SMOOTH_BRICK:1,20,SMOOTH_BRICK:2,30,SMOOTH_BRICK:0,100)
RandomBlock(-3,0,7,SMOOTH_BRICK:0,40,SMOOTH_BRICK:1,20,SMOOTH_BRICK:2,30,SMOOTH_BRICK:0,100)
RandomBlock(-3,0,8,SMOOTH_BRICK:0,40,SMOOTH_BRICK:1,20,SMOOTH_BRICK:2,30,SMOOTH_BRICK:0,100)
Block(-3,1,-5,SMOOTH_BRICK:1)
RandomBlock(-3,1,-4,SMOOTH_BRICK:0,40,SMOOTH_BRICK:1,20,SMOOTH_BRICK:2,30,SMOOTH_BRICK:0,100)
RandomBlock(-3,1,-3,SMOOTH_BRICK:0,40,SMOOTH_BRICK:1,20,SMOOTH_BRICK:2,30,SMOOTH_BRICK:0,100)
RandomBlock(-3,1,-2,SMOOTH_BRICK:0,40,SMOOTH_BRICK:1,20,SMOOTH_BRICK:2,30,SMOOTH_BRICK:0,100)
RandomBlock(-3,1,-1,SMOOTH_BRICK:0,40,SMOOTH_BRICK:1,20,SMOOTH_BRICK:2,30,SMOOTH_BRICK:0,100)
RandomBlock(-3,1,0,SMOOTH_BRICK:0,40,SMOOTH_BRICK:1,20,SMOOTH_BRICK:2,30,SMOOTH_BRICK:0,100)
RandomBlock(-3,1,1,SMOOTH_BRICK:0,40,SMOOTH_BRICK:1,20,SMOOTH_BRICK:2,30,SMOOTH_BRICK:0,100)
RandomBlock(-3,1,2,SMOOTH_BRICK:0,40,SMOOTH_BRICK:1,20,SMOOTH_BRICK:2,30,SMOOTH_BRICK:0,100)
Block(-3,1,3,SMOOTH_BRICK:1)
RandomBlock(-3,1,4,SMOOTH_BRICK:0,40,SMOOTH_BRICK:1,20,SMOOTH_BRICK:2,30,SMOOTH_BRICK:0,100)
RandomBlock(-3,1,5,SMOOTH_BRICK:0,40,SMOOTH_BRICK:1,20,SMOOTH_BRICK:2,30,SMOOTH_BRICK:0,100)
RandomBlock(-3,1,6,SMOOTH_BRICK:0,40,SMOOTH_BRICK:1,20,SMOOTH_BRICK:2,30,SMOOTH_BRICK:0,100)
RandomBlock(-3,1,7,SMOOTH_BRICK:0,40,SMOOTH_BRICK:1,20,SMOOTH_BRICK:2,30,SMOOTH_BRICK:0,100)
RandomBlock(-3,1,8,SMOOTH_BRICK:0,40,SMOOTH_BRICK:1,20,SMOOTH_BRICK:2,30,SMOOTH_BRICK:0,100)
Block(-3,2,-5,lycanitesmobs:lushstone_slab:0)
Block(-3,2,-4,SMOOTH_BRICK:1)
Block(-3,2,-3,SMOOTH_BRICK:1)
Block(-3,2,-2,rustic:stone_pillar:0)
Block(-3,2,-1,AIR:0)
Block(-3,2,0,AIR:0)
Block(-3,2,1,rustic:stone_pillar:0)
Block(-3,2,2,AIR:0)
Block(-3,2,3,AIR:0)
Block(-3,2,4,AIR:0)
Block(-3,2,5,rustic:stone_pillar:0)
RandomBlock(-3,2,6,CHEST:5,null,20,CHEST:5,null,10,CHEST:5,null,15,CHEST:5,null,100)
Block(-3,2,7,AIR:0)
Block(-3,2,8,rustic:stone_pillar:0)
RandomBlock(-3,3,-3,SMOOTH_BRICK:0,40,SMOOTH_BRICK:1,20,SMOOTH_BRICK:2,30,SMOOTH_BRICK:0,100)
Block(-3,3,-2,rustic:stone_pillar:0)
Block(-3,3,-1,AIR:0)
Block(-3,3,0,AIR:0)
Block(-3,3,1,rustic:stone_pillar:0)
Block(-3,3,2,AIR:0)
Block(-3,3,3,AIR:0)
Block(-3,3,4,AIR:0)
Block(-3,3,5,rustic:stone_pillar:0)
Block(-3,3,6,AIR:0)
Block(-3,3,7,AIR:0)
Block(-3,3,8,rustic:stone_pillar:0)
Block(-3,4,-3,VINE:1)
RandomBlock(-3,4,-2,SMOOTH_BRICK:0,40,SMOOTH_BRICK:1,20,SMOOTH_BRICK:2,30,SMOOTH_BRICK:0,100)
RandomBlock(-3,4,-1,SMOOTH_BRICK:0,40,SMOOTH_BRICK:1,20,SMOOTH_BRICK:2,30,SMOOTH_BRICK:0,100)
Block(-3,4,0,SMOOTH_BRICK:2)
RandomBlock(-3,4,1,SMOOTH_BRICK:0,40,SMOOTH_BRICK:1,20,SMOOTH_BRICK:2,30,SMOOTH_BRICK:0,100)
Block(-3,4,2,SMOOTH_STAIRS:7)
Block(-3,4,3,AIR:0)
Block(-3,4,4,SMOOTH_STAIRS:6)
RandomBlock(-3,4,5,SMOOTH_BRICK:0,40,SMOOTH_BRICK:1,20,SMOOTH_BRICK:2,30,SMOOTH_BRICK:0,100)
Block(-3,4,6,SMOOTH_BRICK:1)
RandomBlock(-3,4,7,SMOOTH_BRICK:0,40,SMOOTH_BRICK:1,20,SMOOTH_BRICK:2,30,SMOOTH_BRICK:0,100)
RandomBlock(-3,4,8,SMOOTH_BRICK:0,40,SMOOTH_BRICK:1,20,SMOOTH_BRICK:2,30,SMOOTH_BRICK:0,100)
Block(-3,5,0,VINE:8)
Block(-3,5,1,SMOOTH_BRICK:1)
Block(-3,5,2,SMOOTH_STAIRS:0)
Block(-3,5,3,SMOOTH_STAIRS:0)
Block(-3,5,4,SMOOTH_STAIRS:0)
Block(-3,5,5,SMOOTH_BRICK:1)
Block(-3,5,7,VINE:8)
Block(-3,6,1,lycanitesmobs:lushstonetile_stairs:0)
Block(-3,6,5,lycanitesmobs:lushstonetile_stairs:0)
RandomBlock(-2,0,-6,SMOOTH_BRICK:0,40,SMOOTH_BRICK:1,20,SMOOTH_BRICK:2,30,SMOOTH_BRICK:0,100)
RandomBlock(-2,0,-5,SMOOTH_BRICK:0,40,SMOOTH_BRICK:1,20,SMOOTH_BRICK:2,30,SMOOTH_BRICK:0,100)
RandomBlock(-2,0,-4,SMOOTH_BRICK:0,40,SMOOTH_BRICK:1,20,SMOOTH_BRICK:2,30,SMOOTH_BRICK:0,100)
RandomBlock(-2,0,-3,SMOOTH_BRICK:0,40,SMOOTH_BRICK:1,20,SMOOTH_BRICK:2,30,SMOOTH_BRICK:0,100)
RandomBlock(-2,0,-2,SMOOTH_BRICK:0,40,SMOOTH_BRICK:1,20,SMOOTH_BRICK:2,30,SMOOTH_BRICK:0,100)
RandomBlock(-2,0,-1,SMOOTH_BRICK:0,40,SMOOTH_BRICK:1,20,SMOOTH_BRICK:2,30,SMOOTH_BRICK:0,100)
RandomBlock(-2,0,0,SMOOTH_BRICK:0,40,SMOOTH_BRICK:1,20,SMOOTH_BRICK:2,30,SMOOTH_BRICK:0,100)
RandomBlock(-2,0,1,SMOOTH_BRICK:0,40,SMOOTH_BRICK:1,20,SMOOTH_BRICK:2,30,SMOOTH_BRICK:0,100)
RandomBlock(-2,0,2,SMOOTH_BRICK:0,40,SMOOTH_BRICK:1,20,SMOOTH_BRICK:2,30,SMOOTH_BRICK:0,100)
RandomBlock(-2,0,3,SMOOTH_BRICK:0,40,SMOOTH_BRICK:1,20,SMOOTH_BRICK:2,30,SMOOTH_BRICK:0,100)
RandomBlock(-2,0,4,SMOOTH_BRICK:0,40,SMOOTH_BRICK:1,20,SMOOTH_BRICK:2,30,SMOOTH_BRICK:0,100)
RandomBlock(-2,0,5,SMOOTH_BRICK:0,40,SMOOTH_BRICK:1,20,SMOOTH_BRICK:2,30,SMOOTH_BRICK:0,100)
RandomBlock(-2,0,6,SMOOTH_BRICK:0,40,SMOOTH_BRICK:1,20,SMOOTH_BRICK:2,30,SMOOTH_BRICK:0,100)
RandomBlock(-2,0,7,SMOOTH_BRICK:0,40,SMOOTH_BRICK:1,20,SMOOTH_BRICK:2,30,SMOOTH_BRICK:0,100)
RandomBlock(-2,0,8,SMOOTH_BRICK:0,40,SMOOTH_BRICK:1,20,SMOOTH_BRICK:2,30,SMOOTH_BRICK:0,100)
Block(-2,1,-5,SMOOTH_BRICK:1)
RandomBlock(-2,1,-4,SMOOTH_BRICK:0,40,SMOOTH_BRICK:1,20,SMOOTH_BRICK:2,30,SMOOTH_BRICK:0,100)
RandomBlock(-2,1,-3,SMOOTH_BRICK:0,40,SMOOTH_BRICK:1,20,SMOOTH_BRICK:2,30,SMOOTH_BRICK:0,100)
RandomBlock(-2,1,-2,SMOOTH_BRICK:0,40,SMOOTH_BRICK:1,20,SMOOTH_BRICK:2,30,SMOOTH_BRICK:0,100)
RandomBlock(-2,1,-1,SMOOTH_BRICK:0,40,SMOOTH_BRICK:1,20,SMOOTH_BRICK:2,30,SMOOTH_BRICK:0,100)
RandomBlock(-2,1,0,SMOOTH_BRICK:0,40,SMOOTH_BRICK:1,20,SMOOTH_BRICK:2,30,SMOOTH_BRICK:0,100)
RandomBlock(-2,1,1,SMOOTH_BRICK:0,40,SMOOTH_BRICK:1,20,SMOOTH_BRICK:2,30,SMOOTH_BRICK:0,100)
RandomBlock(-2,1,2,SMOOTH_BRICK:0,40,SMOOTH_BRICK:1,20,SMOOTH_BRICK:2,30,SMOOTH_BRICK:0,100)
RandomBlock(-2,1,3,SMOOTH_BRICK:0,40,SMOOTH_BRICK:1,20,SMOOTH_BRICK:2,30,SMOOTH_BRICK:0,100)
RandomBlock(-2,1,4,SMOOTH_BRICK:0,40,SMOOTH_BRICK:1,20,SMOOTH_BRICK:2,30,SMOOTH_BRICK:0,100)
RandomBlock(-2,1,5,SMOOTH_BRICK:0,40,SMOOTH_BRICK:1,20,SMOOTH_BRICK:2,30,SMOOTH_BRICK:0,100)
RandomBlock(-2,1,6,SMOOTH_BRICK:0,40,SMOOTH_BRICK:1,20,SMOOTH_BRICK:2,30,SMOOTH_BRICK:0,100)
RandomBlock(-2,1,7,SMOOTH_BRICK:0,40,SMOOTH_BRICK:1,20,SMOOTH_BRICK:2,30,SMOOTH_BRICK:0,100)
RandomBlock(-2,1,8,SMOOTH_BRICK:0,40,SMOOTH_BRICK:1,20,SMOOTH_BRICK:2,30,SMOOTH_BRICK:0,100)
Block(-2,2,-5,lycanitesmobs:lushstone_slab:0)
Block(-2,2,-4,SMOOTH_BRICK:1)
Block(-2,2,-3,SMOOTH_BRICK:1)
Block(-2,2,-2,AIR:0)
Block(-2,2,-1,AIR:0)
Block(-2,2,0,AIR:0)
Block(-2,2,1,AIR:0)
Block(-2,2,2,AIR:0)
Block(-2,2,3,AIR:0)
Block(-2,2,4,AIR:0)
Block(-2,2,5,AIR:0)
Block(-2,2,6,AIR:0)
Block(-2,2,7,AIR:0)
Block(-2,2,8,AIR:0)
Block(-2,3,-3,SMOOTH_BRICK:1)
Block(-2,3,-2,AIR:0)
Block(-2,3,-1,AIR:0)
Block(-2,3,0,AIR:0)
Block(-2,3,1,AIR:0)
Block(-2,3,2,AIR:0)
Block(-2,3,3,AIR:0)
Block(-2,3,4,AIR:0)
Block(-2,3,5,AIR:0)
Block(-2,3,6,AIR:0)
Block(-2,3,7,AIR:0)
Block(-2,3,8,AIR:0)
Block(-2,4,-2,SMOOTH_BRICK:2)
Block(-2,4,-1,AIR:0)
Block(-2,4,0,AIR:0)
Block(-2,4,1,AIR:0)
Block(-2,4,2,AIR:0)
Block(-2,4,3,AIR:0)
Block(-2,4,4,AIR:0)
Block(-2,4,5,AIR:0)
Block(-2,4,6,AIR:0)
Block(-2,4,7,AIR:0)
RandomBlock(-2,4,8,SMOOTH_BRICK:0,40,SMOOTH_BRICK:1,20,SMOOTH_BRICK:2,30,SMOOTH_BRICK:0,100)
Block(-2,5,-2,VINE:1)
RandomBlock(-2,5,-1,SMOOTH_BRICK:0,40,SMOOTH_BRICK:1,20,SMOOTH_BRICK:2,30,SMOOTH_BRICK:0,100)
RandomBlock(-2,5,0,SMOOTH_BRICK:0,40,SMOOTH_BRICK:1,20,SMOOTH_BRICK:2,30,SMOOTH_BRICK:0,100)
RandomBlock(-2,5,1,SMOOTH_BRICK:0,40,SMOOTH_BRICK:1,20,SMOOTH_BRICK:2,30,SMOOTH_BRICK:0,100)
RandomBlock(-2,5,2,SMOOTH_BRICK:0,40,SMOOTH_BRICK:1,20,SMOOTH_BRICK:2,30,SMOOTH_BRICK:0,100)
RandomBlock(-2,5,3,SMOOTH_BRICK:0,40,SMOOTH_BRICK:1,20,SMOOTH_BRICK:2,30,SMOOTH_BRICK:0,100)
RandomBlock(-2,5,4,SMOOTH_BRICK:0,40,SMOOTH_BRICK:1,20,SMOOTH_BRICK:2,30,SMOOTH_BRICK:0,100)
RandomBlock(-2,5,5,SMOOTH_BRICK:0,40,SMOOTH_BRICK:1,20,SMOOTH_BRICK:2,30,SMOOTH_BRICK:0,100)
Block(-2,5,6,SMOOTH_BRICK:1)
Block(-2,5,7,SMOOTH_BRICK:1)
Block(-2,6,1,SMOOTH_BRICK:1)
Block(-2,6,2,SMOOTH_STAIRS:0)
Block(-2,6,3,SMOOTH_STAIRS:0)
Block(-2,6,4,SMOOTH_STAIRS:0)
Block(-2,6,5,SMOOTH_BRICK:1)
Block(-2,6,6,VINE:4)
Block(-2,7,1,lycanitesmobs:lushstonetile_stairs:0)
Block(-2,7,5,lycanitesmobs:lushstonetile_stairs:0)
RandomBlock(-1,0,-6,SMOOTH_BRICK:0,40,SMOOTH_BRICK:1,20,SMOOTH_BRICK:2,30,SMOOTH_BRICK:0,100)
RandomBlock(-1,0,-5,SMOOTH_BRICK:0,40,SMOOTH_BRICK:1,20,SMOOTH_BRICK:2,30,SMOOTH_BRICK:0,100)
RandomBlock(-1,0,-4,SMOOTH_BRICK:0,40,SMOOTH_BRICK:1,20,SMOOTH_BRICK:2,30,SMOOTH_BRICK:0,100)
RandomBlock(-1,0,-3,SMOOTH_BRICK:0,40,SMOOTH_BRICK:1,20,SMOOTH_BRICK:2,30,SMOOTH_BRICK:0,100)
RandomBlock(-1,0,-2,SMOOTH_BRICK:0,40,SMOOTH_BRICK:1,20,SMOOTH_BRICK:2,30,SMOOTH_BRICK:0,100)
RandomBlock(-1,0,-1,SMOOTH_BRICK:0,40,SMOOTH_BRICK:1,20,SMOOTH_BRICK:2,30,SMOOTH_BRICK:0,100)
Block(-1,0,0,lycanitesmobs:lushstonepolished:0)
Block(-1,0,1,lycanitesmobs:lushstonepolished:0)
Block(-1,0,2,lycanitesmobs:lushstonepolished:0)
Block(-1,0,3,lycanitesmobs:lushstonechiseled:0)
Block(-1,0,4,lycanitesmobs:lushstonepolished:0)
Block(-1,0,5,lycanitesmobs:lushstonepolished:0)
Block(-1,0,6,lycanitesmobs:lushstonepolished:0)
RandomBlock(-1,0,7,SMOOTH_BRICK:0,40,SMOOTH_BRICK:1,20,SMOOTH_BRICK:2,30,SMOOTH_BRICK:0,100)
RandomBlock(-1,0,8,SMOOTH_BRICK:0,40,SMOOTH_BRICK:1,20,SMOOTH_BRICK:2,30,SMOOTH_BRICK:0,100)
RandomBlock(-1,1,-5,SMOOTH_BRICK:0,40,SMOOTH_BRICK:1,20,SMOOTH_BRICK:2,30,SMOOTH_BRICK:0,100)
RandomBlock(-1,1,-4,SMOOTH_BRICK:0,40,SMOOTH_BRICK:1,20,SMOOTH_BRICK:2,30,SMOOTH_BRICK:0,100)
RandomBlock(-1,1,-3,SMOOTH_BRICK:0,40,SMOOTH_BRICK:1,20,SMOOTH_BRICK:2,30,SMOOTH_BRICK:0,100)
RandomBlock(-1,1,-2,SMOOTH_BRICK:0,40,SMOOTH_BRICK:1,20,SMOOTH_BRICK:2,30,SMOOTH_BRICK:0,100)
RandomBlock(-1,1,-1,SMOOTH_BRICK:0,40,SMOOTH_BRICK:1,20,SMOOTH_BRICK:2,30,SMOOTH_BRICK:0,100)
Block(-1,1,0,biomesoplenty:blood:3)
Block(-1,1,1,biomesoplenty:blood:2)
Block(-1,1,2,biomesoplenty:blood:1)
Block(-1,1,3,biomesoplenty:blood:0)
Block(-1,1,4,biomesoplenty:blood:1)
Block(-1,1,5,biomesoplenty:blood:2)
Block(-1,1,6,biomesoplenty:blood:3)
RandomBlock(-1,1,7,SMOOTH_BRICK:0,40,SMOOTH_BRICK:1,20,SMOOTH_BRICK:2,30,SMOOTH_BRICK:0,100)
RandomBlock(-1,1,8,SMOOTH_BRICK:0,40,SMOOTH_BRICK:1,20,SMOOTH_BRICK:2,30,SMOOTH_BRICK:0,100)
Block(-1,2,-5,lycanitesmobs:lushstone_slab:0)
Block(-1,2,-4,SMOOTH_BRICK:1)
RandomBlock(-1,2,-3,SMOOTH_BRICK:0,40,SMOOTH_BRICK:1,20,SMOOTH_BRICK:2,30,SMOOTH_BRICK:0,100)
Block(-1,2,-2,AIR:0)
Block(-1,2,-1,AIR:0)
Block(-1,2,0,AIR:0)
Block(-1,2,1,AIR:0)
Block(-1,2,2,AIR:0)
Block(-1,2,3,AIR:0)
Block(-1,2,4,AIR:0)
Block(-1,2,5,AIR:0)
Block(-1,2,6,AIR:0)
Block(-1,2,7,AIR:0)
Block(-1,2,8,AIR:0)
Block(-1,3,-4,VINE:1)
RandomBlock(-1,3,-3,SMOOTH_BRICK:0,40,SMOOTH_BRICK:1,20,SMOOTH_BRICK:2,30,SMOOTH_BRICK:0,100)
Block(-1,3,-2,AIR:0)
Block(-1,3,-1,AIR:0)
Block(-1,3,0,AIR:0)
Block(-1,3,1,AIR:0)
Block(-1,3,2,AIR:0)
Block(-1,3,3,AIR:0)
Block(-1,3,4,AIR:0)
Block(-1,3,5,AIR:0)
Block(-1,3,6,AIR:0)
Block(-1,3,7,AIR:0)
Block(-1,3,8,AIR:0)
Block(-1,4,-3,VINE:1)
RandomBlock(-1,4,-2,SMOOTH_BRICK:0,40,SMOOTH_BRICK:1,20,SMOOTH_BRICK:2,30,SMOOTH_BRICK:0,100)
Block(-1,4,-1,AIR:0)
Block(-1,4,0,AIR:0)
Block(-1,4,1,AIR:0)
Block(-1,4,2,AIR:0)
Block(-1,4,3,AIR:0)
Block(-1,4,4,AIR:0)
Block(-1,4,5,AIR:0)
Block(-1,4,6,AIR:0)
Block(-1,4,7,AIR:0)
Block(-1,4,8,SMOOTH_BRICK:1)
Block(-1,5,-1,SMOOTH_BRICK:1)
Block(-1,5,0,AIR:0)
Block(-1,5,1,AIR:0)
Block(-1,5,2,AIR:0)
Block(-1,5,3,AIR:0)
Block(-1,5,4,AIR:0)
Block(-1,5,5,AIR:0)
Block(-1,5,6,AIR:0)
Block(-1,5,7,SMOOTH_BRICK:1)
Block(-1,5,8,VINE:4)
Block(-1,6,0,SMOOTH_BRICK:1)
RandomBlock(-1,6,1,SMOOTH_BRICK:0,40,SMOOTH_BRICK:1,20,SMOOTH_BRICK:2,30,SMOOTH_BRICK:0,100)
RandomBlock(-1,6,2,SMOOTH_BRICK:0,40,SMOOTH_BRICK:1,20,SMOOTH_BRICK:2,30,SMOOTH_BRICK:0,100)
RandomBlock(-1,6,3,SMOOTH_BRICK:0,40,SMOOTH_BRICK:1,20,SMOOTH_BRICK:2,30,SMOOTH_BRICK:0,100)
RandomBlock(-1,6,4,SMOOTH_BRICK:0,40,SMOOTH_BRICK:1,20,SMOOTH_BRICK:2,30,SMOOTH_BRICK:0,100)
RandomBlock(-1,6,5,SMOOTH_BRICK:0,40,SMOOTH_BRICK:1,20,SMOOTH_BRICK:2,30,SMOOTH_BRICK:0,100)
Block(-1,6,6,SMOOTH_BRICK:1)
Block(-1,6,7,VINE:4)
RandomBlock(-1,7,1,SMOOTH_BRICK:0,40,SMOOTH_BRICK:1,20,SMOOTH_BRICK:2,30,SMOOTH_BRICK:0,100)
Block(-1,7,2,SMOOTH_STAIRS:0)
Block(-1,7,3,SMOOTH_STAIRS:0)
Block(-1,7,4,SMOOTH_STAIRS:0)
RandomBlock(-1,7,5,SMOOTH_BRICK:0,40,SMOOTH_BRICK:1,20,SMOOTH_BRICK:2,30,SMOOTH_BRICK:0,100)
Block(-1,7,6,VINE:8)
Block(-1,8,1,lycanitesmobs:lushstonechiseled:0)
Block(-1,8,3,VINE:8)
Block(-1,8,5,lycanitesmobs:lushstonechiseled:0)
Block(-1,9,1,VINE:8)
Block(-1,9,3,VINE:8)
Block(-1,10,1,VINE:8)
Block(-1,10,3,VINE:8)
RandomBlock(0,0,-7,SMOOTH_BRICK:0,40,SMOOTH_BRICK:1,20,SMOOTH_BRICK:2,30,SMOOTH_BRICK:0,100)
RandomBlock(0,0,-6,SMOOTH_BRICK:0,40,SMOOTH_BRICK:1,20,SMOOTH_BRICK:2,30,SMOOTH_BRICK:0,100)
RandomBlock(0,0,-5,SMOOTH_BRICK:0,40,SMOOTH_BRICK:1,20,SMOOTH_BRICK:2,30,SMOOTH_BRICK:0,100)
RandomBlock(0,0,-4,SMOOTH_BRICK:0,40,SMOOTH_BRICK:1,20,SMOOTH_BRICK:2,30,SMOOTH_BRICK:0,100)
RandomBlock(0,0,-3,SMOOTH_BRICK:0,40,SMOOTH_BRICK:1,20,SMOOTH_BRICK:2,30,SMOOTH_BRICK:0,100)
RandomBlock(0,0,-2,SMOOTH_BRICK:0,40,SMOOTH_BRICK:1,20,SMOOTH_BRICK:2,30,SMOOTH_BRICK:0,100)
RandomBlock(0,0,-1,SMOOTH_BRICK:0,40,SMOOTH_BRICK:1,20,SMOOTH_BRICK:2,30,SMOOTH_BRICK:0,100)
Block(0,0,0,lycanitesmobs:lushstonepolished:0)
RandomBlock(0,0,1,SMOOTH_BRICK:0,40,SMOOTH_BRICK:1,20,SMOOTH_BRICK:2,30,SMOOTH_BRICK:0,100)
RandomBlock(0,0,2,SMOOTH_BRICK:0,40,SMOOTH_BRICK:1,20,SMOOTH_BRICK:2,30,SMOOTH_BRICK:0,100)
Block(0,0,3,lycanitesmobs:lushstonepolished:0)
RandomBlock(0,0,4,SMOOTH_BRICK:0,40,SMOOTH_BRICK:1,20,SMOOTH_BRICK:2,30,SMOOTH_BRICK:0,100)
RandomBlock(0,0,5,SMOOTH_BRICK:0,40,SMOOTH_BRICK:1,20,SMOOTH_BRICK:2,30,SMOOTH_BRICK:0,100)
Block(0,0,6,lycanitesmobs:lushstonepolished:0)
RandomBlock(0,0,7,SMOOTH_BRICK:0,40,SMOOTH_BRICK:1,20,SMOOTH_BRICK:2,30,SMOOTH_BRICK:0,100)
RandomBlock(0,0,8,SMOOTH_BRICK:0,40,SMOOTH_BRICK:1,20,SMOOTH_BRICK:2,30,SMOOTH_BRICK:0,100)
Block(0,1,-7,lycanitesmobs:lushstonetile_stairs:2)
RandomBlock(0,1,-6,SMOOTH_BRICK:0,40,SMOOTH_BRICK:1,20,SMOOTH_BRICK:2,30,SMOOTH_BRICK:0,100)
RandomBlock(0,1,-5,SMOOTH_BRICK:0,40,SMOOTH_BRICK:1,20,SMOOTH_BRICK:2,30,SMOOTH_BRICK:0,100)
RandomBlock(0,1,-4,SMOOTH_BRICK:0,40,SMOOTH_BRICK:1,20,SMOOTH_BRICK:2,30,SMOOTH_BRICK:0,100)
RandomBlock(0,1,-3,SMOOTH_BRICK:0,40,SMOOTH_BRICK:1,20,SMOOTH_BRICK:2,30,SMOOTH_BRICK:0,100)
RandomBlock(0,1,-2,SMOOTH_BRICK:0,40,SMOOTH_BRICK:1,20,SMOOTH_BRICK:2,30,SMOOTH_BRICK:0,100)
RandomBlock(0,1,-1,SMOOTH_BRICK:0,40,SMOOTH_BRICK:1,20,SMOOTH_BRICK:2,30,SMOOTH_BRICK:0,100)
Block(0,1,0,biomesoplenty:blood:4)
RandomBlock(0,1,1,SMOOTH_BRICK:0,40,SMOOTH_BRICK:1,20,SMOOTH_BRICK:2,30,SMOOTH_BRICK:0,100)
RandomBlock(0,1,2,SMOOTH_BRICK:0,40,SMOOTH_BRICK:1,20,SMOOTH_BRICK:2,30,SMOOTH_BRICK:0,100)
Block(0,1,3,biomesoplenty:blood:1)
RandomBlock(0,1,4,SMOOTH_BRICK:0,40,SMOOTH_BRICK:1,20,SMOOTH_BRICK:2,30,SMOOTH_BRICK:0,100)
RandomBlock(0,1,5,SMOOTH_BRICK:0,40,SMOOTH_BRICK:1,20,SMOOTH_BRICK:2,30,SMOOTH_BRICK:0,100)
Block(0,1,6,biomesoplenty:blood:4)
RandomBlock(0,1,7,SMOOTH_BRICK:0,40,SMOOTH_BRICK:1,20,SMOOTH_BRICK:2,30,SMOOTH_BRICK:0,100)
RandomBlock(0,1,8,SMOOTH_BRICK:0,40,SMOOTH_BRICK:1,20,SMOOTH_BRICK:2,30,SMOOTH_BRICK:0,100)
Block(0,2,-6,lycanitesmobs:lushstonetile_stairs:2)
Block(0,2,-5,SMOOTH_BRICK:1)
RandomBlock(0,2,-4,SMOOTH_BRICK:0,40,SMOOTH_BRICK:1,20,SMOOTH_BRICK:2,30,SMOOTH_BRICK:0,100)
RandomBlock(0,2,-3,SMOOTH_BRICK:0,40,SMOOTH_BRICK:1,20,SMOOTH_BRICK:2,30,SMOOTH_BRICK:0,100)
Block(0,2,-2,rustic:stone_pillar:0)
Block(0,2,-1,AIR:0)
Block(0,2,0,AIR:0)
Block(0,2,1,AIR:0)
Block(0,2,2,AIR:0)
Block(0,2,3,AIR:0)
Block(0,2,4,AIR:0)
Block(0,2,5,AIR:0)
Block(0,2,6,AIR:0)
Block(0,2,7,AIR:0)
Block(0,2,8,rustic:stone_pillar:0)
Block(0,3,-5,lycanitesmobs:lushstonetile_stairs:2)
Block(0,3,-4,SMOOTH_BRICK:1)
RandomBlock(0,3,-3,SMOOTH_BRICK:0,40,SMOOTH_BRICK:1,20,SMOOTH_BRICK:2,30,SMOOTH_BRICK:0,100)
Block(0,3,-2,rustic:stone_pillar:0)
Block(0,3,-1,AIR:0)
Block(0,3,0,AIR:0)
Block(0,3,1,AIR:0)
Block(0,3,2,AIR:0)
Block(0,3,3,AIR:0)
Block(0,3,4,AIR:0)
Block(0,3,5,AIR:0)
Block(0,3,6,AIR:0)
Block(0,3,7,AIR:0)
Block(0,3,8,rustic:stone_pillar:0)
Block(0,4,-4,lycanitesmobs:lushstonetile_stairs:2)
Block(0,4,-3,SMOOTH_BRICK:1)
RandomBlock(0,4,-2,SMOOTH_BRICK:0,40,SMOOTH_BRICK:1,20,SMOOTH_BRICK:2,30,SMOOTH_BRICK:0,100)
Block(0,4,-1,AIR:0)
Block(0,4,0,AIR:0)
Block(0,4,1,AIR:0)
Block(0,4,2,AIR:0)
Block(0,4,3,AIR:0)
Block(0,4,4,AIR:0)
Block(0,4,5,AIR:0)
Block(0,4,6,AIR:0)
Block(0,4,7,AIR:0)
RandomBlock(0,4,8,SMOOTH_BRICK:0,40,SMOOTH_BRICK:1,20,SMOOTH_BRICK:2,30,SMOOTH_BRICK:0,100)
Block(0,5,-3,lycanitesmobs:lushstonetile_stairs:2)
Block(0,5,-2,SMOOTH_BRICK:1)
RandomBlock(0,5,-1,SMOOTH_BRICK:0,40,SMOOTH_BRICK:1,20,SMOOTH_BRICK:2,30,SMOOTH_BRICK:0,100)
Block(0,5,0,AIR:0)
Block(0,5,1,AIR:0)
Block(0,5,2,AIR:0)
Block(0,5,3,AIR:0)
Block(0,5,4,AIR:0)
Block(0,5,5,AIR:0)
Block(0,5,6,AIR:0)
RandomBlock(0,5,7,SMOOTH_BRICK:0,40,SMOOTH_BRICK:1,20,SMOOTH_BRICK:2,30,SMOOTH_BRICK:0,100)
Block(0,5,8,SMOOTH_BRICK:1)
Block(0,6,-2,lycanitesmobs:lushstonetile_stairs:2)
Block(0,6,-1,SMOOTH_BRICK:1)
RandomBlock(0,6,0,SMOOTH_BRICK:0,40,SMOOTH_BRICK:1,20,SMOOTH_BRICK:2,30,SMOOTH_BRICK:0,100)
RandomBlock(0,6,1,SMOOTH_BRICK:0,40,SMOOTH_BRICK:1,20,SMOOTH_BRICK:2,30,SMOOTH_BRICK:0,100)
RandomBlock(0,6,2,SMOOTH_BRICK:0,40,SMOOTH_BRICK:1,20,SMOOTH_BRICK:2,30,SMOOTH_BRICK:0,100)
RandomBlock(0,6,3,SMOOTH_BRICK:0,40,SMOOTH_BRICK:1,20,SMOOTH_BRICK:2,30,SMOOTH_BRICK:0,100)
RandomBlock(0,6,4,SMOOTH_BRICK:0,40,SMOOTH_BRICK:1,20,SMOOTH_BRICK:2,30,SMOOTH_BRICK:0,100)
RandomBlock(0,6,5,SMOOTH_BRICK:0,40,SMOOTH_BRICK:1,20,SMOOTH_BRICK:2,30,SMOOTH_BRICK:0,100)
RandomBlock(0,6,6,SMOOTH_BRICK:0,40,SMOOTH_BRICK:1,20,SMOOTH_BRICK:2,30,SMOOTH_BRICK:0,100)
RandomBlock(0,6,7,SMOOTH_BRICK:0,40,SMOOTH_BRICK:1,20,SMOOTH_BRICK:2,30,SMOOTH_BRICK:0,100)
Block(0,6,8,lycanitesmobs:lushstonetile_stairs:3)
Block(0,7,-1,lycanitesmobs:lushstonetile_stairs:2)
RandomBlock(0,7,0,SMOOTH_BRICK:0,40,SMOOTH_BRICK:1,20,SMOOTH_BRICK:2,30,SMOOTH_BRICK:0,100)
Block(0,7,1,lycanitesmobs:lushstone_slab:0)
Block(0,7,2,lycanitesmobs:lushstone_slab:0)
Block(0,7,3,lycanitesmobs:lushstone_slab:0)
Block(0,7,4,lycanitesmobs:lushstone_slab:0)
Block(0,7,5,lycanitesmobs:lushstone_slab:0)
Block(0,7,6,SMOOTH_BRICK:1)
Block(0,7,7,lycanitesmobs:lushstonetile_stairs:3)
Block(0,8,0,lycanitesmobs:lushstonechiseled:0)
Block(0,8,6,lycanitesmobs:lushstonechiseled:0)
Block(0,10,1,SMOOTH_BRICK:2)
RandomBlock(0,10,2,SMOOTH_BRICK:0,40,SMOOTH_BRICK:1,20,SMOOTH_BRICK:2,30,SMOOTH_BRICK:0,100)
Block(0,10,3,SMOOTH_BRICK:1)
Block(0,10,4,SMOOTH_BRICK:1)
Block(0,10,5,SMOOTH_BRICK:2)
RandomBlock(1,0,-7,SMOOTH_BRICK:0,40,SMOOTH_BRICK:1,20,SMOOTH_BRICK:2,30,SMOOTH_BRICK:0,100)
RandomBlock(1,0,-6,SMOOTH_BRICK:0,40,SMOOTH_BRICK:1,20,SMOOTH_BRICK:2,30,SMOOTH_BRICK:0,100)
RandomBlock(1,0,-5,SMOOTH_BRICK:0,40,SMOOTH_BRICK:1,20,SMOOTH_BRICK:2,30,SMOOTH_BRICK:0,100)
RandomBlock(1,0,-4,SMOOTH_BRICK:0,40,SMOOTH_BRICK:1,20,SMOOTH_BRICK:2,30,SMOOTH_BRICK:0,100)
RandomBlock(1,0,-3,SMOOTH_BRICK:0,40,SMOOTH_BRICK:1,20,SMOOTH_BRICK:2,30,SMOOTH_BRICK:0,100)
RandomBlock(1,0,-2,SMOOTH_BRICK:0,40,SMOOTH_BRICK:1,20,SMOOTH_BRICK:2,30,SMOOTH_BRICK:0,100)
RandomBlock(1,0,-1,SMOOTH_BRICK:0,40,SMOOTH_BRICK:1,20,SMOOTH_BRICK:2,30,SMOOTH_BRICK:0,100)
Block(1,0,0,lycanitesmobs:lushstonepolished:0)
RandomBlock(1,0,1,SMOOTH_BRICK:0,40,SMOOTH_BRICK:1,20,SMOOTH_BRICK:2,30,SMOOTH_BRICK:0,100)
RandomBlock(1,0,2,SMOOTH_BRICK:0,40,SMOOTH_BRICK:1,20,SMOOTH_BRICK:2,30,SMOOTH_BRICK:0,100)
Block(1,0,3,lycanitesmobs:lushstonepolished:0)
RandomBlock(1,0,4,SMOOTH_BRICK:0,40,SMOOTH_BRICK:1,20,SMOOTH_BRICK:2,30,SMOOTH_BRICK:0,100)
RandomBlock(1,0,5,SMOOTH_BRICK:0,40,SMOOTH_BRICK:1,20,SMOOTH_BRICK:2,30,SMOOTH_BRICK:0,100)
Block(1,0,6,lycanitesmobs:lushstonepolished:0)
RandomBlock(1,0,7,SMOOTH_BRICK:0,40,SMOOTH_BRICK:1,20,SMOOTH_BRICK:2,30,SMOOTH_BRICK:0,100)
RandomBlock(1,0,8,SMOOTH_BRICK:0,40,SMOOTH_BRICK:1,20,SMOOTH_BRICK:2,30,SMOOTH_BRICK:0,100)
Block(1,1,-6,SMOOTH_STAIRS:2)
RandomBlock(1,1,-5,SMOOTH_BRICK:0,40,SMOOTH_BRICK:1,20,SMOOTH_BRICK:2,30,SMOOTH_BRICK:0,100)
RandomBlock(1,1,-4,SMOOTH_BRICK:0,40,SMOOTH_BRICK:1,20,SMOOTH_BRICK:2,30,SMOOTH_BRICK:0,100)
RandomBlock(1,1,-3,SMOOTH_BRICK:0,40,SMOOTH_BRICK:1,20,SMOOTH_BRICK:2,30,SMOOTH_BRICK:0,100)
RandomBlock(1,1,-2,SMOOTH_BRICK:0,40,SMOOTH_BRICK:1,20,SMOOTH_BRICK:2,30,SMOOTH_BRICK:0,100)
RandomBlock(1,1,-1,SMOOTH_BRICK:0,40,SMOOTH_BRICK:1,20,SMOOTH_BRICK:2,30,SMOOTH_BRICK:0,100)
Block(1,1,0,biomesoplenty:blood:5)
RandomBlock(1,1,1,SMOOTH_BRICK:0,40,SMOOTH_BRICK:1,20,SMOOTH_BRICK:2,30,SMOOTH_BRICK:0,100)
RandomBlock(1,1,2,SMOOTH_BRICK:0,40,SMOOTH_BRICK:1,20,SMOOTH_BRICK:2,30,SMOOTH_BRICK:0,100)
Block(1,1,3,biomesoplenty:blood:0)
RandomBlock(1,1,4,SMOOTH_BRICK:0,40,SMOOTH_BRICK:1,20,SMOOTH_BRICK:2,30,SMOOTH_BRICK:0,100)
RandomBlock(1,1,5,SMOOTH_BRICK:0,40,SMOOTH_BRICK:1,20,SMOOTH_BRICK:2,30,SMOOTH_BRICK:0,100)
Block(1,1,6,biomesoplenty:blood:5)
RandomBlock(1,1,7,SMOOTH_BRICK:0,40,SMOOTH_BRICK:1,20,SMOOTH_BRICK:2,30,SMOOTH_BRICK:0,100)
RandomBlock(1,1,8,SMOOTH_BRICK:0,40,SMOOTH_BRICK:1,20,SMOOTH_BRICK:2,30,SMOOTH_BRICK:0,100)
Block(1,2,-5,SMOOTH_STAIRS:2)
RandomBlock(1,2,-4,SMOOTH_BRICK:0,40,SMOOTH_BRICK:1,20,SMOOTH_BRICK:2,30,SMOOTH_BRICK:0,100)
RandomBlock(1,2,-3,SMOOTH_BRICK:0,40,SMOOTH_BRICK:1,20,SMOOTH_BRICK:2,30,SMOOTH_BRICK:0,100)
Block(1,2,-2,AIR:0)
Block(1,2,-1,AIR:0)
Block(1,2,0,AIR:0)
Block(1,2,1,AIR:0)
Block(1,2,2,AIR:0)
Block(1,2,3,AIR:0)
Block(1,2,4,AIR:0)
Block(1,2,5,AIR:0)
Block(1,2,6,AIR:0)
Block(1,2,7,AIR:0)
Block(1,2,8,AIR:0)
Block(1,3,-4,SMOOTH_STAIRS:2)
RandomBlock(1,3,-3,SMOOTH_BRICK:0,40,SMOOTH_BRICK:1,20,SMOOTH_BRICK:2,30,SMOOTH_BRICK:0,100)
Block(1,3,-2,AIR:0)
Block(1,3,-1,AIR:0)
Block(1,3,0,AIR:0)
Block(1,3,1,AIR:0)
Block(1,3,2,AIR:0)
Block(1,3,3,AIR:0)
Block(1,3,4,AIR:0)
Block(1,3,5,AIR:0)
Block(1,3,6,AIR:0)
Block(1,3,7,AIR:0)
Block(1,3,8,AIR:0)
Block(1,4,-3,SMOOTH_STAIRS:2)
RandomBlock(1,4,-2,SMOOTH_BRICK:0,40,SMOOTH_BRICK:1,20,SMOOTH_BRICK:2,30,SMOOTH_BRICK:0,100)
Block(1,4,-1,AIR:0)
Block(1,4,0,AIR:0)
Block(1,4,1,AIR:0)
Block(1,4,2,AIR:0)
Block(1,4,3,AIR:0)
Block(1,4,4,AIR:0)
Block(1,4,5,AIR:0)
Block(1,4,6,AIR:0)
Block(1,4,7,AIR:0)
RandomBlock(1,4,8,SMOOTH_BRICK:0,40,SMOOTH_BRICK:1,20,SMOOTH_BRICK:2,30,SMOOTH_BRICK:0,100)
Block(1,5,-2,SMOOTH_STAIRS:2)
RandomBlock(1,5,-1,SMOOTH_BRICK:0,40,SMOOTH_BRICK:1,20,SMOOTH_BRICK:2,30,SMOOTH_BRICK:0,100)
Block(1,5,0,AIR:0)
Block(1,5,1,AIR:0)
Block(1,5,2,AIR:0)
Block(1,5,3,AIR:0)
Block(1,5,4,AIR:0)
Block(1,5,5,AIR:0)
Block(1,5,6,AIR:0)
RandomBlock(1,5,7,SMOOTH_BRICK:0,40,SMOOTH_BRICK:1,20,SMOOTH_BRICK:2,30,SMOOTH_BRICK:0,100)
Block(1,5,8,SMOOTH_STAIRS:3)
Block(1,6,-1,SMOOTH_STAIRS:2)
RandomBlock(1,6,0,SMOOTH_BRICK:0,40,SMOOTH_BRICK:1,20,SMOOTH_BRICK:2,30,SMOOTH_BRICK:0,100)
RandomBlock(1,6,1,SMOOTH_BRICK:0,40,SMOOTH_BRICK:1,20,SMOOTH_BRICK:2,30,SMOOTH_BRICK:0,100)
RandomBlock(1,6,2,SMOOTH_BRICK:0,40,SMOOTH_BRICK:1,20,SMOOTH_BRICK:2,30,SMOOTH_BRICK:0,100)
Block(1,6,3,SMOOTH_STAIRS:1)
RandomBlock(1,6,4,SMOOTH_BRICK:0,40,SMOOTH_BRICK:1,20,SMOOTH_BRICK:2,30,SMOOTH_BRICK:0,100)
RandomBlock(1,6,5,SMOOTH_BRICK:0,40,SMOOTH_BRICK:1,20,SMOOTH_BRICK:2,30,SMOOTH_BRICK:0,100)
RandomBlock(1,6,6,SMOOTH_BRICK:0,40,SMOOTH_BRICK:1,20,SMOOTH_BRICK:2,30,SMOOTH_BRICK:0,100)
Block(1,6,7,SMOOTH_STAIRS:3)
Block(1,7,0,SMOOTH_STAIRS:2)
Block(1,7,1,lycanitesmobs:lushstone_slab:0)
Block(1,7,2,SMOOTH_BRICK:3)
Block(1,7,3,SMOOTH_STAIRS:5)
Block(1,7,4,SMOOTH_BRICK:3)
Block(1,7,5,lycanitesmobs:lushstone_slab:0)
Block(1,7,6,SMOOTH_STAIRS:3)
Block(1,8,2,SMOOTH_BRICK:3)
Block(1,8,4,SMOOTH_BRICK:3)
Block(1,9,2,SMOOTH_BRICK:3)
Block(1,9,4,SMOOTH_BRICK:3)
Block(1,10,1,SMOOTH_BRICK:1)
Block(1,10,2,SMOOTH_BRICK:3)
Block(1,10,3,SMOOTH_STAIRS:4)
Block(1,10,4,SMOOTH_BRICK:3)
RandomBlock(1,10,5,SMOOTH_BRICK:0,40,SMOOTH_BRICK:1,20,SMOOTH_BRICK:2,30,SMOOTH_BRICK:0,100)
RandomBlock(1,11,2,SMOOTH_BRICK:0,40,SMOOTH_BRICK:1,20,SMOOTH_BRICK:2,30,SMOOTH_BRICK:0,100)
RandomBlock(1,11,3,SMOOTH_BRICK:0,40,SMOOTH_BRICK:1,20,SMOOTH_BRICK:2,30,SMOOTH_BRICK:0,100)
Block(1,11,4,SMOOTH_BRICK:2)
Block(1,12,3,VINE:8)
RandomBlock(2,0,-7,SMOOTH_BRICK:0,40,SMOOTH_BRICK:1,20,SMOOTH_BRICK:2,30,SMOOTH_BRICK:0,100)
RandomBlock(2,0,-6,SMOOTH_BRICK:0,40,SMOOTH_BRICK:1,20,SMOOTH_BRICK:2,30,SMOOTH_BRICK:0,100)
RandomBlock(2,0,-5,SMOOTH_BRICK:0,40,SMOOTH_BRICK:1,20,SMOOTH_BRICK:2,30,SMOOTH_BRICK:0,100)
RandomBlock(2,0,-4,SMOOTH_BRICK:0,40,SMOOTH_BRICK:1,20,SMOOTH_BRICK:2,30,SMOOTH_BRICK:0,100)
RandomBlock(2,0,-3,SMOOTH_BRICK:0,40,SMOOTH_BRICK:1,20,SMOOTH_BRICK:2,30,SMOOTH_BRICK:0,100)
RandomBlock(2,0,-2,SMOOTH_BRICK:0,40,SMOOTH_BRICK:1,20,SMOOTH_BRICK:2,30,SMOOTH_BRICK:0,100)
RandomBlock(2,0,-1,SMOOTH_BRICK:0,40,SMOOTH_BRICK:1,20,SMOOTH_BRICK:2,30,SMOOTH_BRICK:0,100)
Block(2,0,0,lycanitesmobs:lushstonepolished:0)
Block(2,0,1,lycanitesmobs:lushstonepolished:0)
RandomBlock(2,0,2,SMOOTH_BRICK:0,40,SMOOTH_BRICK:1,20,SMOOTH_BRICK:2,30,SMOOTH_BRICK:0,100)
Block(2,0,3,lycanitesmobs:lushstonepolished:0)
RandomBlock(2,0,4,SMOOTH_BRICK:0,40,SMOOTH_BRICK:1,20,SMOOTH_BRICK:2,30,SMOOTH_BRICK:0,100)
Block(2,0,5,lycanitesmobs:lushstonepolished:0)
Block(2,0,6,lycanitesmobs:lushstonepolished:0)
RandomBlock(2,0,7,SMOOTH_BRICK:0,40,SMOOTH_BRICK:1,20,SMOOTH_BRICK:2,30,SMOOTH_BRICK:0,100)
RandomBlock(2,0,8,SMOOTH_BRICK:0,40,SMOOTH_BRICK:1,20,SMOOTH_BRICK:2,30,SMOOTH_BRICK:0,100)
Block(2,1,-6,SMOOTH_STAIRS:2)
RandomBlock(2,1,-5,SMOOTH_BRICK:0,40,SMOOTH_BRICK:1,20,SMOOTH_BRICK:2,30,SMOOTH_BRICK:0,100)
RandomBlock(2,1,-4,SMOOTH_BRICK:0,40,SMOOTH_BRICK:1,20,SMOOTH_BRICK:2,30,SMOOTH_BRICK:0,100)
RandomBlock(2,1,-3,SMOOTH_BRICK:0,40,SMOOTH_BRICK:1,20,SMOOTH_BRICK:2,30,SMOOTH_BRICK:0,100)
RandomBlock(2,1,-2,SMOOTH_BRICK:0,40,SMOOTH_BRICK:1,20,SMOOTH_BRICK:2,30,SMOOTH_BRICK:0,100)
RandomBlock(2,1,-1,SMOOTH_BRICK:0,40,SMOOTH_BRICK:1,20,SMOOTH_BRICK:2,30,SMOOTH_BRICK:0,100)
Block(2,1,0,biomesoplenty:blood:6)
Block(2,1,1,biomesoplenty:blood:7)
RandomBlock(2,1,2,SMOOTH_BRICK:0,40,SMOOTH_BRICK:1,20,SMOOTH_BRICK:2,30,SMOOTH_BRICK:0,100)
Block(2,1,3,biomesoplenty:blood:0)
RandomBlock(2,1,4,SMOOTH_BRICK:0,40,SMOOTH_BRICK:1,20,SMOOTH_BRICK:2,30,SMOOTH_BRICK:0,100)
Block(2,1,5,biomesoplenty:blood:7)
Block(2,1,6,biomesoplenty:blood:6)
RandomBlock(2,1,7,SMOOTH_BRICK:0,40,SMOOTH_BRICK:1,20,SMOOTH_BRICK:2,30,SMOOTH_BRICK:0,100)
RandomBlock(2,1,8,SMOOTH_BRICK:0,40,SMOOTH_BRICK:1,20,SMOOTH_BRICK:2,30,SMOOTH_BRICK:0,100)
Block(2,2,-5,SMOOTH_STAIRS:2)
RandomBlock(2,2,-4,SMOOTH_BRICK:0,40,SMOOTH_BRICK:1,20,SMOOTH_BRICK:2,30,SMOOTH_BRICK:0,100)
RandomBlock(2,2,-3,SMOOTH_BRICK:0,40,SMOOTH_BRICK:1,20,SMOOTH_BRICK:2,30,SMOOTH_BRICK:0,100)
Block(2,2,-2,AIR:0)
Block(2,2,-1,AIR:0)
Block(2,2,0,AIR:0)
Block(2,2,1,AIR:0)
Block(2,2,2,rustic:stone_pillar:0)
Block(2,2,3,AIR:0)
Block(2,2,4,rustic:stone_pillar:0)
Block(2,2,5,AIR:0)
Block(2,2,6,AIR:0)
Block(2,2,7,AIR:0)
Block(2,2,8,AIR:0)
Block(2,3,-4,SMOOTH_STAIRS:2)
RandomBlock(2,3,-3,SMOOTH_BRICK:0,40,SMOOTH_BRICK:1,20,SMOOTH_BRICK:2,30,SMOOTH_BRICK:0,100)
Block(2,3,-2,AIR:0)
Block(2,3,-1,AIR:0)
Block(2,3,0,AIR:0)
Block(2,3,1,AIR:0)
Block(2,3,2,rustic:stone_pillar:0)
Block(2,3,3,AIR:0)
Block(2,3,4,rustic:stone_pillar:0)
Block(2,3,5,AIR:0)
Block(2,3,6,AIR:0)
Block(2,3,7,AIR:0)
Block(2,3,8,AIR:0)
Block(2,4,-3,SMOOTH_STAIRS:2)
RandomBlock(2,4,-2,SMOOTH_BRICK:0,40,SMOOTH_BRICK:1,20,SMOOTH_BRICK:2,30,SMOOTH_BRICK:0,100)
Block(2,4,-1,AIR:0)
Block(2,4,0,AIR:0)
Block(2,4,1,AIR:0)
Block(2,4,2,rustic:stone_pillar:0)
Block(2,4,3,AIR:0)
Block(2,4,4,rustic:stone_pillar:0)
Block(2,4,5,AIR:0)
Block(2,4,6,AIR:0)
Block(2,4,7,AIR:0)
RandomBlock(2,4,8,SMOOTH_BRICK:0,40,SMOOTH_BRICK:1,20,SMOOTH_BRICK:2,30,SMOOTH_BRICK:0,100)
Block(2,5,-2,SMOOTH_STAIRS:2)
RandomBlock(2,5,-1,SMOOTH_BRICK:0,40,SMOOTH_BRICK:1,20,SMOOTH_BRICK:2,30,SMOOTH_BRICK:0,100)
Block(2,5,0,AIR:0)
Block(2,5,1,AIR:0)
Block(2,5,2,rustic:stone_pillar:0)
Block(2,5,3,AIR:0)
Block(2,5,4,rustic:stone_pillar:0)
Block(2,5,5,AIR:0)
Block(2,5,6,AIR:0)
RandomBlock(2,5,7,SMOOTH_BRICK:0,40,SMOOTH_BRICK:1,20,SMOOTH_BRICK:2,30,SMOOTH_BRICK:0,100)
Block(2,5,8,SMOOTH_STAIRS:3)
Block(2,6,-1,SMOOTH_STAIRS:2)
RandomBlock(2,6,0,SMOOTH_BRICK:0,40,SMOOTH_BRICK:1,20,SMOOTH_BRICK:2,30,SMOOTH_BRICK:0,100)
RandomBlock(2,6,1,SMOOTH_BRICK:0,40,SMOOTH_BRICK:1,20,SMOOTH_BRICK:2,30,SMOOTH_BRICK:0,100)
RandomBlock(2,6,2,SMOOTH_BRICK:0,40,SMOOTH_BRICK:1,20,SMOOTH_BRICK:2,30,SMOOTH_BRICK:0,100)
Block(2,6,3,AIR:0)
RandomBlock(2,6,4,SMOOTH_BRICK:0,40,SMOOTH_BRICK:1,20,SMOOTH_BRICK:2,30,SMOOTH_BRICK:0,100)
RandomBlock(2,6,5,SMOOTH_BRICK:0,40,SMOOTH_BRICK:1,20,SMOOTH_BRICK:2,30,SMOOTH_BRICK:0,100)
RandomBlock(2,6,6,SMOOTH_BRICK:0,40,SMOOTH_BRICK:1,20,SMOOTH_BRICK:2,30,SMOOTH_BRICK:0,100)
Block(2,6,7,SMOOTH_STAIRS:3)
Block(2,7,0,SMOOTH_STAIRS:2)
Block(2,7,1,lycanitesmobs:lushstone_slab:0)
Block(2,7,2,SMOOTH_STAIRS:2)
Block(2,7,3,lycanitesmobs:lushstonebrick_fence:0)
Block(2,7,4,SMOOTH_STAIRS:3)
Block(2,7,5,lycanitesmobs:lushstone_slab:0)
Block(2,7,6,SMOOTH_STAIRS:3)
Block(2,8,6,VINE:4)
Block(2,9,6,VINE:4)
RandomBlock(2,10,1,SMOOTH_BRICK:0,40,SMOOTH_BRICK:1,20,SMOOTH_BRICK:2,30,SMOOTH_BRICK:0,100)
Block(2,10,2,SMOOTH_STAIRS:6)
RandomBlock(2,10,3,CHEST:3,null,20,CHEST:3,null,10,CHEST:3,null,15,CHEST:3,null,100)
Block(2,10,4,SMOOTH_STAIRS:7)
RandomBlock(2,10,5,SMOOTH_BRICK:0,40,SMOOTH_BRICK:1,20,SMOOTH_BRICK:2,30,SMOOTH_BRICK:0,100)
Block(2,10,6,VINE:4)
RandomBlock(2,11,2,SMOOTH_BRICK:0,40,SMOOTH_BRICK:1,20,SMOOTH_BRICK:2,30,SMOOTH_BRICK:0,100)
Block(2,11,3,AIR:0)
RandomBlock(2,11,4,SMOOTH_BRICK:0,40,SMOOTH_BRICK:1,20,SMOOTH_BRICK:2,30,SMOOTH_BRICK:0,100)
Block(2,11,5,VINE:4)
Block(2,12,2,VINE:1)
RandomBlock(2,12,3,SMOOTH_BRICK:0,40,SMOOTH_BRICK:1,20,SMOOTH_BRICK:2,30,SMOOTH_BRICK:0,100)
Block(2,12,4,VINE:4)
RandomBlock(3,0,-7,SMOOTH_BRICK:0,40,SMOOTH_BRICK:1,20,SMOOTH_BRICK:2,30,SMOOTH_BRICK:0,100)
RandomBlock(3,0,-6,SMOOTH_BRICK:0,40,SMOOTH_BRICK:1,20,SMOOTH_BRICK:2,30,SMOOTH_BRICK:0,100)
RandomBlock(3,0,-5,SMOOTH_BRICK:0,40,SMOOTH_BRICK:1,20,SMOOTH_BRICK:2,30,SMOOTH_BRICK:0,100)
RandomBlock(3,0,-4,SMOOTH_BRICK:0,40,SMOOTH_BRICK:1,20,SMOOTH_BRICK:2,30,SMOOTH_BRICK:0,100)
RandomBlock(3,0,-3,SMOOTH_BRICK:0,40,SMOOTH_BRICK:1,20,SMOOTH_BRICK:2,30,SMOOTH_BRICK:0,100)
RandomBlock(3,0,-2,SMOOTH_BRICK:0,40,SMOOTH_BRICK:1,20,SMOOTH_BRICK:2,30,SMOOTH_BRICK:0,100)
RandomBlock(3,0,-1,SMOOTH_BRICK:0,40,SMOOTH_BRICK:1,20,SMOOTH_BRICK:2,30,SMOOTH_BRICK:0,100)
RandomBlock(3,0,0,SMOOTH_BRICK:0,40,SMOOTH_BRICK:1,20,SMOOTH_BRICK:2,30,SMOOTH_BRICK:0,100)
RandomBlock(3,0,1,SMOOTH_BRICK:0,40,SMOOTH_BRICK:1,20,SMOOTH_BRICK:2,30,SMOOTH_BRICK:0,100)
RandomBlock(3,0,2,SMOOTH_BRICK:0,40,SMOOTH_BRICK:1,20,SMOOTH_BRICK:2,30,SMOOTH_BRICK:0,100)
Block(3,0,3,lycanitesmobs:lushstonepolished:0)
RandomBlock(3,0,4,SMOOTH_BRICK:0,40,SMOOTH_BRICK:1,20,SMOOTH_BRICK:2,30,SMOOTH_BRICK:0,100)
RandomBlock(3,0,5,SMOOTH_BRICK:0,40,SMOOTH_BRICK:1,20,SMOOTH_BRICK:2,30,SMOOTH_BRICK:0,100)
RandomBlock(3,0,6,SMOOTH_BRICK:0,40,SMOOTH_BRICK:1,20,SMOOTH_BRICK:2,30,SMOOTH_BRICK:0,100)
RandomBlock(3,0,7,SMOOTH_BRICK:0,40,SMOOTH_BRICK:1,20,SMOOTH_BRICK:2,30,SMOOTH_BRICK:0,100)
RandomBlock(3,0,8,SMOOTH_BRICK:0,40,SMOOTH_BRICK:1,20,SMOOTH_BRICK:2,30,SMOOTH_BRICK:0,100)
Block(3,1,-6,SMOOTH_STAIRS:2)
RandomBlock(3,1,-5,SMOOTH_BRICK:0,40,SMOOTH_BRICK:1,20,SMOOTH_BRICK:2,30,SMOOTH_BRICK:0,100)
RandomBlock(3,1,-4,SMOOTH_BRICK:0,40,SMOOTH_BRICK:1,20,SMOOTH_BRICK:2,30,SMOOTH_BRICK:0,100)
RandomBlock(3,1,-3,SMOOTH_BRICK:0,40,SMOOTH_BRICK:1,20,SMOOTH_BRICK:2,30,SMOOTH_BRICK:0,100)
RandomBlock(3,1,-2,SMOOTH_BRICK:0,40,SMOOTH_BRICK:1,20,SMOOTH_BRICK:2,30,SMOOTH_BRICK:0,100)
RandomBlock(3,1,-1,SMOOTH_BRICK:0,40,SMOOTH_BRICK:1,20,SMOOTH_BRICK:2,30,SMOOTH_BRICK:0,100)
RandomBlock(3,1,0,SMOOTH_BRICK:0,40,SMOOTH_BRICK:1,20,SMOOTH_BRICK:2,30,SMOOTH_BRICK:0,100)
RandomBlock(3,1,1,SMOOTH_BRICK:0,40,SMOOTH_BRICK:1,20,SMOOTH_BRICK:2,30,SMOOTH_BRICK:0,100)
RandomBlock(3,1,2,SMOOTH_BRICK:0,40,SMOOTH_BRICK:1,20,SMOOTH_BRICK:2,30,SMOOTH_BRICK:0,100)
Block(3,1,3,biomesoplenty:blood:0)
RandomBlock(3,1,4,SMOOTH_BRICK:0,40,SMOOTH_BRICK:1,20,SMOOTH_BRICK:2,30,SMOOTH_BRICK:0,100)
RandomBlock(3,1,5,SMOOTH_BRICK:0,40,SMOOTH_BRICK:1,20,SMOOTH_BRICK:2,30,SMOOTH_BRICK:0,100)
RandomBlock(3,1,6,SMOOTH_BRICK:0,40,SMOOTH_BRICK:1,20,SMOOTH_BRICK:2,30,SMOOTH_BRICK:0,100)
RandomBlock(3,1,7,SMOOTH_BRICK:0,40,SMOOTH_BRICK:1,20,SMOOTH_BRICK:2,30,SMOOTH_BRICK:0,100)
RandomBlock(3,1,8,SMOOTH_BRICK:0,40,SMOOTH_BRICK:1,20,SMOOTH_BRICK:2,30,SMOOTH_BRICK:0,100)
Block(3,2,-5,SMOOTH_STAIRS:2)
RandomBlock(3,2,-4,SMOOTH_BRICK:0,40,SMOOTH_BRICK:1,20,SMOOTH_BRICK:2,30,SMOOTH_BRICK:0,100)
RandomBlock(3,2,-3,SMOOTH_BRICK:0,40,SMOOTH_BRICK:1,20,SMOOTH_BRICK:2,30,SMOOTH_BRICK:0,100)
Block(3,2,-2,AIR:0)
Block(3,2,-1,AIR:0)
Block(3,2,0,AIR:0)
Block(3,2,1,AIR:0)
Block(3,2,2,AIR:0)
Block(3,2,3,AIR:0)
Block(3,2,4,AIR:0)
Block(3,2,5,AIR:0)
Block(3,2,6,AIR:0)
Block(3,2,7,AIR:0)
RandomBlock(3,2,8,CHEST:2,null,20,CHEST:2,null,10,CHEST:2,null,15,CHEST:2,null,100)
Block(3,3,-4,SMOOTH_STAIRS:2)
RandomBlock(3,3,-3,SMOOTH_BRICK:0,40,SMOOTH_BRICK:1,20,SMOOTH_BRICK:2,30,SMOOTH_BRICK:0,100)
Block(3,3,-2,AIR:0)
Block(3,3,-1,AIR:0)
Block(3,3,0,AIR:0)
Block(3,3,1,AIR:0)
Block(3,3,2,AIR:0)
Block(3,3,3,AIR:0)
Block(3,3,4,AIR:0)
Block(3,3,5,AIR:0)
Block(3,3,6,AIR:0)
Block(3,3,7,AIR:0)
Block(3,3,8,AIR:0)
Block(3,4,-3,SMOOTH_STAIRS:2)
RandomBlock(3,4,-2,SMOOTH_BRICK:0,40,SMOOTH_BRICK:1,20,SMOOTH_BRICK:2,30,SMOOTH_BRICK:0,100)
Block(3,4,-1,AIR:0)
Block(3,4,0,AIR:0)
Block(3,4,1,AIR:0)
Block(3,4,2,AIR:0)
Block(3,4,3,AIR:0)
Block(3,4,4,AIR:0)
Block(3,4,5,AIR:0)
Block(3,4,6,AIR:0)
Block(3,4,7,AIR:0)
RandomBlock(3,4,8,SMOOTH_BRICK:0,40,SMOOTH_BRICK:1,20,SMOOTH_BRICK:2,30,SMOOTH_BRICK:0,100)
Block(3,5,-2,SMOOTH_STAIRS:2)
RandomBlock(3,5,-1,SMOOTH_BRICK:0,40,SMOOTH_BRICK:1,20,SMOOTH_BRICK:2,30,SMOOTH_BRICK:0,100)
Block(3,5,0,AIR:0)
Block(3,5,1,AIR:0)
Block(3,5,2,AIR:0)
Block(3,5,3,AIR:0)
Block(3,5,4,AIR:0)
Block(3,5,5,AIR:0)
Block(3,5,6,AIR:0)
RandomBlock(3,5,7,SMOOTH_BRICK:0,40,SMOOTH_BRICK:1,20,SMOOTH_BRICK:2,30,SMOOTH_BRICK:0,100)
Block(3,5,8,SMOOTH_STAIRS:3)
Block(3,6,-1,SMOOTH_STAIRS:2)
RandomBlock(3,6,0,SMOOTH_BRICK:0,40,SMOOTH_BRICK:1,20,SMOOTH_BRICK:2,30,SMOOTH_BRICK:0,100)
RandomBlock(3,6,1,SMOOTH_BRICK:0,40,SMOOTH_BRICK:1,20,SMOOTH_BRICK:2,30,SMOOTH_BRICK:0,100)
RandomBlock(3,6,2,SMOOTH_BRICK:0,40,SMOOTH_BRICK:1,20,SMOOTH_BRICK:2,30,SMOOTH_BRICK:0,100)
Block(3,6,3,SMOOTH_STAIRS:0)
RandomBlock(3,6,4,SMOOTH_BRICK:0,40,SMOOTH_BRICK:1,20,SMOOTH_BRICK:2,30,SMOOTH_BRICK:0,100)
RandomBlock(3,6,5,SMOOTH_BRICK:0,40,SMOOTH_BRICK:1,20,SMOOTH_BRICK:2,30,SMOOTH_BRICK:0,100)
RandomBlock(3,6,6,SMOOTH_BRICK:0,40,SMOOTH_BRICK:1,20,SMOOTH_BRICK:2,30,SMOOTH_BRICK:0,100)
Block(3,6,7,SMOOTH_STAIRS:3)
Block(3,7,0,SMOOTH_STAIRS:2)
Block(3,7,1,lycanitesmobs:lushstone_slab:0)
Block(3,7,2,SMOOTH_BRICK:3)
Block(3,7,3,SMOOTH_STAIRS:4)
Block(3,7,4,SMOOTH_BRICK:3)
Block(3,7,5,lycanitesmobs:lushstone_slab:0)
Block(3,7,6,SMOOTH_STAIRS:3)
Block(3,8,2,SMOOTH_BRICK:3)
Block(3,8,4,SMOOTH_BRICK:3)
Block(3,8,6,VINE:4)
Block(3,9,2,SMOOTH_BRICK:3)
Block(3,9,4,SMOOTH_BRICK:3)
Block(3,9,6,VINE:4)
Block(3,10,0,VINE:1)
Block(3,10,1,SMOOTH_BRICK:1)
Block(3,10,2,SMOOTH_BRICK:3)
Block(3,10,3,SMOOTH_STAIRS:5)
Block(3,10,4,SMOOTH_BRICK:3)
RandomBlock(3,10,5,SMOOTH_BRICK:0,40,SMOOTH_BRICK:1,20,SMOOTH_BRICK:2,30,SMOOTH_BRICK:0,100)
Block(3,10,6,VINE:4)
Block(3,11,2,SMOOTH_BRICK:1)
Block(3,11,3,SMOOTH_BRICK:1)
Block(3,11,4,SMOOTH_BRICK:2)
Block(3,12,3,VINE:2)
RandomBlock(4,0,-7,SMOOTH_BRICK:0,40,SMOOTH_BRICK:1,20,SMOOTH_BRICK:2,30,SMOOTH_BRICK:0,100)
RandomBlock(4,0,-6,SMOOTH_BRICK:0,40,SMOOTH_BRICK:1,20,SMOOTH_BRICK:2,30,SMOOTH_BRICK:0,100)
RandomBlock(4,0,-5,SMOOTH_BRICK:0,40,SMOOTH_BRICK:1,20,SMOOTH_BRICK:2,30,SMOOTH_BRICK:0,100)
RandomBlock(4,0,-4,SMOOTH_BRICK:0,40,SMOOTH_BRICK:1,20,SMOOTH_BRICK:2,30,SMOOTH_BRICK:0,100)
RandomBlock(4,0,-3,SMOOTH_BRICK:0,40,SMOOTH_BRICK:1,20,SMOOTH_BRICK:2,30,SMOOTH_BRICK:0,100)
RandomBlock(4,0,-2,SMOOTH_BRICK:0,40,SMOOTH_BRICK:1,20,SMOOTH_BRICK:2,30,SMOOTH_BRICK:0,100)
RandomBlock(4,0,-1,SMOOTH_BRICK:0,40,SMOOTH_BRICK:1,20,SMOOTH_BRICK:2,30,SMOOTH_BRICK:0,100)
Block(4,0,0,lycanitesmobs:lushstonepolished:0)
RandomBlock(4,0,1,SMOOTH_BRICK:0,40,SMOOTH_BRICK:1,20,SMOOTH_BRICK:2,30,SMOOTH_BRICK:0,100)
RandomBlock(4,0,2,SMOOTH_BRICK:0,40,SMOOTH_BRICK:1,20,SMOOTH_BRICK:2,30,SMOOTH_BRICK:0,100)
Block(4,0,3,lycanitesmobs:lushstonepolished:0)
RandomBlock(4,0,4,SMOOTH_BRICK:0,40,SMOOTH_BRICK:1,20,SMOOTH_BRICK:2,30,SMOOTH_BRICK:0,100)
RandomBlock(4,0,5,SMOOTH_BRICK:0,40,SMOOTH_BRICK:1,20,SMOOTH_BRICK:2,30,SMOOTH_BRICK:0,100)
Block(4,0,6,lycanitesmobs:lushstonepolished:0)
RandomBlock(4,0,7,SMOOTH_BRICK:0,40,SMOOTH_BRICK:1,20,SMOOTH_BRICK:2,30,SMOOTH_BRICK:0,100)
RandomBlock(4,0,8,SMOOTH_BRICK:0,40,SMOOTH_BRICK:1,20,SMOOTH_BRICK:2,30,SMOOTH_BRICK:0,100)
Block(4,1,-7,lycanitesmobs:lushstonetile_stairs:2)
Block(4,1,-6,SMOOTH_BRICK:1)
RandomBlock(4,1,-5,SMOOTH_BRICK:0,40,SMOOTH_BRICK:1,20,SMOOTH_BRICK:2,30,SMOOTH_BRICK:0,100)
RandomBlock(4,1,-4,SMOOTH_BRICK:0,40,SMOOTH_BRICK:1,20,SMOOTH_BRICK:2,30,SMOOTH_BRICK:0,100)
RandomBlock(4,1,-3,SMOOTH_BRICK:0,40,SMOOTH_BRICK:1,20,SMOOTH_BRICK:2,30,SMOOTH_BRICK:0,100)
RandomBlock(4,1,-2,SMOOTH_BRICK:0,40,SMOOTH_BRICK:1,20,SMOOTH_BRICK:2,30,SMOOTH_BRICK:0,100)
RandomBlock(4,1,-1,SMOOTH_BRICK:0,40,SMOOTH_BRICK:1,20,SMOOTH_BRICK:2,30,SMOOTH_BRICK:0,100)
Block(4,1,0,biomesoplenty:blood:5)
RandomBlock(4,1,1,SMOOTH_BRICK:0,40,SMOOTH_BRICK:1,20,SMOOTH_BRICK:2,30,SMOOTH_BRICK:0,100)
RandomBlock(4,1,2,SMOOTH_BRICK:0,40,SMOOTH_BRICK:1,20,SMOOTH_BRICK:2,30,SMOOTH_BRICK:0,100)
Block(4,1,3,biomesoplenty:blood:0)
RandomBlock(4,1,4,SMOOTH_BRICK:0,40,SMOOTH_BRICK:1,20,SMOOTH_BRICK:2,30,SMOOTH_BRICK:0,100)
RandomBlock(4,1,5,SMOOTH_BRICK:0,40,SMOOTH_BRICK:1,20,SMOOTH_BRICK:2,30,SMOOTH_BRICK:0,100)
Block(4,1,6,biomesoplenty:blood:5)
RandomBlock(4,1,7,SMOOTH_BRICK:0,40,SMOOTH_BRICK:1,20,SMOOTH_BRICK:2,30,SMOOTH_BRICK:0,100)
RandomBlock(4,1,8,SMOOTH_BRICK:0,40,SMOOTH_BRICK:1,20,SMOOTH_BRICK:2,30,SMOOTH_BRICK:0,100)
Block(4,2,-6,lycanitesmobs:lushstonetile_stairs:2)
Block(4,2,-5,SMOOTH_BRICK:1)
RandomBlock(4,2,-4,SMOOTH_BRICK:0,40,SMOOTH_BRICK:1,20,SMOOTH_BRICK:2,30,SMOOTH_BRICK:0,100)
RandomBlock(4,2,-3,SMOOTH_BRICK:0,40,SMOOTH_BRICK:1,20,SMOOTH_BRICK:2,30,SMOOTH_BRICK:0,100)
Block(4,2,-2,rustic:stone_pillar:0)
Block(4,2,-1,AIR:0)
Block(4,2,0,AIR:0)
Block(4,2,1,AIR:0)
Block(4,2,2,AIR:0)
Block(4,2,3,AIR:0)
Block(4,2,4,AIR:0)
Block(4,2,5,AIR:0)
Block(4,2,6,AIR:0)
Block(4,2,7,AIR:0)
Block(4,2,8,rustic:stone_pillar:0)
Block(4,3,-5,lycanitesmobs:lushstonetile_stairs:2)
Block(4,3,-4,SMOOTH_BRICK:1)
RandomBlock(4,3,-3,SMOOTH_BRICK:0,40,SMOOTH_BRICK:1,20,SMOOTH_BRICK:2,30,SMOOTH_BRICK:0,100)
Block(4,3,-2,rustic:stone_pillar:0)
Block(4,3,-1,AIR:0)
Block(4,3,0,AIR:0)
Block(4,3,1,AIR:0)
Block(4,3,2,AIR:0)
Block(4,3,3,AIR:0)
Block(4,3,4,AIR:0)
Block(4,3,5,AIR:0)
Block(4,3,6,AIR:0)
Block(4,3,7,AIR:0)
Block(4,3,8,rustic:stone_pillar:0)
Block(4,4,-4,lycanitesmobs:lushstonetile_stairs:2)
Block(4,4,-3,SMOOTH_BRICK:1)
RandomBlock(4,4,-2,SMOOTH_BRICK:0,40,SMOOTH_BRICK:1,20,SMOOTH_BRICK:2,30,SMOOTH_BRICK:0,100)
Block(4,4,-1,AIR:0)
Block(4,4,0,AIR:0)
Block(4,4,1,AIR:0)
Block(4,4,2,AIR:0)
Block(4,4,3,AIR:0)
Block(4,4,4,AIR:0)
Block(4,4,5,AIR:0)
Block(4,4,6,AIR:0)
Block(4,4,7,AIR:0)
RandomBlock(4,4,8,SMOOTH_BRICK:0,40,SMOOTH_BRICK:1,20,SMOOTH_BRICK:2,30,SMOOTH_BRICK:0,100)
Block(4,5,-3,lycanitesmobs:lushstonetile_stairs:2)
Block(4,5,-2,SMOOTH_BRICK:1)
RandomBlock(4,5,-1,SMOOTH_BRICK:0,40,SMOOTH_BRICK:1,20,SMOOTH_BRICK:2,30,SMOOTH_BRICK:0,100)
Block(4,5,0,AIR:0)
Block(4,5,1,AIR:0)
Block(4,5,2,AIR:0)
Block(4,5,3,AIR:0)
Block(4,5,4,AIR:0)
Block(4,5,5,AIR:0)
Block(4,5,6,AIR:0)
RandomBlock(4,5,7,SMOOTH_BRICK:0,40,SMOOTH_BRICK:1,20,SMOOTH_BRICK:2,30,SMOOTH_BRICK:0,100)
Block(4,5,8,SMOOTH_BRICK:1)
Block(4,6,-2,lycanitesmobs:lushstonetile_stairs:2)
Block(4,6,-1,SMOOTH_BRICK:1)
RandomBlock(4,6,0,SMOOTH_BRICK:0,40,SMOOTH_BRICK:1,20,SMOOTH_BRICK:2,30,SMOOTH_BRICK:0,100)
RandomBlock(4,6,1,SMOOTH_BRICK:0,40,SMOOTH_BRICK:1,20,SMOOTH_BRICK:2,30,SMOOTH_BRICK:0,100)
RandomBlock(4,6,2,SMOOTH_BRICK:0,40,SMOOTH_BRICK:1,20,SMOOTH_BRICK:2,30,SMOOTH_BRICK:0,100)
RandomBlock(4,6,3,SMOOTH_BRICK:0,40,SMOOTH_BRICK:1,20,SMOOTH_BRICK:2,30,SMOOTH_BRICK:0,100)
RandomBlock(4,6,4,SMOOTH_BRICK:0,40,SMOOTH_BRICK:1,20,SMOOTH_BRICK:2,30,SMOOTH_BRICK:0,100)
RandomBlock(4,6,5,SMOOTH_BRICK:0,40,SMOOTH_BRICK:1,20,SMOOTH_BRICK:2,30,SMOOTH_BRICK:0,100)
RandomBlock(4,6,6,SMOOTH_BRICK:0,40,SMOOTH_BRICK:1,20,SMOOTH_BRICK:2,30,SMOOTH_BRICK:0,100)
RandomBlock(4,6,7,SMOOTH_BRICK:0,40,SMOOTH_BRICK:1,20,SMOOTH_BRICK:2,30,SMOOTH_BRICK:0,100)
Block(4,6,8,lycanitesmobs:lushstonetile_stairs:3)
Block(4,7,-1,lycanitesmobs:lushstonetile_stairs:2)
RandomBlock(4,7,0,SMOOTH_BRICK:0,40,SMOOTH_BRICK:1,20,SMOOTH_BRICK:2,30,SMOOTH_BRICK:0,100)
Block(4,7,1,lycanitesmobs:lushstone_slab:0)
Block(4,7,2,lycanitesmobs:lushstone_slab:0)
Block(4,7,3,lycanitesmobs:lushstone_slab:0)
Block(4,7,4,lycanitesmobs:lushstone_slab:0)
Block(4,7,5,lycanitesmobs:lushstone_slab:0)
RandomBlock(4,7,6,SMOOTH_BRICK:0,40,SMOOTH_BRICK:1,20,SMOOTH_BRICK:2,30,SMOOTH_BRICK:0,100)
Block(4,7,7,lycanitesmobs:lushstonetile_stairs:3)
Block(4,8,0,lycanitesmobs:lushstonechiseled:0)
Block(4,8,6,lycanitesmobs:lushstonechiseled:0)
Block(4,9,0,VINE:1)
Block(4,10,0,VINE:1)
Block(4,10,1,SMOOTH_BRICK:1)
RandomBlock(4,10,2,SMOOTH_BRICK:0,40,SMOOTH_BRICK:1,20,SMOOTH_BRICK:2,30,SMOOTH_BRICK:0,100)
RandomBlock(4,10,3,SMOOTH_BRICK:0,40,SMOOTH_BRICK:1,20,SMOOTH_BRICK:2,30,SMOOTH_BRICK:0,100)
RandomBlock(4,10,4,SMOOTH_BRICK:0,40,SMOOTH_BRICK:1,20,SMOOTH_BRICK:2,30,SMOOTH_BRICK:0,100)
RandomBlock(4,10,5,SMOOTH_BRICK:0,40,SMOOTH_BRICK:1,20,SMOOTH_BRICK:2,30,SMOOTH_BRICK:0,100)
RandomBlock(5,0,-6,SMOOTH_BRICK:0,40,SMOOTH_BRICK:1,20,SMOOTH_BRICK:2,30,SMOOTH_BRICK:0,100)
RandomBlock(5,0,-5,SMOOTH_BRICK:0,40,SMOOTH_BRICK:1,20,SMOOTH_BRICK:2,30,SMOOTH_BRICK:0,100)
RandomBlock(5,0,-4,SMOOTH_BRICK:0,40,SMOOTH_BRICK:1,20,SMOOTH_BRICK:2,30,SMOOTH_BRICK:0,100)
RandomBlock(5,0,-3,SMOOTH_BRICK:0,40,SMOOTH_BRICK:1,20,SMOOTH_BRICK:2,30,SMOOTH_BRICK:0,100)
RandomBlock(5,0,-2,SMOOTH_BRICK:0,40,SMOOTH_BRICK:1,20,SMOOTH_BRICK:2,30,SMOOTH_BRICK:0,100)
RandomBlock(5,0,-1,SMOOTH_BRICK:0,40,SMOOTH_BRICK:1,20,SMOOTH_BRICK:2,30,SMOOTH_BRICK:0,100)
Block(5,0,0,lycanitesmobs:lushstonepolished:0)
Block(5,0,1,lycanitesmobs:lushstonepolished:0)
Block(5,0,2,lycanitesmobs:lushstonepolished:0)
Block(5,0,3,lycanitesmobs:lushstonechiseled:0)
Block(5,0,4,lycanitesmobs:lushstonepolished:0)
Block(5,0,5,lycanitesmobs:lushstonepolished:0)
Block(5,0,6,lycanitesmobs:lushstonepolished:0)
RandomBlock(5,0,7,SMOOTH_BRICK:0,40,SMOOTH_BRICK:1,20,SMOOTH_BRICK:2,30,SMOOTH_BRICK:0,100)
RandomBlock(5,0,8,SMOOTH_BRICK:0,40,SMOOTH_BRICK:1,20,SMOOTH_BRICK:2,30,SMOOTH_BRICK:0,100)
RandomBlock(5,1,-5,SMOOTH_BRICK:0,40,SMOOTH_BRICK:1,20,SMOOTH_BRICK:2,30,SMOOTH_BRICK:0,100)
RandomBlock(5,1,-4,SMOOTH_BRICK:0,40,SMOOTH_BRICK:1,20,SMOOTH_BRICK:2,30,SMOOTH_BRICK:0,100)
RandomBlock(5,1,-3,SMOOTH_BRICK:0,40,SMOOTH_BRICK:1,20,SMOOTH_BRICK:2,30,SMOOTH_BRICK:0,100)
RandomBlock(5,1,-2,SMOOTH_BRICK:0,40,SMOOTH_BRICK:1,20,SMOOTH_BRICK:2,30,SMOOTH_BRICK:0,100)
RandomBlock(5,1,-1,SMOOTH_BRICK:0,40,SMOOTH_BRICK:1,20,SMOOTH_BRICK:2,30,SMOOTH_BRICK:0,100)
Block(5,1,0,biomesoplenty:blood:4)
Block(5,1,1,biomesoplenty:blood:3)
Block(5,1,2,biomesoplenty:blood:2)
Block(5,1,3,biomesoplenty:blood:1)
Block(5,1,4,biomesoplenty:blood:2)
Block(5,1,5,biomesoplenty:blood:3)
Block(5,1,6,biomesoplenty:blood:4)
RandomBlock(5,1,7,SMOOTH_BRICK:0,40,SMOOTH_BRICK:1,20,SMOOTH_BRICK:2,30,SMOOTH_BRICK:0,100)
RandomBlock(5,1,8,SMOOTH_BRICK:0,40,SMOOTH_BRICK:1,20,SMOOTH_BRICK:2,30,SMOOTH_BRICK:0,100)
Block(5,2,-5,lycanitesmobs:lushstone_slab:0)
RandomBlock(5,2,-4,SMOOTH_BRICK:0,40,SMOOTH_BRICK:1,20,SMOOTH_BRICK:2,30,SMOOTH_BRICK:0,100)
Block(5,2,-3,SMOOTH_BRICK:1)
Block(5,2,-2,AIR:0)
Block(5,2,-1,AIR:0)
Block(5,2,0,AIR:0)
Block(5,2,1,AIR:0)
Block(5,2,2,AIR:0)
Block(5,2,3,AIR:0)
Block(5,2,4,AIR:0)
Block(5,2,5,AIR:0)
Block(5,2,6,AIR:0)
Block(5,2,7,AIR:0)
Block(5,2,8,AIR:0)
Block(5,3,-3,SMOOTH_BRICK:1)
Block(5,3,-2,AIR:0)
Block(5,3,-1,AIR:0)
Block(5,3,0,AIR:0)
Block(5,3,1,AIR:0)
Block(5,3,2,AIR:0)
Block(5,3,3,AIR:0)
Block(5,3,4,AIR:0)
Block(5,3,5,AIR:0)
Block(5,3,6,AIR:0)
Block(5,3,7,AIR:0)
Block(5,3,8,AIR:0)
RandomBlock(5,4,-2,SMOOTH_BRICK:0,40,SMOOTH_BRICK:1,20,SMOOTH_BRICK:2,30,SMOOTH_BRICK:0,100)
Block(5,4,-1,AIR:0)
Block(5,4,0,AIR:0)
Block(5,4,1,AIR:0)
Block(5,4,2,AIR:0)
Block(5,4,3,AIR:0)
Block(5,4,4,AIR:0)
Block(5,4,5,AIR:0)
Block(5,4,6,AIR:0)
Block(5,4,7,AIR:0)
Block(5,4,8,SMOOTH_BRICK:1)
Block(5,5,-2,VINE:3)
Block(5,5,-1,SMOOTH_BRICK:1)
Block(5,5,0,AIR:0)
Block(5,5,1,AIR:0)
Block(5,5,2,AIR:0)
Block(5,5,3,AIR:0)
Block(5,5,4,AIR:0)
Block(5,5,5,AIR:0)
Block(5,5,6,AIR:0)
Block(5,5,7,SMOOTH_BRICK:1)
Block(5,6,0,SMOOTH_BRICK:1)
RandomBlock(5,6,1,SMOOTH_BRICK:0,40,SMOOTH_BRICK:1,20,SMOOTH_BRICK:2,30,SMOOTH_BRICK:0,100)
RandomBlock(5,6,2,SMOOTH_BRICK:0,40,SMOOTH_BRICK:1,20,SMOOTH_BRICK:2,30,SMOOTH_BRICK:0,100)
RandomBlock(5,6,3,SMOOTH_BRICK:0,40,SMOOTH_BRICK:1,20,SMOOTH_BRICK:2,30,SMOOTH_BRICK:0,100)
RandomBlock(5,6,4,SMOOTH_BRICK:0,40,SMOOTH_BRICK:1,20,SMOOTH_BRICK:2,30,SMOOTH_BRICK:0,100)
RandomBlock(5,6,5,SMOOTH_BRICK:0,40,SMOOTH_BRICK:1,20,SMOOTH_BRICK:2,30,SMOOTH_BRICK:0,100)
Block(5,6,6,SMOOTH_BRICK:1)
RandomBlock(5,7,1,SMOOTH_BRICK:0,40,SMOOTH_BRICK:1,20,SMOOTH_BRICK:2,30,SMOOTH_BRICK:0,100)
Block(5,7,2,SMOOTH_STAIRS:1)
Block(5,7,3,SMOOTH_STAIRS:1)
Block(5,7,4,SMOOTH_STAIRS:1)
RandomBlock(5,7,5,SMOOTH_BRICK:0,40,SMOOTH_BRICK:1,20,SMOOTH_BRICK:2,30,SMOOTH_BRICK:0,100)
Block(5,8,1,lycanitesmobs:lushstonechiseled:0)
Block(5,8,5,lycanitesmobs:lushstonechiseled:0)
Block(5,9,1,VINE:2)
Block(5,10,1,VINE:2)
RandomBlock(6,0,-6,SMOOTH_BRICK:0,40,SMOOTH_BRICK:1,20,SMOOTH_BRICK:2,30,SMOOTH_BRICK:0,100)
RandomBlock(6,0,-5,SMOOTH_BRICK:0,40,SMOOTH_BRICK:1,20,SMOOTH_BRICK:2,30,SMOOTH_BRICK:0,100)
RandomBlock(6,0,-4,SMOOTH_BRICK:0,40,SMOOTH_BRICK:1,20,SMOOTH_BRICK:2,30,SMOOTH_BRICK:0,100)
RandomBlock(6,0,-3,SMOOTH_BRICK:0,40,SMOOTH_BRICK:1,20,SMOOTH_BRICK:2,30,SMOOTH_BRICK:0,100)
RandomBlock(6,0,-2,SMOOTH_BRICK:0,40,SMOOTH_BRICK:1,20,SMOOTH_BRICK:2,30,SMOOTH_BRICK:0,100)
RandomBlock(6,0,-1,SMOOTH_BRICK:0,40,SMOOTH_BRICK:1,20,SMOOTH_BRICK:2,30,SMOOTH_BRICK:0,100)
RandomBlock(6,0,0,SMOOTH_BRICK:0,40,SMOOTH_BRICK:1,20,SMOOTH_BRICK:2,30,SMOOTH_BRICK:0,100)
RandomBlock(6,0,1,SMOOTH_BRICK:0,40,SMOOTH_BRICK:1,20,SMOOTH_BRICK:2,30,SMOOTH_BRICK:0,100)
RandomBlock(6,0,2,SMOOTH_BRICK:0,40,SMOOTH_BRICK:1,20,SMOOTH_BRICK:2,30,SMOOTH_BRICK:0,100)
RandomBlock(6,0,3,SMOOTH_BRICK:0,40,SMOOTH_BRICK:1,20,SMOOTH_BRICK:2,30,SMOOTH_BRICK:0,100)
RandomBlock(6,0,4,SMOOTH_BRICK:0,40,SMOOTH_BRICK:1,20,SMOOTH_BRICK:2,30,SMOOTH_BRICK:0,100)
RandomBlock(6,0,5,SMOOTH_BRICK:0,40,SMOOTH_BRICK:1,20,SMOOTH_BRICK:2,30,SMOOTH_BRICK:0,100)
RandomBlock(6,0,6,SMOOTH_BRICK:0,40,SMOOTH_BRICK:1,20,SMOOTH_BRICK:2,30,SMOOTH_BRICK:0,100)
RandomBlock(6,0,7,SMOOTH_BRICK:0,40,SMOOTH_BRICK:1,20,SMOOTH_BRICK:2,30,SMOOTH_BRICK:0,100)
RandomBlock(6,0,8,SMOOTH_BRICK:0,40,SMOOTH_BRICK:1,20,SMOOTH_BRICK:2,30,SMOOTH_BRICK:0,100)
RandomBlock(6,1,-5,SMOOTH_BRICK:0,40,SMOOTH_BRICK:1,20,SMOOTH_BRICK:2,30,SMOOTH_BRICK:0,100)
RandomBlock(6,1,-4,SMOOTH_BRICK:0,40,SMOOTH_BRICK:1,20,SMOOTH_BRICK:2,30,SMOOTH_BRICK:0,100)
RandomBlock(6,1,-3,SMOOTH_BRICK:0,40,SMOOTH_BRICK:1,20,SMOOTH_BRICK:2,30,SMOOTH_BRICK:0,100)
RandomBlock(6,1,-2,SMOOTH_BRICK:0,40,SMOOTH_BRICK:1,20,SMOOTH_BRICK:2,30,SMOOTH_BRICK:0,100)
RandomBlock(6,1,-1,SMOOTH_BRICK:0,40,SMOOTH_BRICK:1,20,SMOOTH_BRICK:2,30,SMOOTH_BRICK:0,100)
RandomBlock(6,1,0,SMOOTH_BRICK:0,40,SMOOTH_BRICK:1,20,SMOOTH_BRICK:2,30,SMOOTH_BRICK:0,100)
RandomBlock(6,1,1,SMOOTH_BRICK:0,40,SMOOTH_BRICK:1,20,SMOOTH_BRICK:2,30,SMOOTH_BRICK:0,100)
RandomBlock(6,1,2,SMOOTH_BRICK:0,40,SMOOTH_BRICK:1,20,SMOOTH_BRICK:2,30,SMOOTH_BRICK:0,100)
RandomBlock(6,1,3,SMOOTH_BRICK:0,40,SMOOTH_BRICK:1,20,SMOOTH_BRICK:2,30,SMOOTH_BRICK:0,100)
RandomBlock(6,1,4,SMOOTH_BRICK:0,40,SMOOTH_BRICK:1,20,SMOOTH_BRICK:2,30,SMOOTH_BRICK:0,100)
RandomBlock(6,1,5,SMOOTH_BRICK:0,40,SMOOTH_BRICK:1,20,SMOOTH_BRICK:2,30,SMOOTH_BRICK:0,100)
RandomBlock(6,1,6,SMOOTH_BRICK:0,40,SMOOTH_BRICK:1,20,SMOOTH_BRICK:2,30,SMOOTH_BRICK:0,100)
RandomBlock(6,1,7,SMOOTH_BRICK:0,40,SMOOTH_BRICK:1,20,SMOOTH_BRICK:2,30,SMOOTH_BRICK:0,100)
RandomBlock(6,1,8,SMOOTH_BRICK:0,40,SMOOTH_BRICK:1,20,SMOOTH_BRICK:2,30,SMOOTH_BRICK:0,100)
Block(6,2,-5,lycanitesmobs:lushstone_slab:0)
RandomBlock(6,2,-4,SMOOTH_BRICK:0,40,SMOOTH_BRICK:1,20,SMOOTH_BRICK:2,30,SMOOTH_BRICK:0,100)
Block(6,2,-3,SMOOTH_BRICK:1)
RandomBlock(6,2,-2,CHEST:3,null,20,CHEST:3,null,10,CHEST:3,null,15,CHEST:3,null,100)
Block(6,2,-1,AIR:0)
Block(6,2,0,AIR:0)
Block(6,2,1,AIR:0)
Block(6,2,2,AIR:0)
Block(6,2,3,AIR:0)
Block(6,2,4,AIR:0)
Block(6,2,5,AIR:0)
Block(6,2,6,AIR:0)
Block(6,2,7,AIR:0)
Block(6,2,8,AIR:0)
RandomBlock(6,3,-3,SMOOTH_BRICK:0,40,SMOOTH_BRICK:1,20,SMOOTH_BRICK:2,30,SMOOTH_BRICK:0,100)
Block(6,3,-2,AIR:0)
Block(6,3,-1,AIR:0)
Block(6,3,0,AIR:0)
Block(6,3,1,AIR:0)
Block(6,3,2,AIR:0)
Block(6,3,3,AIR:0)
Block(6,3,4,AIR:0)
Block(6,3,5,AIR:0)
Block(6,3,6,AIR:0)
Block(6,3,7,AIR:0)
Block(6,3,8,AIR:0)
RandomBlock(6,4,-2,SMOOTH_BRICK:0,40,SMOOTH_BRICK:1,20,SMOOTH_BRICK:2,30,SMOOTH_BRICK:0,100)
Block(6,4,-1,AIR:0)
Block(6,4,0,AIR:0)
Block(6,4,1,AIR:0)
Block(6,4,2,AIR:0)
Block(6,4,3,AIR:0)
Block(6,4,4,AIR:0)
Block(6,4,5,AIR:0)
Block(6,4,6,AIR:0)
Block(6,4,7,AIR:0)
RandomBlock(6,4,8,SMOOTH_BRICK:0,40,SMOOTH_BRICK:1,20,SMOOTH_BRICK:2,30,SMOOTH_BRICK:0,100)
Block(6,5,-2,VINE:1)
RandomBlock(6,5,-1,SMOOTH_BRICK:0,40,SMOOTH_BRICK:1,20,SMOOTH_BRICK:2,30,SMOOTH_BRICK:0,100)
Block(6,5,0,SMOOTH_BRICK:1)
RandomBlock(6,5,1,SMOOTH_BRICK:0,40,SMOOTH_BRICK:1,20,SMOOTH_BRICK:2,30,SMOOTH_BRICK:0,100)
RandomBlock(6,5,2,SMOOTH_BRICK:0,40,SMOOTH_BRICK:1,20,SMOOTH_BRICK:2,30,SMOOTH_BRICK:0,100)
RandomBlock(6,5,3,SMOOTH_BRICK:0,40,SMOOTH_BRICK:1,20,SMOOTH_BRICK:2,30,SMOOTH_BRICK:0,100)
RandomBlock(6,5,4,SMOOTH_BRICK:0,40,SMOOTH_BRICK:1,20,SMOOTH_BRICK:2,30,SMOOTH_BRICK:0,100)
RandomBlock(6,5,5,SMOOTH_BRICK:0,40,SMOOTH_BRICK:1,20,SMOOTH_BRICK:2,30,SMOOTH_BRICK:0,100)
Block(6,5,6,SMOOTH_BRICK:1)
Block(6,5,7,SMOOTH_BRICK:1)
RandomBlock(6,6,1,SMOOTH_BRICK:0,40,SMOOTH_BRICK:1,20,SMOOTH_BRICK:2,30,SMOOTH_BRICK:0,100)
Block(6,6,2,SMOOTH_STAIRS:1)
Block(6,6,3,SMOOTH_STAIRS:1)
Block(6,6,4,SMOOTH_STAIRS:1)
RandomBlock(6,6,5,SMOOTH_BRICK:0,40,SMOOTH_BRICK:1,20,SMOOTH_BRICK:2,30,SMOOTH_BRICK:0,100)
Block(6,7,1,lycanitesmobs:lushstonetile_stairs:1)
Block(6,7,5,lycanitesmobs:lushstonetile_stairs:1)
RandomBlock(7,0,-6,SMOOTH_BRICK:0,40,SMOOTH_BRICK:1,20,SMOOTH_BRICK:2,30,SMOOTH_BRICK:0,100)
RandomBlock(7,0,-5,SMOOTH_BRICK:0,40,SMOOTH_BRICK:1,20,SMOOTH_BRICK:2,30,SMOOTH_BRICK:0,100)
RandomBlock(7,0,-4,SMOOTH_BRICK:0,40,SMOOTH_BRICK:1,20,SMOOTH_BRICK:2,30,SMOOTH_BRICK:0,100)
RandomBlock(7,0,-3,SMOOTH_BRICK:0,40,SMOOTH_BRICK:1,20,SMOOTH_BRICK:2,30,SMOOTH_BRICK:0,100)
RandomBlock(7,0,-2,SMOOTH_BRICK:0,40,SMOOTH_BRICK:1,20,SMOOTH_BRICK:2,30,SMOOTH_BRICK:0,100)
RandomBlock(7,0,-1,SMOOTH_BRICK:0,40,SMOOTH_BRICK:1,20,SMOOTH_BRICK:2,30,SMOOTH_BRICK:0,100)
RandomBlock(7,0,0,SMOOTH_BRICK:0,40,SMOOTH_BRICK:1,20,SMOOTH_BRICK:2,30,SMOOTH_BRICK:0,100)
RandomBlock(7,0,1,SMOOTH_BRICK:0,40,SMOOTH_BRICK:1,20,SMOOTH_BRICK:2,30,SMOOTH_BRICK:0,100)
RandomBlock(7,0,2,SMOOTH_BRICK:0,40,SMOOTH_BRICK:1,20,SMOOTH_BRICK:2,30,SMOOTH_BRICK:0,100)
RandomBlock(7,0,3,SMOOTH_BRICK:0,40,SMOOTH_BRICK:1,20,SMOOTH_BRICK:2,30,SMOOTH_BRICK:0,100)
RandomBlock(7,0,4,SMOOTH_BRICK:0,40,SMOOTH_BRICK:1,20,SMOOTH_BRICK:2,30,SMOOTH_BRICK:0,100)
RandomBlock(7,0,5,SMOOTH_BRICK:0,40,SMOOTH_BRICK:1,20,SMOOTH_BRICK:2,30,SMOOTH_BRICK:0,100)
RandomBlock(7,0,6,SMOOTH_BRICK:0,40,SMOOTH_BRICK:1,20,SMOOTH_BRICK:2,30,SMOOTH_BRICK:0,100)
RandomBlock(7,0,7,SMOOTH_BRICK:0,40,SMOOTH_BRICK:1,20,SMOOTH_BRICK:2,30,SMOOTH_BRICK:0,100)
RandomBlock(7,0,8,SMOOTH_BRICK:0,40,SMOOTH_BRICK:1,20,SMOOTH_BRICK:2,30,SMOOTH_BRICK:0,100)
RandomBlock(7,1,-5,SMOOTH_BRICK:0,40,SMOOTH_BRICK:1,20,SMOOTH_BRICK:2,30,SMOOTH_BRICK:0,100)
RandomBlock(7,1,-4,SMOOTH_BRICK:0,40,SMOOTH_BRICK:1,20,SMOOTH_BRICK:2,30,SMOOTH_BRICK:0,100)
RandomBlock(7,1,-3,SMOOTH_BRICK:0,40,SMOOTH_BRICK:1,20,SMOOTH_BRICK:2,30,SMOOTH_BRICK:0,100)
RandomBlock(7,1,-2,SMOOTH_BRICK:0,40,SMOOTH_BRICK:1,20,SMOOTH_BRICK:2,30,SMOOTH_BRICK:0,100)
RandomBlock(7,1,-1,SMOOTH_BRICK:0,40,SMOOTH_BRICK:1,20,SMOOTH_BRICK:2,30,SMOOTH_BRICK:0,100)
RandomBlock(7,1,0,SMOOTH_BRICK:0,40,SMOOTH_BRICK:1,20,SMOOTH_BRICK:2,30,SMOOTH_BRICK:0,100)
RandomBlock(7,1,1,SMOOTH_BRICK:0,40,SMOOTH_BRICK:1,20,SMOOTH_BRICK:2,30,SMOOTH_BRICK:0,100)
RandomBlock(7,1,2,SMOOTH_BRICK:0,40,SMOOTH_BRICK:1,20,SMOOTH_BRICK:2,30,SMOOTH_BRICK:0,100)
RandomBlock(7,1,3,SMOOTH_BRICK:0,40,SMOOTH_BRICK:1,20,SMOOTH_BRICK:2,30,SMOOTH_BRICK:0,100)
RandomBlock(7,1,4,SMOOTH_BRICK:0,40,SMOOTH_BRICK:1,20,SMOOTH_BRICK:2,30,SMOOTH_BRICK:0,100)
RandomBlock(7,1,5,SMOOTH_BRICK:0,40,SMOOTH_BRICK:1,20,SMOOTH_BRICK:2,30,SMOOTH_BRICK:0,100)
RandomBlock(7,1,6,SMOOTH_BRICK:0,40,SMOOTH_BRICK:1,20,SMOOTH_BRICK:2,30,SMOOTH_BRICK:0,100)
RandomBlock(7,1,7,SMOOTH_BRICK:0,40,SMOOTH_BRICK:1,20,SMOOTH_BRICK:2,30,SMOOTH_BRICK:0,100)
RandomBlock(7,1,8,SMOOTH_BRICK:0,40,SMOOTH_BRICK:1,20,SMOOTH_BRICK:2,30,SMOOTH_BRICK:0,100)
Block(7,2,-5,lycanitesmobs:lushstone_slab:0)
RandomBlock(7,2,-4,SMOOTH_BRICK:0,40,SMOOTH_BRICK:1,20,SMOOTH_BRICK:2,30,SMOOTH_BRICK:0,100)
Block(7,2,-3,SMOOTH_BRICK:1)
Block(7,2,-2,rustic:stone_pillar:0)
Block(7,2,-1,AIR:0)
Block(7,2,0,AIR:0)
Block(7,2,1,rustic:stone_pillar:0)
Block(7,2,2,AIR:0)
Block(7,2,3,AIR:0)
Block(7,2,4,AIR:0)
Block(7,2,5,rustic:stone_pillar:0)
Block(7,2,6,AIR:0)
Block(7,2,7,AIR:0)
Block(7,2,8,rustic:stone_pillar:0)
Block(7,3,-4,VINE:1)
RandomBlock(7,3,-3,SMOOTH_BRICK:0,40,SMOOTH_BRICK:1,20,SMOOTH_BRICK:2,30,SMOOTH_BRICK:0,100)
Block(7,3,-2,rustic:stone_pillar:0)
Block(7,3,-1,AIR:0)
Block(7,3,0,AIR:0)
Block(7,3,1,rustic:stone_pillar:0)
Block(7,3,2,AIR:0)
Block(7,3,3,AIR:0)
Block(7,3,4,AIR:0)
Block(7,3,5,rustic:stone_pillar:0)
Block(7,3,6,AIR:0)
Block(7,3,7,AIR:0)
Block(7,3,8,rustic:stone_pillar:0)
RandomBlock(7,4,-2,SMOOTH_BRICK:0,40,SMOOTH_BRICK:1,20,SMOOTH_BRICK:2,30,SMOOTH_BRICK:0,100)
RandomBlock(7,4,-1,SMOOTH_BRICK:0,40,SMOOTH_BRICK:1,20,SMOOTH_BRICK:2,30,SMOOTH_BRICK:0,100)
Block(7,4,0,SMOOTH_BRICK:1)
RandomBlock(7,4,1,SMOOTH_BRICK:0,40,SMOOTH_BRICK:1,20,SMOOTH_BRICK:2,30,SMOOTH_BRICK:0,100)
RandomBlock(7,4,2,SMOOTH_BRICK:0,40,SMOOTH_BRICK:1,20,SMOOTH_BRICK:2,30,SMOOTH_BRICK:0,100)
RandomBlock(7,4,3,SMOOTH_BRICK:0,40,SMOOTH_BRICK:1,20,SMOOTH_BRICK:2,30,SMOOTH_BRICK:0,100)
RandomBlock(7,4,4,SMOOTH_BRICK:0,40,SMOOTH_BRICK:1,20,SMOOTH_BRICK:2,30,SMOOTH_BRICK:0,100)
RandomBlock(7,4,5,SMOOTH_BRICK:0,40,SMOOTH_BRICK:1,20,SMOOTH_BRICK:2,30,SMOOTH_BRICK:0,100)
RandomBlock(7,4,6,SMOOTH_BRICK:0,40,SMOOTH_BRICK:1,20,SMOOTH_BRICK:2,30,SMOOTH_BRICK:0,100)
RandomBlock(7,4,7,SMOOTH_BRICK:0,40,SMOOTH_BRICK:1,20,SMOOTH_BRICK:2,30,SMOOTH_BRICK:0,100)
RandomBlock(7,4,8,SMOOTH_BRICK:0,40,SMOOTH_BRICK:1,20,SMOOTH_BRICK:2,30,SMOOTH_BRICK:0,100)
Block(7,5,1,SMOOTH_BRICK:1)
Block(7,5,2,SMOOTH_STAIRS:1)
Block(7,5,3,SMOOTH_STAIRS:1)
Block(7,5,4,SMOOTH_STAIRS:1)
Block(7,5,5,SMOOTH_BRICK:1)
Block(7,6,1,lycanitesmobs:lushstonetile_stairs:1)
Block(7,6,5,lycanitesmobs:lushstonetile_stairs:1)

#######################################################################
# +-----------------------------------------------------------------+ #
# |                             Branches                            | #
# +-----------------------------------------------------------------+ #
#######################################################################

Branch(16,0,0,true,PyramidStoneC1R0,NORTH,100.0,0)

#######################################################################
# +-----------------------------------------------------------------+ #
# |                             Entities                            | #
# +-----------------------------------------------------------------+ #
#######################################################################


#######################################################################
# +-----------------------------------------------------------------+ #
# |                            Particles                            | #
# +-----------------------------------------------------------------+ #
#######################################################################


#######################################################################
# +-----------------------------------------------------------------+ #
# |                             Spawners                            | #
# +-----------------------------------------------------------------+ #
#######################################################################


#######################################################################
# +-----------------------------------------------------------------+ #
# |                             ModData                             | #
# +-----------------------------------------------------------------+ #
#######################################################################

