
#######################################################################
# +-----------------------------------------------------------------+ #
# |                            BO4 object                           | #
# +-----------------------------------------------------------------+ #
#######################################################################

Author: NLBlackEagle

Description: No description given

SettingsMode: WriteWithoutComments


#######################################################################
# +-----------------------------------------------------------------+ #
# |                          Main settings                          | #
# +-----------------------------------------------------------------+ #
#######################################################################

FixedRotation: 

Frequency: 0

SpawnHeight: highestBlock

UseCenterForHighestBlock: true

##############################
# Height Limits for the BO4. #
##############################

MinHeight: 0

MaxHeight: 255

InheritBO3: 

InheritBO3Rotation: NORTH

OverrideChildSettings: true

OverrideParentHeight: false

CanOverride: true

BranchFrequency: 0

BranchFrequencyGroup: 

MustBeBelowOther: false

MustBeInside: 

CannotBeInside: 

ReplacesBO3: 

MustBeInsideWorldBorders: false

CanSpawnOnWater: true

SpawnOnWaterOnly: false

SpawnUnderWater: false

SpawnAtWaterLevel: false

HeightOffset: 0

RemoveAir: false

ReplaceAbove: 

ReplaceBelow: 

ReplaceWithBiomeBlocks: false

ReplaceWithSurfaceBlock: GRASS

ReplaceWithGroundBlock: DIRT

ReplaceWithStoneBlock: STONE

SmoothRadius: 0

SmoothHeightOffset: 0

SmoothStartTop: false

SmoothStartWood: false

SmoothingSurfaceBlock: 

SmoothingGroundBlock: 

BO3Group: 

IsSpawnPoint: false

DoReplaceBlocks: true


#######################################################################
# +-----------------------------------------------------------------+ #
# |                              Blocks                             | #
# +-----------------------------------------------------------------+ #
#######################################################################

Block(-8,0,-7,quark:world_stone_pavement:2)
Block(-8,0,-6,quark:world_stone_pavement:1)
Block(-8,0,-5,quark:world_stone_pavement:2)
Block(-8,0,-4,quark:world_stone_pavement:1)
Block(-8,0,-3,quark:world_stone_pavement:1)
Block(-8,0,-2,quark:world_stone_pavement:4)
Block(-8,0,-1,quark:world_stone_pavement:2)
Block(-8,0,0,quark:world_stone_pavement:2)
Block(-8,0,1,quark:limestone:1)
Block(-8,0,2,quark:world_stone_pavement:2)
Block(-8,0,3,quark:world_stone_pavement:2)
Block(-8,0,4,quark:world_stone_pavement:2)
Block(-8,0,5,quark:limestone:1)
Block(-8,0,6,quark:world_stone_pavement:5)
Block(-8,0,7,quark:world_stone_pavement:5)
Block(-8,0,8,quark:limestone:1)
Block(-8,1,-7,quark:world_stone_pavement:2)
Block(-8,1,-6,quark:world_stone_pavement:2)
Block(-8,1,-5,quark:world_stone_pavement:2)
Block(-8,1,-4,quark:world_stone_pavement:1)
Block(-8,1,-3,quark:world_stone_pavement:4)
Block(-8,1,-2,quark:world_stone_pavement:2)
Block(-8,1,-1,quark:world_stone_pavement:2)
Block(-8,1,0,quark:world_stone_pavement:2)
Block(-8,1,1,quark:world_stone_pavement:5)
Block(-8,1,2,quark:world_stone_pavement:5)
Block(-8,1,3,quark:world_stone_pavement:2)
Block(-8,1,4,quark:world_stone_pavement:2)
Block(-8,1,5,quark:limestone:1)
Block(-8,1,6,quark:world_stone_pavement:2)
Block(-8,1,7,quark:limestone:1)
Block(-8,1,8,quark:limestone:1)
Block(-8,2,-7,quark:world_stone_pavement:4)
Block(-8,2,-6,quark:world_stone_pavement:2)
Block(-8,2,-5,quark:world_stone_pavement:2)
Block(-8,2,-4,quark:world_stone_pavement:4)
Block(-8,2,-3,quark:world_stone_pavement:1)
Block(-8,2,-2,quark:world_stone_pavement:4)
Block(-8,2,-1,quark:world_stone_pavement:2)
Block(-8,2,0,quark:world_stone_pavement:2)
Block(-8,2,1,quark:world_stone_pavement:2)
Block(-8,2,2,quark:world_stone_pavement:2)
Block(-8,2,3,quark:world_stone_pavement:5)
Block(-8,2,4,quark:world_stone_pavement:5)
Block(-8,2,5,quark:world_stone_pavement:2)
Block(-8,2,6,quark:limestone:1)
Block(-8,2,7,quark:limestone:1)
Block(-8,2,8,quark:limestone:1)
Block(-8,3,-7,quark:world_stone_pavement:2)
Block(-8,3,-6,quark:world_stone_pavement:1)
Block(-8,3,-5,quark:world_stone_pavement:2)
Block(-8,3,-4,quark:world_stone_pavement:2)
Block(-8,3,-3,quark:world_stone_pavement:2)
Block(-8,3,-2,quark:world_stone_pavement:4)
Block(-8,3,-1,quark:world_stone_pavement:2)
Block(-8,3,0,quark:world_stone_pavement:2)
Block(-8,3,1,quark:world_stone_pavement:2)
Block(-8,3,2,quark:limestone:1)
Block(-8,3,3,quark:world_stone_pavement:2)
Block(-8,3,4,quark:world_stone_pavement:2)
Block(-8,3,5,quark:limestone:1)
Block(-8,3,6,quark:world_stone_pavement:2)
Block(-8,3,7,quark:limestone:1)
Block(-8,3,8,quark:world_stone_pavement:2)
Block(-8,4,-7,quark:world_stone_pavement:4)
Block(-8,4,-6,quark:world_stone_pavement:2)
Block(-8,4,-5,quark:world_stone_pavement:2)
Block(-8,4,-4,quark:world_stone_pavement:4)
Block(-8,4,-3,quark:world_stone_pavement:2)
Block(-8,4,-2,quark:world_stone_pavement:2)
Block(-8,4,-1,quark:world_stone_pavement:2)
Block(-8,4,0,quark:world_stone_pavement:2)
Block(-8,4,1,quark:iron_plate:1)
Block(-8,4,2,quark:world_stone_pavement:2)
Block(-8,4,3,quark:world_stone_pavement:2)
Block(-8,4,4,quark:iron_plate:1)
Block(-8,4,5,quark:world_stone_pavement:5)
Block(-8,4,6,quark:world_stone_pavement:2)
Block(-8,4,7,quark:world_stone_pavement:2)
Block(-8,4,8,quark:world_stone_pavement:5)
Block(-8,5,-7,quark:world_stone_pavement:1)
Block(-8,5,-6,quark:world_stone_pavement:4)
Block(-8,5,-5,quark:world_stone_pavement:2)
Block(-8,5,-4,quark:world_stone_pavement:2)
Block(-8,5,-3,quark:world_stone_pavement:1)
Block(-8,5,-2,quark:world_stone_pavement:2)
Block(-8,5,-1,quark:world_stone_pavement:2)
Block(-8,5,0,quark:world_stone_pavement:2)
Block(-8,5,1,quark:world_stone_pavement:2)
Block(-8,5,2,quark:world_stone_pavement:5)
Block(-8,5,3,quark:world_stone_pavement:5)
RandomBlock(-8,5,4,rustic:iron_lattice:0,30,rustic:iron_lattice:1,100)
Block(-8,5,5,quark:world_stone_pavement:5)
Block(-8,5,6,quark:world_stone_pavement:2)
Block(-8,5,7,quark:world_stone_pavement:2)
Block(-8,5,8,quark:world_stone_pavement:5)
Block(-8,6,-7,REDSTONE_WIRE:0)
Block(-8,6,-6,quark:world_stone_pavement:1)
Block(-8,6,-5,quark:world_stone_pavement:1)
Block(-8,6,-4,quark:world_stone_pavement:1)
Block(-8,6,-3,quark:marble_wall:0)
Block(-8,6,-2,quark:marble_wall:0)
Block(-8,6,-1,quark:marble_wall:0)
Block(-8,6,0,quark:marble_wall:0)
Block(-8,6,1,quark:marble_wall:0)
Block(-8,6,2,AIR:0)
Block(-8,6,3,AIR:0)
Block(-8,6,4,quark:iron_plate_slab:8)
Block(-8,6,5,quark:world_stone_pavement:5)
Block(-8,6,6,quark:world_stone_pavement:2)
Block(-8,6,7,quark:world_stone_pavement:5)
Block(-8,6,8,quark:limestone:1)
Block(-8,7,-7,STEP:8)
Block(-8,7,-6,REDSTONE_WIRE:0)
Block(-8,7,-5,OBSERVER:2)
Block(-8,7,-4,REDSTONE_WIRE:0)
Block(-8,7,-3,quark:marble_wall:0)
Block(-8,7,-2,quark:marble_wall:0)
Block(-8,7,-1,quark:marble_wall:0)
Block(-8,7,0,quark:marble_wall:0)
Block(-8,7,1,quark:marble_wall:0)
Block(-8,7,2,AIR:0)
Block(-8,7,3,AIR:0)
Block(-8,7,4,AIR:0)
Block(-8,7,5,srparasites:infestedstain:0)
Block(-8,7,6,quark:limestone:1)
Block(-8,7,7,quark:world_stone_pavement:5)
Block(-8,7,8,quark:world_stone_pavement:5)
Block(-8,8,-7,quark:world_stone_pavement:2)
Block(-8,8,-6,quark:world_stone_pavement:4)
Block(-8,8,-5,quark:world_stone_pavement:4)
Block(-8,8,-4,quark:world_stone_pavement:2)
Block(-8,8,-3,quark:world_stone_pavement:1)
Block(-8,8,-2,quark:world_stone_pavement:2)
Block(-8,8,-1,quark:world_stone_pavement:5)
Block(-8,8,0,quark:limestone:1)
Block(-8,8,1,quark:limestone:1)
Block(-8,8,2,quark:limestone:1)
Block(-8,8,3,quark:world_stone_pavement:5)
Block(-8,8,4,quark:world_stone_pavement:2)
Block(-8,8,5,quark:polished_stone:0)
Block(-8,8,6,quark:limestone:1)
Block(-8,8,7,quark:polished_stone:0)
Block(-8,8,8,quark:polished_stone:0)
Block(-8,9,-7,quark:limestone:1)
Block(-8,9,-6,quark:world_stone_pavement:5)
Block(-8,9,-5,quark:world_stone_pavement:2)
Block(-8,9,-4,quark:world_stone_pavement:2)
Block(-8,9,-3,quark:world_stone_pavement:5)
Block(-8,9,-2,quark:world_stone_pavement:5)
Block(-8,9,-1,quark:world_stone_pavement:5)
Block(-8,9,0,quark:limestone:1)
Block(-8,9,1,quark:world_stone_pavement:5)
Block(-8,9,2,quark:world_stone_pavement:2)
Block(-8,9,3,quark:polished_stone:0)
Block(-8,9,4,quark:world_stone_pavement:2)
Block(-8,9,5,quark:polished_stone:0)
Block(-8,9,6,quark:world_stone_pavement:2)
Block(-8,9,7,quark:polished_stone:0)
Block(-8,9,8,quark:world_stone_pavement:5)
Block(-8,10,-7,quark:world_stone_pavement:2)
Block(-8,10,-6,srparasites:infestedstain:0)
Block(-8,10,-5,quark:limestone:1)
Block(-8,10,-4,quark:world_stone_pavement:5)
Block(-8,10,-3,quark:world_stone_pavement:2)
Block(-8,10,-2,quark:limestone:1)
Block(-8,10,-1,quark:limestone:1)
Block(-8,10,0,srparasites:infestedstain:0)
Block(-8,10,1,srparasites:parasitestain:1)
Block(-8,10,2,quark:limestone:1)
Block(-8,10,3,quark:polished_stone:0)
Block(-8,10,4,quark:polished_stone:0)
Block(-8,10,5,quark:polished_stone:0)
Block(-8,10,6,quark:polished_stone:0)
Block(-8,10,7,quark:world_stone_pavement:2)
Block(-8,10,8,quark:world_stone_pavement:5)
Block(-8,11,-6,srparasites:infestedbush:0)
Block(-8,11,0,srparasites:parasitebush:3)
Block(-8,11,1,srparasites:parasitebush:0)
Block(-8,11,4,quark:iron_plate:1)
Block(-8,11,5,quark:iron_plate:1)
Block(-8,11,6,quark:polished_stone:0)
Block(-8,11,7,quark:polished_stone:0)
Block(-8,12,4,quark:iron_plate:1)
Block(-8,12,5,quark:iron_plate:1)
Block(-8,12,6,DOUBLE_STEP:0)
Block(-8,12,7,quark:polished_stone:0)
Block(-8,13,2,quark:iron_plate:1)
Block(-8,13,4,quark:iron_plate:1)
Block(-8,13,5,quark:iron_plate:1)
Block(-8,13,6,DOUBLE_STEP:0)
Block(-8,13,7,quark:polished_stone:0)
Block(-8,13,8,quark:grate:0)
Block(-8,14,4,quark:iron_plate:1)
Block(-8,14,5,quark:iron_plate:1)
Block(-8,14,6,DOUBLE_STEP:0)
Block(-8,14,7,quark:polished_stone:0)
RandomBlock(-8,14,8,CHEST:3,../../../../Chests/Loot/moderncity_useful_loot.nbt,20,CHEST:3,../../../../Chests/Loot/moderncity_rare_loot.nbt,10,CHEST:3,../../../../Chests/Loot/moderncity_epic_loot.nbt,5,CHEST:3,../../../../Chests/RLCraft/Ruins/industrial.nbt,50,CHEST:3,../../../../Chests/RLCraft/Ruins/nuclear.nbt,100)
Block(-8,15,2,quark:iron_plate_slab:8)
Block(-8,15,3,quark:grate:0)
Block(-8,15,4,quark:iron_plate:1)
Block(-8,15,5,quark:iron_plate:1)
Block(-8,15,6,DOUBLE_STEP:0)
Block(-8,15,7,quark:polished_stone:0)
RandomBlock(-8,16,2,rustic:iron_lattice:0,30,rustic:iron_lattice:1,100)
Block(-8,16,4,quark:iron_plate:1)
Block(-8,16,5,quark:iron_plate:1)
Block(-8,16,6,DOUBLE_STEP:0)
Block(-8,16,7,quark:world_stone_pavement:2)
RandomBlock(-8,17,2,rustic:iron_lattice:0,30,rustic:iron_lattice:1,100)
Block(-8,17,4,quark:iron_plate:1)
Block(-8,17,5,quark:iron_plate:1)
RandomBlock(-8,17,6,SMOOTH_BRICK:0,40,SMOOTH_BRICK:1,30,SMOOTH_BRICK:2,30,MOSSY_COBBLESTONE:0,30,COBBLESTONE:0,20,SMOOTH_BRICK:0,100)
Block(-8,17,7,quark:limestone:1)
Block(-8,18,4,STEP:0)
Block(-8,18,5,STEP:0)
Block(-8,18,6,DOUBLE_STEP:0)
Block(-8,18,7,quark:iron_plate:1)
Block(-8,18,8,srparasites:parasitestain:1)
Block(-8,19,5,srparasites:parasitetendril:1)
Block(-8,19,6,quark:iron_plate:1)
Block(-8,19,7,quark:iron_plate:1)
RandomBlock(-8,19,8,SMOOTH_BRICK:0,40,SMOOTH_BRICK:1,30,SMOOTH_BRICK:2,30,MOSSY_COBBLESTONE:0,30,COBBLESTONE:0,20,SMOOTH_BRICK:0,100)
Block(-8,20,-5,quark:iron_plate_slab:8)
Block(-8,20,-4,quark:iron_plate_slab:8)
Block(-8,20,-3,quark:iron_plate_slab:8)
Block(-8,20,2,srparasites:parasitethin:0)
Block(-8,20,5,quark:world_stone_pavement:2)
Block(-8,20,6,SMOOTH_STAIRS:3)
Block(-8,21,-7,STEP:0)
Block(-8,21,-6,STEP:0)
Block(-8,21,-5,quark:polished_stone:0)
Block(-8,21,-4,quark:polished_stone:0)
Block(-8,21,-3,quark:polished_stone:0)
Block(-8,21,-2,quark:polished_stone:0)
Block(-8,21,-1,quark:world_stone_pavement:2)
Block(-8,21,0,DOUBLE_STEP:0)
Block(-8,21,1,DOUBLE_STEP:0)
Block(-8,21,2,DOUBLE_STEP:0)
Block(-8,21,3,DOUBLE_STEP:0)
Block(-8,21,4,DOUBLE_STEP:0)
Block(-8,21,5,STEP:0)
Block(-8,22,-7,quark:world_stone_pavement:5)
Block(-8,22,-6,quark:world_stone_pavement:2)
Block(-8,22,-5,STEP:0)
Block(-8,22,-4,STEP:0)
Block(-8,23,-7,STEP:0)
Block(-8,23,-6,STEP:0)
Block(-7,0,-7,quark:world_stone_pavement:2)
Block(-7,0,-6,quark:world_stone_pavement:2)
Block(-7,0,-5,quark:limestone:1)
Block(-7,0,-4,quark:world_stone_pavement:2)
Block(-7,0,-3,quark:world_stone_pavement:2)
Block(-7,0,-2,quark:limestone:1)
Block(-7,0,-1,quark:world_stone_pavement:2)
Block(-7,0,0,quark:limestone:1)
Block(-7,0,1,quark:world_stone_pavement:2)
Block(-7,0,2,quark:world_stone_pavement:5)
Block(-7,0,3,quark:limestone:1)
Block(-7,0,4,quark:world_stone_pavement:5)
Block(-7,0,5,quark:limestone:1)
Block(-7,0,6,quark:limestone:1)
Block(-7,0,7,quark:limestone:1)
Block(-7,0,8,quark:world_stone_pavement:5)
Block(-7,1,-7,quark:world_stone_pavement:2)
Block(-7,1,-6,quark:world_stone_pavement:2)
Block(-7,1,-5,quark:limestone:1)
Block(-7,1,-4,quark:world_stone_pavement:5)
Block(-7,1,-3,quark:limestone:1)
Block(-7,1,-2,quark:world_stone_pavement:2)
Block(-7,1,-1,quark:world_stone_pavement:2)
Block(-7,1,0,quark:world_stone_pavement:5)
Block(-7,1,1,quark:world_stone_pavement:5)
Block(-7,1,2,quark:world_stone_pavement:2)
Block(-7,1,3,quark:limestone:1)
Block(-7,1,4,quark:limestone:1)
Block(-7,1,5,quark:world_stone_pavement:2)
Block(-7,1,6,quark:world_stone_pavement:2)
Block(-7,1,7,quark:world_stone_pavement:5)
Block(-7,1,8,quark:world_stone_pavement:2)
Block(-7,2,-7,quark:limestone:1)
Block(-7,2,-6,quark:world_stone_pavement:2)
Block(-7,2,-5,quark:world_stone_pavement:5)
Block(-7,2,-4,quark:limestone:1)
Block(-7,2,-3,quark:world_stone_pavement:2)
Block(-7,2,-2,quark:world_stone_pavement:2)
Block(-7,2,-1,quark:world_stone_pavement:2)
Block(-7,2,0,quark:limestone:1)
Block(-7,2,1,quark:world_stone_pavement:2)
Block(-7,2,2,quark:world_stone_pavement:2)
Block(-7,2,3,quark:world_stone_pavement:2)
Block(-7,2,4,quark:limestone:1)
Block(-7,2,5,quark:world_stone_pavement:5)
Block(-7,2,6,quark:world_stone_pavement:2)
Block(-7,2,7,quark:world_stone_pavement:2)
Block(-7,2,8,quark:world_stone_pavement:5)
Block(-7,3,-7,quark:world_stone_pavement:2)
Block(-7,3,-6,quark:world_stone_pavement:2)
Block(-7,3,-5,quark:world_stone_pavement:2)
Block(-7,3,-4,quark:world_stone_pavement:5)
Block(-7,3,-3,quark:limestone:1)
Block(-7,3,-2,quark:world_stone_pavement:2)
Block(-7,3,-1,quark:world_stone_pavement:2)
Block(-7,3,0,quark:world_stone_pavement:2)
Block(-7,3,1,quark:limestone:1)
Block(-7,3,2,quark:limestone:1)
Block(-7,3,3,quark:world_stone_pavement:2)
Block(-7,3,4,quark:world_stone_pavement:5)
Block(-7,3,5,quark:world_stone_pavement:2)
Block(-7,3,6,quark:world_stone_pavement:2)
Block(-7,3,7,quark:world_stone_pavement:2)
Block(-7,3,8,quark:limestone:1)
Block(-7,4,-7,quark:limestone:1)
Block(-7,4,-6,quark:world_stone_pavement:2)
Block(-7,4,-5,quark:world_stone_pavement:5)
Block(-7,4,-4,quark:limestone:1)
Block(-7,4,-3,quark:world_stone_pavement:5)
Block(-7,4,-2,quark:iron_plate:1)
Block(-7,4,-1,quark:world_stone_pavement:2)
Block(-7,4,0,quark:world_stone_pavement:5)
Block(-7,4,1,quark:iron_plate:1)
Block(-7,4,2,quark:world_stone_pavement:5)
Block(-7,4,3,quark:world_stone_pavement:5)
Block(-7,4,4,quark:iron_plate:1)
Block(-7,4,5,quark:world_stone_pavement:5)
Block(-7,4,6,quark:world_stone_pavement:2)
Block(-7,4,7,quark:world_stone_pavement:5)
Block(-7,4,8,quark:world_stone_pavement:5)
Block(-7,5,-7,quark:limestone:1)
Block(-7,5,-6,quark:world_stone_pavement:2)
Block(-7,5,-5,quark:world_stone_pavement:2)
Block(-7,5,-4,quark:limestone:1)
Block(-7,5,-3,quark:limestone:1)
Block(-7,5,-2,quark:grate:0)
Block(-7,5,-1,quark:world_stone_pavement:2)
Block(-7,5,0,quark:world_stone_pavement:5)
Block(-7,5,1,quark:grate:0)
Block(-7,5,2,quark:world_stone_pavement:5)
Block(-7,5,3,srparasites:infestedstain:0)
RandomBlock(-7,5,4,rustic:iron_lattice:0,30,rustic:iron_lattice:1,100)
Block(-7,5,5,quark:world_stone_pavement:5)
Block(-7,5,6,quark:world_stone_pavement:2)
Block(-7,5,7,quark:world_stone_pavement:2)
Block(-7,5,8,quark:world_stone_pavement:5)
Block(-7,6,-7,quark:marble_wall:0)
Block(-7,6,-6,quark:world_stone_pavement:1)
Block(-7,6,-5,quark:world_stone_pavement:1)
Block(-7,6,-4,quark:world_stone_pavement:1)
Block(-7,6,-3,quark:marble_wall:0)
RandomBlock(-7,6,-2,CHEST:5,../../../../Chests/Loot/moderncity_useful_loot.nbt,20,CHEST:5,../../../../Chests/Loot/moderncity_rare_loot.nbt,10,CHEST:5,../../../../Chests/Loot/moderncity_epic_loot.nbt,5,CHEST:5,../../../../Chests/RLCraft/Ruins/industrial.nbt,50,CHEST:5,../../../../Chests/RLCraft/Ruins/nuclear.nbt,100)
Block(-7,6,-1,inspirations:redstone_barrel:0)
Block(-7,6,0,inspirations:redstone_barrel:0)
Block(-7,6,1,AIR:0)
Block(-7,6,2,quark:basalt_wall:0)
Block(-7,6,4,quark:iron_plate_slab:8)
Block(-7,6,5,quark:limestone:1)
Block(-7,6,6,quark:limestone:1)
Block(-7,6,7,quark:limestone:1)
Block(-7,6,8,quark:limestone:1)
Block(-7,7,-7,quark:marble_wall:0)
Block(-7,7,-6,quark:marble_wall:0)
Block(-7,7,-5,quark:marble_wall:0)
Block(-7,7,-4,DIODE_BLOCK_OFF:11)
Block(-7,7,-3,quark:marble_wall:0)
Block(-7,7,-2,AIR:0)
Block(-7,7,-1,inspirations:redstone_barrel:0)
Block(-7,7,0,inspirations:redstone_barrel:0)
Block(-7,7,1,AIR:0)
Block(-7,7,2,quark:basalt_wall:0)
Block(-7,7,4,AIR:0)
Block(-7,7,5,quark:polished_stone:0)
Block(-7,7,6,quark:world_stone_pavement:2)
Block(-7,7,7,quark:world_stone_pavement:2)
Block(-7,7,8,quark:world_stone_pavement:2)
Block(-7,8,-7,quark:limestone:1)
Block(-7,8,-6,quark:world_stone_pavement:5)
Block(-7,8,-5,quark:world_stone_pavement:5)
Block(-7,8,-4,quark:world_stone_pavement:2)
Block(-7,8,-3,quark:world_stone_pavement:2)
Block(-7,8,-2,quark:world_stone_pavement:5)
Block(-7,8,-1,quark:limestone:1)
Block(-7,8,0,quark:world_stone_pavement:2)
Block(-7,8,1,quark:limestone:1)
Block(-7,8,2,quark:limestone:1)
Block(-7,8,3,quark:polished_stone:0)
Block(-7,8,4,quark:polished_stone:0)
Block(-7,8,5,quark:polished_stone:0)
Block(-7,8,6,quark:world_stone_pavement:5)
Block(-7,8,7,quark:polished_stone:0)
Block(-7,8,8,quark:polished_stone:0)
Block(-7,9,-7,quark:world_stone_pavement:2)
Block(-7,9,-6,quark:limestone:1)
Block(-7,9,-5,quark:limestone:1)
Block(-7,9,-4,quark:world_stone_pavement:2)
Block(-7,9,-3,quark:limestone:1)
Block(-7,9,-2,quark:world_stone_pavement:2)
Block(-7,9,-1,quark:world_stone_pavement:2)
Block(-7,9,0,quark:world_stone_pavement:2)
Block(-7,9,1,quark:world_stone_pavement:2)
Block(-7,9,2,quark:world_stone_pavement:2)
Block(-7,9,3,quark:polished_stone:0)
Block(-7,9,4,quark:world_stone_pavement:2)
Block(-7,9,5,quark:iron_plate:1)
Block(-7,9,6,quark:world_stone_pavement:5)
Block(-7,9,7,quark:polished_stone:0)
Block(-7,9,8,quark:world_stone_pavement:2)
Block(-7,10,-7,srparasites:parasitestain:1)
Block(-7,10,-6,quark:world_stone_pavement:2)
Block(-7,10,-5,quark:limestone:1)
Block(-7,10,-4,quark:world_stone_pavement:2)
Block(-7,10,-3,quark:world_stone_pavement:2)
Block(-7,10,-2,quark:world_stone_pavement:5)
Block(-7,10,-1,quark:world_stone_pavement:2)
Block(-7,10,0,quark:limestone:1)
Block(-7,10,1,MOB_SPAWNER:0,../../ruins_spawners/brutal_multi.nbt)
Block(-7,10,2,quark:world_stone_pavement:2)
Block(-7,10,3,quark:world_stone_pavement:2)
Block(-7,10,4,quark:polished_stone:0)
Block(-7,10,5,quark:iron_plate:1)
Block(-7,10,6,quark:world_stone_pavement:2)
Block(-7,10,7,quark:polished_stone:0)
Block(-7,10,8,quark:world_stone_pavement:2)
Block(-7,11,-7,srparasites:parasitebush:0)
Block(-7,11,-5,quark:iron_plate:1)
Block(-7,11,-4,quark:iron_plate:1)
Block(-7,11,-3,quark:iron_plate:1)
Block(-7,11,-2,quark:iron_plate:1)
Block(-7,11,-1,quark:iron_plate:1)
Block(-7,11,0,quark:iron_plate:1)
Block(-7,11,1,quark:iron_plate:1)
Block(-7,11,2,quark:iron_plate:1)
Block(-7,11,3,quark:iron_plate:1)
Block(-7,11,4,quark:iron_plate:1)
Block(-7,11,5,quark:iron_plate:1)
Block(-7,11,6,quark:world_stone_pavement:2)
Block(-7,11,7,quark:polished_stone:0)
RandomBlock(-7,11,8,rustic:iron_lattice:0,30,rustic:iron_lattice:1,100)
Block(-7,12,-2,STEP:0)
Block(-7,12,4,quark:iron_plate:1)
Block(-7,12,5,quark:iron_plate:1)
Block(-7,12,6,quark:world_stone_pavement:2)
Block(-7,12,7,quark:polished_stone:0)
RandomBlock(-7,12,8,rustic:iron_lattice:0,30,rustic:iron_lattice:1,100)
Block(-7,13,2,quark:iron_plate:1)
Block(-7,13,4,quark:iron_plate:1)
Block(-7,13,5,quark:iron_plate:1)
Block(-7,13,6,quark:world_stone_pavement:2)
Block(-7,13,7,quark:polished_stone:0)
RandomBlock(-7,13,8,rustic:iron_lattice:0,30,rustic:iron_lattice:1,100)
Block(-7,14,4,quark:iron_plate:1)
Block(-7,14,5,quark:iron_plate:1)
Block(-7,14,6,quark:iron_plate:1)
Block(-7,14,7,quark:iron_plate:1)
Block(-7,14,8,quark:iron_plate:1)
Block(-7,15,2,quark:iron_plate_slab:8)
Block(-7,15,3,quark:grate:0)
Block(-7,15,4,quark:iron_plate:1)
Block(-7,15,5,quark:iron_plate:1)
RandomBlock(-7,15,6,SMOOTH_BRICK:0,40,SMOOTH_BRICK:1,30,SMOOTH_BRICK:2,30,MOSSY_COBBLESTONE:0,30,COBBLESTONE:0,20,SMOOTH_BRICK:0,100)
Block(-7,15,7,quark:world_stone_pavement:2)
RandomBlock(-7,16,2,rustic:iron_lattice:0,30,rustic:iron_lattice:1,100)
Block(-7,16,4,quark:iron_plate:1)
Block(-7,16,5,quark:iron_plate:1)
Block(-7,16,6,quark:iron_plate:1)
Block(-7,16,7,quark:iron_plate:1)
Block(-7,16,8,quark:iron_plate:1)
Block(-7,17,-1,srparasites:parasitecanister:2)
Block(-7,17,1,srparasites:parasitethin:0)
RandomBlock(-7,17,2,rustic:iron_lattice:0,30,rustic:iron_lattice:1,100)
Block(-7,17,4,quark:iron_plate:1)
Block(-7,17,5,quark:iron_plate:1)
RandomBlock(-7,17,6,SMOOTH_BRICK:0,40,SMOOTH_BRICK:1,30,SMOOTH_BRICK:2,30,MOSSY_COBBLESTONE:0,30,COBBLESTONE:0,20,SMOOTH_BRICK:0,100)
Block(-7,17,7,quark:world_stone_pavement:2)
Block(-7,18,-1,srparasites:parasitethin:0)
Block(-7,18,0,srparasites:parasitethin:0)
Block(-7,18,1,srparasites:parasitethin:0)
Block(-7,18,4,STEP:0)
Block(-7,18,5,STEP:0)
RandomBlock(-7,18,6,SMOOTH_BRICK:0,40,SMOOTH_BRICK:1,30,SMOOTH_BRICK:2,30,MOSSY_COBBLESTONE:0,30,COBBLESTONE:0,20,SMOOTH_BRICK:0,100)
Block(-7,18,7,quark:iron_plate:1)
Block(-7,18,8,srparasites:parasitestain:1)
Block(-7,19,-4,srparasites:parasitecanister:0)
Block(-7,19,-3,srparasites:parasitethin:0)
Block(-7,19,-2,srparasites:parasitethin:0)
Block(-7,19,-1,srparasites:parasitethin:0)
Block(-7,19,1,srparasites:parasitethin:0)
Block(-7,19,2,srparasites:parasitethin:0)
Block(-7,19,5,srparasites:parasitetendril:1)
Block(-7,19,6,quark:iron_plate:1)
Block(-7,19,7,quark:iron_plate:1)
Block(-7,19,8,quark:iron_plate:1)
Block(-7,20,-7,srparasites:parasitethin:0)
Block(-7,20,-6,srparasites:parasitethin:0)
Block(-7,20,-5,srparasites:parasitethin:0)
Block(-7,20,-4,srparasites:parasitethin:0)
Block(-7,20,-3,srparasites:parasitethin:0)
Block(-7,20,2,srparasites:parasitethin:0)
Block(-7,20,5,quark:polished_stone:0)
Block(-7,20,6,SMOOTH_STAIRS:3)
Block(-7,20,7,quark:stone_diorite_bricks_wall:0)
Block(-7,20,8,quark:stone_diorite_bricks_wall:0)
Block(-7,21,-7,DOUBLE_STEP:0)
Block(-7,21,-6,DOUBLE_STEP:0)
Block(-7,21,-5,STEP:0)
Block(-7,21,-4,CONCRETE:15)
Block(-7,21,-3,quark:world_stone_pavement:2)
Block(-7,21,-2,quark:polished_stone:0)
Block(-7,21,-1,quark:polished_stone:0)
Block(-7,21,0,DOUBLE_STEP:0)
Block(-7,21,1,STEP:0)
Block(-7,21,2,STEP:0)
Block(-7,21,3,STEP:0)
Block(-7,21,4,STEP:0)
Block(-7,21,5,STEP:0)
Block(-7,22,-7,quark:world_stone_pavement:2)
Block(-7,22,-6,quark:world_stone_pavement:2)
Block(-7,22,-5,STEP:0)
Block(-7,22,-4,STEP:0)
Block(-7,23,-7,DOUBLE_STEP:0)
Block(-7,23,-6,DOUBLE_STEP:0)
Block(-7,24,-7,quark:basalt_wall:0)
Block(-7,24,-6,quark:basalt_wall:0)
Block(-6,0,-7,quark:world_stone_pavement:2)
Block(-6,0,-6,quark:world_stone_pavement:2)
Block(-6,0,-5,quark:world_stone_pavement:5)
Block(-6,0,-4,quark:limestone:1)
Block(-6,0,-3,quark:limestone:1)
Block(-6,0,-2,quark:world_stone_pavement:2)
Block(-6,0,-1,quark:world_stone_pavement:2)
Block(-6,0,0,quark:limestone:1)
Block(-6,0,1,quark:limestone:1)
Block(-6,0,2,quark:world_stone_pavement:2)
Block(-6,0,3,quark:limestone:1)
Block(-6,0,4,quark:world_stone_pavement:2)
Block(-6,0,5,quark:world_stone_pavement:2)
Block(-6,0,6,quark:limestone:1)
Block(-6,0,7,quark:world_stone_pavement:2)
Block(-6,0,8,quark:world_stone_pavement:5)
Block(-6,1,-7,quark:world_stone_pavement:2)
Block(-6,1,-6,quark:world_stone_pavement:5)
Block(-6,1,-5,quark:world_stone_pavement:5)
Block(-6,1,-4,quark:world_stone_pavement:2)
Block(-6,1,-3,quark:world_stone_pavement:5)
Block(-6,1,-2,quark:world_stone_pavement:2)
Block(-6,1,-1,quark:world_stone_pavement:2)
Block(-6,1,0,quark:world_stone_pavement:2)
Block(-6,1,1,quark:world_stone_pavement:2)
Block(-6,1,2,quark:world_stone_pavement:5)
Block(-6,1,3,quark:world_stone_pavement:5)
Block(-6,1,4,quark:world_stone_pavement:2)
Block(-6,1,5,quark:world_stone_pavement:2)
Block(-6,1,6,quark:world_stone_pavement:2)
Block(-6,1,7,quark:world_stone_pavement:2)
Block(-6,1,8,quark:world_stone_pavement:5)
Block(-6,2,-7,quark:world_stone_pavement:2)
Block(-6,2,-6,quark:world_stone_pavement:2)
Block(-6,2,-5,quark:limestone:1)
Block(-6,2,-4,quark:limestone:1)
Block(-6,2,-3,quark:world_stone_pavement:5)
Block(-6,2,-2,quark:world_stone_pavement:2)
Block(-6,2,-1,quark:world_stone_pavement:2)
Block(-6,2,0,quark:limestone:1)
Block(-6,2,1,quark:limestone:1)
Block(-6,2,2,quark:limestone:1)
Block(-6,2,3,quark:world_stone_pavement:5)
Block(-6,2,4,quark:limestone:1)
Block(-6,2,5,quark:world_stone_pavement:2)
Block(-6,2,6,quark:world_stone_pavement:5)
Block(-6,2,7,quark:limestone:1)
Block(-6,2,8,quark:limestone:1)
Block(-6,3,-7,quark:world_stone_pavement:2)
Block(-6,3,-6,quark:world_stone_pavement:2)
Block(-6,3,-5,quark:world_stone_pavement:2)
Block(-6,3,-4,quark:limestone:1)
Block(-6,3,-3,quark:world_stone_pavement:2)
Block(-6,3,-2,quark:world_stone_pavement:2)
Block(-6,3,-1,quark:world_stone_pavement:2)
Block(-6,3,0,quark:limestone:1)
Block(-6,3,1,quark:world_stone_pavement:5)
Block(-6,3,2,quark:world_stone_pavement:5)
Block(-6,3,3,quark:limestone:1)
Block(-6,3,4,quark:world_stone_pavement:2)
Block(-6,3,5,quark:world_stone_pavement:2)
Block(-6,3,6,quark:limestone:1)
Block(-6,3,7,quark:world_stone_pavement:2)
Block(-6,3,8,quark:world_stone_pavement:2)
Block(-6,4,-7,quark:world_stone_pavement:2)
Block(-6,4,-6,quark:world_stone_pavement:5)
Block(-6,4,-5,quark:world_stone_pavement:5)
Block(-6,4,-4,quark:world_stone_pavement:5)
Block(-6,4,-3,quark:world_stone_pavement:2)
Block(-6,4,-2,quark:iron_plate:1)
Block(-6,4,-1,quark:world_stone_pavement:2)
Block(-6,4,0,quark:world_stone_pavement:5)
Block(-6,4,1,quark:iron_plate:1)
Block(-6,4,2,quark:world_stone_pavement:5)
Block(-6,4,3,quark:world_stone_pavement:2)
Block(-6,4,4,quark:iron_plate:1)
Block(-6,4,5,quark:world_stone_pavement:2)
Block(-6,4,6,quark:world_stone_pavement:5)
Block(-6,4,7,quark:world_stone_pavement:2)
Block(-6,4,8,quark:world_stone_pavement:5)
Block(-6,5,-7,quark:world_stone_pavement:2)
Block(-6,5,-6,quark:limestone:1)
Block(-6,5,-5,quark:world_stone_pavement:2)
Block(-6,5,-4,quark:world_stone_pavement:5)
Block(-6,5,-3,quark:world_stone_pavement:5)
Block(-6,5,-2,quark:grate:0)
Block(-6,5,-1,quark:world_stone_pavement:2)
Block(-6,5,0,srparasites:infestedstain:0)
Block(-6,5,1,quark:grate:0)
Block(-6,5,2,quark:limestone:1)
Block(-6,5,3,srparasites:infestedstain:0)
RandomBlock(-6,5,4,rustic:iron_lattice:0,30,rustic:iron_lattice:1,100)
Block(-6,5,5,quark:world_stone_pavement:2)
Block(-6,5,6,quark:limestone:1)
Block(-6,5,7,quark:world_stone_pavement:5)
Block(-6,5,8,quark:limestone:1)
Block(-6,6,-7,quark:marble_wall:0)
Block(-6,6,-6,quark:world_stone_pavement:1)
Block(-6,6,-5,quark:world_stone_pavement:1)
Block(-6,6,-4,quark:world_stone_pavement:1)
Block(-6,6,-3,quark:marble_wall:0)
Block(-6,6,-2,AIR:0)
Block(-6,6,-1,quark:basalt_wall:0)
Block(-6,6,0,AIR:0)
Block(-6,6,1,AIR:0)
RandomBlock(-6,6,2,rustic:iron_lattice:0,30,rustic:iron_lattice:1,100)
Block(-6,6,3,AIR:0)
Block(-6,6,4,quark:iron_plate_slab:8)
Block(-6,6,5,quark:world_stone_pavement:2)
Block(-6,6,6,quark:world_stone_pavement:5)
Block(-6,6,7,quark:limestone:1)
Block(-6,6,8,quark:world_stone_pavement:2)
Block(-6,7,-7,quark:marble_wall:0)
Block(-6,7,-6,quark:marble_wall:0)
Block(-6,7,-5,quark:marble_wall:0)
Block(-6,7,-4,DIODE_BLOCK_ON:11)
Block(-6,7,-3,quark:marble_wall:0)
Block(-6,7,-2,AIR:0)
Block(-6,7,-1,quark:basalt_wall:0)
Block(-6,7,0,AIR:0)
RandomBlock(-6,7,2,rustic:iron_lattice:0,30,rustic:iron_lattice:1,100)
Block(-6,7,3,AIR:0)
Block(-6,7,4,quark:iron_plate_slab_double:0)
Block(-6,7,5,quark:polished_stone:0)
Block(-6,7,6,quark:limestone:1)
Block(-6,7,7,quark:limestone:1)
Block(-6,7,8,quark:world_stone_pavement:5)
Block(-6,8,-7,quark:world_stone_pavement:5)
Block(-6,8,-6,quark:limestone:1)
Block(-6,8,-5,quark:world_stone_pavement:5)
Block(-6,8,-4,quark:world_stone_pavement:5)
Block(-6,8,-3,quark:world_stone_pavement:5)
Block(-6,8,-2,quark:world_stone_pavement:2)
Block(-6,8,-1,quark:limestone:1)
Block(-6,8,0,quark:world_stone_pavement:5)
Block(-6,8,1,srparasites:parasitestain:1)
Block(-6,8,2,quark:world_stone_pavement:2)
Block(-6,8,3,quark:polished_stone:0)
Block(-6,8,4,quark:world_stone_pavement:2)
Block(-6,8,5,quark:world_stone_pavement:2)
Block(-6,8,6,quark:limestone:1)
Block(-6,8,7,quark:world_stone_pavement:2)
Block(-6,8,8,quark:world_stone_pavement:2)
Block(-6,9,-7,quark:limestone:1)
Block(-6,9,-6,quark:limestone:1)
Block(-6,9,-5,quark:world_stone_pavement:5)
Block(-6,9,-4,quark:limestone:1)
Block(-6,9,-3,quark:world_stone_pavement:2)
Block(-6,9,-2,quark:world_stone_pavement:2)
Block(-6,9,-1,quark:world_stone_pavement:5)
Block(-6,9,0,quark:world_stone_pavement:5)
Block(-6,9,1,quark:limestone:1)
Block(-6,9,2,quark:world_stone_pavement:2)
Block(-6,9,3,quark:world_stone_pavement:2)
Block(-6,9,4,quark:world_stone_pavement:2)
Block(-6,9,5,quark:world_stone_pavement:2)
Block(-6,9,6,quark:world_stone_pavement:2)
Block(-6,9,7,quark:world_stone_pavement:2)
Block(-6,9,8,quark:polished_stone:0)
Block(-6,10,-7,srparasites:infestedstain:0)
Block(-6,10,-6,quark:world_stone_pavement:2)
Block(-6,10,-5,quark:world_stone_pavement:5)
Block(-6,10,-4,quark:world_stone_pavement:2)
Block(-6,10,-3,quark:world_stone_pavement:5)
Block(-6,10,-2,quark:world_stone_pavement:2)
Block(-6,10,-1,quark:world_stone_pavement:2)
Block(-6,10,0,quark:limestone:1)
Block(-6,10,1,srparasites:infestedstain:0)
Block(-6,10,2,srparasites:infestedstain:0)
Block(-6,10,3,quark:polished_stone:0)
Block(-6,10,4,quark:polished_stone:0)
Block(-6,10,5,quark:world_stone_pavement:2)
Block(-6,10,6,quark:world_stone_pavement:2)
Block(-6,10,7,quark:polished_stone:0)
Block(-6,10,8,quark:polished_stone:0)
Block(-6,11,-5,quark:iron_plate:1)
Block(-6,11,-2,quark:iron_plate:1)
Block(-6,11,6,quark:world_stone_pavement:2)
Block(-6,11,7,quark:iron_plate:1)
Block(-6,12,6,quark:world_stone_pavement:2)
Block(-6,12,7,quark:iron_plate:1)
Block(-6,13,2,quark:iron_plate:1)
Block(-6,13,6,DOUBLE_STEP:0)
Block(-6,13,7,quark:iron_plate:1)
Block(-6,13,8,quark:grate:0)
Block(-6,14,6,DOUBLE_STEP:0)
Block(-6,14,7,quark:iron_plate:1)
Block(-6,15,2,quark:iron_plate_slab:8)
Block(-6,15,3,quark:grate:0)
Block(-6,15,4,quark:grate:0)
Block(-6,15,5,quark:grate:0)
Block(-6,15,6,DOUBLE_STEP:0)
Block(-6,15,7,quark:iron_plate:1)
RandomBlock(-6,16,2,rustic:iron_lattice:0,30,rustic:iron_lattice:1,100)
Block(-6,16,5,srparasites:parasitetendril:1)
Block(-6,16,6,DOUBLE_STEP:0)
Block(-6,16,7,quark:iron_plate:1)
RandomBlock(-6,17,2,rustic:iron_lattice:0,30,rustic:iron_lattice:1,100)
Block(-6,17,5,srparasites:parasitetendril:1)
Block(-6,17,6,DOUBLE_STEP:0)
Block(-6,17,7,quark:iron_plate:1)
Block(-6,18,5,srparasites:parasitetendril:1)
Block(-6,18,6,DOUBLE_STEP:0)
Block(-6,18,7,quark:iron_plate:1)
Block(-6,18,8,quark:polished_stone:0)
Block(-6,19,-7,srparasites:parasitecanister:0)
Block(-6,19,5,srparasites:parasitetendril:1)
Block(-6,19,6,quark:iron_plate:1)
Block(-6,19,7,SMOOTH_STAIRS:1)
Block(-6,19,8,SMOOTH_STAIRS:1)
Block(-6,20,-7,srparasites:parasitethin:0)
Block(-6,20,-5,quark:iron_plate_slab:8)
Block(-6,20,-4,quark:iron_plate_slab:8)
Block(-6,20,-3,quark:iron_plate_slab:8)
Block(-6,20,5,quark:polished_stone:0)
Block(-6,20,6,SMOOTH_STAIRS:3)
Block(-6,21,-7,STEP:0)
Block(-6,21,-6,STEP:0)
Block(-6,21,-5,quark:world_stone_pavement:2)
Block(-6,21,-4,quark:polished_stone:0)
Block(-6,21,-3,quark:polished_stone:0)
Block(-6,21,-2,quark:world_stone_pavement:2)
Block(-6,21,-1,quark:polished_stone:0)
Block(-6,21,0,DOUBLE_STEP:0)
Block(-6,21,1,STEP:0)
Block(-6,21,2,STEP:0)
Block(-6,21,3,STEP:0)
Block(-6,21,4,STEP:0)
Block(-6,21,5,STEP:0)
Block(-6,22,-7,quark:world_stone_pavement:2)
Block(-6,22,-6,quark:world_stone_pavement:2)
Block(-6,22,-5,STEP:0)
Block(-6,23,-7,STEP:0)
Block(-6,23,-6,STEP:0)
Block(-5,0,-7,quark:world_stone_pavement:2)
Block(-5,0,-6,quark:world_stone_pavement:2)
Block(-5,0,-5,quark:world_stone_pavement:5)
Block(-5,0,-4,quark:world_stone_pavement:2)
Block(-5,0,-3,quark:limestone:1)
Block(-5,0,-2,quark:limestone:1)
Block(-5,0,-1,quark:world_stone_pavement:5)
Block(-5,0,0,quark:world_stone_pavement:2)
Block(-5,0,1,quark:world_stone_pavement:2)
Block(-5,0,2,quark:world_stone_pavement:2)
Block(-5,0,3,quark:world_stone_pavement:5)
Block(-5,0,4,quark:world_stone_pavement:2)
Block(-5,0,5,quark:world_stone_pavement:2)
Block(-5,0,6,quark:world_stone_pavement:2)
Block(-5,0,7,quark:world_stone_pavement:5)
Block(-5,0,8,quark:world_stone_pavement:2)
Block(-5,1,-7,quark:limestone:1)
Block(-5,1,-6,quark:limestone:1)
Block(-5,1,-5,quark:limestone:1)
Block(-5,1,-4,quark:world_stone_pavement:2)
Block(-5,1,-3,quark:world_stone_pavement:2)
Block(-5,1,-2,quark:world_stone_pavement:2)
Block(-5,1,-1,quark:world_stone_pavement:5)
Block(-5,1,0,quark:world_stone_pavement:5)
Block(-5,1,1,quark:world_stone_pavement:2)
Block(-5,1,2,quark:world_stone_pavement:2)
Block(-5,1,3,quark:world_stone_pavement:2)
Block(-5,1,4,quark:world_stone_pavement:2)
Block(-5,1,5,quark:world_stone_pavement:2)
Block(-5,1,6,quark:world_stone_pavement:2)
Block(-5,1,7,quark:world_stone_pavement:5)
Block(-5,1,8,quark:limestone:1)
Block(-5,2,-7,quark:world_stone_pavement:2)
Block(-5,2,-6,quark:world_stone_pavement:2)
Block(-5,2,-5,quark:world_stone_pavement:2)
Block(-5,2,-4,quark:world_stone_pavement:2)
Block(-5,2,-3,quark:world_stone_pavement:5)
Block(-5,2,-2,quark:world_stone_pavement:2)
Block(-5,2,-1,quark:world_stone_pavement:5)
Block(-5,2,0,quark:world_stone_pavement:2)
Block(-5,2,1,quark:world_stone_pavement:2)
Block(-5,2,2,quark:world_stone_pavement:2)
Block(-5,2,3,quark:world_stone_pavement:5)
Block(-5,2,4,quark:world_stone_pavement:2)
Block(-5,2,5,quark:world_stone_pavement:2)
Block(-5,2,6,quark:world_stone_pavement:2)
Block(-5,2,7,quark:limestone:1)
Block(-5,2,8,quark:world_stone_pavement:2)
Block(-5,3,-7,quark:world_stone_pavement:2)
Block(-5,3,-6,quark:world_stone_pavement:5)
Block(-5,3,-5,quark:limestone:1)
Block(-5,3,-4,quark:world_stone_pavement:2)
Block(-5,3,-3,quark:world_stone_pavement:5)
Block(-5,3,-2,quark:world_stone_pavement:5)
Block(-5,3,-1,quark:limestone:1)
Block(-5,3,0,quark:limestone:1)
Block(-5,3,1,quark:limestone:1)
Block(-5,3,2,quark:world_stone_pavement:2)
Block(-5,3,3,quark:world_stone_pavement:5)
Block(-5,3,4,quark:limestone:1)
Block(-5,3,5,quark:world_stone_pavement:2)
Block(-5,3,6,quark:world_stone_pavement:2)
Block(-5,3,7,quark:world_stone_pavement:5)
Block(-5,3,8,quark:limestone:1)
Block(-5,4,-7,quark:world_stone_pavement:2)
Block(-5,4,-6,quark:limestone:1)
Block(-5,4,-5,quark:world_stone_pavement:2)
Block(-5,4,-4,quark:world_stone_pavement:2)
Block(-5,4,-3,quark:world_stone_pavement:5)
Block(-5,4,-2,quark:iron_plate:1)
Block(-5,4,-1,quark:world_stone_pavement:5)
Block(-5,4,0,quark:world_stone_pavement:2)
Block(-5,4,1,quark:iron_plate:1)
Block(-5,4,2,quark:world_stone_pavement:2)
Block(-5,4,3,quark:limestone:1)
Block(-5,4,4,quark:basalt_wall:0)
Block(-5,4,5,quark:world_stone_pavement:2)
Block(-5,4,6,quark:world_stone_pavement:2)
Block(-5,4,7,quark:world_stone_pavement:2)
Block(-5,4,8,quark:world_stone_pavement:2)
Block(-5,5,-7,quark:limestone:1)
Block(-5,5,-6,quark:limestone:1)
Block(-5,5,-5,quark:world_stone_pavement:2)
Block(-5,5,-4,quark:world_stone_pavement:2)
Block(-5,5,-3,quark:world_stone_pavement:5)
Block(-5,5,-2,quark:grate:0)
Block(-5,5,-1,quark:world_stone_pavement:5)
Block(-5,5,0,srparasites:infestedstain:0)
Block(-5,5,1,quark:grate:0)
Block(-5,5,2,quark:world_stone_pavement:2)
Block(-5,5,3,quark:world_stone_pavement:2)
Block(-5,5,4,quark:basalt_wall:0)
Block(-5,5,5,quark:world_stone_pavement:2)
Block(-5,5,6,quark:world_stone_pavement:2)
Block(-5,5,7,quark:world_stone_pavement:2)
Block(-5,5,8,quark:world_stone_pavement:2)
Block(-5,6,-7,REDSTONE_WIRE:0)
Block(-5,6,-6,quark:world_stone_pavement:1)
Block(-5,6,-5,quark:world_stone_pavement:1)
Block(-5,6,-4,quark:world_stone_pavement:1)
Block(-5,6,-3,quark:marble_wall:0)
Block(-5,6,-2,AIR:0)
RandomBlock(-5,6,-1,rustic:iron_lattice:0,30,rustic:iron_lattice:1,100)
Block(-5,6,1,AIR:0)
Block(-5,6,2,AIR:0)
Block(-5,6,3,AIR:0)
Block(-5,6,4,quark:basalt_wall:0)
Block(-5,6,5,quark:world_stone_pavement:2)
Block(-5,6,6,quark:world_stone_pavement:2)
Block(-5,6,7,quark:limestone:1)
Block(-5,6,8,quark:limestone:1)
Block(-5,7,-7,STEP:8)
Block(-5,7,-6,REDSTONE_WIRE:0)
Block(-5,7,-5,REDSTONE_WIRE:0)
Block(-5,7,-4,REDSTONE_WIRE:0)
Block(-5,7,-3,quark:marble_wall:0)
Block(-5,7,-2,AIR:0)
RandomBlock(-5,7,-1,rustic:iron_lattice:0,30,rustic:iron_lattice:1,100)
Block(-5,7,0,AIR:0)
Block(-5,7,3,AIR:0)
Block(-5,7,4,quark:basalt_wall:0)
Block(-5,7,5,quark:polished_stone:0)
Block(-5,7,6,quark:polished_stone:0)
Block(-5,7,7,quark:limestone:1)
Block(-5,7,8,quark:limestone:1)
Block(-5,8,-7,quark:world_stone_pavement:5)
Block(-5,8,-6,quark:world_stone_pavement:5)
Block(-5,8,-5,quark:world_stone_pavement:5)
Block(-5,8,-4,quark:limestone:1)
Block(-5,8,-3,quark:world_stone_pavement:2)
Block(-5,8,-2,quark:world_stone_pavement:2)
Block(-5,8,-1,quark:world_stone_pavement:5)
Block(-5,8,0,quark:limestone:1)
Block(-5,8,1,srparasites:parasitestain:1)
Block(-5,8,2,srparasites:parasitestain:1)
Block(-5,8,3,quark:world_stone_pavement:2)
Block(-5,8,4,quark:world_stone_pavement:2)
Block(-5,8,5,quark:world_stone_pavement:2)
Block(-5,8,6,quark:polished_stone:0)
Block(-5,8,7,quark:polished_stone:0)
Block(-5,8,8,quark:world_stone_pavement:2)
Block(-5,9,-7,quark:limestone:1)
Block(-5,9,-6,quark:world_stone_pavement:5)
Block(-5,9,-5,quark:limestone:1)
Block(-5,9,-4,quark:world_stone_pavement:5)
Block(-5,9,-3,quark:limestone:1)
Block(-5,9,-2,quark:world_stone_pavement:2)
Block(-5,9,-1,quark:limestone:1)
Block(-5,9,0,quark:limestone:1)
Block(-5,9,1,quark:world_stone_pavement:5)
Block(-5,9,2,quark:world_stone_pavement:2)
Block(-5,9,3,quark:polished_stone:0)
Block(-5,9,4,quark:world_stone_pavement:2)
Block(-5,9,5,quark:world_stone_pavement:2)
Block(-5,9,6,quark:polished_stone:0)
Block(-5,9,7,quark:world_stone_pavement:2)
Block(-5,9,8,quark:polished_stone:0)
Block(-5,10,-7,srparasites:infestedstain:0)
Block(-5,10,-6,quark:limestone:1)
Block(-5,10,-5,quark:world_stone_pavement:5)
Block(-5,10,-4,quark:limestone:1)
Block(-5,10,-3,quark:world_stone_pavement:5)
Block(-5,10,-2,quark:world_stone_pavement:5)
Block(-5,10,-1,quark:limestone:1)
Block(-5,10,0,srparasites:parasitestain:1)
Block(-5,10,1,quark:world_stone_pavement:2)
Block(-5,10,2,quark:polished_stone:0)
Block(-5,10,3,srparasites:infestedstain:0)
Block(-5,10,4,quark:polished_stone:0)
Block(-5,10,5,quark:polished_stone:0)
Block(-5,10,6,quark:polished_stone:0)
Block(-5,10,7,quark:polished_stone:0)
Block(-5,10,8,srparasites:parasitestain:1)
Block(-5,11,-5,quark:iron_plate:1)
Block(-5,11,-3,srparasites:parasitetendril:8)
Block(-5,11,-2,quark:iron_plate:1)
Block(-5,11,0,srparasites:infestedbush:3)
Block(-5,11,2,quark:quartz_wall:0)
Block(-5,11,6,quark:world_stone_pavement:2)
Block(-5,11,7,quark:polished_stone:0)
Block(-5,11,8,srparasites:gore:1)
Block(-5,12,-5,srparasites:parasitetendril:8)
Block(-5,12,-3,srparasites:parasitetendril:8)
Block(-5,12,-2,srparasites:parasitetendril:8)
Block(-5,12,0,srparasites:infestedbush:3)
Block(-5,12,2,quark:quartz_wall:0)
Block(-5,12,6,quark:polished_stone:0)
Block(-5,12,7,quark:polished_stone:0)
Block(-5,13,-5,srparasites:parasitetendril:8)
Block(-5,13,-3,srparasites:parasitetendril:8)
Block(-5,13,-2,srparasites:parasitetendril:8)
Block(-5,13,0,srparasites:infestedbush:3)
Block(-5,13,2,quark:iron_plate:1)
RandomBlock(-5,13,6,SMOOTH_BRICK:0,40,SMOOTH_BRICK:1,30,SMOOTH_BRICK:2,30,MOSSY_COBBLESTONE:0,30,COBBLESTONE:0,20,SMOOTH_BRICK:0,100)
Block(-5,13,7,quark:world_stone_pavement:2)
Block(-5,13,8,quark:grate:0)
Block(-5,14,-5,srparasites:parasitetendril:8)
Block(-5,14,-3,srparasites:parasitetendril:8)
Block(-5,14,-2,srparasites:parasitetendril:8)
Block(-5,14,0,srparasites:infestedbush:3)
RandomBlock(-5,14,6,SMOOTH_BRICK:0,40,SMOOTH_BRICK:1,30,SMOOTH_BRICK:2,30,MOSSY_COBBLESTONE:0,30,COBBLESTONE:0,20,SMOOTH_BRICK:0,100)
Block(-5,14,7,quark:world_stone_pavement:2)
Block(-5,15,-5,srparasites:parasitetendril:8)
Block(-5,15,-3,srparasites:parasitetendril:8)
Block(-5,15,-2,srparasites:parasitetendril:8)
Block(-5,15,0,srparasites:infestedbush:3)
Block(-5,15,2,quark:iron_plate_slab:8)
Block(-5,15,3,quark:grate:0)
Block(-5,15,4,quark:grate:0)
Block(-5,15,5,quark:grate:0)
RandomBlock(-5,15,6,SMOOTH_BRICK:0,40,SMOOTH_BRICK:1,30,SMOOTH_BRICK:2,30,MOSSY_COBBLESTONE:0,30,COBBLESTONE:0,20,SMOOTH_BRICK:0,100)
Block(-5,15,7,quark:world_stone_pavement:2)
Block(-5,16,-5,srparasites:parasitetendril:8)
Block(-5,16,-2,srparasites:parasitetendril:8)
Block(-5,16,0,srparasites:infestedbush:3)
RandomBlock(-5,16,2,rustic:iron_lattice:0,30,rustic:iron_lattice:1,100)
Block(-5,16,5,srparasites:parasitetendril:1)
RandomBlock(-5,16,6,SMOOTH_BRICK:0,40,SMOOTH_BRICK:1,30,SMOOTH_BRICK:2,30,MOSSY_COBBLESTONE:0,30,COBBLESTONE:0,20,SMOOTH_BRICK:0,100)
Block(-5,16,7,quark:limestone:1)
Block(-5,17,-5,srparasites:parasitetendril:8)
Block(-5,17,-2,srparasites:parasitetendril:8)
Block(-5,17,0,srparasites:infestedbush:3)
RandomBlock(-5,17,2,rustic:iron_lattice:0,30,rustic:iron_lattice:1,100)
Block(-5,17,5,srparasites:parasitetendril:1)
RandomBlock(-5,17,6,SMOOTH_BRICK:0,40,SMOOTH_BRICK:1,30,SMOOTH_BRICK:2,30,MOSSY_COBBLESTONE:0,30,COBBLESTONE:0,20,SMOOTH_BRICK:0,100)
Block(-5,17,7,quark:iron_plate:1)
Block(-5,17,8,SMOOTH_STAIRS:4)
Block(-5,18,-5,srparasites:parasitetendril:8)
Block(-5,18,-2,srparasites:parasitetendril:8)
Block(-5,18,0,srparasites:infestedbush:3)
Block(-5,18,5,srparasites:parasitetendril:1)
RandomBlock(-5,18,6,SMOOTH_BRICK:0,40,SMOOTH_BRICK:1,30,SMOOTH_BRICK:2,30,MOSSY_COBBLESTONE:0,30,COBBLESTONE:0,20,SMOOTH_BRICK:0,100)
Block(-5,18,7,quark:iron_plate:1)
Block(-5,18,8,quark:polished_stone:0)
Block(-5,19,-5,srparasites:parasitetendril:8)
Block(-5,19,-2,srparasites:parasitetendril:8)
Block(-5,19,5,srparasites:parasitetendril:1)
Block(-5,19,6,quark:iron_plate:1)
Block(-5,20,-7,srparasites:parasitethin:0)
Block(-5,20,-5,srparasites:parasitetendril:8)
Block(-5,20,-2,srparasites:parasitetendril:8)
Block(-5,20,5,quark:polished_stone:0)
Block(-5,20,6,SMOOTH_STAIRS:3)
Block(-5,21,-7,STEP:0)
Block(-5,21,-6,STEP:0)
Block(-5,21,-5,quark:world_stone_pavement:5)
Block(-5,21,-4,quark:polished_stone:0)
Block(-5,21,-3,quark:polished_stone:0)
Block(-5,21,-2,quark:polished_stone:0)
Block(-5,21,-1,quark:polished_stone:0)
Block(-5,21,0,DOUBLE_STEP:0)
Block(-5,21,1,STEP:0)
Block(-5,21,2,STEP:0)
Block(-5,21,3,STEP:0)
Block(-5,21,4,STEP:0)
Block(-5,21,5,STEP:0)
Block(-5,22,-7,quark:polished_stone:0)
Block(-5,22,-6,quark:polished_stone:0)
Block(-5,22,-5,STEP:0)
Block(-5,23,-7,STEP:0)
Block(-5,23,-6,STEP:0)
Block(-4,0,-7,quark:world_stone_pavement:5)
Block(-4,0,-6,quark:limestone:1)
Block(-4,0,-5,quark:world_stone_pavement:5)
Block(-4,0,-4,quark:world_stone_pavement:5)
Block(-4,0,-3,quark:world_stone_pavement:5)
Block(-4,0,-2,quark:world_stone_pavement:2)
Block(-4,0,-1,quark:world_stone_pavement:2)
Block(-4,0,0,quark:world_stone_pavement:2)
Block(-4,0,1,quark:limestone:1)
Block(-4,0,2,quark:world_stone_pavement:2)
Block(-4,0,3,quark:limestone:1)
Block(-4,0,4,quark:limestone:1)
Block(-4,0,5,quark:limestone:1)
Block(-4,0,6,quark:world_stone_pavement:2)
Block(-4,0,7,quark:world_stone_pavement:5)
Block(-4,0,8,quark:world_stone_pavement:2)
Block(-4,1,-7,quark:world_stone_pavement:5)
Block(-4,1,-6,quark:world_stone_pavement:5)
Block(-4,1,-5,quark:world_stone_pavement:5)
Block(-4,1,-4,quark:world_stone_pavement:2)
Block(-4,1,-3,quark:world_stone_pavement:2)
Block(-4,1,-2,quark:limestone:1)
Block(-4,1,-1,quark:world_stone_pavement:2)
Block(-4,1,0,quark:world_stone_pavement:2)
Block(-4,1,1,quark:world_stone_pavement:2)
Block(-4,1,2,quark:world_stone_pavement:2)
Block(-4,1,3,quark:world_stone_pavement:5)
Block(-4,1,4,quark:limestone:1)
Block(-4,1,5,quark:world_stone_pavement:2)
Block(-4,1,6,quark:world_stone_pavement:5)
Block(-4,1,7,quark:world_stone_pavement:2)
Block(-4,1,8,quark:limestone:1)
Block(-4,2,-7,quark:limestone:1)
Block(-4,2,-6,quark:world_stone_pavement:5)
Block(-4,2,-5,quark:limestone:1)
Block(-4,2,-4,quark:world_stone_pavement:5)
Block(-4,2,-3,quark:world_stone_pavement:5)
Block(-4,2,-2,quark:limestone:1)
Block(-4,2,-1,quark:world_stone_pavement:2)
Block(-4,2,0,quark:world_stone_pavement:2)
Block(-4,2,1,quark:world_stone_pavement:5)
Block(-4,2,2,quark:world_stone_pavement:2)
Block(-4,2,3,quark:world_stone_pavement:5)
Block(-4,2,4,quark:world_stone_pavement:2)
Block(-4,2,5,quark:world_stone_pavement:2)
Block(-4,2,6,quark:limestone:1)
Block(-4,2,7,quark:limestone:1)
Block(-4,2,8,quark:limestone:1)
Block(-4,3,-7,quark:world_stone_pavement:2)
Block(-4,3,-6,quark:world_stone_pavement:2)
Block(-4,3,-5,quark:world_stone_pavement:5)
Block(-4,3,-4,quark:world_stone_pavement:5)
Block(-4,3,-3,quark:limestone:1)
Block(-4,3,-2,quark:world_stone_pavement:5)
Block(-4,3,-1,quark:world_stone_pavement:2)
Block(-4,3,0,quark:world_stone_pavement:2)
Block(-4,3,1,quark:world_stone_pavement:5)
Block(-4,3,2,quark:world_stone_pavement:2)
Block(-4,3,3,quark:world_stone_pavement:5)
Block(-4,3,4,quark:limestone:1)
Block(-4,3,5,quark:world_stone_pavement:2)
Block(-4,3,6,quark:world_stone_pavement:2)
Block(-4,3,7,quark:world_stone_pavement:5)
Block(-4,3,8,quark:world_stone_pavement:2)
Block(-4,4,-7,quark:limestone:1)
Block(-4,4,-6,quark:world_stone_pavement:5)
Block(-4,4,-5,quark:limestone:1)
Block(-4,4,-4,quark:world_stone_pavement:5)
Block(-4,4,-3,quark:limestone:1)
Block(-4,4,-2,quark:iron_plate:1)
Block(-4,4,-1,quark:world_stone_pavement:2)
Block(-4,4,0,quark:world_stone_pavement:2)
Block(-4,4,1,quark:iron_plate:1)
Block(-4,4,2,quark:world_stone_pavement:2)
Block(-4,4,3,quark:world_stone_pavement:2)
Block(-4,4,4,inspirations:redstone_barrel:0)
Block(-4,4,5,quark:limestone:1)
Block(-4,4,6,quark:world_stone_pavement:2)
Block(-4,4,7,quark:world_stone_pavement:2)
Block(-4,4,8,quark:limestone:1)
Block(-4,5,-7,quark:world_stone_pavement:5)
Block(-4,5,-6,quark:limestone:1)
Block(-4,5,-5,quark:limestone:1)
Block(-4,5,-4,quark:world_stone_pavement:2)
Block(-4,5,-3,quark:world_stone_pavement:2)
Block(-4,5,-2,quark:grate:0)
Block(-4,5,-1,srparasites:infestedstain:0)
Block(-4,5,0,quark:world_stone_pavement:2)
Block(-4,5,1,quark:grate:0)
Block(-4,5,2,quark:world_stone_pavement:2)
Block(-4,5,3,quark:world_stone_pavement:5)
Block(-4,5,4,inspirations:redstone_barrel:0)
Block(-4,5,5,quark:world_stone_pavement:5)
Block(-4,5,6,quark:world_stone_pavement:5)
Block(-4,5,7,quark:limestone:1)
Block(-4,5,8,quark:world_stone_pavement:5)
Block(-4,6,-7,inspirations:redstone_barrel:0)
Block(-4,6,-6,quark:marble_wall:0)
Block(-4,6,-5,quark:marble_wall:0)
Block(-4,6,-4,quark:marble_wall:0)
Block(-4,6,-3,quark:marble_wall:0)
Block(-4,6,-2,AIR:0)
RandomBlock(-4,6,0,rustic:iron_lattice:0,30,rustic:iron_lattice:1,100)
Block(-4,6,1,AIR:0)
Block(-4,6,2,AIR:0)
Block(-4,6,3,quark:basalt_wall:0)
Block(-4,6,4,inspirations:redstone_barrel:0)
Block(-4,6,5,quark:world_stone_pavement:5)
Block(-4,6,6,quark:world_stone_pavement:5)
Block(-4,6,7,quark:world_stone_pavement:5)
Block(-4,6,8,quark:world_stone_pavement:5)
Block(-4,7,-7,inspirations:redstone_barrel:0)
Block(-4,7,-6,quark:marble_wall:0)
Block(-4,7,-5,quark:marble_wall:0)
Block(-4,7,-4,quark:marble_wall:0)
Block(-4,7,-3,quark:marble_wall:0)
Block(-4,7,-2,AIR:0)
Block(-4,7,-1,AIR:0)
RandomBlock(-4,7,0,rustic:iron_lattice:0,30,rustic:iron_lattice:1,100)
Block(-4,7,1,AIR:0)
Block(-4,7,2,AIR:0)
Block(-4,7,3,quark:basalt_wall:0)
Block(-4,7,4,inspirations:redstone_barrel:0)
Block(-4,7,5,quark:world_stone_pavement:2)
Block(-4,7,6,quark:polished_stone:0)
Block(-4,7,7,quark:limestone:1)
Block(-4,7,8,quark:world_stone_pavement:5)
Block(-4,8,-7,inspirations:redstone_barrel:0)
Block(-4,8,-6,quark:world_stone_pavement:5)
Block(-4,8,-5,quark:world_stone_pavement:2)
Block(-4,8,-4,quark:world_stone_pavement:5)
Block(-4,8,-3,quark:world_stone_pavement:5)
Block(-4,8,-2,quark:limestone:1)
Block(-4,8,-1,quark:world_stone_pavement:2)
Block(-4,8,0,quark:world_stone_pavement:5)
Block(-4,8,1,quark:world_stone_pavement:2)
Block(-4,8,2,quark:world_stone_pavement:5)
Block(-4,8,3,quark:world_stone_pavement:2)
Block(-4,8,4,quark:polished_stone:0)
Block(-4,8,5,quark:polished_stone:0)
Block(-4,8,6,quark:world_stone_pavement:2)
Block(-4,8,7,quark:limestone:1)
Block(-4,8,8,quark:world_stone_pavement:2)
Block(-4,9,-7,inspirations:redstone_barrel:0)
Block(-4,9,-6,quark:world_stone_pavement:5)
Block(-4,9,-5,quark:world_stone_pavement:5)
Block(-4,9,-4,quark:polished_stone:0)
Block(-4,9,-3,quark:polished_stone:0)
Block(-4,9,-2,quark:polished_stone:0)
Block(-4,9,-1,quark:world_stone_pavement:5)
Block(-4,9,0,quark:polished_stone:0)
Block(-4,9,1,quark:polished_stone:0)
Block(-4,9,2,quark:world_stone_pavement:2)
Block(-4,9,3,quark:polished_stone:0)
Block(-4,9,4,quark:polished_stone:0)
Block(-4,9,5,quark:polished_stone:0)
Block(-4,9,6,quark:polished_stone:0)
Block(-4,9,7,quark:world_stone_pavement:2)
Block(-4,9,8,quark:world_stone_pavement:2)
Block(-4,10,-7,inspirations:redstone_barrel:0)
Block(-4,10,-6,quark:polished_stone:0)
Block(-4,10,-5,quark:limestone:1)
Block(-4,10,-4,quark:polished_stone:0)
Block(-4,10,-3,quark:polished_stone:0)
Block(-4,10,-2,quark:polished_stone:0)
Block(-4,10,-1,srparasites:parasitestain:1)
Block(-4,10,0,quark:polished_stone:0)
Block(-4,10,1,quark:world_stone_pavement:2)
Block(-4,10,2,quark:world_stone_pavement:2)
Block(-4,10,3,quark:polished_stone:0)
Block(-4,10,4,srparasites:infestedstain:0)
Block(-4,10,5,quark:world_stone_pavement:2)
Block(-4,10,6,quark:polished_stone:0)
Block(-4,10,7,quark:world_stone_pavement:2)
Block(-4,10,8,srparasites:parasitestain:1)
Block(-4,11,-7,quark:iron_plate:1)
Block(-4,11,-6,quark:iron_plate:1)
Block(-4,11,-5,quark:iron_plate:1)
Block(-4,11,-4,quark:polished_stone:0)
Block(-4,11,-3,quark:world_stone_pavement:2)
Block(-4,11,-2,quark:iron_plate:1)
Block(-4,11,-1,srparasites:parasitebush:0)
Block(-4,11,1,quark:iron_plate:1)
Block(-4,11,2,quark:iron_plate:1)
Block(-4,11,6,quark:polished_stone:0)
Block(-4,11,7,quark:polished_stone:0)
Block(-4,11,8,srparasites:parasitestain:1)
Block(-4,12,-4,quark:world_stone_pavement:2)
Block(-4,12,-3,quark:world_stone_pavement:2)
Block(-4,12,-2,srparasites:parasitetendril:4)
Block(-4,12,-1,srparasites:parasitebush:0)
Block(-4,12,2,quark:iron_plate:1)
Block(-4,12,6,DOUBLE_STEP:0)
Block(-4,12,7,quark:polished_stone:0)
Block(-4,13,-4,quark:polished_stone:0)
Block(-4,13,-3,quark:polished_stone:0)
Block(-4,13,-2,srparasites:parasitetendril:4)
Block(-4,13,2,quark:iron_plate:1)
Block(-4,13,6,DOUBLE_STEP:0)
Block(-4,13,7,quark:polished_stone:0)
Block(-4,13,8,quark:grate:0)
Block(-4,14,-4,quark:polished_stone:0)
Block(-4,14,-3,quark:polished_stone:0)
Block(-4,14,-2,srparasites:parasitetendril:4)
Block(-4,14,6,DOUBLE_STEP:0)
Block(-4,14,7,quark:polished_stone:0)
RandomBlock(-4,15,-7,SMOOTH_BRICK:0,40,SMOOTH_BRICK:1,30,SMOOTH_BRICK:2,30,MOSSY_COBBLESTONE:0,30,COBBLESTONE:0,20,SMOOTH_BRICK:0,100)
RandomBlock(-4,15,-6,SMOOTH_BRICK:0,40,SMOOTH_BRICK:1,30,SMOOTH_BRICK:2,30,MOSSY_COBBLESTONE:0,30,COBBLESTONE:0,20,SMOOTH_BRICK:0,100)
RandomBlock(-4,15,-5,SMOOTH_BRICK:0,40,SMOOTH_BRICK:1,30,SMOOTH_BRICK:2,30,MOSSY_COBBLESTONE:0,30,COBBLESTONE:0,20,SMOOTH_BRICK:0,100)
RandomBlock(-4,15,-4,SMOOTH_BRICK:0,40,SMOOTH_BRICK:1,30,SMOOTH_BRICK:2,30,MOSSY_COBBLESTONE:0,30,COBBLESTONE:0,20,SMOOTH_BRICK:0,100)
RandomBlock(-4,15,-3,SMOOTH_BRICK:0,40,SMOOTH_BRICK:1,30,SMOOTH_BRICK:2,30,MOSSY_COBBLESTONE:0,30,COBBLESTONE:0,20,SMOOTH_BRICK:0,100)
Block(-4,15,-2,quark:iron_plate_slab:8)
Block(-4,15,-1,quark:iron_plate_slab:8)
Block(-4,15,0,quark:iron_plate_slab:8)
Block(-4,15,1,quark:iron_plate_slab:8)
Block(-4,15,2,quark:iron_plate_slab:8)
Block(-4,15,3,quark:grate:0)
Block(-4,15,4,quark:grate:0)
Block(-4,15,5,quark:grate:0)
Block(-4,15,6,DOUBLE_STEP:0)
Block(-4,15,7,quark:world_stone_pavement:2)
RandomBlock(-4,16,-7,rustic:iron_lattice:0,30,rustic:iron_lattice:1,100)
RandomBlock(-4,16,-6,rustic:iron_lattice:0,30,rustic:iron_lattice:1,100)
RandomBlock(-4,16,-5,rustic:iron_lattice:0,30,rustic:iron_lattice:1,100)
RandomBlock(-4,16,-4,rustic:iron_lattice:0,30,rustic:iron_lattice:1,100)
RandomBlock(-4,16,-3,rustic:iron_lattice:0,30,rustic:iron_lattice:1,100)
RandomBlock(-4,16,-2,rustic:iron_lattice:0,30,rustic:iron_lattice:1,100)
RandomBlock(-4,16,-1,rustic:iron_lattice:0,30,rustic:iron_lattice:1,100)
RandomBlock(-4,16,0,rustic:iron_lattice:0,30,rustic:iron_lattice:1,100)
RandomBlock(-4,16,1,rustic:iron_lattice:0,30,rustic:iron_lattice:1,100)
RandomBlock(-4,16,2,rustic:iron_lattice:0,30,rustic:iron_lattice:1,100)
Block(-4,16,3,srparasites:parasitetendril:8)
Block(-4,16,5,srparasites:parasitetendril:1)
Block(-4,16,6,DOUBLE_STEP:0)
Block(-4,16,7,quark:iron_plate:1)
Block(-4,16,8,SMOOTH_STAIRS:4)
RandomBlock(-4,17,-7,rustic:iron_lattice:0,30,rustic:iron_lattice:1,100)
RandomBlock(-4,17,-6,rustic:iron_lattice:0,30,rustic:iron_lattice:1,100)
RandomBlock(-4,17,-5,rustic:iron_lattice:0,30,rustic:iron_lattice:1,100)
RandomBlock(-4,17,-4,rustic:iron_lattice:0,30,rustic:iron_lattice:1,100)
RandomBlock(-4,17,-3,rustic:iron_lattice:0,30,rustic:iron_lattice:1,100)
RandomBlock(-4,17,-2,rustic:iron_lattice:0,30,rustic:iron_lattice:1,100)
RandomBlock(-4,17,-1,rustic:iron_lattice:0,30,rustic:iron_lattice:1,100)
RandomBlock(-4,17,0,rustic:iron_lattice:0,30,rustic:iron_lattice:1,100)
RandomBlock(-4,17,1,rustic:iron_lattice:0,30,rustic:iron_lattice:1,100)
RandomBlock(-4,17,2,rustic:iron_lattice:0,30,rustic:iron_lattice:1,100)
Block(-4,17,3,srparasites:parasitetendril:8)
Block(-4,17,5,srparasites:parasitetendril:1)
Block(-4,17,6,DOUBLE_STEP:0)
Block(-4,17,7,quark:iron_plate:1)
Block(-4,17,8,quark:polished_stone:0)
Block(-4,18,-6,srparasites:parasitetendril:1)
RandomBlock(-4,18,-2,rustic:iron_lattice:0,30,rustic:iron_lattice:1,100)
RandomBlock(-4,18,1,rustic:iron_lattice:0,30,rustic:iron_lattice:1,100)
Block(-4,18,3,srparasites:parasitetendril:8)
Block(-4,18,5,srparasites:parasitetendril:1)
Block(-4,18,6,DOUBLE_STEP:0)
Block(-4,18,7,SMOOTH_STAIRS:1)
Block(-4,18,8,SMOOTH_STAIRS:1)
Block(-4,19,-6,srparasites:parasitetendril:1)
RandomBlock(-4,19,-2,rustic:iron_lattice:0,30,rustic:iron_lattice:1,100)
RandomBlock(-4,19,1,rustic:iron_lattice:0,30,rustic:iron_lattice:1,100)
Block(-4,19,3,srparasites:parasitetendril:8)
Block(-4,19,5,srparasites:parasitetendril:1)
Block(-4,19,6,quark:iron_plate:1)
Block(-4,20,-7,srparasites:parasitethin:0)
Block(-4,20,-6,srparasites:parasitetendril:1)
Block(-4,20,-5,quark:polished_stone:0)
Block(-4,20,-2,quark:polished_stone:0)
Block(-4,20,1,quark:polished_stone:0)
Block(-4,20,5,quark:polished_stone:0)
Block(-4,20,6,SMOOTH_STAIRS:3)
Block(-4,21,-7,DOUBLE_STEP:0)
Block(-4,21,-6,DOUBLE_STEP:0)
Block(-4,21,-5,quark:world_stone_pavement:2)
Block(-4,21,-4,quark:polished_stone:0)
Block(-4,21,-3,quark:polished_stone:0)
Block(-4,21,-2,quark:polished_stone:0)
Block(-4,21,-1,quark:polished_stone:0)
Block(-4,21,0,DOUBLE_STEP:0)
Block(-4,21,1,STEP:0)
Block(-4,21,2,STEP:0)
Block(-4,21,3,STEP:0)
Block(-4,21,4,STEP:0)
Block(-4,21,5,STEP:0)
Block(-4,22,-7,STEP:0)
Block(-4,22,-6,STEP:0)
Block(-4,22,-5,STEP:0)
Block(-3,0,-7,quark:world_stone_pavement:2)
Block(-3,0,-6,quark:limestone:1)
Block(-3,0,-5,quark:world_stone_pavement:5)
Block(-3,0,-4,quark:limestone:1)
Block(-3,0,-3,quark:world_stone_pavement:5)
Block(-3,0,-2,quark:world_stone_pavement:2)
Block(-3,0,-1,quark:limestone:1)
Block(-3,0,0,quark:world_stone_pavement:5)
Block(-3,0,1,quark:world_stone_pavement:2)
Block(-3,0,2,quark:world_stone_pavement:2)
Block(-3,0,3,quark:world_stone_pavement:2)
Block(-3,0,4,quark:world_stone_pavement:2)
Block(-3,0,5,quark:limestone:1)
Block(-3,0,6,quark:world_stone_pavement:2)
Block(-3,0,7,quark:world_stone_pavement:5)
Block(-3,0,8,quark:world_stone_pavement:2)
Block(-3,1,-7,quark:limestone:1)
Block(-3,1,-6,quark:world_stone_pavement:5)
Block(-3,1,-5,quark:world_stone_pavement:2)
Block(-3,1,-4,quark:world_stone_pavement:5)
Block(-3,1,-3,quark:world_stone_pavement:2)
Block(-3,1,-2,quark:world_stone_pavement:2)
Block(-3,1,-1,quark:world_stone_pavement:5)
Block(-3,1,0,quark:world_stone_pavement:5)
Block(-3,1,1,quark:limestone:1)
Block(-3,1,2,quark:world_stone_pavement:2)
Block(-3,1,3,quark:world_stone_pavement:5)
Block(-3,1,4,quark:world_stone_pavement:2)
Block(-3,1,5,quark:limestone:1)
Block(-3,1,6,quark:world_stone_pavement:2)
Block(-3,1,7,quark:world_stone_pavement:2)
Block(-3,1,8,quark:limestone:1)
Block(-3,2,-7,quark:limestone:1)
Block(-3,2,-6,quark:world_stone_pavement:2)
Block(-3,2,-5,quark:world_stone_pavement:2)
Block(-3,2,-4,quark:world_stone_pavement:5)
Block(-3,2,-3,quark:world_stone_pavement:5)
Block(-3,2,-2,quark:world_stone_pavement:2)
Block(-3,2,-1,quark:world_stone_pavement:5)
Block(-3,2,0,quark:world_stone_pavement:5)
Block(-3,2,1,quark:world_stone_pavement:5)
Block(-3,2,2,quark:world_stone_pavement:2)
Block(-3,2,3,quark:world_stone_pavement:5)
Block(-3,2,4,quark:world_stone_pavement:2)
Block(-3,2,5,quark:world_stone_pavement:5)
Block(-3,2,6,quark:world_stone_pavement:5)
Block(-3,2,7,quark:limestone:1)
Block(-3,2,8,quark:limestone:1)
Block(-3,3,-7,quark:world_stone_pavement:2)
Block(-3,3,-6,quark:world_stone_pavement:2)
Block(-3,3,-5,quark:limestone:1)
Block(-3,3,-4,quark:world_stone_pavement:5)
Block(-3,3,-3,quark:world_stone_pavement:2)
Block(-3,3,-2,quark:world_stone_pavement:2)
Block(-3,3,-1,quark:world_stone_pavement:2)
Block(-3,3,0,quark:world_stone_pavement:5)
Block(-3,3,1,quark:world_stone_pavement:5)
Block(-3,3,2,quark:world_stone_pavement:5)
Block(-3,3,3,quark:world_stone_pavement:5)
Block(-3,3,4,quark:world_stone_pavement:2)
Block(-3,3,5,quark:world_stone_pavement:2)
Block(-3,3,6,quark:world_stone_pavement:5)
Block(-3,3,7,quark:world_stone_pavement:5)
Block(-3,3,8,quark:world_stone_pavement:2)
Block(-3,4,-7,quark:limestone:1)
Block(-3,4,-6,quark:world_stone_pavement:5)
Block(-3,4,-5,quark:limestone:1)
Block(-3,4,-4,quark:world_stone_pavement:5)
Block(-3,4,-3,quark:limestone:1)
Block(-3,4,-2,quark:iron_plate:1)
Block(-3,4,-1,quark:limestone:1)
Block(-3,4,0,quark:world_stone_pavement:5)
Block(-3,4,1,quark:iron_plate:1)
Block(-3,4,2,quark:world_stone_pavement:2)
Block(-3,4,3,quark:world_stone_pavement:2)
Block(-3,4,4,inspirations:redstone_barrel:0)
Block(-3,4,5,quark:limestone:1)
Block(-3,4,6,quark:limestone:1)
Block(-3,4,7,quark:world_stone_pavement:2)
Block(-3,4,8,quark:limestone:1)
Block(-3,5,-7,srparasites:parasitestain:1)
Block(-3,5,-6,srparasites:parasitestain:1)
Block(-3,5,-5,quark:limestone:1)
Block(-3,5,-4,srparasites:parasitestain:1)
Block(-3,5,-3,quark:limestone:1)
Block(-3,5,-2,quark:grate:0)
Block(-3,5,-1,srparasites:infestedstain:0)
Block(-3,5,0,quark:world_stone_pavement:2)
Block(-3,5,1,quark:grate:0)
Block(-3,5,2,quark:limestone:1)
Block(-3,5,3,quark:world_stone_pavement:5)
Block(-3,5,4,inspirations:redstone_barrel:0)
Block(-3,5,5,quark:world_stone_pavement:5)
Block(-3,5,6,quark:world_stone_pavement:5)
Block(-3,5,7,quark:limestone:1)
Block(-3,5,8,quark:world_stone_pavement:5)
Block(-3,6,-7,AIR:0)
Block(-3,6,-5,AIR:0)
Block(-3,6,-4,AIR:0)
Block(-3,6,-3,AIR:0)
Block(-3,6,-2,AIR:0)
Block(-3,6,0,quark:basalt_wall:0)
Block(-3,6,1,AIR:0)
Block(-3,6,2,inspirations:redstone_barrel:0)
Block(-3,6,3,inspirations:redstone_barrel:0)
Block(-3,6,4,inspirations:redstone_barrel:0)
Block(-3,6,5,quark:world_stone_pavement:2)
Block(-3,6,6,quark:world_stone_pavement:2)
Block(-3,6,7,quark:world_stone_pavement:5)
Block(-3,6,8,quark:world_stone_pavement:5)
Block(-3,7,-7,AIR:0)
Block(-3,7,-6,AIR:0)
Block(-3,7,-5,AIR:0)
Block(-3,7,-4,AIR:0)
Block(-3,7,-3,AIR:0)
Block(-3,7,-2,AIR:0)
Block(-3,7,0,quark:basalt_wall:0)
Block(-3,7,1,AIR:0)
Block(-3,7,2,inspirations:redstone_barrel:0)
Block(-3,7,3,inspirations:redstone_barrel:0)
Block(-3,7,4,inspirations:redstone_barrel:0)
Block(-3,7,5,quark:polished_stone:0)
Block(-3,7,6,quark:world_stone_pavement:2)
Block(-3,7,7,quark:limestone:1)
Block(-3,7,8,quark:world_stone_pavement:5)
Block(-3,8,-7,AIR:0)
Block(-3,8,-6,AIR:0)
Block(-3,8,-5,quark:world_stone_pavement:2)
Block(-3,8,-4,quark:polished_stone:0)
Block(-3,8,-3,quark:world_stone_pavement:2)
Block(-3,8,-2,AIR:0)
Block(-3,8,-1,quark:world_stone_pavement:2)
Block(-3,8,0,quark:world_stone_pavement:5)
Block(-3,8,1,quark:world_stone_pavement:2)
Block(-3,8,2,quark:world_stone_pavement:5)
Block(-3,8,3,quark:world_stone_pavement:2)
Block(-3,8,4,quark:world_stone_pavement:2)
Block(-3,8,5,quark:world_stone_pavement:2)
Block(-3,8,6,quark:world_stone_pavement:2)
Block(-3,8,7,quark:limestone:1)
Block(-3,8,8,quark:world_stone_pavement:2)
RandomBlock(-3,9,-7,rustic:iron_lattice:0,30,rustic:iron_lattice:1,100)
Block(-3,9,-6,AIR:0)
Block(-3,9,-5,quark:polished_stone:0)
Block(-3,9,-4,quark:polished_stone:0)
Block(-3,9,-3,quark:polished_stone:0)
Block(-3,9,-2,quark:polished_stone:0)
Block(-3,9,-1,quark:polished_stone:0)
Block(-3,9,0,quark:polished_stone:0)
Block(-3,9,1,quark:polished_stone:0)
Block(-3,9,2,quark:polished_stone:0)
Block(-3,9,3,quark:polished_stone:0)
Block(-3,9,4,quark:polished_stone:0)
Block(-3,9,5,quark:polished_stone:0)
Block(-3,9,6,quark:polished_stone:0)
Block(-3,9,7,quark:world_stone_pavement:2)
Block(-3,9,8,quark:world_stone_pavement:2)
RandomBlock(-3,10,-7,rustic:iron_lattice:0,30,rustic:iron_lattice:1,100)
Block(-3,10,-6,AIR:0)
Block(-3,10,-5,quark:polished_stone:0)
Block(-3,10,-4,quark:polished_stone:0)
Block(-3,10,-3,quark:world_stone_pavement:2)
Block(-3,10,-2,quark:polished_stone:0)
Block(-3,10,-1,srparasites:infestedstain:0)
Block(-3,10,0,quark:polished_stone:0)
Block(-3,10,1,quark:world_stone_pavement:2)
Block(-3,10,2,quark:world_stone_pavement:2)
Block(-3,10,3,quark:polished_stone:0)
Block(-3,10,4,quark:polished_stone:0)
Block(-3,10,5,srparasites:infestedstain:0)
Block(-3,10,6,quark:polished_stone:0)
Block(-3,10,7,quark:world_stone_pavement:2)
Block(-3,10,8,quark:polished_stone:0)
RandomBlock(-3,11,-7,rustic:iron_lattice:0,30,rustic:iron_lattice:1,100)
RandomBlock(-3,11,-6,rustic:iron_lattice:0,30,rustic:iron_lattice:1,100)
Block(-3,11,-5,quark:iron_plate:1)
Block(-3,11,-2,quark:iron_plate:1)
Block(-3,11,1,quark:iron_plate:1)
Block(-3,11,6,quark:polished_stone:0)
RandomBlock(-3,11,7,SMOOTH_BRICK:0,40,SMOOTH_BRICK:1,30,SMOOTH_BRICK:2,30,MOSSY_COBBLESTONE:0,30,COBBLESTONE:0,20,SMOOTH_BRICK:0,100)
Block(-3,11,8,DOUBLE_STEP:0)
RandomBlock(-3,12,-7,rustic:iron_lattice:0,30,rustic:iron_lattice:1,100)
RandomBlock(-3,12,-6,rustic:iron_lattice:0,30,rustic:iron_lattice:1,100)
Block(-3,12,6,quark:world_stone_pavement:2)
RandomBlock(-3,12,7,SMOOTH_BRICK:0,40,SMOOTH_BRICK:1,30,SMOOTH_BRICK:2,30,MOSSY_COBBLESTONE:0,30,COBBLESTONE:0,20,SMOOTH_BRICK:0,100)
Block(-3,12,8,DOUBLE_STEP:0)
RandomBlock(-3,13,6,SMOOTH_BRICK:0,40,SMOOTH_BRICK:1,30,SMOOTH_BRICK:2,30,MOSSY_COBBLESTONE:0,30,COBBLESTONE:0,20,SMOOTH_BRICK:0,100)
RandomBlock(-3,13,7,SMOOTH_BRICK:0,40,SMOOTH_BRICK:1,30,SMOOTH_BRICK:2,30,MOSSY_COBBLESTONE:0,30,COBBLESTONE:0,20,SMOOTH_BRICK:0,100)
Block(-3,13,8,DOUBLE_STEP:0)
RandomBlock(-3,14,6,SMOOTH_BRICK:0,40,SMOOTH_BRICK:1,30,SMOOTH_BRICK:2,30,MOSSY_COBBLESTONE:0,30,COBBLESTONE:0,20,SMOOTH_BRICK:0,100)
RandomBlock(-3,14,7,SMOOTH_BRICK:0,40,SMOOTH_BRICK:1,30,SMOOTH_BRICK:2,30,MOSSY_COBBLESTONE:0,30,COBBLESTONE:0,20,SMOOTH_BRICK:0,100)
Block(-3,14,8,DOUBLE_STEP:0)
RandomBlock(-3,15,-7,SMOOTH_BRICK:0,40,SMOOTH_BRICK:1,30,SMOOTH_BRICK:2,30,MOSSY_COBBLESTONE:0,30,COBBLESTONE:0,20,SMOOTH_BRICK:0,100)
RandomBlock(-3,15,-6,SMOOTH_BRICK:0,40,SMOOTH_BRICK:1,30,SMOOTH_BRICK:2,30,MOSSY_COBBLESTONE:0,30,COBBLESTONE:0,20,SMOOTH_BRICK:0,100)
RandomBlock(-3,15,-5,SMOOTH_BRICK:0,40,SMOOTH_BRICK:1,30,SMOOTH_BRICK:2,30,MOSSY_COBBLESTONE:0,30,COBBLESTONE:0,20,SMOOTH_BRICK:0,100)
RandomBlock(-3,15,-4,SMOOTH_BRICK:0,40,SMOOTH_BRICK:1,30,SMOOTH_BRICK:2,30,MOSSY_COBBLESTONE:0,30,COBBLESTONE:0,20,SMOOTH_BRICK:0,100)
RandomBlock(-3,15,-3,SMOOTH_BRICK:0,40,SMOOTH_BRICK:1,30,SMOOTH_BRICK:2,30,MOSSY_COBBLESTONE:0,30,COBBLESTONE:0,20,SMOOTH_BRICK:0,100)
Block(-3,15,-2,quark:grate:0)
Block(-3,15,-1,quark:grate:0)
Block(-3,15,0,quark:grate:0)
Block(-3,15,1,quark:grate:0)
Block(-3,15,2,quark:grate:0)
Block(-3,15,3,quark:grate:0)
Block(-3,15,4,quark:grate:0)
Block(-3,15,5,quark:grate:0)
RandomBlock(-3,15,6,SMOOTH_BRICK:0,40,SMOOTH_BRICK:1,30,SMOOTH_BRICK:2,30,MOSSY_COBBLESTONE:0,30,COBBLESTONE:0,20,SMOOTH_BRICK:0,100)
RandomBlock(-3,15,7,SMOOTH_BRICK:0,40,SMOOTH_BRICK:1,30,SMOOTH_BRICK:2,30,MOSSY_COBBLESTONE:0,30,COBBLESTONE:0,20,SMOOTH_BRICK:0,100)
Block(-3,15,8,DOUBLE_STEP:0)
RandomBlock(-3,16,6,SMOOTH_BRICK:0,40,SMOOTH_BRICK:1,30,SMOOTH_BRICK:2,30,MOSSY_COBBLESTONE:0,30,COBBLESTONE:0,20,SMOOTH_BRICK:0,100)
Block(-3,16,7,quark:iron_plate:1)
Block(-3,16,8,quark:iron_plate:1)
RandomBlock(-3,17,6,SMOOTH_BRICK:0,40,SMOOTH_BRICK:1,30,SMOOTH_BRICK:2,30,MOSSY_COBBLESTONE:0,30,COBBLESTONE:0,20,SMOOTH_BRICK:0,100)
Block(-3,17,7,quark:iron_plate:1)
RandomBlock(-3,18,6,SMOOTH_BRICK:0,40,SMOOTH_BRICK:1,30,SMOOTH_BRICK:2,30,MOSSY_COBBLESTONE:0,30,COBBLESTONE:0,20,SMOOTH_BRICK:0,100)
Block(-3,18,7,STEP:0)
Block(-3,19,-5,quark:world_stone_pavement:2)
Block(-3,19,-2,quark:polished_stone:0)
Block(-3,19,1,quark:world_stone_pavement:2)
Block(-3,19,2,quark:iron_plate:1)
Block(-3,19,3,quark:iron_plate:1)
Block(-3,19,4,quark:iron_plate:1)
Block(-3,19,5,quark:iron_plate:1)
Block(-3,19,6,quark:iron_plate:1)
Block(-3,20,-7,srparasites:parasitethin:0)
Block(-3,20,-5,quark:polished_stone:0)
Block(-3,20,-2,quark:polished_stone:0)
Block(-3,20,1,quark:polished_stone:0)
Block(-3,20,2,quark:iron_plate:1)
Block(-3,20,3,quark:iron_plate:1)
Block(-3,20,4,quark:iron_plate:1)
Block(-3,20,5,quark:iron_plate:1)
Block(-3,20,6,SMOOTH_STAIRS:3)
Block(-3,21,-7,STEP:0)
Block(-3,21,-6,STEP:0)
Block(-3,21,-5,quark:polished_stone:0)
Block(-3,21,-4,quark:world_stone_pavement:2)
Block(-3,21,-3,quark:polished_stone:0)
Block(-3,21,-2,quark:polished_stone:0)
Block(-3,21,-1,quark:polished_stone:0)
Block(-3,21,0,DOUBLE_STEP:0)
Block(-3,21,1,STEP:0)
Block(-3,21,2,STEP:0)
Block(-3,21,3,STEP:0)
Block(-3,21,4,STEP:0)
Block(-3,21,5,STEP:0)
Block(-2,0,-7,quark:world_stone_pavement:2)
Block(-2,0,-6,quark:limestone:1)
Block(-2,0,-5,quark:world_stone_pavement:2)
Block(-2,0,-4,quark:world_stone_pavement:5)
Block(-2,0,-3,quark:limestone:1)
Block(-2,0,-2,quark:limestone:1)
Block(-2,0,-1,quark:world_stone_pavement:2)
Block(-2,0,0,quark:world_stone_pavement:2)
Block(-2,0,1,quark:world_stone_pavement:5)
Block(-2,0,2,quark:world_stone_pavement:5)
Block(-2,0,3,quark:world_stone_pavement:2)
Block(-2,0,4,quark:world_stone_pavement:2)
Block(-2,0,5,quark:limestone:1)
Block(-2,0,6,quark:world_stone_pavement:2)
Block(-2,0,7,quark:limestone:1)
RandomBlock(-2,0,8,SMOOTH_BRICK:0,40,SMOOTH_BRICK:1,30,SMOOTH_BRICK:2,30,MOSSY_COBBLESTONE:0,30,COBBLESTONE:0,20,SMOOTH_BRICK:0,100)
Block(-2,1,-7,quark:limestone:1)
Block(-2,1,-6,quark:world_stone_pavement:2)
Block(-2,1,-5,quark:limestone:1)
Block(-2,1,-4,quark:world_stone_pavement:2)
Block(-2,1,-3,quark:limestone:1)
Block(-2,1,-2,quark:world_stone_pavement:2)
Block(-2,1,-1,quark:world_stone_pavement:2)
Block(-2,1,0,quark:world_stone_pavement:2)
Block(-2,1,1,quark:limestone:1)
Block(-2,1,2,quark:world_stone_pavement:2)
Block(-2,1,3,quark:limestone:1)
Block(-2,1,4,quark:world_stone_pavement:2)
Block(-2,1,5,quark:limestone:1)
Block(-2,1,6,quark:world_stone_pavement:5)
Block(-2,1,7,quark:world_stone_pavement:2)
RandomBlock(-2,1,8,SMOOTH_BRICK:0,40,SMOOTH_BRICK:1,30,SMOOTH_BRICK:2,30,MOSSY_COBBLESTONE:0,30,COBBLESTONE:0,20,SMOOTH_BRICK:0,100)
Block(-2,2,-7,quark:world_stone_pavement:5)
Block(-2,2,-6,quark:world_stone_pavement:5)
Block(-2,2,-5,quark:world_stone_pavement:5)
Block(-2,2,-4,quark:world_stone_pavement:5)
Block(-2,2,-3,quark:limestone:1)
Block(-2,2,-2,quark:limestone:1)
Block(-2,2,-1,quark:world_stone_pavement:2)
Block(-2,2,0,quark:world_stone_pavement:2)
Block(-2,2,1,quark:world_stone_pavement:2)
Block(-2,2,2,quark:limestone:1)
Block(-2,2,3,quark:world_stone_pavement:5)
Block(-2,2,4,quark:world_stone_pavement:2)
Block(-2,2,5,quark:limestone:1)
Block(-2,2,6,quark:world_stone_pavement:5)
Block(-2,2,7,quark:world_stone_pavement:2)
RandomBlock(-2,2,8,SMOOTH_BRICK:0,40,SMOOTH_BRICK:1,30,SMOOTH_BRICK:2,30,MOSSY_COBBLESTONE:0,30,COBBLESTONE:0,20,SMOOTH_BRICK:0,100)
Block(-2,3,-7,quark:world_stone_pavement:5)
Block(-2,3,-6,quark:limestone:1)
Block(-2,3,-5,quark:world_stone_pavement:5)
Block(-2,3,-4,quark:world_stone_pavement:2)
Block(-2,3,-3,quark:limestone:1)
Block(-2,3,-2,quark:world_stone_pavement:5)
Block(-2,3,-1,quark:world_stone_pavement:2)
Block(-2,3,0,quark:world_stone_pavement:2)
Block(-2,3,1,quark:world_stone_pavement:2)
Block(-2,3,2,quark:world_stone_pavement:5)
Block(-2,3,3,quark:world_stone_pavement:2)
Block(-2,3,4,quark:world_stone_pavement:2)
Block(-2,3,5,quark:world_stone_pavement:2)
Block(-2,3,6,quark:limestone:1)
Block(-2,3,7,quark:world_stone_pavement:5)
RandomBlock(-2,3,8,SMOOTH_BRICK:0,40,SMOOTH_BRICK:1,30,SMOOTH_BRICK:2,30,MOSSY_COBBLESTONE:0,30,COBBLESTONE:0,20,SMOOTH_BRICK:0,100)
Block(-2,4,-7,quark:limestone:1)
Block(-2,4,-6,quark:limestone:1)
Block(-2,4,-5,quark:world_stone_pavement:5)
Block(-2,4,-4,quark:limestone:1)
Block(-2,4,-3,quark:limestone:1)
Block(-2,4,-2,quark:iron_plate:1)
Block(-2,4,-1,quark:world_stone_pavement:2)
Block(-2,4,0,quark:world_stone_pavement:2)
Block(-2,4,1,quark:iron_plate:1)
Block(-2,4,2,quark:world_stone_pavement:5)
Block(-2,4,3,quark:world_stone_pavement:5)
Block(-2,4,4,quark:world_stone_pavement:2)
Block(-2,4,5,quark:world_stone_pavement:2)
Block(-2,4,6,quark:limestone:1)
Block(-2,4,7,quark:limestone:1)
RandomBlock(-2,4,8,SMOOTH_BRICK:0,40,SMOOTH_BRICK:1,30,SMOOTH_BRICK:2,30,MOSSY_COBBLESTONE:0,30,COBBLESTONE:0,20,SMOOTH_BRICK:0,100)
Block(-2,5,-7,quark:limestone:1)
Block(-2,5,-6,quark:world_stone_pavement:2)
Block(-2,5,-5,quark:world_stone_pavement:2)
Block(-2,5,-4,quark:world_stone_pavement:5)
Block(-2,5,-3,quark:world_stone_pavement:2)
Block(-2,5,-2,quark:iron_plate:1)
Block(-2,5,-1,quark:world_stone_pavement:2)
Block(-2,5,0,quark:world_stone_pavement:2)
Block(-2,5,1,quark:iron_plate:1)
Block(-2,5,2,quark:world_stone_pavement:2)
Block(-2,5,3,quark:world_stone_pavement:2)
Block(-2,5,4,quark:world_stone_pavement:2)
Block(-2,5,5,quark:world_stone_pavement:2)
Block(-2,5,6,quark:limestone:1)
Block(-2,5,7,quark:world_stone_pavement:2)
RandomBlock(-2,5,8,SMOOTH_BRICK:0,40,SMOOTH_BRICK:1,30,SMOOTH_BRICK:2,30,MOSSY_COBBLESTONE:0,30,COBBLESTONE:0,20,SMOOTH_BRICK:0,100)
Block(-2,6,-7,quark:iron_plate_stairs:3)
Block(-2,6,-6,AIR:0)
Block(-2,6,-5,quark:iron_plate:1)
RandomBlock(-2,6,-4,rustic:iron_lattice:0,30,rustic:iron_lattice:1,100)
RandomBlock(-2,6,-3,rustic:iron_lattice:0,30,rustic:iron_lattice:1,100)
Block(-2,6,-2,quark:iron_plate:1)
RandomBlock(-2,6,-1,rustic:iron_lattice:0,30,rustic:iron_lattice:1,100)
Block(-2,6,0,inspirations:redstone_barrel:0)
Block(-2,6,1,quark:iron_plate:1)
Block(-2,6,2,quark:world_stone_pavement:1)
Block(-2,6,3,quark:limestone:1)
Block(-2,6,4,quark:world_stone_pavement:2)
Block(-2,6,5,quark:world_stone_pavement:5)
Block(-2,6,6,quark:world_stone_pavement:5)
Block(-2,6,7,quark:world_stone_pavement:5)
RandomBlock(-2,6,8,SMOOTH_BRICK:0,40,SMOOTH_BRICK:1,30,SMOOTH_BRICK:2,30,MOSSY_COBBLESTONE:0,30,COBBLESTONE:0,20,SMOOTH_BRICK:0,100)
Block(-2,7,-7,AIR:0)
Block(-2,7,-6,AIR:0)
Block(-2,7,-5,quark:iron_plate:1)
RandomBlock(-2,7,-4,rustic:iron_lattice:0,30,rustic:iron_lattice:1,100)
RandomBlock(-2,7,-3,rustic:iron_lattice:0,30,rustic:iron_lattice:1,100)
Block(-2,7,-2,quark:iron_plate:1)
RandomBlock(-2,7,-1,rustic:iron_lattice:0,30,rustic:iron_lattice:1,100)
Block(-2,7,0,inspirations:redstone_barrel:0)
Block(-2,7,1,quark:iron_plate:1)
Block(-2,7,2,quark:limestone:1)
Block(-2,7,3,quark:limestone:1)
Block(-2,7,4,quark:limestone:1)
Block(-2,7,5,quark:polished_stone:0)
Block(-2,7,6,quark:world_stone_pavement:2)
Block(-2,7,7,quark:world_stone_pavement:2)
RandomBlock(-2,7,8,SMOOTH_BRICK:0,40,SMOOTH_BRICK:1,30,SMOOTH_BRICK:2,30,MOSSY_COBBLESTONE:0,30,COBBLESTONE:0,20,SMOOTH_BRICK:0,100)
Block(-2,8,-7,AIR:0)
Block(-2,8,-6,AIR:0)
Block(-2,8,-5,quark:iron_plate:1)
Block(-2,8,-4,quark:world_stone_pavement:2)
Block(-2,8,-3,quark:polished_stone:0)
Block(-2,8,-2,quark:iron_plate:1)
Block(-2,8,-1,quark:world_stone_pavement:5)
Block(-2,8,0,quark:world_stone_pavement:5)
Block(-2,8,1,quark:world_stone_pavement:2)
Block(-2,8,2,quark:limestone:1)
Block(-2,8,3,quark:world_stone_pavement:5)
Block(-2,8,4,quark:polished_stone:0)
Block(-2,8,5,quark:world_stone_pavement:2)
Block(-2,8,6,quark:world_stone_pavement:2)
Block(-2,8,7,quark:polished_stone:0)
RandomBlock(-2,8,8,SMOOTH_BRICK:0,40,SMOOTH_BRICK:1,30,SMOOTH_BRICK:2,30,MOSSY_COBBLESTONE:0,30,COBBLESTONE:0,20,SMOOTH_BRICK:0,100)
Block(-2,9,-7,AIR:0)
Block(-2,9,-6,AIR:0)
Block(-2,9,-5,quark:iron_plate:1)
Block(-2,9,-4,quark:world_stone_pavement:2)
Block(-2,9,-3,quark:polished_stone:0)
Block(-2,9,-2,quark:iron_plate:1)
Block(-2,9,-1,quark:world_stone_pavement:2)
Block(-2,9,0,quark:polished_stone:0)
Block(-2,9,1,quark:polished_stone:0)
Block(-2,9,2,quark:polished_stone:0)
Block(-2,9,3,quark:polished_stone:0)
Block(-2,9,4,quark:world_stone_pavement:2)
Block(-2,9,5,quark:polished_stone:0)
Block(-2,9,6,quark:polished_stone:0)
Block(-2,9,7,quark:polished_stone:0)
RandomBlock(-2,9,8,SMOOTH_BRICK:0,40,SMOOTH_BRICK:1,30,SMOOTH_BRICK:2,30,MOSSY_COBBLESTONE:0,30,COBBLESTONE:0,20,SMOOTH_BRICK:0,100)
Block(-2,10,-7,AIR:0)
Block(-2,10,-6,AIR:0)
Block(-2,10,-5,quark:iron_plate:1)
Block(-2,10,-4,quark:polished_stone:0)
Block(-2,10,-3,quark:polished_stone:0)
Block(-2,10,-2,quark:iron_plate:1)
Block(-2,10,-1,srparasites:infestedstain:0)
Block(-2,10,0,quark:polished_stone:0)
Block(-2,10,1,quark:world_stone_pavement:2)
Block(-2,10,2,quark:world_stone_pavement:2)
Block(-2,10,3,quark:polished_stone:0)
Block(-2,10,4,quark:world_stone_pavement:2)
Block(-2,10,5,quark:polished_stone:0)
Block(-2,10,6,quark:polished_stone:0)
Block(-2,10,7,quark:world_stone_pavement:2)
RandomBlock(-2,10,8,SMOOTH_BRICK:0,40,SMOOTH_BRICK:1,30,SMOOTH_BRICK:2,30,MOSSY_COBBLESTONE:0,30,COBBLESTONE:0,20,SMOOTH_BRICK:0,100)
RandomBlock(-2,11,-6,rustic:iron_lattice:0,30,rustic:iron_lattice:1,100)
Block(-2,11,-5,quark:iron_plate:1)
Block(-2,11,-2,quark:iron_plate:1)
Block(-2,11,1,quark:polished_stone:0)
Block(-2,11,3,quark:polished_stone:0)
Block(-2,11,4,quark:polished_stone:0)
Block(-2,11,5,quark:world_stone_pavement:2)
Block(-2,11,6,quark:polished_stone:0)
Block(-2,11,7,quark:world_stone_pavement:2)
RandomBlock(-2,11,8,SMOOTH_BRICK:0,40,SMOOTH_BRICK:1,30,SMOOTH_BRICK:2,30,MOSSY_COBBLESTONE:0,30,COBBLESTONE:0,20,SMOOTH_BRICK:0,100)
RandomBlock(-2,12,-6,rustic:iron_lattice:0,30,rustic:iron_lattice:1,100)
Block(-2,12,-5,quark:polished_stone:0)
Block(-2,12,-2,quark:polished_stone:0)
Block(-2,12,1,quark:polished_stone:0)
Block(-2,12,3,DOUBLE_STEP:0)
Block(-2,12,4,DOUBLE_STEP:0)
Block(-2,12,5,DOUBLE_STEP:0)
Block(-2,12,6,DOUBLE_STEP:0)
Block(-2,12,7,DOUBLE_STEP:0)
Block(-2,12,8,DOUBLE_STEP:0)
Block(-2,13,-5,quark:world_stone_pavement:2)
Block(-2,13,-2,quark:world_stone_pavement:2)
Block(-2,13,1,quark:world_stone_pavement:2)
Block(-2,13,3,quark:polished_stone:0)
Block(-2,13,4,quark:polished_stone:0)
Block(-2,13,5,quark:polished_stone:0)
Block(-2,13,6,quark:polished_stone:0)
Block(-2,13,7,quark:world_stone_pavement:2)
Block(-2,13,8,quark:polished_stone:0)
Block(-2,14,-5,quark:polished_stone:0)
Block(-2,14,-2,quark:polished_stone:0)
Block(-2,14,1,quark:polished_stone:0)
Block(-2,14,3,quark:polished_stone:0)
Block(-2,14,4,quark:world_stone_pavement:2)
Block(-2,14,5,quark:polished_stone:0)
Block(-2,14,6,quark:polished_stone:0)
Block(-2,14,7,quark:world_stone_pavement:2)
Block(-2,14,8,quark:world_stone_pavement:2)
RandomBlock(-2,15,-7,SMOOTH_BRICK:0,40,SMOOTH_BRICK:1,30,SMOOTH_BRICK:2,30,MOSSY_COBBLESTONE:0,30,COBBLESTONE:0,20,SMOOTH_BRICK:0,100)
RandomBlock(-2,15,-6,SMOOTH_BRICK:0,40,SMOOTH_BRICK:1,30,SMOOTH_BRICK:2,30,MOSSY_COBBLESTONE:0,30,COBBLESTONE:0,20,SMOOTH_BRICK:0,100)
Block(-2,15,-5,quark:world_stone_pavement:2)
RandomBlock(-2,15,-4,SMOOTH_BRICK:0,40,SMOOTH_BRICK:1,30,SMOOTH_BRICK:2,30,MOSSY_COBBLESTONE:0,30,COBBLESTONE:0,20,SMOOTH_BRICK:0,100)
RandomBlock(-2,15,-3,SMOOTH_BRICK:0,40,SMOOTH_BRICK:1,30,SMOOTH_BRICK:2,30,MOSSY_COBBLESTONE:0,30,COBBLESTONE:0,20,SMOOTH_BRICK:0,100)
Block(-2,15,-2,quark:polished_stone:0)
Block(-2,15,-1,quark:grate:0)
Block(-2,15,0,quark:grate:0)
Block(-2,15,1,quark:polished_stone:0)
Block(-2,15,2,quark:grate:0)
Block(-2,15,3,quark:polished_stone:0)
Block(-2,15,4,quark:world_stone_pavement:2)
Block(-2,15,5,quark:polished_stone:0)
Block(-2,15,6,quark:limestone:1)
Block(-2,15,7,quark:world_stone_pavement:5)
Block(-2,15,8,quark:world_stone_pavement:2)
Block(-2,16,-7,srparasites:parasitetendril:8)
RandomBlock(-2,16,-6,CHEST:4,../../../../Chests/Loot/moderncity_useful_loot.nbt,20,CHEST:4,../../../../Chests/Loot/moderncity_rare_loot.nbt,10,CHEST:4,../../../../Chests/Loot/moderncity_epic_loot.nbt,5,CHEST:4,../../../../Chests/RLCraft/Ruins/industrial.nbt,50,CHEST:4,../../../../Chests/RLCraft/Ruins/nuclear.nbt,100)
Block(-2,16,-5,quark:world_stone_pavement:5)
Block(-2,16,-2,quark:world_stone_pavement:2)
Block(-2,16,1,quark:world_stone_pavement:5)
Block(-2,16,3,quark:polished_stone:0)
Block(-2,16,4,quark:polished_stone:0)
Block(-2,16,5,quark:world_stone_pavement:2)
Block(-2,16,6,quark:world_stone_pavement:2)
Block(-2,16,7,quark:world_stone_pavement:5)
Block(-2,16,8,quark:polished_stone:0)
Block(-2,17,-7,srparasites:parasitetendril:8)
Block(-2,17,-5,quark:limestone:1)
Block(-2,17,-2,quark:world_stone_pavement:2)
Block(-2,17,1,quark:world_stone_pavement:2)
Block(-2,17,3,quark:world_stone_pavement:2)
Block(-2,17,4,quark:world_stone_pavement:5)
Block(-2,17,5,quark:world_stone_pavement:5)
Block(-2,17,6,quark:world_stone_pavement:2)
Block(-2,17,7,quark:world_stone_pavement:2)
Block(-2,17,8,quark:polished_stone:0)
Block(-2,18,-7,srparasites:parasitetendril:8)
Block(-2,18,-5,quark:limestone:1)
Block(-2,18,-2,quark:limestone:1)
Block(-2,18,1,quark:world_stone_pavement:2)
Block(-2,18,3,quark:limestone:1)
Block(-2,18,4,quark:limestone:1)
Block(-2,18,5,quark:world_stone_pavement:2)
Block(-2,18,6,quark:limestone:1)
Block(-2,18,7,quark:world_stone_pavement:5)
Block(-2,18,8,quark:polished_stone:0)
Block(-2,19,-5,quark:polished_stone:0)
Block(-2,19,-2,quark:world_stone_pavement:2)
Block(-2,19,1,quark:limestone:1)
Block(-2,19,2,quark:iron_plate:1)
Block(-2,19,3,STEP:0)
Block(-2,19,4,STEP:0)
Block(-2,19,5,STEP:0)
Block(-2,19,6,STEP:0)
Block(-2,19,7,STEP:0)
Block(-2,19,8,STEP:0)
Block(-2,20,-7,srparasites:parasitethin:0)
Block(-2,20,-5,quark:polished_stone:0)
Block(-2,20,-2,quark:world_stone_pavement:2)
Block(-2,20,1,quark:polished_stone:0)
Block(-2,20,2,quark:iron_plate:1)
Block(-2,21,-7,DOUBLE_STEP:0)
Block(-2,21,-6,DOUBLE_STEP:0)
Block(-2,21,-5,quark:polished_stone:0)
Block(-2,21,-4,quark:polished_stone:0)
Block(-2,21,-3,quark:polished_stone:0)
Block(-2,21,-2,quark:polished_stone:0)
Block(-2,21,-1,quark:polished_stone:0)
Block(-2,21,0,DOUBLE_STEP:0)
Block(-2,21,1,STEP:0)
Block(-2,21,2,STEP:0)
Block(-1,0,-7,quark:limestone:1)
Block(-1,0,-6,quark:world_stone_pavement:5)
Block(-1,0,-5,quark:world_stone_pavement:2)
Block(-1,0,-4,quark:limestone:1)
Block(-1,0,-3,quark:world_stone_pavement:2)
Block(-1,0,-2,quark:limestone:1)
Block(-1,0,-1,quark:world_stone_pavement:2)
Block(-1,0,0,quark:world_stone_pavement:5)
Block(-1,0,1,quark:world_stone_pavement:2)
Block(-1,0,2,quark:world_stone_pavement:5)
Block(-1,0,3,quark:limestone:1)
Block(-1,0,4,quark:world_stone_pavement:5)
Block(-1,0,5,quark:world_stone_pavement:5)
Block(-1,0,6,quark:world_stone_pavement:5)
Block(-1,0,7,quark:world_stone_pavement:2)
Block(-1,0,8,quark:limestone:1)
Block(-1,1,-7,quark:world_stone_pavement:5)
Block(-1,1,-6,quark:world_stone_pavement:2)
Block(-1,1,-5,quark:limestone:1)
Block(-1,1,-4,quark:limestone:1)
Block(-1,1,-3,quark:world_stone_pavement:5)
Block(-1,1,-2,quark:limestone:1)
Block(-1,1,-1,quark:world_stone_pavement:2)
Block(-1,1,0,quark:world_stone_pavement:2)
Block(-1,1,1,quark:world_stone_pavement:5)
Block(-1,1,2,quark:limestone:1)
Block(-1,1,3,quark:limestone:1)
Block(-1,1,4,quark:world_stone_pavement:5)
Block(-1,1,5,quark:limestone:1)
Block(-1,1,6,quark:world_stone_pavement:5)
Block(-1,1,7,quark:world_stone_pavement:2)
Block(-1,1,8,quark:limestone:1)
Block(-1,2,-7,quark:world_stone_pavement:5)
Block(-1,2,-6,quark:limestone:1)
Block(-1,2,-5,quark:limestone:1)
Block(-1,2,-4,quark:world_stone_pavement:5)
Block(-1,2,-3,quark:limestone:1)
Block(-1,2,-2,quark:limestone:1)
Block(-1,2,-1,quark:world_stone_pavement:5)
Block(-1,2,0,quark:world_stone_pavement:5)
Block(-1,2,1,quark:world_stone_pavement:5)
Block(-1,2,2,quark:world_stone_pavement:5)
Block(-1,2,3,quark:world_stone_pavement:2)
Block(-1,2,4,quark:world_stone_pavement:5)
Block(-1,2,5,quark:world_stone_pavement:2)
Block(-1,2,6,quark:world_stone_pavement:5)
Block(-1,2,7,quark:world_stone_pavement:2)
Block(-1,2,8,quark:limestone:1)
Block(-1,3,-7,quark:limestone:1)
Block(-1,3,-6,quark:world_stone_pavement:5)
Block(-1,3,-5,quark:limestone:1)
Block(-1,3,-4,quark:world_stone_pavement:2)
Block(-1,3,-3,quark:limestone:1)
Block(-1,3,-2,quark:world_stone_pavement:5)
Block(-1,3,-1,quark:world_stone_pavement:5)
Block(-1,3,0,quark:world_stone_pavement:2)
Block(-1,3,1,quark:world_stone_pavement:2)
Block(-1,3,2,quark:world_stone_pavement:2)
Block(-1,3,3,quark:limestone:1)
Block(-1,3,4,quark:world_stone_pavement:5)
Block(-1,3,5,quark:world_stone_pavement:2)
Block(-1,3,6,quark:world_stone_pavement:2)
Block(-1,3,7,quark:world_stone_pavement:2)
Block(-1,3,8,quark:limestone:1)
Block(-1,4,-7,quark:limestone:1)
Block(-1,4,-6,quark:world_stone_pavement:5)
Block(-1,4,-5,quark:world_stone_pavement:5)
Block(-1,4,-4,quark:limestone:1)
Block(-1,4,-3,quark:world_stone_pavement:5)
Block(-1,4,-2,quark:world_stone_pavement:5)
Block(-1,4,-1,quark:world_stone_pavement:2)
Block(-1,4,0,quark:limestone:1)
Block(-1,4,1,quark:world_stone_pavement:2)
Block(-1,4,2,quark:limestone:1)
Block(-1,4,3,quark:world_stone_pavement:5)
Block(-1,4,4,quark:limestone:1)
Block(-1,4,5,quark:world_stone_pavement:5)
Block(-1,4,6,quark:world_stone_pavement:2)
Block(-1,4,7,quark:world_stone_pavement:2)
Block(-1,4,8,quark:world_stone_pavement:2)
Block(-1,5,-7,quark:limestone:1)
Block(-1,5,-6,quark:limestone:1)
Block(-1,5,-5,quark:world_stone_pavement:5)
Block(-1,5,-4,quark:world_stone_pavement:2)
Block(-1,5,-3,quark:world_stone_pavement:2)
Block(-1,5,-2,quark:limestone:1)
Block(-1,5,-1,quark:world_stone_pavement:5)
Block(-1,5,0,quark:limestone:1)
Block(-1,5,1,quark:limestone:1)
Block(-1,5,2,quark:world_stone_pavement:5)
Block(-1,5,3,quark:world_stone_pavement:5)
Block(-1,5,4,quark:limestone:1)
Block(-1,5,5,quark:limestone:1)
Block(-1,5,6,quark:world_stone_pavement:2)
Block(-1,5,7,quark:world_stone_pavement:2)
Block(-1,5,8,quark:limestone:1)
Block(-1,6,-7,quark:world_stone_pavement:2)
Block(-1,6,-6,quark:limestone:1)
Block(-1,6,-5,quark:world_stone_pavement:2)
Block(-1,6,-4,quark:world_stone_pavement:2)
Block(-1,6,-3,quark:world_stone_pavement:2)
Block(-1,6,-2,quark:world_stone_pavement:5)
Block(-1,6,-1,quark:world_stone_pavement:2)
Block(-1,6,0,quark:world_stone_pavement:5)
Block(-1,6,1,quark:world_stone_pavement:5)
Block(-1,6,2,quark:world_stone_pavement:2)
Block(-1,6,3,quark:limestone:1)
Block(-1,6,4,quark:limestone:1)
Block(-1,6,5,quark:world_stone_pavement:5)
Block(-1,6,6,quark:world_stone_pavement:2)
Block(-1,6,7,quark:world_stone_pavement:2)
Block(-1,6,8,quark:world_stone_pavement:2)
Block(-1,7,-7,quark:limestone:1)
Block(-1,7,-6,quark:world_stone_pavement:2)
Block(-1,7,-5,quark:limestone:1)
Block(-1,7,-4,quark:world_stone_pavement:5)
Block(-1,7,-3,quark:world_stone_pavement:2)
Block(-1,7,-2,quark:limestone:1)
Block(-1,7,-1,quark:world_stone_pavement:2)
Block(-1,7,0,quark:limestone:1)
Block(-1,7,1,quark:world_stone_pavement:5)
Block(-1,7,2,quark:world_stone_pavement:2)
Block(-1,7,3,quark:world_stone_pavement:2)
Block(-1,7,4,quark:limestone:1)
Block(-1,7,5,quark:limestone:1)
Block(-1,7,6,quark:world_stone_pavement:2)
Block(-1,7,7,quark:polished_stone:0)
Block(-1,7,8,quark:world_stone_pavement:2)
Block(-1,8,-7,quark:world_stone_pavement:5)
Block(-1,8,-6,quark:limestone:1)
Block(-1,8,-5,quark:limestone:1)
Block(-1,8,-4,quark:world_stone_pavement:2)
Block(-1,8,-3,quark:polished_stone:0)
Block(-1,8,-2,quark:polished_stone:0)
Block(-1,8,-1,quark:world_stone_pavement:5)
Block(-1,8,0,quark:limestone:1)
Block(-1,8,1,quark:world_stone_pavement:2)
Block(-1,8,2,quark:world_stone_pavement:5)
Block(-1,8,3,quark:world_stone_pavement:5)
Block(-1,8,4,quark:world_stone_pavement:5)
Block(-1,8,5,quark:world_stone_pavement:5)
Block(-1,8,6,quark:polished_stone:0)
Block(-1,8,7,quark:polished_stone:0)
Block(-1,8,8,quark:polished_stone:0)
Block(-1,9,-7,quark:polished_stone:0)
Block(-1,9,-6,quark:polished_stone:0)
Block(-1,9,-5,quark:polished_stone:0)
Block(-1,9,-4,quark:world_stone_pavement:2)
Block(-1,9,-3,quark:polished_stone:0)
Block(-1,9,-2,quark:polished_stone:0)
Block(-1,9,-1,quark:world_stone_pavement:2)
Block(-1,9,0,quark:world_stone_pavement:2)
Block(-1,9,1,quark:world_stone_pavement:2)
Block(-1,9,2,quark:polished_stone:0)
Block(-1,9,3,quark:polished_stone:0)
Block(-1,9,4,quark:polished_stone:0)
Block(-1,9,5,quark:polished_stone:0)
Block(-1,9,6,quark:polished_stone:0)
Block(-1,9,7,quark:polished_stone:0)
Block(-1,9,8,quark:world_stone_pavement:2)
Block(-1,10,-7,quark:world_stone_pavement:2)
Block(-1,10,-6,quark:world_stone_pavement:2)
Block(-1,10,-5,quark:polished_stone:0)
Block(-1,10,-4,quark:polished_stone:0)
Block(-1,10,-3,quark:polished_stone:0)
Block(-1,10,-2,quark:polished_stone:0)
Block(-1,10,-1,quark:polished_stone:0)
Block(-1,10,0,quark:polished_stone:0)
Block(-1,10,1,quark:polished_stone:0)
Block(-1,10,2,quark:world_stone_pavement:2)
Block(-1,10,3,quark:polished_stone:0)
Block(-1,10,4,quark:polished_stone:0)
Block(-1,10,5,quark:polished_stone:0)
Block(-1,10,6,quark:world_stone_pavement:2)
Block(-1,10,7,quark:polished_stone:0)
Block(-1,10,8,quark:polished_stone:0)
Block(-1,11,-7,quark:world_stone_pavement:2)
Block(-1,11,-6,quark:polished_stone:0)
Block(-1,11,-5,quark:polished_stone:0)
Block(-1,11,-4,quark:world_stone_pavement:2)
Block(-1,11,-3,quark:polished_stone:0)
Block(-1,11,-2,quark:polished_stone:0)
Block(-1,11,-1,quark:polished_stone:0)
Block(-1,11,0,quark:world_stone_pavement:2)
Block(-1,11,1,quark:polished_stone:0)
Block(-1,11,2,quark:polished_stone:0)
Block(-1,11,3,quark:polished_stone:0)
Block(-1,11,4,MOB_SPAWNER:0,../../ruins_spawners/brutal_multi.nbt)
Block(-1,11,5,MOB_SPAWNER:0,../../ruins_spawners/brutal_multi.nbt)
Block(-1,11,6,quark:polished_stone:0)
Block(-1,11,7,quark:limestone:1)
Block(-1,11,8,quark:world_stone_pavement:2)
Block(-1,12,-7,DOUBLE_STEP:0)
Block(-1,12,-6,DOUBLE_STEP:0)
Block(-1,12,-5,DOUBLE_STEP:0)
Block(-1,12,-4,DOUBLE_STEP:0)
Block(-1,12,-3,DOUBLE_STEP:0)
Block(-1,12,-2,DOUBLE_STEP:0)
Block(-1,12,-1,DOUBLE_STEP:0)
Block(-1,12,0,DOUBLE_STEP:0)
Block(-1,12,1,DOUBLE_STEP:0)
Block(-1,12,2,DOUBLE_STEP:0)
Block(-1,12,3,DOUBLE_STEP:0)
Block(-1,12,4,quark:world_stone_pavement:2)
Block(-1,12,5,quark:world_stone_pavement:2)
Block(-1,12,6,quark:limestone:1)
Block(-1,12,7,quark:limestone:1)
Block(-1,12,8,DOUBLE_STEP:0)
Block(-1,13,-7,quark:iron_plate:1)
Block(-1,13,-6,quark:iron_plate:1)
Block(-1,13,-5,quark:iron_plate:1)
Block(-1,13,-4,quark:iron_plate:1)
Block(-1,13,-3,quark:iron_plate:1)
Block(-1,13,-2,quark:iron_plate:1)
Block(-1,13,-1,quark:iron_plate:1)
Block(-1,13,0,quark:iron_plate:1)
Block(-1,13,1,quark:iron_plate:1)
Block(-1,13,2,quark:iron_plate:1)
Block(-1,13,3,quark:polished_stone:0)
Block(-1,13,4,quark:polished_stone:0)
Block(-1,13,5,quark:world_stone_pavement:2)
Block(-1,13,6,quark:world_stone_pavement:2)
Block(-1,13,7,quark:polished_stone:0)
Block(-1,13,8,quark:polished_stone:0)
Block(-1,14,-7,quark:iron_plate:1)
Block(-1,14,-6,quark:iron_plate:1)
Block(-1,14,-5,quark:iron_plate:1)
Block(-1,14,-4,quark:iron_plate:1)
Block(-1,14,-3,quark:iron_plate:1)
Block(-1,14,-2,quark:iron_plate:1)
Block(-1,14,-1,quark:iron_plate:1)
Block(-1,14,0,quark:iron_plate:1)
Block(-1,14,1,quark:iron_plate:1)
Block(-1,14,2,quark:iron_plate:1)
Block(-1,14,3,quark:polished_stone:0)
Block(-1,14,4,quark:polished_stone:0)
Block(-1,14,5,quark:polished_stone:0)
Block(-1,14,6,quark:limestone:1)
Block(-1,14,7,quark:polished_stone:0)
Block(-1,14,8,quark:polished_stone:0)
Block(-1,15,-7,quark:iron_plate:1)
Block(-1,15,-6,quark:iron_plate:1)
Block(-1,15,-5,quark:iron_plate:1)
Block(-1,15,-4,quark:iron_plate:1)
Block(-1,15,-3,quark:iron_plate:1)
Block(-1,15,-2,quark:iron_plate:1)
Block(-1,15,-1,quark:iron_plate:1)
Block(-1,15,0,quark:iron_plate:1)
Block(-1,15,1,quark:iron_plate:1)
Block(-1,15,2,quark:iron_plate:1)
Block(-1,15,3,quark:world_stone_pavement:2)
Block(-1,15,4,quark:polished_stone:0)
Block(-1,15,5,quark:polished_stone:0)
Block(-1,15,6,quark:world_stone_pavement:2)
Block(-1,15,7,quark:polished_stone:0)
Block(-1,15,8,quark:world_stone_pavement:2)
Block(-1,16,-7,quark:iron_plate:1)
Block(-1,16,-6,quark:iron_plate:1)
Block(-1,16,-5,quark:iron_plate:1)
Block(-1,16,-4,quark:iron_plate:1)
Block(-1,16,-3,quark:iron_plate:1)
Block(-1,16,-2,quark:iron_plate:1)
Block(-1,16,-1,quark:iron_plate:1)
Block(-1,16,0,quark:iron_plate:1)
Block(-1,16,1,quark:iron_plate:1)
Block(-1,16,2,quark:iron_plate:1)
Block(-1,16,3,quark:world_stone_pavement:2)
Block(-1,16,4,quark:world_stone_pavement:2)
Block(-1,16,5,quark:world_stone_pavement:2)
Block(-1,16,6,quark:limestone:1)
Block(-1,16,7,quark:polished_stone:0)
Block(-1,16,8,quark:world_stone_pavement:2)
Block(-1,17,-7,quark:iron_plate:1)
Block(-1,17,-6,quark:iron_plate:1)
Block(-1,17,-5,quark:iron_plate:1)
Block(-1,17,-4,quark:iron_plate:1)
Block(-1,17,-3,quark:iron_plate:1)
Block(-1,17,-2,quark:iron_plate:1)
Block(-1,17,-1,quark:iron_plate:1)
Block(-1,17,0,quark:iron_plate:1)
Block(-1,17,1,quark:iron_plate:1)
Block(-1,17,2,quark:iron_plate:1)
Block(-1,17,3,quark:world_stone_pavement:5)
Block(-1,17,4,quark:limestone:1)
Block(-1,17,5,quark:world_stone_pavement:2)
Block(-1,17,6,quark:world_stone_pavement:5)
Block(-1,17,7,quark:world_stone_pavement:2)
Block(-1,17,8,quark:polished_stone:0)
Block(-1,18,-7,quark:iron_plate:1)
Block(-1,18,-6,quark:iron_plate:1)
Block(-1,18,-5,quark:iron_plate:1)
Block(-1,18,-4,quark:iron_plate:1)
Block(-1,18,-3,quark:iron_plate:1)
Block(-1,18,-2,quark:iron_plate:1)
Block(-1,18,-1,quark:iron_plate:1)
Block(-1,18,0,quark:iron_plate:1)
Block(-1,18,1,quark:iron_plate:1)
Block(-1,18,2,quark:iron_plate:1)
Block(-1,18,3,quark:world_stone_pavement:5)
Block(-1,18,4,quark:world_stone_pavement:2)
Block(-1,18,5,quark:world_stone_pavement:2)
Block(-1,18,6,quark:world_stone_pavement:5)
Block(-1,18,7,quark:world_stone_pavement:2)
Block(-1,18,8,quark:polished_stone:0)
Block(-1,19,-7,quark:iron_plate:1)
Block(-1,19,-6,quark:iron_plate:1)
Block(-1,19,-5,quark:iron_plate:1)
Block(-1,19,-4,quark:iron_plate:1)
Block(-1,19,-3,quark:iron_plate:1)
Block(-1,19,-2,quark:iron_plate:1)
Block(-1,19,-1,quark:iron_plate:1)
Block(-1,19,0,quark:iron_plate:1)
Block(-1,19,1,quark:iron_plate:1)
Block(-1,19,2,quark:iron_plate:1)
Block(-1,19,3,STEP:0)
RandomBlock(-1,19,4,SMOOTH_BRICK:0,40,SMOOTH_BRICK:1,30,SMOOTH_BRICK:2,30,MOSSY_COBBLESTONE:0,30,COBBLESTONE:0,20,SMOOTH_BRICK:0,100)
RandomBlock(-1,19,5,SMOOTH_BRICK:0,40,SMOOTH_BRICK:1,30,SMOOTH_BRICK:2,30,MOSSY_COBBLESTONE:0,30,COBBLESTONE:0,20,SMOOTH_BRICK:0,100)
RandomBlock(-1,19,6,SMOOTH_BRICK:0,40,SMOOTH_BRICK:1,30,SMOOTH_BRICK:2,30,MOSSY_COBBLESTONE:0,30,COBBLESTONE:0,20,SMOOTH_BRICK:0,100)
RandomBlock(-1,19,7,SMOOTH_BRICK:0,40,SMOOTH_BRICK:1,30,SMOOTH_BRICK:2,30,MOSSY_COBBLESTONE:0,30,COBBLESTONE:0,20,SMOOTH_BRICK:0,100)
Block(-1,19,8,STEP:0)
Block(-1,20,-7,quark:iron_plate:1)
Block(-1,20,-6,quark:iron_plate:1)
Block(-1,20,-5,quark:iron_plate:1)
Block(-1,20,-4,quark:iron_plate:1)
Block(-1,20,-3,quark:iron_plate:1)
Block(-1,20,-2,quark:iron_plate:1)
Block(-1,20,-1,quark:iron_plate:1)
Block(-1,20,0,quark:iron_plate:1)
Block(-1,20,1,quark:iron_plate:1)
Block(-1,20,2,quark:iron_plate:1)
Block(-1,21,-7,STEP:0)
Block(-1,21,-6,STEP:0)
Block(-1,21,-5,SMOOTH_STAIRS:1)
Block(-1,21,-4,SMOOTH_STAIRS:1)
Block(-1,21,-3,SMOOTH_STAIRS:1)
Block(-1,21,-2,SMOOTH_STAIRS:1)
Block(-1,21,-1,SMOOTH_STAIRS:1)
Block(-1,21,0,STEP:0)
Block(-1,21,1,STEP:0)
Block(-1,21,2,STEP:0)
RandomBlock(0,0,-7,SMOOTH_BRICK:0,40,SMOOTH_BRICK:1,30,SMOOTH_BRICK:2,30,MOSSY_COBBLESTONE:0,30,COBBLESTONE:0,20,SMOOTH_BRICK:0,100)
RandomBlock(0,0,-6,SMOOTH_BRICK:0,40,SMOOTH_BRICK:1,30,SMOOTH_BRICK:2,30,MOSSY_COBBLESTONE:0,30,COBBLESTONE:0,20,SMOOTH_BRICK:0,100)
RandomBlock(0,0,-5,SMOOTH_BRICK:0,40,SMOOTH_BRICK:1,30,SMOOTH_BRICK:2,30,MOSSY_COBBLESTONE:0,30,COBBLESTONE:0,20,SMOOTH_BRICK:0,100)
RandomBlock(0,0,-4,SMOOTH_BRICK:0,40,SMOOTH_BRICK:1,30,SMOOTH_BRICK:2,30,MOSSY_COBBLESTONE:0,30,COBBLESTONE:0,20,SMOOTH_BRICK:0,100)
RandomBlock(0,0,-3,SMOOTH_BRICK:0,40,SMOOTH_BRICK:1,30,SMOOTH_BRICK:2,30,MOSSY_COBBLESTONE:0,30,COBBLESTONE:0,20,SMOOTH_BRICK:0,100)
RandomBlock(0,0,-2,SMOOTH_BRICK:0,40,SMOOTH_BRICK:1,30,SMOOTH_BRICK:2,30,MOSSY_COBBLESTONE:0,30,COBBLESTONE:0,20,SMOOTH_BRICK:0,100)
RandomBlock(0,0,-1,SMOOTH_BRICK:0,40,SMOOTH_BRICK:1,30,SMOOTH_BRICK:2,30,MOSSY_COBBLESTONE:0,30,COBBLESTONE:0,20,SMOOTH_BRICK:0,100)
RandomBlock(0,0,0,SMOOTH_BRICK:0,40,SMOOTH_BRICK:1,30,SMOOTH_BRICK:2,30,MOSSY_COBBLESTONE:0,30,COBBLESTONE:0,20,SMOOTH_BRICK:0,100)
RandomBlock(0,0,1,SMOOTH_BRICK:0,40,SMOOTH_BRICK:1,30,SMOOTH_BRICK:2,30,MOSSY_COBBLESTONE:0,30,COBBLESTONE:0,20,SMOOTH_BRICK:0,100)
RandomBlock(0,0,2,SMOOTH_BRICK:0,40,SMOOTH_BRICK:1,30,SMOOTH_BRICK:2,30,MOSSY_COBBLESTONE:0,30,COBBLESTONE:0,20,SMOOTH_BRICK:0,100)
Block(0,0,3,quark:limestone:1)
Block(0,0,4,quark:world_stone_pavement:2)
Block(0,0,5,quark:limestone:1)
Block(0,0,6,quark:limestone:1)
Block(0,0,7,quark:world_stone_pavement:2)
Block(0,0,8,quark:world_stone_pavement:2)
RandomBlock(0,1,-7,SMOOTH_BRICK:0,40,SMOOTH_BRICK:1,30,SMOOTH_BRICK:2,30,MOSSY_COBBLESTONE:0,30,COBBLESTONE:0,20,SMOOTH_BRICK:0,100)
RandomBlock(0,1,-6,SMOOTH_BRICK:0,40,SMOOTH_BRICK:1,30,SMOOTH_BRICK:2,30,MOSSY_COBBLESTONE:0,30,COBBLESTONE:0,20,SMOOTH_BRICK:0,100)
RandomBlock(0,1,-5,SMOOTH_BRICK:0,40,SMOOTH_BRICK:1,30,SMOOTH_BRICK:2,30,MOSSY_COBBLESTONE:0,30,COBBLESTONE:0,20,SMOOTH_BRICK:0,100)
RandomBlock(0,1,-4,SMOOTH_BRICK:0,40,SMOOTH_BRICK:1,30,SMOOTH_BRICK:2,30,MOSSY_COBBLESTONE:0,30,COBBLESTONE:0,20,SMOOTH_BRICK:0,100)
RandomBlock(0,1,-3,SMOOTH_BRICK:0,40,SMOOTH_BRICK:1,30,SMOOTH_BRICK:2,30,MOSSY_COBBLESTONE:0,30,COBBLESTONE:0,20,SMOOTH_BRICK:0,100)
RandomBlock(0,1,-2,SMOOTH_BRICK:0,40,SMOOTH_BRICK:1,30,SMOOTH_BRICK:2,30,MOSSY_COBBLESTONE:0,30,COBBLESTONE:0,20,SMOOTH_BRICK:0,100)
RandomBlock(0,1,-1,SMOOTH_BRICK:0,40,SMOOTH_BRICK:1,30,SMOOTH_BRICK:2,30,MOSSY_COBBLESTONE:0,30,COBBLESTONE:0,20,SMOOTH_BRICK:0,100)
RandomBlock(0,1,0,SMOOTH_BRICK:0,40,SMOOTH_BRICK:1,30,SMOOTH_BRICK:2,30,MOSSY_COBBLESTONE:0,30,COBBLESTONE:0,20,SMOOTH_BRICK:0,100)
RandomBlock(0,1,1,SMOOTH_BRICK:0,40,SMOOTH_BRICK:1,30,SMOOTH_BRICK:2,30,MOSSY_COBBLESTONE:0,30,COBBLESTONE:0,20,SMOOTH_BRICK:0,100)
RandomBlock(0,1,2,SMOOTH_BRICK:0,40,SMOOTH_BRICK:1,30,SMOOTH_BRICK:2,30,MOSSY_COBBLESTONE:0,30,COBBLESTONE:0,20,SMOOTH_BRICK:0,100)
Block(0,1,3,quark:world_stone_pavement:2)
Block(0,1,4,quark:world_stone_pavement:2)
Block(0,1,5,quark:world_stone_pavement:5)
Block(0,1,6,quark:world_stone_pavement:2)
Block(0,1,7,quark:world_stone_pavement:2)
Block(0,1,8,quark:world_stone_pavement:2)
RandomBlock(0,2,-7,SMOOTH_BRICK:0,40,SMOOTH_BRICK:1,30,SMOOTH_BRICK:2,30,MOSSY_COBBLESTONE:0,30,COBBLESTONE:0,20,SMOOTH_BRICK:0,100)
RandomBlock(0,2,-6,SMOOTH_BRICK:0,40,SMOOTH_BRICK:1,30,SMOOTH_BRICK:2,30,MOSSY_COBBLESTONE:0,30,COBBLESTONE:0,20,SMOOTH_BRICK:0,100)
RandomBlock(0,2,-5,SMOOTH_BRICK:0,40,SMOOTH_BRICK:1,30,SMOOTH_BRICK:2,30,MOSSY_COBBLESTONE:0,30,COBBLESTONE:0,20,SMOOTH_BRICK:0,100)
RandomBlock(0,2,-4,SMOOTH_BRICK:0,40,SMOOTH_BRICK:1,30,SMOOTH_BRICK:2,30,MOSSY_COBBLESTONE:0,30,COBBLESTONE:0,20,SMOOTH_BRICK:0,100)
RandomBlock(0,2,-3,SMOOTH_BRICK:0,40,SMOOTH_BRICK:1,30,SMOOTH_BRICK:2,30,MOSSY_COBBLESTONE:0,30,COBBLESTONE:0,20,SMOOTH_BRICK:0,100)
RandomBlock(0,2,-2,SMOOTH_BRICK:0,40,SMOOTH_BRICK:1,30,SMOOTH_BRICK:2,30,MOSSY_COBBLESTONE:0,30,COBBLESTONE:0,20,SMOOTH_BRICK:0,100)
RandomBlock(0,2,-1,SMOOTH_BRICK:0,40,SMOOTH_BRICK:1,30,SMOOTH_BRICK:2,30,MOSSY_COBBLESTONE:0,30,COBBLESTONE:0,20,SMOOTH_BRICK:0,100)
RandomBlock(0,2,0,SMOOTH_BRICK:0,40,SMOOTH_BRICK:1,30,SMOOTH_BRICK:2,30,MOSSY_COBBLESTONE:0,30,COBBLESTONE:0,20,SMOOTH_BRICK:0,100)
RandomBlock(0,2,1,SMOOTH_BRICK:0,40,SMOOTH_BRICK:1,30,SMOOTH_BRICK:2,30,MOSSY_COBBLESTONE:0,30,COBBLESTONE:0,20,SMOOTH_BRICK:0,100)
RandomBlock(0,2,2,SMOOTH_BRICK:0,40,SMOOTH_BRICK:1,30,SMOOTH_BRICK:2,30,MOSSY_COBBLESTONE:0,30,COBBLESTONE:0,20,SMOOTH_BRICK:0,100)
Block(0,2,3,quark:world_stone_pavement:5)
Block(0,2,4,quark:world_stone_pavement:2)
Block(0,2,5,quark:limestone:1)
Block(0,2,6,quark:world_stone_pavement:5)
Block(0,2,7,quark:world_stone_pavement:2)
Block(0,2,8,quark:world_stone_pavement:2)
RandomBlock(0,3,-7,SMOOTH_BRICK:0,40,SMOOTH_BRICK:1,30,SMOOTH_BRICK:2,30,MOSSY_COBBLESTONE:0,30,COBBLESTONE:0,20,SMOOTH_BRICK:0,100)
RandomBlock(0,3,-6,SMOOTH_BRICK:0,40,SMOOTH_BRICK:1,30,SMOOTH_BRICK:2,30,MOSSY_COBBLESTONE:0,30,COBBLESTONE:0,20,SMOOTH_BRICK:0,100)
RandomBlock(0,3,-5,SMOOTH_BRICK:0,40,SMOOTH_BRICK:1,30,SMOOTH_BRICK:2,30,MOSSY_COBBLESTONE:0,30,COBBLESTONE:0,20,SMOOTH_BRICK:0,100)
RandomBlock(0,3,-4,SMOOTH_BRICK:0,40,SMOOTH_BRICK:1,30,SMOOTH_BRICK:2,30,MOSSY_COBBLESTONE:0,30,COBBLESTONE:0,20,SMOOTH_BRICK:0,100)
RandomBlock(0,3,-3,SMOOTH_BRICK:0,40,SMOOTH_BRICK:1,30,SMOOTH_BRICK:2,30,MOSSY_COBBLESTONE:0,30,COBBLESTONE:0,20,SMOOTH_BRICK:0,100)
RandomBlock(0,3,-2,SMOOTH_BRICK:0,40,SMOOTH_BRICK:1,30,SMOOTH_BRICK:2,30,MOSSY_COBBLESTONE:0,30,COBBLESTONE:0,20,SMOOTH_BRICK:0,100)
RandomBlock(0,3,-1,SMOOTH_BRICK:0,40,SMOOTH_BRICK:1,30,SMOOTH_BRICK:2,30,MOSSY_COBBLESTONE:0,30,COBBLESTONE:0,20,SMOOTH_BRICK:0,100)
RandomBlock(0,3,0,SMOOTH_BRICK:0,40,SMOOTH_BRICK:1,30,SMOOTH_BRICK:2,30,MOSSY_COBBLESTONE:0,30,COBBLESTONE:0,20,SMOOTH_BRICK:0,100)
RandomBlock(0,3,1,SMOOTH_BRICK:0,40,SMOOTH_BRICK:1,30,SMOOTH_BRICK:2,30,MOSSY_COBBLESTONE:0,30,COBBLESTONE:0,20,SMOOTH_BRICK:0,100)
RandomBlock(0,3,2,SMOOTH_BRICK:0,40,SMOOTH_BRICK:1,30,SMOOTH_BRICK:2,30,MOSSY_COBBLESTONE:0,30,COBBLESTONE:0,20,SMOOTH_BRICK:0,100)
Block(0,3,3,quark:limestone:1)
Block(0,3,4,quark:world_stone_pavement:2)
Block(0,3,5,quark:world_stone_pavement:5)
Block(0,3,6,quark:world_stone_pavement:5)
Block(0,3,7,quark:world_stone_pavement:2)
Block(0,3,8,quark:world_stone_pavement:2)
RandomBlock(0,4,-7,SMOOTH_BRICK:0,40,SMOOTH_BRICK:1,30,SMOOTH_BRICK:2,30,MOSSY_COBBLESTONE:0,30,COBBLESTONE:0,20,SMOOTH_BRICK:0,100)
RandomBlock(0,4,-6,SMOOTH_BRICK:0,40,SMOOTH_BRICK:1,30,SMOOTH_BRICK:2,30,MOSSY_COBBLESTONE:0,30,COBBLESTONE:0,20,SMOOTH_BRICK:0,100)
RandomBlock(0,4,-5,SMOOTH_BRICK:0,40,SMOOTH_BRICK:1,30,SMOOTH_BRICK:2,30,MOSSY_COBBLESTONE:0,30,COBBLESTONE:0,20,SMOOTH_BRICK:0,100)
RandomBlock(0,4,-4,SMOOTH_BRICK:0,40,SMOOTH_BRICK:1,30,SMOOTH_BRICK:2,30,MOSSY_COBBLESTONE:0,30,COBBLESTONE:0,20,SMOOTH_BRICK:0,100)
RandomBlock(0,4,-3,SMOOTH_BRICK:0,40,SMOOTH_BRICK:1,30,SMOOTH_BRICK:2,30,MOSSY_COBBLESTONE:0,30,COBBLESTONE:0,20,SMOOTH_BRICK:0,100)
RandomBlock(0,4,-2,SMOOTH_BRICK:0,40,SMOOTH_BRICK:1,30,SMOOTH_BRICK:2,30,MOSSY_COBBLESTONE:0,30,COBBLESTONE:0,20,SMOOTH_BRICK:0,100)
