
#######################################################################
# +-----------------------------------------------------------------+ #
# |                            BO4 object                           | #
# +-----------------------------------------------------------------+ #
#######################################################################

Author: NLBlackEagle

Description: No description given

SettingsMode: WriteWithoutComments


#######################################################################
# +-----------------------------------------------------------------+ #
# |                          Main settings                          | #
# +-----------------------------------------------------------------+ #
#######################################################################

FixedRotation: 

Frequency: 0

SpawnHeight: highestBlock

UseCenterForHighestBlock: true

##############################
# Height Limits for the BO4. #
##############################

MinHeight: 0

MaxHeight: 255

InheritBO3: 

InheritBO3Rotation: NORTH

OverrideChildSettings: true

OverrideParentHeight: false

CanOverride: true

BranchFrequency: 0

BranchFrequencyGroup: 

MustBeBelowOther: false

MustBeInside: 

CannotBeInside: 

ReplacesBO3: 

MustBeInsideWorldBorders: false

CanSpawnOnWater: true

SpawnOnWaterOnly: false

SpawnUnderWater: false

SpawnAtWaterLevel: false

HeightOffset: 0

RemoveAir: false

ReplaceAbove: 

ReplaceBelow: 

ReplaceWithBiomeBlocks: false

ReplaceWithSurfaceBlock: GRASS

ReplaceWithGroundBlock: DIRT

ReplaceWithStoneBlock: STONE

SmoothRadius: 0

SmoothHeightOffset: 0

SmoothStartTop: false

SmoothStartWood: false

SmoothingSurfaceBlock: 

SmoothingGroundBlock: 

BO3Group: 

IsSpawnPoint: false

DoReplaceBlocks: true


#######################################################################
# +-----------------------------------------------------------------+ #
# |                              Blocks                             | #
# +-----------------------------------------------------------------+ #
#######################################################################

Block(-8,0,-3,contenttweaker:reinforced_concrete:0)
Block(-8,0,-2,quark:world_stone_pavement:2)
Block(-8,0,-1,quark:world_stone_pavement:2)
Block(-8,0,0,contenttweaker:reinforced_concrete:0)
Block(-8,0,1,contenttweaker:reinforced_concrete:0)
Block(-8,0,2,contenttweaker:reinforced_concrete:0)
Block(-8,0,3,contenttweaker:reinforced_concrete:0)
Block(-8,0,4,contenttweaker:reinforced_concrete:0)
Block(-8,0,5,quark:world_stone_pavement:2)
Block(-8,0,6,quark:world_stone_pavement:2)
Block(-8,0,7,contenttweaker:reinforced_concrete:0)
Block(-8,0,8,quark:world_stone_pavement:2)
Block(-8,1,-3,contenttweaker:reinforced_concrete:0)
Block(-8,1,-2,quark:world_stone_pavement:2)
Block(-8,1,-1,contenttweaker:reinforced_concrete:0)
Block(-8,1,0,contenttweaker:reinforced_concrete:0)
Block(-8,1,1,contenttweaker:reinforced_concrete:0)
Block(-8,1,2,contenttweaker:reinforced_concrete:0)
Block(-8,1,3,contenttweaker:reinforced_concrete:0)
Block(-8,1,4,contenttweaker:reinforced_concrete:0)
Block(-8,1,5,quark:world_stone_pavement:2)
Block(-8,1,6,quark:world_stone_pavement:2)
Block(-8,1,7,contenttweaker:reinforced_concrete:0)
Block(-8,1,8,quark:world_stone_pavement:2)
Block(-8,2,-3,quark:world_stone_pavement:2)
Block(-8,2,-2,quark:world_stone_pavement:2)
Block(-8,2,-1,quark:world_stone_pavement:2)
Block(-8,2,0,contenttweaker:reinforced_concrete:0)
Block(-8,2,1,contenttweaker:reinforced_concrete:0)
Block(-8,2,2,quark:world_stone_pavement:2)
Block(-8,2,3,quark:world_stone_pavement:2)
Block(-8,2,4,contenttweaker:reinforced_concrete:0)
Block(-8,2,5,contenttweaker:reinforced_concrete:0)
Block(-8,2,6,quark:world_stone_pavement:2)
Block(-8,2,7,contenttweaker:reinforced_concrete:0)
Block(-8,2,8,quark:world_stone_pavement:2)
Block(-8,3,-3,quark:world_stone_pavement:2)
Block(-8,3,-2,quark:world_stone_pavement:2)
Block(-8,3,-1,quark:world_stone_pavement:2)
Block(-8,3,0,contenttweaker:reinforced_concrete:0)
Block(-8,3,1,contenttweaker:reinforced_concrete:0)
Block(-8,3,2,contenttweaker:reinforced_concrete:0)
Block(-8,3,3,contenttweaker:reinforced_concrete:0)
Block(-8,3,4,quark:world_stone_pavement:2)
Block(-8,3,5,quark:world_stone_pavement:2)
Block(-8,3,6,quark:world_stone_pavement:2)
Block(-8,3,7,contenttweaker:reinforced_concrete:0)
Block(-8,3,8,quark:world_stone_pavement:2)
Block(-8,4,-3,contenttweaker:reinforced_concrete:0)
Block(-8,4,-2,quark:world_stone_pavement:2)
Block(-8,4,-1,contenttweaker:reinforced_concrete:0)
Block(-8,4,0,quark:world_stone_pavement:2)
Block(-8,4,1,quark:world_stone_pavement:2)
Block(-8,4,2,contenttweaker:reinforced_concrete:0)
Block(-8,4,3,contenttweaker:reinforced_concrete:0)
Block(-8,4,4,quark:world_stone_pavement:2)
Block(-8,4,5,contenttweaker:reinforced_concrete:0)
Block(-8,4,6,quark:world_stone_pavement:2)
Block(-8,4,7,quark:world_stone_pavement:2)
Block(-8,4,8,quark:world_stone_pavement:2)
Block(-8,5,-3,quark:world_stone_pavement:2)
Block(-8,5,-2,quark:world_stone_pavement:2)
Block(-8,5,-1,quark:world_stone_pavement:2)
Block(-8,5,0,contenttweaker:reinforced_concrete:0)
Block(-8,5,1,contenttweaker:reinforced_concrete:0)
Block(-8,5,2,contenttweaker:reinforced_concrete:0)
Block(-8,5,3,contenttweaker:reinforced_concrete:0)
Block(-8,5,4,contenttweaker:reinforced_concrete:0)
Block(-8,5,5,quark:world_stone_pavement:2)
Block(-8,5,6,quark:world_stone_pavement:2)
Block(-8,5,7,quark:world_stone_pavement:2)
Block(-8,5,8,quark:world_stone_pavement:2)
Block(-8,6,-3,contenttweaker:reinforced_concrete:0)
Block(-8,6,-2,quark:world_stone_pavement:2)
Block(-8,6,-1,contenttweaker:reinforced_concrete:0)
Block(-8,6,0,contenttweaker:reinforced_concrete:0)
Block(-8,6,1,contenttweaker:reinforced_concrete:0)
Block(-8,6,2,contenttweaker:reinforced_concrete:0)
Block(-8,6,3,contenttweaker:reinforced_concrete:0)
Block(-8,6,4,contenttweaker:reinforced_concrete:0)
Block(-8,6,5,contenttweaker:reinforced_concrete:0)
Block(-8,6,6,quark:world_stone_pavement:2)
Block(-8,6,7,quark:world_stone_pavement:2)
Block(-8,6,8,quark:world_stone_pavement:2)
Block(-8,7,-3,contenttweaker:reinforced_concrete:0)
Block(-8,7,-2,contenttweaker:reinforced_concrete:0)
Block(-8,7,-1,contenttweaker:reinforced_concrete:0)
Block(-8,7,0,contenttweaker:reinforced_concrete:0)
Block(-8,7,1,contenttweaker:reinforced_concrete:0)
Block(-8,7,2,contenttweaker:reinforced_concrete:0)
Block(-8,7,3,quark:world_stone_pavement:2)
Block(-8,7,4,contenttweaker:reinforced_concrete:0)
Block(-8,7,5,contenttweaker:reinforced_concrete:0)
Block(-8,7,6,contenttweaker:reinforced_concrete:0)
Block(-8,7,7,contenttweaker:reinforced_concrete:0)
Block(-8,7,8,contenttweaker:reinforced_concrete:0)
Block(-8,8,-3,contenttweaker:reinforced_concrete:0)
Block(-8,8,-2,contenttweaker:reinforced_concrete:0)
Block(-8,8,-1,contenttweaker:reinforced_concrete:0)
Block(-8,8,0,contenttweaker:reinforced_concrete:0)
Block(-8,8,1,contenttweaker:reinforced_concrete:0)
Block(-8,8,2,contenttweaker:reinforced_concrete:0)
Block(-8,8,3,quark:world_stone_pavement:2)
Block(-8,8,4,contenttweaker:reinforced_concrete:0)
Block(-8,8,5,contenttweaker:reinforced_concrete:0)
Block(-8,8,6,contenttweaker:reinforced_concrete:0)
Block(-8,8,7,contenttweaker:reinforced_concrete:0)
Block(-8,8,8,quark:world_stone_pavement:2)
Block(-8,9,-3,quark:world_stone_pavement:2)
Block(-8,9,-2,quark:polished_stone:0)
Block(-8,9,-1,quark:polished_stone:0)
Block(-8,9,0,quark:world_stone_pavement:2)
Block(-8,9,1,quark:world_stone_pavement:2)
Block(-8,9,2,contenttweaker:reinforced_concrete:0)
Block(-8,9,3,contenttweaker:reinforced_concrete:0)
Block(-8,9,4,contenttweaker:reinforced_concrete:0)
Block(-8,9,5,quark:world_stone_pavement:2)
Block(-8,9,6,contenttweaker:reinforced_concrete:0)
Block(-8,9,7,contenttweaker:reinforced_concrete:0)
Block(-8,9,8,contenttweaker:reinforced_concrete:0)
Block(-8,10,-3,contenttweaker:reinforced_concrete:0)
Block(-8,10,-2,quark:world_stone_pavement:2)
Block(-8,10,-1,quark:polished_stone:0)
Block(-8,10,0,quark:world_stone_pavement:2)
Block(-8,10,1,quark:iron_plate:0)
Block(-8,10,2,contenttweaker:reinforced_concrete:0)
Block(-8,10,3,contenttweaker:reinforced_concrete:0)
Block(-8,10,4,quark:world_stone_pavement:2)
Block(-8,10,5,quark:world_stone_pavement:2)
Block(-8,10,6,contenttweaker:reinforced_concrete:0)
Block(-8,10,7,contenttweaker:reinforced_concrete:0)
Block(-8,10,8,quark:world_stone_pavement:2)
Block(-8,11,-3,quark:world_stone_pavement:2)
Block(-8,11,-2,STEP:0)
Block(-8,12,-3,DOUBLE_STEP:0)
Block(-8,13,-3,DOUBLE_STEP:0)
Block(-8,14,-3,DOUBLE_STEP:0)
Block(-8,15,-3,DOUBLE_STEP:0)
Block(-8,15,-2,quark:grate:0)
Block(-8,15,-1,quark:iron_plate:1)
Block(-8,16,-3,DOUBLE_STEP:0)
RandomBlock(-8,16,-1,rustic:iron_lattice:0,30,rustic:iron_lattice:1,100)
Block(-8,17,-3,DOUBLE_STEP:0)
RandomBlock(-8,17,-1,rustic:iron_lattice:0,30,rustic:iron_lattice:1,100)
Block(-8,18,-3,DOUBLE_STEP:0)
Block(-8,19,-3,quark:iron_plate:1)
Block(-8,20,-3,STEP:0)
RandomBlock(-8,20,-2,contenttweaker:reinforced_concrete:0,40,SMOOTH_BRICK:1,30,SMOOTH_BRICK:2,30,MOSSY_COBBLESTONE:0,30,COBBLESTONE:0,20,contenttweaker:reinforced_concrete:0,100)
Block(-8,21,-2,DOUBLE_STEP:0)
Block(-8,21,-1,quark:iron_plate:1)
Block(-8,21,0,STEP:0)
Block(-8,22,-2,quark:iron_plate:1)
Block(-8,22,-1,STEP:0)
Block(-8,22,0,DOUBLE_STEP:0)
Block(-8,23,-2,DOUBLE_STEP:0)
Block(-8,23,-1,STEP:0)
Block(-8,23,0,DOUBLE_STEP:0)
Block(-8,24,-2,DOUBLE_STEP:0)
Block(-8,24,0,DOUBLE_STEP:0)
Block(-8,25,-2,DOUBLE_STEP:0)
Block(-8,25,-1,STEP:0)
RandomBlock(-8,25,0,contenttweaker:reinforced_concrete:0,40,SMOOTH_BRICK:1,30,SMOOTH_BRICK:2,30,MOSSY_COBBLESTONE:0,30,COBBLESTONE:0,20,contenttweaker:reinforced_concrete:0,100)
Block(-8,26,-2,STEP:0)
Block(-8,26,-1,DOUBLE_STEP:0)
RandomBlock(-8,26,0,contenttweaker:reinforced_concrete:0,40,SMOOTH_BRICK:1,30,SMOOTH_BRICK:2,30,MOSSY_COBBLESTONE:0,30,COBBLESTONE:0,20,contenttweaker:reinforced_concrete:0,100)
Block(-8,27,-1,STEP:0)
Block(-8,27,0,quark:sturdy_stone:0)
Block(-8,28,0,SMOOTH_STAIRS:2)
Block(-8,28,1,STEP:0)
Block(-8,28,2,STEP:0)
Block(-8,28,3,STEP:0)
Block(-8,28,4,STEP:0)
Block(-8,28,5,STEP:0)
Block(-8,28,6,STEP:0)
Block(-8,28,7,STEP:0)
Block(-8,28,8,STEP:0)
Block(-8,29,1,SMOOTH_STAIRS:2)
RandomBlock(-8,29,2,contenttweaker:reinforced_concrete:0,40,SMOOTH_BRICK:1,30,SMOOTH_BRICK:2,30,MOSSY_COBBLESTONE:0,30,COBBLESTONE:0,20,contenttweaker:reinforced_concrete:0,100)
Block(-8,29,3,DOUBLE_STEP:0)
Block(-8,29,4,DOUBLE_STEP:0)
Block(-8,29,5,quark:world_stone_pavement:2)
RandomBlock(-8,29,6,contenttweaker:reinforced_concrete:0,40,SMOOTH_BRICK:1,30,SMOOTH_BRICK:2,30,MOSSY_COBBLESTONE:0,30,COBBLESTONE:0,20,contenttweaker:reinforced_concrete:0,100)
RandomBlock(-8,29,7,contenttweaker:reinforced_concrete:0,40,SMOOTH_BRICK:1,30,SMOOTH_BRICK:2,30,MOSSY_COBBLESTONE:0,30,COBBLESTONE:0,20,contenttweaker:reinforced_concrete:0,100)
RandomBlock(-8,29,8,contenttweaker:reinforced_concrete:0,40,SMOOTH_BRICK:1,30,SMOOTH_BRICK:2,30,MOSSY_COBBLESTONE:0,30,COBBLESTONE:0,20,contenttweaker:reinforced_concrete:0,100)
Block(-8,30,3,DOUBLE_STEP:0)
Block(-8,30,7,quark:iron_plate:1)
Block(-8,30,8,STEP:0)
Block(-8,31,7,quark:iron_plate:1)
Block(-7,0,-7,quark:iron_plate:1)
Block(-7,0,-5,quark:iron_plate:1)
Block(-7,0,-3,quark:world_stone_pavement:2)
Block(-7,0,-2,contenttweaker:reinforced_concrete:0)
Block(-7,0,-1,quark:world_stone_pavement:2)
Block(-7,0,0,quark:world_stone_pavement:2)
Block(-7,0,1,quark:world_stone_pavement:2)
Block(-7,0,2,quark:world_stone_pavement:2)
Block(-7,0,3,quark:world_stone_pavement:2)
Block(-7,0,4,quark:world_stone_pavement:2)
Block(-7,0,5,quark:world_stone_pavement:2)
Block(-7,0,6,quark:world_stone_pavement:2)
Block(-7,0,7,quark:world_stone_pavement:2)
Block(-7,0,8,quark:world_stone_pavement:2)
Block(-7,1,-7,quark:iron_plate:1)
Block(-7,1,-5,quark:iron_plate:1)
Block(-7,1,-3,quark:world_stone_pavement:2)
Block(-7,1,-2,contenttweaker:reinforced_concrete:0)
Block(-7,1,-1,quark:world_stone_pavement:2)
Block(-7,1,0,quark:world_stone_pavement:2)
Block(-7,1,1,quark:world_stone_pavement:2)
Block(-7,1,2,quark:world_stone_pavement:2)
Block(-7,1,3,quark:world_stone_pavement:2)
Block(-7,1,4,contenttweaker:reinforced_concrete:0)
Block(-7,1,5,contenttweaker:reinforced_concrete:0)
Block(-7,1,6,quark:world_stone_pavement:2)
Block(-7,1,7,contenttweaker:reinforced_concrete:0)
Block(-7,1,8,quark:world_stone_pavement:2)
Block(-7,2,-7,quark:iron_plate:1)
Block(-7,2,-5,quark:iron_plate:1)
Block(-7,2,-3,quark:world_stone_pavement:2)
Block(-7,2,-2,quark:world_stone_pavement:2)
Block(-7,2,-1,quark:world_stone_pavement:2)
Block(-7,2,0,quark:world_stone_pavement:2)
Block(-7,2,1,quark:world_stone_pavement:2)
Block(-7,2,2,quark:world_stone_pavement:2)
Block(-7,2,3,quark:world_stone_pavement:2)
Block(-7,2,4,contenttweaker:reinforced_concrete:0)
Block(-7,2,5,contenttweaker:reinforced_concrete:0)
Block(-7,2,6,quark:world_stone_pavement:2)
Block(-7,2,7,contenttweaker:reinforced_concrete:0)
Block(-7,2,8,quark:world_stone_pavement:2)
Block(-7,3,-7,quark:iron_plate:1)
Block(-7,3,-5,quark:iron_plate:1)
Block(-7,3,-3,quark:world_stone_pavement:2)
Block(-7,3,-2,contenttweaker:reinforced_concrete:0)
Block(-7,3,-1,quark:world_stone_pavement:2)
Block(-7,3,0,quark:world_stone_pavement:2)
Block(-7,3,1,quark:world_stone_pavement:2)
Block(-7,3,2,quark:world_stone_pavement:2)
Block(-7,3,3,quark:world_stone_pavement:2)
Block(-7,3,4,contenttweaker:reinforced_concrete:0)
Block(-7,3,5,contenttweaker:reinforced_concrete:0)
Block(-7,3,6,quark:world_stone_pavement:2)
Block(-7,3,7,contenttweaker:reinforced_concrete:0)
Block(-7,3,8,quark:world_stone_pavement:2)
Block(-7,4,-7,quark:iron_plate:1)
Block(-7,4,-5,quark:iron_plate:1)
Block(-7,4,-3,quark:world_stone_pavement:2)
Block(-7,4,-2,contenttweaker:reinforced_concrete:0)
Block(-7,4,-1,quark:world_stone_pavement:2)
Block(-7,4,0,quark:world_stone_pavement:2)
Block(-7,4,1,quark:world_stone_pavement:2)
Block(-7,4,2,quark:world_stone_pavement:2)
Block(-7,4,3,quark:world_stone_pavement:2)
Block(-7,4,4,quark:world_stone_pavement:2)
Block(-7,4,5,contenttweaker:reinforced_concrete:0)
Block(-7,4,6,quark:world_stone_pavement:2)
Block(-7,4,7,contenttweaker:reinforced_concrete:0)
Block(-7,4,8,quark:world_stone_pavement:2)
Block(-7,5,-7,quark:iron_plate:1)
Block(-7,5,-5,quark:iron_plate:1)
Block(-7,5,-3,quark:world_stone_pavement:2)
Block(-7,5,-2,quark:world_stone_pavement:2)
Block(-7,5,-1,quark:world_stone_pavement:2)
Block(-7,5,0,quark:world_stone_pavement:2)
Block(-7,5,1,quark:world_stone_pavement:2)
Block(-7,5,2,quark:world_stone_pavement:2)
Block(-7,5,3,quark:world_stone_pavement:2)
Block(-7,5,4,contenttweaker:reinforced_concrete:0)
Block(-7,5,5,contenttweaker:reinforced_concrete:0)
Block(-7,5,6,quark:world_stone_pavement:2)
Block(-7,5,7,quark:world_stone_pavement:2)
Block(-7,5,8,quark:world_stone_pavement:2)
Block(-7,6,-7,quark:iron_plate:1)
Block(-7,6,-5,quark:iron_plate:1)
Block(-7,6,-3,quark:world_stone_pavement:2)
Block(-7,6,-2,contenttweaker:reinforced_concrete:0)
Block(-7,6,-1,quark:world_stone_pavement:2)
Block(-7,6,0,quark:world_stone_pavement:2)
Block(-7,6,1,quark:world_stone_pavement:2)
Block(-7,6,2,quark:world_stone_pavement:2)
Block(-7,6,3,quark:world_stone_pavement:2)
Block(-7,6,4,contenttweaker:reinforced_concrete:0)
Block(-7,6,5,contenttweaker:reinforced_concrete:0)
Block(-7,6,6,quark:world_stone_pavement:2)
Block(-7,6,7,contenttweaker:reinforced_concrete:0)
Block(-7,6,8,quark:world_stone_pavement:2)
Block(-7,7,-7,quark:iron_plate:1)
Block(-7,7,-5,quark:iron_plate:1)
Block(-7,7,-3,contenttweaker:reinforced_concrete:0)
Block(-7,7,-2,quark:world_stone_pavement:2)
Block(-7,7,-1,contenttweaker:reinforced_concrete:0)
Block(-7,7,0,contenttweaker:reinforced_concrete:0)
Block(-7,7,1,contenttweaker:reinforced_concrete:0)
Block(-7,7,2,contenttweaker:reinforced_concrete:0)
Block(-7,7,3,quark:world_stone_pavement:2)
Block(-7,7,4,contenttweaker:reinforced_concrete:0)
Block(-7,7,5,contenttweaker:reinforced_concrete:0)
Block(-7,7,6,contenttweaker:reinforced_concrete:0)
Block(-7,7,7,contenttweaker:reinforced_concrete:0)
Block(-7,7,8,contenttweaker:reinforced_concrete:0)
Block(-7,8,-7,quark:iron_plate:1)
Block(-7,8,-5,quark:iron_plate:1)
Block(-7,8,-3,contenttweaker:reinforced_concrete:0)
Block(-7,8,-2,contenttweaker:reinforced_concrete:0)
Block(-7,8,-1,contenttweaker:reinforced_concrete:0)
Block(-7,8,0,contenttweaker:reinforced_concrete:0)
Block(-7,8,1,contenttweaker:reinforced_concrete:0)
Block(-7,8,2,quark:world_stone_pavement:2)
Block(-7,8,3,contenttweaker:reinforced_concrete:0)
Block(-7,8,4,contenttweaker:reinforced_concrete:0)
Block(-7,8,5,quark:world_stone_pavement:2)
Block(-7,8,6,contenttweaker:reinforced_concrete:0)
Block(-7,8,7,contenttweaker:reinforced_concrete:0)
Block(-7,8,8,contenttweaker:reinforced_concrete:0)
Block(-7,9,-7,quark:iron_plate:1)
Block(-7,9,-5,quark:iron_plate:1)
Block(-7,9,-3,quark:world_stone_pavement:2)
Block(-7,9,-2,quark:world_stone_pavement:2)
Block(-7,9,-1,quark:polished_stone:0)
Block(-7,9,0,quark:world_stone_pavement:2)
Block(-7,9,1,quark:world_stone_pavement:2)
Block(-7,9,2,contenttweaker:reinforced_concrete:0)
Block(-7,9,3,quark:world_stone_pavement:2)
Block(-7,9,4,quark:world_stone_pavement:2)
Block(-7,9,5,MOB_SPAWNER:0,../../ruins_spawners/brutal_multi.nbt)
Block(-7,9,6,contenttweaker:reinforced_concrete:0)
Block(-7,9,7,contenttweaker:reinforced_concrete:0)
Block(-7,9,8,contenttweaker:reinforced_concrete:0)
Block(-7,10,-7,quark:iron_plate:1)
Block(-7,10,-5,quark:iron_plate:1)
Block(-7,10,-3,quark:world_stone_pavement:2)
Block(-7,10,-2,quark:world_stone_pavement:2)
Block(-7,10,-1,quark:polished_stone:0)
Block(-7,10,0,quark:world_stone_pavement:2)
Block(-7,10,1,quark:iron_plate:0)
Block(-7,10,2,quark:world_stone_pavement:2)
Block(-7,10,3,quark:world_stone_pavement:2)
Block(-7,10,4,quark:world_stone_pavement:2)
Block(-7,10,5,quark:world_stone_pavement:2)
Block(-7,10,6,contenttweaker:reinforced_concrete:0)
Block(-7,10,7,contenttweaker:reinforced_concrete:0)
Block(-7,10,8,contenttweaker:reinforced_concrete:0)
Block(-7,11,-7,quark:iron_plate_stairs:0)
Block(-7,11,-5,quark:iron_plate_stairs:0)
Block(-7,11,-3,quark:world_stone_pavement:2)
Block(-7,11,-2,quark:iron_plate:0)
Block(-7,12,-3,contenttweaker:reinforced_concrete:0)
Block(-7,12,-2,quark:iron_plate:0)
RandomBlock(-7,13,-3,contenttweaker:reinforced_concrete:0,40,SMOOTH_BRICK:1,30,SMOOTH_BRICK:2,30,MOSSY_COBBLESTONE:0,30,COBBLESTONE:0,20,contenttweaker:reinforced_concrete:0,100)
Block(-7,13,-2,SMOOTH_STAIRS:0)
RandomBlock(-7,14,-3,contenttweaker:reinforced_concrete:0,40,SMOOTH_BRICK:1,30,SMOOTH_BRICK:2,30,MOSSY_COBBLESTONE:0,30,COBBLESTONE:0,20,contenttweaker:reinforced_concrete:0,100)
RandomBlock(-7,15,-3,contenttweaker:reinforced_concrete:0,40,SMOOTH_BRICK:1,30,SMOOTH_BRICK:2,30,MOSSY_COBBLESTONE:0,30,COBBLESTONE:0,20,contenttweaker:reinforced_concrete:0,100)
Block(-7,15,-2,quark:grate:0)
Block(-7,15,-1,quark:iron_plate:1)
RandomBlock(-7,16,-3,contenttweaker:reinforced_concrete:0,40,SMOOTH_BRICK:1,30,SMOOTH_BRICK:2,30,MOSSY_COBBLESTONE:0,30,COBBLESTONE:0,20,contenttweaker:reinforced_concrete:0,100)
Block(-7,16,-2,LEVER:4)
RandomBlock(-7,16,-1,contenttweaker:reinforced_concrete:0,40,SMOOTH_BRICK:1,30,SMOOTH_BRICK:2,30,MOSSY_COBBLESTONE:0,30,COBBLESTONE:0,20,contenttweaker:reinforced_concrete:0,100)
RandomBlock(-7,17,-3,contenttweaker:reinforced_concrete:0,40,SMOOTH_BRICK:1,30,SMOOTH_BRICK:2,30,MOSSY_COBBLESTONE:0,30,COBBLESTONE:0,20,contenttweaker:reinforced_concrete:0,100)
Block(-7,17,-1,nuclearcraft:radiation_scrubber:0)
RandomBlock(-7,18,-3,contenttweaker:reinforced_concrete:0,40,SMOOTH_BRICK:1,30,SMOOTH_BRICK:2,30,MOSSY_COBBLESTONE:0,30,COBBLESTONE:0,20,contenttweaker:reinforced_concrete:0,100)
Block(-7,19,-3,quark:iron_plate:1)
Block(-7,20,-3,STEP:0)
RandomBlock(-7,20,-2,contenttweaker:reinforced_concrete:0,40,SMOOTH_BRICK:1,30,SMOOTH_BRICK:2,30,MOSSY_COBBLESTONE:0,30,COBBLESTONE:0,20,contenttweaker:reinforced_concrete:0,100)
Block(-7,21,-2,STEP:0)
Block(-7,21,-1,quark:iron_plate:1)
Block(-7,21,0,STEP:0)
RandomBlock(-7,22,0,contenttweaker:reinforced_concrete:0,40,SMOOTH_BRICK:1,30,SMOOTH_BRICK:2,30,MOSSY_COBBLESTONE:0,30,COBBLESTONE:0,20,contenttweaker:reinforced_concrete:0,100)
Block(-7,23,0,quark:framed_glass:0)
Block(-7,24,0,quark:framed_glass:0)
Block(-7,25,0,DOUBLE_STEP:0)
RandomBlock(-7,26,0,contenttweaker:reinforced_concrete:0,40,SMOOTH_BRICK:1,30,SMOOTH_BRICK:2,30,MOSSY_COBBLESTONE:0,30,COBBLESTONE:0,20,contenttweaker:reinforced_concrete:0,100)
Block(-7,27,0,quark:sturdy_stone:0)
Block(-7,28,0,SMOOTH_STAIRS:2)
Block(-7,28,1,STEP:0)
Block(-7,28,3,STEP:0)
Block(-7,28,5,STEP:0)
Block(-7,28,7,STEP:0)
Block(-7,29,1,SMOOTH_STAIRS:2)
RandomBlock(-7,29,2,contenttweaker:reinforced_concrete:0,40,SMOOTH_BRICK:1,30,SMOOTH_BRICK:2,30,MOSSY_COBBLESTONE:0,30,COBBLESTONE:0,20,contenttweaker:reinforced_concrete:0,100)
Block(-7,29,3,DOUBLE_STEP:0)
Block(-7,29,4,DOUBLE_STEP:0)
Block(-7,29,5,quark:polished_stone:0)
RandomBlock(-7,29,6,contenttweaker:reinforced_concrete:0,40,SMOOTH_BRICK:1,30,SMOOTH_BRICK:2,30,MOSSY_COBBLESTONE:0,30,COBBLESTONE:0,20,contenttweaker:reinforced_concrete:0,100)
RandomBlock(-7,29,7,contenttweaker:reinforced_concrete:0,40,SMOOTH_BRICK:1,30,SMOOTH_BRICK:2,30,MOSSY_COBBLESTONE:0,30,COBBLESTONE:0,20,contenttweaker:reinforced_concrete:0,100)
RandomBlock(-7,29,8,contenttweaker:reinforced_concrete:0,40,SMOOTH_BRICK:1,30,SMOOTH_BRICK:2,30,MOSSY_COBBLESTONE:0,30,COBBLESTONE:0,20,contenttweaker:reinforced_concrete:0,100)
Block(-7,30,3,DOUBLE_STEP:0)
Block(-7,30,7,STEP:0)
Block(-7,30,8,DOUBLE_STEP:0)
Block(-7,31,7,quark:iron_plate:1)
RandomBlock(-7,34,8,rustic:iron_lattice:0,30,rustic:iron_lattice:1,100)
RandomBlock(-7,35,8,rustic:iron_lattice:0,30,rustic:iron_lattice:1,100)
RandomBlock(-7,39,8,rustic:iron_lattice:0,30,rustic:iron_lattice:1,100)
RandomBlock(-7,40,8,rustic:iron_lattice:0,30,rustic:iron_lattice:1,100)
RandomBlock(-7,44,8,rustic:iron_lattice:0,30,rustic:iron_lattice:1,100)
RandomBlock(-7,45,8,rustic:iron_lattice:0,30,rustic:iron_lattice:1,100)
Block(-6,0,-3,contenttweaker:reinforced_concrete:0)
Block(-6,0,-2,contenttweaker:reinforced_concrete:0)
Block(-6,0,-1,quark:world_stone_pavement:2)
Block(-6,0,0,quark:world_stone_pavement:2)
Block(-6,0,1,contenttweaker:reinforced_concrete:0)
Block(-6,0,2,contenttweaker:reinforced_concrete:0)
Block(-6,0,3,quark:world_stone_pavement:2)
Block(-6,0,4,quark:world_stone_pavement:2)
Block(-6,0,5,quark:world_stone_pavement:2)
Block(-6,0,6,quark:world_stone_pavement:2)
Block(-6,0,7,contenttweaker:reinforced_concrete:0)
Block(-6,0,8,quark:world_stone_pavement:2)
Block(-6,1,-3,quark:world_stone_pavement:2)
Block(-6,1,-2,contenttweaker:reinforced_concrete:0)
Block(-6,1,-1,quark:world_stone_pavement:2)
Block(-6,1,0,quark:world_stone_pavement:2)
Block(-6,1,1,contenttweaker:reinforced_concrete:0)
Block(-6,1,2,contenttweaker:reinforced_concrete:0)
Block(-6,1,3,quark:world_stone_pavement:2)
Block(-6,1,4,quark:world_stone_pavement:2)
Block(-6,1,5,contenttweaker:reinforced_concrete:0)
Block(-6,1,6,contenttweaker:reinforced_concrete:0)
Block(-6,1,7,contenttweaker:reinforced_concrete:0)
Block(-6,1,8,quark:world_stone_pavement:2)
Block(-6,2,-3,contenttweaker:reinforced_concrete:0)
Block(-6,2,-2,quark:world_stone_pavement:2)
Block(-6,2,-1,quark:world_stone_pavement:2)
Block(-6,2,0,quark:world_stone_pavement:2)
Block(-6,2,1,contenttweaker:reinforced_concrete:0)
Block(-6,2,2,contenttweaker:reinforced_concrete:0)
Block(-6,2,3,contenttweaker:reinforced_concrete:0)
Block(-6,2,4,quark:world_stone_pavement:2)
Block(-6,2,5,contenttweaker:reinforced_concrete:0)
Block(-6,2,6,contenttweaker:reinforced_concrete:0)
Block(-6,2,7,contenttweaker:reinforced_concrete:0)
Block(-6,2,8,quark:world_stone_pavement:2)
Block(-6,3,-3,quark:world_stone_pavement:2)
Block(-6,3,-2,contenttweaker:reinforced_concrete:0)
Block(-6,3,-1,quark:world_stone_pavement:2)
Block(-6,3,0,quark:world_stone_pavement:2)
Block(-6,3,1,contenttweaker:reinforced_concrete:0)
Block(-6,3,2,contenttweaker:reinforced_concrete:0)
Block(-6,3,3,contenttweaker:reinforced_concrete:0)
Block(-6,3,4,quark:world_stone_pavement:2)
Block(-6,3,5,contenttweaker:reinforced_concrete:0)
Block(-6,3,6,quark:world_stone_pavement:2)
Block(-6,3,7,quark:world_stone_pavement:2)
Block(-6,3,8,quark:world_stone_pavement:2)
Block(-6,4,-3,contenttweaker:reinforced_concrete:0)
Block(-6,4,-2,contenttweaker:reinforced_concrete:0)
Block(-6,4,-1,quark:world_stone_pavement:2)
Block(-6,4,0,contenttweaker:reinforced_concrete:0)
Block(-6,4,1,quark:world_stone_pavement:2)
Block(-6,4,2,quark:world_stone_pavement:2)
Block(-6,4,3,quark:world_stone_pavement:2)
Block(-6,4,4,quark:world_stone_pavement:2)
Block(-6,4,5,quark:world_stone_pavement:2)
Block(-6,4,6,contenttweaker:reinforced_concrete:0)
Block(-6,4,7,quark:world_stone_pavement:2)
Block(-6,4,8,quark:world_stone_pavement:2)
Block(-6,5,-3,contenttweaker:reinforced_concrete:0)
Block(-6,5,-2,quark:world_stone_pavement:2)
Block(-6,5,-1,quark:world_stone_pavement:2)
Block(-6,5,0,contenttweaker:reinforced_concrete:0)
Block(-6,5,1,contenttweaker:reinforced_concrete:0)
Block(-6,5,2,contenttweaker:reinforced_concrete:0)
Block(-6,5,3,contenttweaker:reinforced_concrete:0)
Block(-6,5,4,quark:world_stone_pavement:2)
Block(-6,5,5,quark:world_stone_pavement:2)
Block(-6,5,6,contenttweaker:reinforced_concrete:0)
Block(-6,5,7,contenttweaker:reinforced_concrete:0)
Block(-6,5,8,quark:world_stone_pavement:2)
Block(-6,6,-3,contenttweaker:reinforced_concrete:0)
Block(-6,6,-2,contenttweaker:reinforced_concrete:0)
Block(-6,6,-1,quark:world_stone_pavement:2)
Block(-6,6,0,contenttweaker:reinforced_concrete:0)
Block(-6,6,1,contenttweaker:reinforced_concrete:0)
Block(-6,6,2,contenttweaker:reinforced_concrete:0)
Block(-6,6,3,contenttweaker:reinforced_concrete:0)
Block(-6,6,4,quark:world_stone_pavement:2)
Block(-6,6,5,contenttweaker:reinforced_concrete:0)
Block(-6,6,6,contenttweaker:reinforced_concrete:0)
Block(-6,6,7,contenttweaker:reinforced_concrete:0)
Block(-6,6,8,quark:world_stone_pavement:2)
Block(-6,7,-3,contenttweaker:reinforced_concrete:0)
Block(-6,7,-2,contenttweaker:reinforced_concrete:0)
Block(-6,7,-1,contenttweaker:reinforced_concrete:0)
Block(-6,7,0,quark:world_stone_pavement:2)
Block(-6,7,1,contenttweaker:reinforced_concrete:0)
Block(-6,7,2,quark:world_stone_pavement:2)
Block(-6,7,3,quark:world_stone_pavement:2)
Block(-6,7,4,contenttweaker:reinforced_concrete:0)
Block(-6,7,5,contenttweaker:reinforced_concrete:0)
Block(-6,7,6,contenttweaker:reinforced_concrete:0)
Block(-6,7,7,quark:world_stone_pavement:2)
Block(-6,7,8,quark:world_stone_pavement:2)
Block(-6,8,-3,contenttweaker:reinforced_concrete:0)
Block(-6,8,-2,quark:world_stone_pavement:2)
Block(-6,8,-1,contenttweaker:reinforced_concrete:0)
Block(-6,8,0,contenttweaker:reinforced_concrete:0)
Block(-6,8,1,contenttweaker:reinforced_concrete:0)
Block(-6,8,2,contenttweaker:reinforced_concrete:0)
Block(-6,8,3,contenttweaker:reinforced_concrete:0)
Block(-6,8,4,quark:world_stone_pavement:2)
Block(-6,8,5,contenttweaker:reinforced_concrete:0)
Block(-6,8,6,contenttweaker:reinforced_concrete:0)
Block(-6,8,7,contenttweaker:reinforced_concrete:0)
Block(-6,8,8,contenttweaker:reinforced_concrete:0)
Block(-6,9,-3,contenttweaker:reinforced_concrete:0)
Block(-6,9,-2,contenttweaker:reinforced_concrete:0)
Block(-6,9,-1,contenttweaker:reinforced_concrete:0)
Block(-6,9,0,contenttweaker:reinforced_concrete:0)
Block(-6,9,1,contenttweaker:reinforced_concrete:0)
Block(-6,9,2,quark:world_stone_pavement:2)
Block(-6,9,3,contenttweaker:reinforced_concrete:0)
Block(-6,9,4,contenttweaker:reinforced_concrete:0)
Block(-6,9,5,contenttweaker:reinforced_concrete:0)
Block(-6,9,6,contenttweaker:reinforced_concrete:0)
Block(-6,9,7,contenttweaker:reinforced_concrete:0)
Block(-6,9,8,quark:world_stone_pavement:2)
Block(-6,10,-3,contenttweaker:reinforced_concrete:0)
Block(-6,10,-2,quark:world_stone_pavement:2)
Block(-6,10,-1,quark:polished_stone:0)
Block(-6,10,0,quark:polished_stone:0)
Block(-6,10,1,quark:iron_plate:0)
Block(-6,10,2,quark:world_stone_pavement:2)
Block(-6,10,3,quark:world_stone_pavement:2)
Block(-6,10,4,contenttweaker:reinforced_concrete:0)
Block(-6,10,5,contenttweaker:reinforced_concrete:0)
Block(-6,10,6,contenttweaker:reinforced_concrete:0)
Block(-6,10,7,contenttweaker:reinforced_concrete:0)
Block(-6,10,8,contenttweaker:reinforced_concrete:0)
Block(-6,11,-7,quark:iron_plate:1)
Block(-6,11,-5,quark:iron_plate:1)
Block(-6,11,-3,contenttweaker:reinforced_concrete:0)
Block(-6,11,-2,quark:iron_plate:0)
Block(-6,11,-1,SMOOTH_STAIRS:4)
Block(-6,11,1,SMOOTH_STAIRS:0)
Block(-6,12,-3,DOUBLE_STEP:0)
Block(-6,12,-2,quark:iron_plate:0)
Block(-6,12,-1,quark:iron_plate:0)
Block(-6,13,-3,DOUBLE_STEP:0)
Block(-6,13,-2,quark:iron_plate:0)
Block(-6,13,-1,SMOOTH_STAIRS:0)
Block(-6,14,-3,DOUBLE_STEP:0)
Block(-6,14,-2,SMOOTH_STAIRS:0)
Block(-6,15,-3,DOUBLE_STEP:0)
Block(-6,15,-2,quark:grate:0)
Block(-6,15,-1,quark:iron_plate:1)
Block(-6,16,-3,DOUBLE_STEP:0)
Block(-6,16,-2,LEVER:4)
RandomBlock(-6,16,-1,contenttweaker:reinforced_concrete:0,40,SMOOTH_BRICK:1,30,SMOOTH_BRICK:2,30,MOSSY_COBBLESTONE:0,30,COBBLESTONE:0,20,contenttweaker:reinforced_concrete:0,100)
Block(-6,17,-3,DOUBLE_STEP:0)
RandomBlock(-6,17,-1,rustic:iron_lattice:0,30,rustic:iron_lattice:1,100)
Block(-6,18,-3,DOUBLE_STEP:0)
Block(-6,19,-3,quark:iron_plate:1)
Block(-6,20,-3,STEP:0)
RandomBlock(-6,20,-2,contenttweaker:reinforced_concrete:0,40,SMOOTH_BRICK:1,30,SMOOTH_BRICK:2,30,MOSSY_COBBLESTONE:0,30,COBBLESTONE:0,20,contenttweaker:reinforced_concrete:0,100)
Block(-6,21,-2,STEP:0)
Block(-6,21,-1,quark:iron_plate:1)
Block(-6,21,0,STEP:0)
RandomBlock(-6,22,0,contenttweaker:reinforced_concrete:0,40,SMOOTH_BRICK:1,30,SMOOTH_BRICK:2,30,MOSSY_COBBLESTONE:0,30,COBBLESTONE:0,20,contenttweaker:reinforced_concrete:0,100)
Block(-6,23,0,quark:framed_glass:0)
Block(-6,24,0,quark:framed_glass:0)
Block(-6,25,0,DOUBLE_STEP:0)
RandomBlock(-6,26,0,contenttweaker:reinforced_concrete:0,40,SMOOTH_BRICK:1,30,SMOOTH_BRICK:2,30,MOSSY_COBBLESTONE:0,30,COBBLESTONE:0,20,contenttweaker:reinforced_concrete:0,100)
Block(-6,27,0,quark:sturdy_stone:0)
Block(-6,28,0,SMOOTH_STAIRS:2)
Block(-6,28,1,STEP:0)
Block(-6,28,2,STEP:0)
Block(-6,28,3,STEP:0)
Block(-6,28,4,STEP:0)
Block(-6,28,5,STEP:0)
Block(-6,28,6,STEP:0)
Block(-6,28,7,STEP:0)
Block(-6,28,8,STEP:0)
Block(-6,29,1,SMOOTH_STAIRS:2)
RandomBlock(-6,29,2,contenttweaker:reinforced_concrete:0,40,SMOOTH_BRICK:1,30,SMOOTH_BRICK:2,30,MOSSY_COBBLESTONE:0,30,COBBLESTONE:0,20,contenttweaker:reinforced_concrete:0,100)
Block(-6,29,3,DOUBLE_STEP:0)
Block(-6,29,4,DOUBLE_STEP:0)
Block(-6,29,5,quark:polished_stone:0)
Block(-6,29,6,quark:world_stone_pavement:2)
Block(-6,29,7,quark:polished_stone:0)
Block(-6,29,8,quark:polished_stone:0)
Block(-6,30,3,DOUBLE_STEP:0)
Block(-6,30,8,DOUBLE_STEP:0)
Block(-6,31,7,quark:iron_plate:1)
Block(-6,31,8,quark:iron_plate:1)
Block(-6,32,8,quark:basalt_wall:0)
Block(-6,33,8,quark:iron_plate_stairs:2)
RandomBlock(-6,34,8,rustic:iron_lattice:0,30,rustic:iron_lattice:1,100)
RandomBlock(-6,35,8,rustic:iron_lattice:0,30,rustic:iron_lattice:1,100)
RandomBlock(-6,39,8,rustic:iron_lattice:0,30,rustic:iron_lattice:1,100)
RandomBlock(-6,40,8,rustic:iron_lattice:0,30,rustic:iron_lattice:1,100)
RandomBlock(-6,44,8,rustic:iron_lattice:0,30,rustic:iron_lattice:1,100)
RandomBlock(-6,45,8,rustic:iron_lattice:0,30,rustic:iron_lattice:1,100)
Block(-5,0,-3,quark:world_stone_pavement:2)
Block(-5,0,-2,contenttweaker:reinforced_concrete:0)
Block(-5,0,-1,contenttweaker:reinforced_concrete:0)
Block(-5,0,0,contenttweaker:reinforced_concrete:0)
Block(-5,0,1,contenttweaker:reinforced_concrete:0)
Block(-5,0,2,contenttweaker:reinforced_concrete:0)
Block(-5,0,3,contenttweaker:reinforced_concrete:0)
Block(-5,0,4,quark:world_stone_pavement:2)
Block(-5,0,5,contenttweaker:reinforced_concrete:0)
Block(-5,0,6,contenttweaker:reinforced_concrete:0)
Block(-5,0,7,quark:world_stone_pavement:2)
Block(-5,0,8,contenttweaker:reinforced_concrete:0)
Block(-5,1,-3,quark:world_stone_pavement:2)
Block(-5,1,-2,contenttweaker:reinforced_concrete:0)
Block(-5,1,-1,contenttweaker:reinforced_concrete:0)
Block(-5,1,0,contenttweaker:reinforced_concrete:0)
Block(-5,1,1,quark:world_stone_pavement:2)
Block(-5,1,2,quark:world_stone_pavement:2)
Block(-5,1,3,contenttweaker:reinforced_concrete:0)
Block(-5,1,4,quark:world_stone_pavement:2)
Block(-5,1,5,contenttweaker:reinforced_concrete:0)
Block(-5,1,6,contenttweaker:reinforced_concrete:0)
Block(-5,1,7,quark:world_stone_pavement:2)
Block(-5,1,8,contenttweaker:reinforced_concrete:0)
Block(-5,2,-3,quark:world_stone_pavement:2)
Block(-5,2,-2,contenttweaker:reinforced_concrete:0)
Block(-5,2,-1,quark:world_stone_pavement:2)
Block(-5,2,0,contenttweaker:reinforced_concrete:0)
Block(-5,2,1,contenttweaker:reinforced_concrete:0)
Block(-5,2,2,contenttweaker:reinforced_concrete:0)
Block(-5,2,3,contenttweaker:reinforced_concrete:0)
Block(-5,2,4,quark:world_stone_pavement:2)
Block(-5,2,5,contenttweaker:reinforced_concrete:0)
Block(-5,2,6,contenttweaker:reinforced_concrete:0)
Block(-5,2,7,quark:world_stone_pavement:2)
Block(-5,2,8,contenttweaker:reinforced_concrete:0)
Block(-5,3,-3,quark:world_stone_pavement:2)
Block(-5,3,-2,contenttweaker:reinforced_concrete:0)
Block(-5,3,-1,quark:world_stone_pavement:2)
Block(-5,3,0,contenttweaker:reinforced_concrete:0)
Block(-5,3,1,quark:world_stone_pavement:2)
Block(-5,3,2,quark:world_stone_pavement:2)
Block(-5,3,3,contenttweaker:reinforced_concrete:0)
Block(-5,3,4,quark:world_stone_pavement:2)
Block(-5,3,5,contenttweaker:reinforced_concrete:0)
Block(-5,3,6,contenttweaker:reinforced_concrete:0)
Block(-5,3,7,quark:world_stone_pavement:2)
Block(-5,3,8,contenttweaker:reinforced_concrete:0)
Block(-5,4,-3,quark:world_stone_pavement:2)
Block(-5,4,-2,contenttweaker:reinforced_concrete:0)
Block(-5,4,-1,contenttweaker:reinforced_concrete:0)
Block(-5,4,0,contenttweaker:reinforced_concrete:0)
Block(-5,4,1,contenttweaker:reinforced_concrete:0)
Block(-5,4,2,quark:world_stone_pavement:2)
Block(-5,4,3,quark:world_stone_pavement:2)
Block(-5,4,4,quark:world_stone_pavement:2)
Block(-5,4,5,quark:world_stone_pavement:2)
Block(-5,4,6,contenttweaker:reinforced_concrete:0)
Block(-5,4,7,contenttweaker:reinforced_concrete:0)
Block(-5,4,8,contenttweaker:reinforced_concrete:0)
Block(-5,5,-3,quark:world_stone_pavement:2)
Block(-5,5,-2,quark:world_stone_pavement:2)
Block(-5,5,-1,contenttweaker:reinforced_concrete:0)
Block(-5,5,0,quark:world_stone_pavement:2)
Block(-5,5,1,quark:world_stone_pavement:2)
Block(-5,5,2,contenttweaker:reinforced_concrete:0)
Block(-5,5,3,quark:world_stone_pavement:2)
Block(-5,5,4,quark:world_stone_pavement:2)
Block(-5,5,5,quark:world_stone_pavement:2)
Block(-5,5,6,quark:world_stone_pavement:2)
Block(-5,5,7,contenttweaker:reinforced_concrete:0)
Block(-5,5,8,contenttweaker:reinforced_concrete:0)
Block(-5,6,-3,quark:world_stone_pavement:2)
Block(-5,6,-2,quark:world_stone_pavement:2)
Block(-5,6,-1,contenttweaker:reinforced_concrete:0)
Block(-5,6,0,contenttweaker:reinforced_concrete:0)
Block(-5,6,1,quark:world_stone_pavement:2)
Block(-5,6,2,contenttweaker:reinforced_concrete:0)
Block(-5,6,3,quark:world_stone_pavement:2)
Block(-5,6,4,quark:world_stone_pavement:2)
Block(-5,6,5,contenttweaker:reinforced_concrete:0)
Block(-5,6,6,quark:world_stone_pavement:2)
Block(-5,6,7,contenttweaker:reinforced_concrete:0)
Block(-5,6,8,quark:world_stone_pavement:2)
Block(-5,7,-3,contenttweaker:reinforced_concrete:0)
Block(-5,7,-2,quark:world_stone_pavement:2)
Block(-5,7,-1,quark:world_stone_pavement:2)
Block(-5,7,0,contenttweaker:reinforced_concrete:0)
Block(-5,7,1,contenttweaker:reinforced_concrete:0)
Block(-5,7,2,contenttweaker:reinforced_concrete:0)
Block(-5,7,3,contenttweaker:reinforced_concrete:0)
Block(-5,7,4,quark:world_stone_pavement:2)
Block(-5,7,5,contenttweaker:reinforced_concrete:0)
Block(-5,7,6,contenttweaker:reinforced_concrete:0)
Block(-5,7,7,quark:world_stone_pavement:2)
Block(-5,7,8,contenttweaker:reinforced_concrete:0)
Block(-5,8,-3,quark:world_stone_pavement:2)
Block(-5,8,-2,quark:world_stone_pavement:2)
Block(-5,8,-1,contenttweaker:reinforced_concrete:0)
Block(-5,8,0,quark:world_stone_pavement:2)
Block(-5,8,1,contenttweaker:reinforced_concrete:0)
Block(-5,8,2,quark:world_stone_pavement:2)
Block(-5,8,3,contenttweaker:reinforced_concrete:0)
Block(-5,8,4,contenttweaker:reinforced_concrete:0)
Block(-5,8,5,contenttweaker:reinforced_concrete:0)
Block(-5,8,6,contenttweaker:reinforced_concrete:0)
Block(-5,8,7,contenttweaker:reinforced_concrete:0)
Block(-5,8,8,quark:world_stone_pavement:2)
Block(-5,9,-3,quark:world_stone_pavement:2)
Block(-5,9,-2,contenttweaker:reinforced_concrete:0)
Block(-5,9,-1,quark:world_stone_pavement:2)
Block(-5,9,0,contenttweaker:reinforced_concrete:0)
Block(-5,9,1,contenttweaker:reinforced_concrete:0)
Block(-5,9,2,quark:world_stone_pavement:2)
Block(-5,9,3,contenttweaker:reinforced_concrete:0)
Block(-5,9,4,contenttweaker:reinforced_concrete:0)
Block(-5,9,5,contenttweaker:reinforced_concrete:0)
Block(-5,9,6,contenttweaker:reinforced_concrete:0)
Block(-5,9,7,contenttweaker:reinforced_concrete:0)
Block(-5,9,8,contenttweaker:reinforced_concrete:0)
Block(-5,10,-3,contenttweaker:reinforced_concrete:0)
Block(-5,10,-2,quark:world_stone_pavement:2)
Block(-5,10,-1,quark:world_stone_pavement:2)
Block(-5,10,0,contenttweaker:reinforced_concrete:0)
Block(-5,10,1,quark:iron_plate:0)
Block(-5,10,2,contenttweaker:reinforced_concrete:0)
Block(-5,10,3,quark:world_stone_pavement:2)
Block(-5,10,4,contenttweaker:reinforced_concrete:0)
Block(-5,10,5,quark:world_stone_pavement:2)
Block(-5,10,6,contenttweaker:reinforced_concrete:0)
Block(-5,10,7,contenttweaker:reinforced_concrete:0)
Block(-5,10,8,contenttweaker:reinforced_concrete:0)
Block(-5,11,-7,quark:iron_plate:1)
Block(-5,11,-5,quark:iron_plate:1)
Block(-5,11,-3,contenttweaker:reinforced_concrete:0)
Block(-5,11,-2,quark:iron_plate:0)
Block(-5,11,-1,quark:iron_plate:0)
RandomBlock(-5,11,0,rustic:iron_lattice:0,30,rustic:iron_lattice:1,100)
RandomBlock(-5,11,1,rustic:iron_lattice:0,30,rustic:iron_lattice:1,100)
Block(-5,11,2,quark:iron_plate:0)
Block(-5,12,-3,quark:world_stone_pavement:2)
Block(-5,12,-2,quark:iron_plate:0)
Block(-5,12,-1,quark:iron_plate:0)
Block(-5,12,0,quark:iron_plate:0)
Block(-5,12,1,quark:iron_plate:0)
Block(-5,12,2,quark:iron_plate_stairs:3)
RandomBlock(-5,13,-3,contenttweaker:reinforced_concrete:0,40,SMOOTH_BRICK:1,30,SMOOTH_BRICK:2,30,MOSSY_COBBLESTONE:0,30,COBBLESTONE:0,20,contenttweaker:reinforced_concrete:0,100)
Block(-5,13,-2,quark:iron_plate:0)
Block(-5,13,-1,quark:iron_plate:0)
RandomBlock(-5,14,-3,contenttweaker:reinforced_concrete:0,40,SMOOTH_BRICK:1,30,SMOOTH_BRICK:2,30,MOSSY_COBBLESTONE:0,30,COBBLESTONE:0,20,contenttweaker:reinforced_concrete:0,100)
Block(-5,14,-2,quark:iron_plate:0)
RandomBlock(-5,15,-3,contenttweaker:reinforced_concrete:0,40,SMOOTH_BRICK:1,30,SMOOTH_BRICK:2,30,MOSSY_COBBLESTONE:0,30,COBBLESTONE:0,20,contenttweaker:reinforced_concrete:0,100)
Block(-5,15,-2,quark:grate:0)
Block(-5,15,-1,quark:iron_plate:1)
RandomBlock(-5,16,-3,contenttweaker:reinforced_concrete:0,40,SMOOTH_BRICK:1,30,SMOOTH_BRICK:2,30,MOSSY_COBBLESTONE:0,30,COBBLESTONE:0,20,contenttweaker:reinforced_concrete:0,100)
RandomBlock(-5,16,-1,rustic:iron_lattice:0,30,rustic:iron_lattice:1,100)
RandomBlock(-5,17,-3,contenttweaker:reinforced_concrete:0,40,SMOOTH_BRICK:1,30,SMOOTH_BRICK:2,30,MOSSY_COBBLESTONE:0,30,COBBLESTONE:0,20,contenttweaker:reinforced_concrete:0,100)
RandomBlock(-5,17,-1,rustic:iron_lattice:0,30,rustic:iron_lattice:1,100)
RandomBlock(-5,18,-3,contenttweaker:reinforced_concrete:0,40,SMOOTH_BRICK:1,30,SMOOTH_BRICK:2,30,MOSSY_COBBLESTONE:0,30,COBBLESTONE:0,20,contenttweaker:reinforced_concrete:0,100)
Block(-5,19,-3,quark:iron_plate:1)
Block(-5,20,-3,STEP:0)
RandomBlock(-5,20,-2,contenttweaker:reinforced_concrete:0,40,SMOOTH_BRICK:1,30,SMOOTH_BRICK:2,30,MOSSY_COBBLESTONE:0,30,COBBLESTONE:0,20,contenttweaker:reinforced_concrete:0,100)
Block(-5,21,-2,DOUBLE_STEP:0)
Block(-5,21,-1,quark:iron_plate:1)
Block(-5,21,0,STEP:0)
Block(-5,22,-2,quark:iron_plate:1)
Block(-5,22,-1,STEP:0)
Block(-5,22,0,DOUBLE_STEP:0)
Block(-5,23,-2,DOUBLE_STEP:0)
Block(-5,23,-1,STEP:0)
Block(-5,23,0,DOUBLE_STEP:0)
Block(-5,24,-2,DOUBLE_STEP:0)
Block(-5,24,-1,STEP:0)
Block(-5,24,0,DOUBLE_STEP:0)
Block(-5,25,-2,DOUBLE_STEP:0)
Block(-5,25,-1,STEP:0)
RandomBlock(-5,25,0,contenttweaker:reinforced_concrete:0,40,SMOOTH_BRICK:1,30,SMOOTH_BRICK:2,30,MOSSY_COBBLESTONE:0,30,COBBLESTONE:0,20,contenttweaker:reinforced_concrete:0,100)
Block(-5,26,-2,STEP:0)
Block(-5,26,-1,DOUBLE_STEP:0)
RandomBlock(-5,26,0,contenttweaker:reinforced_concrete:0,40,SMOOTH_BRICK:1,30,SMOOTH_BRICK:2,30,MOSSY_COBBLESTONE:0,30,COBBLESTONE:0,20,contenttweaker:reinforced_concrete:0,100)
Block(-5,27,-1,STEP:0)
Block(-5,27,0,quark:sturdy_stone:0)
Block(-5,28,0,SMOOTH_STAIRS:2)
Block(-5,28,1,STEP:0)
Block(-5,28,3,STEP:0)
Block(-5,28,5,STEP:0)
Block(-5,28,7,STEP:0)
Block(-5,29,1,SMOOTH_STAIRS:2)
RandomBlock(-5,29,2,contenttweaker:reinforced_concrete:0,40,SMOOTH_BRICK:1,30,SMOOTH_BRICK:2,30,MOSSY_COBBLESTONE:0,30,COBBLESTONE:0,20,contenttweaker:reinforced_concrete:0,100)
RandomBlock(-5,29,3,contenttweaker:reinforced_concrete:0,40,SMOOTH_BRICK:1,30,SMOOTH_BRICK:2,30,MOSSY_COBBLESTONE:0,30,COBBLESTONE:0,20,contenttweaker:reinforced_concrete:0,100)
RandomBlock(-5,29,4,contenttweaker:reinforced_concrete:0,40,SMOOTH_BRICK:1,30,SMOOTH_BRICK:2,30,MOSSY_COBBLESTONE:0,30,COBBLESTONE:0,20,contenttweaker:reinforced_concrete:0,100)
Block(-5,29,5,quark:polished_stone:0)
RandomBlock(-5,29,6,contenttweaker:reinforced_concrete:0,40,SMOOTH_BRICK:1,30,SMOOTH_BRICK:2,30,MOSSY_COBBLESTONE:0,30,COBBLESTONE:0,20,contenttweaker:reinforced_concrete:0,100)
RandomBlock(-5,29,7,contenttweaker:reinforced_concrete:0,40,SMOOTH_BRICK:1,30,SMOOTH_BRICK:2,30,MOSSY_COBBLESTONE:0,30,COBBLESTONE:0,20,contenttweaker:reinforced_concrete:0,100)
RandomBlock(-5,29,8,contenttweaker:reinforced_concrete:0,40,SMOOTH_BRICK:1,30,SMOOTH_BRICK:2,30,MOSSY_COBBLESTONE:0,30,COBBLESTONE:0,20,contenttweaker:reinforced_concrete:0,100)
Block(-5,30,2,SMOOTH_STAIRS:2)
Block(-5,30,5,quark:iron_plate:1)
Block(-5,30,8,DOUBLE_STEP:0)
Block(-5,31,5,quark:iron_plate:1)
Block(-5,31,6,quark:iron_plate:1)
Block(-5,31,7,quark:iron_plate:1)
Block(-5,31,8,quark:iron_plate:1)
Block(-5,32,8,quark:basalt_wall:0)
Block(-5,33,8,quark:iron_plate_stairs:2)
RandomBlock(-5,34,8,rustic:iron_lattice:0,30,rustic:iron_lattice:1,100)
RandomBlock(-5,35,8,rustic:iron_lattice:0,30,rustic:iron_lattice:1,100)
RandomBlock(-5,39,8,rustic:iron_lattice:0,30,rustic:iron_lattice:1,100)
RandomBlock(-5,40,8,rustic:iron_lattice:0,30,rustic:iron_lattice:1,100)
RandomBlock(-5,44,8,rustic:iron_lattice:0,30,rustic:iron_lattice:1,100)
RandomBlock(-5,45,8,rustic:iron_lattice:0,30,rustic:iron_lattice:1,100)
Block(-4,0,-3,contenttweaker:reinforced_concrete:0)
Block(-4,0,-2,contenttweaker:reinforced_concrete:0)
Block(-4,0,-1,quark:world_stone_pavement:2)
Block(-4,0,0,contenttweaker:reinforced_concrete:0)
Block(-4,0,1,quark:world_stone_pavement:2)
Block(-4,0,2,quark:world_stone_pavement:2)
Block(-4,0,3,contenttweaker:reinforced_concrete:0)
Block(-4,0,4,quark:world_stone_pavement:2)
Block(-4,0,5,quark:world_stone_pavement:2)
Block(-4,0,6,contenttweaker:reinforced_concrete:0)
Block(-4,0,7,contenttweaker:reinforced_concrete:0)
Block(-4,0,8,quark:world_stone_pavement:2)
Block(-4,1,-3,quark:world_stone_pavement:2)
Block(-4,1,-2,contenttweaker:reinforced_concrete:0)
Block(-4,1,-1,quark:world_stone_pavement:2)
Block(-4,1,0,quark:world_stone_pavement:2)
Block(-4,1,1,quark:world_stone_pavement:2)
Block(-4,1,2,quark:world_stone_pavement:2)
Block(-4,1,3,quark:world_stone_pavement:2)
Block(-4,1,4,quark:world_stone_pavement:2)
Block(-4,1,5,quark:world_stone_pavement:2)
Block(-4,1,6,quark:world_stone_pavement:2)
Block(-4,1,7,quark:world_stone_pavement:2)
Block(-4,1,8,quark:world_stone_pavement:2)
Block(-4,2,-3,contenttweaker:reinforced_concrete:0)
Block(-4,2,-2,contenttweaker:reinforced_concrete:0)
Block(-4,2,-1,quark:world_stone_pavement:2)
Block(-4,2,0,contenttweaker:reinforced_concrete:0)
Block(-4,2,1,quark:world_stone_pavement:2)
Block(-4,2,2,contenttweaker:reinforced_concrete:0)
Block(-4,2,3,contenttweaker:reinforced_concrete:0)
Block(-4,2,4,quark:world_stone_pavement:2)
Block(-4,2,5,quark:world_stone_pavement:2)
Block(-4,2,6,quark:world_stone_pavement:2)
Block(-4,2,7,contenttweaker:reinforced_concrete:0)
Block(-4,2,8,quark:world_stone_pavement:2)
Block(-4,3,-3,contenttweaker:reinforced_concrete:0)
Block(-4,3,-2,contenttweaker:reinforced_concrete:0)
Block(-4,3,-1,quark:world_stone_pavement:2)
Block(-4,3,0,quark:world_stone_pavement:2)
Block(-4,3,1,quark:world_stone_pavement:2)
Block(-4,3,2,contenttweaker:reinforced_concrete:0)
Block(-4,3,3,quark:world_stone_pavement:2)
Block(-4,3,4,quark:world_stone_pavement:2)
Block(-4,3,5,quark:world_stone_pavement:2)
Block(-4,3,6,quark:world_stone_pavement:2)
Block(-4,3,7,contenttweaker:reinforced_concrete:0)
Block(-4,3,8,quark:world_stone_pavement:2)
Block(-4,4,-3,contenttweaker:reinforced_concrete:0)
Block(-4,4,-2,contenttweaker:reinforced_concrete:0)
Block(-4,4,-1,quark:world_stone_pavement:2)
Block(-4,4,0,quark:world_stone_pavement:2)
Block(-4,4,1,quark:world_stone_pavement:2)
Block(-4,4,2,contenttweaker:reinforced_concrete:0)
Block(-4,4,3,contenttweaker:reinforced_concrete:0)
Block(-4,4,4,quark:world_stone_pavement:2)
Block(-4,4,5,quark:world_stone_pavement:2)
Block(-4,4,6,quark:world_stone_pavement:2)
Block(-4,4,7,contenttweaker:reinforced_concrete:0)
Block(-4,4,8,quark:world_stone_pavement:2)
Block(-4,5,-3,quark:world_stone_pavement:2)
Block(-4,5,-2,contenttweaker:reinforced_concrete:0)
Block(-4,5,-1,quark:world_stone_pavement:2)
Block(-4,5,0,contenttweaker:reinforced_concrete:0)
Block(-4,5,1,quark:world_stone_pavement:2)
Block(-4,5,2,contenttweaker:reinforced_concrete:0)
Block(-4,5,3,contenttweaker:reinforced_concrete:0)
Block(-4,5,4,quark:world_stone_pavement:2)
Block(-4,5,5,quark:world_stone_pavement:2)
Block(-4,5,6,contenttweaker:reinforced_concrete:0)
Block(-4,5,7,contenttweaker:reinforced_concrete:0)
Block(-4,5,8,quark:world_stone_pavement:2)
Block(-4,6,-3,quark:world_stone_pavement:2)
Block(-4,6,-2,quark:world_stone_pavement:2)
Block(-4,6,-1,quark:world_stone_pavement:2)
Block(-4,6,0,contenttweaker:reinforced_concrete:0)
Block(-4,6,1,quark:world_stone_pavement:2)
Block(-4,6,2,contenttweaker:reinforced_concrete:0)
Block(-4,6,3,quark:world_stone_pavement:2)
Block(-4,6,4,quark:world_stone_pavement:2)
Block(-4,6,5,quark:world_stone_pavement:2)
Block(-4,6,6,contenttweaker:reinforced_concrete:0)
Block(-4,6,7,contenttweaker:reinforced_concrete:0)
Block(-4,6,8,quark:world_stone_pavement:2)
Block(-4,7,-3,contenttweaker:reinforced_concrete:0)
Block(-4,7,-2,contenttweaker:reinforced_concrete:0)
Block(-4,7,-1,quark:world_stone_pavement:2)
Block(-4,7,0,contenttweaker:reinforced_concrete:0)
Block(-4,7,1,contenttweaker:reinforced_concrete:0)
Block(-4,7,2,contenttweaker:reinforced_concrete:0)
Block(-4,7,3,contenttweaker:reinforced_concrete:0)
Block(-4,7,4,quark:world_stone_pavement:2)
Block(-4,7,5,contenttweaker:reinforced_concrete:0)
Block(-4,7,6,contenttweaker:reinforced_concrete:0)
Block(-4,7,7,contenttweaker:reinforced_concrete:0)
Block(-4,7,8,contenttweaker:reinforced_concrete:0)
Block(-4,8,-3,contenttweaker:reinforced_concrete:0)
Block(-4,8,-2,quark:world_stone_pavement:2)
Block(-4,8,-1,quark:world_stone_pavement:2)
Block(-4,8,0,contenttweaker:reinforced_concrete:0)
Block(-4,8,1,quark:world_stone_pavement:2)
Block(-4,8,2,quark:world_stone_pavement:2)
Block(-4,8,3,contenttweaker:reinforced_concrete:0)
Block(-4,8,4,quark:world_stone_pavement:2)
Block(-4,8,5,contenttweaker:reinforced_concrete:0)
Block(-4,8,6,contenttweaker:reinforced_concrete:0)
Block(-4,8,7,contenttweaker:reinforced_concrete:0)
Block(-4,8,8,quark:world_stone_pavement:2)
Block(-4,9,-3,contenttweaker:reinforced_concrete:0)
Block(-4,9,-2,contenttweaker:reinforced_concrete:0)
Block(-4,9,-1,contenttweaker:reinforced_concrete:0)
Block(-4,9,0,quark:world_stone_pavement:2)
Block(-4,9,1,contenttweaker:reinforced_concrete:0)
Block(-4,9,2,quark:world_stone_pavement:2)
Block(-4,9,3,contenttweaker:reinforced_concrete:0)
Block(-4,9,4,quark:world_stone_pavement:2)
Block(-4,9,5,contenttweaker:reinforced_concrete:0)
Block(-4,9,6,contenttweaker:reinforced_concrete:0)
Block(-4,9,7,quark:world_stone_pavement:2)
Block(-4,9,8,quark:world_stone_pavement:2)
Block(-4,10,-3,contenttweaker:reinforced_concrete:0)
Block(-4,10,-2,quark:world_stone_pavement:2)
Block(-4,10,-1,quark:polished_stone:0)
Block(-4,10,0,quark:polished_stone:0)
Block(-4,10,1,quark:iron_plate:0)
Block(-4,10,2,quark:world_stone_pavement:2)
Block(-4,10,3,contenttweaker:reinforced_concrete:0)
Block(-4,10,4,contenttweaker:reinforced_concrete:0)
Block(-4,10,5,quark:world_stone_pavement:2)
Block(-4,10,6,quark:world_stone_pavement:2)
Block(-4,10,7,contenttweaker:reinforced_concrete:0)
Block(-4,10,8,contenttweaker:reinforced_concrete:0)
Block(-4,11,-7,quark:iron_plate:1)
Block(-4,11,-5,quark:iron_plate:1)
Block(-4,11,-3,quark:world_stone_pavement:2)
Block(-4,11,-2,quark:iron_plate:0)
Block(-4,11,-1,SMOOTH_STAIRS:5)
Block(-4,11,1,SMOOTH_STAIRS:1)
Block(-4,12,-3,DOUBLE_STEP:0)
Block(-4,12,-2,quark:iron_plate:0)
Block(-4,12,-1,quark:iron_plate:0)
Block(-4,13,-3,DOUBLE_STEP:0)
Block(-4,13,-2,quark:iron_plate:0)
Block(-4,13,-1,SMOOTH_STAIRS:1)
Block(-4,14,-3,DOUBLE_STEP:0)
Block(-4,14,-2,SMOOTH_STAIRS:1)
Block(-4,15,-3,DOUBLE_STEP:0)
Block(-4,15,-2,quark:grate:0)
Block(-4,15,-1,quark:iron_plate:1)
Block(-4,16,-3,DOUBLE_STEP:0)
RandomBlock(-4,16,-1,rustic:iron_lattice:0,30,rustic:iron_lattice:1,100)
Block(-4,17,-3,DOUBLE_STEP:0)
RandomBlock(-4,17,-1,rustic:iron_lattice:0,30,rustic:iron_lattice:1,100)
Block(-4,18,-3,DOUBLE_STEP:0)
Block(-4,19,-3,quark:iron_plate:1)
Block(-4,20,-3,STEP:0)
RandomBlock(-4,20,-2,contenttweaker:reinforced_concrete:0,40,SMOOTH_BRICK:1,30,SMOOTH_BRICK:2,30,MOSSY_COBBLESTONE:0,30,COBBLESTONE:0,20,contenttweaker:reinforced_concrete:0,100)
Block(-4,21,-2,STEP:0)
Block(-4,21,-1,quark:iron_plate:1)
Block(-4,21,0,STEP:0)
RandomBlock(-4,22,0,contenttweaker:reinforced_concrete:0,40,SMOOTH_BRICK:1,30,SMOOTH_BRICK:2,30,MOSSY_COBBLESTONE:0,30,COBBLESTONE:0,20,contenttweaker:reinforced_concrete:0,100)
Block(-4,23,0,quark:framed_glass:0)
Block(-4,24,0,quark:framed_glass:0)
Block(-4,25,0,DOUBLE_STEP:0)
RandomBlock(-4,26,0,contenttweaker:reinforced_concrete:0,40,SMOOTH_BRICK:1,30,SMOOTH_BRICK:2,30,MOSSY_COBBLESTONE:0,30,COBBLESTONE:0,20,contenttweaker:reinforced_concrete:0,100)
Block(-4,27,0,quark:sturdy_stone:0)
Block(-4,28,0,SMOOTH_STAIRS:2)
Block(-4,28,1,STEP:0)
Block(-4,28,2,STEP:0)
Block(-4,28,3,STEP:0)
Block(-4,28,4,STEP:0)
Block(-4,28,5,STEP:0)
Block(-4,28,6,STEP:0)
Block(-4,28,7,STEP:0)
Block(-4,28,8,STEP:0)
Block(-4,29,1,SMOOTH_STAIRS:2)
RandomBlock(-4,29,2,contenttweaker:reinforced_concrete:0,40,SMOOTH_BRICK:1,30,SMOOTH_BRICK:2,30,MOSSY_COBBLESTONE:0,30,COBBLESTONE:0,20,contenttweaker:reinforced_concrete:0,100)
RandomBlock(-4,29,3,contenttweaker:reinforced_concrete:0,40,SMOOTH_BRICK:1,30,SMOOTH_BRICK:2,30,MOSSY_COBBLESTONE:0,30,COBBLESTONE:0,20,contenttweaker:reinforced_concrete:0,100)
RandomBlock(-4,29,4,contenttweaker:reinforced_concrete:0,40,SMOOTH_BRICK:1,30,SMOOTH_BRICK:2,30,MOSSY_COBBLESTONE:0,30,COBBLESTONE:0,20,contenttweaker:reinforced_concrete:0,100)
Block(-4,29,5,quark:polished_stone:0)
RandomBlock(-4,29,6,contenttweaker:reinforced_concrete:0,40,SMOOTH_BRICK:1,30,SMOOTH_BRICK:2,30,MOSSY_COBBLESTONE:0,30,COBBLESTONE:0,20,contenttweaker:reinforced_concrete:0,100)
RandomBlock(-4,29,7,contenttweaker:reinforced_concrete:0,40,SMOOTH_BRICK:1,30,SMOOTH_BRICK:2,30,MOSSY_COBBLESTONE:0,30,COBBLESTONE:0,20,contenttweaker:reinforced_concrete:0,100)
RandomBlock(-4,29,8,contenttweaker:reinforced_concrete:0,40,SMOOTH_BRICK:1,30,SMOOTH_BRICK:2,30,MOSSY_COBBLESTONE:0,30,COBBLESTONE:0,20,contenttweaker:reinforced_concrete:0,100)
Block(-4,30,2,SMOOTH_STAIRS:2)
Block(-4,30,7,STEP:0)
Block(-4,30,8,DOUBLE_STEP:0)
RandomBlock(-4,34,8,rustic:iron_lattice:0,30,rustic:iron_lattice:1,100)
RandomBlock(-4,35,8,rustic:iron_lattice:0,30,rustic:iron_lattice:1,100)
RandomBlock(-4,39,8,rustic:iron_lattice:0,30,rustic:iron_lattice:1,100)
RandomBlock(-4,40,8,rustic:iron_lattice:0,30,rustic:iron_lattice:1,100)
RandomBlock(-4,44,8,rustic:iron_lattice:0,30,rustic:iron_lattice:1,100)
RandomBlock(-4,45,8,rustic:iron_lattice:0,30,rustic:iron_lattice:1,100)
Block(-3,0,-7,quark:world_stone_pavement:2)
Block(-3,0,-6,quark:world_stone_pavement:2)
Block(-3,0,-5,quark:world_stone_pavement:2)
Block(-3,0,-4,contenttweaker:reinforced_concrete:0)
Block(-3,0,-3,contenttweaker:reinforced_concrete:0)
Block(-3,0,-2,contenttweaker:reinforced_concrete:0)
Block(-3,0,-1,quark:world_stone_pavement:2)
Block(-3,0,0,contenttweaker:reinforced_concrete:0)
Block(-3,0,1,quark:world_stone_pavement:2)
Block(-3,0,2,quark:world_stone_pavement:2)
Block(-3,0,3,contenttweaker:reinforced_concrete:0)
Block(-3,0,4,quark:world_stone_pavement:2)
Block(-3,0,5,quark:world_stone_pavement:2)
Block(-3,0,6,quark:world_stone_pavement:2)
Block(-3,0,7,quark:world_stone_pavement:2)
Block(-3,0,8,quark:world_stone_pavement:2)
Block(-3,1,-7,contenttweaker:reinforced_concrete:0)
Block(-3,1,-6,quark:world_stone_pavement:2)
Block(-3,1,-5,contenttweaker:reinforced_concrete:0)
Block(-3,1,-4,contenttweaker:reinforced_concrete:0)
Block(-3,1,-3,contenttweaker:reinforced_concrete:0)
Block(-3,1,-2,contenttweaker:reinforced_concrete:0)
Block(-3,1,-1,quark:world_stone_pavement:2)
Block(-3,1,0,contenttweaker:reinforced_concrete:0)
Block(-3,1,1,quark:world_stone_pavement:2)
Block(-3,1,2,contenttweaker:reinforced_concrete:0)
Block(-3,1,3,quark:world_stone_pavement:2)
Block(-3,1,4,quark:world_stone_pavement:2)
Block(-3,1,5,quark:world_stone_pavement:2)
Block(-3,1,6,quark:world_stone_pavement:2)
Block(-3,1,7,quark:world_stone_pavement:2)
Block(-3,1,8,contenttweaker:reinforced_concrete:0)
Block(-3,2,-7,contenttweaker:reinforced_concrete:0)
Block(-3,2,-6,quark:world_stone_pavement:2)
Block(-3,2,-5,contenttweaker:reinforced_concrete:0)
Block(-3,2,-4,quark:world_stone_pavement:2)
Block(-3,2,-3,quark:world_stone_pavement:2)
Block(-3,2,-2,contenttweaker:reinforced_concrete:0)
Block(-3,2,-1,quark:world_stone_pavement:2)
Block(-3,2,0,quark:world_stone_pavement:2)
Block(-3,2,1,quark:world_stone_pavement:2)
Block(-3,2,2,contenttweaker:reinforced_concrete:0)
Block(-3,2,3,quark:world_stone_pavement:2)
Block(-3,2,4,quark:world_stone_pavement:2)
Block(-3,2,5,quark:world_stone_pavement:2)
Block(-3,2,6,contenttweaker:reinforced_concrete:0)
Block(-3,2,7,quark:world_stone_pavement:2)
Block(-3,2,8,contenttweaker:reinforced_concrete:0)
Block(-3,3,-7,contenttweaker:reinforced_concrete:0)
Block(-3,3,-6,quark:world_stone_pavement:2)
Block(-3,3,-5,contenttweaker:reinforced_concrete:0)
Block(-3,3,-4,contenttweaker:reinforced_concrete:0)
Block(-3,3,-3,contenttweaker:reinforced_concrete:0)
Block(-3,3,-2,contenttweaker:reinforced_concrete:0)
Block(-3,3,-1,quark:world_stone_pavement:2)
Block(-3,3,0,contenttweaker:reinforced_concrete:0)
Block(-3,3,1,quark:world_stone_pavement:2)
Block(-3,3,2,quark:world_stone_pavement:2)
Block(-3,3,3,contenttweaker:reinforced_concrete:0)
Block(-3,3,4,quark:world_stone_pavement:2)
Block(-3,3,5,quark:world_stone_pavement:2)
Block(-3,3,6,contenttweaker:reinforced_concrete:0)
Block(-3,3,7,quark:world_stone_pavement:2)
Block(-3,3,8,contenttweaker:reinforced_concrete:0)
Block(-3,4,-7,quark:world_stone_pavement:2)
Block(-3,4,-6,quark:world_stone_pavement:2)
Block(-3,4,-5,contenttweaker:reinforced_concrete:0)
Block(-3,4,-4,quark:world_stone_pavement:2)
Block(-3,4,-3,contenttweaker:reinforced_concrete:0)
Block(-3,4,-2,contenttweaker:reinforced_concrete:0)
Block(-3,4,-1,quark:world_stone_pavement:2)
Block(-3,4,0,contenttweaker:reinforced_concrete:0)
Block(-3,4,1,quark:world_stone_pavement:2)
Block(-3,4,2,contenttweaker:reinforced_concrete:0)
Block(-3,4,3,quark:world_stone_pavement:2)
Block(-3,4,4,quark:world_stone_pavement:2)
Block(-3,4,5,quark:world_stone_pavement:2)
Block(-3,4,6,quark:world_stone_pavement:2)
Block(-3,4,7,quark:world_stone_pavement:2)
Block(-3,4,8,quark:world_stone_pavement:2)
Block(-3,5,-7,contenttweaker:reinforced_concrete:0)
Block(-3,5,-6,quark:world_stone_pavement:2)
Block(-3,5,-5,contenttweaker:reinforced_concrete:0)
Block(-3,5,-4,contenttweaker:reinforced_concrete:0)
Block(-3,5,-3,contenttweaker:reinforced_concrete:0)
Block(-3,5,-2,contenttweaker:reinforced_concrete:0)
Block(-3,5,-1,quark:world_stone_pavement:2)
Block(-3,5,0,contenttweaker:reinforced_concrete:0)
Block(-3,5,1,quark:world_stone_pavement:2)
Block(-3,5,2,quark:world_stone_pavement:2)
Block(-3,5,3,contenttweaker:reinforced_concrete:0)
Block(-3,5,4,quark:world_stone_pavement:2)
Block(-3,5,5,quark:world_stone_pavement:2)
Block(-3,5,6,contenttweaker:reinforced_concrete:0)
Block(-3,5,7,quark:world_stone_pavement:2)
Block(-3,5,8,quark:world_stone_pavement:2)
Block(-3,6,-7,contenttweaker:reinforced_concrete:0)
Block(-3,6,-6,quark:world_stone_pavement:2)
Block(-3,6,-5,quark:world_stone_pavement:2)
Block(-3,6,-4,contenttweaker:reinforced_concrete:0)
Block(-3,6,-3,contenttweaker:reinforced_concrete:0)
Block(-3,6,-2,contenttweaker:reinforced_concrete:0)
Block(-3,6,-1,quark:world_stone_pavement:2)
Block(-3,6,0,contenttweaker:reinforced_concrete:0)
Block(-3,6,1,quark:world_stone_pavement:2)
Block(-3,6,2,quark:world_stone_pavement:2)
Block(-3,6,3,contenttweaker:reinforced_concrete:0)
Block(-3,6,4,quark:world_stone_pavement:2)
Block(-3,6,5,quark:world_stone_pavement:2)
Block(-3,6,6,contenttweaker:reinforced_concrete:0)
Block(-3,6,7,quark:world_stone_pavement:2)
Block(-3,6,8,contenttweaker:reinforced_concrete:0)
Block(-3,7,-7,contenttweaker:reinforced_concrete:0)
Block(-3,7,-6,contenttweaker:reinforced_concrete:0)
Block(-3,7,-5,contenttweaker:reinforced_concrete:0)
Block(-3,7,-4,contenttweaker:reinforced_concrete:0)
Block(-3,7,-3,contenttweaker:reinforced_concrete:0)
Block(-3,7,-2,contenttweaker:reinforced_concrete:0)
Block(-3,7,-1,contenttweaker:reinforced_concrete:0)
Block(-3,7,0,quark:world_stone_pavement:2)
Block(-3,7,1,contenttweaker:reinforced_concrete:0)
Block(-3,7,2,contenttweaker:reinforced_concrete:0)
Block(-3,7,3,quark:world_stone_pavement:2)
Block(-3,7,4,contenttweaker:reinforced_concrete:0)
Block(-3,7,5,contenttweaker:reinforced_concrete:0)
Block(-3,7,6,contenttweaker:reinforced_concrete:0)
Block(-3,7,7,contenttweaker:reinforced_concrete:0)
Block(-3,7,8,contenttweaker:reinforced_concrete:0)
Block(-3,8,-7,quark:world_stone_pavement:2)
Block(-3,8,-6,quark:world_stone_pavement:2)
Block(-3,8,-5,contenttweaker:reinforced_concrete:0)
Block(-3,8,-4,contenttweaker:reinforced_concrete:0)
Block(-3,8,-3,quark:world_stone_pavement:2)
Block(-3,8,-2,contenttweaker:reinforced_concrete:0)
Block(-3,8,-1,quark:world_stone_pavement:2)
Block(-3,8,0,quark:world_stone_pavement:2)
Block(-3,8,1,contenttweaker:reinforced_concrete:0)
Block(-3,8,2,contenttweaker:reinforced_concrete:0)
Block(-3,8,3,contenttweaker:reinforced_concrete:0)
Block(-3,8,4,quark:world_stone_pavement:2)
Block(-3,8,5,quark:world_stone_pavement:2)
Block(-3,8,6,contenttweaker:reinforced_concrete:0)
Block(-3,8,7,quark:world_stone_pavement:2)
Block(-3,8,8,quark:world_stone_pavement:2)
Block(-3,9,-7,quark:world_stone_pavement:2)
Block(-3,9,-6,contenttweaker:reinforced_concrete:0)
Block(-3,9,-5,quark:world_stone_pavement:2)
Block(-3,9,-4,contenttweaker:reinforced_concrete:0)
Block(-3,9,-3,contenttweaker:reinforced_concrete:0)
Block(-3,9,-2,contenttweaker:reinforced_concrete:0)
Block(-3,9,-1,quark:polished_stone:0)
Block(-3,9,0,quark:world_stone_pavement:2)
Block(-3,9,1,contenttweaker:reinforced_concrete:0)
Block(-3,9,2,quark:world_stone_pavement:2)
Block(-3,9,3,contenttweaker:reinforced_concrete:0)
Block(-3,9,4,quark:world_stone_pavement:2)
Block(-3,9,5,quark:world_stone_pavement:2)
Block(-3,9,6,contenttweaker:reinforced_concrete:0)
Block(-3,9,7,contenttweaker:reinforced_concrete:0)
Block(-3,9,8,contenttweaker:reinforced_concrete:0)
Block(-3,10,-7,contenttweaker:reinforced_concrete:0)
Block(-3,10,-6,quark:world_stone_pavement:2)
Block(-3,10,-5,quark:world_stone_pavement:2)
Block(-3,10,-4,quark:world_stone_pavement:2)
Block(-3,10,-3,contenttweaker:reinforced_concrete:0)
Block(-3,10,-2,quark:world_stone_pavement:2)
Block(-3,10,-1,quark:world_stone_pavement:2)
Block(-3,10,0,quark:polished_stone:0)
Block(-3,10,1,quark:iron_plate:0)
Block(-3,10,2,contenttweaker:reinforced_concrete:0)
Block(-3,10,3,contenttweaker:reinforced_concrete:0)
Block(-3,10,4,contenttweaker:reinforced_concrete:0)
Block(-3,10,5,contenttweaker:reinforced_concrete:0)
Block(-3,10,6,contenttweaker:reinforced_concrete:0)
Block(-3,10,7,contenttweaker:reinforced_concrete:0)
Block(-3,10,8,quark:world_stone_pavement:2)
Block(-3,11,-7,quark:world_stone_pavement:2)
Block(-3,11,-6,quark:world_stone_pavement:2)
Block(-3,11,-5,quark:world_stone_pavement:2)
Block(-3,11,-4,contenttweaker:reinforced_concrete:0)
Block(-3,11,-3,contenttweaker:reinforced_concrete:0)
Block(-3,11,-2,quark:iron_plate:0)
Block(-3,12,-7,DOUBLE_STEP:0)
Block(-3,12,-6,DOUBLE_STEP:0)
Block(-3,12,-5,DOUBLE_STEP:0)
Block(-3,12,-4,DOUBLE_STEP:0)
Block(-3,12,-3,quark:world_stone_pavement:2)
Block(-3,12,-2,quark:iron_plate:0)
Block(-3,13,-7,DOUBLE_STEP:0)
Block(-3,13,-6,SMOOTH_STAIRS:0)
Block(-3,13,-5,SMOOTH_STAIRS:0)
Block(-3,13,-4,SMOOTH_STAIRS:0)
RandomBlock(-3,13,-3,contenttweaker:reinforced_concrete:0,40,SMOOTH_BRICK:1,30,SMOOTH_BRICK:2,30,MOSSY_COBBLESTONE:0,30,COBBLESTONE:0,20,contenttweaker:reinforced_concrete:0,100)
Block(-3,13,-2,SMOOTH_STAIRS:1)
Block(-3,14,-7,STEP:0)
Block(-3,14,-6,STEP:0)
Block(-3,14,-5,STEP:0)
Block(-3,14,-4,STEP:0)
RandomBlock(-3,14,-3,contenttweaker:reinforced_concrete:0,40,SMOOTH_BRICK:1,30,SMOOTH_BRICK:2,30,MOSSY_COBBLESTONE:0,30,COBBLESTONE:0,20,contenttweaker:reinforced_concrete:0,100)
RandomBlock(-3,15,-3,contenttweaker:reinforced_concrete:0,40,SMOOTH_BRICK:1,30,SMOOTH_BRICK:2,30,MOSSY_COBBLESTONE:0,30,COBBLESTONE:0,20,contenttweaker:reinforced_concrete:0,100)
Block(-3,15,-2,quark:grate:0)
Block(-3,15,-1,quark:iron_plate:1)
RandomBlock(-3,16,-3,contenttweaker:reinforced_concrete:0,40,SMOOTH_BRICK:1,30,SMOOTH_BRICK:2,30,MOSSY_COBBLESTONE:0,30,COBBLESTONE:0,20,contenttweaker:reinforced_concrete:0,100)
Block(-3,16,-2,LEVER:4)
RandomBlock(-3,16,-1,contenttweaker:reinforced_concrete:0,40,SMOOTH_BRICK:1,30,SMOOTH_BRICK:2,30,MOSSY_COBBLESTONE:0,30,COBBLESTONE:0,20,contenttweaker:reinforced_concrete:0,100)
RandomBlock(-3,17,-3,contenttweaker:reinforced_concrete:0,40,SMOOTH_BRICK:1,30,SMOOTH_BRICK:2,30,MOSSY_COBBLESTONE:0,30,COBBLESTONE:0,20,contenttweaker:reinforced_concrete:0,100)
Block(-3,17,-1,nuclearcraft:radiation_scrubber:0)
RandomBlock(-3,18,-3,contenttweaker:reinforced_concrete:0,40,SMOOTH_BRICK:1,30,SMOOTH_BRICK:2,30,MOSSY_COBBLESTONE:0,30,COBBLESTONE:0,20,contenttweaker:reinforced_concrete:0,100)
Block(-3,19,-3,quark:iron_plate:1)
Block(-3,20,-3,STEP:0)
RandomBlock(-3,20,-2,contenttweaker:reinforced_concrete:0,40,SMOOTH_BRICK:1,30,SMOOTH_BRICK:2,30,MOSSY_COBBLESTONE:0,30,COBBLESTONE:0,20,contenttweaker:reinforced_concrete:0,100)
Block(-3,21,-2,STEP:0)
Block(-3,21,-1,quark:iron_plate:1)
Block(-3,21,0,STEP:0)
RandomBlock(-3,22,0,contenttweaker:reinforced_concrete:0,40,SMOOTH_BRICK:1,30,SMOOTH_BRICK:2,30,MOSSY_COBBLESTONE:0,30,COBBLESTONE:0,20,contenttweaker:reinforced_concrete:0,100)
Block(-3,23,0,quark:framed_glass:0)
Block(-3,24,0,quark:framed_glass:0)
Block(-3,25,0,DOUBLE_STEP:0)
RandomBlock(-3,26,0,contenttweaker:reinforced_concrete:0,40,SMOOTH_BRICK:1,30,SMOOTH_BRICK:2,30,MOSSY_COBBLESTONE:0,30,COBBLESTONE:0,20,contenttweaker:reinforced_concrete:0,100)
Block(-3,27,0,quark:sturdy_stone:0)
Block(-3,28,0,SMOOTH_STAIRS:2)
Block(-3,28,1,STEP:0)
Block(-3,28,3,STEP:0)
Block(-3,28,5,STEP:0)
Block(-3,28,7,STEP:0)
Block(-3,29,1,SMOOTH_STAIRS:2)
Block(-3,29,2,DOUBLE_STEP:0)
Block(-3,29,3,DOUBLE_STEP:0)
Block(-3,29,4,DOUBLE_STEP:0)
Block(-3,29,5,quark:world_stone_pavement:2)
Block(-3,29,6,quark:polished_stone:0)
Block(-3,29,7,quark:polished_stone:0)
Block(-3,29,8,contenttweaker:reinforced_concrete:0)
Block(-3,30,2,quark:stone_diorite_bricks_wall:0)
Block(-3,30,8,STEP:0)
Block(-2,0,-7,quark:world_stone_pavement:2)
Block(-2,0,-6,contenttweaker:reinforced_concrete:0)
Block(-2,0,-5,quark:world_stone_pavement:2)
Block(-2,0,-4,contenttweaker:reinforced_concrete:0)
Block(-2,0,-3,quark:world_stone_pavement:2)
Block(-2,0,-2,contenttweaker:reinforced_concrete:0)
Block(-2,0,-1,contenttweaker:reinforced_concrete:0)
Block(-2,0,0,quark:world_stone_pavement:2)
Block(-2,0,1,quark:world_stone_pavement:2)
Block(-2,0,2,contenttweaker:reinforced_concrete:0)
Block(-2,0,3,quark:world_stone_pavement:2)
Block(-2,0,4,contenttweaker:reinforced_concrete:0)
Block(-2,0,5,quark:world_stone_pavement:2)
Block(-2,0,6,quark:world_stone_pavement:2)
Block(-2,0,7,contenttweaker:reinforced_concrete:0)
Block(-2,0,8,contenttweaker:reinforced_concrete:0)
Block(-2,1,-7,quark:world_stone_pavement:2)
Block(-2,1,-6,contenttweaker:reinforced_concrete:0)
Block(-2,1,-5,contenttweaker:reinforced_concrete:0)
Block(-2,1,-4,contenttweaker:reinforced_concrete:0)
Block(-2,1,-3,quark:world_stone_pavement:2)
Block(-2,1,-2,quark:world_stone_pavement:2)
Block(-2,1,-1,contenttweaker:reinforced_concrete:0)
Block(-2,1,0,contenttweaker:reinforced_concrete:0)
Block(-2,1,1,quark:world_stone_pavement:2)
Block(-2,1,2,contenttweaker:reinforced_concrete:0)
Block(-2,1,3,quark:world_stone_pavement:2)
Block(-2,1,4,quark:world_stone_pavement:2)
Block(-2,1,5,quark:world_stone_pavement:2)
Block(-2,1,6,quark:world_stone_pavement:2)
Block(-2,1,7,contenttweaker:reinforced_concrete:0)
Block(-2,1,8,contenttweaker:reinforced_concrete:0)
Block(-2,2,-7,quark:world_stone_pavement:2)
Block(-2,2,-6,quark:world_stone_pavement:2)
Block(-2,2,-5,contenttweaker:reinforced_concrete:0)
Block(-2,2,-4,contenttweaker:reinforced_concrete:0)
Block(-2,2,-3,quark:world_stone_pavement:2)
Block(-2,2,-2,contenttweaker:reinforced_concrete:0)
Block(-2,2,-1,quark:world_stone_pavement:2)
Block(-2,2,0,contenttweaker:reinforced_concrete:0)
Block(-2,2,1,quark:world_stone_pavement:2)
Block(-2,2,2,contenttweaker:reinforced_concrete:0)
Block(-2,2,3,quark:world_stone_pavement:2)
Block(-2,2,4,contenttweaker:reinforced_concrete:0)
Block(-2,2,5,contenttweaker:reinforced_concrete:0)
Block(-2,2,6,quark:world_stone_pavement:2)
Block(-2,2,7,contenttweaker:reinforced_concrete:0)
Block(-2,2,8,contenttweaker:reinforced_concrete:0)
Block(-2,3,-7,quark:world_stone_pavement:2)
Block(-2,3,-6,contenttweaker:reinforced_concrete:0)
Block(-2,3,-5,quark:world_stone_pavement:2)
Block(-2,3,-4,quark:world_stone_pavement:2)
Block(-2,3,-3,quark:world_stone_pavement:2)
Block(-2,3,-2,quark:world_stone_pavement:2)
Block(-2,3,-1,contenttweaker:reinforced_concrete:0)
Block(-2,3,0,quark:world_stone_pavement:2)
Block(-2,3,1,quark:world_stone_pavement:2)
Block(-2,3,2,contenttweaker:reinforced_concrete:0)
Block(-2,3,3,quark:world_stone_pavement:2)
Block(-2,3,4,contenttweaker:reinforced_concrete:0)
Block(-2,3,5,contenttweaker:reinforced_concrete:0)
Block(-2,3,6,quark:world_stone_pavement:2)
Block(-2,3,7,contenttweaker:reinforced_concrete:0)
Block(-2,3,8,contenttweaker:reinforced_concrete:0)
Block(-2,4,-7,quark:world_stone_pavement:2)
Block(-2,4,-6,contenttweaker:reinforced_concrete:0)
Block(-2,4,-5,contenttweaker:reinforced_concrete:0)
Block(-2,4,-4,contenttweaker:reinforced_concrete:0)
Block(-2,4,-3,quark:world_stone_pavement:2)
Block(-2,4,-2,quark:world_stone_pavement:2)
Block(-2,4,-1,contenttweaker:reinforced_concrete:0)
Block(-2,4,0,contenttweaker:reinforced_concrete:0)
Block(-2,4,1,quark:world_stone_pavement:2)
Block(-2,4,2,contenttweaker:reinforced_concrete:0)
Block(-2,4,3,quark:world_stone_pavement:2)
Block(-2,4,4,quark:world_stone_pavement:2)
Block(-2,4,5,contenttweaker:reinforced_concrete:0)
Block(-2,4,6,quark:world_stone_pavement:2)
Block(-2,4,7,contenttweaker:reinforced_concrete:0)
Block(-2,4,8,quark:world_stone_pavement:2)
Block(-2,5,-7,quark:world_stone_pavement:2)
Block(-2,5,-6,quark:world_stone_pavement:2)
Block(-2,5,-5,quark:world_stone_pavement:2)
Block(-2,5,-4,quark:world_stone_pavement:2)
Block(-2,5,-3,quark:world_stone_pavement:2)
Block(-2,5,-2,contenttweaker:reinforced_concrete:0)
Block(-2,5,-1,contenttweaker:reinforced_concrete:0)
Block(-2,5,0,quark:world_stone_pavement:2)
Block(-2,5,1,quark:world_stone_pavement:2)
Block(-2,5,2,contenttweaker:reinforced_concrete:0)
Block(-2,5,3,quark:world_stone_pavement:2)
Block(-2,5,4,quark:world_stone_pavement:2)
Block(-2,5,5,contenttweaker:reinforced_concrete:0)
Block(-2,5,6,quark:world_stone_pavement:2)
Block(-2,5,7,contenttweaker:reinforced_concrete:0)
Block(-2,5,8,quark:world_stone_pavement:2)
Block(-2,6,-7,quark:world_stone_pavement:2)
Block(-2,6,-6,contenttweaker:reinforced_concrete:0)
Block(-2,6,-5,contenttweaker:reinforced_concrete:0)
Block(-2,6,-4,contenttweaker:reinforced_concrete:0)
Block(-2,6,-3,quark:world_stone_pavement:2)
Block(-2,6,-2,contenttweaker:reinforced_concrete:0)
Block(-2,6,-1,contenttweaker:reinforced_concrete:0)
Block(-2,6,0,contenttweaker:reinforced_concrete:0)
Block(-2,6,1,quark:world_stone_pavement:2)
Block(-2,6,2,contenttweaker:reinforced_concrete:0)
Block(-2,6,3,quark:world_stone_pavement:2)
Block(-2,6,4,contenttweaker:reinforced_concrete:0)
Block(-2,6,5,contenttweaker:reinforced_concrete:0)
Block(-2,6,6,quark:world_stone_pavement:2)
Block(-2,6,7,contenttweaker:reinforced_concrete:0)
Block(-2,6,8,contenttweaker:reinforced_concrete:0)
Block(-2,7,-7,contenttweaker:reinforced_concrete:0)
Block(-2,7,-6,contenttweaker:reinforced_concrete:0)
Block(-2,7,-5,contenttweaker:reinforced_concrete:0)
Block(-2,7,-4,contenttweaker:reinforced_concrete:0)
Block(-2,7,-3,contenttweaker:reinforced_concrete:0)
Block(-2,7,-2,contenttweaker:reinforced_concrete:0)
Block(-2,7,-1,quark:world_stone_pavement:2)
Block(-2,7,0,contenttweaker:reinforced_concrete:0)
Block(-2,7,1,quark:world_stone_pavement:2)
Block(-2,7,2,contenttweaker:reinforced_concrete:0)
Block(-2,7,3,quark:world_stone_pavement:2)
Block(-2,7,4,contenttweaker:reinforced_concrete:0)
Block(-2,7,5,contenttweaker:reinforced_concrete:0)
Block(-2,7,6,contenttweaker:reinforced_concrete:0)
Block(-2,7,7,contenttweaker:reinforced_concrete:0)
Block(-2,7,8,contenttweaker:reinforced_concrete:0)
Block(-2,8,-7,contenttweaker:reinforced_concrete:0)
Block(-2,8,-6,quark:world_stone_pavement:2)
Block(-2,8,-5,contenttweaker:reinforced_concrete:0)
Block(-2,8,-4,contenttweaker:reinforced_concrete:0)
Block(-2,8,-3,contenttweaker:reinforced_concrete:0)
Block(-2,8,-2,contenttweaker:reinforced_concrete:0)
Block(-2,8,-1,contenttweaker:reinforced_concrete:0)
Block(-2,8,0,contenttweaker:reinforced_concrete:0)
Block(-2,8,1,quark:world_stone_pavement:2)
Block(-2,8,2,contenttweaker:reinforced_concrete:0)
Block(-2,8,3,contenttweaker:reinforced_concrete:0)
Block(-2,8,4,contenttweaker:reinforced_concrete:0)
Block(-2,8,5,contenttweaker:reinforced_concrete:0)
Block(-2,8,6,contenttweaker:reinforced_concrete:0)
Block(-2,8,7,contenttweaker:reinforced_concrete:0)
Block(-2,8,8,quark:world_stone_pavement:2)
Block(-2,9,-7,contenttweaker:reinforced_concrete:0)
Block(-2,9,-6,quark:world_stone_pavement:2)
Block(-2,9,-5,quark:world_stone_pavement:2)
Block(-2,9,-4,contenttweaker:reinforced_concrete:0)
Block(-2,9,-3,contenttweaker:reinforced_concrete:0)
Block(-2,9,-2,quark:world_stone_pavement:2)
Block(-2,9,-1,quark:polished_stone:0)
Block(-2,9,0,quark:world_stone_pavement:2)
Block(-2,9,1,contenttweaker:reinforced_concrete:0)
Block(-2,9,2,quark:world_stone_pavement:2)
Block(-2,9,3,contenttweaker:reinforced_concrete:0)
Block(-2,9,4,MOB_SPAWNER:0,../../ruins_spawners/brutal_multi.nbt)
Block(-2,9,5,contenttweaker:reinforced_concrete:0)
Block(-2,9,6,contenttweaker:reinforced_concrete:0)
Block(-2,9,7,contenttweaker:reinforced_concrete:0)
Block(-2,9,8,quark:world_stone_pavement:2)
Block(-2,10,-7,contenttweaker:reinforced_concrete:0)
Block(-2,10,-6,contenttweaker:reinforced_concrete:0)
Block(-2,10,-5,contenttweaker:reinforced_concrete:0)
Block(-2,10,-4,quark:world_stone_pavement:2)
Block(-2,10,-3,contenttweaker:reinforced_concrete:0)
Block(-2,10,-2,quark:polished_stone:0)
Block(-2,10,-1,quark:polished_stone:0)
Block(-2,10,0,quark:world_stone_pavement:2)
Block(-2,10,1,quark:iron_plate:0)
Block(-2,10,2,contenttweaker:reinforced_concrete:0)
Block(-2,10,3,quark:world_stone_pavement:2)
Block(-2,10,4,quark:world_stone_pavement:2)
Block(-2,10,5,contenttweaker:reinforced_concrete:0)
Block(-2,10,6,quark:world_stone_pavement:2)
Block(-2,10,7,contenttweaker:reinforced_concrete:0)
Block(-2,10,8,quark:world_stone_pavement:2)
Block(-2,11,-7,quark:world_stone_pavement:2)
Block(-2,11,-3,contenttweaker:reinforced_concrete:0)
Block(-2,11,-2,quark:basalt_wall:0)
Block(-2,11,1,quark:iron_plate:0)
Block(-2,11,5,AIR:0)
Block(-2,12,-7,DOUBLE_STEP:0)
Block(-2,12,-3,DOUBLE_STEP:0)
Block(-2,12,-2,quark:basalt_wall:0)
Block(-2,12,1,quark:iron_plate:0)
Block(-2,12,5,AIR:0)
Block(-2,13,-7,SMOOTH_STAIRS:2)
Block(-2,13,-6,STEP:0)
Block(-2,13,-5,STEP:0)
Block(-2,13,-4,STEP:0)
Block(-2,13,-3,DOUBLE_STEP:0)
Block(-2,13,-2,quark:basalt_wall:0)
Block(-2,13,5,AIR:0)
Block(-2,14,-7,STEP:0)
Block(-2,14,-6,quark:iron_plate:1)
Block(-2,14,-5,quark:iron_plate:1)
Block(-2,14,-4,quark:iron_plate:1)
Block(-2,14,-3,DOUBLE_STEP:0)
Block(-2,15,-3,DOUBLE_STEP:0)
Block(-2,15,-2,quark:grate:0)
Block(-2,15,-1,quark:iron_plate:1)
Block(-2,16,-3,DOUBLE_STEP:0)
RandomBlock(-2,16,-1,rustic:iron_lattice:0,30,rustic:iron_lattice:1,100)
Block(-2,17,-3,DOUBLE_STEP:0)
RandomBlock(-2,17,-1,rustic:iron_lattice:0,30,rustic:iron_lattice:1,100)
Block(-2,18,-3,DOUBLE_STEP:0)
Block(-2,19,-3,quark:iron_plate:1)
Block(-2,20,-3,STEP:0)
RandomBlock(-2,20,-2,contenttweaker:reinforced_concrete:0,40,SMOOTH_BRICK:1,30,SMOOTH_BRICK:2,30,MOSSY_COBBLESTONE:0,30,COBBLESTONE:0,20,contenttweaker:reinforced_concrete:0,100)
Block(-2,21,-2,DOUBLE_STEP:0)
Block(-2,21,-1,quark:iron_plate:1)
Block(-2,21,0,STEP:0)
Block(-2,22,-2,quark:iron_plate:1)
Block(-2,22,-1,STEP:0)
Block(-2,22,0,DOUBLE_STEP:0)
Block(-2,23,-2,DOUBLE_STEP:0)
Block(-2,23,-1,STEP:0)
Block(-2,23,0,DOUBLE_STEP:0)
Block(-2,24,-2,DOUBLE_STEP:0)
Block(-2,24,0,DOUBLE_STEP:0)
Block(-2,25,-2,DOUBLE_STEP:0)
Block(-2,25,-1,STEP:0)
RandomBlock(-2,25,0,contenttweaker:reinforced_concrete:0,40,SMOOTH_BRICK:1,30,SMOOTH_BRICK:2,30,MOSSY_COBBLESTONE:0,30,COBBLESTONE:0,20,contenttweaker:reinforced_concrete:0,100)
Block(-2,26,-2,STEP:0)
Block(-2,26,-1,DOUBLE_STEP:0)
RandomBlock(-2,26,0,contenttweaker:reinforced_concrete:0,40,SMOOTH_BRICK:1,30,SMOOTH_BRICK:2,30,MOSSY_COBBLESTONE:0,30,COBBLESTONE:0,20,contenttweaker:reinforced_concrete:0,100)
Block(-2,27,-1,STEP:0)
Block(-2,27,0,quark:sturdy_stone:0)
Block(-2,28,0,SMOOTH_STAIRS:2)
Block(-2,28,1,STEP:0)
Block(-2,28,2,STEP:0)
Block(-2,28,3,STEP:0)
Block(-2,28,4,STEP:0)
Block(-2,28,5,STEP:0)
Block(-2,28,6,STEP:0)
Block(-2,28,7,STEP:0)
Block(-2,28,8,STEP:0)
Block(-2,29,1,SMOOTH_STAIRS:2)
Block(-2,29,2,DOUBLE_STEP:0)
Block(-2,29,3,DOUBLE_STEP:0)
Block(-2,29,4,DOUBLE_STEP:0)
Block(-2,29,5,quark:world_stone_pavement:2)
RandomBlock(-2,29,6,contenttweaker:reinforced_concrete:0,40,SMOOTH_BRICK:1,30,SMOOTH_BRICK:2,30,MOSSY_COBBLESTONE:0,30,COBBLESTONE:0,20,contenttweaker:reinforced_concrete:0,100)
RandomBlock(-2,29,7,contenttweaker:reinforced_concrete:0,40,SMOOTH_BRICK:1,30,SMOOTH_BRICK:2,30,MOSSY_COBBLESTONE:0,30,COBBLESTONE:0,20,contenttweaker:reinforced_concrete:0,100)
RandomBlock(-2,29,8,contenttweaker:reinforced_concrete:0,40,SMOOTH_BRICK:1,30,SMOOTH_BRICK:2,30,MOSSY_COBBLESTONE:0,30,COBBLESTONE:0,20,contenttweaker:reinforced_concrete:0,100)
Block(-2,30,2,quark:stone_diorite_bricks_wall:0)
Block(-2,30,6,quark:iron_plate:1)
Block(-2,30,8,STEP:0)
Block(-2,31,6,quark:iron_plate:1)
Block(-2,31,7,quark:iron_plate:1)
Block(-2,31,8,quark:iron_plate:1)
Block(-1,0,-7,contenttweaker:reinforced_concrete:0)
Block(-1,0,-6,contenttweaker:reinforced_concrete:0)
Block(-1,0,-5,contenttweaker:reinforced_concrete:0)
Block(-1,0,-4,contenttweaker:reinforced_concrete:0)
Block(-1,0,-3,contenttweaker:reinforced_concrete:0)
Block(-1,0,-2,quark:world_stone_pavement:2)
Block(-1,0,-1,quark:world_stone_pavement:2)
Block(-1,0,0,quark:world_stone_pavement:2)
Block(-1,0,1,quark:world_stone_pavement:2)
Block(-1,0,2,contenttweaker:reinforced_concrete:0)
Block(-1,0,3,contenttweaker:reinforced_concrete:0)
Block(-1,0,4,quark:world_stone_pavement:2)
Block(-1,0,5,contenttweaker:reinforced_concrete:0)
Block(-1,0,6,quark:world_stone_pavement:2)
Block(-1,0,7,quark:world_stone_pavement:2)
Block(-1,0,8,contenttweaker:reinforced_concrete:0)
Block(-1,1,-7,contenttweaker:reinforced_concrete:0)
Block(-1,1,-6,quark:world_stone_pavement:2)
Block(-1,1,-5,contenttweaker:reinforced_concrete:0)
Block(-1,1,-4,contenttweaker:reinforced_concrete:0)
Block(-1,1,-3,contenttweaker:reinforced_concrete:0)
Block(-1,1,-2,quark:world_stone_pavement:2)
Block(-1,1,-1,quark:world_stone_pavement:2)
Block(-1,1,0,contenttweaker:reinforced_concrete:0)
Block(-1,1,1,contenttweaker:reinforced_concrete:0)
Block(-1,1,2,quark:world_stone_pavement:2)
Block(-1,1,3,contenttweaker:reinforced_concrete:0)
Block(-1,1,4,quark:world_stone_pavement:2)
Block(-1,1,5,quark:world_stone_pavement:2)
Block(-1,1,6,contenttweaker:reinforced_concrete:0)
Block(-1,1,7,contenttweaker:reinforced_concrete:0)
Block(-1,1,8,contenttweaker:reinforced_concrete:0)
Block(-1,2,-7,quark:world_stone_pavement:2)
Block(-1,2,-6,contenttweaker:reinforced_concrete:0)
Block(-1,2,-5,contenttweaker:reinforced_concrete:0)
Block(-1,2,-4,quark:world_stone_pavement:2)
Block(-1,2,-3,contenttweaker:reinforced_concrete:0)
Block(-1,2,-2,quark:world_stone_pavement:2)
Block(-1,2,-1,quark:world_stone_pavement:2)
Block(-1,2,0,contenttweaker:reinforced_concrete:0)
Block(-1,2,1,contenttweaker:reinforced_concrete:0)
Block(-1,2,2,quark:world_stone_pavement:2)
Block(-1,2,3,quark:world_stone_pavement:2)
Block(-1,2,4,quark:world_stone_pavement:2)
Block(-1,2,5,quark:world_stone_pavement:2)
Block(-1,2,6,contenttweaker:reinforced_concrete:0)
Block(-1,2,7,contenttweaker:reinforced_concrete:0)
Block(-1,2,8,contenttweaker:reinforced_concrete:0)
Block(-1,3,-7,contenttweaker:reinforced_concrete:0)
Block(-1,3,-6,quark:world_stone_pavement:2)
Block(-1,3,-5,contenttweaker:reinforced_concrete:0)
Block(-1,3,-4,quark:world_stone_pavement:2)
Block(-1,3,-3,contenttweaker:reinforced_concrete:0)
Block(-1,3,-2,quark:world_stone_pavement:2)
Block(-1,3,-1,quark:world_stone_pavement:2)
Block(-1,3,0,quark:world_stone_pavement:2)
Block(-1,3,1,contenttweaker:reinforced_concrete:0)
Block(-1,3,2,contenttweaker:reinforced_concrete:0)
Block(-1,3,3,contenttweaker:reinforced_concrete:0)
Block(-1,3,4,quark:world_stone_pavement:2)
Block(-1,3,5,quark:world_stone_pavement:2)
Block(-1,3,6,quark:world_stone_pavement:2)
Block(-1,3,7,quark:world_stone_pavement:2)
Block(-1,3,8,contenttweaker:reinforced_concrete:0)
Block(-1,4,-7,contenttweaker:reinforced_concrete:0)
Block(-1,4,-6,contenttweaker:reinforced_concrete:0)
Block(-1,4,-5,contenttweaker:reinforced_concrete:0)
Block(-1,4,-4,contenttweaker:reinforced_concrete:0)
Block(-1,4,-3,quark:world_stone_pavement:2)
Block(-1,4,-2,quark:world_stone_pavement:2)
Block(-1,4,-1,quark:world_stone_pavement:2)
Block(-1,4,0,contenttweaker:reinforced_concrete:0)
Block(-1,4,1,contenttweaker:reinforced_concrete:0)
Block(-1,4,2,quark:world_stone_pavement:2)
Block(-1,4,3,quark:world_stone_pavement:2)
Block(-1,4,4,quark:world_stone_pavement:2)
Block(-1,4,5,contenttweaker:reinforced_concrete:0)
Block(-1,4,6,quark:world_stone_pavement:2)
Block(-1,4,7,contenttweaker:reinforced_concrete:0)
Block(-1,4,8,contenttweaker:reinforced_concrete:0)
Block(-1,5,-7,contenttweaker:reinforced_concrete:0)
Block(-1,5,-6,quark:world_stone_pavement:2)
Block(-1,5,-5,contenttweaker:reinforced_concrete:0)
Block(-1,5,-4,contenttweaker:reinforced_concrete:0)
Block(-1,5,-3,quark:world_stone_pavement:2)
Block(-1,5,-2,quark:world_stone_pavement:2)
Block(-1,5,-1,quark:world_stone_pavement:2)
Block(-1,5,0,quark:world_stone_pavement:2)
Block(-1,5,1,contenttweaker:reinforced_concrete:0)
Block(-1,5,2,quark:world_stone_pavement:2)
Block(-1,5,3,quark:world_stone_pavement:2)
Block(-1,5,4,quark:world_stone_pavement:2)
Block(-1,5,5,contenttweaker:reinforced_concrete:0)
Block(-1,5,6,contenttweaker:reinforced_concrete:0)
Block(-1,5,7,contenttweaker:reinforced_concrete:0)
Block(-1,5,8,quark:world_stone_pavement:2)
Block(-1,6,-7,contenttweaker:reinforced_concrete:0)
Block(-1,6,-6,contenttweaker:reinforced_concrete:0)
Block(-1,6,-5,contenttweaker:reinforced_concrete:0)
Block(-1,6,-4,quark:world_stone_pavement:2)
Block(-1,6,-3,quark:world_stone_pavement:2)
Block(-1,6,-2,quark:world_stone_pavement:2)
Block(-1,6,-1,quark:world_stone_pavement:2)
Block(-1,6,0,contenttweaker:reinforced_concrete:0)
Block(-1,6,1,quark:world_stone_pavement:2)
Block(-1,6,2,contenttweaker:reinforced_concrete:0)
Block(-1,6,3,quark:world_stone_pavement:2)
Block(-1,6,4,quark:world_stone_pavement:2)
Block(-1,6,5,quark:world_stone_pavement:2)
Block(-1,6,6,contenttweaker:reinforced_concrete:0)
Block(-1,6,7,quark:world_stone_pavement:2)
Block(-1,6,8,quark:world_stone_pavement:2)
Block(-1,7,-7,contenttweaker:reinforced_concrete:0)
Block(-1,7,-6,quark:world_stone_pavement:2)
Block(-1,7,-5,contenttweaker:reinforced_concrete:0)
Block(-1,7,-4,quark:world_stone_pavement:2)
Block(-1,7,-3,contenttweaker:reinforced_concrete:0)
Block(-1,7,-2,contenttweaker:reinforced_concrete:0)
Block(-1,7,-1,contenttweaker:reinforced_concrete:0)
Block(-1,7,0,contenttweaker:reinforced_concrete:0)
Block(-1,7,1,quark:world_stone_pavement:2)
Block(-1,7,2,quark:world_stone_pavement:2)
Block(-1,7,3,contenttweaker:reinforced_concrete:0)
Block(-1,7,4,quark:world_stone_pavement:2)
Block(-1,7,5,contenttweaker:reinforced_concrete:0)
Block(-1,7,6,quark:world_stone_pavement:2)
Block(-1,7,7,contenttweaker:reinforced_concrete:0)
Block(-1,7,8,contenttweaker:reinforced_concrete:0)
Block(-1,8,-7,contenttweaker:reinforced_concrete:0)
Block(-1,8,-6,contenttweaker:reinforced_concrete:0)
Block(-1,8,-5,quark:world_stone_pavement:2)
Block(-1,8,-4,contenttweaker:reinforced_concrete:0)
Block(-1,8,-3,contenttweaker:reinforced_concrete:0)
Block(-1,8,-2,quark:world_stone_pavement:2)
Block(-1,8,-1,quark:world_stone_pavement:2)
Block(-1,8,0,contenttweaker:reinforced_concrete:0)
Block(-1,8,1,contenttweaker:reinforced_concrete:0)
Block(-1,8,2,contenttweaker:reinforced_concrete:0)
Block(-1,8,3,contenttweaker:reinforced_concrete:0)
Block(-1,8,4,quark:world_stone_pavement:2)
Block(-1,8,5,contenttweaker:reinforced_concrete:0)
Block(-1,8,6,quark:world_stone_pavement:2)
Block(-1,8,7,quark:world_stone_pavement:2)
Block(-1,8,8,contenttweaker:reinforced_concrete:0)
Block(-1,9,-7,contenttweaker:reinforced_concrete:0)
Block(-1,9,-6,quark:world_stone_pavement:2)
Block(-1,9,-5,quark:world_stone_pavement:2)
Block(-1,9,-4,contenttweaker:reinforced_concrete:0)
Block(-1,9,-3,quark:world_stone_pavement:2)
Block(-1,9,-2,quark:polished_stone:0)
Block(-1,9,-1,quark:polished_stone:0)
Block(-1,9,0,quark:world_stone_pavement:2)
Block(-1,9,1,quark:world_stone_pavement:2)
Block(-1,9,2,contenttweaker:reinforced_concrete:0)
Block(-1,9,3,contenttweaker:reinforced_concrete:0)
Block(-1,9,4,contenttweaker:reinforced_concrete:0)
Block(-1,9,5,contenttweaker:reinforced_concrete:0)
Block(-1,9,6,quark:world_stone_pavement:2)
Block(-1,9,7,quark:world_stone_pavement:2)
Block(-1,9,8,quark:world_stone_pavement:2)
Block(-1,10,-7,contenttweaker:reinforced_concrete:0)
Block(-1,10,-6,contenttweaker:reinforced_concrete:0)
Block(-1,10,-5,quark:world_stone_pavement:2)
Block(-1,10,-4,contenttweaker:reinforced_concrete:0)
Block(-1,10,-3,quark:polished_stone:0)
Block(-1,10,-2,quark:polished_stone:0)
Block(-1,10,-1,quark:polished_stone:0)
Block(-1,10,0,quark:polished_stone:0)
Block(-1,10,1,quark:polished_stone:0)
Block(-1,10,2,quark:polished_stone:0)
Block(-1,10,3,contenttweaker:reinforced_concrete:0)
Block(-1,10,4,contenttweaker:reinforced_concrete:0)
Block(-1,10,5,contenttweaker:reinforced_concrete:0)
Block(-1,10,6,contenttweaker:reinforced_concrete:0)
Block(-1,10,7,contenttweaker:reinforced_concrete:0)
Block(-1,10,8,contenttweaker:reinforced_concrete:0)
Block(-1,11,-7,contenttweaker:reinforced_concrete:0)
Block(-1,11,-6,quark:iron_plate:1)
Block(-1,11,-5,quark:iron_plate:1)
Block(-1,11,-4,quark:iron_plate:1)
Block(-1,11,-3,quark:world_stone_pavement:2)
Block(-1,12,-7,DOUBLE_STEP:0)
Block(-1,12,-6,quark:basalt_wall:0)
Block(-1,12,-5,quark:basalt_wall:0)
Block(-1,12,-4,quark:basalt_wall:0)
Block(-1,12,-3,quark:world_stone_pavement:2)
Block(-1,12,-1,quark:iron_plate:0)
Block(-1,12,0,quark:iron_plate:0)
Block(-1,12,1,quark:iron_plate:0)
Block(-1,13,-7,SMOOTH_STAIRS:2)
RandomBlock(-1,13,-3,contenttweaker:reinforced_concrete:0,40,SMOOTH_BRICK:1,30,SMOOTH_BRICK:2,30,MOSSY_COBBLESTONE:0,30,COBBLESTONE:0,20,contenttweaker:reinforced_concrete:0,100)
Block(-1,13,-2,quark:basalt_wall:0)
Block(-1,14,-7,STEP:0)
Block(-1,14,-6,quark:iron_plate:1)
Block(-1,14,-5,DISPENSER:1)
Block(-1,14,-4,DISPENSER:1)
RandomBlock(-1,14,-3,contenttweaker:reinforced_concrete:0,40,SMOOTH_BRICK:1,30,SMOOTH_BRICK:2,30,MOSSY_COBBLESTONE:0,30,COBBLESTONE:0,20,contenttweaker:reinforced_concrete:0,100)
Block(-1,15,-5,IRON_TRAPDOOR:0)
Block(-1,15,-4,IRON_TRAPDOOR:0)
RandomBlock(-1,15,-3,contenttweaker:reinforced_concrete:0,40,SMOOTH_BRICK:1,30,SMOOTH_BRICK:2,30,MOSSY_COBBLESTONE:0,30,COBBLESTONE:0,20,contenttweaker:reinforced_concrete:0,100)
Block(-1,15,-2,quark:grate:0)
Block(-1,15,-1,quark:iron_plate:1)
RandomBlock(-1,16,-3,contenttweaker:reinforced_concrete:0,40,SMOOTH_BRICK:1,30,SMOOTH_BRICK:2,30,MOSSY_COBBLESTONE:0,30,COBBLESTONE:0,20,contenttweaker:reinforced_concrete:0,100)
RandomBlock(-1,16,-1,rustic:iron_lattice:0,30,rustic:iron_lattice:1,100)
RandomBlock(-1,17,-3,contenttweaker:reinforced_concrete:0,40,SMOOTH_BRICK:1,30,SMOOTH_BRICK:2,30,MOSSY_COBBLESTONE:0,30,COBBLESTONE:0,20,contenttweaker:reinforced_concrete:0,100)
RandomBlock(-1,17,-1,rustic:iron_lattice:0,30,rustic:iron_lattice:1,100)
RandomBlock(-1,18,-3,contenttweaker:reinforced_concrete:0,40,SMOOTH_BRICK:1,30,SMOOTH_BRICK:2,30,MOSSY_COBBLESTONE:0,30,COBBLESTONE:0,20,contenttweaker:reinforced_concrete:0,100)
Block(-1,19,-3,quark:iron_plate:1)
Block(-1,20,-3,STEP:0)
RandomBlock(-1,20,-2,contenttweaker:reinforced_concrete:0,40,SMOOTH_BRICK:1,30,SMOOTH_BRICK:2,30,MOSSY_COBBLESTONE:0,30,COBBLESTONE:0,20,contenttweaker:reinforced_concrete:0,100)
Block(-1,21,-2,STEP:0)
Block(-1,21,-1,quark:iron_plate:1)
Block(-1,21,0,STEP:0)
RandomBlock(-1,22,0,contenttweaker:reinforced_concrete:0,40,SMOOTH_BRICK:1,30,SMOOTH_BRICK:2,30,MOSSY_COBBLESTONE:0,30,COBBLESTONE:0,20,contenttweaker:reinforced_concrete:0,100)
Block(-1,23,0,quark:framed_glass:0)
Block(-1,24,0,quark:framed_glass:0)
Block(-1,25,0,DOUBLE_STEP:0)
RandomBlock(-1,26,0,contenttweaker:reinforced_concrete:0,40,SMOOTH_BRICK:1,30,SMOOTH_BRICK:2,30,MOSSY_COBBLESTONE:0,30,COBBLESTONE:0,20,contenttweaker:reinforced_concrete:0,100)
Block(-1,27,0,quark:sturdy_stone:0)
Block(-1,28,0,SMOOTH_STAIRS:2)
Block(-1,28,1,STEP:0)
Block(-1,28,3,STEP:0)
Block(-1,28,5,STEP:0)
Block(-1,28,7,STEP:0)
Block(-1,29,1,SMOOTH_STAIRS:2)
Block(-1,29,2,DOUBLE_STEP:0)
Block(-1,29,3,DOUBLE_STEP:0)
Block(-1,29,4,DOUBLE_STEP:0)
Block(-1,29,5,quark:polished_stone:0)
RandomBlock(-1,29,6,contenttweaker:reinforced_concrete:0,40,SMOOTH_BRICK:1,30,SMOOTH_BRICK:2,30,MOSSY_COBBLESTONE:0,30,COBBLESTONE:0,20,contenttweaker:reinforced_concrete:0,100)
RandomBlock(-1,29,7,contenttweaker:reinforced_concrete:0,40,SMOOTH_BRICK:1,30,SMOOTH_BRICK:2,30,MOSSY_COBBLESTONE:0,30,COBBLESTONE:0,20,contenttweaker:reinforced_concrete:0,100)
RandomBlock(-1,29,8,contenttweaker:reinforced_concrete:0,40,SMOOTH_BRICK:1,30,SMOOTH_BRICK:2,30,MOSSY_COBBLESTONE:0,30,COBBLESTONE:0,20,contenttweaker:reinforced_concrete:0,100)
Block(-1,30,2,quark:stone_diorite_bricks_wall:0)
Block(-1,30,8,STEP:0)
Block(0,0,-7,contenttweaker:reinforced_concrete:0)
Block(0,0,-6,contenttweaker:reinforced_concrete:0)
Block(0,0,-5,contenttweaker:reinforced_concrete:0)
Block(0,0,-4,contenttweaker:reinforced_concrete:0)
Block(0,0,-3,quark:world_stone_pavement:2)
Block(0,0,-2,quark:world_stone_pavement:2)
Block(0,0,-1,contenttweaker:reinforced_concrete:0)
Block(0,0,0,quark:world_stone_pavement:2)
Block(0,0,1,contenttweaker:reinforced_concrete:0)
Block(0,0,2,contenttweaker:reinforced_concrete:0)
Block(0,0,3,quark:world_stone_pavement:2)
Block(0,0,4,contenttweaker:reinforced_concrete:0)
Block(0,0,5,quark:world_stone_pavement:2)
Block(0,0,6,contenttweaker:reinforced_concrete:0)
Block(0,0,7,contenttweaker:reinforced_concrete:0)
Block(0,0,8,contenttweaker:reinforced_concrete:0)
Block(0,1,-7,contenttweaker:reinforced_concrete:0)
Block(0,1,-6,contenttweaker:reinforced_concrete:0)
Block(0,1,-5,quark:world_stone_pavement:2)
Block(0,1,-4,quark:world_stone_pavement:2)
Block(0,1,-3,quark:world_stone_pavement:2)
Block(0,1,-2,quark:world_stone_pavement:2)
Block(0,1,-1,contenttweaker:reinforced_concrete:0)
Block(0,1,0,quark:world_stone_pavement:2)
Block(0,1,1,contenttweaker:reinforced_concrete:0)
Block(0,1,2,contenttweaker:reinforced_concrete:0)
Block(0,1,3,quark:world_stone_pavement:2)
Block(0,1,4,contenttweaker:reinforced_concrete:0)
Block(0,1,5,quark:world_stone_pavement:2)
Block(0,1,6,contenttweaker:reinforced_concrete:0)
Block(0,1,7,contenttweaker:reinforced_concrete:0)
Block(0,1,8,quark:world_stone_pavement:2)
Block(0,2,-7,contenttweaker:reinforced_concrete:0)
Block(0,2,-6,contenttweaker:reinforced_concrete:0)
Block(0,2,-5,contenttweaker:reinforced_concrete:0)
Block(0,2,-4,contenttweaker:reinforced_concrete:0)
Block(0,2,-3,quark:world_stone_pavement:2)
Block(0,2,-2,quark:world_stone_pavement:2)
Block(0,2,-1,contenttweaker:reinforced_concrete:0)
Block(0,2,0,quark:world_stone_pavement:2)
Block(0,2,1,contenttweaker:reinforced_concrete:0)
Block(0,2,2,contenttweaker:reinforced_concrete:0)
Block(0,2,3,contenttweaker:reinforced_concrete:0)
Block(0,2,4,quark:world_stone_pavement:2)
Block(0,2,5,quark:world_stone_pavement:2)
Block(0,2,6,contenttweaker:reinforced_concrete:0)
Block(0,2,7,contenttweaker:reinforced_concrete:0)
Block(0,2,8,contenttweaker:reinforced_concrete:0)
Block(0,3,-7,contenttweaker:reinforced_concrete:0)
Block(0,3,-6,contenttweaker:reinforced_concrete:0)
Block(0,3,-5,contenttweaker:reinforced_concrete:0)
Block(0,3,-4,contenttweaker:reinforced_concrete:0)
Block(0,3,-3,quark:world_stone_pavement:2)
Block(0,3,-2,contenttweaker:reinforced_concrete:0)
Block(0,3,-1,contenttweaker:reinforced_concrete:0)
Block(0,3,0,quark:world_stone_pavement:2)
Block(0,3,1,contenttweaker:reinforced_concrete:0)
Block(0,3,2,contenttweaker:reinforced_concrete:0)
Block(0,3,3,contenttweaker:reinforced_concrete:0)
Block(0,3,4,contenttweaker:reinforced_concrete:0)
Block(0,3,5,quark:world_stone_pavement:2)
Block(0,3,6,contenttweaker:reinforced_concrete:0)
Block(0,3,7,contenttweaker:reinforced_concrete:0)
Block(0,3,8,quark:world_stone_pavement:2)
Block(0,4,-7,contenttweaker:reinforced_concrete:0)
Block(0,4,-6,contenttweaker:reinforced_concrete:0)
Block(0,4,-5,quark:world_stone_pavement:2)
Block(0,4,-4,contenttweaker:reinforced_concrete:0)
Block(0,4,-3,quark:world_stone_pavement:2)
Block(0,4,-2,contenttweaker:reinforced_concrete:0)
Block(0,4,-1,contenttweaker:reinforced_concrete:0)
Block(0,4,0,quark:world_stone_pavement:2)
Block(0,4,1,contenttweaker:reinforced_concrete:0)
Block(0,4,2,contenttweaker:reinforced_concrete:0)
Block(0,4,3,contenttweaker:reinforced_concrete:0)
Block(0,4,4,contenttweaker:reinforced_concrete:0)
Block(0,4,5,quark:world_stone_pavement:2)
Block(0,4,6,quark:world_stone_pavement:2)
Block(0,4,7,quark:world_stone_pavement:2)
Block(0,4,8,contenttweaker:reinforced_concrete:0)
Block(0,5,-7,contenttweaker:reinforced_concrete:0)
Block(0,5,-6,contenttweaker:reinforced_concrete:0)
Block(0,5,-5,contenttweaker:reinforced_concrete:0)
Block(0,5,-4,contenttweaker:reinforced_concrete:0)
Block(0,5,-3,quark:world_stone_pavement:2)
Block(0,5,-2,contenttweaker:reinforced_concrete:0)
Block(0,5,-1,contenttweaker:reinforced_concrete:0)
Block(0,5,0,quark:world_stone_pavement:2)
Block(0,5,1,quark:world_stone_pavement:2)
Block(0,5,2,contenttweaker:reinforced_concrete:0)
Block(0,5,3,quark:world_stone_pavement:2)
Block(0,5,4,contenttweaker:reinforced_concrete:0)
Block(0,5,5,quark:world_stone_pavement:2)
Block(0,5,6,contenttweaker:reinforced_concrete:0)
Block(0,5,7,quark:world_stone_pavement:2)
Block(0,5,8,contenttweaker:reinforced_concrete:0)
Block(0,6,-7,contenttweaker:reinforced_concrete:0)
Block(0,6,-6,quark:world_stone_pavement:2)
Block(0,6,-5,contenttweaker:reinforced_concrete:0)
Block(0,6,-4,contenttweaker:reinforced_concrete:0)
Block(0,6,-3,quark:world_stone_pavement:2)
Block(0,6,-2,contenttweaker:reinforced_concrete:0)
Block(0,6,-1,contenttweaker:reinforced_concrete:0)
Block(0,6,0,quark:world_stone_pavement:2)
Block(0,6,1,contenttweaker:reinforced_concrete:0)
Block(0,6,2,quark:world_stone_pavement:2)
Block(0,6,3,quark:world_stone_pavement:2)
Block(0,6,4,contenttweaker:reinforced_concrete:0)
Block(0,6,5,quark:world_stone_pavement:2)
Block(0,6,6,contenttweaker:reinforced_concrete:0)
Block(0,6,7,contenttweaker:reinforced_concrete:0)
Block(0,6,8,quark:world_stone_pavement:2)
Block(0,7,-7,contenttweaker:reinforced_concrete:0)
Block(0,7,-6,contenttweaker:reinforced_concrete:0)
Block(0,7,-5,quark:world_stone_pavement:2)
Block(0,7,-4,contenttweaker:reinforced_concrete:0)
Block(0,7,-3,quark:world_stone_pavement:2)
Block(0,7,-2,quark:world_stone_pavement:2)
Block(0,7,-1,contenttweaker:reinforced_concrete:0)
Block(0,7,0,contenttweaker:reinforced_concrete:0)
Block(0,7,1,quark:world_stone_pavement:2)
Block(0,7,2,contenttweaker:reinforced_concrete:0)
Block(0,7,3,quark:world_stone_pavement:2)
Block(0,7,4,contenttweaker:reinforced_concrete:0)
Block(0,7,5,contenttweaker:reinforced_concrete:0)
Block(0,7,6,quark:world_stone_pavement:2)
Block(0,7,7,contenttweaker:reinforced_concrete:0)
Block(0,7,8,quark:world_stone_pavement:2)
Block(0,8,-7,quark:world_stone_pavement:2)
Block(0,8,-6,contenttweaker:reinforced_concrete:0)
Block(0,8,-5,contenttweaker:reinforced_concrete:0)
Block(0,8,-4,quark:world_stone_pavement:2)
Block(0,8,-3,contenttweaker:reinforced_concrete:0)
Block(0,8,-2,quark:world_stone_pavement:2)
Block(0,8,-1,quark:world_stone_pavement:2)
Block(0,8,0,contenttweaker:reinforced_concrete:0)
Block(0,8,1,contenttweaker:reinforced_concrete:0)
Block(0,8,2,quark:world_stone_pavement:2)
Block(0,8,3,contenttweaker:reinforced_concrete:0)
Block(0,8,4,contenttweaker:reinforced_concrete:0)
Block(0,8,5,quark:world_stone_pavement:2)
Block(0,8,6,contenttweaker:reinforced_concrete:0)
Block(0,8,7,quark:world_stone_pavement:2)
Block(0,8,8,contenttweaker:reinforced_concrete:0)
Block(0,9,-7,contenttweaker:reinforced_concrete:0)
Block(0,9,-6,quark:world_stone_pavement:2)
Block(0,9,-5,quark:world_stone_pavement:2)
Block(0,9,-4,quark:world_stone_pavement:2)
Block(0,9,-3,quark:polished_stone:0)
Block(0,9,-2,quark:polished_stone:0)
Block(0,9,-1,quark:polished_stone:0)
Block(0,9,0,quark:polished_stone:0)
Block(0,9,1,quark:polished_stone:0)
Block(0,9,2,quark:polished_stone:0)
Block(0,9,3,quark:polished_stone:0)
Block(0,9,4,contenttweaker:reinforced_concrete:0)
Block(0,9,5,contenttweaker:reinforced_concrete:0)
Block(0,9,6,contenttweaker:reinforced_concrete:0)
Block(0,9,7,quark:world_stone_pavement:2)
Block(0,9,8,contenttweaker:reinforced_concrete:0)
Block(0,10,-7,contenttweaker:reinforced_concrete:0)
Block(0,10,-6,quark:world_stone_pavement:2)
Block(0,10,-5,contenttweaker:reinforced_concrete:0)
Block(0,10,-4,contenttweaker:reinforced_concrete:0)
Block(0,10,-3,quark:polished_stone:0)
Block(0,10,-2,quark:polished_stone:0)
Block(0,10,-1,quark:world_stone_pavement:2)
Block(0,10,0,quark:polished_stone:0)
Block(0,10,1,quark:polished_stone:0)
Block(0,10,2,quark:polished_stone:0)
Block(0,10,3,quark:polished_stone:0)
Block(0,10,4,quark:polished_stone:0)
Block(0,10,5,quark:world_stone_pavement:2)
Block(0,10,6,quark:world_stone_pavement:2)
Block(0,10,7,contenttweaker:reinforced_concrete:0)
Block(0,10,8,contenttweaker:reinforced_concrete:0)
Block(0,11,-7,biomesoplenty:fir_door_block:3)
Block(0,11,-3,quark:polished_stone:0)
Block(0,11,2,quark:quartz_wall:0)
Block(0,11,6,quark:quartz_wall:0)
Block(0,12,-7,biomesoplenty:fir_door_block:9)
Block(0,12,-3,DOUBLE_STEP:0)
Block(0,12,-1,quark:iron_plate:0)
Block(0,12,1,quark:iron_plate:0)
Block(0,12,2,quark:quartz_wall:0)
Block(0,12,6,quark:quartz_wall:0)
Block(0,13,-7,SMOOTH_STAIRS:2)
Block(0,13,-3,DOUBLE_STEP:0)
Block(0,13,-2,quark:basalt_wall:0)
Block(0,13,2,quark:quartz_wall:0)
Block(0,13,6,quark:quartz_wall:0)
Block(0,14,-7,STEP:0)
Block(0,14,-6,quark:iron_plate:1)
Block(0,14,-5,DISPENSER:1)
Block(0,14,-4,DISPENSER:1)
Block(0,14,-3,DOUBLE_STEP:0)
Block(0,14,2,quark:quartz_wall:0)
Block(0,14,6,quark:quartz_wall:0)
Block(0,15,-5,IRON_TRAPDOOR:0)
Block(0,15,-4,IRON_TRAPDOOR:0)
Block(0,15,-3,DOUBLE_STEP:0)
Block(0,15,-2,quark:grate:0)
Block(0,15,-1,quark:iron_plate:1)
RandomBlock(0,15,0,rustic:iron_lattice:0,30,rustic:iron_lattice:1,100)
Block(0,15,2,quark:quartz_wall:0)
Block(0,15,6,quark:quartz_wall:0)
Block(0,16,-3,DOUBLE_STEP:0)
RandomBlock(0,16,-1,rustic:iron_lattice:0,30,rustic:iron_lattice:1,100)
RandomBlock(0,16,0,rustic:iron_lattice:0,30,rustic:iron_lattice:1,100)
Block(0,16,2,quark:quartz_wall:0)
Block(0,16,6,quark:quartz_wall:0)
Block(0,17,-3,DOUBLE_STEP:0)
RandomBlock(0,17,-1,rustic:iron_lattice:0,30,rustic:iron_lattice:1,100)
RandomBlock(0,17,0,rustic:iron_lattice:0,30,rustic:iron_lattice:1,100)
Block(0,17,2,quark:quartz_wall:0)
Block(0,17,6,quark:quartz_wall:0)
Block(0,18,-3,DOUBLE_STEP:0)
RandomBlock(0,18,-1,rustic:iron_lattice:0,30,rustic:iron_lattice:1,100)
Block(0,18,0,quark:iron_plate:1)
Block(0,18,1,quark:iron_plate:1)
Block(0,18,2,quark:iron_plate:1)
Block(0,18,3,quark:iron_plate:1)
Block(0,18,4,quark:iron_plate:1)
Block(0,18,5,quark:iron_plate:1)
Block(0,18,6,quark:iron_plate:1)
Block(0,19,-3,quark:iron_plate:1)
RandomBlock(0,19,-1,rustic:iron_lattice:0,30,rustic:iron_lattice:1,100)
RandomBlock(0,19,0,rustic:iron_lattice:0,30,rustic:iron_lattice:1,100)
RandomBlock(0,19,1,rustic:iron_lattice:0,30,rustic:iron_lattice:1,100)
RandomBlock(0,19,2,contenttweaker:reinforced_concrete:0,40,SMOOTH_BRICK:1,30,SMOOTH_BRICK:2,30,MOSSY_COBBLESTONE:0,30,COBBLESTONE:0,20,contenttweaker:reinforced_concrete:0,100)
RandomBlock(0,19,3,rustic:iron_lattice:0,30,rustic:iron_lattice:1,100)
RandomBlock(0,19,4,rustic:iron_lattice:0,30,rustic:iron_lattice:1,100)
RandomBlock(0,19,5,rustic:iron_lattice:0,30,rustic:iron_lattice:1,100)
RandomBlock(0,19,6,rustic:iron_lattice:0,30,rustic:iron_lattice:1,100)
Block(0,20,-3,STEP:0)
RandomBlock(0,20,-2,contenttweaker:reinforced_concrete:0,40,SMOOTH_BRICK:1,30,SMOOTH_BRICK:2,30,MOSSY_COBBLESTONE:0,30,COBBLESTONE:0,20,contenttweaker:reinforced_concrete:0,100)
RandomBlock(0,20,-1,rustic:iron_lattice:0,30,rustic:iron_lattice:1,100)
RandomBlock(0,20,0,rustic:iron_lattice:0,30,rustic:iron_lattice:1,100)
RandomBlock(0,20,1,rustic:iron_lattice:0,30,rustic:iron_lattice:1,100)
Block(0,20,2,nuclearcraft:radiation_scrubber:0)
RandomBlock(0,20,3,rustic:iron_lattice:0,30,rustic:iron_lattice:1,100)
RandomBlock(0,20,4,rustic:iron_lattice:0,30,rustic:iron_lattice:1,100)
RandomBlock(0,20,5,rustic:iron_lattice:0,30,rustic:iron_lattice:1,100)
RandomBlock(0,20,6,rustic:iron_lattice:0,30,rustic:iron_lattice:1,100)
Block(0,21,-2,STEP:0)
Block(0,21,-1,quark:iron_plate:1)
Block(0,21,0,STEP:0)
RandomBlock(0,22,0,contenttweaker:reinforced_concrete:0,40,SMOOTH_BRICK:1,30,SMOOTH_BRICK:2,30,MOSSY_COBBLESTONE:0,30,COBBLESTONE:0,20,contenttweaker:reinforced_concrete:0,100)
Block(0,23,0,quark:framed_glass:0)
Block(0,24,0,quark:framed_glass:0)
Block(0,25,0,DOUBLE_STEP:0)
RandomBlock(0,26,0,contenttweaker:reinforced_concrete:0,40,SMOOTH_BRICK:1,30,SMOOTH_BRICK:2,30,MOSSY_COBBLESTONE:0,30,COBBLESTONE:0,20,contenttweaker:reinforced_concrete:0,100)
Block(0,27,0,quark:sturdy_stone:0)
Block(0,28,0,SMOOTH_STAIRS:2)
Block(0,28,1,STEP:0)
Block(0,28,2,STEP:0)
Block(0,28,3,STEP:0)
Block(0,28,4,STEP:0)
Block(0,28,5,STEP:0)
