
#######################################################################
# +-----------------------------------------------------------------+ #
# |                            BO4 object                           | #
# +-----------------------------------------------------------------+ #
#######################################################################

Author: NLBlackEagle

Description: No description given

SettingsMode: WriteWithoutComments


#######################################################################
# +-----------------------------------------------------------------+ #
# |                          Main settings                          | #
# +-----------------------------------------------------------------+ #
#######################################################################

FixedRotation: 

Frequency: 0

SpawnHeight: highestBlock

UseCenterForHighestBlock: true

##############################
# Height Limits for the BO4. #
##############################

MinHeight: 0

MaxHeight: 255

InheritBO3: 

InheritBO3Rotation: NORTH

OverrideChildSettings: true

OverrideParentHeight: false

CanOverride: true

BranchFrequency: 0

BranchFrequencyGroup: 

MustBeBelowOther: false

MustBeInside: 

CannotBeInside: 

ReplacesBO3: 

MustBeInsideWorldBorders: false

CanSpawnOnWater: true

SpawnOnWaterOnly: false

SpawnUnderWater: false

SpawnAtWaterLevel: false

HeightOffset: 0

RemoveAir: false

ReplaceAbove: 

ReplaceBelow: 

ReplaceWithBiomeBlocks: false

ReplaceWithSurfaceBlock: GRASS

ReplaceWithGroundBlock: DIRT

ReplaceWithStoneBlock: STONE

SmoothRadius: 0

SmoothHeightOffset: 0

SmoothStartTop: false

SmoothStartWood: false

SmoothingSurfaceBlock: 

SmoothingGroundBlock: 

BO3Group: 

IsSpawnPoint: false

DoReplaceBlocks: true


#######################################################################
# +-----------------------------------------------------------------+ #
# |                              Blocks                             | #
# +-----------------------------------------------------------------+ #
#######################################################################

Block(-8,0,-7,quark:world_stone_pavement:2)
Block(-8,0,-6,quark:world_stone_pavement:2)
Block(-8,0,-5,quark:world_stone_pavement:2)
Block(-8,0,-4,quark:world_stone_pavement:2)
Block(-8,0,-3,quark:world_stone_pavement:2)
Block(-8,0,-2,quark:world_stone_pavement:2)
Block(-8,0,-1,quark:world_stone_pavement:2)
Block(-8,0,0,contenttweaker:reinforced_concrete:0)
Block(-8,0,1,quark:world_stone_pavement:2)
Block(-8,0,2,quark:world_stone_pavement:2)
Block(-8,0,3,quark:world_stone_pavement:2)
Block(-8,1,-7,contenttweaker:reinforced_concrete:0)
Block(-8,1,-6,contenttweaker:reinforced_concrete:0)
Block(-8,1,-5,quark:world_stone_pavement:2)
Block(-8,1,-4,quark:world_stone_pavement:2)
Block(-8,1,-3,contenttweaker:reinforced_concrete:0)
Block(-8,1,-2,contenttweaker:reinforced_concrete:0)
Block(-8,1,-1,contenttweaker:reinforced_concrete:0)
Block(-8,1,0,quark:world_stone_pavement:2)
Block(-8,1,1,quark:world_stone_pavement:2)
Block(-8,1,2,contenttweaker:reinforced_concrete:0)
Block(-8,1,3,contenttweaker:reinforced_concrete:0)
Block(-8,2,-7,contenttweaker:reinforced_concrete:0)
Block(-8,2,-6,contenttweaker:reinforced_concrete:0)
Block(-8,2,-5,contenttweaker:reinforced_concrete:0)
Block(-8,2,-4,contenttweaker:reinforced_concrete:0)
Block(-8,2,-3,contenttweaker:reinforced_concrete:0)
Block(-8,2,-2,contenttweaker:reinforced_concrete:0)
Block(-8,2,-1,contenttweaker:reinforced_concrete:0)
Block(-8,2,0,quark:world_stone_pavement:2)
Block(-8,2,1,contenttweaker:reinforced_concrete:0)
Block(-8,2,2,quark:world_stone_pavement:2)
Block(-8,2,3,quark:world_stone_pavement:2)
Block(-8,3,-7,contenttweaker:reinforced_concrete:0)
Block(-8,3,-6,quark:world_stone_pavement:2)
Block(-8,3,-5,contenttweaker:reinforced_concrete:0)
Block(-8,3,-4,contenttweaker:reinforced_concrete:0)
Block(-8,3,-3,contenttweaker:reinforced_concrete:0)
Block(-8,3,-2,contenttweaker:reinforced_concrete:0)
Block(-8,3,-1,quark:world_stone_pavement:2)
Block(-8,3,0,contenttweaker:reinforced_concrete:0)
Block(-8,3,1,contenttweaker:reinforced_concrete:0)
Block(-8,3,2,contenttweaker:reinforced_concrete:0)
Block(-8,3,3,quark:world_stone_pavement:2)
Block(-8,4,-7,quark:world_stone_pavement:2)
Block(-8,4,-6,contenttweaker:reinforced_concrete:0)
Block(-8,4,-5,quark:world_stone_pavement:2)
Block(-8,4,-4,quark:world_stone_pavement:2)
Block(-8,4,-3,quark:world_stone_pavement:2)
Block(-8,4,-2,contenttweaker:reinforced_concrete:0)
Block(-8,4,-1,quark:world_stone_pavement:2)
Block(-8,4,0,contenttweaker:reinforced_concrete:0)
Block(-8,4,1,contenttweaker:reinforced_concrete:0)
Block(-8,4,2,quark:world_stone_pavement:2)
Block(-8,4,3,contenttweaker:reinforced_concrete:0)
Block(-8,5,-7,contenttweaker:reinforced_concrete:0)
Block(-8,5,-6,contenttweaker:reinforced_concrete:0)
Block(-8,5,-5,quark:world_stone_pavement:2)
Block(-8,5,-4,quark:world_stone_pavement:2)
Block(-8,5,-3,quark:world_stone_pavement:2)
Block(-8,5,-2,contenttweaker:reinforced_concrete:0)
Block(-8,5,-1,contenttweaker:reinforced_concrete:0)
Block(-8,5,0,contenttweaker:reinforced_concrete:0)
Block(-8,5,1,quark:world_stone_pavement:2)
Block(-8,5,2,quark:world_stone_pavement:2)
Block(-8,5,3,contenttweaker:reinforced_concrete:0)
Block(-8,6,-7,contenttweaker:reinforced_concrete:0)
Block(-8,6,-6,contenttweaker:reinforced_concrete:0)
Block(-8,6,-5,quark:world_stone_pavement:2)
Block(-8,6,-4,quark:world_stone_pavement:2)
Block(-8,6,-3,quark:world_stone_pavement:2)
Block(-8,6,-2,quark:world_stone_pavement:2)
Block(-8,6,-1,contenttweaker:reinforced_concrete:0)
Block(-8,6,0,contenttweaker:reinforced_concrete:0)
Block(-8,6,1,quark:world_stone_pavement:2)
Block(-8,6,2,contenttweaker:reinforced_concrete:0)
Block(-8,6,3,contenttweaker:reinforced_concrete:0)
Block(-8,7,-7,contenttweaker:reinforced_concrete:0)
Block(-8,7,-6,contenttweaker:reinforced_concrete:0)
Block(-8,7,-5,contenttweaker:reinforced_concrete:0)
Block(-8,7,-4,contenttweaker:reinforced_concrete:0)
Block(-8,7,-3,contenttweaker:reinforced_concrete:0)
Block(-8,7,-2,quark:world_stone_pavement:2)
Block(-8,7,-1,contenttweaker:reinforced_concrete:0)
Block(-8,7,0,contenttweaker:reinforced_concrete:0)
Block(-8,7,1,contenttweaker:reinforced_concrete:0)
Block(-8,7,2,quark:polished_stone:0)
Block(-8,7,3,quark:world_stone_pavement:2)
Block(-8,8,-7,contenttweaker:reinforced_concrete:0)
Block(-8,8,-6,contenttweaker:reinforced_concrete:0)
Block(-8,8,-5,quark:polished_stone:0)
Block(-8,8,-4,quark:polished_stone:0)
Block(-8,8,-3,quark:world_stone_pavement:2)
Block(-8,8,-2,contenttweaker:reinforced_concrete:0)
Block(-8,8,-1,contenttweaker:reinforced_concrete:0)
Block(-8,8,0,contenttweaker:reinforced_concrete:0)
Block(-8,8,1,quark:polished_stone:0)
Block(-8,8,2,quark:polished_stone:0)
Block(-8,8,3,quark:polished_stone:0)
Block(-8,9,-7,quark:polished_stone:0)
Block(-8,9,-6,quark:polished_stone:0)
Block(-8,9,-5,quark:polished_stone:0)
Block(-8,9,-4,quark:polished_stone:0)
Block(-8,9,-3,quark:world_stone_pavement:2)
Block(-8,9,-2,contenttweaker:reinforced_concrete:0)
Block(-8,9,-1,contenttweaker:reinforced_concrete:0)
Block(-8,9,0,contenttweaker:reinforced_concrete:0)
Block(-8,9,1,quark:polished_stone:0)
Block(-8,9,2,quark:world_stone_pavement:2)
Block(-8,9,3,quark:world_stone_pavement:2)
Block(-8,10,-7,quark:polished_stone:0)
Block(-8,10,-6,quark:polished_stone:0)
Block(-8,10,-5,quark:world_stone_pavement:2)
Block(-8,10,-4,contenttweaker:reinforced_concrete:0)
Block(-8,10,-3,quark:polished_stone:0)
Block(-8,10,-2,contenttweaker:reinforced_concrete:0)
Block(-8,10,-1,contenttweaker:reinforced_concrete:0)
Block(-8,10,0,contenttweaker:reinforced_concrete:0)
Block(-8,10,1,quark:polished_stone:0)
Block(-8,10,2,quark:world_stone_pavement:2)
Block(-8,10,3,quark:polished_stone:0)
Block(-8,11,-4,AIR:0)
RandomBlock(-8,11,-3,rustic:iron_lattice:0,30,rustic:iron_lattice:1,100)
RandomBlock(-8,11,3,contenttweaker:reinforced_concrete:0,40,SMOOTH_BRICK:1,30,SMOOTH_BRICK:2,30,MOSSY_COBBLESTONE:0,30,COBBLESTONE:0,20,contenttweaker:reinforced_concrete:0,100)
Block(-8,12,-4,AIR:0)
RandomBlock(-8,12,-3,rustic:iron_lattice:0,30,rustic:iron_lattice:1,100)
Block(-8,12,-1,quark:grate:0)
Block(-8,12,0,quark:grate:0)
Block(-8,12,1,quark:grate:0)
Block(-8,12,2,quark:grate:0)
RandomBlock(-8,12,3,contenttweaker:reinforced_concrete:0,40,SMOOTH_BRICK:1,30,SMOOTH_BRICK:2,30,MOSSY_COBBLESTONE:0,30,COBBLESTONE:0,20,contenttweaker:reinforced_concrete:0,100)
Block(-8,13,-4,AIR:0)
RandomBlock(-8,13,-3,rustic:iron_lattice:0,30,rustic:iron_lattice:1,100)
Block(-8,13,-2,quark:iron_plate_slab:0)
Block(-8,13,2,quark:iron_plate_slab:0)
RandomBlock(-8,13,3,contenttweaker:reinforced_concrete:0,40,SMOOTH_BRICK:1,30,SMOOTH_BRICK:2,30,MOSSY_COBBLESTONE:0,30,COBBLESTONE:0,20,contenttweaker:reinforced_concrete:0,100)
Block(-8,14,-4,AIR:0)
RandomBlock(-8,14,-3,rustic:iron_lattice:0,30,rustic:iron_lattice:1,100)
Block(-8,14,2,VINE:1)
RandomBlock(-8,14,3,contenttweaker:reinforced_concrete:0,40,SMOOTH_BRICK:1,30,SMOOTH_BRICK:2,30,MOSSY_COBBLESTONE:0,30,COBBLESTONE:0,20,contenttweaker:reinforced_concrete:0,100)
Block(-8,15,-4,AIR:0)
Block(-8,15,2,VINE:1)
RandomBlock(-8,15,3,contenttweaker:reinforced_concrete:0,40,SMOOTH_BRICK:1,30,SMOOTH_BRICK:2,30,MOSSY_COBBLESTONE:0,30,COBBLESTONE:0,20,contenttweaker:reinforced_concrete:0,100)
Block(-8,16,-4,AIR:0)
Block(-8,16,2,SMOOTH_STAIRS:6)
Block(-8,16,3,quark:iron_plate:1)
Block(-8,17,-6,quark:iron_plate:1)
Block(-8,17,-1,quark:iron_plate:1)
Block(-8,17,1,SMOOTH_STAIRS:6)
Block(-8,17,2,quark:polished_stone:0)
Block(-8,18,-7,quark:polished_stone:0)
Block(-8,18,-6,quark:iron_plate:1)
Block(-8,18,-5,quark:polished_stone:0)
Block(-8,18,-4,quark:polished_stone:0)
Block(-8,18,-3,quark:polished_stone:0)
Block(-8,18,-2,quark:polished_stone:0)
Block(-8,18,-1,quark:iron_plate:1)
Block(-8,18,0,quark:polished_stone:0)
Block(-8,18,1,quark:polished_stone:0)
Block(-8,18,2,SMOOTH_STAIRS:3)
Block(-8,19,-7,SMOOTH_STAIRS:0)
Block(-8,19,-6,SMOOTH_STAIRS:0)
Block(-8,19,-5,SMOOTH_STAIRS:0)
Block(-8,19,-4,SMOOTH_STAIRS:0)
Block(-8,19,-3,SMOOTH_STAIRS:0)
Block(-8,19,-2,SMOOTH_STAIRS:0)
Block(-8,19,-1,SMOOTH_STAIRS:0)
Block(-8,19,0,SMOOTH_STAIRS:0)
Block(-7,0,-7,contenttweaker:reinforced_concrete:0)
Block(-7,0,-6,contenttweaker:reinforced_concrete:0)
Block(-7,0,-5,contenttweaker:reinforced_concrete:0)
Block(-7,0,-4,contenttweaker:reinforced_concrete:0)
Block(-7,0,-3,contenttweaker:reinforced_concrete:0)
Block(-7,0,-2,contenttweaker:reinforced_concrete:0)
Block(-7,0,-1,contenttweaker:reinforced_concrete:0)
Block(-7,0,0,contenttweaker:reinforced_concrete:0)
Block(-7,0,1,quark:world_stone_pavement:2)
Block(-7,0,2,contenttweaker:reinforced_concrete:0)
Block(-7,0,3,quark:world_stone_pavement:2)
Block(-7,1,-7,quark:world_stone_pavement:2)
Block(-7,1,-6,contenttweaker:reinforced_concrete:0)
Block(-7,1,-5,contenttweaker:reinforced_concrete:0)
Block(-7,1,-4,contenttweaker:reinforced_concrete:0)
Block(-7,1,-3,contenttweaker:reinforced_concrete:0)
Block(-7,1,-2,contenttweaker:reinforced_concrete:0)
Block(-7,1,-1,quark:world_stone_pavement:2)
Block(-7,1,0,contenttweaker:reinforced_concrete:0)
Block(-7,1,1,quark:world_stone_pavement:2)
Block(-7,1,2,contenttweaker:reinforced_concrete:0)
Block(-7,1,3,quark:world_stone_pavement:2)
Block(-7,2,-7,quark:world_stone_pavement:2)
Block(-7,2,-6,quark:world_stone_pavement:2)
Block(-7,2,-5,contenttweaker:reinforced_concrete:0)
Block(-7,2,-4,contenttweaker:reinforced_concrete:0)
Block(-7,2,-3,contenttweaker:reinforced_concrete:0)
Block(-7,2,-2,contenttweaker:reinforced_concrete:0)
Block(-7,2,-1,contenttweaker:reinforced_concrete:0)
Block(-7,2,0,contenttweaker:reinforced_concrete:0)
Block(-7,2,1,quark:world_stone_pavement:2)
Block(-7,2,2,quark:world_stone_pavement:2)
Block(-7,2,3,contenttweaker:reinforced_concrete:0)
Block(-7,3,-7,quark:world_stone_pavement:2)
Block(-7,3,-6,contenttweaker:reinforced_concrete:0)
Block(-7,3,-5,quark:world_stone_pavement:2)
Block(-7,3,-4,quark:world_stone_pavement:2)
Block(-7,3,-3,quark:world_stone_pavement:2)
Block(-7,3,-2,quark:world_stone_pavement:2)
Block(-7,3,-1,quark:world_stone_pavement:2)
Block(-7,3,0,quark:world_stone_pavement:2)
Block(-7,3,1,contenttweaker:reinforced_concrete:0)
Block(-7,3,2,contenttweaker:reinforced_concrete:0)
Block(-7,3,3,contenttweaker:reinforced_concrete:0)
Block(-7,4,-7,contenttweaker:reinforced_concrete:0)
Block(-7,4,-6,quark:world_stone_pavement:2)
Block(-7,4,-5,contenttweaker:reinforced_concrete:0)
Block(-7,4,-4,contenttweaker:reinforced_concrete:0)
Block(-7,4,-3,contenttweaker:reinforced_concrete:0)
Block(-7,4,-2,contenttweaker:reinforced_concrete:0)
Block(-7,4,-1,quark:world_stone_pavement:2)
Block(-7,4,0,contenttweaker:reinforced_concrete:0)
Block(-7,4,1,quark:world_stone_pavement:2)
Block(-7,4,2,contenttweaker:reinforced_concrete:0)
Block(-7,4,3,quark:world_stone_pavement:2)
Block(-7,5,-7,quark:world_stone_pavement:2)
Block(-7,5,-6,contenttweaker:reinforced_concrete:0)
Block(-7,5,-5,contenttweaker:reinforced_concrete:0)
Block(-7,5,-4,contenttweaker:reinforced_concrete:0)
Block(-7,5,-3,contenttweaker:reinforced_concrete:0)
Block(-7,5,-2,contenttweaker:reinforced_concrete:0)
Block(-7,5,-1,contenttweaker:reinforced_concrete:0)
Block(-7,5,0,quark:world_stone_pavement:2)
Block(-7,5,1,quark:world_stone_pavement:2)
Block(-7,5,2,quark:world_stone_pavement:2)
Block(-7,5,3,contenttweaker:reinforced_concrete:0)
Block(-7,6,-7,contenttweaker:reinforced_concrete:0)
Block(-7,6,-6,quark:world_stone_pavement:2)
Block(-7,6,-5,contenttweaker:reinforced_concrete:0)
Block(-7,6,-4,contenttweaker:reinforced_concrete:0)
Block(-7,6,-3,contenttweaker:reinforced_concrete:0)
Block(-7,6,-2,contenttweaker:reinforced_concrete:0)
Block(-7,6,-1,contenttweaker:reinforced_concrete:0)
Block(-7,6,0,contenttweaker:reinforced_concrete:0)
Block(-7,6,1,quark:world_stone_pavement:2)
Block(-7,6,2,contenttweaker:reinforced_concrete:0)
Block(-7,6,3,quark:world_stone_pavement:2)
Block(-7,7,-7,quark:world_stone_pavement:2)
Block(-7,7,-6,quark:world_stone_pavement:2)
Block(-7,7,-5,quark:world_stone_pavement:2)
Block(-7,7,-4,quark:world_stone_pavement:2)
Block(-7,7,-3,contenttweaker:reinforced_concrete:0)
Block(-7,7,-2,quark:world_stone_pavement:2)
Block(-7,7,-1,quark:world_stone_pavement:2)
Block(-7,7,0,contenttweaker:reinforced_concrete:0)
Block(-7,7,1,quark:world_stone_pavement:2)
Block(-7,7,2,quark:world_stone_pavement:2)
Block(-7,7,3,quark:polished_stone:0)
Block(-7,8,-7,contenttweaker:reinforced_concrete:0)
Block(-7,8,-6,contenttweaker:reinforced_concrete:0)
Block(-7,8,-5,quark:polished_stone:0)
Block(-7,8,-4,quark:polished_stone:0)
Block(-7,8,-3,quark:polished_stone:0)
Block(-7,8,-2,contenttweaker:reinforced_concrete:0)
Block(-7,8,-1,contenttweaker:reinforced_concrete:0)
Block(-7,8,0,contenttweaker:reinforced_concrete:0)
Block(-7,8,1,quark:world_stone_pavement:2)
Block(-7,8,2,quark:world_stone_pavement:2)
Block(-7,8,3,quark:world_stone_pavement:2)
Block(-7,9,-7,quark:world_stone_pavement:2)
Block(-7,9,-6,contenttweaker:reinforced_concrete:0)
Block(-7,9,-5,quark:polished_stone:0)
Block(-7,9,-4,quark:polished_stone:0)
Block(-7,9,-3,quark:polished_stone:0)
Block(-7,9,-2,quark:world_stone_pavement:2)
Block(-7,9,-1,quark:world_stone_pavement:2)
Block(-7,9,0,quark:world_stone_pavement:2)
Block(-7,9,1,quark:polished_stone:0)
Block(-7,9,2,quark:polished_stone:0)
Block(-7,9,3,quark:world_stone_pavement:2)
Block(-7,10,-7,quark:iron_plate:1)
Block(-7,10,-6,quark:iron_plate:1)
Block(-7,10,-5,quark:polished_stone:0)
Block(-7,10,-4,quark:polished_stone:0)
Block(-7,10,-3,quark:polished_stone:0)
Block(-7,10,-2,quark:world_stone_pavement:2)
Block(-7,10,-1,quark:world_stone_pavement:2)
Block(-7,10,0,contenttweaker:reinforced_concrete:0)
Block(-7,10,1,quark:polished_stone:0)
Block(-7,10,2,quark:polished_stone:0)
Block(-7,10,3,quark:world_stone_pavement:2)
Block(-7,11,-7,quark:iron_plate:1)
Block(-7,11,-6,quark:iron_plate:1)
RandomBlock(-7,11,-3,rustic:iron_lattice:0,30,rustic:iron_lattice:1,100)
Block(-7,11,3,DOUBLE_STEP:0)
Block(-7,12,-6,quark:stone_limestone_bricks_stairs:0)
RandomBlock(-7,12,-3,rustic:iron_lattice:0,30,rustic:iron_lattice:1,100)
RandomBlock(-7,12,-2,rustic:iron_lattice:0,30,rustic:iron_lattice:1,100)
Block(-7,12,-1,quark:grate:0)
Block(-7,12,0,quark:grate:0)
Block(-7,12,1,quark:grate:0)
Block(-7,12,2,quark:grate:0)
Block(-7,12,3,DOUBLE_STEP:0)
RandomBlock(-7,13,-3,rustic:iron_lattice:0,30,rustic:iron_lattice:1,100)
Block(-7,13,-2,quark:iron_plate_slab:0)
Block(-7,13,-1,quark:iron_plate_slab:0)
Block(-7,13,0,quark:iron_plate_slab:0)
Block(-7,13,1,quark:iron_plate_slab:0)
Block(-7,13,2,quark:iron_plate_slab:0)
Block(-7,13,3,DOUBLE_STEP:0)
RandomBlock(-7,14,-3,rustic:iron_lattice:0,30,rustic:iron_lattice:1,100)
Block(-7,14,2,VINE:1)
Block(-7,14,3,DOUBLE_STEP:0)
Block(-7,15,2,VINE:1)
Block(-7,15,3,DOUBLE_STEP:0)
Block(-7,16,2,SMOOTH_STAIRS:6)
Block(-7,16,3,quark:iron_plate:1)
Block(-7,17,1,SMOOTH_STAIRS:6)
Block(-7,17,2,quark:polished_stone:0)
Block(-7,18,-7,SMOOTH_STAIRS:5)
Block(-7,18,-6,quark:iron_plate:1)
Block(-7,18,-5,SMOOTH_STAIRS:5)
Block(-7,18,-4,SMOOTH_STAIRS:5)
Block(-7,18,-3,SMOOTH_STAIRS:5)
Block(-7,18,-2,SMOOTH_STAIRS:5)
Block(-7,18,-1,quark:iron_plate:1)
Block(-7,18,0,quark:polished_stone:0)
Block(-7,18,1,quark:polished_stone:0)
Block(-7,18,2,SMOOTH_STAIRS:3)
Block(-7,19,-7,quark:iron_plate:1)
Block(-7,19,-6,quark:iron_plate:1)
Block(-7,19,-5,quark:iron_plate:1)
Block(-7,19,-4,quark:iron_plate:1)
Block(-7,19,-3,quark:iron_plate:1)
Block(-7,19,-2,quark:iron_plate:1)
Block(-7,19,-1,quark:iron_plate:1)
Block(-7,19,0,SMOOTH_STAIRS:3)
Block(-7,20,-7,quark:stone_diorite_bricks_wall:0)
Block(-7,20,-6,quark:stone_diorite_bricks_wall:0)
Block(-7,20,-5,quark:stone_diorite_bricks_wall:0)
Block(-7,20,-4,quark:stone_diorite_bricks_wall:0)
Block(-7,20,-3,quark:stone_diorite_bricks_wall:0)
Block(-7,20,-2,quark:stone_diorite_bricks_wall:0)
Block(-7,20,-1,quark:stone_diorite_bricks_wall:0)
Block(-6,0,-7,contenttweaker:reinforced_concrete:0)
Block(-6,0,-6,contenttweaker:reinforced_concrete:0)
Block(-6,0,-5,contenttweaker:reinforced_concrete:0)
Block(-6,0,-4,contenttweaker:reinforced_concrete:0)
Block(-6,0,-3,contenttweaker:reinforced_concrete:0)
Block(-6,0,-2,contenttweaker:reinforced_concrete:0)
Block(-6,0,-1,contenttweaker:reinforced_concrete:0)
Block(-6,0,0,contenttweaker:reinforced_concrete:0)
Block(-6,0,1,contenttweaker:reinforced_concrete:0)
Block(-6,0,2,quark:world_stone_pavement:2)
Block(-6,0,3,contenttweaker:reinforced_concrete:0)
Block(-6,1,-7,contenttweaker:reinforced_concrete:0)
Block(-6,1,-6,contenttweaker:reinforced_concrete:0)
Block(-6,1,-5,quark:world_stone_pavement:2)
Block(-6,1,-4,quark:world_stone_pavement:2)
Block(-6,1,-3,contenttweaker:reinforced_concrete:0)
Block(-6,1,-2,contenttweaker:reinforced_concrete:0)
Block(-6,1,-1,contenttweaker:reinforced_concrete:0)
Block(-6,1,0,contenttweaker:reinforced_concrete:0)
Block(-6,1,1,contenttweaker:reinforced_concrete:0)
Block(-6,1,2,quark:world_stone_pavement:2)
Block(-6,1,3,contenttweaker:reinforced_concrete:0)
Block(-6,2,-7,quark:world_stone_pavement:2)
Block(-6,2,-6,contenttweaker:reinforced_concrete:0)
Block(-6,2,-5,quark:world_stone_pavement:2)
Block(-6,2,-4,quark:world_stone_pavement:2)
Block(-6,2,-3,contenttweaker:reinforced_concrete:0)
Block(-6,2,-2,quark:world_stone_pavement:2)
Block(-6,2,-1,contenttweaker:reinforced_concrete:0)
Block(-6,2,0,quark:world_stone_pavement:2)
Block(-6,2,1,quark:world_stone_pavement:2)
Block(-6,2,2,contenttweaker:reinforced_concrete:0)
Block(-6,2,3,contenttweaker:reinforced_concrete:0)
Block(-6,3,-7,quark:world_stone_pavement:2)
Block(-6,3,-6,quark:polished_stone:0)
Block(-6,3,-5,quark:polished_stone:0)
Block(-6,3,-4,contenttweaker:reinforced_concrete:0)
Block(-6,3,-3,contenttweaker:reinforced_concrete:0)
Block(-6,3,-2,contenttweaker:reinforced_concrete:0)
Block(-6,3,-1,quark:world_stone_pavement:2)
Block(-6,3,0,contenttweaker:reinforced_concrete:0)
Block(-6,3,1,contenttweaker:reinforced_concrete:0)
Block(-6,3,2,quark:world_stone_pavement:2)
Block(-6,3,3,contenttweaker:reinforced_concrete:0)
Block(-6,4,-7,quark:polished_stone:0)
Block(-6,4,-6,quark:polished_stone:0)
Block(-6,4,-5,quark:polished_stone:0)
Block(-6,4,-4,contenttweaker:reinforced_concrete:0)
Block(-6,4,-3,contenttweaker:reinforced_concrete:0)
Block(-6,4,-2,contenttweaker:reinforced_concrete:0)
Block(-6,4,-1,quark:world_stone_pavement:2)
Block(-6,4,0,contenttweaker:reinforced_concrete:0)
Block(-6,4,1,quark:world_stone_pavement:2)
Block(-6,4,2,contenttweaker:reinforced_concrete:0)
Block(-6,4,3,quark:world_stone_pavement:2)
Block(-6,5,-7,quark:world_stone_pavement:2)
Block(-6,5,-6,quark:polished_stone:0)
Block(-6,5,-5,quark:polished_stone:0)
Block(-6,5,-4,contenttweaker:reinforced_concrete:0)
Block(-6,5,-3,contenttweaker:reinforced_concrete:0)
Block(-6,5,-2,contenttweaker:reinforced_concrete:0)
Block(-6,5,-1,contenttweaker:reinforced_concrete:0)
Block(-6,5,0,contenttweaker:reinforced_concrete:0)
Block(-6,5,1,contenttweaker:reinforced_concrete:0)
Block(-6,5,2,contenttweaker:reinforced_concrete:0)
Block(-6,5,3,contenttweaker:reinforced_concrete:0)
Block(-6,6,-7,contenttweaker:reinforced_concrete:0)
Block(-6,6,-6,contenttweaker:reinforced_concrete:0)
Block(-6,6,-5,contenttweaker:reinforced_concrete:0)
Block(-6,6,-4,contenttweaker:reinforced_concrete:0)
Block(-6,6,-3,quark:world_stone_pavement:2)
Block(-6,6,-2,contenttweaker:reinforced_concrete:0)
Block(-6,6,-1,quark:world_stone_pavement:2)
Block(-6,6,0,contenttweaker:reinforced_concrete:0)
Block(-6,6,1,contenttweaker:reinforced_concrete:0)
Block(-6,6,2,contenttweaker:reinforced_concrete:0)
Block(-6,6,3,contenttweaker:reinforced_concrete:0)
Block(-6,7,-7,contenttweaker:reinforced_concrete:0)
Block(-6,7,-6,quark:world_stone_pavement:2)
Block(-6,7,-5,contenttweaker:reinforced_concrete:0)
Block(-6,7,-4,contenttweaker:reinforced_concrete:0)
Block(-6,7,-3,contenttweaker:reinforced_concrete:0)
Block(-6,7,-2,contenttweaker:reinforced_concrete:0)
Block(-6,7,-1,quark:world_stone_pavement:2)
Block(-6,7,0,quark:world_stone_pavement:2)
Block(-6,7,1,quark:world_stone_pavement:2)
Block(-6,7,2,quark:polished_stone:0)
Block(-6,7,3,quark:world_stone_pavement:2)
Block(-6,8,-7,contenttweaker:reinforced_concrete:0)
Block(-6,8,-6,contenttweaker:reinforced_concrete:0)
Block(-6,8,-5,quark:world_stone_pavement:2)
Block(-6,8,-4,quark:world_stone_pavement:2)
Block(-6,8,-3,quark:polished_stone:0)
Block(-6,8,-2,contenttweaker:reinforced_concrete:0)
Block(-6,8,-1,contenttweaker:reinforced_concrete:0)
Block(-6,8,0,contenttweaker:reinforced_concrete:0)
Block(-6,8,1,quark:polished_stone:0)
Block(-6,8,2,quark:world_stone_pavement:2)
Block(-6,8,3,quark:polished_stone:0)
Block(-6,9,-7,quark:iron_plate:1)
Block(-6,9,-6,quark:world_stone_pavement:2)
Block(-6,9,-5,quark:world_stone_pavement:2)
Block(-6,9,-4,quark:world_stone_pavement:2)
Block(-6,9,-3,quark:polished_stone:0)
Block(-6,9,-2,contenttweaker:reinforced_concrete:0)
Block(-6,9,-1,contenttweaker:reinforced_concrete:0)
Block(-6,9,0,quark:world_stone_pavement:2)
Block(-6,9,1,quark:polished_stone:0)
Block(-6,9,2,quark:polished_stone:0)
Block(-6,9,3,quark:polished_stone:0)
Block(-6,10,-7,STAINED_CLAY:14)
Block(-6,10,-6,quark:iron_plate:1)
Block(-6,10,-5,quark:polished_stone:0)
Block(-6,10,-4,quark:polished_stone:0)
Block(-6,10,-3,quark:polished_stone:0)
Block(-6,10,-2,contenttweaker:reinforced_concrete:0)
Block(-6,10,-1,quark:world_stone_pavement:2)
Block(-6,10,0,contenttweaker:reinforced_concrete:0)
Block(-6,10,1,quark:world_stone_pavement:2)
Block(-6,10,2,quark:polished_stone:0)
Block(-6,10,3,quark:polished_stone:0)
Block(-6,11,-7,IRON_TRAPDOOR:4)
Block(-6,11,-6,quark:iron_plate:1)
RandomBlock(-6,11,-3,rustic:iron_lattice:0,30,rustic:iron_lattice:1,100)
Block(-6,11,0,quark:iron_plate:0)
RandomBlock(-6,11,3,contenttweaker:reinforced_concrete:0,40,SMOOTH_BRICK:1,30,SMOOTH_BRICK:2,30,MOSSY_COBBLESTONE:0,30,COBBLESTONE:0,20,contenttweaker:reinforced_concrete:0,100)
Block(-6,12,-7,STAINED_CLAY:4)
Block(-6,12,-6,CONCRETE:4)
RandomBlock(-6,12,-3,rustic:iron_lattice:0,30,rustic:iron_lattice:1,100)
Block(-6,12,0,quark:iron_plate_stairs:0)
RandomBlock(-6,12,3,contenttweaker:reinforced_concrete:0,40,SMOOTH_BRICK:1,30,SMOOTH_BRICK:2,30,MOSSY_COBBLESTONE:0,30,COBBLESTONE:0,20,contenttweaker:reinforced_concrete:0,100)
Block(-6,13,-6,quark:iron_plate_slab:0)
RandomBlock(-6,13,-3,rustic:iron_lattice:0,30,rustic:iron_lattice:1,100)
Block(-6,13,-2,quark:iron_plate_slab:0)
RandomBlock(-6,13,-1,rustic:iron_lattice:0,30,rustic:iron_lattice:1,100)
RandomBlock(-6,13,0,rustic:iron_lattice:0,30,rustic:iron_lattice:1,100)
RandomBlock(-6,13,1,rustic:iron_lattice:0,30,rustic:iron_lattice:1,100)
Block(-6,13,2,quark:iron_plate_slab:0)
RandomBlock(-6,13,3,contenttweaker:reinforced_concrete:0,40,SMOOTH_BRICK:1,30,SMOOTH_BRICK:2,30,MOSSY_COBBLESTONE:0,30,COBBLESTONE:0,20,contenttweaker:reinforced_concrete:0,100)
RandomBlock(-6,14,-3,rustic:iron_lattice:0,30,rustic:iron_lattice:1,100)
Block(-6,14,2,VINE:1)
RandomBlock(-6,14,3,contenttweaker:reinforced_concrete:0,40,SMOOTH_BRICK:1,30,SMOOTH_BRICK:2,30,MOSSY_COBBLESTONE:0,30,COBBLESTONE:0,20,contenttweaker:reinforced_concrete:0,100)
Block(-6,15,2,VINE:1)
RandomBlock(-6,15,3,contenttweaker:reinforced_concrete:0,40,SMOOTH_BRICK:1,30,SMOOTH_BRICK:2,30,MOSSY_COBBLESTONE:0,30,COBBLESTONE:0,20,contenttweaker:reinforced_concrete:0,100)
Block(-6,16,2,SMOOTH_STAIRS:6)
Block(-6,16,3,quark:iron_plate:1)
Block(-6,17,1,SMOOTH_STAIRS:6)
Block(-6,17,2,quark:polished_stone:0)
Block(-6,18,-6,quark:iron_plate:1)
Block(-6,18,-1,quark:iron_plate:1)
Block(-6,18,0,quark:polished_stone:0)
Block(-6,18,1,quark:polished_stone:0)
Block(-6,18,2,SMOOTH_STAIRS:3)
RandomBlock(-6,19,-7,contenttweaker:reinforced_concrete:0,40,SMOOTH_BRICK:1,30,SMOOTH_BRICK:2,30,MOSSY_COBBLESTONE:0,30,COBBLESTONE:0,20,contenttweaker:reinforced_concrete:0,100)
Block(-6,19,-6,quark:iron_plate:1)
RandomBlock(-6,19,-5,contenttweaker:reinforced_concrete:0,40,SMOOTH_BRICK:1,30,SMOOTH_BRICK:2,30,MOSSY_COBBLESTONE:0,30,COBBLESTONE:0,20,contenttweaker:reinforced_concrete:0,100)
RandomBlock(-6,19,-4,contenttweaker:reinforced_concrete:0,40,SMOOTH_BRICK:1,30,SMOOTH_BRICK:2,30,MOSSY_COBBLESTONE:0,30,COBBLESTONE:0,20,contenttweaker:reinforced_concrete:0,100)
RandomBlock(-6,19,-3,contenttweaker:reinforced_concrete:0,40,SMOOTH_BRICK:1,30,SMOOTH_BRICK:2,30,MOSSY_COBBLESTONE:0,30,COBBLESTONE:0,20,contenttweaker:reinforced_concrete:0,100)
RandomBlock(-6,19,-2,contenttweaker:reinforced_concrete:0,40,SMOOTH_BRICK:1,30,SMOOTH_BRICK:2,30,MOSSY_COBBLESTONE:0,30,COBBLESTONE:0,20,contenttweaker:reinforced_concrete:0,100)
Block(-6,19,-1,quark:iron_plate:1)
Block(-6,19,0,SMOOTH_STAIRS:3)
Block(-6,20,-1,quark:stone_diorite_bricks_wall:0)
Block(-5,0,-7,contenttweaker:reinforced_concrete:0)
Block(-5,0,-6,contenttweaker:reinforced_concrete:0)
Block(-5,0,-5,quark:world_stone_pavement:2)
Block(-5,0,-4,quark:world_stone_pavement:2)
Block(-5,0,-3,contenttweaker:reinforced_concrete:0)
Block(-5,0,-2,contenttweaker:reinforced_concrete:0)
Block(-5,0,-1,contenttweaker:reinforced_concrete:0)
Block(-5,0,0,contenttweaker:reinforced_concrete:0)
Block(-5,0,1,contenttweaker:reinforced_concrete:0)
Block(-5,0,2,contenttweaker:reinforced_concrete:0)
Block(-5,0,3,contenttweaker:reinforced_concrete:0)
Block(-5,1,-7,contenttweaker:reinforced_concrete:0)
Block(-5,1,-6,contenttweaker:reinforced_concrete:0)
Block(-5,1,-5,contenttweaker:reinforced_concrete:0)
Block(-5,1,-4,contenttweaker:reinforced_concrete:0)
Block(-5,1,-3,contenttweaker:reinforced_concrete:0)
Block(-5,1,-2,quark:world_stone_pavement:2)
Block(-5,1,-1,contenttweaker:reinforced_concrete:0)
Block(-5,1,0,contenttweaker:reinforced_concrete:0)
Block(-5,1,1,contenttweaker:reinforced_concrete:0)
Block(-5,1,2,quark:world_stone_pavement:2)
Block(-5,1,3,contenttweaker:reinforced_concrete:0)
Block(-5,2,-7,quark:polished_stone:0)
Block(-5,2,-6,quark:world_stone_pavement:2)
Block(-5,2,-5,quark:polished_stone:0)
Block(-5,2,-4,contenttweaker:reinforced_concrete:0)
Block(-5,2,-3,quark:world_stone_pavement:2)
Block(-5,2,-2,quark:world_stone_pavement:2)
Block(-5,2,-1,contenttweaker:reinforced_concrete:0)
Block(-5,2,0,contenttweaker:reinforced_concrete:0)
Block(-5,2,1,quark:world_stone_pavement:2)
Block(-5,2,2,contenttweaker:reinforced_concrete:0)
Block(-5,2,3,contenttweaker:reinforced_concrete:0)
Block(-5,3,-7,quark:polished_stone:0)
Block(-5,3,-6,quark:polished_stone:0)
Block(-5,3,-5,quark:polished_stone:0)
Block(-5,3,-4,quark:polished_stone:0)
Block(-5,3,-3,contenttweaker:reinforced_concrete:0)
Block(-5,3,-2,contenttweaker:reinforced_concrete:0)
Block(-5,3,-1,contenttweaker:reinforced_concrete:0)
Block(-5,3,0,contenttweaker:reinforced_concrete:0)
Block(-5,3,1,contenttweaker:reinforced_concrete:0)
Block(-5,3,2,contenttweaker:reinforced_concrete:0)
Block(-5,3,3,contenttweaker:reinforced_concrete:0)
Block(-5,4,-7,quark:polished_stone:0)
Block(-5,4,-6,quark:polished_stone:0)
Block(-5,4,-5,quark:polished_stone:0)
Block(-5,4,-4,quark:polished_stone:0)
Block(-5,4,-3,quark:polished_stone:0)
Block(-5,4,-2,quark:world_stone_pavement:2)
Block(-5,4,-1,contenttweaker:reinforced_concrete:0)
Block(-5,4,0,quark:world_stone_pavement:2)
Block(-5,4,1,contenttweaker:reinforced_concrete:0)
Block(-5,4,2,contenttweaker:reinforced_concrete:0)
Block(-5,4,3,contenttweaker:reinforced_concrete:0)
Block(-5,5,-7,quark:polished_stone:0)
Block(-5,5,-6,quark:polished_stone:0)
Block(-5,5,-5,quark:polished_stone:0)
Block(-5,5,-4,quark:polished_stone:0)
Block(-5,5,-3,quark:world_stone_pavement:2)
Block(-5,5,-2,contenttweaker:reinforced_concrete:0)
Block(-5,5,-1,contenttweaker:reinforced_concrete:0)
Block(-5,5,0,quark:world_stone_pavement:2)
Block(-5,5,1,contenttweaker:reinforced_concrete:0)
Block(-5,5,2,contenttweaker:reinforced_concrete:0)
Block(-5,5,3,contenttweaker:reinforced_concrete:0)
Block(-5,6,-7,quark:polished_stone:0)
Block(-5,6,-6,quark:polished_stone:0)
Block(-5,6,-5,quark:polished_stone:0)
Block(-5,6,-4,quark:polished_stone:0)
Block(-5,6,-3,quark:world_stone_pavement:2)
Block(-5,6,-2,contenttweaker:reinforced_concrete:0)
Block(-5,6,-1,contenttweaker:reinforced_concrete:0)
Block(-5,6,0,contenttweaker:reinforced_concrete:0)
Block(-5,6,1,contenttweaker:reinforced_concrete:0)
Block(-5,6,2,contenttweaker:reinforced_concrete:0)
Block(-5,6,3,contenttweaker:reinforced_concrete:0)
Block(-5,7,-7,contenttweaker:reinforced_concrete:0)
Block(-5,7,-6,contenttweaker:reinforced_concrete:0)
Block(-5,7,-5,quark:world_stone_pavement:2)
Block(-5,7,-4,quark:world_stone_pavement:2)
Block(-5,7,-3,contenttweaker:reinforced_concrete:0)
Block(-5,7,-2,contenttweaker:reinforced_concrete:0)
Block(-5,7,-1,quark:world_stone_pavement:2)
Block(-5,7,0,contenttweaker:reinforced_concrete:0)
Block(-5,7,1,contenttweaker:reinforced_concrete:0)
Block(-5,7,2,quark:polished_stone:0)
Block(-5,7,3,quark:polished_stone:0)
Block(-5,8,-7,contenttweaker:reinforced_concrete:0)
Block(-5,8,-6,contenttweaker:reinforced_concrete:0)
Block(-5,8,-5,quark:polished_stone:0)
Block(-5,8,-4,quark:polished_stone:0)
Block(-5,8,-3,quark:world_stone_pavement:2)
Block(-5,8,-2,contenttweaker:reinforced_concrete:0)
Block(-5,8,-1,quark:world_stone_pavement:2)
Block(-5,8,0,contenttweaker:reinforced_concrete:0)
Block(-5,8,1,quark:polished_stone:0)
Block(-5,8,2,quark:polished_stone:0)
Block(-5,8,3,quark:world_stone_pavement:2)
Block(-5,9,-7,quark:iron_plate:1)
Block(-5,9,-6,contenttweaker:reinforced_concrete:0)
Block(-5,9,-5,quark:iron_plate:1)
Block(-5,9,-4,quark:iron_plate:1)
Block(-5,9,-3,quark:iron_plate:1)
Block(-5,9,-2,quark:iron_plate:1)
Block(-5,9,-1,quark:iron_plate:1)
Block(-5,9,0,contenttweaker:reinforced_concrete:0)
Block(-5,9,1,quark:polished_stone:0)
Block(-5,9,2,quark:world_stone_pavement:2)
Block(-5,9,3,quark:world_stone_pavement:2)
Block(-5,10,-7,IRON_TRAPDOOR:5)
Block(-5,10,-6,quark:iron_plate:1)
Block(-5,10,-5,quark:iron_plate:1)
Block(-5,10,-4,quark:grate:0)
Block(-5,10,-3,quark:grate:0)
Block(-5,10,-2,quark:grate:0)
Block(-5,10,-1,quark:iron_plate:1)
Block(-5,10,0,contenttweaker:reinforced_concrete:0)
Block(-5,10,1,quark:world_stone_pavement:2)
Block(-5,10,2,quark:world_stone_pavement:2)
Block(-5,10,3,quark:world_stone_pavement:2)
Block(-5,11,-7,quark:iron_plate:0)
Block(-5,11,-6,quark:iron_plate:0)
Block(-5,11,-5,quark:iron_plate:1)
Block(-5,11,-1,quark:iron_plate:0)
Block(-5,11,1,quark:iron_plate:0)
Block(-5,11,3,DOUBLE_STEP:0)
Block(-5,12,-7,IRON_TRAPDOOR:5)
Block(-5,12,-6,CONCRETE:4)
Block(-5,12,-5,quark:iron_plate_stairs:3)
Block(-5,12,-1,quark:iron_plate_stairs:2)
Block(-5,12,0,quark:iron_plate:0)
Block(-5,12,1,quark:iron_plate_stairs:3)
Block(-5,12,3,DOUBLE_STEP:0)
Block(-5,13,-7,STAINED_CLAY:4)
Block(-5,13,-6,STAINED_CLAY:4)
RandomBlock(-5,13,-3,rustic:iron_lattice:0,30,rustic:iron_lattice:1,100)
Block(-5,13,-2,quark:iron_plate_slab:0)
RandomBlock(-5,13,-1,rustic:iron_lattice:0,30,rustic:iron_lattice:1,100)
RandomBlock(-5,13,0,rustic:iron_lattice:0,30,rustic:iron_lattice:1,100)
RandomBlock(-5,13,1,rustic:iron_lattice:0,30,rustic:iron_lattice:1,100)
Block(-5,13,2,quark:iron_plate_slab:0)
Block(-5,13,3,DOUBLE_STEP:0)
RandomBlock(-5,14,-3,rustic:iron_lattice:0,30,rustic:iron_lattice:1,100)
Block(-5,14,2,VINE:1)
Block(-5,14,3,DOUBLE_STEP:0)
Block(-5,15,2,VINE:1)
Block(-5,15,3,DOUBLE_STEP:0)
Block(-5,16,-7,quark:iron_plate_slab:8)
Block(-5,16,-6,quark:iron_plate_slab:8)
Block(-5,16,2,SMOOTH_STAIRS:6)
Block(-5,16,3,quark:iron_plate:1)
RandomBlock(-5,17,-7,rustic:iron_lattice:0,30,rustic:iron_lattice:1,100)
RandomBlock(-5,17,-6,rustic:iron_lattice:0,30,rustic:iron_lattice:1,100)
Block(-5,17,1,SMOOTH_STAIRS:6)
Block(-5,17,2,quark:polished_stone:0)
Block(-5,18,-7,quark:iron_plate:1)
Block(-5,18,-6,quark:iron_plate:1)
Block(-5,18,-1,quark:iron_plate:1)
Block(-5,18,0,quark:polished_stone:0)
Block(-5,18,1,quark:polished_stone:0)
Block(-5,18,2,SMOOTH_STAIRS:3)
RandomBlock(-5,19,-7,contenttweaker:reinforced_concrete:0,40,SMOOTH_BRICK:1,30,SMOOTH_BRICK:2,30,MOSSY_COBBLESTONE:0,30,COBBLESTONE:0,20,contenttweaker:reinforced_concrete:0,100)
Block(-5,19,-6,quark:iron_plate:1)
RandomBlock(-5,19,-5,contenttweaker:reinforced_concrete:0,40,SMOOTH_BRICK:1,30,SMOOTH_BRICK:2,30,MOSSY_COBBLESTONE:0,30,COBBLESTONE:0,20,contenttweaker:reinforced_concrete:0,100)
RandomBlock(-5,19,-4,contenttweaker:reinforced_concrete:0,40,SMOOTH_BRICK:1,30,SMOOTH_BRICK:2,30,MOSSY_COBBLESTONE:0,30,COBBLESTONE:0,20,contenttweaker:reinforced_concrete:0,100)
RandomBlock(-5,19,-3,contenttweaker:reinforced_concrete:0,40,SMOOTH_BRICK:1,30,SMOOTH_BRICK:2,30,MOSSY_COBBLESTONE:0,30,COBBLESTONE:0,20,contenttweaker:reinforced_concrete:0,100)
RandomBlock(-5,19,-2,contenttweaker:reinforced_concrete:0,40,SMOOTH_BRICK:1,30,SMOOTH_BRICK:2,30,MOSSY_COBBLESTONE:0,30,COBBLESTONE:0,20,contenttweaker:reinforced_concrete:0,100)
Block(-5,19,-1,quark:iron_plate:1)
Block(-5,19,0,SMOOTH_STAIRS:3)
Block(-5,20,-7,STEP:0)
Block(-5,20,-6,STEP:0)
Block(-5,20,-5,STEP:0)
Block(-5,20,-4,STEP:0)
Block(-5,20,-3,quark:iron_plate:1)
Block(-5,20,-1,quark:stone_diorite_bricks_wall:0)
Block(-4,0,-7,contenttweaker:reinforced_concrete:0)
Block(-4,0,-6,contenttweaker:reinforced_concrete:0)
Block(-4,0,-5,contenttweaker:reinforced_concrete:0)
Block(-4,0,-4,contenttweaker:reinforced_concrete:0)
Block(-4,0,-3,quark:world_stone_pavement:2)
Block(-4,0,-2,quark:world_stone_pavement:2)
Block(-4,0,-1,quark:world_stone_pavement:2)
Block(-4,0,0,quark:world_stone_pavement:2)
Block(-4,0,1,quark:world_stone_pavement:2)
Block(-4,0,2,quark:world_stone_pavement:2)
Block(-4,0,3,contenttweaker:reinforced_concrete:0)
Block(-4,1,-7,quark:polished_stone:0)
Block(-4,1,-6,quark:polished_stone:0)
Block(-4,1,-5,quark:polished_stone:0)
Block(-4,1,-4,contenttweaker:reinforced_concrete:0)
Block(-4,1,-3,contenttweaker:reinforced_concrete:0)
Block(-4,1,-2,quark:world_stone_pavement:2)
Block(-4,1,-1,contenttweaker:reinforced_concrete:0)
Block(-4,1,0,quark:world_stone_pavement:2)
Block(-4,1,1,contenttweaker:reinforced_concrete:0)
Block(-4,1,2,contenttweaker:reinforced_concrete:0)
Block(-4,1,3,quark:world_stone_pavement:2)
Block(-4,2,-7,quark:world_stone_pavement:2)
Block(-4,2,-6,quark:polished_stone:0)
Block(-4,2,-5,quark:polished_stone:0)
Block(-4,2,-4,quark:polished_stone:0)
Block(-4,2,-3,contenttweaker:reinforced_concrete:0)
Block(-4,2,-2,contenttweaker:reinforced_concrete:0)
Block(-4,2,-1,quark:world_stone_pavement:2)
Block(-4,2,0,quark:world_stone_pavement:2)
Block(-4,2,1,contenttweaker:reinforced_concrete:0)
Block(-4,2,2,quark:world_stone_pavement:2)
Block(-4,2,3,contenttweaker:reinforced_concrete:0)
Block(-4,3,-7,quark:world_stone_pavement:2)
Block(-4,3,-6,quark:polished_stone:0)
Block(-4,3,-5,quark:polished_stone:0)
Block(-4,3,-4,quark:polished_stone:0)
Block(-4,3,-3,quark:world_stone_pavement:2)
Block(-4,3,-2,contenttweaker:reinforced_concrete:0)
Block(-4,3,-1,quark:world_stone_pavement:2)
Block(-4,3,0,contenttweaker:reinforced_concrete:0)
Block(-4,3,1,contenttweaker:reinforced_concrete:0)
Block(-4,3,2,quark:world_stone_pavement:2)
Block(-4,3,3,contenttweaker:reinforced_concrete:0)
Block(-4,4,-7,quark:world_stone_pavement:2)
Block(-4,4,-6,quark:polished_stone:0)
Block(-4,4,-5,quark:polished_stone:0)
Block(-4,4,-4,quark:polished_stone:0)
Block(-4,4,-3,quark:polished_stone:0)
Block(-4,4,-2,contenttweaker:reinforced_concrete:0)
Block(-4,4,-1,contenttweaker:reinforced_concrete:0)
Block(-4,4,0,contenttweaker:reinforced_concrete:0)
Block(-4,4,1,contenttweaker:reinforced_concrete:0)
Block(-4,4,2,contenttweaker:reinforced_concrete:0)
Block(-4,4,3,contenttweaker:reinforced_concrete:0)
Block(-4,5,-7,quark:polished_stone:0)
Block(-4,5,-6,quark:polished_stone:0)
Block(-4,5,-5,quark:polished_stone:0)
Block(-4,5,-4,quark:polished_stone:0)
Block(-4,5,-3,quark:polished_stone:0)
Block(-4,5,-2,quark:world_stone_pavement:2)
Block(-4,5,-1,quark:world_stone_pavement:2)
Block(-4,5,0,quark:world_stone_pavement:2)
Block(-4,5,1,contenttweaker:reinforced_concrete:0)
Block(-4,5,2,quark:world_stone_pavement:2)
Block(-4,5,3,contenttweaker:reinforced_concrete:0)
Block(-4,6,-7,quark:polished_stone:0)
Block(-4,6,-6,quark:polished_stone:0)
Block(-4,6,-5,quark:world_stone_pavement:2)
Block(-4,6,-4,quark:world_stone_pavement:2)
Block(-4,6,-3,quark:polished_stone:0)
Block(-4,6,-2,contenttweaker:reinforced_concrete:0)
Block(-4,6,-1,quark:world_stone_pavement:2)
Block(-4,6,0,quark:world_stone_pavement:2)
Block(-4,6,1,contenttweaker:reinforced_concrete:0)
Block(-4,6,2,contenttweaker:reinforced_concrete:0)
Block(-4,6,3,contenttweaker:reinforced_concrete:0)
Block(-4,7,-7,quark:world_stone_pavement:2)
Block(-4,7,-6,quark:polished_stone:0)
Block(-4,7,-5,quark:polished_stone:0)
Block(-4,7,-4,quark:polished_stone:0)
Block(-4,7,-3,quark:polished_stone:0)
Block(-4,7,-2,contenttweaker:reinforced_concrete:0)
Block(-4,7,-1,contenttweaker:reinforced_concrete:0)
Block(-4,7,0,contenttweaker:reinforced_concrete:0)
Block(-4,7,1,contenttweaker:reinforced_concrete:0)
Block(-4,7,2,quark:world_stone_pavement:2)
Block(-4,7,3,quark:polished_stone:0)
Block(-4,8,-7,contenttweaker:reinforced_concrete:0)
Block(-4,8,-6,contenttweaker:reinforced_concrete:0)
Block(-4,8,-5,quark:world_stone_pavement:2)
Block(-4,8,-4,quark:world_stone_pavement:2)
Block(-4,8,-3,quark:world_stone_pavement:2)
Block(-4,8,-2,quark:world_stone_pavement:2)
Block(-4,8,-1,quark:world_stone_pavement:2)
Block(-4,8,0,quark:world_stone_pavement:2)
Block(-4,8,1,quark:world_stone_pavement:2)
Block(-4,8,2,quark:polished_stone:0)
Block(-4,8,3,quark:polished_stone:0)
Block(-4,9,-7,quark:iron_plate:1)
Block(-4,9,-6,contenttweaker:reinforced_concrete:0)
Block(-4,9,-5,quark:polished_stone:0)
Block(-4,9,-4,quark:polished_stone:0)
Block(-4,9,-3,quark:world_stone_pavement:2)
Block(-4,9,-2,contenttweaker:reinforced_concrete:0)
Block(-4,9,-1,quark:world_stone_pavement:2)
Block(-4,9,0,quark:iron_plate:1)
Block(-4,9,1,quark:world_stone_pavement:2)
Block(-4,9,2,quark:world_stone_pavement:2)
Block(-4,9,3,quark:world_stone_pavement:2)
Block(-4,10,-7,STAINED_CLAY:14)
Block(-4,10,-6,quark:iron_plate:1)
Block(-4,10,-5,quark:world_stone_pavement:2)
Block(-4,10,-4,quark:world_stone_pavement:2)
Block(-4,10,-3,quark:world_stone_pavement:2)
Block(-4,10,-2,quark:world_stone_pavement:2)
Block(-4,10,-1,quark:world_stone_pavement:2)
Block(-4,10,0,quark:iron_plate:1)
Block(-4,10,1,quark:world_stone_pavement:2)
Block(-4,10,2,quark:polished_stone:0)
Block(-4,10,3,quark:polished_stone:0)
Block(-4,11,-7,IRON_TRAPDOOR:4)
Block(-4,11,-6,quark:iron_plate:1)
RandomBlock(-4,11,-3,rustic:iron_lattice:0,30,rustic:iron_lattice:1,100)
Block(-4,11,0,quark:iron_plate:0)
RandomBlock(-4,11,3,contenttweaker:reinforced_concrete:0,40,SMOOTH_BRICK:1,30,SMOOTH_BRICK:2,30,MOSSY_COBBLESTONE:0,30,COBBLESTONE:0,20,contenttweaker:reinforced_concrete:0,100)
Block(-4,12,-7,CONCRETE:4)
Block(-4,12,-6,CONCRETE:4)
RandomBlock(-4,12,-3,rustic:iron_lattice:0,30,rustic:iron_lattice:1,100)
Block(-4,12,0,quark:iron_plate_stairs:1)
RandomBlock(-4,12,3,contenttweaker:reinforced_concrete:0,40,SMOOTH_BRICK:1,30,SMOOTH_BRICK:2,30,MOSSY_COBBLESTONE:0,30,COBBLESTONE:0,20,contenttweaker:reinforced_concrete:0,100)
Block(-4,13,-7,VINE:2)
Block(-4,13,-6,quark:iron_plate_slab:0)
RandomBlock(-4,13,-3,rustic:iron_lattice:0,30,rustic:iron_lattice:1,100)
Block(-4,13,-2,quark:iron_plate_slab:0)
RandomBlock(-4,13,-1,rustic:iron_lattice:0,30,rustic:iron_lattice:1,100)
RandomBlock(-4,13,0,rustic:iron_lattice:0,30,rustic:iron_lattice:1,100)
RandomBlock(-4,13,1,rustic:iron_lattice:0,30,rustic:iron_lattice:1,100)
Block(-4,13,2,quark:iron_plate_slab:0)
RandomBlock(-4,13,3,contenttweaker:reinforced_concrete:0,40,SMOOTH_BRICK:1,30,SMOOTH_BRICK:2,30,MOSSY_COBBLESTONE:0,30,COBBLESTONE:0,20,contenttweaker:reinforced_concrete:0,100)
RandomBlock(-4,14,-3,rustic:iron_lattice:0,30,rustic:iron_lattice:1,100)
Block(-4,14,2,VINE:1)
RandomBlock(-4,14,3,contenttweaker:reinforced_concrete:0,40,SMOOTH_BRICK:1,30,SMOOTH_BRICK:2,30,MOSSY_COBBLESTONE:0,30,COBBLESTONE:0,20,contenttweaker:reinforced_concrete:0,100)
Block(-4,15,2,VINE:1)
RandomBlock(-4,15,3,contenttweaker:reinforced_concrete:0,40,SMOOTH_BRICK:1,30,SMOOTH_BRICK:2,30,MOSSY_COBBLESTONE:0,30,COBBLESTONE:0,20,contenttweaker:reinforced_concrete:0,100)
Block(-4,16,2,SMOOTH_STAIRS:6)
Block(-4,16,3,quark:iron_plate:1)
Block(-4,17,1,SMOOTH_STAIRS:6)
Block(-4,17,2,quark:polished_stone:0)
Block(-4,18,-6,quark:iron_plate:1)
Block(-4,18,-1,quark:iron_plate:1)
Block(-4,18,0,quark:polished_stone:0)
Block(-4,18,1,quark:polished_stone:0)
Block(-4,18,2,SMOOTH_STAIRS:3)
RandomBlock(-4,19,-7,contenttweaker:reinforced_concrete:0,40,SMOOTH_BRICK:1,30,SMOOTH_BRICK:2,30,MOSSY_COBBLESTONE:0,30,COBBLESTONE:0,20,contenttweaker:reinforced_concrete:0,100)
Block(-4,19,-6,quark:iron_plate:1)
RandomBlock(-4,19,-5,contenttweaker:reinforced_concrete:0,40,SMOOTH_BRICK:1,30,SMOOTH_BRICK:2,30,MOSSY_COBBLESTONE:0,30,COBBLESTONE:0,20,contenttweaker:reinforced_concrete:0,100)
RandomBlock(-4,19,-4,contenttweaker:reinforced_concrete:0,40,SMOOTH_BRICK:1,30,SMOOTH_BRICK:2,30,MOSSY_COBBLESTONE:0,30,COBBLESTONE:0,20,contenttweaker:reinforced_concrete:0,100)
RandomBlock(-4,19,-3,contenttweaker:reinforced_concrete:0,40,SMOOTH_BRICK:1,30,SMOOTH_BRICK:2,30,MOSSY_COBBLESTONE:0,30,COBBLESTONE:0,20,contenttweaker:reinforced_concrete:0,100)
RandomBlock(-4,19,-2,contenttweaker:reinforced_concrete:0,40,SMOOTH_BRICK:1,30,SMOOTH_BRICK:2,30,MOSSY_COBBLESTONE:0,30,COBBLESTONE:0,20,contenttweaker:reinforced_concrete:0,100)
Block(-4,19,-1,quark:iron_plate:1)
Block(-4,19,0,SMOOTH_STAIRS:3)
Block(-4,20,-3,quark:basalt_wall:0)
Block(-4,20,-1,quark:stone_diorite_bricks_wall:0)
Block(-3,0,-7,quark:polished_stone:0)
Block(-3,0,-6,quark:world_stone_pavement:2)
Block(-3,0,-5,quark:polished_stone:0)
Block(-3,0,-4,contenttweaker:reinforced_concrete:0)
Block(-3,0,-3,contenttweaker:reinforced_concrete:0)
Block(-3,0,-2,quark:world_stone_pavement:2)
Block(-3,0,-1,quark:world_stone_pavement:2)
Block(-3,0,0,contenttweaker:reinforced_concrete:0)
Block(-3,0,1,contenttweaker:reinforced_concrete:0)
Block(-3,0,2,contenttweaker:reinforced_concrete:0)
Block(-3,0,3,contenttweaker:reinforced_concrete:0)
Block(-3,1,-7,quark:polished_stone:0)
Block(-3,1,-6,quark:world_stone_pavement:2)
Block(-3,1,-5,quark:polished_stone:0)
Block(-3,1,-4,quark:polished_stone:0)
Block(-3,1,-3,quark:world_stone_pavement:2)
Block(-3,1,-2,contenttweaker:reinforced_concrete:0)
Block(-3,1,-1,contenttweaker:reinforced_concrete:0)
Block(-3,1,0,contenttweaker:reinforced_concrete:0)
Block(-3,1,1,contenttweaker:reinforced_concrete:0)
Block(-3,1,2,contenttweaker:reinforced_concrete:0)
Block(-3,1,3,contenttweaker:reinforced_concrete:0)
Block(-3,2,-7,quark:world_stone_pavement:2)
Block(-3,2,-6,quark:world_stone_pavement:2)
Block(-3,2,-5,quark:polished_stone:0)
Block(-3,2,-4,quark:polished_stone:0)
Block(-3,2,-3,contenttweaker:reinforced_concrete:0)
Block(-3,2,-2,quark:world_stone_pavement:2)
Block(-3,2,-1,quark:world_stone_pavement:2)
Block(-3,2,0,contenttweaker:reinforced_concrete:0)
Block(-3,2,1,contenttweaker:reinforced_concrete:0)
Block(-3,2,2,quark:world_stone_pavement:2)
Block(-3,2,3,quark:world_stone_pavement:2)
Block(-3,3,-7,quark:world_stone_pavement:2)
Block(-3,3,-6,quark:polished_stone:0)
Block(-3,3,-5,quark:polished_stone:0)
Block(-3,3,-4,quark:polished_stone:0)
Block(-3,3,-3,quark:polished_stone:0)
Block(-3,3,-2,quark:world_stone_pavement:2)
Block(-3,3,-1,contenttweaker:reinforced_concrete:0)
Block(-3,3,0,quark:world_stone_pavement:2)
Block(-3,3,1,contenttweaker:reinforced_concrete:0)
Block(-3,3,2,contenttweaker:reinforced_concrete:0)
Block(-3,3,3,contenttweaker:reinforced_concrete:0)
Block(-3,4,-7,AIR:0)
Block(-3,4,-6,AIR:0)
RandomBlock(-3,4,-5,CHEST:2,20,CHEST:2,10,CHEST:2,5,CHEST:2,50,CHEST:2,100)
Block(-3,4,-4,quark:world_stone_pavement:2)
Block(-3,4,-3,quark:polished_stone:0)
Block(-3,4,-2,contenttweaker:reinforced_concrete:0)
Block(-3,4,-1,contenttweaker:reinforced_concrete:0)
Block(-3,4,0,contenttweaker:reinforced_concrete:0)
Block(-3,4,1,quark:world_stone_pavement:2)
Block(-3,4,2,contenttweaker:reinforced_concrete:0)
Block(-3,4,3,quark:world_stone_pavement:2)
Block(-3,5,-7,AIR:0)
Block(-3,5,-6,AIR:0)
Block(-3,5,-5,AIR:0)
Block(-3,5,-4,quark:polished_stone:0)
Block(-3,5,-3,quark:world_stone_pavement:2)
Block(-3,5,-2,quark:world_stone_pavement:2)
Block(-3,5,-1,contenttweaker:reinforced_concrete:0)
Block(-3,5,0,contenttweaker:reinforced_concrete:0)
Block(-3,5,1,quark:world_stone_pavement:2)
Block(-3,5,2,contenttweaker:reinforced_concrete:0)
Block(-3,5,3,contenttweaker:reinforced_concrete:0)
Block(-3,6,-7,AIR:0)
Block(-3,6,-6,AIR:0)
Block(-3,6,-5,variedcommodities:lamp:0)
Block(-3,6,-4,quark:polished_stone:0)
Block(-3,6,-3,quark:polished_stone:0)
Block(-3,6,-2,contenttweaker:reinforced_concrete:0)
Block(-3,6,-1,quark:world_stone_pavement:2)
Block(-3,6,0,contenttweaker:reinforced_concrete:0)
Block(-3,6,1,quark:world_stone_pavement:2)
Block(-3,6,2,quark:world_stone_pavement:2)
Block(-3,6,3,quark:world_stone_pavement:2)
Block(-3,7,-7,quark:world_stone_pavement:2)
Block(-3,7,-6,quark:polished_stone:0)
Block(-3,7,-5,quark:polished_stone:0)
Block(-3,7,-4,quark:polished_stone:0)
Block(-3,7,-3,quark:polished_stone:0)
Block(-3,7,-2,contenttweaker:reinforced_concrete:0)
Block(-3,7,-1,contenttweaker:reinforced_concrete:0)
Block(-3,7,0,contenttweaker:reinforced_concrete:0)
Block(-3,7,1,quark:world_stone_pavement:2)
Block(-3,7,2,contenttweaker:reinforced_concrete:0)
Block(-3,7,3,quark:world_stone_pavement:2)
Block(-3,8,-7,quark:world_stone_pavement:2)
Block(-3,8,-6,quark:polished_stone:0)
Block(-3,8,-5,quark:world_stone_pavement:2)
Block(-3,8,-4,quark:world_stone_pavement:2)
Block(-3,8,-3,quark:polished_stone:0)
Block(-3,8,-2,contenttweaker:reinforced_concrete:0)
Block(-3,8,-1,contenttweaker:reinforced_concrete:0)
Block(-3,8,0,contenttweaker:reinforced_concrete:0)
Block(-3,8,1,contenttweaker:reinforced_concrete:0)
Block(-3,8,2,quark:polished_stone:0)
Block(-3,8,3,quark:polished_stone:0)
Block(-3,9,-7,quark:world_stone_pavement:2)
Block(-3,9,-6,contenttweaker:reinforced_concrete:0)
Block(-3,9,-5,quark:polished_stone:0)
Block(-3,9,-4,quark:polished_stone:0)
Block(-3,9,-3,quark:polished_stone:0)
Block(-3,9,-2,contenttweaker:reinforced_concrete:0)
Block(-3,9,-1,contenttweaker:reinforced_concrete:0)
Block(-3,9,0,quark:iron_plate:1)
Block(-3,9,1,quark:polished_stone:0)
Block(-3,9,2,quark:polished_stone:0)
Block(-3,9,3,quark:world_stone_pavement:2)
Block(-3,10,-7,quark:iron_plate:1)
Block(-3,10,-6,quark:iron_plate:1)
Block(-3,10,-5,quark:world_stone_pavement:2)
Block(-3,10,-4,quark:world_stone_pavement:2)
Block(-3,10,-3,quark:polished_stone:0)
Block(-3,10,-2,quark:world_stone_pavement:2)
Block(-3,10,-1,contenttweaker:reinforced_concrete:0)
Block(-3,10,0,quark:grate:0)
Block(-3,10,1,quark:polished_stone:0)
Block(-3,10,2,quark:world_stone_pavement:2)
Block(-3,10,3,quark:world_stone_pavement:2)
Block(-3,11,-7,quark:iron_plate:1)
Block(-3,11,-6,quark:iron_plate:1)
RandomBlock(-3,11,-3,rustic:iron_lattice:0,30,rustic:iron_lattice:1,100)
Block(-3,11,3,DOUBLE_STEP:0)
Block(-3,12,-6,quark:stone_limestone_bricks_stairs:1)
RandomBlock(-3,12,-3,rustic:iron_lattice:0,30,rustic:iron_lattice:1,100)
Block(-3,12,1,quark:iron_plate_stairs:4)
Block(-3,12,2,quark:iron_plate_stairs:4)
Block(-3,12,3,DOUBLE_STEP:0)
RandomBlock(-3,13,-3,rustic:iron_lattice:0,30,rustic:iron_lattice:1,100)
Block(-3,13,-2,quark:iron_plate_slab:0)
Block(-3,13,-1,quark:iron_plate_slab:0)
Block(-3,13,0,quark:iron_plate_slab:0)
Block(-3,13,1,quark:iron_plate_slab:0)
Block(-3,13,2,quark:iron_plate_slab:0)
Block(-3,13,3,DOUBLE_STEP:0)
RandomBlock(-3,14,-3,rustic:iron_lattice:0,30,rustic:iron_lattice:1,100)
Block(-3,14,2,VINE:1)
Block(-3,14,3,DOUBLE_STEP:0)
Block(-3,15,2,VINE:1)
Block(-3,15,3,DOUBLE_STEP:0)
Block(-3,16,2,SMOOTH_STAIRS:6)
Block(-3,16,3,quark:iron_plate:1)
Block(-3,17,1,SMOOTH_STAIRS:6)
Block(-3,17,2,quark:polished_stone:0)
Block(-3,18,-6,quark:iron_plate:1)
Block(-3,18,-1,quark:iron_plate:1)
Block(-3,18,0,quark:polished_stone:0)
Block(-3,18,1,quark:polished_stone:0)
Block(-3,18,2,SMOOTH_STAIRS:3)
RandomBlock(-3,19,-7,contenttweaker:reinforced_concrete:0,40,SMOOTH_BRICK:1,30,SMOOTH_BRICK:2,30,MOSSY_COBBLESTONE:0,30,COBBLESTONE:0,20,contenttweaker:reinforced_concrete:0,100)
Block(-3,19,-6,quark:iron_plate:1)
RandomBlock(-3,19,-5,contenttweaker:reinforced_concrete:0,40,SMOOTH_BRICK:1,30,SMOOTH_BRICK:2,30,MOSSY_COBBLESTONE:0,30,COBBLESTONE:0,20,contenttweaker:reinforced_concrete:0,100)
RandomBlock(-3,19,-4,contenttweaker:reinforced_concrete:0,40,SMOOTH_BRICK:1,30,SMOOTH_BRICK:2,30,MOSSY_COBBLESTONE:0,30,COBBLESTONE:0,20,contenttweaker:reinforced_concrete:0,100)
RandomBlock(-3,19,-3,contenttweaker:reinforced_concrete:0,40,SMOOTH_BRICK:1,30,SMOOTH_BRICK:2,30,MOSSY_COBBLESTONE:0,30,COBBLESTONE:0,20,contenttweaker:reinforced_concrete:0,100)
RandomBlock(-3,19,-2,contenttweaker:reinforced_concrete:0,40,SMOOTH_BRICK:1,30,SMOOTH_BRICK:2,30,MOSSY_COBBLESTONE:0,30,COBBLESTONE:0,20,contenttweaker:reinforced_concrete:0,100)
Block(-3,19,-1,quark:iron_plate:1)
Block(-3,19,0,SMOOTH_STAIRS:3)
Block(-3,20,-3,quark:basalt_wall:0)
Block(-3,20,-1,quark:stone_diorite_bricks_wall:0)
Block(-2,0,-7,quark:polished_stone:0)
Block(-2,0,-6,quark:polished_stone:0)
Block(-2,0,-5,quark:world_stone_pavement:2)
Block(-2,0,-4,quark:world_stone_pavement:2)
Block(-2,0,-3,contenttweaker:reinforced_concrete:0)
Block(-2,0,-2,contenttweaker:reinforced_concrete:0)
Block(-2,0,-1,quark:world_stone_pavement:2)
Block(-2,0,0,contenttweaker:reinforced_concrete:0)
Block(-2,0,1,contenttweaker:reinforced_concrete:0)
Block(-2,0,2,contenttweaker:reinforced_concrete:0)
Block(-2,0,3,quark:world_stone_pavement:2)
Block(-2,1,-7,quark:polished_stone:0)
Block(-2,1,-6,quark:polished_stone:0)
Block(-2,1,-5,quark:polished_stone:0)
Block(-2,1,-4,quark:polished_stone:0)
Block(-2,1,-3,quark:world_stone_pavement:2)
Block(-2,1,-2,quark:world_stone_pavement:2)
Block(-2,1,-1,contenttweaker:reinforced_concrete:0)
Block(-2,1,0,contenttweaker:reinforced_concrete:0)
Block(-2,1,1,quark:world_stone_pavement:2)
Block(-2,1,2,quark:world_stone_pavement:2)
Block(-2,1,3,contenttweaker:reinforced_concrete:0)
Block(-2,2,-7,quark:polished_stone:0)
Block(-2,2,-6,quark:polished_stone:0)
Block(-2,2,-5,quark:polished_stone:0)
Block(-2,2,-4,quark:polished_stone:0)
Block(-2,2,-3,contenttweaker:reinforced_concrete:0)
Block(-2,2,-2,contenttweaker:reinforced_concrete:0)
Block(-2,2,-1,contenttweaker:reinforced_concrete:0)
Block(-2,2,0,quark:world_stone_pavement:2)
Block(-2,2,1,contenttweaker:reinforced_concrete:0)
Block(-2,2,2,contenttweaker:reinforced_concrete:0)
Block(-2,2,3,contenttweaker:reinforced_concrete:0)
Block(-2,3,-7,quark:polished_stone:0)
Block(-2,3,-6,quark:world_stone_pavement:2)
Block(-2,3,-5,quark:world_stone_pavement:2)
Block(-2,3,-4,quark:world_stone_pavement:2)
Block(-2,3,-3,quark:polished_stone:0)
Block(-2,3,-2,quark:world_stone_pavement:2)
Block(-2,3,-1,quark:world_stone_pavement:2)
Block(-2,3,0,contenttweaker:reinforced_concrete:0)
Block(-2,3,1,contenttweaker:reinforced_concrete:0)
Block(-2,3,2,contenttweaker:reinforced_concrete:0)
Block(-2,3,3,quark:world_stone_pavement:2)
RandomBlock(-2,4,-7,rustic:iron_lattice:0,30,rustic:iron_lattice:1,100)
RandomBlock(-2,4,-6,rustic:iron_lattice:0,30,rustic:iron_lattice:1,100)
RandomBlock(-2,4,-5,rustic:iron_lattice:0,30,rustic:iron_lattice:1,100)
Block(-2,4,-4,quark:polished_stone:0)
Block(-2,4,-3,quark:polished_stone:0)
Block(-2,4,-2,contenttweaker:reinforced_concrete:0)
Block(-2,4,-1,quark:world_stone_pavement:2)
Block(-2,4,0,contenttweaker:reinforced_concrete:0)
Block(-2,4,1,contenttweaker:reinforced_concrete:0)
Block(-2,4,2,quark:world_stone_pavement:2)
Block(-2,4,3,quark:world_stone_pavement:2)
RandomBlock(-2,5,-7,rustic:iron_lattice:0,30,rustic:iron_lattice:1,100)
RandomBlock(-2,5,-6,rustic:iron_lattice:0,30,rustic:iron_lattice:1,100)
RandomBlock(-2,5,-5,rustic:iron_lattice:0,30,rustic:iron_lattice:1,100)
Block(-2,5,-4,quark:world_stone_pavement:2)
Block(-2,5,-3,quark:world_stone_pavement:2)
Block(-2,5,-2,contenttweaker:reinforced_concrete:0)
Block(-2,5,-1,contenttweaker:reinforced_concrete:0)
Block(-2,5,0,quark:world_stone_pavement:2)
Block(-2,5,1,quark:world_stone_pavement:2)
Block(-2,5,2,quark:world_stone_pavement:2)
Block(-2,5,3,quark:world_stone_pavement:2)
RandomBlock(-2,6,-7,rustic:iron_lattice:0,30,rustic:iron_lattice:1,100)
RandomBlock(-2,6,-6,rustic:iron_lattice:0,30,rustic:iron_lattice:1,100)
RandomBlock(-2,6,-5,rustic:iron_lattice:0,30,rustic:iron_lattice:1,100)
Block(-2,6,-4,quark:polished_stone:0)
Block(-2,6,-3,quark:polished_stone:0)
Block(-2,6,-2,quark:world_stone_pavement:2)
Block(-2,6,-1,contenttweaker:reinforced_concrete:0)
Block(-2,6,0,contenttweaker:reinforced_concrete:0)
Block(-2,6,1,contenttweaker:reinforced_concrete:0)
Block(-2,6,2,quark:world_stone_pavement:2)
Block(-2,6,3,contenttweaker:reinforced_concrete:0)
Block(-2,7,-7,AIR:0)
Block(-2,7,-6,AIR:0)
Block(-2,7,-5,AIR:0)
Block(-2,7,-4,quark:polished_stone:0)
Block(-2,7,-3,quark:world_stone_pavement:2)
Block(-2,7,-2,quark:world_stone_pavement:2)
Block(-2,7,-1,contenttweaker:reinforced_concrete:0)
Block(-2,7,0,quark:world_stone_pavement:2)
Block(-2,7,1,quark:world_stone_pavement:2)
Block(-2,7,2,contenttweaker:reinforced_concrete:0)
Block(-2,7,3,contenttweaker:reinforced_concrete:0)
Block(-2,8,-7,AIR:0)
Block(-2,8,-6,AIR:0)
Block(-2,8,-5,AIR:0)
Block(-2,8,-4,contenttweaker:reinforced_concrete:0)
Block(-2,8,-3,contenttweaker:reinforced_concrete:0)
Block(-2,8,-2,contenttweaker:reinforced_concrete:0)
Block(-2,8,-1,quark:world_stone_pavement:2)
Block(-2,8,0,contenttweaker:reinforced_concrete:0)
Block(-2,8,1,contenttweaker:reinforced_concrete:0)
Block(-2,8,2,quark:polished_stone:0)
Block(-2,8,3,quark:polished_stone:0)
Block(-2,9,-7,contenttweaker:reinforced_concrete:0)
Block(-2,9,-6,quark:world_stone_pavement:2)
Block(-2,9,-5,quark:polished_stone:0)
Block(-2,9,-4,quark:polished_stone:0)
Block(-2,9,-3,quark:polished_stone:0)
Block(-2,9,-2,quark:world_stone_pavement:2)
Block(-2,9,-1,contenttweaker:reinforced_concrete:0)
Block(-2,9,0,quark:iron_plate:1)
Block(-2,9,1,quark:polished_stone:0)
Block(-2,9,2,quark:world_stone_pavement:2)
Block(-2,9,3,quark:polished_stone:0)
Block(-2,10,-7,contenttweaker:reinforced_concrete:0)
Block(-2,10,-6,contenttweaker:reinforced_concrete:0)
Block(-2,10,-5,quark:world_stone_pavement:2)
Block(-2,10,-4,quark:world_stone_pavement:2)
Block(-2,10,-3,quark:polished_stone:0)
Block(-2,10,-2,quark:world_stone_pavement:2)
Block(-2,10,-1,contenttweaker:reinforced_concrete:0)
Block(-2,10,0,quark:grate:0)
Block(-2,10,1,quark:polished_stone:0)
Block(-2,10,2,quark:polished_stone:0)
Block(-2,10,3,quark:polished_stone:0)
RandomBlock(-2,11,-3,rustic:iron_lattice:0,30,rustic:iron_lattice:1,100)
RandomBlock(-2,11,-2,rustic:iron_lattice:0,30,rustic:iron_lattice:1,100)
RandomBlock(-2,11,-1,rustic:iron_lattice:0,30,rustic:iron_lattice:1,100)
Block(-2,11,1,quark:iron_plate_stairs:4)
Block(-2,11,2,quark:iron_plate_stairs:4)
RandomBlock(-2,11,3,contenttweaker:reinforced_concrete:0,40,SMOOTH_BRICK:1,30,SMOOTH_BRICK:2,30,MOSSY_COBBLESTONE:0,30,COBBLESTONE:0,20,contenttweaker:reinforced_concrete:0,100)
RandomBlock(-2,12,-3,rustic:iron_lattice:0,30,rustic:iron_lattice:1,100)
RandomBlock(-2,12,-2,rustic:iron_lattice:0,30,rustic:iron_lattice:1,100)
RandomBlock(-2,12,-1,rustic:iron_lattice:0,30,rustic:iron_lattice:1,100)
Block(-2,12,1,quark:iron_plate_stairs:1)
Block(-2,12,2,quark:iron_plate_stairs:1)
RandomBlock(-2,12,3,contenttweaker:reinforced_concrete:0,40,SMOOTH_BRICK:1,30,SMOOTH_BRICK:2,30,MOSSY_COBBLESTONE:0,30,COBBLESTONE:0,20,contenttweaker:reinforced_concrete:0,100)
RandomBlock(-2,13,-3,rustic:iron_lattice:0,30,rustic:iron_lattice:1,100)
RandomBlock(-2,13,-2,rustic:iron_lattice:0,30,rustic:iron_lattice:1,100)
RandomBlock(-2,13,-1,rustic:iron_lattice:0,30,rustic:iron_lattice:1,100)
RandomBlock(-2,13,0,rustic:iron_lattice:0,30,rustic:iron_lattice:1,100)
Block(-2,13,2,VINE:1)
RandomBlock(-2,13,3,contenttweaker:reinforced_concrete:0,40,SMOOTH_BRICK:1,30,SMOOTH_BRICK:2,30,MOSSY_COBBLESTONE:0,30,COBBLESTONE:0,20,contenttweaker:reinforced_concrete:0,100)
RandomBlock(-2,14,-3,rustic:iron_lattice:0,30,rustic:iron_lattice:1,100)
RandomBlock(-2,14,-2,rustic:iron_lattice:0,30,rustic:iron_lattice:1,100)
RandomBlock(-2,14,-1,rustic:iron_lattice:0,30,rustic:iron_lattice:1,100)
Block(-2,14,2,VINE:1)
RandomBlock(-2,14,3,contenttweaker:reinforced_concrete:0,40,SMOOTH_BRICK:1,30,SMOOTH_BRICK:2,30,MOSSY_COBBLESTONE:0,30,COBBLESTONE:0,20,contenttweaker:reinforced_concrete:0,100)
Block(-2,15,2,VINE:1)
RandomBlock(-2,15,3,contenttweaker:reinforced_concrete:0,40,SMOOTH_BRICK:1,30,SMOOTH_BRICK:2,30,MOSSY_COBBLESTONE:0,30,COBBLESTONE:0,20,contenttweaker:reinforced_concrete:0,100)
Block(-2,16,2,SMOOTH_STAIRS:6)
Block(-2,16,3,quark:iron_plate:1)
Block(-2,17,1,SMOOTH_STAIRS:6)
Block(-2,17,2,quark:polished_stone:0)
Block(-2,18,-6,quark:iron_plate:1)
Block(-2,18,-1,quark:iron_plate:1)
Block(-2,18,0,quark:polished_stone:0)
Block(-2,18,1,quark:polished_stone:0)
Block(-2,18,2,SMOOTH_STAIRS:3)
RandomBlock(-2,19,-7,contenttweaker:reinforced_concrete:0,40,SMOOTH_BRICK:1,30,SMOOTH_BRICK:2,30,MOSSY_COBBLESTONE:0,30,COBBLESTONE:0,20,contenttweaker:reinforced_concrete:0,100)
Block(-2,19,-6,quark:iron_plate:1)
RandomBlock(-2,19,-5,contenttweaker:reinforced_concrete:0,40,SMOOTH_BRICK:1,30,SMOOTH_BRICK:2,30,MOSSY_COBBLESTONE:0,30,COBBLESTONE:0,20,contenttweaker:reinforced_concrete:0,100)
RandomBlock(-2,19,-4,contenttweaker:reinforced_concrete:0,40,SMOOTH_BRICK:1,30,SMOOTH_BRICK:2,30,MOSSY_COBBLESTONE:0,30,COBBLESTONE:0,20,contenttweaker:reinforced_concrete:0,100)
RandomBlock(-2,19,-3,contenttweaker:reinforced_concrete:0,40,SMOOTH_BRICK:1,30,SMOOTH_BRICK:2,30,MOSSY_COBBLESTONE:0,30,COBBLESTONE:0,20,contenttweaker:reinforced_concrete:0,100)
RandomBlock(-2,19,-2,contenttweaker:reinforced_concrete:0,40,SMOOTH_BRICK:1,30,SMOOTH_BRICK:2,30,MOSSY_COBBLESTONE:0,30,COBBLESTONE:0,20,contenttweaker:reinforced_concrete:0,100)
Block(-2,19,-1,quark:iron_plate:1)
Block(-2,19,0,SMOOTH_STAIRS:3)
Block(-2,20,-3,DISPENSER:1)
Block(-2,20,-1,quark:stone_diorite_bricks_wall:0)
Block(-2,21,-3,IRON_TRAPDOOR:2)
Block(-1,0,-7,quark:polished_stone:0)
Block(-1,0,-6,quark:polished_stone:0)
Block(-1,0,-5,quark:world_stone_pavement:2)
Block(-1,0,-4,contenttweaker:reinforced_concrete:0)
Block(-1,0,-3,quark:world_stone_pavement:2)
Block(-1,0,-2,quark:world_stone_pavement:2)
Block(-1,0,-1,quark:world_stone_pavement:2)
Block(-1,0,0,quark:world_stone_pavement:2)
Block(-1,0,1,contenttweaker:reinforced_concrete:0)
Block(-1,0,2,contenttweaker:reinforced_concrete:0)
Block(-1,0,3,contenttweaker:reinforced_concrete:0)
Block(-1,1,-7,quark:grate:0)
Block(-1,1,-6,quark:grate:0)
Block(-1,1,-5,quark:grate:0)
Block(-1,1,-4,quark:grate:0)
Block(-1,1,-3,contenttweaker:reinforced_concrete:0)
Block(-1,1,-2,contenttweaker:reinforced_concrete:0)
Block(-1,1,-1,quark:world_stone_pavement:2)
Block(-1,1,0,contenttweaker:reinforced_concrete:0)
Block(-1,1,1,contenttweaker:reinforced_concrete:0)
Block(-1,1,2,quark:world_stone_pavement:2)
Block(-1,1,3,quark:world_stone_pavement:2)
Block(-1,2,-7,AIR:0)
Block(-1,2,-6,AIR:0)
Block(-1,2,-5,AIR:0)
Block(-1,2,-4,AIR:0)
Block(-1,2,-3,quark:world_stone_pavement:2)
Block(-1,2,-2,contenttweaker:reinforced_concrete:0)
Block(-1,2,-1,contenttweaker:reinforced_concrete:0)
Block(-1,2,0,contenttweaker:reinforced_concrete:0)
Block(-1,2,1,contenttweaker:reinforced_concrete:0)
Block(-1,2,2,quark:world_stone_pavement:2)
Block(-1,2,3,contenttweaker:reinforced_concrete:0)
Block(-1,3,-7,AIR:0)
Block(-1,3,-6,AIR:0)
Block(-1,3,-5,AIR:0)
Block(-1,3,-4,AIR:0)
Block(-1,3,-3,quark:world_stone_pavement:2)
Block(-1,3,-2,contenttweaker:reinforced_concrete:0)
Block(-1,3,-1,contenttweaker:reinforced_concrete:0)
Block(-1,3,0,contenttweaker:reinforced_concrete:0)
Block(-1,3,1,contenttweaker:reinforced_concrete:0)
Block(-1,3,2,quark:world_stone_pavement:2)
Block(-1,3,3,contenttweaker:reinforced_concrete:0)
Block(-1,4,-7,AIR:0)
Block(-1,4,-6,AIR:0)
Block(-1,4,-5,AIR:0)
Block(-1,4,-4,AIR:0)
Block(-1,4,-3,quark:polished_stone:0)
Block(-1,4,-2,contenttweaker:reinforced_concrete:0)
Block(-1,4,-1,contenttweaker:reinforced_concrete:0)
Block(-1,4,0,contenttweaker:reinforced_concrete:0)
Block(-1,4,1,quark:world_stone_pavement:2)
Block(-1,4,2,contenttweaker:reinforced_concrete:0)
Block(-1,4,3,quark:world_stone_pavement:2)
Block(-1,5,-7,AIR:0)
Block(-1,5,-6,AIR:0)
Block(-1,5,-5,AIR:0)
Block(-1,5,-4,AIR:0)
Block(-1,5,-3,quark:polished_stone:0)
Block(-1,5,-2,contenttweaker:reinforced_concrete:0)
Block(-1,5,-1,contenttweaker:reinforced_concrete:0)
Block(-1,5,0,contenttweaker:reinforced_concrete:0)
Block(-1,5,1,contenttweaker:reinforced_concrete:0)
Block(-1,5,2,quark:world_stone_pavement:2)
Block(-1,5,3,quark:world_stone_pavement:2)
Block(-1,6,-7,AIR:0)
Block(-1,6,-6,AIR:0)
Block(-1,6,-5,AIR:0)
Block(-1,6,-4,AIR:0)
Block(-1,6,-3,quark:world_stone_pavement:2)
Block(-1,6,-2,contenttweaker:reinforced_concrete:0)
Block(-1,6,-1,contenttweaker:reinforced_concrete:0)
Block(-1,6,0,quark:world_stone_pavement:2)
Block(-1,6,1,contenttweaker:reinforced_concrete:0)
Block(-1,6,2,contenttweaker:reinforced_concrete:0)
Block(-1,6,3,quark:world_stone_pavement:2)
Block(-1,7,-7,AIR:0)
Block(-1,7,-6,AIR:0)
Block(-1,7,-5,AIR:0)
Block(-1,7,-4,AIR:0)
Block(-1,7,-3,quark:world_stone_pavement:2)
Block(-1,7,-2,contenttweaker:reinforced_concrete:0)
Block(-1,7,-1,contenttweaker:reinforced_concrete:0)
Block(-1,7,0,contenttweaker:reinforced_concrete:0)
Block(-1,7,1,quark:world_stone_pavement:2)
Block(-1,7,2,quark:world_stone_pavement:2)
Block(-1,7,3,quark:world_stone_pavement:2)
Block(-1,8,-7,AIR:0)
Block(-1,8,-6,AIR:0)
Block(-1,8,-5,AIR:0)
Block(-1,8,-4,AIR:0)
Block(-1,8,-3,quark:world_stone_pavement:2)
Block(-1,8,-2,contenttweaker:reinforced_concrete:0)
Block(-1,8,-1,quark:world_stone_pavement:2)
Block(-1,8,0,contenttweaker:reinforced_concrete:0)
Block(-1,8,1,contenttweaker:reinforced_concrete:0)
Block(-1,8,2,quark:polished_stone:0)
Block(-1,8,3,quark:polished_stone:0)
Block(-1,9,-7,AIR:0)
Block(-1,9,-6,AIR:0)
Block(-1,9,-5,AIR:0)
Block(-1,9,-4,quark:iron_plate_stairs:6)
Block(-1,9,-3,quark:world_stone_pavement:2)
Block(-1,9,-2,contenttweaker:reinforced_concrete:0)
Block(-1,9,-1,contenttweaker:reinforced_concrete:0)
Block(-1,9,0,quark:iron_plate:1)
Block(-1,9,1,quark:polished_stone:0)
Block(-1,9,2,quark:polished_stone:0)
Block(-1,9,3,quark:world_stone_pavement:2)
Block(-1,10,-7,quark:iron_plate_stairs:5)
Block(-1,10,-6,quark:iron_plate_stairs:5)
Block(-1,10,-5,quark:iron_plate_stairs:6)
Block(-1,10,-4,quark:world_stone_pavement:2)
Block(-1,10,-3,quark:polished_stone:0)
Block(-1,10,-2,quark:world_stone_pavement:2)
Block(-1,10,-1,contenttweaker:reinforced_concrete:0)
Block(-1,10,0,quark:grate:0)
Block(-1,10,1,quark:polished_stone:0)
Block(-1,10,2,quark:polished_stone:0)
Block(-1,10,3,quark:polished_stone:0)
RandomBlock(-1,11,-7,rustic:iron_lattice:0,30,rustic:iron_lattice:1,100)
RandomBlock(-1,11,-6,rustic:iron_lattice:0,30,rustic:iron_lattice:1,100)
RandomBlock(-1,11,-5,rustic:iron_lattice:0,30,rustic:iron_lattice:1,100)
Block(-1,11,1,quark:iron_plate_stairs:1)
Block(-1,11,2,quark:iron_plate_stairs:1)
Block(-1,11,3,DOUBLE_STEP:0)
RandomBlock(-1,12,-7,rustic:iron_lattice:0,30,rustic:iron_lattice:1,100)
RandomBlock(-1,12,-6,rustic:iron_lattice:0,30,rustic:iron_lattice:1,100)
RandomBlock(-1,12,-5,rustic:iron_lattice:0,30,rustic:iron_lattice:1,100)
Block(-1,12,2,VINE:1)
Block(-1,12,3,DOUBLE_STEP:0)
Block(-1,13,2,VINE:1)
Block(-1,13,3,DOUBLE_STEP:0)
Block(-1,14,2,VINE:1)
Block(-1,14,3,DOUBLE_STEP:0)
Block(-1,15,2,VINE:1)
Block(-1,15,3,DOUBLE_STEP:0)
Block(-1,16,2,SMOOTH_STAIRS:6)
Block(-1,16,3,quark:iron_plate:1)
Block(-1,17,1,SMOOTH_STAIRS:6)
Block(-1,17,2,quark:polished_stone:0)
Block(-1,18,-6,quark:iron_plate:1)
Block(-1,18,-1,quark:iron_plate:1)
Block(-1,18,0,quark:polished_stone:0)
Block(-1,18,1,quark:polished_stone:0)
Block(-1,18,2,SMOOTH_STAIRS:3)
RandomBlock(-1,19,-7,contenttweaker:reinforced_concrete:0,40,SMOOTH_BRICK:1,30,SMOOTH_BRICK:2,30,MOSSY_COBBLESTONE:0,30,COBBLESTONE:0,20,contenttweaker:reinforced_concrete:0,100)
Block(-1,19,-6,quark:iron_plate:1)
RandomBlock(-1,19,-5,contenttweaker:reinforced_concrete:0,40,SMOOTH_BRICK:1,30,SMOOTH_BRICK:2,30,MOSSY_COBBLESTONE:0,30,COBBLESTONE:0,20,contenttweaker:reinforced_concrete:0,100)
RandomBlock(-1,19,-4,contenttweaker:reinforced_concrete:0,40,SMOOTH_BRICK:1,30,SMOOTH_BRICK:2,30,MOSSY_COBBLESTONE:0,30,COBBLESTONE:0,20,contenttweaker:reinforced_concrete:0,100)
RandomBlock(-1,19,-3,contenttweaker:reinforced_concrete:0,40,SMOOTH_BRICK:1,30,SMOOTH_BRICK:2,30,MOSSY_COBBLESTONE:0,30,COBBLESTONE:0,20,contenttweaker:reinforced_concrete:0,100)
RandomBlock(-1,19,-2,contenttweaker:reinforced_concrete:0,40,SMOOTH_BRICK:1,30,SMOOTH_BRICK:2,30,MOSSY_COBBLESTONE:0,30,COBBLESTONE:0,20,contenttweaker:reinforced_concrete:0,100)
Block(-1,19,-1,quark:iron_plate:1)
Block(-1,19,0,SMOOTH_STAIRS:3)
Block(-1,20,-1,quark:stone_diorite_bricks_wall:0)
Block(0,0,-7,contenttweaker:reinforced_concrete:0)
Block(0,0,-6,quark:world_stone_pavement:2)
Block(0,0,-5,quark:world_stone_pavement:2)
Block(0,0,-4,quark:world_stone_pavement:2)
Block(0,0,-3,contenttweaker:reinforced_concrete:0)
Block(0,0,-2,contenttweaker:reinforced_concrete:0)
Block(0,0,-1,contenttweaker:reinforced_concrete:0)
Block(0,0,0,quark:world_stone_pavement:2)
Block(0,0,1,contenttweaker:reinforced_concrete:0)
Block(0,0,2,quark:world_stone_pavement:2)
Block(0,0,3,quark:world_stone_pavement:2)
Block(0,1,-7,quark:iron_plate:1)
Block(0,1,-6,quark:iron_plate:1)
Block(0,1,-5,quark:iron_plate:1)
Block(0,1,-4,quark:iron_plate:1)
Block(0,1,-3,quark:world_stone_pavement:2)
Block(0,1,-2,contenttweaker:reinforced_concrete:0)
Block(0,1,-1,contenttweaker:reinforced_concrete:0)
Block(0,1,0,contenttweaker:reinforced_concrete:0)
Block(0,1,1,contenttweaker:reinforced_concrete:0)
Block(0,1,2,contenttweaker:reinforced_concrete:0)
Block(0,1,3,contenttweaker:reinforced_concrete:0)
Block(0,2,-7,quark:iron_plate:1)
Block(0,2,-6,quark:iron_plate:1)
Block(0,2,-5,AIR:0)
Block(0,2,-4,quark:iron_plate:1)
Block(0,2,-3,quark:world_stone_pavement:2)
Block(0,2,-2,contenttweaker:reinforced_concrete:0)
Block(0,2,-1,quark:world_stone_pavement:2)
Block(0,2,0,contenttweaker:reinforced_concrete:0)
Block(0,2,1,contenttweaker:reinforced_concrete:0)
Block(0,2,2,contenttweaker:reinforced_concrete:0)
Block(0,2,3,contenttweaker:reinforced_concrete:0)
Block(0,3,-7,quark:iron_plate:1)
Block(0,3,-6,quark:iron_plate:1)
Block(0,3,-5,AIR:0)
Block(0,3,-4,quark:iron_plate:1)
Block(0,3,-3,quark:polished_stone:0)
Block(0,3,-2,contenttweaker:reinforced_concrete:0)
Block(0,3,-1,quark:world_stone_pavement:2)
Block(0,3,0,contenttweaker:reinforced_concrete:0)
Block(0,3,1,contenttweaker:reinforced_concrete:0)
Block(0,3,2,contenttweaker:reinforced_concrete:0)
Block(0,3,3,quark:world_stone_pavement:2)
Block(0,4,-7,quark:iron_plate:1)
Block(0,4,-6,quark:iron_plate:1)
Block(0,4,-5,AIR:0)
Block(0,4,-4,quark:iron_plate:1)
Block(0,4,-3,quark:world_stone_pavement:2)
Block(0,4,-2,contenttweaker:reinforced_concrete:0)
Block(0,4,-1,contenttweaker:reinforced_concrete:0)
Block(0,4,0,contenttweaker:reinforced_concrete:0)
Block(0,4,1,quark:world_stone_pavement:2)
Block(0,4,2,contenttweaker:reinforced_concrete:0)
Block(0,4,3,contenttweaker:reinforced_concrete:0)
Block(0,5,-7,quark:iron_plate:1)
Block(0,5,-6,quark:iron_plate:1)
Block(0,5,-5,AIR:0)
Block(0,5,-4,quark:iron_plate:1)
Block(0,5,-3,quark:polished_stone:0)
Block(0,5,-2,contenttweaker:reinforced_concrete:0)
Block(0,5,-1,contenttweaker:reinforced_concrete:0)
Block(0,5,0,contenttweaker:reinforced_concrete:0)
Block(0,5,1,contenttweaker:reinforced_concrete:0)
Block(0,5,2,quark:world_stone_pavement:2)
Block(0,5,3,contenttweaker:reinforced_concrete:0)
Block(0,6,-7,quark:iron_plate:1)
Block(0,6,-6,quark:iron_plate:1)
Block(0,6,-5,AIR:0)
Block(0,6,-4,quark:iron_plate:1)
Block(0,6,-3,quark:world_stone_pavement:2)
Block(0,6,-2,contenttweaker:reinforced_concrete:0)
Block(0,6,-1,contenttweaker:reinforced_concrete:0)
Block(0,6,0,contenttweaker:reinforced_concrete:0)
Block(0,6,1,quark:world_stone_pavement:2)
Block(0,6,2,quark:world_stone_pavement:2)
Block(0,6,3,contenttweaker:reinforced_concrete:0)
Block(0,7,-7,quark:iron_plate:1)
Block(0,7,-6,quark:iron_plate:1)
Block(0,7,-5,AIR:0)
Block(0,7,-4,quark:iron_plate:1)
Block(0,7,-3,contenttweaker:reinforced_concrete:0)
Block(0,7,-2,contenttweaker:reinforced_concrete:0)
Block(0,7,-1,contenttweaker:reinforced_concrete:0)
Block(0,7,0,contenttweaker:reinforced_concrete:0)
Block(0,7,1,quark:world_stone_pavement:2)
Block(0,7,2,contenttweaker:reinforced_concrete:0)
Block(0,7,3,contenttweaker:reinforced_concrete:0)
Block(0,8,-7,quark:iron_plate_stairs:0)
Block(0,8,-6,quark:iron_plate_stairs:0)
Block(0,8,-5,AIR:0)
Block(0,8,-4,quark:iron_plate:1)
Block(0,8,-3,quark:polished_stone:0)
Block(0,8,-2,contenttweaker:reinforced_concrete:0)
Block(0,8,-1,contenttweaker:reinforced_concrete:0)
Block(0,8,0,quark:world_stone_pavement:2)
Block(0,8,1,contenttweaker:reinforced_concrete:0)
Block(0,8,2,contenttweaker:reinforced_concrete:0)
Block(0,8,3,quark:world_stone_pavement:2)
RandomBlock(0,9,-7,rustic:iron_lattice:0,30,rustic:iron_lattice:1,100)
RandomBlock(0,9,-6,rustic:iron_lattice:0,30,rustic:iron_lattice:1,100)
Block(0,9,-5,AIR:0)
Block(0,9,-4,quark:iron_plate:1)
Block(0,9,-3,quark:iron_plate:1)
Block(0,9,-2,quark:iron_plate:1)
Block(0,9,-1,quark:iron_plate:1)
Block(0,9,0,quark:iron_plate:1)
Block(0,9,1,contenttweaker:reinforced_concrete:0)
Block(0,9,2,quark:polished_stone:0)
Block(0,9,3,quark:polished_stone:0)
Block(0,10,-7,AIR:0)
Block(0,10,-6,AIR:0)
Block(0,10,-5,quark:iron_plate_stairs:6)
Block(0,10,-4,quark:grate:0)
Block(0,10,-3,quark:grate:0)
Block(0,10,-2,quark:grate:0)
Block(0,10,-1,quark:grate:0)
Block(0,10,0,quark:grate:0)
Block(0,10,1,quark:world_stone_pavement:2)
Block(0,10,2,quark:polished_stone:0)
Block(0,10,3,quark:polished_stone:0)
RandomBlock(0,11,-5,rustic:iron_lattice:0,30,rustic:iron_lattice:1,100)
RandomBlock(0,11,3,contenttweaker:reinforced_concrete:0,40,SMOOTH_BRICK:1,30,SMOOTH_BRICK:2,30,MOSSY_COBBLESTONE:0,30,COBBLESTONE:0,20,contenttweaker:reinforced_concrete:0,100)
RandomBlock(0,12,-5,rustic:iron_lattice:0,30,rustic:iron_lattice:1,100)
RandomBlock(0,12,3,contenttweaker:reinforced_concrete:0,40,SMOOTH_BRICK:1,30,SMOOTH_BRICK:2,30,MOSSY_COBBLESTONE:0,30,COBBLESTONE:0,20,contenttweaker:reinforced_concrete:0,100)
RandomBlock(0,13,3,contenttweaker:reinforced_concrete:0,40,SMOOTH_BRICK:1,30,SMOOTH_BRICK:2,30,MOSSY_COBBLESTONE:0,30,COBBLESTONE:0,20,contenttweaker:reinforced_concrete:0,100)
RandomBlock(0,14,3,contenttweaker:reinforced_concrete:0,40,SMOOTH_BRICK:1,30,SMOOTH_BRICK:2,30,MOSSY_COBBLESTONE:0,30,COBBLESTONE:0,20,contenttweaker:reinforced_concrete:0,100)
RandomBlock(0,15,3,contenttweaker:reinforced_concrete:0,40,SMOOTH_BRICK:1,30,SMOOTH_BRICK:2,30,MOSSY_COBBLESTONE:0,30,COBBLESTONE:0,20,contenttweaker:reinforced_concrete:0,100)
Block(0,16,2,SMOOTH_STAIRS:6)
Block(0,16,3,quark:iron_plate:1)
Block(0,17,1,SMOOTH_STAIRS:6)
Block(0,17,2,quark:polished_stone:0)
Block(0,18,-6,quark:iron_plate:1)
Block(0,18,-1,quark:iron_plate:1)
Block(0,18,0,quark:polished_stone:0)
Block(0,18,1,quark:polished_stone:0)
Block(0,18,2,SMOOTH_STAIRS:3)
RandomBlock(0,19,-7,contenttweaker:reinforced_concrete:0,40,SMOOTH_BRICK:1,30,SMOOTH_BRICK:2,30,MOSSY_COBBLESTONE:0,30,COBBLESTONE:0,20,contenttweaker:reinforced_concrete:0,100)
Block(0,19,-6,quark:iron_plate:1)
RandomBlock(0,19,-5,contenttweaker:reinforced_concrete:0,40,SMOOTH_BRICK:1,30,SMOOTH_BRICK:2,30,MOSSY_COBBLESTONE:0,30,COBBLESTONE:0,20,contenttweaker:reinforced_concrete:0,100)
RandomBlock(0,19,-4,contenttweaker:reinforced_concrete:0,40,SMOOTH_BRICK:1,30,SMOOTH_BRICK:2,30,MOSSY_COBBLESTONE:0,30,COBBLESTONE:0,20,contenttweaker:reinforced_concrete:0,100)
RandomBlock(0,19,-3,contenttweaker:reinforced_concrete:0,40,SMOOTH_BRICK:1,30,SMOOTH_BRICK:2,30,MOSSY_COBBLESTONE:0,30,COBBLESTONE:0,20,contenttweaker:reinforced_concrete:0,100)
RandomBlock(0,19,-2,contenttweaker:reinforced_concrete:0,40,SMOOTH_BRICK:1,30,SMOOTH_BRICK:2,30,MOSSY_COBBLESTONE:0,30,COBBLESTONE:0,20,contenttweaker:reinforced_concrete:0,100)
Block(0,19,-1,quark:iron_plate:1)
Block(0,19,0,SMOOTH_STAIRS:3)
Block(0,20,-7,quark:iron_plate:1)
Block(0,20,-6,quark:iron_plate:1)
Block(0,20,-5,quark:iron_plate:1)
Block(0,20,-1,quark:stone_diorite_bricks_wall:0)
Block(1,0,-7,contenttweaker:reinforced_concrete:0)
Block(1,0,-6,quark:world_stone_pavement:2)
Block(1,0,-5,quark:world_stone_pavement:2)
Block(1,0,-4,quark:world_stone_pavement:2)
Block(1,0,-3,contenttweaker:reinforced_concrete:0)
Block(1,0,-2,contenttweaker:reinforced_concrete:0)
Block(1,0,-1,contenttweaker:reinforced_concrete:0)
Block(1,0,0,contenttweaker:reinforced_concrete:0)
Block(1,0,1,quark:world_stone_pavement:2)
Block(1,0,2,contenttweaker:reinforced_concrete:0)
Block(1,0,3,quark:world_stone_pavement:2)
Block(1,1,-7,quark:iron_plate:1)
Block(1,1,-6,quark:iron_plate:1)
Block(1,1,-5,quark:grate:0)
Block(1,1,-4,quark:grate:0)
Block(1,1,-3,quark:world_stone_pavement:2)
Block(1,1,-2,quark:world_stone_pavement:2)
Block(1,1,-1,quark:world_stone_pavement:2)
Block(1,1,0,quark:world_stone_pavement:2)
Block(1,1,1,contenttweaker:reinforced_concrete:0)
Block(1,1,2,contenttweaker:reinforced_concrete:0)
Block(1,1,3,quark:world_stone_pavement:2)
Block(1,2,-7,contenttweaker:coolant_fluid:0)
Block(1,2,-6,quark:iron_plate:1)
Block(1,2,-5,AIR:0)
Block(1,2,-4,AIR:0)
Block(1,2,-3,quark:world_stone_pavement:2)
Block(1,2,-2,contenttweaker:reinforced_concrete:0)
Block(1,2,-1,quark:world_stone_pavement:2)
Block(1,2,0,quark:world_stone_pavement:2)
Block(1,2,1,quark:world_stone_pavement:2)
Block(1,2,2,contenttweaker:reinforced_concrete:0)
Block(1,2,3,quark:world_stone_pavement:2)
Block(1,3,-7,contenttweaker:coolant_fluid:0)
Block(1,3,-6,quark:iron_plate:1)
Block(1,3,-5,AIR:0)
Block(1,3,-4,AIR:0)
Block(1,3,-3,quark:polished_stone:0)
Block(1,3,-2,contenttweaker:reinforced_concrete:0)
Block(1,3,-1,quark:world_stone_pavement:2)
Block(1,3,0,contenttweaker:reinforced_concrete:0)
Block(1,3,1,contenttweaker:reinforced_concrete:0)
Block(1,3,2,contenttweaker:reinforced_concrete:0)
Block(1,3,3,contenttweaker:reinforced_concrete:0)
Block(1,4,-7,contenttweaker:coolant_fluid:0)
Block(1,4,-6,quark:iron_plate:1)
Block(1,4,-5,AIR:0)
Block(1,4,-4,AIR:0)
Block(1,4,-3,quark:world_stone_pavement:2)
Block(1,4,-2,quark:world_stone_pavement:2)
Block(1,4,-1,quark:world_stone_pavement:2)
Block(1,4,0,contenttweaker:reinforced_concrete:0)
Block(1,4,1,quark:world_stone_pavement:2)
Block(1,4,2,contenttweaker:reinforced_concrete:0)
Block(1,4,3,quark:world_stone_pavement:2)
Block(1,5,-7,contenttweaker:coolant_fluid:0)
Block(1,5,-6,quark:iron_plate:1)
Block(1,5,-5,AIR:0)
Block(1,5,-4,AIR:0)
Block(1,5,-3,quark:polished_stone:0)
Block(1,5,-2,quark:world_stone_pavement:2)
Block(1,5,-1,quark:world_stone_pavement:2)
Block(1,5,0,contenttweaker:reinforced_concrete:0)
Block(1,5,1,contenttweaker:reinforced_concrete:0)
Block(1,5,2,contenttweaker:reinforced_concrete:0)
Block(1,5,3,quark:world_stone_pavement:2)
Block(1,6,-7,contenttweaker:coolant_fluid:0)
Block(1,6,-6,quark:iron_plate:1)
Block(1,6,-5,AIR:0)
Block(1,6,-4,AIR:0)
Block(1,6,-3,quark:world_stone_pavement:2)
Block(1,6,-2,contenttweaker:reinforced_concrete:0)
Block(1,6,-1,quark:world_stone_pavement:2)
Block(1,6,0,contenttweaker:reinforced_concrete:0)
Block(1,6,1,contenttweaker:reinforced_concrete:0)
Block(1,6,2,contenttweaker:reinforced_concrete:0)
Block(1,6,3,quark:world_stone_pavement:2)
Block(1,7,-7,contenttweaker:coolant_fluid:0)
Block(1,7,-6,quark:iron_plate:1)
Block(1,7,-5,AIR:0)
Block(1,7,-4,AIR:0)
Block(1,7,-3,contenttweaker:reinforced_concrete:0)
Block(1,7,-2,quark:world_stone_pavement:2)
Block(1,7,-1,contenttweaker:reinforced_concrete:0)
Block(1,7,0,quark:world_stone_pavement:2)
Block(1,7,1,contenttweaker:reinforced_concrete:0)
Block(1,7,2,contenttweaker:reinforced_concrete:0)
Block(1,7,3,quark:world_stone_pavement:2)
Block(1,8,-7,STAINED_CLAY:4)
Block(1,8,-6,quark:iron_plate_stairs:3)
Block(1,8,-5,AIR:0)
Block(1,8,-4,AIR:0)
Block(1,8,-3,quark:polished_stone:0)
Block(1,8,-2,contenttweaker:reinforced_concrete:0)
Block(1,8,-1,contenttweaker:reinforced_concrete:0)
Block(1,8,0,contenttweaker:reinforced_concrete:0)
Block(1,8,1,quark:world_stone_pavement:2)
Block(1,8,2,quark:polished_stone:0)
Block(1,8,3,quark:world_stone_pavement:2)
RandomBlock(1,9,-7,rustic:iron_lattice:0,30,rustic:iron_lattice:1,100)
RandomBlock(1,9,-6,rustic:iron_lattice:0,30,rustic:iron_lattice:1,100)
Block(1,9,-5,AIR:0)
Block(1,9,-4,quark:iron_plate_stairs:6)
Block(1,9,-3,quark:world_stone_pavement:2)
Block(1,9,-2,contenttweaker:reinforced_concrete:0)
Block(1,9,-1,contenttweaker:reinforced_concrete:0)
Block(1,9,0,contenttweaker:reinforced_concrete:0)
Block(1,9,1,quark:polished_stone:0)
Block(1,9,2,quark:polished_stone:0)
Block(1,9,3,quark:polished_stone:0)
Block(1,10,-7,AIR:0)
Block(1,10,-6,AIR:0)
Block(1,10,-5,quark:iron_plate_stairs:6)
Block(1,10,-4,quark:polished_stone:0)
Block(1,10,-3,quark:polished_stone:0)
Block(1,10,-2,contenttweaker:reinforced_concrete:0)
Block(1,10,-1,contenttweaker:reinforced_concrete:0)
Block(1,10,0,contenttweaker:reinforced_concrete:0)
Block(1,10,1,contenttweaker:reinforced_concrete:0)
Block(1,10,2,contenttweaker:reinforced_concrete:0)
Block(1,10,3,quark:world_stone_pavement:2)
RandomBlock(1,11,-5,rustic:iron_lattice:0,30,rustic:iron_lattice:1,100)
Block(1,11,1,AIR:0)
Block(1,11,2,AIR:0)
Block(1,11,3,DOUBLE_STEP:0)
RandomBlock(1,12,-5,rustic:iron_lattice:0,30,rustic:iron_lattice:1,100)
Block(1,12,2,AIR:0)
Block(1,12,3,DOUBLE_STEP:0)
Block(1,13,2,AIR:0)
Block(1,13,3,DOUBLE_STEP:0)
Block(1,14,2,AIR:0)
Block(1,14,3,DOUBLE_STEP:0)
Block(1,15,3,DOUBLE_STEP:0)
Block(1,16,2,SMOOTH_STAIRS:6)
Block(1,16,3,quark:iron_plate:1)
Block(1,17,1,SMOOTH_STAIRS:6)
Block(1,17,2,quark:polished_stone:0)
Block(1,18,-6,quark:iron_plate:1)
Block(1,18,-1,quark:iron_plate:1)
Block(1,18,0,quark:polished_stone:0)
Block(1,18,1,quark:polished_stone:0)
Block(1,18,2,SMOOTH_STAIRS:3)
RandomBlock(1,19,-7,contenttweaker:reinforced_concrete:0,40,SMOOTH_BRICK:1,30,SMOOTH_BRICK:2,30,MOSSY_COBBLESTONE:0,30,COBBLESTONE:0,20,contenttweaker:reinforced_concrete:0,100)
Block(1,19,-6,quark:iron_plate:1)
RandomBlock(1,19,-5,contenttweaker:reinforced_concrete:0,40,SMOOTH_BRICK:1,30,SMOOTH_BRICK:2,30,MOSSY_COBBLESTONE:0,30,COBBLESTONE:0,20,contenttweaker:reinforced_concrete:0,100)
RandomBlock(1,19,-4,contenttweaker:reinforced_concrete:0,40,SMOOTH_BRICK:1,30,SMOOTH_BRICK:2,30,MOSSY_COBBLESTONE:0,30,COBBLESTONE:0,20,contenttweaker:reinforced_concrete:0,100)
RandomBlock(1,19,-3,contenttweaker:reinforced_concrete:0,40,SMOOTH_BRICK:1,30,SMOOTH_BRICK:2,30,MOSSY_COBBLESTONE:0,30,COBBLESTONE:0,20,contenttweaker:reinforced_concrete:0,100)
RandomBlock(1,19,-2,contenttweaker:reinforced_concrete:0,40,SMOOTH_BRICK:1,30,SMOOTH_BRICK:2,30,MOSSY_COBBLESTONE:0,30,COBBLESTONE:0,20,contenttweaker:reinforced_concrete:0,100)
Block(1,19,-1,quark:iron_plate:1)
Block(1,19,0,SMOOTH_STAIRS:3)
Block(1,20,-5,quark:iron_plate:1)
Block(1,20,-1,quark:stone_diorite_bricks_wall:0)
Block(2,0,-7,contenttweaker:reinforced_concrete:0)
Block(2,0,-6,contenttweaker:reinforced_concrete:0)
Block(2,0,-5,quark:world_stone_pavement:2)
Block(2,0,-4,quark:world_stone_pavement:2)
Block(2,0,-3,quark:polished_stone:0)
Block(2,0,-2,contenttweaker:reinforced_concrete:0)
Block(2,0,-1,quark:world_stone_pavement:2)
Block(2,0,0,contenttweaker:reinforced_concrete:0)
Block(2,0,1,contenttweaker:reinforced_concrete:0)
Block(2,0,2,contenttweaker:reinforced_concrete:0)
Block(2,0,3,contenttweaker:reinforced_concrete:0)
Block(2,1,-7,quark:iron_plate:1)
Block(2,1,-6,quark:iron_plate:1)
Block(2,1,-5,quark:iron_plate:1)
Block(2,1,-4,quark:iron_plate:1)
Block(2,1,-3,quark:polished_stone:0)
Block(2,1,-2,contenttweaker:reinforced_concrete:0)
Block(2,1,-1,contenttweaker:reinforced_concrete:0)
Block(2,1,0,quark:world_stone_pavement:2)
Block(2,1,1,contenttweaker:reinforced_concrete:0)
Block(2,1,2,contenttweaker:reinforced_concrete:0)
Block(2,1,3,quark:world_stone_pavement:2)
Block(2,2,-7,quark:iron_plate:1)
Block(2,2,-6,quark:iron_plate:1)
Block(2,2,-5,AIR:0)
Block(2,2,-4,quark:iron_plate:1)
Block(2,2,-3,quark:world_stone_pavement:2)
Block(2,2,-2,quark:world_stone_pavement:2)
Block(2,2,-1,contenttweaker:reinforced_concrete:0)
Block(2,2,0,contenttweaker:reinforced_concrete:0)
Block(2,2,1,quark:world_stone_pavement:2)
Block(2,2,2,contenttweaker:reinforced_concrete:0)
Block(2,2,3,quark:world_stone_pavement:2)
Block(2,3,-7,quark:iron_plate:1)
Block(2,3,-6,quark:iron_plate:1)
Block(2,3,-5,AIR:0)
Block(2,3,-4,quark:iron_plate:1)
Block(2,3,-3,quark:world_stone_pavement:2)
Block(2,3,-2,quark:world_stone_pavement:2)
Block(2,3,-1,quark:world_stone_pavement:2)
Block(2,3,0,quark:world_stone_pavement:2)
Block(2,3,1,contenttweaker:reinforced_concrete:0)
Block(2,3,2,contenttweaker:reinforced_concrete:0)
Block(2,3,3,contenttweaker:reinforced_concrete:0)
Block(2,4,-7,quark:iron_plate:1)
Block(2,4,-6,quark:iron_plate:1)
Block(2,4,-5,AIR:0)
Block(2,4,-4,quark:iron_plate:1)
Block(2,4,-3,quark:polished_stone:0)
Block(2,4,-2,quark:world_stone_pavement:2)
Block(2,4,-1,contenttweaker:reinforced_concrete:0)
Block(2,4,0,quark:world_stone_pavement:2)
Block(2,4,1,contenttweaker:reinforced_concrete:0)
Block(2,4,2,quark:world_stone_pavement:2)
Block(2,4,3,contenttweaker:reinforced_concrete:0)
Block(2,5,-7,quark:iron_plate:1)
Block(2,5,-6,quark:iron_plate:1)
Block(2,5,-5,AIR:0)
Block(2,5,-4,quark:iron_plate:1)
Block(2,5,-3,quark:world_stone_pavement:2)
Block(2,5,-2,contenttweaker:reinforced_concrete:0)
Block(2,5,-1,contenttweaker:reinforced_concrete:0)
Block(2,5,0,contenttweaker:reinforced_concrete:0)
Block(2,5,1,contenttweaker:reinforced_concrete:0)
Block(2,5,2,contenttweaker:reinforced_concrete:0)
Block(2,5,3,quark:world_stone_pavement:2)
Block(2,6,-7,quark:iron_plate:1)
Block(2,6,-6,quark:iron_plate:1)
Block(2,6,-5,AIR:0)
Block(2,6,-4,quark:iron_plate:1)
Block(2,6,-3,contenttweaker:reinforced_concrete:0)
Block(2,6,-2,contenttweaker:reinforced_concrete:0)
Block(2,6,-1,contenttweaker:reinforced_concrete:0)
Block(2,6,0,quark:world_stone_pavement:2)
Block(2,6,1,contenttweaker:reinforced_concrete:0)
Block(2,6,2,quark:world_stone_pavement:2)
Block(2,6,3,contenttweaker:reinforced_concrete:0)
Block(2,7,-7,quark:iron_plate:1)
Block(2,7,-6,quark:iron_plate:1)
Block(2,7,-5,AIR:0)
Block(2,7,-4,quark:iron_plate:1)
Block(2,7,-3,quark:world_stone_pavement:2)
Block(2,7,-2,quark:world_stone_pavement:2)
Block(2,7,-1,contenttweaker:reinforced_concrete:0)
Block(2,7,0,quark:world_stone_pavement:2)
Block(2,7,1,quark:world_stone_pavement:2)
Block(2,7,2,contenttweaker:reinforced_concrete:0)
Block(2,7,3,contenttweaker:reinforced_concrete:0)
Block(2,8,-7,quark:iron_plate_stairs:1)
Block(2,8,-6,quark:iron_plate_stairs:3)
Block(2,8,-5,AIR:0)
Block(2,8,-4,quark:iron_plate:1)
Block(2,8,-3,quark:polished_stone:0)
Block(2,8,-2,contenttweaker:reinforced_concrete:0)
Block(2,8,-1,contenttweaker:reinforced_concrete:0)
Block(2,8,0,contenttweaker:reinforced_concrete:0)
Block(2,8,1,quark:world_stone_pavement:2)
Block(2,8,2,quark:polished_stone:0)
Block(2,8,3,quark:polished_stone:0)
RandomBlock(2,9,-7,rustic:iron_lattice:0,30,rustic:iron_lattice:1,100)
RandomBlock(2,9,-6,rustic:iron_lattice:0,30,rustic:iron_lattice:1,100)
Block(2,9,-5,AIR:0)
Block(2,9,-4,quark:iron_plate:1)
Block(2,9,-3,quark:iron_plate:1)
Block(2,9,-2,quark:iron_plate:1)
Block(2,9,-1,quark:iron_plate:1)
Block(2,9,0,quark:iron_plate:1)
Block(2,9,1,quark:polished_stone:0)
Block(2,9,2,quark:world_stone_pavement:2)
Block(2,9,3,quark:polished_stone:0)
Block(2,10,-7,AIR:0)
Block(2,10,-6,AIR:0)
Block(2,10,-5,quark:iron_plate_stairs:6)
Block(2,10,-4,quark:grate:0)
Block(2,10,-3,quark:grate:0)
Block(2,10,-2,quark:grate:0)
Block(2,10,-1,quark:grate:0)
Block(2,10,0,quark:grate:0)
Block(2,10,1,quark:world_stone_pavement:2)
Block(2,10,2,contenttweaker:reinforced_concrete:0)
Block(2,10,3,quark:polished_stone:0)
RandomBlock(2,11,-5,rustic:iron_lattice:0,30,rustic:iron_lattice:1,100)
RandomBlock(2,11,3,contenttweaker:reinforced_concrete:0,40,SMOOTH_BRICK:1,30,SMOOTH_BRICK:2,30,MOSSY_COBBLESTONE:0,30,COBBLESTONE:0,20,contenttweaker:reinforced_concrete:0,100)
RandomBlock(2,12,-5,rustic:iron_lattice:0,30,rustic:iron_lattice:1,100)
RandomBlock(2,12,3,contenttweaker:reinforced_concrete:0,40,SMOOTH_BRICK:1,30,SMOOTH_BRICK:2,30,MOSSY_COBBLESTONE:0,30,COBBLESTONE:0,20,contenttweaker:reinforced_concrete:0,100)
RandomBlock(2,13,3,contenttweaker:reinforced_concrete:0,40,SMOOTH_BRICK:1,30,SMOOTH_BRICK:2,30,MOSSY_COBBLESTONE:0,30,COBBLESTONE:0,20,contenttweaker:reinforced_concrete:0,100)
RandomBlock(2,14,3,contenttweaker:reinforced_concrete:0,40,SMOOTH_BRICK:1,30,SMOOTH_BRICK:2,30,MOSSY_COBBLESTONE:0,30,COBBLESTONE:0,20,contenttweaker:reinforced_concrete:0,100)
RandomBlock(2,15,3,contenttweaker:reinforced_concrete:0,40,SMOOTH_BRICK:1,30,SMOOTH_BRICK:2,30,MOSSY_COBBLESTONE:0,30,COBBLESTONE:0,20,contenttweaker:reinforced_concrete:0,100)
Block(2,16,2,SMOOTH_STAIRS:6)
Block(2,16,3,quark:iron_plate:1)
Block(2,17,1,SMOOTH_STAIRS:6)
Block(2,17,2,quark:polished_stone:0)
Block(2,18,-6,quark:iron_plate:1)
Block(2,18,-1,quark:iron_plate:1)
Block(2,18,0,quark:polished_stone:0)
Block(2,18,1,quark:polished_stone:0)
Block(2,18,2,SMOOTH_STAIRS:3)
RandomBlock(2,19,-7,contenttweaker:reinforced_concrete:0,40,SMOOTH_BRICK:1,30,SMOOTH_BRICK:2,30,MOSSY_COBBLESTONE:0,30,COBBLESTONE:0,20,contenttweaker:reinforced_concrete:0,100)
Block(2,19,-6,quark:iron_plate:1)
RandomBlock(2,19,-5,contenttweaker:reinforced_concrete:0,40,SMOOTH_BRICK:1,30,SMOOTH_BRICK:2,30,MOSSY_COBBLESTONE:0,30,COBBLESTONE:0,20,contenttweaker:reinforced_concrete:0,100)
RandomBlock(2,19,-4,contenttweaker:reinforced_concrete:0,40,SMOOTH_BRICK:1,30,SMOOTH_BRICK:2,30,MOSSY_COBBLESTONE:0,30,COBBLESTONE:0,20,contenttweaker:reinforced_concrete:0,100)
RandomBlock(2,19,-3,contenttweaker:reinforced_concrete:0,40,SMOOTH_BRICK:1,30,SMOOTH_BRICK:2,30,MOSSY_COBBLESTONE:0,30,COBBLESTONE:0,20,contenttweaker:reinforced_concrete:0,100)
RandomBlock(2,19,-2,contenttweaker:reinforced_concrete:0,40,SMOOTH_BRICK:1,30,SMOOTH_BRICK:2,30,MOSSY_COBBLESTONE:0,30,COBBLESTONE:0,20,contenttweaker:reinforced_concrete:0,100)
Block(2,19,-1,quark:iron_plate:1)
Block(2,19,0,SMOOTH_STAIRS:3)
Block(2,20,-5,quark:iron_plate:1)
Block(2,20,-1,quark:stone_diorite_bricks_wall:0)
Block(3,0,-7,quark:world_stone_pavement:2)
Block(3,0,-6,contenttweaker:reinforced_concrete:0)
Block(3,0,-5,quark:polished_stone:0)
Block(3,0,-4,quark:polished_stone:0)
Block(3,0,-3,quark:world_stone_pavement:2)
Block(3,0,-2,quark:world_stone_pavement:2)
Block(3,0,-1,quark:world_stone_pavement:2)
Block(3,0,0,quark:world_stone_pavement:2)
Block(3,0,1,quark:world_stone_pavement:2)
Block(3,0,2,contenttweaker:reinforced_concrete:0)
Block(3,0,3,contenttweaker:reinforced_concrete:0)
Block(3,1,-7,quark:grate:0)
Block(3,1,-6,quark:grate:0)
Block(3,1,-5,quark:grate:0)
Block(3,1,-4,quark:grate:0)
Block(3,1,-3,quark:polished_stone:0)
Block(3,1,-2,contenttweaker:reinforced_concrete:0)
Block(3,1,-1,quark:world_stone_pavement:2)
Block(3,1,0,quark:world_stone_pavement:2)
Block(3,1,1,contenttweaker:reinforced_concrete:0)
Block(3,1,2,quark:world_stone_pavement:2)
Block(3,1,3,contenttweaker:reinforced_concrete:0)
Block(3,2,-7,AIR:0)
Block(3,2,-6,AIR:0)
Block(3,2,-5,AIR:0)
Block(3,2,-4,AIR:0)
Block(3,2,-3,quark:world_stone_pavement:2)
Block(3,2,-2,contenttweaker:reinforced_concrete:0)
Block(3,2,-1,quark:world_stone_pavement:2)
Block(3,2,0,contenttweaker:reinforced_concrete:0)
Block(3,2,1,quark:world_stone_pavement:2)
Block(3,2,2,contenttweaker:reinforced_concrete:0)
Block(3,2,3,quark:world_stone_pavement:2)
Block(3,3,-7,AIR:0)
Block(3,3,-6,AIR:0)
Block(3,3,-5,AIR:0)
Block(3,3,-4,AIR:0)
Block(3,3,-3,quark:world_stone_pavement:2)
Block(3,3,-2,contenttweaker:reinforced_concrete:0)
Block(3,3,-1,contenttweaker:reinforced_concrete:0)
Block(3,3,0,contenttweaker:reinforced_concrete:0)
Block(3,3,1,quark:world_stone_pavement:2)
Block(3,3,2,contenttweaker:reinforced_concrete:0)
Block(3,3,3,contenttweaker:reinforced_concrete:0)
Block(3,4,-7,AIR:0)
Block(3,4,-6,AIR:0)
Block(3,4,-5,AIR:0)
Block(3,4,-4,AIR:0)
Block(3,4,-3,quark:polished_stone:0)
Block(3,4,-2,quark:world_stone_pavement:2)
Block(3,4,-1,quark:world_stone_pavement:2)
Block(3,4,0,contenttweaker:reinforced_concrete:0)
Block(3,4,1,contenttweaker:reinforced_concrete:0)
Block(3,4,2,quark:world_stone_pavement:2)
Block(3,4,3,contenttweaker:reinforced_concrete:0)
Block(3,5,-7,AIR:0)
Block(3,5,-6,AIR:0)
Block(3,5,-5,AIR:0)
Block(3,5,-4,AIR:0)
Block(3,5,-3,quark:world_stone_pavement:2)
Block(3,5,-2,quark:world_stone_pavement:2)
Block(3,5,-1,contenttweaker:reinforced_concrete:0)
Block(3,5,0,contenttweaker:reinforced_concrete:0)
Block(3,5,1,contenttweaker:reinforced_concrete:0)
Block(3,5,2,quark:world_stone_pavement:2)
Block(3,5,3,contenttweaker:reinforced_concrete:0)
Block(3,6,-7,AIR:0)
Block(3,6,-6,AIR:0)
Block(3,6,-5,AIR:0)
Block(3,6,-4,AIR:0)
Block(3,6,-3,contenttweaker:reinforced_concrete:0)
Block(3,6,-2,quark:world_stone_pavement:2)
Block(3,6,-1,contenttweaker:reinforced_concrete:0)
Block(3,6,0,contenttweaker:reinforced_concrete:0)
Block(3,6,1,quark:world_stone_pavement:2)
Block(3,6,2,contenttweaker:reinforced_concrete:0)
Block(3,6,3,quark:world_stone_pavement:2)
Block(3,7,-7,AIR:0)
Block(3,7,-6,AIR:0)
Block(3,7,-5,AIR:0)
Block(3,7,-4,AIR:0)
Block(3,7,-3,contenttweaker:reinforced_concrete:0)
Block(3,7,-2,quark:world_stone_pavement:2)
Block(3,7,-1,contenttweaker:reinforced_concrete:0)
Block(3,7,0,contenttweaker:reinforced_concrete:0)
Block(3,7,1,contenttweaker:reinforced_concrete:0)
Block(3,7,2,contenttweaker:reinforced_concrete:0)
Block(3,7,3,quark:world_stone_pavement:2)
Block(3,8,-7,AIR:0)
Block(3,8,-6,AIR:0)
Block(3,8,-5,AIR:0)
Block(3,8,-4,AIR:0)
Block(3,8,-3,quark:polished_stone:0)
Block(3,8,-2,contenttweaker:reinforced_concrete:0)
Block(3,8,-1,quark:world_stone_pavement:2)
Block(3,8,0,contenttweaker:reinforced_concrete:0)
Block(3,8,1,contenttweaker:reinforced_concrete:0)
Block(3,8,2,quark:polished_stone:0)
Block(3,8,3,quark:world_stone_pavement:2)
Block(3,9,-7,AIR:0)
Block(3,9,-6,AIR:0)
Block(3,9,-5,AIR:0)
Block(3,9,-4,quark:iron_plate_stairs:6)
Block(3,9,-3,quark:polished_stone:0)
Block(3,9,-2,quark:world_stone_pavement:2)
Block(3,9,-1,contenttweaker:reinforced_concrete:0)
Block(3,9,0,quark:iron_plate:1)
Block(3,9,1,quark:world_stone_pavement:2)
Block(3,9,2,quark:polished_stone:0)
Block(3,9,3,quark:polished_stone:0)
Block(3,10,-7,quark:iron_plate_stairs:4)
Block(3,10,-6,quark:iron_plate_stairs:4)
Block(3,10,-5,quark:iron_plate_stairs:4)
Block(3,10,-4,quark:polished_stone:0)
Block(3,10,-3,quark:world_stone_pavement:2)
Block(3,10,-2,contenttweaker:reinforced_concrete:0)
Block(3,10,-1,quark:world_stone_pavement:2)
Block(3,10,0,quark:grate:0)
Block(3,10,1,quark:polished_stone:0)
Block(3,10,2,quark:polished_stone:0)
Block(3,10,3,quark:polished_stone:0)
RandomBlock(3,11,-7,rustic:iron_lattice:0,30,rustic:iron_lattice:1,100)
RandomBlock(3,11,-6,rustic:iron_lattice:0,30,rustic:iron_lattice:1,100)
RandomBlock(3,11,-5,rustic:iron_lattice:0,30,rustic:iron_lattice:1,100)
Block(3,11,1,quark:iron_plate_stairs:0)
Block(3,11,2,quark:iron_plate_stairs:0)
Block(3,11,3,DOUBLE_STEP:0)
RandomBlock(3,12,-7,rustic:iron_lattice:0,30,rustic:iron_lattice:1,100)
RandomBlock(3,12,-6,rustic:iron_lattice:0,30,rustic:iron_lattice:1,100)
RandomBlock(3,12,-5,rustic:iron_lattice:0,30,rustic:iron_lattice:1,100)
Block(3,12,2,VINE:9)
Block(3,12,3,DOUBLE_STEP:0)
Block(3,13,2,VINE:1)
Block(3,13,3,DOUBLE_STEP:0)
Block(3,14,2,VINE:1)
Block(3,14,3,DOUBLE_STEP:0)
Block(3,15,2,VINE:1)
Block(3,15,3,DOUBLE_STEP:0)
Block(3,16,2,SMOOTH_STAIRS:6)
Block(3,16,3,quark:iron_plate:1)
Block(3,17,1,SMOOTH_STAIRS:6)
Block(3,17,2,quark:polished_stone:0)
Block(3,18,-6,quark:iron_plate:1)
Block(3,18,-1,quark:iron_plate:1)
Block(3,18,0,quark:polished_stone:0)
Block(3,18,1,quark:polished_stone:0)
Block(3,18,2,SMOOTH_STAIRS:3)
RandomBlock(3,19,-7,contenttweaker:reinforced_concrete:0,40,SMOOTH_BRICK:1,30,SMOOTH_BRICK:2,30,MOSSY_COBBLESTONE:0,30,COBBLESTONE:0,20,contenttweaker:reinforced_concrete:0,100)
Block(3,19,-6,quark:iron_plate:1)
RandomBlock(3,19,-5,contenttweaker:reinforced_concrete:0,40,SMOOTH_BRICK:1,30,SMOOTH_BRICK:2,30,MOSSY_COBBLESTONE:0,30,COBBLESTONE:0,20,contenttweaker:reinforced_concrete:0,100)
RandomBlock(3,19,-4,contenttweaker:reinforced_concrete:0,40,SMOOTH_BRICK:1,30,SMOOTH_BRICK:2,30,MOSSY_COBBLESTONE:0,30,COBBLESTONE:0,20,contenttweaker:reinforced_concrete:0,100)
RandomBlock(3,19,-3,contenttweaker:reinforced_concrete:0,40,SMOOTH_BRICK:1,30,SMOOTH_BRICK:2,30,MOSSY_COBBLESTONE:0,30,COBBLESTONE:0,20,contenttweaker:reinforced_concrete:0,100)
RandomBlock(3,19,-2,contenttweaker:reinforced_concrete:0,40,SMOOTH_BRICK:1,30,SMOOTH_BRICK:2,30,MOSSY_COBBLESTONE:0,30,COBBLESTONE:0,20,contenttweaker:reinforced_concrete:0,100)
Block(3,19,-1,quark:iron_plate:1)
Block(3,19,0,SMOOTH_STAIRS:3)
Block(3,20,-5,quark:iron_plate:1)
Block(3,20,-1,quark:stone_diorite_bricks_wall:0)
Block(4,0,-7,contenttweaker:reinforced_concrete:0)
Block(4,0,-6,contenttweaker:reinforced_concrete:0)
Block(4,0,-5,quark:polished_stone:0)
Block(4,0,-4,quark:polished_stone:0)
Block(4,0,-3,quark:world_stone_pavement:2)
Block(4,0,-2,contenttweaker:reinforced_concrete:0)
Block(4,0,-1,contenttweaker:reinforced_concrete:0)
Block(4,0,0,quark:world_stone_pavement:2)
Block(4,0,1,contenttweaker:reinforced_concrete:0)
Block(4,0,2,contenttweaker:reinforced_concrete:0)
Block(4,0,3,contenttweaker:reinforced_concrete:0)
Block(4,1,-7,contenttweaker:reinforced_concrete:0)
Block(4,1,-6,quark:world_stone_pavement:2)
Block(4,1,-5,quark:polished_stone:0)
Block(4,1,-4,quark:polished_stone:0)
Block(4,1,-3,quark:polished_stone:0)
Block(4,1,-2,quark:world_stone_pavement:2)
Block(4,1,-1,contenttweaker:reinforced_concrete:0)
Block(4,1,0,contenttweaker:reinforced_concrete:0)
Block(4,1,1,quark:world_stone_pavement:2)
Block(4,1,2,contenttweaker:reinforced_concrete:0)
Block(4,1,3,contenttweaker:reinforced_concrete:0)
Block(4,2,-7,quark:polished_stone:0)
Block(4,2,-6,quark:polished_stone:0)
Block(4,2,-5,quark:polished_stone:0)
Block(4,2,-4,quark:polished_stone:0)
Block(4,2,-3,quark:polished_stone:0)
Block(4,2,-2,contenttweaker:reinforced_concrete:0)
Block(4,2,-1,contenttweaker:reinforced_concrete:0)
Block(4,2,0,contenttweaker:reinforced_concrete:0)
Block(4,2,1,contenttweaker:reinforced_concrete:0)
Block(4,2,2,quark:world_stone_pavement:2)
Block(4,2,3,contenttweaker:reinforced_concrete:0)
Block(4,3,-7,quark:polished_stone:0)
Block(4,3,-6,quark:polished_stone:0)
Block(4,3,-5,quark:polished_stone:0)
Block(4,3,-4,quark:polished_stone:0)
Block(4,3,-3,quark:polished_stone:0)
Block(4,3,-2,contenttweaker:reinforced_concrete:0)
Block(4,3,-1,contenttweaker:reinforced_concrete:0)
Block(4,3,0,quark:world_stone_pavement:2)
Block(4,3,1,quark:world_stone_pavement:2)
Block(4,3,2,quark:world_stone_pavement:2)
Block(4,3,3,contenttweaker:reinforced_concrete:0)
Block(4,4,-7,quark:world_stone_pavement:2)
Block(4,4,-6,quark:world_stone_pavement:2)
Block(4,4,-5,quark:polished_stone:0)
Block(4,4,-4,quark:polished_stone:0)
Block(4,4,-3,quark:polished_stone:0)
Block(4,4,-2,contenttweaker:reinforced_concrete:0)
Block(4,4,-1,contenttweaker:reinforced_concrete:0)
Block(4,4,0,contenttweaker:reinforced_concrete:0)
Block(4,4,1,quark:world_stone_pavement:2)
Block(4,4,2,contenttweaker:reinforced_concrete:0)
Block(4,4,3,contenttweaker:reinforced_concrete:0)
Block(4,5,-7,quark:world_stone_pavement:2)
Block(4,5,-6,quark:polished_stone:0)
Block(4,5,-5,quark:world_stone_pavement:2)
Block(4,5,-4,quark:world_stone_pavement:2)
Block(4,5,-3,quark:polished_stone:0)
Block(4,5,-2,contenttweaker:reinforced_concrete:0)
Block(4,5,-1,contenttweaker:reinforced_concrete:0)
Block(4,5,0,contenttweaker:reinforced_concrete:0)
Block(4,5,1,contenttweaker:reinforced_concrete:0)
Block(4,5,2,contenttweaker:reinforced_concrete:0)
Block(4,5,3,quark:world_stone_pavement:2)
Block(4,6,-7,quark:polished_stone:0)
Block(4,6,-6,quark:polished_stone:0)
Block(4,6,-5,contenttweaker:reinforced_concrete:0)
Block(4,6,-4,contenttweaker:reinforced_concrete:0)
Block(4,6,-3,contenttweaker:reinforced_concrete:0)
Block(4,6,-2,contenttweaker:reinforced_concrete:0)
Block(4,6,-1,contenttweaker:reinforced_concrete:0)
Block(4,6,0,contenttweaker:reinforced_concrete:0)
Block(4,6,1,contenttweaker:reinforced_concrete:0)
Block(4,6,2,quark:world_stone_pavement:2)
Block(4,6,3,contenttweaker:reinforced_concrete:0)
Block(4,7,-7,contenttweaker:reinforced_concrete:0)
Block(4,7,-6,quark:world_stone_pavement:2)
Block(4,7,-5,quark:world_stone_pavement:2)
Block(4,7,-4,quark:world_stone_pavement:2)
Block(4,7,-3,contenttweaker:reinforced_concrete:0)
Block(4,7,-2,quark:world_stone_pavement:2)
Block(4,7,-1,quark:world_stone_pavement:2)
Block(4,7,0,contenttweaker:reinforced_concrete:0)
Block(4,7,1,contenttweaker:reinforced_concrete:0)
Block(4,7,2,contenttweaker:reinforced_concrete:0)
Block(4,7,3,contenttweaker:reinforced_concrete:0)
Block(4,8,-7,contenttweaker:reinforced_concrete:0)
Block(4,8,-6,quark:polished_stone:0)
Block(4,8,-5,quark:world_stone_pavement:2)
Block(4,8,-4,quark:world_stone_pavement:2)
Block(4,8,-3,quark:polished_stone:0)
Block(4,8,-2,contenttweaker:reinforced_concrete:0)
Block(4,8,-1,contenttweaker:reinforced_concrete:0)
Block(4,8,0,contenttweaker:reinforced_concrete:0)
Block(4,8,1,contenttweaker:reinforced_concrete:0)
Block(4,8,2,quark:polished_stone:0)
Block(4,8,3,quark:polished_stone:0)
Block(4,9,-7,quark:polished_stone:0)
Block(4,9,-6,quark:world_stone_pavement:2)
Block(4,9,-5,quark:polished_stone:0)
Block(4,9,-4,quark:polished_stone:0)
Block(4,9,-3,quark:polished_stone:0)
Block(4,9,-2,quark:world_stone_pavement:2)
Block(4,9,-1,contenttweaker:reinforced_concrete:0)
Block(4,9,0,quark:iron_plate:1)
Block(4,9,1,quark:world_stone_pavement:2)
Block(4,9,2,quark:world_stone_pavement:2)
Block(4,9,3,quark:polished_stone:0)
Block(4,10,-7,quark:polished_stone:0)
Block(4,10,-6,quark:polished_stone:0)
