
#######################################################################
# +-----------------------------------------------------------------+ #
# |                            BO4 object                           | #
# +-----------------------------------------------------------------+ #
#######################################################################


Author: NLBlackEagle

Description: No description given

SettingsMode: WriteWithoutComments


#######################################################################
# +-----------------------------------------------------------------+ #
# |                          Main settings                          | #
# +-----------------------------------------------------------------+ #
#######################################################################

Frequency: 0

SpawnHeight: highestBlock

UseCenterForHighestBlock: true

##############################
# Height Limits for the BO4. #
##############################

MinHeight: 0

MaxHeight: 256

InheritBO3: 

InheritBO3Rotation: NORTH

OverrideChildSettings: true

OverrideParentHeight: false

CanOverride: false

BranchFrequency: 0

BranchFrequencyGroup: 

MustBeBelowOther: false

MustBeInside: 

CannotBeInside: 

ReplacesBO3: 

MustBeInsideWorldBorders: false

CanSpawnOnWater: true

SpawnOnWaterOnly: false

SpawnUnderWater: false

SpawnAtWaterLevel: false

HeightOffset: 0

RemoveAir: false

ReplaceAbove: 

ReplaceBelow: 

ReplaceWithBiomeBlocks: true

ReplaceWithSurfaceBlock: GRASS

ReplaceWithGroundBlock: DIRT

ReplaceWithStoneBlock: STONE

SmoothRadius: 0

SmoothHeightOffset: 0

SmoothStartTop: false

SmoothStartWood: false

SmoothingSurfaceBlock: 

SmoothingGroundBlock: 

BO3Group: 

IsSpawnPoint: false

DoReplaceBlocks: false


#######################################################################
# +-----------------------------------------------------------------+ #
# |                              Blocks                             | #
# +-----------------------------------------------------------------+ #
#######################################################################

Block(-8,0,-7,dimstack:bedrock:7)
Block(-8,0,-6,dimstack:bedrock:7)
Block(-8,0,-5,dimstack:bedrock:7)
Block(-8,0,-4,dimstack:bedrock:7)
Block(-8,0,-3,dimstack:bedrock:7)
Block(-8,0,-2,dimstack:bedrock:7)
Block(-8,0,-1,dimstack:bedrock:7)
Block(-8,0,0,dimstack:bedrock:7)
Block(-8,0,1,dimstack:bedrock:7)
Block(-8,0,2,dimstack:bedrock:7)
Block(-8,0,3,dimstack:bedrock:7)
Block(-8,0,4,dimstack:bedrock:7)
Block(-8,0,5,dimstack:bedrock:7)
Block(-8,0,6,dimstack:bedrock:7)
Block(-8,0,7,dimstack:bedrock:7)
Block(-8,0,8,dimstack:bedrock:7)
Block(-8,1,-7,dimstack:bedrock:7)
Block(-8,1,-6,dimstack:bedrock:7)
Block(-8,1,-5,dimstack:bedrock:7)
Block(-8,1,-4,dimstack:bedrock:7)
Block(-8,1,-3,dimstack:bedrock:7)
Block(-8,1,-2,dimstack:bedrock:7)
Block(-8,1,-1,dimstack:bedrock:7)
Block(-8,1,0,dimstack:bedrock:7)
Block(-8,1,1,dimstack:bedrock:7)
Block(-8,1,2,dimstack:bedrock:7)
Block(-8,1,3,dimstack:bedrock:7)
Block(-8,1,4,dimstack:bedrock:7)
Block(-8,1,5,dimstack:bedrock:7)
Block(-8,1,6,dimstack:bedrock:7)
Block(-8,1,7,dimstack:bedrock:7)
Block(-8,1,8,dimstack:bedrock:7)
Block(-8,2,-7,dimstack:bedrock:7)
Block(-8,2,-6,dimstack:bedrock:7)
Block(-8,2,-5,dimstack:bedrock:7)
Block(-8,2,-4,dimstack:bedrock:7)
Block(-8,2,-3,dimstack:bedrock:7)
Block(-8,2,-2,dimstack:bedrock:7)
Block(-8,2,-1,dimstack:bedrock:7)
Block(-8,2,0,dimstack:bedrock:7)
Block(-8,2,1,dimstack:bedrock:7)
Block(-8,2,2,dimstack:bedrock:7)
Block(-8,2,3,dimstack:bedrock:7)
Block(-8,2,4,dimstack:bedrock:7)
Block(-8,2,5,dimstack:bedrock:7)
Block(-8,2,6,dimstack:bedrock:7)
Block(-8,2,7,dimstack:bedrock:7)
Block(-8,2,8,dimstack:bedrock:7)
Block(-8,3,-7,dimstack:bedrock:7)
Block(-8,3,-6,dimstack:bedrock:7)
Block(-8,3,-5,dimstack:bedrock:7)
Block(-8,3,-4,dimstack:bedrock:7)
Block(-8,3,-3,dimstack:bedrock:7)
Block(-8,3,-2,dimstack:bedrock:7)
Block(-8,3,-1,dimstack:bedrock:7)
Block(-8,3,0,dimstack:bedrock:7)
Block(-8,3,1,dimstack:bedrock:7)
Block(-8,3,2,dimstack:bedrock:7)
Block(-8,3,3,dimstack:bedrock:7)
Block(-8,3,4,dimstack:bedrock:7)
Block(-8,3,5,dimstack:bedrock:7)
Block(-8,3,6,dimstack:bedrock:7)
Block(-8,3,7,dimstack:bedrock:7)
Block(-8,3,8,dimstack:bedrock:7)
Block(-8,4,-7,dimstack:bedrock:7)
Block(-8,4,-6,dimstack:bedrock:7)
Block(-8,4,-5,dimstack:bedrock:7)
Block(-8,4,-4,dimstack:bedrock:7)
Block(-8,4,-3,dimstack:bedrock:7)
Block(-8,4,-2,dimstack:bedrock:7)
Block(-8,4,-1,dimstack:bedrock:7)
Block(-8,4,0,dimstack:bedrock:7)
Block(-8,4,1,dimstack:bedrock:7)
Block(-8,4,2,dimstack:bedrock:7)
Block(-8,4,3,dimstack:bedrock:7)
Block(-8,4,4,dimstack:bedrock:7)
Block(-8,4,5,dimstack:bedrock:7)
Block(-8,4,6,dimstack:bedrock:7)
Block(-8,4,7,dimstack:bedrock:7)
Block(-8,4,8,dimstack:bedrock:7)
Block(-8,5,-7,dimstack:bedrock:7)
Block(-8,5,-6,dimstack:bedrock:7)
Block(-8,5,-5,dimstack:bedrock:7)
Block(-8,5,-4,dimstack:bedrock:7)
Block(-8,5,-3,dimstack:bedrock:7)
Block(-8,5,-2,dimstack:bedrock:7)
Block(-8,5,-1,dimstack:bedrock:7)
Block(-8,5,0,dimstack:bedrock:7)
Block(-8,5,1,dimstack:bedrock:7)
Block(-8,5,2,dimstack:bedrock:7)
Block(-8,5,3,dimstack:bedrock:7)
Block(-8,5,4,dimstack:bedrock:7)
Block(-8,5,5,dimstack:bedrock:7)
Block(-8,5,6,dimstack:bedrock:7)
Block(-8,5,7,dimstack:bedrock:7)
Block(-8,5,8,dimstack:bedrock:7)
Block(-8,6,-7,dimstack:bedrock:7)
Block(-8,6,-6,dimstack:bedrock:7)
Block(-8,6,-5,dimstack:bedrock:7)
Block(-8,6,-4,dimstack:bedrock:7)
Block(-8,6,-3,dimstack:bedrock:7)
Block(-8,6,-2,dimstack:bedrock:7)
Block(-8,6,-1,dimstack:bedrock:7)
Block(-8,6,0,dimstack:bedrock:7)
Block(-8,6,1,dimstack:bedrock:7)
Block(-8,6,2,dimstack:bedrock:7)
Block(-8,6,3,dimstack:bedrock:7)
Block(-8,6,4,dimstack:bedrock:7)
Block(-8,6,5,dimstack:bedrock:7)
Block(-8,6,6,dimstack:bedrock:7)
Block(-8,6,7,dimstack:bedrock:7)
Block(-8,6,8,dimstack:bedrock:7)
Block(-8,7,-7,dimstack:bedrock:7)
Block(-8,7,-6,dimstack:bedrock:7)
Block(-8,7,-5,dimstack:bedrock:7)
Block(-8,7,-4,dimstack:bedrock:7)
Block(-8,7,-3,dimstack:bedrock:7)
Block(-8,7,-2,dimstack:bedrock:7)
Block(-8,7,-1,dimstack:bedrock:7)
Block(-8,7,0,dimstack:bedrock:7)
Block(-8,7,1,dimstack:bedrock:7)
Block(-8,7,2,dimstack:bedrock:7)
Block(-8,7,3,dimstack:bedrock:7)
Block(-8,7,4,dimstack:bedrock:7)
Block(-8,7,5,dimstack:bedrock:7)
Block(-8,7,6,dimstack:bedrock:7)
Block(-8,7,7,dimstack:bedrock:7)
Block(-8,7,8,dimstack:bedrock:7)
Block(-8,8,-7,dimstack:bedrock:7)
Block(-8,8,-6,dimstack:bedrock:7)
Block(-8,8,-5,dimstack:bedrock:7)
Block(-8,8,-4,dimstack:bedrock:7)
Block(-8,8,-3,dimstack:bedrock:7)
Block(-8,8,-2,dimstack:bedrock:7)
Block(-8,8,-1,dimstack:bedrock:7)
Block(-8,8,0,dimstack:bedrock:7)
Block(-8,8,1,dimstack:bedrock:7)
Block(-8,8,2,dimstack:bedrock:7)
Block(-8,8,3,dimstack:bedrock:7)
Block(-8,8,4,dimstack:bedrock:7)
Block(-8,8,5,dimstack:bedrock:7)
Block(-8,8,6,dimstack:bedrock:7)
Block(-8,8,7,dimstack:bedrock:7)
Block(-8,8,8,dimstack:bedrock:7)
Block(-8,9,-7,dimstack:bedrock:7)
Block(-8,9,-6,dimstack:bedrock:7)
Block(-8,9,-5,dimstack:bedrock:7)
Block(-8,9,-4,dimstack:bedrock:7)
Block(-8,9,-3,dimstack:bedrock:7)
Block(-8,9,-2,dimstack:bedrock:7)
Block(-8,9,-1,dimstack:bedrock:7)
Block(-8,9,0,dimstack:bedrock:7)
Block(-8,9,1,dimstack:bedrock:7)
Block(-8,9,2,dimstack:bedrock:7)
Block(-8,9,3,dimstack:bedrock:7)
Block(-8,9,4,dimstack:bedrock:7)
Block(-8,9,5,dimstack:bedrock:7)
Block(-8,9,6,dimstack:bedrock:7)
Block(-8,9,7,dimstack:bedrock:7)
Block(-8,9,8,dimstack:bedrock:7)
Block(-8,10,-7,dimstack:bedrock:7)
Block(-8,10,-6,dimstack:bedrock:7)
Block(-8,10,-5,dimstack:bedrock:7)
Block(-8,10,-4,dimstack:bedrock:7)
Block(-8,10,-3,dimstack:bedrock:7)
Block(-8,10,-2,dimstack:bedrock:7)
Block(-8,10,-1,dimstack:bedrock:7)
Block(-8,10,0,dimstack:bedrock:7)
Block(-8,10,1,dimstack:bedrock:7)
Block(-8,10,2,dimstack:bedrock:7)
Block(-8,10,3,dimstack:bedrock:7)
Block(-8,10,4,dimstack:bedrock:7)
Block(-8,10,5,dimstack:bedrock:7)
Block(-8,10,6,dimstack:bedrock:7)
Block(-8,10,7,dimstack:bedrock:7)
Block(-8,10,8,dimstack:bedrock:7)
Block(-8,11,-7,dimstack:bedrock:7)
Block(-8,11,-6,dimstack:bedrock:7)
Block(-8,11,-5,dimstack:bedrock:7)
Block(-8,11,-4,dimstack:bedrock:7)
Block(-8,11,-3,dimstack:bedrock:7)
Block(-8,11,-2,dimstack:bedrock:7)
Block(-8,11,-1,dimstack:bedrock:7)
Block(-8,11,0,dimstack:bedrock:7)
Block(-8,11,1,dimstack:bedrock:7)
Block(-8,11,2,dimstack:bedrock:7)
Block(-8,11,3,dimstack:bedrock:7)
Block(-8,11,4,dimstack:bedrock:7)
Block(-8,11,5,dimstack:bedrock:7)
Block(-8,11,6,dimstack:bedrock:7)
Block(-8,11,7,dimstack:bedrock:7)
Block(-8,11,8,dimstack:bedrock:7)
Block(-8,12,-7,dimstack:bedrock:7)
Block(-8,12,-6,dimstack:bedrock:7)
Block(-8,12,-5,dimstack:bedrock:7)
Block(-8,12,-4,dimstack:bedrock:7)
Block(-8,12,-3,dimstack:bedrock:7)
Block(-8,12,-2,dimstack:bedrock:7)
Block(-8,12,-1,dimstack:bedrock:7)
Block(-8,12,0,dimstack:bedrock:7)
Block(-8,12,1,dimstack:bedrock:7)
Block(-8,12,2,dimstack:bedrock:7)
Block(-8,12,3,dimstack:bedrock:7)
Block(-8,12,4,dimstack:bedrock:7)
Block(-8,12,5,dimstack:bedrock:7)
Block(-8,12,6,dimstack:bedrock:7)
Block(-8,12,7,dimstack:bedrock:7)
Block(-8,12,8,dimstack:bedrock:7)
Block(-8,13,-7,dimstack:bedrock:7)
Block(-8,13,-6,dimstack:bedrock:7)
Block(-8,13,-5,dimstack:bedrock:7)
Block(-8,13,-4,dimstack:bedrock:7)
Block(-8,13,-3,dimstack:bedrock:7)
Block(-8,13,-2,dimstack:bedrock:7)
Block(-8,13,-1,dimstack:bedrock:7)
Block(-8,13,0,dimstack:bedrock:7)
Block(-8,13,1,dimstack:bedrock:7)
Block(-8,13,2,dimstack:bedrock:7)
Block(-8,13,3,dimstack:bedrock:7)
Block(-8,13,4,dimstack:bedrock:7)
Block(-8,13,5,dimstack:bedrock:7)
Block(-8,13,6,dimstack:bedrock:7)
Block(-8,13,7,dimstack:bedrock:7)
Block(-8,13,8,dimstack:bedrock:7)
Block(-8,14,-7,dimstack:bedrock:7)
Block(-8,14,-6,dimstack:bedrock:7)
Block(-8,14,-5,dimstack:bedrock:7)
Block(-8,14,-4,dimstack:bedrock:7)
Block(-8,14,-3,dimstack:bedrock:7)
Block(-8,14,-2,dimstack:bedrock:7)
Block(-8,14,-1,dimstack:bedrock:7)
Block(-8,14,0,dimstack:bedrock:7)
Block(-8,14,1,dimstack:bedrock:7)
Block(-8,14,2,dimstack:bedrock:7)
Block(-8,14,3,dimstack:bedrock:7)
Block(-8,14,4,dimstack:bedrock:7)
Block(-8,14,5,dimstack:bedrock:7)
Block(-8,14,6,dimstack:bedrock:7)
Block(-8,14,7,dimstack:bedrock:7)
Block(-8,14,8,dimstack:bedrock:7)
Block(-8,15,-7,dimstack:bedrock:7)
Block(-8,15,-6,dimstack:bedrock:7)
Block(-8,15,-5,dimstack:bedrock:7)
Block(-8,15,-4,dimstack:bedrock:7)
Block(-8,15,-3,dimstack:bedrock:7)
Block(-8,15,-2,dimstack:bedrock:7)
Block(-8,15,-1,dimstack:bedrock:7)
Block(-8,15,0,dimstack:bedrock:7)
Block(-8,15,1,dimstack:bedrock:7)
Block(-8,15,2,dimstack:bedrock:7)
Block(-8,15,3,dimstack:bedrock:7)
Block(-8,15,4,dimstack:bedrock:7)
Block(-8,15,5,dimstack:bedrock:7)
Block(-8,15,6,dimstack:bedrock:7)
Block(-8,15,7,dimstack:bedrock:7)
Block(-8,15,8,dimstack:bedrock:7)
Block(-8,16,-7,dimstack:bedrock:7)
Block(-8,16,-6,dimstack:bedrock:7)
Block(-8,16,-5,dimstack:bedrock:7)
Block(-8,16,-4,dimstack:bedrock:7)
Block(-8,16,-3,dimstack:bedrock:7)
Block(-8,16,-2,dimstack:bedrock:7)
Block(-8,16,-1,dimstack:bedrock:7)
Block(-8,16,0,dimstack:bedrock:7)
Block(-8,16,1,dimstack:bedrock:7)
Block(-8,16,2,dimstack:bedrock:7)
Block(-8,16,3,dimstack:bedrock:7)
Block(-8,16,4,dimstack:bedrock:7)
Block(-8,16,5,dimstack:bedrock:7)
Block(-8,16,6,dimstack:bedrock:7)
Block(-8,16,7,dimstack:bedrock:7)
Block(-8,16,8,dimstack:bedrock:7)
Block(-8,17,-7,dimstack:bedrock:7)
Block(-8,17,-6,dimstack:bedrock:7)
Block(-8,17,-5,dimstack:bedrock:7)
Block(-8,17,-4,dimstack:bedrock:7)
Block(-8,17,-3,dimstack:bedrock:7)
Block(-8,17,-2,dimstack:bedrock:7)
Block(-8,17,-1,dimstack:bedrock:7)
Block(-8,17,0,dimstack:bedrock:7)
Block(-8,17,1,dimstack:bedrock:7)
Block(-8,17,2,dimstack:bedrock:7)
Block(-8,17,3,dimstack:bedrock:7)
Block(-8,17,4,dimstack:bedrock:7)
Block(-8,17,5,dimstack:bedrock:7)
Block(-8,17,6,dimstack:bedrock:7)
Block(-8,17,7,dimstack:bedrock:7)
Block(-8,17,8,dimstack:bedrock:7)
Block(-8,18,-7,dimstack:bedrock:7)
Block(-8,18,-6,dimstack:bedrock:7)
Block(-8,18,-5,dimstack:bedrock:7)
Block(-8,18,-4,dimstack:bedrock:7)
Block(-8,18,-3,dimstack:bedrock:7)
Block(-8,18,-2,dimstack:bedrock:7)
Block(-8,18,-1,dimstack:bedrock:7)
Block(-8,18,0,dimstack:bedrock:7)
Block(-8,18,1,dimstack:bedrock:7)
Block(-8,18,2,dimstack:bedrock:7)
Block(-8,18,3,dimstack:bedrock:7)
Block(-8,18,4,dimstack:bedrock:7)
Block(-8,18,5,dimstack:bedrock:7)
Block(-8,18,6,dimstack:bedrock:7)
Block(-8,18,7,dimstack:bedrock:7)
Block(-8,18,8,dimstack:bedrock:7)
Block(-8,19,-7,dimstack:bedrock:7)
Block(-8,19,-6,dimstack:bedrock:7)
Block(-8,19,-5,dimstack:bedrock:7)
Block(-8,19,-4,dimstack:bedrock:7)
Block(-8,19,-3,dimstack:bedrock:7)
Block(-8,19,-2,dimstack:bedrock:7)
Block(-8,19,-1,dimstack:bedrock:7)
Block(-8,19,0,dimstack:bedrock:7)
Block(-8,19,1,dimstack:bedrock:7)
Block(-8,19,2,dimstack:bedrock:7)
Block(-8,19,3,dimstack:bedrock:7)
Block(-8,19,4,dimstack:bedrock:7)
Block(-8,19,5,dimstack:bedrock:7)
Block(-8,19,6,dimstack:bedrock:7)
Block(-8,19,7,dimstack:bedrock:7)
Block(-8,19,8,dimstack:bedrock:7)
Block(-8,20,-7,dimstack:bedrock:7)
Block(-8,20,-6,dimstack:bedrock:7)
Block(-8,20,-5,dimstack:bedrock:7)
Block(-8,20,-4,dimstack:bedrock:7)
Block(-8,20,-3,dimstack:bedrock:7)
Block(-8,20,-2,dimstack:bedrock:7)
Block(-8,20,-1,dimstack:bedrock:7)
Block(-8,20,0,dimstack:bedrock:7)
Block(-8,20,1,dimstack:bedrock:7)
Block(-8,20,2,dimstack:bedrock:7)
Block(-8,20,3,dimstack:bedrock:7)
Block(-8,20,4,dimstack:bedrock:7)
Block(-8,20,5,dimstack:bedrock:7)
Block(-8,20,6,dimstack:bedrock:7)
Block(-8,20,7,dimstack:bedrock:7)
Block(-8,20,8,dimstack:bedrock:7)
Block(-8,21,-7,dimstack:bedrock:7)
Block(-8,21,-6,dimstack:bedrock:7)
Block(-8,21,-5,dimstack:bedrock:7)
Block(-8,21,-4,dimstack:bedrock:7)
Block(-8,21,-3,dimstack:bedrock:7)
Block(-8,21,-2,dimstack:bedrock:7)
Block(-8,21,-1,dimstack:bedrock:7)
Block(-8,21,0,dimstack:bedrock:7)
Block(-8,21,1,dimstack:bedrock:7)
Block(-8,21,2,dimstack:bedrock:7)
Block(-8,21,3,dimstack:bedrock:7)
Block(-8,21,4,dimstack:bedrock:7)
Block(-8,21,5,dimstack:bedrock:7)
Block(-8,21,6,dimstack:bedrock:7)
Block(-8,21,7,dimstack:bedrock:7)
Block(-8,21,8,dimstack:bedrock:7)
Block(-8,22,-7,dimstack:bedrock:7)
Block(-8,22,-6,dimstack:bedrock:7)
Block(-8,22,-5,dimstack:bedrock:7)
Block(-8,22,-4,dimstack:bedrock:7)
Block(-8,22,-3,dimstack:bedrock:7)
Block(-8,22,-2,dimstack:bedrock:7)
Block(-8,22,-1,dimstack:bedrock:7)
Block(-8,22,0,dimstack:bedrock:7)
Block(-8,22,1,dimstack:bedrock:7)
Block(-8,22,2,dimstack:bedrock:7)
Block(-8,22,3,dimstack:bedrock:7)
Block(-8,22,4,dimstack:bedrock:7)
Block(-8,22,5,dimstack:bedrock:7)
Block(-8,22,6,dimstack:bedrock:7)
Block(-8,22,7,dimstack:bedrock:7)
Block(-8,22,8,dimstack:bedrock:7)
Block(-8,23,-7,dimstack:bedrock:7)
Block(-8,23,-6,dimstack:bedrock:7)
Block(-8,23,-5,dimstack:bedrock:7)
Block(-8,23,-4,dimstack:bedrock:7)
Block(-8,23,-3,dimstack:bedrock:7)
Block(-8,23,-2,dimstack:bedrock:7)
Block(-8,23,-1,dimstack:bedrock:7)
Block(-8,23,0,dimstack:bedrock:7)
Block(-8,23,1,dimstack:bedrock:7)
Block(-8,23,2,dimstack:bedrock:7)
Block(-8,23,3,dimstack:bedrock:7)
Block(-8,23,4,dimstack:bedrock:7)
Block(-8,23,5,dimstack:bedrock:7)
Block(-8,23,6,dimstack:bedrock:7)
Block(-8,23,7,dimstack:bedrock:7)
Block(-8,23,8,dimstack:bedrock:7)
Block(-8,24,-7,dimstack:bedrock:7)
Block(-8,24,-6,dimstack:bedrock:7)
Block(-8,24,-5,dimstack:bedrock:7)
Block(-8,24,-4,dimstack:bedrock:7)
Block(-8,24,-3,dimstack:bedrock:7)
Block(-8,24,-2,dimstack:bedrock:7)
Block(-8,24,-1,dimstack:bedrock:7)
Block(-8,24,0,dimstack:bedrock:7)
Block(-8,24,1,dimstack:bedrock:7)
Block(-8,24,2,dimstack:bedrock:7)
Block(-8,24,3,dimstack:bedrock:7)
Block(-8,24,4,dimstack:bedrock:7)
Block(-8,24,5,dimstack:bedrock:7)
Block(-8,24,6,dimstack:bedrock:7)
Block(-8,24,7,dimstack:bedrock:7)
Block(-8,24,8,dimstack:bedrock:7)
Block(-8,25,-7,dimstack:bedrock:7)
Block(-8,25,-6,dimstack:bedrock:7)
Block(-8,25,-5,dimstack:bedrock:7)
Block(-8,25,-4,dimstack:bedrock:7)
Block(-8,25,-3,dimstack:bedrock:7)
Block(-8,25,-2,dimstack:bedrock:7)
Block(-8,25,-1,dimstack:bedrock:7)
Block(-8,25,0,dimstack:bedrock:7)
Block(-8,25,1,dimstack:bedrock:7)
Block(-8,25,2,dimstack:bedrock:7)
Block(-8,25,3,dimstack:bedrock:7)
Block(-8,25,4,dimstack:bedrock:7)
Block(-8,25,5,dimstack:bedrock:7)
Block(-8,25,6,dimstack:bedrock:7)
Block(-8,25,7,dimstack:bedrock:7)
Block(-8,25,8,dimstack:bedrock:7)
Block(-8,26,-7,dimstack:bedrock:7)
Block(-8,26,-6,dimstack:bedrock:7)
Block(-8,26,-5,dimstack:bedrock:7)
Block(-8,26,-4,dimstack:bedrock:7)
Block(-8,26,-3,dimstack:bedrock:7)
Block(-8,26,-2,dimstack:bedrock:7)
Block(-8,26,-1,dimstack:bedrock:7)
Block(-8,26,0,dimstack:bedrock:7)
Block(-8,26,1,dimstack:bedrock:7)
Block(-8,26,2,dimstack:bedrock:7)
Block(-8,26,3,dimstack:bedrock:7)
Block(-8,26,4,dimstack:bedrock:7)
Block(-8,26,5,dimstack:bedrock:7)
Block(-8,26,6,dimstack:bedrock:7)
Block(-8,26,7,dimstack:bedrock:7)
Block(-8,26,8,dimstack:bedrock:7)
Block(-8,27,-7,dimstack:bedrock:7)
Block(-8,27,-6,dimstack:bedrock:7)
Block(-8,27,-5,dimstack:bedrock:7)
Block(-8,27,-4,dimstack:bedrock:7)
Block(-8,27,-3,dimstack:bedrock:7)
Block(-8,27,-2,dimstack:bedrock:7)
Block(-8,27,-1,dimstack:bedrock:7)
Block(-8,27,0,dimstack:bedrock:7)
Block(-8,27,1,dimstack:bedrock:7)
Block(-8,27,2,dimstack:bedrock:7)
Block(-8,27,3,dimstack:bedrock:7)
Block(-8,27,4,dimstack:bedrock:7)
Block(-8,27,5,dimstack:bedrock:7)
Block(-8,27,6,dimstack:bedrock:7)
Block(-8,27,7,dimstack:bedrock:7)
Block(-8,27,8,dimstack:bedrock:7)
Block(-8,28,-7,dimstack:bedrock:7)
Block(-8,28,-6,dimstack:bedrock:7)
Block(-8,28,-5,dimstack:bedrock:7)
Block(-8,28,-4,dimstack:bedrock:7)
Block(-8,28,-3,dimstack:bedrock:7)
Block(-8,28,-2,dimstack:bedrock:7)
Block(-8,28,-1,dimstack:bedrock:7)
Block(-8,28,0,dimstack:bedrock:7)
Block(-8,28,1,dimstack:bedrock:7)
Block(-8,28,2,dimstack:bedrock:7)
Block(-8,28,3,dimstack:bedrock:7)
Block(-8,28,4,dimstack:bedrock:7)
Block(-8,28,5,dimstack:bedrock:7)
Block(-8,28,6,dimstack:bedrock:7)
Block(-8,28,7,dimstack:bedrock:7)
Block(-8,28,8,dimstack:bedrock:7)
Block(-8,29,-7,dimstack:bedrock:7)
Block(-8,29,-6,dimstack:bedrock:7)
Block(-8,29,-5,dimstack:bedrock:7)
Block(-8,29,-4,dimstack:bedrock:7)
Block(-8,29,-3,dimstack:bedrock:7)
Block(-8,29,-2,dimstack:bedrock:7)
Block(-8,29,-1,dimstack:bedrock:7)
Block(-8,29,0,dimstack:bedrock:7)
Block(-8,29,1,dimstack:bedrock:7)
Block(-8,29,2,dimstack:bedrock:7)
Block(-8,29,3,dimstack:bedrock:7)
Block(-8,29,4,dimstack:bedrock:7)
Block(-8,29,5,dimstack:bedrock:7)
Block(-8,29,6,dimstack:bedrock:7)
Block(-8,29,7,dimstack:bedrock:7)
Block(-8,29,8,dimstack:bedrock:7)
Block(-8,30,-7,dimstack:bedrock:7)
Block(-8,30,-6,dimstack:bedrock:7)
Block(-8,30,-5,dimstack:bedrock:7)
Block(-8,30,-4,dimstack:bedrock:7)
Block(-8,30,-3,dimstack:bedrock:7)
Block(-8,30,-2,dimstack:bedrock:7)
Block(-8,30,-1,dimstack:bedrock:7)
Block(-8,30,0,dimstack:bedrock:7)
Block(-8,30,1,dimstack:bedrock:7)
Block(-8,30,2,dimstack:bedrock:7)
Block(-8,30,3,dimstack:bedrock:7)
Block(-8,30,4,dimstack:bedrock:7)
Block(-8,30,5,dimstack:bedrock:7)
Block(-8,30,6,dimstack:bedrock:7)
Block(-8,30,7,dimstack:bedrock:7)
Block(-8,30,8,dimstack:bedrock:7)
Block(-8,31,-7,dimstack:bedrock:7)
Block(-8,31,-6,dimstack:bedrock:7)
Block(-8,31,-5,dimstack:bedrock:7)
Block(-8,31,-4,dimstack:bedrock:7)
Block(-8,31,-3,dimstack:bedrock:7)
Block(-8,31,-2,dimstack:bedrock:7)
Block(-8,31,-1,dimstack:bedrock:7)
Block(-8,31,0,dimstack:bedrock:7)
Block(-8,31,1,dimstack:bedrock:7)
Block(-8,31,2,dimstack:bedrock:7)
Block(-8,31,3,dimstack:bedrock:7)
Block(-8,31,4,dimstack:bedrock:7)
Block(-8,31,5,dimstack:bedrock:7)
Block(-8,31,6,dimstack:bedrock:7)
Block(-8,31,7,dimstack:bedrock:7)
Block(-8,31,8,dimstack:bedrock:7)
Block(-8,32,-7,dimstack:bedrock:7)
Block(-8,32,-6,dimstack:bedrock:7)
Block(-8,32,-5,dimstack:bedrock:7)
Block(-8,32,-4,dimstack:bedrock:7)
Block(-8,32,-3,dimstack:bedrock:7)
Block(-8,32,-2,dimstack:bedrock:7)
Block(-8,32,-1,dimstack:bedrock:7)
Block(-8,32,0,dimstack:bedrock:7)
Block(-8,32,1,dimstack:bedrock:7)
Block(-8,32,2,dimstack:bedrock:7)
Block(-8,32,3,dimstack:bedrock:7)
Block(-8,32,4,dimstack:bedrock:7)
Block(-8,32,5,dimstack:bedrock:7)
Block(-8,32,6,dimstack:bedrock:7)
Block(-8,32,7,dimstack:bedrock:7)
Block(-8,32,8,dimstack:bedrock:7)
Block(-8,33,-7,dimstack:bedrock:7)
Block(-8,33,-6,dimstack:bedrock:7)
Block(-8,33,-5,dimstack:bedrock:7)
Block(-8,33,-4,dimstack:bedrock:7)
Block(-8,33,-3,dimstack:bedrock:7)
Block(-8,33,-2,dimstack:bedrock:7)
Block(-8,33,-1,dimstack:bedrock:7)
Block(-8,33,0,dimstack:bedrock:7)
Block(-8,33,1,dimstack:bedrock:7)
Block(-8,33,2,dimstack:bedrock:7)
Block(-8,33,3,dimstack:bedrock:7)
Block(-8,33,4,dimstack:bedrock:7)
Block(-8,33,5,dimstack:bedrock:7)
Block(-8,33,6,dimstack:bedrock:7)
Block(-8,33,7,dimstack:bedrock:7)
Block(-8,33,8,dimstack:bedrock:7)
Block(-8,34,-7,dimstack:bedrock:7)
Block(-8,34,-6,dimstack:bedrock:7)
Block(-8,34,-5,dimstack:bedrock:7)
Block(-8,34,-4,dimstack:bedrock:7)
Block(-8,34,-3,dimstack:bedrock:7)
Block(-8,34,-2,dimstack:bedrock:7)
Block(-8,34,-1,dimstack:bedrock:7)
Block(-8,34,0,dimstack:bedrock:7)
Block(-8,34,1,dimstack:bedrock:7)
Block(-8,34,2,dimstack:bedrock:7)
Block(-8,34,3,dimstack:bedrock:7)
Block(-8,34,4,dimstack:bedrock:7)
Block(-8,34,5,dimstack:bedrock:7)
Block(-8,34,6,dimstack:bedrock:7)
Block(-8,34,7,dimstack:bedrock:7)
Block(-8,34,8,dimstack:bedrock:7)
Block(-8,35,-7,dimstack:bedrock:7)
Block(-8,35,-6,dimstack:bedrock:7)
Block(-8,35,-5,dimstack:bedrock:7)
Block(-8,35,-4,dimstack:bedrock:7)
Block(-8,35,-3,dimstack:bedrock:7)
Block(-8,35,-2,dimstack:bedrock:7)
Block(-8,35,-1,dimstack:bedrock:7)
Block(-8,35,0,dimstack:bedrock:7)
Block(-8,35,1,dimstack:bedrock:7)
Block(-8,35,2,dimstack:bedrock:7)
Block(-8,35,3,dimstack:bedrock:7)
Block(-8,35,4,dimstack:bedrock:7)
Block(-8,35,5,dimstack:bedrock:7)
Block(-8,35,6,dimstack:bedrock:7)
Block(-8,35,7,dimstack:bedrock:7)
Block(-8,35,8,dimstack:bedrock:7)
Block(-8,36,-7,dimstack:bedrock:7)
Block(-8,36,-6,dimstack:bedrock:7)
Block(-8,36,-5,dimstack:bedrock:7)
Block(-8,36,-4,dimstack:bedrock:7)
Block(-8,36,-3,dimstack:bedrock:7)
Block(-8,36,-2,dimstack:bedrock:7)
Block(-8,36,-1,dimstack:bedrock:7)
Block(-8,36,0,dimstack:bedrock:7)
Block(-8,36,1,dimstack:bedrock:7)
Block(-8,36,2,dimstack:bedrock:7)
Block(-8,36,3,dimstack:bedrock:7)
Block(-8,36,4,dimstack:bedrock:7)
Block(-8,36,5,dimstack:bedrock:7)
Block(-8,36,6,dimstack:bedrock:7)
Block(-8,36,7,dimstack:bedrock:7)
Block(-8,36,8,dimstack:bedrock:7)
Block(-8,37,-7,dimstack:bedrock:7)
Block(-8,37,-6,dimstack:bedrock:7)
Block(-8,37,-5,dimstack:bedrock:7)
Block(-8,37,-4,dimstack:bedrock:7)
Block(-8,37,-3,dimstack:bedrock:7)
Block(-8,37,-2,dimstack:bedrock:7)
Block(-8,37,-1,dimstack:bedrock:7)
Block(-8,37,0,dimstack:bedrock:7)
Block(-8,37,1,dimstack:bedrock:7)
Block(-8,37,2,dimstack:bedrock:7)
Block(-8,37,3,dimstack:bedrock:7)
Block(-8,37,4,dimstack:bedrock:7)
Block(-8,37,5,dimstack:bedrock:7)
Block(-8,37,6,dimstack:bedrock:7)
Block(-8,37,7,dimstack:bedrock:7)
Block(-8,37,8,dimstack:bedrock:7)
Block(-8,38,-7,dimstack:bedrock:7)
Block(-8,38,-6,dimstack:bedrock:7)
Block(-8,38,-5,dimstack:bedrock:7)
Block(-8,38,-4,dimstack:bedrock:7)
Block(-8,38,-3,dimstack:bedrock:7)
Block(-8,38,-2,dimstack:bedrock:7)
Block(-8,38,-1,dimstack:bedrock:7)
Block(-8,38,0,dimstack:bedrock:7)
Block(-8,38,1,dimstack:bedrock:7)
Block(-8,38,2,dimstack:bedrock:7)
Block(-8,38,3,dimstack:bedrock:7)
Block(-8,38,4,dimstack:bedrock:7)
Block(-8,38,5,dimstack:bedrock:7)
Block(-8,38,6,dimstack:bedrock:7)
Block(-8,38,7,dimstack:bedrock:7)
Block(-8,38,8,dimstack:bedrock:7)
Block(-8,39,-7,dimstack:bedrock:7)
Block(-8,39,-6,dimstack:bedrock:7)
Block(-8,39,-5,dimstack:bedrock:7)
Block(-8,39,-4,dimstack:bedrock:7)
Block(-8,39,-3,dimstack:bedrock:7)
Block(-8,39,-2,dimstack:bedrock:7)
Block(-8,39,-1,dimstack:bedrock:7)
Block(-8,39,0,dimstack:bedrock:7)
Block(-8,39,1,dimstack:bedrock:7)
Block(-8,39,2,dimstack:bedrock:7)
Block(-8,39,3,dimstack:bedrock:7)
Block(-8,39,4,dimstack:bedrock:7)
Block(-8,39,5,dimstack:bedrock:7)
Block(-8,39,6,dimstack:bedrock:7)
Block(-8,39,7,dimstack:bedrock:7)
Block(-8,39,8,dimstack:bedrock:7)
Block(-8,40,-7,dimstack:bedrock:7)
Block(-8,40,-6,dimstack:bedrock:7)
Block(-8,40,-5,dimstack:bedrock:7)
Block(-8,40,-4,dimstack:bedrock:7)
Block(-8,40,-3,dimstack:bedrock:7)
Block(-8,40,-2,dimstack:bedrock:7)
Block(-8,40,-1,dimstack:bedrock:7)
Block(-8,40,0,dimstack:bedrock:7)
Block(-8,40,1,dimstack:bedrock:7)
Block(-8,40,2,dimstack:bedrock:7)
Block(-8,40,3,dimstack:bedrock:7)
Block(-8,40,4,dimstack:bedrock:7)
Block(-8,40,5,dimstack:bedrock:7)
Block(-8,40,6,dimstack:bedrock:7)
Block(-8,40,7,dimstack:bedrock:7)
Block(-8,40,8,dimstack:bedrock:7)
Block(-8,41,-7,dimstack:bedrock:7)
Block(-8,41,-6,dimstack:bedrock:7)
Block(-8,41,-5,dimstack:bedrock:7)
Block(-8,41,-4,dimstack:bedrock:7)
Block(-8,41,-3,dimstack:bedrock:7)
Block(-8,41,-2,dimstack:bedrock:7)
Block(-8,41,-1,dimstack:bedrock:7)
Block(-8,41,0,dimstack:bedrock:7)
Block(-8,41,1,dimstack:bedrock:7)
Block(-8,41,2,dimstack:bedrock:7)
Block(-8,41,3,dimstack:bedrock:7)
Block(-8,41,4,dimstack:bedrock:7)
Block(-8,41,5,dimstack:bedrock:7)
Block(-8,41,6,dimstack:bedrock:7)
Block(-8,41,7,dimstack:bedrock:7)
Block(-8,41,8,dimstack:bedrock:7)
Block(-8,42,-7,dimstack:bedrock:7)
Block(-8,42,-6,dimstack:bedrock:7)
Block(-8,42,-5,dimstack:bedrock:7)
Block(-8,42,-4,dimstack:bedrock:7)
Block(-8,42,-3,dimstack:bedrock:7)
Block(-8,42,-2,dimstack:bedrock:7)
Block(-8,42,-1,dimstack:bedrock:7)
Block(-8,42,0,dimstack:bedrock:7)
Block(-8,42,1,dimstack:bedrock:7)
Block(-8,42,2,dimstack:bedrock:7)
Block(-8,42,3,dimstack:bedrock:7)
Block(-8,42,4,dimstack:bedrock:7)
Block(-8,42,5,dimstack:bedrock:7)
Block(-8,42,6,dimstack:bedrock:7)
Block(-8,42,7,dimstack:bedrock:7)
Block(-8,42,8,dimstack:bedrock:7)
Block(-8,43,-7,dimstack:bedrock:7)
Block(-8,43,-6,dimstack:bedrock:7)
Block(-8,43,-5,dimstack:bedrock:7)
Block(-8,43,-4,dimstack:bedrock:7)
Block(-8,43,-3,dimstack:bedrock:7)
Block(-8,43,-2,dimstack:bedrock:7)
Block(-8,43,-1,dimstack:bedrock:7)
Block(-8,43,0,dimstack:bedrock:7)
Block(-8,43,1,dimstack:bedrock:7)
Block(-8,43,2,dimstack:bedrock:7)
Block(-8,43,3,dimstack:bedrock:7)
Block(-8,43,4,dimstack:bedrock:7)
Block(-8,43,5,dimstack:bedrock:7)
Block(-8,43,6,dimstack:bedrock:7)
Block(-8,43,7,dimstack:bedrock:7)
Block(-8,43,8,dimstack:bedrock:7)
Block(-8,44,-7,dimstack:bedrock:7)
Block(-8,44,-6,dimstack:bedrock:7)
Block(-8,44,-5,dimstack:bedrock:7)
Block(-8,44,-4,dimstack:bedrock:7)
Block(-8,44,-3,dimstack:bedrock:7)
Block(-8,44,-2,dimstack:bedrock:7)
Block(-8,44,-1,dimstack:bedrock:7)
Block(-8,44,0,dimstack:bedrock:7)
Block(-8,44,1,dimstack:bedrock:7)
Block(-8,44,2,dimstack:bedrock:7)
Block(-8,44,3,dimstack:bedrock:7)
Block(-8,44,4,dimstack:bedrock:7)
Block(-8,44,5,dimstack:bedrock:7)
Block(-8,44,6,dimstack:bedrock:7)
Block(-8,44,7,dimstack:bedrock:7)
Block(-8,44,8,dimstack:bedrock:7)
Block(-8,45,-7,dimstack:bedrock:7)
Block(-8,45,-6,dimstack:bedrock:7)
Block(-8,45,-5,dimstack:bedrock:7)
Block(-8,45,-4,dimstack:bedrock:7)
Block(-8,45,-3,dimstack:bedrock:7)
Block(-8,45,-2,dimstack:bedrock:7)
Block(-8,45,-1,dimstack:bedrock:7)
Block(-8,45,0,dimstack:bedrock:7)
Block(-8,45,1,dimstack:bedrock:7)
Block(-8,45,2,dimstack:bedrock:7)
Block(-8,45,3,dimstack:bedrock:7)
Block(-8,45,4,dimstack:bedrock:7)
Block(-8,45,5,dimstack:bedrock:7)
Block(-8,45,6,dimstack:bedrock:7)
Block(-8,45,7,dimstack:bedrock:7)
Block(-8,45,8,dimstack:bedrock:7)
Block(-8,46,-7,dimstack:bedrock:7)
Block(-8,46,-6,dimstack:bedrock:7)
Block(-8,46,-5,dimstack:bedrock:7)
Block(-8,46,-4,dimstack:bedrock:7)
Block(-8,46,-3,dimstack:bedrock:7)
Block(-8,46,-2,dimstack:bedrock:7)
Block(-8,46,-1,dimstack:bedrock:7)
Block(-8,46,0,dimstack:bedrock:7)
Block(-8,46,1,dimstack:bedrock:7)
Block(-8,46,2,dimstack:bedrock:7)
Block(-8,46,3,dimstack:bedrock:7)
Block(-8,46,4,dimstack:bedrock:7)
Block(-8,46,5,dimstack:bedrock:7)
Block(-8,46,6,dimstack:bedrock:7)
Block(-8,46,7,dimstack:bedrock:7)
Block(-8,46,8,dimstack:bedrock:7)
Block(-8,47,-7,dimstack:bedrock:7)
Block(-8,47,-6,dimstack:bedrock:7)
Block(-8,47,-5,dimstack:bedrock:7)
Block(-8,47,-4,dimstack:bedrock:7)
Block(-8,47,-3,dimstack:bedrock:7)
Block(-8,47,-2,dimstack:bedrock:7)
Block(-8,47,-1,dimstack:bedrock:7)
Block(-8,47,0,dimstack:bedrock:7)
Block(-8,47,1,dimstack:bedrock:7)
Block(-8,47,2,dimstack:bedrock:7)
Block(-8,47,3,dimstack:bedrock:7)
Block(-8,47,4,dimstack:bedrock:7)
Block(-8,47,5,dimstack:bedrock:7)
Block(-8,47,6,dimstack:bedrock:7)
Block(-8,47,7,dimstack:bedrock:7)
Block(-8,47,8,dimstack:bedrock:7)
Block(-8,48,-7,dimstack:bedrock:7)
Block(-8,48,-6,dimstack:bedrock:7)
Block(-8,48,-5,dimstack:bedrock:7)
Block(-8,48,-4,dimstack:bedrock:7)
Block(-8,48,-3,dimstack:bedrock:7)
Block(-8,48,-2,dimstack:bedrock:7)
Block(-8,48,-1,dimstack:bedrock:7)
Block(-8,48,0,dimstack:bedrock:7)
Block(-8,48,1,dimstack:bedrock:7)
Block(-8,48,2,dimstack:bedrock:7)
Block(-8,48,3,dimstack:bedrock:7)
Block(-8,48,4,dimstack:bedrock:7)
Block(-8,48,5,dimstack:bedrock:7)
Block(-8,48,6,dimstack:bedrock:7)
Block(-8,48,7,dimstack:bedrock:7)
Block(-8,48,8,dimstack:bedrock:7)
Block(-8,49,-7,dimstack:bedrock:7)
Block(-8,49,-6,dimstack:bedrock:7)
Block(-8,49,-5,dimstack:bedrock:7)
Block(-8,49,-4,dimstack:bedrock:7)
Block(-8,49,-3,dimstack:bedrock:7)
Block(-8,49,-2,dimstack:bedrock:7)
Block(-8,49,-1,dimstack:bedrock:7)
Block(-8,49,0,dimstack:bedrock:7)
Block(-8,49,1,dimstack:bedrock:7)
Block(-8,49,2,dimstack:bedrock:7)
Block(-8,49,3,dimstack:bedrock:7)
Block(-8,49,4,dimstack:bedrock:7)
Block(-8,49,5,dimstack:bedrock:7)
Block(-8,49,6,dimstack:bedrock:7)
Block(-8,49,7,dimstack:bedrock:7)
Block(-8,49,8,dimstack:bedrock:7)
Block(-8,50,-7,dimstack:bedrock:7)
Block(-8,50,-6,dimstack:bedrock:7)
Block(-8,50,-5,dimstack:bedrock:7)
Block(-8,50,-4,dimstack:bedrock:7)
Block(-8,50,-3,dimstack:bedrock:7)
Block(-8,50,-2,dimstack:bedrock:7)
Block(-8,50,-1,dimstack:bedrock:7)
Block(-8,50,0,dimstack:bedrock:7)
Block(-8,50,1,dimstack:bedrock:7)
Block(-8,50,2,dimstack:bedrock:7)
Block(-8,50,3,dimstack:bedrock:7)
Block(-8,50,4,dimstack:bedrock:7)
Block(-8,50,5,dimstack:bedrock:7)
Block(-8,50,6,dimstack:bedrock:7)
Block(-8,50,7,dimstack:bedrock:7)
Block(-8,50,8,dimstack:bedrock:7)
Block(-8,51,-7,dimstack:bedrock:7)
Block(-8,51,-6,dimstack:bedrock:7)
Block(-8,51,-5,dimstack:bedrock:7)
Block(-8,51,-4,dimstack:bedrock:7)
Block(-8,51,-3,dimstack:bedrock:7)
Block(-8,51,-2,dimstack:bedrock:7)
Block(-8,51,-1,dimstack:bedrock:7)
Block(-8,51,0,dimstack:bedrock:7)
Block(-8,51,1,dimstack:bedrock:7)
Block(-8,51,2,dimstack:bedrock:7)
Block(-8,51,3,dimstack:bedrock:7)
Block(-8,51,4,dimstack:bedrock:7)
Block(-8,51,5,dimstack:bedrock:7)
Block(-8,51,6,dimstack:bedrock:7)
Block(-8,51,7,dimstack:bedrock:7)
Block(-8,51,8,dimstack:bedrock:7)
Block(-8,52,-7,dimstack:bedrock:7)
Block(-8,52,-6,dimstack:bedrock:7)
Block(-8,52,-5,dimstack:bedrock:7)
Block(-8,52,-4,dimstack:bedrock:7)
Block(-8,52,-3,dimstack:bedrock:7)
Block(-8,52,-2,dimstack:bedrock:7)
Block(-8,52,-1,dimstack:bedrock:7)
Block(-8,52,0,dimstack:bedrock:7)
Block(-8,52,1,dimstack:bedrock:7)
Block(-8,52,2,dimstack:bedrock:7)
Block(-8,52,3,dimstack:bedrock:7)
Block(-8,52,4,dimstack:bedrock:7)
Block(-8,52,5,dimstack:bedrock:7)
Block(-8,52,6,dimstack:bedrock:7)
Block(-8,52,7,dimstack:bedrock:7)
Block(-8,52,8,dimstack:bedrock:7)
Block(-8,53,-7,dimstack:bedrock:7)
Block(-8,53,-6,dimstack:bedrock:7)
Block(-8,53,-5,dimstack:bedrock:7)
Block(-8,53,-4,dimstack:bedrock:7)
Block(-8,53,-3,dimstack:bedrock:7)
Block(-8,53,-2,dimstack:bedrock:7)
Block(-8,53,-1,dimstack:bedrock:7)
Block(-8,53,0,dimstack:bedrock:7)
Block(-8,53,1,dimstack:bedrock:7)
Block(-8,53,2,dimstack:bedrock:7)
Block(-8,53,3,dimstack:bedrock:7)
Block(-8,53,4,dimstack:bedrock:7)
Block(-8,53,5,dimstack:bedrock:7)
Block(-8,53,6,dimstack:bedrock:7)
Block(-8,53,7,dimstack:bedrock:7)
Block(-8,53,8,dimstack:bedrock:7)
Block(-8,54,-7,dimstack:bedrock:7)
Block(-8,54,-6,dimstack:bedrock:7)
Block(-8,54,-5,dimstack:bedrock:7)
Block(-8,54,-4,dimstack:bedrock:7)
Block(-8,54,-3,dimstack:bedrock:7)
Block(-8,54,-2,dimstack:bedrock:7)
Block(-8,54,-1,dimstack:bedrock:7)
Block(-8,54,0,dimstack:bedrock:7)
Block(-8,54,1,dimstack:bedrock:7)
Block(-8,54,2,dimstack:bedrock:7)
Block(-8,54,3,dimstack:bedrock:7)
Block(-8,54,4,dimstack:bedrock:7)
Block(-8,54,5,dimstack:bedrock:7)
Block(-8,54,6,dimstack:bedrock:7)
Block(-8,54,7,dimstack:bedrock:7)
Block(-8,54,8,dimstack:bedrock:7)
Block(-8,55,-7,dimstack:bedrock:7)
Block(-8,55,-6,dimstack:bedrock:7)
Block(-8,55,-5,dimstack:bedrock:7)
Block(-8,55,-4,dimstack:bedrock:7)
Block(-8,55,-3,dimstack:bedrock:7)
Block(-8,55,-2,dimstack:bedrock:7)
Block(-8,55,-1,dimstack:bedrock:7)
Block(-8,55,0,dimstack:bedrock:7)
Block(-8,55,1,dimstack:bedrock:7)
Block(-8,55,2,dimstack:bedrock:7)
Block(-8,55,3,dimstack:bedrock:7)
Block(-8,55,4,dimstack:bedrock:7)
Block(-8,55,5,dimstack:bedrock:7)
Block(-8,55,6,dimstack:bedrock:7)
Block(-8,55,7,dimstack:bedrock:7)
Block(-8,55,8,dimstack:bedrock:7)
Block(-8,56,-7,dimstack:bedrock:7)
Block(-8,56,-6,dimstack:bedrock:7)
Block(-8,56,-5,dimstack:bedrock:7)
Block(-8,56,-4,dimstack:bedrock:7)
Block(-8,56,-3,dimstack:bedrock:7)
Block(-8,56,-2,dimstack:bedrock:7)
Block(-8,56,-1,dimstack:bedrock:7)
Block(-8,56,0,dimstack:bedrock:7)
Block(-8,56,1,dimstack:bedrock:7)
Block(-8,56,2,dimstack:bedrock:7)
Block(-8,56,3,dimstack:bedrock:7)
Block(-8,56,4,dimstack:bedrock:7)
Block(-8,56,5,dimstack:bedrock:7)
Block(-8,56,6,dimstack:bedrock:7)
Block(-8,56,7,dimstack:bedrock:7)
Block(-8,56,8,dimstack:bedrock:7)
Block(-8,57,-7,dimstack:bedrock:7)
Block(-8,57,-6,dimstack:bedrock:7)
Block(-8,57,-5,dimstack:bedrock:7)
Block(-8,57,-4,dimstack:bedrock:7)
Block(-8,57,-3,dimstack:bedrock:7)
Block(-8,57,-2,dimstack:bedrock:7)
Block(-8,57,-1,dimstack:bedrock:7)
Block(-8,57,0,dimstack:bedrock:7)
Block(-8,57,1,dimstack:bedrock:7)
Block(-8,57,2,dimstack:bedrock:7)
Block(-8,57,3,dimstack:bedrock:7)
Block(-8,57,4,dimstack:bedrock:7)
Block(-8,57,5,dimstack:bedrock:7)
Block(-8,57,6,dimstack:bedrock:7)
Block(-8,57,7,dimstack:bedrock:7)
Block(-8,57,8,dimstack:bedrock:7)
Block(-8,58,-7,dimstack:bedrock:7)
Block(-8,58,-6,dimstack:bedrock:7)
Block(-8,58,-5,dimstack:bedrock:7)
Block(-8,58,-4,dimstack:bedrock:7)
Block(-8,58,-3,dimstack:bedrock:7)
Block(-8,58,-2,dimstack:bedrock:7)
Block(-8,58,-1,dimstack:bedrock:7)
Block(-8,58,0,dimstack:bedrock:7)
Block(-8,58,1,dimstack:bedrock:7)
Block(-8,58,2,dimstack:bedrock:7)
Block(-8,58,3,dimstack:bedrock:7)
Block(-8,58,4,dimstack:bedrock:7)
Block(-8,58,5,dimstack:bedrock:7)
Block(-8,58,6,dimstack:bedrock:7)
Block(-8,58,7,dimstack:bedrock:7)
Block(-8,58,8,dimstack:bedrock:7)
Block(-8,59,-7,dimstack:bedrock:7)
Block(-8,59,-6,dimstack:bedrock:7)
Block(-8,59,-5,dimstack:bedrock:7)
Block(-8,59,-4,dimstack:bedrock:7)
Block(-8,59,-3,dimstack:bedrock:7)
Block(-8,59,-2,dimstack:bedrock:7)
Block(-8,59,-1,dimstack:bedrock:7)
Block(-8,59,0,dimstack:bedrock:7)
Block(-8,59,1,dimstack:bedrock:7)
Block(-8,59,2,dimstack:bedrock:7)
Block(-8,59,3,dimstack:bedrock:7)
Block(-8,59,4,dimstack:bedrock:7)
Block(-8,59,5,dimstack:bedrock:7)
Block(-8,59,6,dimstack:bedrock:7)
Block(-8,59,7,dimstack:bedrock:7)
Block(-8,59,8,dimstack:bedrock:7)
Block(-8,60,-7,dimstack:bedrock:7)
Block(-8,60,-6,dimstack:bedrock:7)
Block(-8,60,-5,dimstack:bedrock:7)
Block(-8,60,-4,dimstack:bedrock:7)
Block(-8,60,-3,dimstack:bedrock:7)
Block(-8,60,-2,dimstack:bedrock:7)
Block(-8,60,-1,dimstack:bedrock:7)
Block(-8,60,0,dimstack:bedrock:7)
Block(-8,60,1,dimstack:bedrock:7)
Block(-8,60,2,dimstack:bedrock:7)
Block(-8,60,3,dimstack:bedrock:7)
Block(-8,60,4,dimstack:bedrock:7)
Block(-8,60,5,dimstack:bedrock:7)
Block(-8,60,6,dimstack:bedrock:7)
Block(-8,60,7,dimstack:bedrock:7)
Block(-8,60,8,dimstack:bedrock:7)
Block(-8,61,-7,dimstack:bedrock:7)
Block(-8,61,-6,dimstack:bedrock:7)
Block(-8,61,-5,dimstack:bedrock:7)
Block(-8,61,-4,dimstack:bedrock:7)
Block(-8,61,-3,dimstack:bedrock:7)
Block(-8,61,-2,dimstack:bedrock:7)
Block(-8,61,-1,dimstack:bedrock:7)
Block(-8,61,0,dimstack:bedrock:7)
Block(-8,61,1,dimstack:bedrock:7)
Block(-8,61,2,dimstack:bedrock:7)
Block(-8,61,3,dimstack:bedrock:7)
Block(-8,61,4,dimstack:bedrock:7)
Block(-8,61,5,dimstack:bedrock:7)
Block(-8,61,6,dimstack:bedrock:7)
Block(-8,61,7,dimstack:bedrock:7)
Block(-8,61,8,dimstack:bedrock:7)
Block(-8,62,-7,dimstack:bedrock:7)
Block(-8,62,-6,dimstack:bedrock:7)
Block(-8,62,-5,dimstack:bedrock:7)
Block(-8,62,-4,dimstack:bedrock:7)
Block(-8,62,-3,dimstack:bedrock:7)
Block(-8,62,-2,dimstack:bedrock:7)
Block(-8,62,-1,dimstack:bedrock:7)
Block(-8,62,0,dimstack:bedrock:7)
Block(-8,62,1,dimstack:bedrock:7)
Block(-8,62,2,dimstack:bedrock:7)
Block(-8,62,3,dimstack:bedrock:7)
Block(-8,62,4,dimstack:bedrock:7)
Block(-8,62,5,dimstack:bedrock:7)
Block(-8,62,6,dimstack:bedrock:7)
Block(-8,62,7,dimstack:bedrock:7)
Block(-8,62,8,dimstack:bedrock:7)
Block(-8,63,-7,dimstack:bedrock:7)
Block(-8,63,-6,dimstack:bedrock:7)
Block(-8,63,-5,dimstack:bedrock:7)
Block(-8,63,-4,dimstack:bedrock:7)
Block(-8,63,-3,dimstack:bedrock:7)
Block(-8,63,-2,dimstack:bedrock:7)
Block(-8,63,-1,dimstack:bedrock:7)
Block(-8,63,0,dimstack:bedrock:7)
Block(-8,63,1,dimstack:bedrock:7)
Block(-8,63,2,dimstack:bedrock:7)
Block(-8,63,3,dimstack:bedrock:7)
Block(-8,63,4,dimstack:bedrock:7)
Block(-8,63,5,dimstack:bedrock:7)
Block(-8,63,6,dimstack:bedrock:7)
Block(-8,63,7,dimstack:bedrock:7)
Block(-8,63,8,dimstack:bedrock:7)
Block(-8,64,-7,dimstack:bedrock:7)
Block(-8,64,-6,dimstack:bedrock:7)
Block(-8,64,-5,dimstack:bedrock:7)
Block(-8,64,-4,dimstack:bedrock:7)
Block(-8,64,-3,dimstack:bedrock:7)
Block(-8,64,-2,dimstack:bedrock:7)
Block(-8,64,-1,dimstack:bedrock:7)
Block(-8,64,0,dimstack:bedrock:7)
Block(-8,64,1,dimstack:bedrock:7)
Block(-8,64,2,dimstack:bedrock:7)
Block(-8,64,3,dimstack:bedrock:7)
Block(-8,64,4,dimstack:bedrock:7)
Block(-8,64,5,dimstack:bedrock:7)
Block(-8,64,6,dimstack:bedrock:7)
Block(-8,64,7,dimstack:bedrock:7)
Block(-8,64,8,dimstack:bedrock:7)
Block(-8,65,-7,dimstack:bedrock:7)
Block(-8,65,-6,dimstack:bedrock:7)
Block(-8,65,-5,dimstack:bedrock:7)
Block(-8,65,-4,dimstack:bedrock:7)
Block(-8,65,-3,dimstack:bedrock:7)
Block(-8,65,-2,dimstack:bedrock:7)
Block(-8,65,-1,dimstack:bedrock:7)
Block(-8,65,0,dimstack:bedrock:7)
Block(-8,65,1,dimstack:bedrock:7)
Block(-8,65,2,dimstack:bedrock:7)
Block(-8,65,3,dimstack:bedrock:7)
Block(-8,65,4,dimstack:bedrock:7)
Block(-8,65,5,dimstack:bedrock:7)
Block(-8,65,6,dimstack:bedrock:7)
Block(-8,65,7,dimstack:bedrock:7)
Block(-8,65,8,dimstack:bedrock:7)
Block(-8,66,-7,dimstack:bedrock:7)
Block(-8,66,-6,dimstack:bedrock:7)
Block(-8,66,-5,dimstack:bedrock:7)
Block(-8,66,-4,dimstack:bedrock:7)
Block(-8,66,-3,dimstack:bedrock:7)
Block(-8,66,-2,dimstack:bedrock:7)
Block(-8,66,-1,dimstack:bedrock:7)
Block(-8,66,0,dimstack:bedrock:7)
Block(-8,66,1,dimstack:bedrock:7)
Block(-8,66,2,dimstack:bedrock:7)
Block(-8,66,3,dimstack:bedrock:7)
Block(-8,66,4,dimstack:bedrock:7)
Block(-8,66,5,dimstack:bedrock:7)
Block(-8,66,6,dimstack:bedrock:7)
Block(-8,66,7,dimstack:bedrock:7)
Block(-8,66,8,dimstack:bedrock:7)
Block(-8,67,-7,dimstack:bedrock:7)
Block(-8,67,-6,dimstack:bedrock:7)
Block(-8,67,-5,dimstack:bedrock:7)
Block(-8,67,-4,dimstack:bedrock:7)
Block(-8,67,-3,dimstack:bedrock:7)
Block(-8,67,-2,dimstack:bedrock:7)
Block(-8,67,-1,dimstack:bedrock:7)
Block(-8,67,0,dimstack:bedrock:7)
Block(-8,67,1,dimstack:bedrock:7)
Block(-8,67,2,dimstack:bedrock:7)
Block(-8,67,3,dimstack:bedrock:7)
Block(-8,67,4,dimstack:bedrock:7)
Block(-8,67,5,dimstack:bedrock:7)
Block(-8,67,6,dimstack:bedrock:7)
Block(-8,67,7,dimstack:bedrock:7)
Block(-8,67,8,dimstack:bedrock:7)
Block(-8,68,-7,dimstack:bedrock:7)
Block(-8,68,-6,dimstack:bedrock:7)
Block(-8,68,-5,dimstack:bedrock:7)
Block(-8,68,-4,dimstack:bedrock:7)
Block(-8,68,-3,dimstack:bedrock:7)
Block(-8,68,-2,dimstack:bedrock:7)
Block(-8,68,-1,dimstack:bedrock:7)
Block(-8,68,0,dimstack:bedrock:7)
Block(-8,68,1,stone:0)
Block(-8,68,2,dimstack:bedrock:7)
Block(-8,68,3,dimstack:bedrock:7)
Block(-8,68,4,dimstack:bedrock:7)
Block(-8,68,5,dimstack:bedrock:7)
Block(-8,68,6,dimstack:bedrock:7)
Block(-8,68,7,dimstack:bedrock:7)
Block(-8,68,8,dimstack:bedrock:7)
RandomBlock(-8,69,-7,SAND:0,50,BIOMESOPLENTY:DRIED_SAND,100)
Block(-8,69,-6,dimstack:bedrock:7)
Block(-8,69,-5,dimstack:bedrock:7)
Block(-8,69,-4,dimstack:bedrock:7)
Block(-8,69,-3,dimstack:bedrock:7)
Block(-8,69,-2,dimstack:bedrock:7)
Block(-8,69,-1,dimstack:bedrock:7)
Block(-8,69,0,dimstack:bedrock:7)
Block(-8,69,1,stone:0)
Block(-8,69,2,stone:0)
Block(-8,69,3,stone:0)
Block(-8,69,4,stone:0)
Block(-8,69,5,stone:0)
Block(-8,69,6,stone:0)
Block(-8,69,7,stone:0)
Block(-8,69,8,dimstack:bedrock:7)
RandomBlock(-8,70,-7,SAND:0,50,BIOMESOPLENTY:DRIED_SAND,100)
RandomBlock(-8,70,-6,SAND:0,50,BIOMESOPLENTY:DRIED_SAND,100)
RandomBlock(-8,70,-5,SAND:0,50,BIOMESOPLENTY:DRIED_SAND,100)
RandomBlock(-8,70,-4,SAND:0,50,BIOMESOPLENTY:DRIED_SAND,100)
RandomBlock(-8,70,-3,SAND:0,50,BIOMESOPLENTY:DRIED_SAND,100)
RandomBlock(-8,70,-2,SAND:0,50,BIOMESOPLENTY:DRIED_SAND,100)
RandomBlock(-8,70,-1,SAND:0,50,BIOMESOPLENTY:DRIED_SAND,100)
RandomBlock(-8,70,0,SAND:0,50,BIOMESOPLENTY:DRIED_SAND,100)
Block(-8,70,1,stone:0)
RandomBlock(-8,70,2,STONEBRICK:1,10,STONEBRICK:2,10,COBBLESTONE,10,MOSSY_COBBLESTONE,10,SMOOTH_BRICK,100)
RandomBlock(-8,70,3,STONEBRICK:1,10,STONEBRICK:2,10,COBBLESTONE,10,MOSSY_COBBLESTONE,10,SMOOTH_BRICK,100)
RandomBlock(-8,70,4,STONEBRICK:1,10,STONEBRICK:2,10,COBBLESTONE,10,MOSSY_COBBLESTONE,10,SMOOTH_BRICK,100)
RandomBlock(-8,70,5,STONEBRICK:1,10,STONEBRICK:2,10,COBBLESTONE,10,MOSSY_COBBLESTONE,10,SMOOTH_BRICK,100)
RandomBlock(-8,70,6,STONEBRICK:1,10,STONEBRICK:2,10,COBBLESTONE,10,MOSSY_COBBLESTONE,10,SMOOTH_BRICK,100)
Block(-8,70,7,stone:0)
Block(-8,70,8,dimstack:bedrock:7)
RandomBlock(-8,71,-6,SAND:0,50,BIOMESOPLENTY:DRIED_SAND,100)
RandomBlock(-8,71,-5,SAND:0,50,BIOMESOPLENTY:DRIED_SAND,100)
RandomBlock(-8,71,-4,SMOOTH_STAIRS:2,50,quark:stonebrick_mossy_stairs:2,100)
RandomBlock(-8,71,-3,SAND:0,50,BIOMESOPLENTY:DRIED_SAND,100)
RandomBlock(-8,71,-2,SAND:0,50,BIOMESOPLENTY:DRIED_SAND,100)
RandomBlock(-8,71,-1,SMOOTH_STAIRS:0,50,quark:stonebrick_mossy_stairs:0,100)
RandomBlock(-8,71,0,SMOOTH_STAIRS:2,50,quark:stonebrick_mossy_stairs:2,100)
RandomBlock(-8,71,1,STONEBRICK:1,10,STONEBRICK:2,10,COBBLESTONE,10,MOSSY_COBBLESTONE,10,SMOOTH_BRICK,100)
RandomBlock(-8,71,2,STONEBRICK:1,10,STONEBRICK:2,10,COBBLESTONE,10,MOSSY_COBBLESTONE,10,SMOOTH_BRICK,100)
RandomBlock(-8,71,3,STONEBRICK:1,10,STONEBRICK:2,10,COBBLESTONE,10,MOSSY_COBBLESTONE,10,SMOOTH_BRICK,100)
RandomBlock(-8,71,4,STONEBRICK:1,10,STONEBRICK:2,10,COBBLESTONE,10,MOSSY_COBBLESTONE,10,SMOOTH_BRICK,100)
RandomBlock(-8,71,5,STONEBRICK:1,10,STONEBRICK:2,10,COBBLESTONE,10,MOSSY_COBBLESTONE,10,SMOOTH_BRICK,100)
RandomBlock(-8,71,6,STONEBRICK:1,10,STONEBRICK:2,10,COBBLESTONE,10,MOSSY_COBBLESTONE,10,SMOOTH_BRICK,100)
RandomBlock(-8,71,7,STONEBRICK:1,10,STONEBRICK:2,10,COBBLESTONE,10,MOSSY_COBBLESTONE,10,SMOOTH_BRICK,100)
RandomBlock(-8,71,8,STONEBRICK:1,10,STONEBRICK:2,10,COBBLESTONE,10,MOSSY_COBBLESTONE,10,SMOOTH_BRICK,100)
RandomBlock(-8,72,1,STONEBRICK:1,10,STONEBRICK:2,10,COBBLESTONE,10,MOSSY_COBBLESTONE,10,SMOOTH_BRICK,100)
RandomBlock(-8,72,2,STONEBRICK:1,10,STONEBRICK:2,10,COBBLESTONE,10,MOSSY_COBBLESTONE,10,SMOOTH_BRICK,100)
RandomBlock(-8,72,3,STONEBRICK:1,10,STONEBRICK:2,10,COBBLESTONE,10,MOSSY_COBBLESTONE,10,SMOOTH_BRICK,100)
RandomBlock(-8,72,6,STEP:5,50,quark:stonebrick_mossy_slab:0,100)
RandomBlock(-8,72,7,STEP:5,50,quark:stonebrick_mossy_slab:0,100)
RandomBlock(-8,72,8,STEP:5,50,quark:stonebrick_mossy_slab:0,100)
RandomBlock(-8,73,2,STEP:5,50,quark:stonebrick_mossy_slab:0,100)
RandomBlock(-8,73,3,STEP:5,50,quark:stonebrick_mossy_slab:0,100)
Block(-7,0,-7,stone:0)
Block(-7,0,-6,stone:0)
Block(-7,0,-5,stone:0)
Block(-7,0,-4,stone:0)
Block(-7,0,-3,stone:0)
Block(-7,0,-2,stone:0)
Block(-7,0,-1,stone:0)
Block(-7,0,0,stone:0)
Block(-7,0,1,stone:0)
Block(-7,0,2,stone:0)
Block(-7,0,3,stone:0)
Block(-7,0,4,stone:0)
Block(-7,0,5,stone:0)
Block(-7,0,6,stone:0)
Block(-7,0,7,stone:0)
Block(-7,0,8,stone:0)
Block(-7,1,-7,stone:0)
Block(-7,1,-6,stone:0)
Block(-7,1,-5,stone:0)
Block(-7,1,-4,stone:0)
Block(-7,1,-3,stone:0)
Block(-7,1,-2,stone:0)
Block(-7,1,-1,stone:0)
Block(-7,1,0,stone:0)
Block(-7,1,1,stone:0)
Block(-7,1,2,stone:0)
Block(-7,1,3,stone:0)
Block(-7,1,4,stone:0)
Block(-7,1,5,stone:0)
Block(-7,1,6,stone:0)
Block(-7,1,7,stone:0)
Block(-7,1,8,stone:0)
Block(-7,2,-7,stone:0)
Block(-7,2,-6,stone:0)
Block(-7,2,-5,stone:0)
Block(-7,2,-4,stone:0)
Block(-7,2,-3,stone:0)
Block(-7,2,-2,stone:0)
Block(-7,2,-1,stone:0)
Block(-7,2,0,stone:0)
Block(-7,2,1,stone:0)
Block(-7,2,2,stone:0)
Block(-7,2,3,stone:0)
Block(-7,2,4,stone:0)
Block(-7,2,5,stone:0)
Block(-7,2,6,stone:0)
Block(-7,2,7,stone:0)
Block(-7,2,8,stone:0)
Block(-7,3,-7,stone:0)
Block(-7,3,-6,stone:0)
Block(-7,3,-5,stone:0)
Block(-7,3,-4,stone:0)
Block(-7,3,-3,stone:0)
Block(-7,3,-2,stone:0)
Block(-7,3,-1,stone:0)
Block(-7,3,0,stone:0)
Block(-7,3,1,stone:0)
Block(-7,3,2,stone:0)
Block(-7,3,3,stone:0)
Block(-7,3,4,stone:0)
Block(-7,3,5,stone:0)
Block(-7,3,6,stone:0)
Block(-7,3,7,stone:0)
Block(-7,3,8,stone:0)
Block(-7,4,-7,stone:0)
Block(-7,4,-6,stone:0)
Block(-7,4,-5,stone:0)
Block(-7,4,-4,stone:0)
Block(-7,4,-3,stone:0)
Block(-7,4,-2,stone:0)
Block(-7,4,-1,stone:0)
Block(-7,4,0,stone:0)
Block(-7,4,1,stone:0)
Block(-7,4,2,stone:0)
Block(-7,4,3,stone:0)
Block(-7,4,4,stone:0)
Block(-7,4,5,stone:0)
Block(-7,4,6,stone:0)
Block(-7,4,7,stone:0)
Block(-7,4,8,stone:0)
Block(-7,5,-7,stone:0)
Block(-7,5,-6,stone:0)
Block(-7,5,-5,stone:0)
Block(-7,5,-4,stone:0)
Block(-7,5,-3,stone:0)
Block(-7,5,-2,stone:0)
Block(-7,5,-1,stone:0)
Block(-7,5,0,stone:0)
Block(-7,5,1,stone:0)
Block(-7,5,2,stone:0)
Block(-7,5,3,stone:0)
Block(-7,5,4,stone:0)
Block(-7,5,5,stone:0)
Block(-7,5,6,stone:0)
Block(-7,5,7,stone:0)
Block(-7,5,8,stone:0)
Block(-7,6,-7,stone:0)
Block(-7,6,-6,stone:0)
Block(-7,6,-5,stone:0)
Block(-7,6,-4,stone:0)
Block(-7,6,-3,stone:0)
Block(-7,6,-2,stone:0)
Block(-7,6,-1,stone:0)
Block(-7,6,0,stone:0)
Block(-7,6,1,stone:0)
Block(-7,6,2,stone:0)
Block(-7,6,3,stone:0)
Block(-7,6,4,stone:0)
Block(-7,6,5,stone:0)
Block(-7,6,6,stone:0)
Block(-7,6,7,stone:0)
Block(-7,6,8,stone:0)
Block(-7,7,-7,stone:0)
Block(-7,7,-6,stone:0)
Block(-7,7,-5,stone:0)
Block(-7,7,-4,stone:0)
Block(-7,7,-3,stone:0)
Block(-7,7,-2,stone:0)
Block(-7,7,-1,stone:0)
Block(-7,7,0,stone:0)
Block(-7,7,1,stone:0)
Block(-7,7,2,stone:0)
Block(-7,7,3,stone:0)
Block(-7,7,4,stone:0)
Block(-7,7,5,stone:0)
Block(-7,7,6,stone:0)
Block(-7,7,7,stone:0)
Block(-7,7,8,stone:0)
Block(-7,8,-7,stone:0)
Block(-7,8,-6,stone:0)
Block(-7,8,-5,stone:0)
Block(-7,8,-4,stone:0)
Block(-7,8,-3,stone:0)
Block(-7,8,-2,stone:0)
Block(-7,8,-1,stone:0)
Block(-7,8,0,stone:0)
Block(-7,8,1,stone:0)
Block(-7,8,2,stone:0)
Block(-7,8,3,stone:0)
Block(-7,8,4,stone:0)
Block(-7,8,5,stone:0)
Block(-7,8,6,stone:0)
Block(-7,8,7,stone:0)
Block(-7,8,8,stone:0)
Block(-7,9,-7,stone:0)
Block(-7,9,-6,stone:0)
Block(-7,9,-5,stone:0)
Block(-7,9,-4,stone:0)
Block(-7,9,-3,stone:0)
Block(-7,9,-2,stone:0)
Block(-7,9,-1,stone:0)
Block(-7,9,0,stone:0)
Block(-7,9,1,stone:0)
Block(-7,9,2,stone:0)
Block(-7,9,3,stone:0)
Block(-7,9,4,stone:0)
Block(-7,9,5,stone:0)
Block(-7,9,6,stone:0)
Block(-7,9,7,stone:0)
Block(-7,9,8,stone:0)
Block(-7,10,-7,stone:0)
Block(-7,10,-6,stone:0)
Block(-7,10,-5,stone:0)
Block(-7,10,-4,stone:0)
Block(-7,10,-3,stone:0)
Block(-7,10,-2,stone:0)
Block(-7,10,-1,stone:0)
Block(-7,10,0,stone:0)
Block(-7,10,1,stone:0)
Block(-7,10,2,stone:0)
Block(-7,10,3,stone:0)
Block(-7,10,4,stone:0)
Block(-7,10,5,stone:0)
Block(-7,10,6,stone:0)
Block(-7,10,7,stone:0)
Block(-7,10,8,stone:0)
Block(-7,11,-7,stone:0)
Block(-7,11,-6,stone:0)
Block(-7,11,-5,stone:0)
Block(-7,11,-4,stone:0)
Block(-7,11,-3,stone:0)
Block(-7,11,-2,stone:0)
Block(-7,11,-1,stone:0)
Block(-7,11,0,stone:0)
Block(-7,11,1,stone:0)
Block(-7,11,2,stone:0)
Block(-7,11,3,stone:0)
Block(-7,11,4,stone:0)
Block(-7,11,5,stone:0)
Block(-7,11,6,stone:0)
Block(-7,11,7,stone:0)
Block(-7,11,8,stone:0)
Block(-7,12,-7,stone:0)
Block(-7,12,-6,stone:0)
Block(-7,12,-5,stone:0)
Block(-7,12,-4,stone:0)
Block(-7,12,-3,stone:0)
Block(-7,12,-2,stone:0)
Block(-7,12,-1,stone:0)
Block(-7,12,0,stone:0)
Block(-7,12,1,stone:0)
Block(-7,12,2,stone:0)
Block(-7,12,3,stone:0)
Block(-7,12,4,stone:0)
Block(-7,12,5,stone:0)
Block(-7,12,6,stone:0)
Block(-7,12,7,stone:0)
Block(-7,12,8,stone:0)
Block(-7,13,-7,stone:0)
Block(-7,13,-6,stone:0)
Block(-7,13,-5,stone:0)
Block(-7,13,-4,stone:0)
Block(-7,13,-3,stone:0)
Block(-7,13,-2,stone:0)
Block(-7,13,-1,stone:0)
Block(-7,13,0,stone:0)
Block(-7,13,1,stone:0)
Block(-7,13,2,stone:0)
Block(-7,13,3,stone:0)
Block(-7,13,4,stone:0)
Block(-7,13,5,stone:0)
Block(-7,13,6,stone:0)
Block(-7,13,7,stone:0)
Block(-7,13,8,stone:0)
Block(-7,14,-7,stone:0)
Block(-7,14,-6,stone:0)
Block(-7,14,-5,stone:0)
Block(-7,14,-4,stone:0)
Block(-7,14,-3,stone:0)
Block(-7,14,-2,stone:0)
Block(-7,14,-1,stone:0)
Block(-7,14,0,stone:0)
Block(-7,14,1,stone:0)
Block(-7,14,2,stone:0)
Block(-7,14,3,stone:0)
Block(-7,14,4,stone:0)
Block(-7,14,5,stone:0)
Block(-7,14,6,stone:0)
Block(-7,14,7,stone:0)
Block(-7,14,8,stone:0)
Block(-7,15,-7,stone:0)
Block(-7,15,-6,stone:0)
Block(-7,15,-5,stone:0)
Block(-7,15,-4,stone:0)
Block(-7,15,-3,stone:0)
Block(-7,15,-2,stone:0)
Block(-7,15,-1,stone:0)
Block(-7,15,0,stone:0)
Block(-7,15,1,stone:0)
Block(-7,15,2,stone:0)
Block(-7,15,3,stone:0)
Block(-7,15,4,stone:0)
Block(-7,15,5,stone:0)
Block(-7,15,6,stone:0)
Block(-7,15,7,stone:0)
Block(-7,15,8,stone:0)
Block(-7,16,-7,stone:0)
Block(-7,16,-6,stone:0)
Block(-7,16,-5,stone:0)
Block(-7,16,-4,stone:0)
Block(-7,16,-3,stone:0)
Block(-7,16,-2,stone:0)
Block(-7,16,-1,stone:0)
Block(-7,16,0,stone:0)
Block(-7,16,1,stone:0)
Block(-7,16,2,stone:0)
Block(-7,16,3,stone:0)
Block(-7,16,4,stone:0)
Block(-7,16,5,stone:0)
Block(-7,16,6,stone:0)
Block(-7,16,7,stone:0)
Block(-7,16,8,stone:0)
Block(-7,17,-7,stone:0)
Block(-7,17,-6,stone:0)
Block(-7,17,-5,stone:0)
Block(-7,17,-4,stone:0)
Block(-7,17,-3,stone:0)
Block(-7,17,-2,stone:0)
Block(-7,17,-1,stone:0)
Block(-7,17,0,stone:0)
Block(-7,17,1,stone:0)
Block(-7,17,2,stone:0)
Block(-7,17,3,stone:0)
Block(-7,17,4,stone:0)
Block(-7,17,5,stone:0)
Block(-7,17,6,stone:0)
Block(-7,17,7,stone:0)
Block(-7,17,8,stone:0)
Block(-7,18,-7,stone:0)
Block(-7,18,-6,stone:0)
Block(-7,18,-5,stone:0)
Block(-7,18,-4,stone:0)
Block(-7,18,-3,stone:0)
Block(-7,18,-2,stone:0)
Block(-7,18,-1,stone:0)
Block(-7,18,0,stone:0)
Block(-7,18,1,stone:0)
Block(-7,18,2,stone:0)
Block(-7,18,3,stone:0)
Block(-7,18,4,stone:0)
Block(-7,18,5,stone:0)
Block(-7,18,6,stone:0)
Block(-7,18,7,stone:0)
Block(-7,18,8,stone:0)
Block(-7,19,-7,stone:0)
Block(-7,19,-6,stone:0)
Block(-7,19,-5,stone:0)
Block(-7,19,-4,stone:0)
Block(-7,19,-3,stone:0)
Block(-7,19,-2,stone:0)
Block(-7,19,-1,stone:0)
Block(-7,19,0,stone:0)
Block(-7,19,1,stone:0)
Block(-7,19,2,stone:0)
Block(-7,19,3,stone:0)
Block(-7,19,4,stone:0)
Block(-7,19,5,stone:0)
Block(-7,19,6,stone:0)
Block(-7,19,7,stone:0)
Block(-7,19,8,stone:0)
Block(-7,20,-7,stone:0)
Block(-7,20,-6,stone:0)
Block(-7,20,-5,stone:0)
Block(-7,20,-4,stone:0)
Block(-7,20,-3,stone:0)
Block(-7,20,-2,stone:0)
Block(-7,20,-1,stone:0)
Block(-7,20,0,stone:0)
Block(-7,20,1,stone:0)
Block(-7,20,2,stone:0)
Block(-7,20,3,stone:0)
Block(-7,20,4,stone:0)
Block(-7,20,5,stone:0)
Block(-7,20,6,stone:0)
Block(-7,20,7,stone:0)
Block(-7,20,8,stone:0)
Block(-7,21,-7,stone:0)
Block(-7,21,-6,stone:0)
Block(-7,21,-5,stone:0)
Block(-7,21,-4,stone:0)
Block(-7,21,-3,stone:0)
Block(-7,21,-2,stone:0)
Block(-7,21,-1,stone:0)
Block(-7,21,0,stone:0)
Block(-7,21,1,stone:0)
Block(-7,21,2,stone:0)
Block(-7,21,3,stone:0)
Block(-7,21,4,stone:0)
Block(-7,21,5,stone:0)
Block(-7,21,6,stone:0)
Block(-7,21,7,stone:0)
Block(-7,21,8,stone:0)
Block(-7,22,-7,stone:0)
Block(-7,22,-6,stone:0)
Block(-7,22,-5,stone:0)
Block(-7,22,-4,stone:0)
Block(-7,22,-3,stone:0)
Block(-7,22,-2,stone:0)
Block(-7,22,-1,stone:0)
Block(-7,22,0,stone:0)
Block(-7,22,1,stone:0)
Block(-7,22,2,stone:0)
Block(-7,22,3,stone:0)
Block(-7,22,4,stone:0)
Block(-7,22,5,stone:0)
Block(-7,22,6,stone:0)
Block(-7,22,7,stone:0)
Block(-7,22,8,stone:0)
Block(-7,23,-7,stone:0)
Block(-7,23,-6,stone:0)
Block(-7,23,-5,stone:0)
Block(-7,23,-4,stone:0)
Block(-7,23,-3,stone:0)
Block(-7,23,-2,stone:0)
Block(-7,23,-1,stone:0)
Block(-7,23,0,stone:0)
Block(-7,23,1,stone:0)
Block(-7,23,2,stone:0)
Block(-7,23,3,stone:0)
Block(-7,23,4,stone:0)
Block(-7,23,5,stone:0)
Block(-7,23,6,stone:0)
Block(-7,23,7,stone:0)
Block(-7,23,8,stone:0)
Block(-7,24,-7,stone:0)
Block(-7,24,-6,stone:0)
Block(-7,24,-5,stone:0)
Block(-7,24,-4,stone:0)
Block(-7,24,-3,stone:0)
Block(-7,24,-2,stone:0)
Block(-7,24,-1,stone:0)
Block(-7,24,0,stone:0)
Block(-7,24,1,stone:0)
Block(-7,24,2,stone:0)
Block(-7,24,3,stone:0)
Block(-7,24,4,stone:0)
Block(-7,24,5,stone:0)
Block(-7,24,6,stone:0)
Block(-7,24,7,stone:0)
Block(-7,24,8,stone:0)
Block(-7,25,-7,stone:0)
Block(-7,25,-6,stone:0)
Block(-7,25,-5,stone:0)
Block(-7,25,-4,stone:0)
Block(-7,25,-3,stone:0)
Block(-7,25,-2,stone:0)
Block(-7,25,-1,stone:0)
Block(-7,25,0,stone:0)
Block(-7,25,1,stone:0)
Block(-7,25,2,stone:0)
Block(-7,25,3,stone:0)
Block(-7,25,4,stone:0)
Block(-7,25,5,stone:0)
Block(-7,25,6,stone:0)
Block(-7,25,7,stone:0)
Block(-7,25,8,stone:0)
Block(-7,26,-7,stone:0)
Block(-7,26,-6,stone:0)
Block(-7,26,-5,stone:0)
Block(-7,26,-4,stone:0)
Block(-7,26,-3,stone:0)
Block(-7,26,-2,stone:0)
Block(-7,26,-1,stone:0)
Block(-7,26,0,stone:0)
Block(-7,26,1,stone:0)
Block(-7,26,2,stone:0)
Block(-7,26,3,stone:0)
Block(-7,26,4,stone:0)
Block(-7,26,5,stone:0)
Block(-7,26,6,stone:0)
Block(-7,26,7,stone:0)
Block(-7,26,8,stone:0)
Block(-7,27,-7,stone:0)
Block(-7,27,-6,stone:0)
Block(-7,27,-5,stone:0)
Block(-7,27,-4,stone:0)
Block(-7,27,-3,stone:0)
Block(-7,27,-2,stone:0)
Block(-7,27,-1,stone:0)
Block(-7,27,0,stone:0)
Block(-7,27,1,stone:0)
Block(-7,27,2,stone:0)
Block(-7,27,3,stone:0)
Block(-7,27,4,stone:0)
Block(-7,27,5,stone:0)
Block(-7,27,6,stone:0)
Block(-7,27,7,stone:0)
Block(-7,27,8,stone:0)
Block(-7,28,-7,stone:0)
Block(-7,28,-6,stone:0)
Block(-7,28,-5,stone:0)
Block(-7,28,-4,stone:0)
Block(-7,28,-3,stone:0)
Block(-7,28,-2,stone:0)
Block(-7,28,-1,stone:0)
Block(-7,28,0,stone:0)
Block(-7,28,1,stone:0)
Block(-7,28,2,stone:0)
Block(-7,28,3,stone:0)
Block(-7,28,4,stone:0)
Block(-7,28,5,stone:0)
Block(-7,28,6,stone:0)
Block(-7,28,7,stone:0)
Block(-7,28,8,stone:0)
Block(-7,29,-7,stone:0)
Block(-7,29,-6,stone:0)
Block(-7,29,-5,stone:0)
Block(-7,29,-4,stone:0)
Block(-7,29,-3,stone:0)
Block(-7,29,-2,stone:0)
Block(-7,29,-1,stone:0)
Block(-7,29,0,stone:0)
Block(-7,29,1,stone:0)
Block(-7,29,2,stone:0)
Block(-7,29,3,stone:0)
Block(-7,29,4,stone:0)
Block(-7,29,5,stone:0)
Block(-7,29,6,stone:0)
Block(-7,29,7,stone:0)
Block(-7,29,8,stone:0)
Block(-7,30,-7,stone:0)
Block(-7,30,-6,stone:0)
Block(-7,30,-5,stone:0)
Block(-7,30,-4,stone:0)
Block(-7,30,-3,stone:0)
Block(-7,30,-2,stone:0)
Block(-7,30,-1,stone:0)
Block(-7,30,0,stone:0)
Block(-7,30,1,stone:0)
Block(-7,30,2,stone:0)
Block(-7,30,3,stone:0)
Block(-7,30,4,stone:0)
Block(-7,30,5,stone:0)
Block(-7,30,6,stone:0)
Block(-7,30,7,stone:0)
Block(-7,30,8,stone:0)
Block(-7,31,-7,stone:0)
Block(-7,31,-6,stone:0)
Block(-7,31,-5,stone:0)
Block(-7,31,-4,stone:0)
Block(-7,31,-3,stone:0)
Block(-7,31,-2,stone:0)
Block(-7,31,-1,stone:0)
Block(-7,31,0,stone:0)
Block(-7,31,1,stone:0)
Block(-7,31,2,stone:0)
Block(-7,31,3,stone:0)
Block(-7,31,4,stone:0)
Block(-7,31,5,stone:0)
Block(-7,31,6,stone:0)
Block(-7,31,7,stone:0)
Block(-7,31,8,stone:0)
Block(-7,32,-7,stone:0)
Block(-7,32,-6,stone:0)
Block(-7,32,-5,stone:0)
Block(-7,32,-4,stone:0)
Block(-7,32,-3,stone:0)
Block(-7,32,-2,stone:0)
Block(-7,32,-1,stone:0)
Block(-7,32,0,stone:0)
Block(-7,32,1,stone:0)
Block(-7,32,2,stone:0)
Block(-7,32,3,stone:0)
Block(-7,32,4,stone:0)
Block(-7,32,5,stone:0)
Block(-7,32,6,stone:0)
Block(-7,32,7,stone:0)
Block(-7,32,8,stone:0)
Block(-7,33,-7,stone:0)
Block(-7,33,-6,stone:0)
Block(-7,33,-5,stone:0)
Block(-7,33,-4,stone:0)
Block(-7,33,-3,stone:0)
Block(-7,33,-2,stone:0)
Block(-7,33,-1,stone:0)
Block(-7,33,0,stone:0)
Block(-7,33,1,stone:0)
Block(-7,33,2,stone:0)
Block(-7,33,3,stone:0)
Block(-7,33,4,stone:0)
Block(-7,33,5,stone:0)
Block(-7,33,6,stone:0)
Block(-7,33,7,stone:0)
Block(-7,33,8,stone:0)
Block(-7,34,-7,stone:0)
Block(-7,34,-6,stone:0)
Block(-7,34,-5,stone:0)
Block(-7,34,-4,stone:0)
Block(-7,34,-3,stone:0)
Block(-7,34,-2,stone:0)
Block(-7,34,-1,stone:0)
Block(-7,34,0,stone:0)
Block(-7,34,1,stone:0)
Block(-7,34,2,stone:0)
Block(-7,34,3,stone:0)
Block(-7,34,4,stone:0)
Block(-7,34,5,stone:0)
Block(-7,34,6,stone:0)
Block(-7,34,7,stone:0)
Block(-7,34,8,stone:0)
Block(-7,35,-7,stone:0)
Block(-7,35,-6,stone:0)
Block(-7,35,-5,stone:0)
Block(-7,35,-4,stone:0)
Block(-7,35,-3,stone:0)
Block(-7,35,-2,stone:0)
Block(-7,35,-1,stone:0)
Block(-7,35,0,stone:0)
Block(-7,35,1,stone:0)
Block(-7,35,2,stone:0)
Block(-7,35,3,stone:0)
Block(-7,35,4,stone:0)
Block(-7,35,5,stone:0)
Block(-7,35,6,stone:0)
Block(-7,35,7,stone:0)
Block(-7,35,8,stone:0)
Block(-7,36,-7,stone:0)
Block(-7,36,-6,stone:0)
Block(-7,36,-5,stone:0)
Block(-7,36,-4,stone:0)
Block(-7,36,-3,stone:0)
Block(-7,36,-2,stone:0)
Block(-7,36,-1,stone:0)
Block(-7,36,0,stone:0)
Block(-7,36,1,stone:0)
Block(-7,36,2,stone:0)
Block(-7,36,3,stone:0)
Block(-7,36,4,stone:0)
Block(-7,36,5,stone:0)
Block(-7,36,6,stone:0)
Block(-7,36,7,stone:0)
Block(-7,36,8,stone:0)
Block(-7,37,-7,stone:0)
Block(-7,37,-6,stone:0)
Block(-7,37,-5,stone:0)
Block(-7,37,-4,stone:0)
Block(-7,37,-3,stone:0)
Block(-7,37,-2,stone:0)
Block(-7,37,-1,stone:0)
Block(-7,37,0,stone:0)
Block(-7,37,1,stone:0)
Block(-7,37,2,stone:0)
Block(-7,37,3,stone:0)
Block(-7,37,4,stone:0)
Block(-7,37,5,stone:0)
Block(-7,37,6,stone:0)
Block(-7,37,7,stone:0)
Block(-7,37,8,stone:0)
Block(-7,38,-7,stone:0)
Block(-7,38,-6,stone:0)
Block(-7,38,-5,stone:0)
Block(-7,38,-4,stone:0)
Block(-7,38,-3,stone:0)
Block(-7,38,-2,stone:0)
Block(-7,38,-1,stone:0)
Block(-7,38,0,stone:0)
Block(-7,38,1,stone:0)
Block(-7,38,2,stone:0)
Block(-7,38,3,stone:0)
Block(-7,38,4,stone:0)
Block(-7,38,5,stone:0)
Block(-7,38,6,stone:0)
Block(-7,38,7,stone:0)
Block(-7,38,8,stone:0)
Block(-7,39,-7,stone:0)
Block(-7,39,-6,stone:0)
Block(-7,39,-5,stone:0)
Block(-7,39,-4,stone:0)
Block(-7,39,-3,stone:0)
Block(-7,39,-2,stone:0)
Block(-7,39,-1,stone:0)
Block(-7,39,0,stone:0)
Block(-7,39,1,stone:0)
Block(-7,39,2,stone:0)
Block(-7,39,3,stone:0)
Block(-7,39,4,stone:0)
Block(-7,39,5,stone:0)
Block(-7,39,6,stone:0)
Block(-7,39,7,stone:0)
Block(-7,39,8,stone:0)
Block(-7,40,-7,stone:0)
Block(-7,40,-6,stone:0)
Block(-7,40,-5,stone:0)
Block(-7,40,-4,stone:0)
Block(-7,40,-3,stone:0)
Block(-7,40,-2,stone:0)
Block(-7,40,-1,stone:0)
Block(-7,40,0,stone:0)
Block(-7,40,1,stone:0)
Block(-7,40,2,stone:0)
Block(-7,40,3,stone:0)
Block(-7,40,4,stone:0)
Block(-7,40,5,stone:0)
Block(-7,40,6,stone:0)
Block(-7,40,7,stone:0)
Block(-7,40,8,stone:0)
Block(-7,41,-7,stone:0)
Block(-7,41,-6,stone:0)
Block(-7,41,-5,stone:0)
Block(-7,41,-4,stone:0)
Block(-7,41,-3,stone:0)
Block(-7,41,-2,stone:0)
Block(-7,41,-1,stone:0)
Block(-7,41,0,stone:0)
Block(-7,41,1,stone:0)
Block(-7,41,2,stone:0)
Block(-7,41,3,stone:0)
Block(-7,41,4,stone:0)
Block(-7,41,5,stone:0)
Block(-7,41,6,stone:0)
Block(-7,41,7,stone:0)
Block(-7,41,8,stone:0)
Block(-7,42,-7,stone:0)
Block(-7,42,-6,stone:0)
Block(-7,42,-5,stone:0)
Block(-7,42,-4,stone:0)
Block(-7,42,-3,stone:0)
Block(-7,42,-2,stone:0)
Block(-7,42,-1,stone:0)
Block(-7,42,0,stone:0)
Block(-7,42,1,stone:0)
Block(-7,42,2,stone:0)
Block(-7,42,3,stone:0)
Block(-7,42,4,stone:0)
Block(-7,42,5,stone:0)
Block(-7,42,6,stone:0)
Block(-7,42,7,stone:0)
Block(-7,42,8,stone:0)
Block(-7,43,-7,stone:0)
Block(-7,43,-6,stone:0)
Block(-7,43,-5,stone:0)
Block(-7,43,-4,stone:0)
Block(-7,43,-3,stone:0)
Block(-7,43,-2,stone:0)
Block(-7,43,-1,stone:0)
Block(-7,43,0,stone:0)
Block(-7,43,1,stone:0)
Block(-7,43,2,stone:0)
Block(-7,43,3,stone:0)
Block(-7,43,4,stone:0)
Block(-7,43,5,stone:0)
Block(-7,43,6,stone:0)
Block(-7,43,7,stone:0)
Block(-7,43,8,stone:0)
Block(-7,44,-7,stone:0)
Block(-7,44,-6,stone:0)
Block(-7,44,-5,stone:0)
Block(-7,44,-4,stone:0)
Block(-7,44,-3,stone:0)
Block(-7,44,-2,stone:0)
Block(-7,44,-1,stone:0)
Block(-7,44,0,stone:0)
Block(-7,44,1,stone:0)
Block(-7,44,2,stone:0)
Block(-7,44,3,stone:0)
Block(-7,44,4,stone:0)
Block(-7,44,5,stone:0)
Block(-7,44,6,stone:0)
Block(-7,44,7,stone:0)
Block(-7,44,8,stone:0)
Block(-7,45,-7,stone:0)
Block(-7,45,-6,stone:0)
Block(-7,45,-5,stone:0)
Block(-7,45,-4,stone:0)
Block(-7,45,-3,stone:0)
Block(-7,45,-2,stone:0)
Block(-7,45,-1,stone:0)
Block(-7,45,0,stone:0)
Block(-7,45,1,stone:0)
Block(-7,45,2,stone:0)
Block(-7,45,3,stone:0)
Block(-7,45,4,stone:0)
Block(-7,45,5,stone:0)
Block(-7,45,6,stone:0)
Block(-7,45,7,stone:0)
Block(-7,45,8,stone:0)
Block(-7,46,-7,stone:0)
Block(-7,46,-6,stone:0)
Block(-7,46,-5,stone:0)
Block(-7,46,-4,stone:0)
Block(-7,46,-3,stone:0)
Block(-7,46,-2,stone:0)
Block(-7,46,-1,stone:0)
Block(-7,46,0,stone:0)
Block(-7,46,1,stone:0)
Block(-7,46,2,stone:0)
Block(-7,46,3,stone:0)
Block(-7,46,4,stone:0)
Block(-7,46,5,stone:0)
Block(-7,46,6,stone:0)
Block(-7,46,7,stone:0)
Block(-7,46,8,stone:0)
Block(-7,47,-7,stone:0)
Block(-7,47,-6,stone:0)
Block(-7,47,-5,stone:0)
Block(-7,47,-4,stone:0)
Block(-7,47,-3,stone:0)
Block(-7,47,-2,stone:0)
Block(-7,47,-1,stone:0)
Block(-7,47,0,stone:0)
Block(-7,47,1,stone:0)
Block(-7,47,2,stone:0)
Block(-7,47,3,stone:0)
Block(-7,47,4,stone:0)
Block(-7,47,5,stone:0)
Block(-7,47,6,stone:0)
Block(-7,47,7,stone:0)
Block(-7,47,8,stone:0)
Block(-7,48,-7,stone:0)
Block(-7,48,-6,stone:0)
Block(-7,48,-5,stone:0)
Block(-7,48,-4,stone:0)
Block(-7,48,-3,stone:0)
Block(-7,48,-2,stone:0)
Block(-7,48,-1,stone:0)
Block(-7,48,0,stone:0)
Block(-7,48,1,stone:0)
Block(-7,48,2,stone:0)
Block(-7,48,3,stone:0)
Block(-7,48,4,stone:0)
Block(-7,48,5,stone:0)
Block(-7,48,6,stone:0)
Block(-7,48,7,stone:0)
Block(-7,48,8,stone:0)
Block(-7,49,-7,stone:0)
Block(-7,49,-6,stone:0)
Block(-7,49,-5,stone:0)
Block(-7,49,-4,stone:0)
Block(-7,49,-3,stone:0)
Block(-7,49,-2,stone:0)
Block(-7,49,-1,stone:0)
Block(-7,49,0,stone:0)
Block(-7,49,1,stone:0)
Block(-7,49,2,stone:0)
Block(-7,49,3,stone:0)
Block(-7,49,4,stone:0)
Block(-7,49,5,stone:0)
Block(-7,49,6,stone:0)
Block(-7,49,7,stone:0)
Block(-7,49,8,stone:0)
Block(-7,50,-7,stone:0)
Block(-7,50,-6,stone:0)
Block(-7,50,-5,stone:0)
Block(-7,50,-4,stone:0)
Block(-7,50,-3,stone:0)
Block(-7,50,-2,stone:0)
Block(-7,50,-1,stone:0)
Block(-7,50,0,stone:0)
Block(-7,50,1,stone:0)
Block(-7,50,2,stone:0)
Block(-7,50,3,stone:0)
Block(-7,50,4,stone:0)
Block(-7,50,5,stone:0)
Block(-7,50,6,stone:0)
Block(-7,50,7,stone:0)
Block(-7,50,8,stone:0)
Block(-7,51,-7,stone:0)
Block(-7,51,-6,stone:0)
Block(-7,51,-5,stone:0)
Block(-7,51,-4,stone:0)
Block(-7,51,-3,stone:0)
Block(-7,51,-2,stone:0)
Block(-7,51,-1,stone:0)
Block(-7,51,0,stone:0)
Block(-7,51,1,stone:0)
Block(-7,51,2,stone:0)
Block(-7,51,3,stone:0)
Block(-7,51,4,stone:0)
Block(-7,51,5,stone:0)
Block(-7,51,6,stone:0)
Block(-7,51,7,stone:0)
Block(-7,51,8,stone:0)
Block(-7,52,-7,stone:0)
Block(-7,52,-6,stone:0)
Block(-7,52,-5,stone:0)
Block(-7,52,-4,stone:0)
Block(-7,52,-3,stone:0)
Block(-7,52,-2,stone:0)
Block(-7,52,-1,stone:0)
Block(-7,52,0,stone:0)
Block(-7,52,1,stone:0)
Block(-7,52,2,stone:0)
Block(-7,52,3,stone:0)
Block(-7,52,4,stone:0)
Block(-7,52,5,stone:0)
Block(-7,52,6,stone:0)
Block(-7,52,7,stone:0)
Block(-7,52,8,stone:0)
Block(-7,53,-7,stone:0)
Block(-7,53,-6,stone:0)
Block(-7,53,-5,stone:0)
Block(-7,53,-4,stone:0)
Block(-7,53,-3,stone:0)
Block(-7,53,-2,stone:0)
Block(-7,53,-1,stone:0)
Block(-7,53,0,stone:0)
Block(-7,53,1,stone:0)
Block(-7,53,2,stone:0)
Block(-7,53,3,stone:0)
Block(-7,53,4,stone:0)
Block(-7,53,5,stone:0)
Block(-7,53,6,stone:0)
Block(-7,53,7,stone:0)
Block(-7,53,8,stone:0)
Block(-7,54,-7,stone:0)
Block(-7,54,-6,stone:0)
Block(-7,54,-5,stone:0)
Block(-7,54,-4,stone:0)
Block(-7,54,-3,stone:0)
Block(-7,54,-2,stone:0)
Block(-7,54,-1,stone:0)
Block(-7,54,0,stone:0)
Block(-7,54,1,stone:0)
Block(-7,54,2,stone:0)
Block(-7,54,3,stone:0)
Block(-7,54,4,stone:0)
Block(-7,54,5,stone:0)
Block(-7,54,6,stone:0)
Block(-7,54,7,stone:0)
Block(-7,54,8,stone:0)
Block(-7,55,-7,stone:0)
Block(-7,55,-6,stone:0)
Block(-7,55,-5,stone:0)
Block(-7,55,-4,stone:0)
Block(-7,55,-3,stone:0)
Block(-7,55,-2,stone:0)
Block(-7,55,-1,stone:0)
Block(-7,55,0,stone:0)
Block(-7,55,1,stone:0)
Block(-7,55,2,stone:0)
Block(-7,55,3,stone:0)
Block(-7,55,4,stone:0)
Block(-7,55,5,stone:0)
Block(-7,55,6,stone:0)
Block(-7,55,7,stone:0)
Block(-7,55,8,stone:0)
Block(-7,56,-7,stone:0)
Block(-7,56,-6,stone:0)
Block(-7,56,-5,stone:0)
Block(-7,56,-4,stone:0)
Block(-7,56,-3,stone:0)
Block(-7,56,-2,stone:0)
Block(-7,56,-1,stone:0)
Block(-7,56,0,stone:0)
Block(-7,56,1,stone:0)
Block(-7,56,2,stone:0)
Block(-7,56,3,stone:0)
Block(-7,56,4,stone:0)
Block(-7,56,5,stone:0)
Block(-7,56,6,stone:0)
Block(-7,56,7,stone:0)
Block(-7,56,8,stone:0)
Block(-7,57,-7,stone:0)
Block(-7,57,-6,stone:0)
Block(-7,57,-5,stone:0)
Block(-7,57,-4,stone:0)
Block(-7,57,-3,stone:0)
Block(-7,57,-2,stone:0)
Block(-7,57,-1,stone:0)
Block(-7,57,0,stone:0)
Block(-7,57,1,stone:0)
Block(-7,57,2,stone:0)
Block(-7,57,3,stone:0)
Block(-7,57,4,stone:0)
Block(-7,57,5,stone:0)
Block(-7,57,6,stone:0)
Block(-7,57,7,stone:0)
Block(-7,57,8,stone:0)
Block(-7,58,-7,stone:0)
Block(-7,58,-6,stone:0)
Block(-7,58,-5,stone:0)
Block(-7,58,-4,stone:0)
Block(-7,58,-3,stone:0)
Block(-7,58,-2,stone:0)
Block(-7,58,-1,stone:0)
Block(-7,58,0,stone:0)
Block(-7,58,1,stone:0)
Block(-7,58,2,stone:0)
Block(-7,58,3,stone:0)
Block(-7,58,4,stone:0)
Block(-7,58,5,stone:0)
Block(-7,58,6,stone:0)
Block(-7,58,7,stone:0)
Block(-7,58,8,stone:0)
Block(-7,59,-7,stone:0)
Block(-7,59,-6,stone:0)
Block(-7,59,-5,stone:0)
Block(-7,59,-4,stone:0)
Block(-7,59,-3,stone:0)
Block(-7,59,-2,stone:0)
Block(-7,59,-1,stone:0)
Block(-7,59,0,stone:0)
Block(-7,59,1,stone:0)
Block(-7,59,2,stone:0)
Block(-7,59,3,stone:0)
Block(-7,59,4,stone:0)
Block(-7,59,5,stone:0)
Block(-7,59,6,stone:0)
Block(-7,59,7,stone:0)
Block(-7,59,8,stone:0)
Block(-7,60,-7,stone:0)
Block(-7,60,-6,stone:0)
Block(-7,60,-5,stone:0)
Block(-7,60,-4,stone:0)
Block(-7,60,-3,stone:0)
Block(-7,60,-2,stone:0)
Block(-7,60,-1,stone:0)
Block(-7,60,0,stone:0)
Block(-7,60,1,stone:0)
Block(-7,60,2,stone:0)
Block(-7,60,3,stone:0)
Block(-7,60,4,stone:0)
Block(-7,60,5,stone:0)
Block(-7,60,6,stone:0)
Block(-7,60,7,stone:0)
Block(-7,60,8,stone:0)
Block(-7,61,-7,stone:0)
Block(-7,61,-6,stone:0)
Block(-7,61,-5,stone:0)
Block(-7,61,-4,stone:0)
Block(-7,61,-3,stone:0)
Block(-7,61,-2,stone:0)
Block(-7,61,-1,stone:0)
Block(-7,61,0,stone:0)
Block(-7,61,1,stone:0)
Block(-7,61,2,stone:0)
Block(-7,61,3,stone:0)
Block(-7,61,4,stone:0)
Block(-7,61,5,stone:0)
Block(-7,61,6,stone:0)
Block(-7,61,7,stone:0)
Block(-7,61,8,stone:0)
Block(-7,62,-7,stone:0)
Block(-7,62,-6,stone:0)
Block(-7,62,-5,stone:0)
Block(-7,62,-4,stone:0)
Block(-7,62,-3,stone:0)
Block(-7,62,-2,stone:0)
Block(-7,62,-1,stone:0)
Block(-7,62,0,stone:0)
Block(-7,62,1,stone:0)
Block(-7,62,2,stone:0)
Block(-7,62,3,stone:0)
Block(-7,62,4,stone:0)
Block(-7,62,5,stone:0)
Block(-7,62,6,stone:0)
Block(-7,62,7,stone:0)
Block(-7,62,8,stone:0)
Block(-7,63,-7,stone:0)
Block(-7,63,-6,stone:0)
Block(-7,63,-5,stone:0)
Block(-7,63,-4,stone:0)
Block(-7,63,-3,stone:0)
Block(-7,63,-2,stone:0)
Block(-7,63,-1,stone:0)
Block(-7,63,0,stone:0)
Block(-7,63,1,stone:0)
Block(-7,63,2,stone:0)
Block(-7,63,3,stone:0)
Block(-7,63,4,stone:0)
Block(-7,63,5,stone:0)
Block(-7,63,6,stone:0)
Block(-7,63,7,stone:0)
Block(-7,63,8,stone:0)
Block(-7,64,-7,stone:0)
Block(-7,64,-6,stone:0)
Block(-7,64,-5,stone:0)
Block(-7,64,-4,stone:0)
RandomBlock(-7,64,-3,STONEBRICK:1,10,STONEBRICK:2,10,COBBLESTONE,10,MOSSY_COBBLESTONE,10,SMOOTH_BRICK,100)
RandomBlock(-7,64,-2,STONEBRICK:1,10,STONEBRICK:2,10,COBBLESTONE,10,MOSSY_COBBLESTONE,10,SMOOTH_BRICK,100)
RandomBlock(-7,64,-1,STONEBRICK:1,10,STONEBRICK:2,10,COBBLESTONE,10,MOSSY_COBBLESTONE,10,SMOOTH_BRICK,100)
Block(-7,64,0,stone:0)
Block(-7,64,1,stone:0)
Block(-7,64,2,stone:0)
Block(-7,64,3,stone:0)
Block(-7,64,4,stone:0)
Block(-7,64,5,stone:0)
Block(-7,64,6,stone:0)
Block(-7,64,7,stone:0)
Block(-7,64,8,stone:0)
Block(-7,65,-7,stone:0)
Block(-7,65,-6,stone:0)
Block(-7,65,-5,stone:0)
Block(-7,65,-4,stone:0)
RandomBlock(-7,65,-3,STONEBRICK:1,10,STONEBRICK:2,10,COBBLESTONE,10,MOSSY_COBBLESTONE,10,SMOOTH_BRICK,100)
RandomBlock(-7,65,-2,STONEBRICK:1,10,STONEBRICK:2,10,COBBLESTONE,10,MOSSY_COBBLESTONE,10,SMOOTH_BRICK,100)
RandomBlock(-7,65,-1,STONEBRICK:1,10,STONEBRICK:2,10,COBBLESTONE,10,MOSSY_COBBLESTONE,10,SMOOTH_BRICK,100)
Block(-7,65,0,stone:0)
Block(-7,65,1,stone:0)
Block(-7,65,2,stone:0)
Block(-7,65,3,stone:0)
Block(-7,65,4,stone:0)
Block(-7,65,5,stone:0)
Block(-7,65,6,stone:0)
Block(-7,65,7,stone:0)
Block(-7,65,8,stone:0)
Block(-7,66,-7,stone:0)
Block(-7,66,-6,stone:0)
Block(-7,66,-5,stone:0)
Block(-7,66,-4,stone:0)
RandomBlock(-7,66,-3,STONEBRICK:1,10,STONEBRICK:2,10,COBBLESTONE,10,MOSSY_COBBLESTONE,10,SMOOTH_BRICK,100)
RandomBlock(-7,66,-2,STONEBRICK:1,10,STONEBRICK:2,10,COBBLESTONE,10,MOSSY_COBBLESTONE,10,SMOOTH_BRICK,100)
RandomBlock(-7,66,-1,STONEBRICK:1,10,STONEBRICK:2,10,COBBLESTONE,10,MOSSY_COBBLESTONE,10,SMOOTH_BRICK,100)
Block(-7,66,0,stone:0)
Block(-7,66,1,stone:0)
Block(-7,66,2,stone:0)
Block(-7,66,3,stone:0)
Block(-7,66,4,stone:0)
Block(-7,66,5,stone:0)
Block(-7,66,6,stone:0)
Block(-7,66,7,stone:0)
Block(-7,66,8,stone:0)
Block(-7,67,-7,stone:0)
Block(-7,67,-6,stone:0)
Block(-7,67,-5,stone:0)
Block(-7,67,-4,stone:0)
RandomBlock(-7,67,-3,STONEBRICK:1,10,STONEBRICK:2,10,COBBLESTONE,10,MOSSY_COBBLESTONE,10,SMOOTH_BRICK,100)
RandomBlock(-7,67,-2,STONEBRICK:1,10,STONEBRICK:2,10,COBBLESTONE,10,MOSSY_COBBLESTONE,10,SMOOTH_BRICK,100)
RandomBlock(-7,67,-1,STONEBRICK:1,10,STONEBRICK:2,10,COBBLESTONE,10,MOSSY_COBBLESTONE,10,SMOOTH_BRICK,100)
Block(-7,67,0,stone:0)
Block(-7,67,1,stone:0)
Block(-7,67,2,stone:0)
Block(-7,67,3,stone:0)
Block(-7,67,4,stone:0)
Block(-7,67,5,stone:0)
Block(-7,67,6,stone:0)
Block(-7,67,7,stone:0)
Block(-7,67,8,stone:0)
Block(-7,68,-7,stone:0)
Block(-7,68,-6,stone:0)
Block(-7,68,-5,stone:0)
Block(-7,68,-4,stone:0)
RandomBlock(-7,68,-3,STONEBRICK:1,10,STONEBRICK:2,10,COBBLESTONE,10,MOSSY_COBBLESTONE,10,SMOOTH_BRICK,100)
RandomBlock(-7,68,-2,STONEBRICK:1,10,STONEBRICK:2,10,COBBLESTONE,10,MOSSY_COBBLESTONE,10,SMOOTH_BRICK,100)
RandomBlock(-7,68,-1,STONEBRICK:1,10,STONEBRICK:2,10,COBBLESTONE,10,MOSSY_COBBLESTONE,10,SMOOTH_BRICK,100)
Block(-7,68,0,stone:0)
RandomBlock(-7,68,1,STONEBRICK:1,10,STONEBRICK:2,10,COBBLESTONE,10,MOSSY_COBBLESTONE,10,SMOOTH_BRICK,100)
Block(-7,68,2,stone:0)
Block(-7,68,3,stone:0)
Block(-7,68,4,stone:0)
Block(-7,68,5,stone:0)
Block(-7,68,6,stone:0)
Block(-7,68,7,stone:0)
Block(-7,68,8,stone:0)
RandomBlock(-7,69,-7,SAND:0,50,BIOMESOPLENTY:DRIED_SAND,100)
Block(-7,69,-6,stone:0)
Block(-7,69,-5,stone:0)
Block(-7,69,-4,stone:0)
RandomBlock(-7,69,-3,STONEBRICK:1,10,STONEBRICK:2,10,COBBLESTONE,10,MOSSY_COBBLESTONE,10,SMOOTH_BRICK,100)
RandomBlock(-7,69,-2,STONEBRICK:1,10,STONEBRICK:2,10,COBBLESTONE,10,MOSSY_COBBLESTONE,10,SMOOTH_BRICK,100)
RandomBlock(-7,69,-1,STONEBRICK:1,10,STONEBRICK:2,10,COBBLESTONE,10,MOSSY_COBBLESTONE,10,SMOOTH_BRICK,100)
Block(-7,69,0,stone:0)
RandomBlock(-7,69,1,STONEBRICK:1,10,STONEBRICK:2,10,COBBLESTONE,10,MOSSY_COBBLESTONE,10,SMOOTH_BRICK,100)
RandomBlock(-7,69,2,STONEBRICK:1,10,STONEBRICK:2,10,COBBLESTONE,10,MOSSY_COBBLESTONE,10,SMOOTH_BRICK,100)
RandomBlock(-7,69,3,STONEBRICK:1,10,STONEBRICK:2,10,COBBLESTONE,10,MOSSY_COBBLESTONE,10,SMOOTH_BRICK,100)
RandomBlock(-7,69,4,STONEBRICK:1,10,STONEBRICK:2,10,COBBLESTONE,10,MOSSY_COBBLESTONE,10,SMOOTH_BRICK,100)
RandomBlock(-7,69,5,STONEBRICK:1,10,STONEBRICK:2,10,COBBLESTONE,10,MOSSY_COBBLESTONE,10,SMOOTH_BRICK,100)
RandomBlock(-7,69,6,STONEBRICK:1,10,STONEBRICK:2,10,COBBLESTONE,10,MOSSY_COBBLESTONE,10,SMOOTH_BRICK,100)
RandomBlock(-7,69,7,STONEBRICK:1,10,STONEBRICK:2,10,COBBLESTONE,10,MOSSY_COBBLESTONE,10,SMOOTH_BRICK,100)
Block(-7,69,8,stone:0)
RandomBlock(-7,70,-7,SAND:0,50,BIOMESOPLENTY:DRIED_SAND,100)
RandomBlock(-7,70,-6,SAND:0,50,BIOMESOPLENTY:DRIED_SAND,100)
RandomBlock(-7,70,-5,SAND:0,50,BIOMESOPLENTY:DRIED_SAND,100)
RandomBlock(-7,70,-4,SAND:0,50,BIOMESOPLENTY:DRIED_SAND,100)
RandomBlock(-7,70,-3,STONEBRICK:1,10,STONEBRICK:2,10,COBBLESTONE,10,MOSSY_COBBLESTONE,10,SMOOTH_BRICK,100)
RandomBlock(-7,70,-2,STONEBRICK:1,10,STONEBRICK:2,10,COBBLESTONE,10,MOSSY_COBBLESTONE,10,SMOOTH_BRICK,100)
RandomBlock(-7,70,-1,STONEBRICK:1,10,STONEBRICK:2,10,COBBLESTONE,10,MOSSY_COBBLESTONE,10,SMOOTH_BRICK,100)
RandomBlock(-7,70,0,STONEBRICK:1,10,STONEBRICK:2,10,COBBLESTONE,10,MOSSY_COBBLESTONE,10,SMOOTH_BRICK,100)
RandomBlock(-7,70,1,STONEBRICK:1,10,STONEBRICK:2,10,COBBLESTONE,10,MOSSY_COBBLESTONE,10,SMOOTH_BRICK,100)
RandomBlock(-7,70,2,STONEBRICK:1,10,STONEBRICK:2,10,COBBLESTONE,10,MOSSY_COBBLESTONE,10,SMOOTH_BRICK,100)
RandomBlock(-7,70,3,STONEBRICK:1,10,STONEBRICK:2,10,COBBLESTONE,10,MOSSY_COBBLESTONE,10,SMOOTH_BRICK,100)
RandomBlock(-7,70,4,STONEBRICK:1,10,STONEBRICK:2,10,COBBLESTONE,10,MOSSY_COBBLESTONE,10,SMOOTH_BRICK,100)
RandomBlock(-7,70,5,STONEBRICK:1,10,STONEBRICK:2,10,COBBLESTONE,10,MOSSY_COBBLESTONE,10,SMOOTH_BRICK,100)
RandomBlock(-7,70,6,STONEBRICK:1,10,STONEBRICK:2,10,COBBLESTONE,10,MOSSY_COBBLESTONE,10,SMOOTH_BRICK,100)
RandomBlock(-7,70,7,STONEBRICK:1,10,STONEBRICK:2,10,COBBLESTONE,10,MOSSY_COBBLESTONE,10,SMOOTH_BRICK,100)
RandomBlock(-7,70,8,STONEBRICK:1,10,STONEBRICK:2,10,COBBLESTONE,10,MOSSY_COBBLESTONE,10,SMOOTH_BRICK,100)
RandomBlock(-7,71,-6,SAND:0,50,BIOMESOPLENTY:DRIED_SAND,100)
RandomBlock(-7,71,-5,SAND:0,50,BIOMESOPLENTY:DRIED_SAND,100)
RandomBlock(-7,71,-4,SMOOTH_STAIRS:2,50,quark:stonebrick_mossy_stairs:2,100)
RandomBlock(-7,71,-3,STONEBRICK:1,10,STONEBRICK:2,10,COBBLESTONE,10,MOSSY_COBBLESTONE,10,SMOOTH_BRICK,100)
RandomBlock(-7,71,-2,SMOOTH_STAIRS:3,50,quark:stonebrick_mossy_stairs:3,100)
RandomBlock(-7,71,-1,SMOOTH_STAIRS:1,50,quark:stonebrick_mossy_stairs:1,100)
RandomBlock(-7,71,0,STONEBRICK:1,10,STONEBRICK:2,10,COBBLESTONE,10,MOSSY_COBBLESTONE,10,SMOOTH_BRICK,100)
RandomBlock(-7,71,1,STEP:5,50,quark:stonebrick_mossy_slab:0,100)
RandomBlock(-7,71,2,STEP:5,50,quark:stonebrick_mossy_slab:0,100)
RandomBlock(-7,71,3,STEP:5,50,quark:stonebrick_mossy_slab:0,100)
RandomBlock(-7,71,4,STONEBRICK:1,10,STONEBRICK:2,10,COBBLESTONE,10,MOSSY_COBBLESTONE,10,SMOOTH_BRICK,100)
RandomBlock(-7,71,5,STONEBRICK:1,10,STONEBRICK:2,10,COBBLESTONE,10,MOSSY_COBBLESTONE,10,SMOOTH_BRICK,100)
RandomBlock(-7,71,6,STONEBRICK:1,10,STONEBRICK:2,10,COBBLESTONE,10,MOSSY_COBBLESTONE,10,SMOOTH_BRICK,100)
RandomBlock(-7,71,7,STONEBRICK:1,10,STONEBRICK:2,10,COBBLESTONE,10,MOSSY_COBBLESTONE,10,SMOOTH_BRICK,100)
RandomBlock(-7,71,8,STONEBRICK:1,10,STONEBRICK:2,10,COBBLESTONE,10,MOSSY_COBBLESTONE,10,SMOOTH_BRICK,100)
RandomBlock(-7,72,-3,STONEBRICK:1,10,STONEBRICK:2,10,COBBLESTONE,10,MOSSY_COBBLESTONE,10,SMOOTH_BRICK,100)
RandomBlock(-7,72,-2,STONEBRICK:1,10,STONEBRICK:2,10,COBBLESTONE,10,MOSSY_COBBLESTONE,10,SMOOTH_BRICK,100)
RandomBlock(-7,72,-1,STONEBRICK:1,10,STONEBRICK:2,10,COBBLESTONE,10,MOSSY_COBBLESTONE,10,SMOOTH_BRICK,100)
RandomBlock(-7,72,0,STONEBRICK:1,10,STONEBRICK:2,10,COBBLESTONE,10,MOSSY_COBBLESTONE,10,SMOOTH_BRICK,100)
RandomBlock(-7,72,7,STEP:5,50,quark:stonebrick_mossy_slab:0,100)
RandomBlock(-7,72,8,STEP:5,50,quark:stonebrick_mossy_slab:0,100)
Block(-6,0,-7,stone:0)
Block(-6,0,-6,stone:0)
Block(-6,0,-5,stone:0)
Block(-6,0,-4,stone:0)
Block(-6,0,-3,stone:0)
Block(-6,0,-2,stone:0)
Block(-6,0,-1,stone:0)
Block(-6,0,0,stone:0)
Block(-6,0,1,stone:0)
Block(-6,0,2,stone:0)
Block(-6,0,3,stone:0)
Block(-6,0,4,stone:0)
Block(-6,0,5,stone:0)
Block(-6,0,6,stone:0)
Block(-6,0,7,stone:0)
Block(-6,0,8,stone:0)
Block(-6,1,-7,stone:0)
Block(-6,1,-6,stone:0)
Block(-6,1,-5,stone:0)
Block(-6,1,-4,stone:0)
Block(-6,1,-3,stone:0)
Block(-6,1,-2,stone:0)
Block(-6,1,-1,stone:0)
Block(-6,1,0,stone:0)
Block(-6,1,1,stone:0)
Block(-6,1,2,stone:0)
Block(-6,1,3,stone:0)
Block(-6,1,4,stone:0)
Block(-6,1,5,stone:0)
Block(-6,1,6,stone:0)
Block(-6,1,7,stone:0)
Block(-6,1,8,stone:0)
Block(-6,2,-7,stone:0)
Block(-6,2,-6,stone:0)
Block(-6,2,-5,stone:0)
Block(-6,2,-4,stone:0)
Block(-6,2,-3,stone:0)
Block(-6,2,-2,stone:0)
Block(-6,2,-1,stone:0)
Block(-6,2,0,stone:0)
Block(-6,2,1,stone:0)
Block(-6,2,2,stone:0)
Block(-6,2,3,stone:0)
Block(-6,2,4,stone:0)
Block(-6,2,5,stone:0)
Block(-6,2,6,stone:0)
Block(-6,2,7,stone:0)
Block(-6,2,8,stone:0)
Block(-6,3,-7,stone:0)
Block(-6,3,-6,stone:0)
Block(-6,3,-5,stone:0)
Block(-6,3,-4,stone:0)
Block(-6,3,-3,stone:0)
Block(-6,3,-2,stone:0)
Block(-6,3,-1,stone:0)
Block(-6,3,0,stone:0)
Block(-6,3,1,stone:0)
Block(-6,3,2,stone:0)
Block(-6,3,3,stone:0)
Block(-6,3,4,stone:0)
Block(-6,3,5,stone:0)
Block(-6,3,6,stone:0)
Block(-6,3,7,stone:0)
Block(-6,3,8,stone:0)
Block(-6,4,-7,stone:0)
Block(-6,4,-6,stone:0)
Block(-6,4,-5,stone:0)
Block(-6,4,-4,stone:0)
Block(-6,4,-3,stone:0)
Block(-6,4,-2,stone:0)
Block(-6,4,-1,stone:0)
Block(-6,4,0,stone:0)
Block(-6,4,1,stone:0)
Block(-6,4,2,stone:0)
Block(-6,4,3,stone:0)
Block(-6,4,4,stone:0)
Block(-6,4,5,stone:0)
Block(-6,4,6,stone:0)
Block(-6,4,7,stone:0)
Block(-6,4,8,stone:0)
Block(-6,5,-7,stone:0)
Block(-6,5,-6,stone:0)
Block(-6,5,-5,stone:0)
Block(-6,5,-4,stone:0)
Block(-6,5,-3,stone:0)
Block(-6,5,-2,stone:0)
Block(-6,5,-1,stone:0)
Block(-6,5,0,stone:0)
Block(-6,5,1,stone:0)
Block(-6,5,2,stone:0)
Block(-6,5,3,stone:0)
Block(-6,5,4,stone:0)
Block(-6,5,5,stone:0)
Block(-6,5,6,stone:0)
Block(-6,5,7,stone:0)
Block(-6,5,8,stone:0)
Block(-6,6,-7,stone:0)
Block(-6,6,-6,stone:0)
Block(-6,6,-5,stone:0)
Block(-6,6,-4,stone:0)
Block(-6,6,-3,stone:0)
Block(-6,6,-2,stone:0)
Block(-6,6,-1,stone:0)
Block(-6,6,0,stone:0)
Block(-6,6,1,stone:0)
Block(-6,6,2,stone:0)
Block(-6,6,3,stone:0)
Block(-6,6,4,stone:0)
Block(-6,6,5,stone:0)
Block(-6,6,6,stone:0)
Block(-6,6,7,stone:0)
Block(-6,6,8,stone:0)
Block(-6,7,-7,stone:0)
Block(-6,7,-6,stone:0)
Block(-6,7,-5,stone:0)
Block(-6,7,-4,stone:0)
Block(-6,7,-3,stone:0)
Block(-6,7,-2,stone:0)
Block(-6,7,-1,stone:0)
Block(-6,7,0,stone:0)
Block(-6,7,1,stone:0)
Block(-6,7,2,stone:0)
Block(-6,7,3,stone:0)
Block(-6,7,4,stone:0)
Block(-6,7,5,stone:0)
Block(-6,7,6,stone:0)
Block(-6,7,7,stone:0)
Block(-6,7,8,stone:0)
Block(-6,8,-7,stone:0)
Block(-6,8,-6,stone:0)
Block(-6,8,-5,stone:0)
Block(-6,8,-4,stone:0)
Block(-6,8,-3,stone:0)
Block(-6,8,-2,stone:0)
Block(-6,8,-1,stone:0)
Block(-6,8,0,stone:0)
Block(-6,8,1,stone:0)
Block(-6,8,2,stone:0)
Block(-6,8,3,stone:0)
Block(-6,8,4,stone:0)
Block(-6,8,5,stone:0)
Block(-6,8,6,stone:0)
Block(-6,8,7,stone:0)
Block(-6,8,8,stone:0)
Block(-6,9,-7,stone:0)
Block(-6,9,-6,stone:0)
Block(-6,9,-5,stone:0)
Block(-6,9,-4,stone:0)
Block(-6,9,-3,stone:0)
Block(-6,9,-2,stone:0)
Block(-6,9,-1,stone:0)
Block(-6,9,0,stone:0)
Block(-6,9,1,stone:0)
Block(-6,9,2,stone:0)
Block(-6,9,3,stone:0)
Block(-6,9,4,stone:0)
Block(-6,9,5,stone:0)
Block(-6,9,6,stone:0)
Block(-6,9,7,stone:0)
Block(-6,9,8,stone:0)
Block(-6,10,-7,stone:0)
Block(-6,10,-6,stone:0)
Block(-6,10,-5,stone:0)
Block(-6,10,-4,stone:0)
Block(-6,10,-3,stone:0)
Block(-6,10,-2,stone:0)
Block(-6,10,-1,stone:0)
Block(-6,10,0,stone:0)
Block(-6,10,1,stone:0)
Block(-6,10,2,stone:0)
Block(-6,10,3,stone:0)
Block(-6,10,4,stone:0)
Block(-6,10,5,stone:0)
Block(-6,10,6,stone:0)
Block(-6,10,7,stone:0)
Block(-6,10,8,stone:0)
Block(-6,11,-7,stone:0)
Block(-6,11,-6,stone:0)
Block(-6,11,-5,stone:0)
Block(-6,11,-4,stone:0)
Block(-6,11,-3,stone:0)
Block(-6,11,-2,stone:0)
Block(-6,11,-1,stone:0)
Block(-6,11,0,stone:0)
Block(-6,11,1,stone:0)
Block(-6,11,2,stone:0)
Block(-6,11,3,stone:0)
Block(-6,11,4,stone:0)
Block(-6,11,5,stone:0)
Block(-6,11,6,stone:0)
Block(-6,11,7,stone:0)
Block(-6,11,8,stone:0)
Block(-6,12,-7,stone:0)
Block(-6,12,-6,stone:0)
Block(-6,12,-5,stone:0)
Block(-6,12,-4,stone:0)
Block(-6,12,-3,stone:0)
Block(-6,12,-2,stone:0)
Block(-6,12,-1,stone:0)
Block(-6,12,0,stone:0)
Block(-6,12,1,stone:0)
Block(-6,12,2,stone:0)
Block(-6,12,3,stone:0)
Block(-6,12,4,stone:0)
Block(-6,12,5,stone:0)
Block(-6,12,6,stone:0)
Block(-6,12,7,stone:0)
Block(-6,12,8,stone:0)
Block(-6,13,-7,stone:0)
Block(-6,13,-6,stone:0)
Block(-6,13,-5,stone:0)
Block(-6,13,-4,stone:0)
Block(-6,13,-3,stone:0)
Block(-6,13,-2,stone:0)
Block(-6,13,-1,stone:0)
Block(-6,13,0,stone:0)
Block(-6,13,1,stone:0)
Block(-6,13,2,stone:0)
Block(-6,13,3,stone:0)
Block(-6,13,4,stone:0)
Block(-6,13,5,stone:0)
Block(-6,13,6,stone:0)
Block(-6,13,7,stone:0)
Block(-6,13,8,stone:0)
Block(-6,14,-7,stone:0)
Block(-6,14,-6,stone:0)
Block(-6,14,-5,stone:0)
Block(-6,14,-4,stone:0)
Block(-6,14,-3,stone:0)
Block(-6,14,-2,stone:0)
Block(-6,14,-1,stone:0)
Block(-6,14,0,stone:0)
Block(-6,14,1,stone:0)
Block(-6,14,2,stone:0)
Block(-6,14,3,stone:0)
Block(-6,14,4,stone:0)
Block(-6,14,5,stone:0)
Block(-6,14,6,stone:0)
Block(-6,14,7,stone:0)
Block(-6,14,8,stone:0)
Block(-6,15,-7,stone:0)
Block(-6,15,-6,stone:0)
Block(-6,15,-5,stone:0)
Block(-6,15,-4,stone:0)
Block(-6,15,-3,stone:0)
Block(-6,15,-2,stone:0)
Block(-6,15,-1,stone:0)
Block(-6,15,0,stone:0)
Block(-6,15,1,stone:0)
Block(-6,15,2,stone:0)
Block(-6,15,3,stone:0)
Block(-6,15,4,stone:0)
Block(-6,15,5,stone:0)
Block(-6,15,6,stone:0)
Block(-6,15,7,stone:0)
Block(-6,15,8,stone:0)
Block(-6,16,-7,stone:0)
Block(-6,16,-6,stone:0)
Block(-6,16,-5,stone:0)
Block(-6,16,-4,stone:0)
Block(-6,16,-3,stone:0)
Block(-6,16,-2,stone:0)
Block(-6,16,-1,stone:0)
Block(-6,16,0,stone:0)
Block(-6,16,1,stone:0)
Block(-6,16,2,stone:0)
Block(-6,16,3,stone:0)
Block(-6,16,4,stone:0)
Block(-6,16,5,stone:0)
Block(-6,16,6,stone:0)
Block(-6,16,7,stone:0)
Block(-6,16,8,stone:0)
Block(-6,17,-7,stone:0)
Block(-6,17,-6,stone:0)
Block(-6,17,-5,stone:0)
Block(-6,17,-4,stone:0)
Block(-6,17,-3,stone:0)
Block(-6,17,-2,stone:0)
Block(-6,17,-1,stone:0)
Block(-6,17,0,stone:0)
Block(-6,17,1,stone:0)
Block(-6,17,2,stone:0)
Block(-6,17,3,stone:0)
Block(-6,17,4,stone:0)
Block(-6,17,5,stone:0)
Block(-6,17,6,stone:0)
Block(-6,17,7,stone:0)
Block(-6,17,8,stone:0)
Block(-6,18,-7,stone:0)
Block(-6,18,-6,stone:0)
Block(-6,18,-5,stone:0)
Block(-6,18,-4,stone:0)
Block(-6,18,-3,stone:0)
Block(-6,18,-2,stone:0)
Block(-6,18,-1,stone:0)
Block(-6,18,0,stone:0)
Block(-6,18,1,stone:0)
Block(-6,18,2,stone:0)
Block(-6,18,3,stone:0)
Block(-6,18,4,stone:0)
Block(-6,18,5,stone:0)
Block(-6,18,6,stone:0)
Block(-6,18,7,stone:0)
Block(-6,18,8,stone:0)
Block(-6,19,-7,stone:0)
Block(-6,19,-6,stone:0)
Block(-6,19,-5,stone:0)
Block(-6,19,-4,stone:0)
Block(-6,19,-3,stone:0)
Block(-6,19,-2,stone:0)
Block(-6,19,-1,stone:0)
Block(-6,19,0,stone:0)
Block(-6,19,1,stone:0)
Block(-6,19,2,stone:0)
Block(-6,19,3,stone:0)
Block(-6,19,4,stone:0)
Block(-6,19,5,stone:0)
Block(-6,19,6,stone:0)
Block(-6,19,7,stone:0)
Block(-6,19,8,stone:0)
Block(-6,20,-7,stone:0)
Block(-6,20,-6,stone:0)
Block(-6,20,-5,stone:0)
Block(-6,20,-4,stone:0)
Block(-6,20,-3,stone:0)
Block(-6,20,-2,stone:0)
Block(-6,20,-1,stone:0)
Block(-6,20,0,stone:0)
Block(-6,20,1,stone:0)
Block(-6,20,2,stone:0)
Block(-6,20,3,stone:0)
Block(-6,20,4,stone:0)
Block(-6,20,5,stone:0)
Block(-6,20,6,stone:0)
Block(-6,20,7,stone:0)
Block(-6,20,8,stone:0)
Block(-6,21,-7,stone:0)
Block(-6,21,-6,stone:0)
Block(-6,21,-5,stone:0)
Block(-6,21,-4,stone:0)
Block(-6,21,-3,stone:0)
Block(-6,21,-2,stone:0)
Block(-6,21,-1,stone:0)
Block(-6,21,0,stone:0)
Block(-6,21,1,stone:0)
Block(-6,21,2,stone:0)
Block(-6,21,3,stone:0)
Block(-6,21,4,stone:0)
Block(-6,21,5,stone:0)
Block(-6,21,6,stone:0)
Block(-6,21,7,stone:0)
Block(-6,21,8,stone:0)
Block(-6,22,-7,stone:0)
Block(-6,22,-6,stone:0)
Block(-6,22,-5,stone:0)
Block(-6,22,-4,stone:0)
Block(-6,22,-3,stone:0)
Block(-6,22,-2,stone:0)
Block(-6,22,-1,stone:0)
Block(-6,22,0,stone:0)
Block(-6,22,1,stone:0)
Block(-6,22,2,stone:0)
Block(-6,22,3,stone:0)
Block(-6,22,4,stone:0)
Block(-6,22,5,stone:0)
Block(-6,22,6,stone:0)
Block(-6,22,7,stone:0)
Block(-6,22,8,stone:0)
Block(-6,23,-7,stone:0)
Block(-6,23,-6,stone:0)
Block(-6,23,-5,stone:0)
Block(-6,23,-4,stone:0)
Block(-6,23,-3,stone:0)
Block(-6,23,-2,stone:0)
Block(-6,23,-1,stone:0)
Block(-6,23,0,stone:0)
Block(-6,23,1,stone:0)
Block(-6,23,2,stone:0)
Block(-6,23,3,stone:0)
Block(-6,23,4,stone:0)
Block(-6,23,5,stone:0)
Block(-6,23,6,stone:0)
Block(-6,23,7,stone:0)
Block(-6,23,8,stone:0)
Block(-6,24,-7,stone:0)
Block(-6,24,-6,stone:0)
Block(-6,24,-5,stone:0)
Block(-6,24,-4,stone:0)
Block(-6,24,-3,stone:0)
Block(-6,24,-2,stone:0)
Block(-6,24,-1,stone:0)
Block(-6,24,0,stone:0)
Block(-6,24,1,stone:0)
Block(-6,24,2,stone:0)
Block(-6,24,3,stone:0)
Block(-6,24,4,stone:0)
Block(-6,24,5,stone:0)
Block(-6,24,6,stone:0)
Block(-6,24,7,stone:0)
Block(-6,24,8,stone:0)
Block(-6,25,-7,stone:0)
Block(-6,25,-6,stone:0)
Block(-6,25,-5,stone:0)
Block(-6,25,-4,stone:0)
Block(-6,25,-3,stone:0)
Block(-6,25,-2,stone:0)
Block(-6,25,-1,stone:0)
Block(-6,25,0,stone:0)
Block(-6,25,1,stone:0)
Block(-6,25,2,stone:0)
Block(-6,25,3,stone:0)
Block(-6,25,4,stone:0)
Block(-6,25,5,stone:0)
Block(-6,25,6,stone:0)
Block(-6,25,7,stone:0)
Block(-6,25,8,stone:0)
Block(-6,26,-7,stone:0)
Block(-6,26,-6,stone:0)
Block(-6,26,-5,stone:0)
Block(-6,26,-4,stone:0)
Block(-6,26,-3,stone:0)
Block(-6,26,-2,stone:0)
Block(-6,26,-1,stone:0)
Block(-6,26,0,stone:0)
Block(-6,26,1,stone:0)
Block(-6,26,2,stone:0)
Block(-6,26,3,stone:0)
Block(-6,26,4,stone:0)
Block(-6,26,5,stone:0)
Block(-6,26,6,stone:0)
Block(-6,26,7,stone:0)
Block(-6,26,8,stone:0)
Block(-6,27,-7,stone:0)
Block(-6,27,-6,stone:0)
Block(-6,27,-5,stone:0)
Block(-6,27,-4,stone:0)
Block(-6,27,-3,stone:0)
Block(-6,27,-2,stone:0)
Block(-6,27,-1,stone:0)
Block(-6,27,0,stone:0)
Block(-6,27,1,stone:0)
Block(-6,27,2,stone:0)
Block(-6,27,3,stone:0)
Block(-6,27,4,stone:0)
Block(-6,27,5,stone:0)
Block(-6,27,6,stone:0)
Block(-6,27,7,stone:0)
Block(-6,27,8,stone:0)
Block(-6,28,-7,stone:0)
Block(-6,28,-6,stone:0)
Block(-6,28,-5,stone:0)
Block(-6,28,-4,stone:0)
Block(-6,28,-3,stone:0)
Block(-6,28,-2,stone:0)
Block(-6,28,-1,stone:0)
Block(-6,28,0,stone:0)
Block(-6,28,1,stone:0)
Block(-6,28,2,stone:0)
Block(-6,28,3,stone:0)
Block(-6,28,4,stone:0)
Block(-6,28,5,stone:0)
Block(-6,28,6,stone:0)
Block(-6,28,7,stone:0)
Block(-6,28,8,stone:0)
Block(-6,29,-7,stone:0)
Block(-6,29,-6,stone:0)
Block(-6,29,-5,stone:0)
Block(-6,29,-4,stone:0)
Block(-6,29,-3,stone:0)
Block(-6,29,-2,stone:0)
Block(-6,29,-1,stone:0)
Block(-6,29,0,stone:0)
Block(-6,29,1,stone:0)
Block(-6,29,2,stone:0)
Block(-6,29,3,stone:0)
Block(-6,29,4,stone:0)
Block(-6,29,5,stone:0)
Block(-6,29,6,stone:0)
Block(-6,29,7,stone:0)
Block(-6,29,8,stone:0)
Block(-6,30,-7,stone:0)
Block(-6,30,-6,stone:0)
Block(-6,30,-5,stone:0)
Block(-6,30,-4,stone:0)
Block(-6,30,-3,stone:0)
Block(-6,30,-2,stone:0)
Block(-6,30,-1,stone:0)
Block(-6,30,0,stone:0)
Block(-6,30,1,stone:0)
Block(-6,30,2,stone:0)
Block(-6,30,3,stone:0)
Block(-6,30,4,stone:0)
Block(-6,30,5,stone:0)
Block(-6,30,6,stone:0)
Block(-6,30,7,stone:0)
Block(-6,30,8,stone:0)
Block(-6,31,-7,stone:0)
Block(-6,31,-6,stone:0)
Block(-6,31,-5,stone:0)
Block(-6,31,-4,stone:0)
Block(-6,31,-3,stone:0)
Block(-6,31,-2,stone:0)
Block(-6,31,-1,stone:0)
Block(-6,31,0,stone:0)
Block(-6,31,1,stone:0)
Block(-6,31,2,stone:0)
Block(-6,31,3,stone:0)
Block(-6,31,4,stone:0)
Block(-6,31,5,stone:0)
Block(-6,31,6,stone:0)
Block(-6,31,7,stone:0)
Block(-6,31,8,stone:0)
Block(-6,32,-7,stone:0)
Block(-6,32,-6,stone:0)
Block(-6,32,-5,stone:0)
Block(-6,32,-4,stone:0)
Block(-6,32,-3,stone:0)
Block(-6,32,-2,stone:0)
Block(-6,32,-1,stone:0)
Block(-6,32,0,stone:0)
Block(-6,32,1,stone:0)
Block(-6,32,2,stone:0)
Block(-6,32,3,stone:0)
Block(-6,32,4,stone:0)
Block(-6,32,5,stone:0)
Block(-6,32,6,stone:0)
Block(-6,32,7,stone:0)
Block(-6,32,8,stone:0)
Block(-6,33,-7,stone:0)
Block(-6,33,-6,stone:0)
Block(-6,33,-5,stone:0)
Block(-6,33,-4,stone:0)
Block(-6,33,-3,stone:0)
Block(-6,33,-2,stone:0)
Block(-6,33,-1,stone:0)
Block(-6,33,0,stone:0)
Block(-6,33,1,stone:0)
Block(-6,33,2,stone:0)
Block(-6,33,3,stone:0)
Block(-6,33,4,stone:0)
Block(-6,33,5,stone:0)
Block(-6,33,6,stone:0)
Block(-6,33,7,stone:0)
Block(-6,33,8,stone:0)
Block(-6,34,-7,stone:0)
Block(-6,34,-6,stone:0)
Block(-6,34,-5,stone:0)
Block(-6,34,-4,stone:0)
Block(-6,34,-3,stone:0)
Block(-6,34,-2,stone:0)
Block(-6,34,-1,stone:0)
Block(-6,34,0,stone:0)
Block(-6,34,1,stone:0)
Block(-6,34,2,stone:0)
Block(-6,34,3,stone:0)
Block(-6,34,4,stone:0)
Block(-6,34,5,stone:0)
Block(-6,34,6,stone:0)
Block(-6,34,7,stone:0)
Block(-6,34,8,stone:0)
Block(-6,35,-7,stone:0)
Block(-6,35,-6,stone:0)
Block(-6,35,-5,stone:0)
Block(-6,35,-4,stone:0)
Block(-6,35,-3,stone:0)
Block(-6,35,-2,stone:0)
Block(-6,35,-1,stone:0)
Block(-6,35,0,stone:0)
Block(-6,35,1,stone:0)
Block(-6,35,2,stone:0)
Block(-6,35,3,stone:0)
Block(-6,35,4,stone:0)
Block(-6,35,5,stone:0)
Block(-6,35,6,stone:0)
Block(-6,35,7,stone:0)
Block(-6,35,8,stone:0)
Block(-6,36,-7,stone:0)
Block(-6,36,-6,stone:0)
Block(-6,36,-5,stone:0)
Block(-6,36,-4,stone:0)
Block(-6,36,-3,stone:0)
Block(-6,36,-2,stone:0)
Block(-6,36,-1,stone:0)
Block(-6,36,0,stone:0)
Block(-6,36,1,stone:0)
Block(-6,36,2,stone:0)
Block(-6,36,3,stone:0)
Block(-6,36,4,stone:0)
Block(-6,36,5,stone:0)
Block(-6,36,6,stone:0)
Block(-6,36,7,stone:0)
Block(-6,36,8,stone:0)
Block(-6,37,-7,stone:0)
Block(-6,37,-6,stone:0)
Block(-6,37,-5,stone:0)
Block(-6,37,-4,stone:0)
Block(-6,37,-3,stone:0)
Block(-6,37,-2,stone:0)
Block(-6,37,-1,stone:0)
Block(-6,37,0,stone:0)
Block(-6,37,1,stone:0)
Block(-6,37,2,stone:0)
Block(-6,37,3,stone:0)
Block(-6,37,4,stone:0)
Block(-6,37,5,stone:0)
Block(-6,37,6,stone:0)
Block(-6,37,7,stone:0)
Block(-6,37,8,stone:0)
Block(-6,38,-7,stone:0)
Block(-6,38,-6,stone:0)
Block(-6,38,-5,stone:0)
Block(-6,38,-4,stone:0)
Block(-6,38,-3,stone:0)
Block(-6,38,-2,stone:0)
Block(-6,38,-1,stone:0)
Block(-6,38,0,stone:0)
Block(-6,38,1,stone:0)
Block(-6,38,2,stone:0)
Block(-6,38,3,stone:0)
Block(-6,38,4,stone:0)
Block(-6,38,5,stone:0)
Block(-6,38,6,stone:0)
Block(-6,38,7,stone:0)
Block(-6,38,8,stone:0)
Block(-6,39,-7,stone:0)
Block(-6,39,-6,stone:0)
Block(-6,39,-5,stone:0)
Block(-6,39,-4,stone:0)
Block(-6,39,-3,stone:0)
Block(-6,39,-2,stone:0)
Block(-6,39,-1,stone:0)
Block(-6,39,0,stone:0)
Block(-6,39,1,stone:0)
Block(-6,39,2,stone:0)
Block(-6,39,3,stone:0)
Block(-6,39,4,stone:0)
Block(-6,39,5,stone:0)
Block(-6,39,6,stone:0)
Block(-6,39,7,stone:0)
Block(-6,39,8,stone:0)
Block(-6,40,-7,stone:0)
Block(-6,40,-6,stone:0)
Block(-6,40,-5,stone:0)
Block(-6,40,-4,stone:0)
Block(-6,40,-3,stone:0)
Block(-6,40,-2,stone:0)
Block(-6,40,-1,stone:0)
Block(-6,40,0,stone:0)
Block(-6,40,1,stone:0)
Block(-6,40,2,stone:0)
Block(-6,40,3,stone:0)
Block(-6,40,4,stone:0)
Block(-6,40,5,stone:0)
Block(-6,40,6,stone:0)
Block(-6,40,7,stone:0)
Block(-6,40,8,stone:0)
Block(-6,41,-7,stone:0)
Block(-6,41,-6,stone:0)
Block(-6,41,-5,stone:0)
Block(-6,41,-4,stone:0)
Block(-6,41,-3,stone:0)
Block(-6,41,-2,stone:0)
Block(-6,41,-1,stone:0)
Block(-6,41,0,stone:0)
Block(-6,41,1,stone:0)
Block(-6,41,2,stone:0)
Block(-6,41,3,stone:0)
Block(-6,41,4,stone:0)
Block(-6,41,5,stone:0)
Block(-6,41,6,stone:0)
Block(-6,41,7,stone:0)
Block(-6,41,8,stone:0)
Block(-6,42,-7,stone:0)
Block(-6,42,-6,stone:0)
Block(-6,42,-5,stone:0)
Block(-6,42,-4,stone:0)
Block(-6,42,-3,stone:0)
Block(-6,42,-2,stone:0)
Block(-6,42,-1,stone:0)
Block(-6,42,0,stone:0)
Block(-6,42,1,stone:0)
Block(-6,42,2,stone:0)
Block(-6,42,3,stone:0)
Block(-6,42,4,stone:0)
Block(-6,42,5,stone:0)
Block(-6,42,6,stone:0)
Block(-6,42,7,stone:0)
Block(-6,42,8,stone:0)
Block(-6,43,-7,stone:0)
Block(-6,43,-6,stone:0)
Block(-6,43,-5,stone:0)
Block(-6,43,-4,stone:0)
Block(-6,43,-3,stone:0)
Block(-6,43,-2,stone:0)
Block(-6,43,-1,stone:0)
Block(-6,43,0,stone:0)
Block(-6,43,1,stone:0)
Block(-6,43,2,stone:0)
Block(-6,43,3,stone:0)
Block(-6,43,4,stone:0)
Block(-6,43,5,stone:0)
Block(-6,43,6,stone:0)
Block(-6,43,7,stone:0)
Block(-6,43,8,stone:0)
Block(-6,44,-7,stone:0)
Block(-6,44,-6,stone:0)
Block(-6,44,-5,stone:0)
Block(-6,44,-4,stone:0)
Block(-6,44,-3,stone:0)
Block(-6,44,-2,stone:0)
Block(-6,44,-1,stone:0)
Block(-6,44,0,stone:0)
Block(-6,44,1,stone:0)
Block(-6,44,2,stone:0)
Block(-6,44,3,stone:0)
Block(-6,44,4,stone:0)
Block(-6,44,5,stone:0)
Block(-6,44,6,stone:0)
Block(-6,44,7,stone:0)
Block(-6,44,8,stone:0)
Block(-6,45,-7,stone:0)
Block(-6,45,-6,stone:0)
Block(-6,45,-5,stone:0)
Block(-6,45,-4,stone:0)
Block(-6,45,-3,stone:0)
Block(-6,45,-2,stone:0)
Block(-6,45,-1,stone:0)
Block(-6,45,0,stone:0)
Block(-6,45,1,stone:0)
Block(-6,45,2,stone:0)
Block(-6,45,3,stone:0)
Block(-6,45,4,stone:0)
Block(-6,45,5,stone:0)
Block(-6,45,6,stone:0)
Block(-6,45,7,stone:0)
Block(-6,45,8,stone:0)
Block(-6,46,-7,stone:0)
Block(-6,46,-6,stone:0)
Block(-6,46,-5,stone:0)
Block(-6,46,-4,stone:0)
Block(-6,46,-3,stone:0)
Block(-6,46,-2,stone:0)
Block(-6,46,-1,stone:0)
Block(-6,46,0,stone:0)
Block(-6,46,1,stone:0)
Block(-6,46,2,stone:0)
Block(-6,46,3,stone:0)
Block(-6,46,4,stone:0)
Block(-6,46,5,stone:0)
Block(-6,46,6,stone:0)
Block(-6,46,7,stone:0)
Block(-6,46,8,stone:0)
Block(-6,47,-7,stone:0)
Block(-6,47,-6,stone:0)
Block(-6,47,-5,stone:0)
Block(-6,47,-4,stone:0)
Block(-6,47,-3,stone:0)
Block(-6,47,-2,stone:0)
Block(-6,47,-1,stone:0)
Block(-6,47,0,stone:0)
Block(-6,47,1,stone:0)
Block(-6,47,2,stone:0)
Block(-6,47,3,stone:0)
Block(-6,47,4,stone:0)
Block(-6,47,5,stone:0)
Block(-6,47,6,stone:0)
Block(-6,47,7,stone:0)
Block(-6,47,8,stone:0)
Block(-6,48,-7,stone:0)
Block(-6,48,-6,stone:0)
Block(-6,48,-5,stone:0)
Block(-6,48,-4,stone:0)
Block(-6,48,-3,stone:0)
Block(-6,48,-2,stone:0)
Block(-6,48,-1,stone:0)
Block(-6,48,0,stone:0)
Block(-6,48,1,stone:0)
Block(-6,48,2,stone:0)
Block(-6,48,3,stone:0)
Block(-6,48,4,stone:0)
Block(-6,48,5,stone:0)
Block(-6,48,6,stone:0)
Block(-6,48,7,stone:0)
Block(-6,48,8,stone:0)
Block(-6,49,-7,stone:0)
Block(-6,49,-6,stone:0)
Block(-6,49,-5,stone:0)
Block(-6,49,-4,stone:0)
Block(-6,49,-3,stone:0)
Block(-6,49,-2,stone:0)
Block(-6,49,-1,stone:0)
Block(-6,49,0,stone:0)
Block(-6,49,1,stone:0)
Block(-6,49,2,stone:0)
Block(-6,49,3,stone:0)
Block(-6,49,4,stone:0)
Block(-6,49,5,stone:0)
Block(-6,49,6,stone:0)
Block(-6,49,7,stone:0)
Block(-6,49,8,stone:0)
Block(-6,50,-7,stone:0)
Block(-6,50,-6,stone:0)
Block(-6,50,-5,stone:0)
Block(-6,50,-4,stone:0)
Block(-6,50,-3,stone:0)
Block(-6,50,-2,stone:0)
Block(-6,50,-1,stone:0)
Block(-6,50,0,stone:0)
Block(-6,50,1,stone:0)
Block(-6,50,2,stone:0)
Block(-6,50,3,stone:0)
Block(-6,50,4,stone:0)
Block(-6,50,5,stone:0)
Block(-6,50,6,stone:0)
Block(-6,50,7,stone:0)
Block(-6,50,8,stone:0)
Block(-6,51,-7,stone:0)
Block(-6,51,-6,stone:0)
Block(-6,51,-5,stone:0)
Block(-6,51,-4,stone:0)
Block(-6,51,-3,stone:0)
Block(-6,51,-2,stone:0)
Block(-6,51,-1,stone:0)
Block(-6,51,0,stone:0)
Block(-6,51,1,stone:0)
Block(-6,51,2,stone:0)
Block(-6,51,3,stone:0)
Block(-6,51,4,stone:0)
Block(-6,51,5,stone:0)
Block(-6,51,6,stone:0)
Block(-6,51,7,stone:0)
Block(-6,51,8,stone:0)
Block(-6,52,-7,stone:0)
Block(-6,52,-6,stone:0)
Block(-6,52,-5,stone:0)
Block(-6,52,-4,stone:0)
Block(-6,52,-3,stone:0)
Block(-6,52,-2,stone:0)
Block(-6,52,-1,stone:0)
Block(-6,52,0,stone:0)
Block(-6,52,1,stone:0)
Block(-6,52,2,stone:0)
Block(-6,52,3,stone:0)
Block(-6,52,4,stone:0)
Block(-6,52,5,stone:0)
Block(-6,52,6,stone:0)
Block(-6,52,7,stone:0)
Block(-6,52,8,stone:0)
Block(-6,53,-7,stone:0)
Block(-6,53,-6,stone:0)
Block(-6,53,-5,stone:0)
Block(-6,53,-4,stone:0)
Block(-6,53,-3,stone:0)
Block(-6,53,-2,stone:0)
Block(-6,53,-1,stone:0)
Block(-6,53,0,stone:0)
Block(-6,53,1,stone:0)
Block(-6,53,2,stone:0)
Block(-6,53,3,stone:0)
Block(-6,53,4,stone:0)
Block(-6,53,5,stone:0)
Block(-6,53,6,stone:0)
Block(-6,53,7,stone:0)
Block(-6,53,8,stone:0)
Block(-6,54,-7,stone:0)
Block(-6,54,-6,stone:0)
Block(-6,54,-5,stone:0)
Block(-6,54,-4,stone:0)
Block(-6,54,-3,stone:0)
Block(-6,54,-2,stone:0)
Block(-6,54,-1,stone:0)
Block(-6,54,0,stone:0)
Block(-6,54,1,stone:0)
Block(-6,54,2,stone:0)
Block(-6,54,3,stone:0)
Block(-6,54,4,stone:0)
Block(-6,54,5,stone:0)
Block(-6,54,6,stone:0)
Block(-6,54,7,stone:0)
Block(-6,54,8,stone:0)
Block(-6,55,-7,stone:0)
Block(-6,55,-6,stone:0)
Block(-6,55,-5,stone:0)
Block(-6,55,-4,stone:0)
Block(-6,55,-3,stone:0)
Block(-6,55,-2,stone:0)
Block(-6,55,-1,stone:0)
Block(-6,55,0,stone:0)
Block(-6,55,1,stone:0)
Block(-6,55,2,stone:0)
Block(-6,55,3,stone:0)
Block(-6,55,4,stone:0)
Block(-6,55,5,stone:0)
Block(-6,55,6,stone:0)
Block(-6,55,7,stone:0)
Block(-6,55,8,stone:0)
Block(-6,56,-7,stone:0)
Block(-6,56,-6,stone:0)
Block(-6,56,-5,stone:0)
Block(-6,56,-4,stone:0)
Block(-6,56,-3,stone:0)
Block(-6,56,-2,stone:0)
Block(-6,56,-1,stone:0)
Block(-6,56,0,stone:0)
Block(-6,56,1,stone:0)
Block(-6,56,2,stone:0)
Block(-6,56,3,stone:0)
Block(-6,56,4,stone:0)
Block(-6,56,5,stone:0)
Block(-6,56,6,stone:0)
Block(-6,56,7,stone:0)
Block(-6,56,8,stone:0)
Block(-6,57,-7,stone:0)
Block(-6,57,-6,stone:0)
Block(-6,57,-5,stone:0)
Block(-6,57,-4,stone:0)
Block(-6,57,-3,stone:0)
Block(-6,57,-2,stone:0)
Block(-6,57,-1,stone:0)
Block(-6,57,0,stone:0)
Block(-6,57,1,stone:0)
Block(-6,57,2,stone:0)
Block(-6,57,3,stone:0)
Block(-6,57,4,stone:0)
Block(-6,57,5,stone:0)
Block(-6,57,6,stone:0)
Block(-6,57,7,stone:0)
Block(-6,57,8,stone:0)
Block(-6,58,-7,stone:0)
Block(-6,58,-6,stone:0)
Block(-6,58,-5,stone:0)
Block(-6,58,-4,stone:0)
Block(-6,58,-3,stone:0)
Block(-6,58,-2,stone:0)
Block(-6,58,-1,stone:0)
Block(-6,58,0,stone:0)
Block(-6,58,1,stone:0)
Block(-6,58,2,stone:0)
Block(-6,58,3,stone:0)
Block(-6,58,4,stone:0)
Block(-6,58,5,stone:0)
Block(-6,58,6,stone:0)
Block(-6,58,7,stone:0)
Block(-6,58,8,stone:0)
Block(-6,59,-7,stone:0)
Block(-6,59,-6,stone:0)
Block(-6,59,-5,stone:0)
Block(-6,59,-4,stone:0)
Block(-6,59,-3,stone:0)
Block(-6,59,-2,stone:0)
Block(-6,59,-1,stone:0)
Block(-6,59,0,stone:0)
Block(-6,59,1,stone:0)
Block(-6,59,2,stone:0)
Block(-6,59,3,stone:0)
Block(-6,59,4,stone:0)
Block(-6,59,5,stone:0)
Block(-6,59,6,stone:0)
Block(-6,59,7,stone:0)
Block(-6,59,8,stone:0)
Block(-6,60,-7,stone:0)
Block(-6,60,-6,stone:0)
Block(-6,60,-5,stone:0)
Block(-6,60,-4,stone:0)
Block(-6,60,-3,stone:0)
Block(-6,60,-2,stone:0)
Block(-6,60,-1,stone:0)
Block(-6,60,0,stone:0)
Block(-6,60,1,stone:0)
Block(-6,60,2,stone:0)
Block(-6,60,3,stone:0)
Block(-6,60,4,stone:0)
Block(-6,60,5,stone:0)
Block(-6,60,6,stone:0)
Block(-6,60,7,stone:0)
Block(-6,60,8,stone:0)
Block(-6,61,-7,stone:0)
Block(-6,61,-6,stone:0)
Block(-6,61,-5,stone:0)
Block(-6,61,-4,stone:0)
Block(-6,61,-3,stone:0)
Block(-6,61,-2,stone:0)
Block(-6,61,-1,stone:0)
Block(-6,61,0,stone:0)
Block(-6,61,1,stone:0)
Block(-6,61,2,stone:0)
Block(-6,61,3,stone:0)
Block(-6,61,4,stone:0)
Block(-6,61,5,stone:0)
Block(-6,61,6,stone:0)
Block(-6,61,7,stone:0)
Block(-6,61,8,stone:0)
Block(-6,62,-7,stone:0)
Block(-6,62,-6,stone:0)
Block(-6,62,-5,stone:0)
Block(-6,62,-4,stone:0)
Block(-6,62,-3,stone:0)
Block(-6,62,-2,stone:0)
Block(-6,62,-1,stone:0)
Block(-6,62,0,stone:0)
Block(-6,62,1,stone:0)
Block(-6,62,2,stone:0)
Block(-6,62,3,stone:0)
Block(-6,62,4,stone:0)
Block(-6,62,5,stone:0)
Block(-6,62,6,stone:0)
Block(-6,62,7,stone:0)
Block(-6,62,8,stone:0)
Block(-6,63,-7,stone:0)
Block(-6,63,-6,stone:0)
Block(-6,63,-5,stone:0)
Block(-6,63,-4,stone:0)
Block(-6,63,-3,stone:0)
Block(-6,63,-2,stone:0)
Block(-6,63,-1,stone:0)
Block(-6,63,0,stone:0)
Block(-6,63,1,stone:0)
Block(-6,63,2,stone:0)
Block(-6,63,3,stone:0)
Block(-6,63,4,stone:0)
Block(-6,63,5,stone:0)
Block(-6,63,6,stone:0)
Block(-6,63,7,stone:0)
Block(-6,63,8,stone:0)
RandomBlock(-6,64,-7,STONEBRICK:1,10,STONEBRICK:2,10,COBBLESTONE,10,MOSSY_COBBLESTONE,10,SMOOTH_BRICK,100)
RandomBlock(-6,64,-6,STONEBRICK:1,10,STONEBRICK:2,10,COBBLESTONE,10,MOSSY_COBBLESTONE,10,SMOOTH_BRICK,100)
RandomBlock(-6,64,-5,STONEBRICK:1,10,STONEBRICK:2,10,COBBLESTONE,10,MOSSY_COBBLESTONE,10,SMOOTH_BRICK,100)
RandomBlock(-6,64,-4,STONEBRICK:1,10,STONEBRICK:2,10,COBBLESTONE,10,MOSSY_COBBLESTONE,10,SMOOTH_BRICK,100)
RandomBlock(-6,64,-3,STONEBRICK:1,10,STONEBRICK:2,10,COBBLESTONE,10,MOSSY_COBBLESTONE,10,SMOOTH_BRICK,100)
RandomBlock(-6,64,-2,STONEBRICK:1,10,STONEBRICK:2,10,COBBLESTONE,10,MOSSY_COBBLESTONE,10,SMOOTH_BRICK,100)
Block(-6,64,-1,stone:0)
Block(-6,64,0,stone:0)
Block(-6,64,1,stone:0)
Block(-6,64,2,stone:0)
Block(-6,64,3,stone:0)
Block(-6,64,4,stone:0)
Block(-6,64,5,stone:0)
Block(-6,64,6,stone:0)
Block(-6,64,7,stone:0)
Block(-6,64,8,stone:0)
