
#######################################################################
# +-----------------------------------------------------------------+ #
# |                            BO4 object                           | #
# +-----------------------------------------------------------------+ #
#######################################################################

Author: NLBlackEagle

Description: No description given

SettingsMode: WriteWithoutComments


#######################################################################
# +-----------------------------------------------------------------+ #
# |                          Main settings                          | #
# +-----------------------------------------------------------------+ #
#######################################################################

FixedRotation: 

Frequency: 0

SpawnHeight: highestBlock

UseCenterForHighestBlock: true

##############################
# Height Limits for the BO4. #
##############################

MinHeight: 0

MaxHeight: 255

InheritBO3: 

InheritBO3Rotation: NORTH

OverrideChildSettings: true

OverrideParentHeight: false

CanOverride: true

BranchFrequency: 0

BranchFrequencyGroup: 

MustBeBelowOther: false

MustBeInside: 

CannotBeInside: 

ReplacesBO3: 

MustBeInsideWorldBorders: false

CanSpawnOnWater: true

SpawnOnWaterOnly: false

SpawnUnderWater: false

SpawnAtWaterLevel: false

HeightOffset: 0

RemoveAir: false

ReplaceAbove: 

ReplaceBelow: 

ReplaceWithBiomeBlocks: false

ReplaceWithSurfaceBlock: GRASS

ReplaceWithGroundBlock: DIRT

ReplaceWithStoneBlock: STONE

SmoothRadius: 0

SmoothHeightOffset: 0

SmoothStartTop: false

SmoothStartWood: false

SmoothingSurfaceBlock: 

SmoothingGroundBlock: 

BO3Group: 

IsSpawnPoint: false

DoReplaceBlocks: true


#######################################################################
# +-----------------------------------------------------------------+ #
# |                              Blocks                             | #
# +-----------------------------------------------------------------+ #
#######################################################################

Block(-8,0,-7,STONE:0)
Block(-8,0,-6,STONE:0)
Block(-8,0,-5,STONE:0)
Block(-8,0,-4,STONE:0)
Block(-8,0,-3,STONE:0)
Block(-8,0,-2,STONE:0)
Block(-8,0,-1,STONE:0)
Block(-8,0,0,STONE:0)
Block(-8,0,1,STONE:0)
Block(-8,0,2,STONE:0)
Block(-8,0,3,STONE:0)
Block(-8,0,4,STONE:0)
Block(-8,0,5,STONE:0)
Block(-8,0,6,STONE:0)
Block(-8,1,-7,STONE:0)
Block(-8,1,-6,STONE:0)
Block(-8,1,-5,STONE:0)
Block(-8,1,-4,STONE:0)
Block(-8,1,-3,STONE:0)
Block(-8,1,-2,STONE:0)
Block(-8,1,-1,STONE:0)
Block(-8,1,0,STONE:0)
Block(-8,1,1,STONE:0)
Block(-8,1,2,STONE:0)
Block(-8,1,3,STONE:0)
Block(-8,1,4,STONE:0)
Block(-8,1,5,STONE:0)
Block(-8,1,6,STONE:0)
Block(-8,2,-7,STONE:0)
Block(-8,2,-6,STONE:0)
Block(-8,2,-5,STONE:0)
Block(-8,2,-4,STONE:0)
Block(-8,2,-3,STONE:0)
Block(-8,2,-2,STONE:0)
Block(-8,2,-1,STONE:0)
Block(-8,2,0,STONE:0)
Block(-8,2,1,STONE:0)
Block(-8,2,2,STONE:0)
Block(-8,2,3,STONE:0)
Block(-8,2,4,STONE:0)
Block(-8,2,5,STONE:0)
Block(-8,2,6,STONE:0)
Block(-8,3,-7,STONE:0)
Block(-8,3,-6,STONE:0)
Block(-8,3,-5,STONE:0)
Block(-8,3,-4,STONE:0)
Block(-8,3,-3,STONE:0)
Block(-8,3,-2,STONE:0)
Block(-8,3,-1,STONE:0)
Block(-8,3,0,STONE:0)
Block(-8,3,1,STONE:0)
Block(-8,3,2,STONE:0)
Block(-8,3,3,STONE:0)
Block(-8,3,4,STONE:0)
Block(-8,3,5,STONE:0)
Block(-8,3,6,STONE:0)
Block(-8,4,-7,STONE:0)
Block(-8,4,-6,STONE:0)
Block(-8,4,-5,STONE:0)
Block(-8,4,-4,DIRT:0)
Block(-8,4,-3,DIRT:0)
Block(-8,4,-2,DIRT:0)
Block(-8,4,-1,STONE:0)
Block(-8,4,0,STONE:0)
Block(-8,4,1,STONE:0)
Block(-8,4,2,STONE:0)
Block(-8,4,3,STONE:0)
Block(-8,4,4,STONE:0)
Block(-8,4,5,STONE:0)
Block(-8,4,6,STONE:0)
Block(-8,5,-7,DIRT:0)
Block(-8,5,-6,DIRT:0)
Block(-8,5,-5,DIRT:0)
Block(-8,5,-4,DIRT:0)
Block(-8,5,-3,DIRT:0)
Block(-8,5,-2,DIRT:0)
Block(-8,5,-1,DIRT:0)
Block(-8,5,0,DIRT:0)
Block(-8,5,1,DIRT:0)
Block(-8,5,2,DIRT:0)
Block(-8,5,3,DIRT:0)
Block(-8,5,4,DIRT:0)
Block(-8,5,5,DIRT:0)
Block(-8,5,6,DIRT:0)
Block(-8,6,-7,DIRT:0)
Block(-8,6,-6,DIRT:0)
Block(-8,6,-5,DIRT:0)
Block(-8,6,-4,DIRT:0)
Block(-8,6,-3,DIRT:0)
Block(-8,6,-2,DIRT:0)
Block(-8,6,-1,DIRT:0)
Block(-8,6,0,DIRT:0)
Block(-8,6,1,DIRT:0)
Block(-8,6,2,DIRT:0)
Block(-8,6,3,DIRT:0)
Block(-8,6,4,DIRT:0)
Block(-8,6,5,DIRT:0)
Block(-8,6,6,DIRT:0)
Block(-8,7,-7,DIRT:0)
Block(-8,7,-6,DIRT:0)
Block(-8,7,-5,DIRT:0)
Block(-8,7,-4,DIRT:0)
Block(-8,7,-3,DIRT:0)
Block(-8,7,-2,DIRT:0)
Block(-8,7,-1,DIRT:0)
Block(-8,7,0,DIRT:0)
Block(-8,7,1,DIRT:0)
Block(-8,7,2,DIRT:0)
Block(-8,7,3,DIRT:0)
Block(-8,7,4,DIRT:0)
Block(-8,7,5,DIRT:0)
Block(-8,7,6,DIRT:0)
Block(-8,8,-5,DIRT:0)
Block(-8,8,-4,DIRT:0)
Block(-8,8,-3,DIRT:0)
Block(-8,8,-2,DIRT:0)
Block(-8,8,-1,DIRT:0)
Block(-8,8,0,DIRT:0)
Block(-8,8,1,DIRT:0)
Block(-8,8,2,DIRT:0)
Block(-8,8,3,DIRT:0)
Block(-8,8,4,DIRT:0)
RandomBlock(-8,9,-5,MONSTER_EGGS:4,null,6,MONSTER_EGGS:2,null,18,MONSTER_EGGS:3,null,6,SMOOTH_BRICK:2,null,12,SMOOTH_BRICK:1,null,12,SMOOTH_BRICK:0,null,80,COBBLESTONE:0,null,100)
RandomBlock(-8,9,-4,MONSTER_EGGS:4,null,6,MONSTER_EGGS:2,null,18,MONSTER_EGGS:3,null,6,SMOOTH_BRICK:2,null,12,SMOOTH_BRICK:1,null,12,SMOOTH_BRICK:0,null,80,COBBLESTONE:0,null,100)
RandomBlock(-8,9,-3,MONSTER_EGGS:4,null,6,MONSTER_EGGS:2,null,18,MONSTER_EGGS:3,null,6,SMOOTH_BRICK:2,null,12,SMOOTH_BRICK:1,null,12,SMOOTH_BRICK:0,null,80,COBBLESTONE:0,null,100)
RandomBlock(-8,9,-2,MONSTER_EGGS:4,null,6,MONSTER_EGGS:2,null,18,MONSTER_EGGS:3,null,6,SMOOTH_BRICK:2,null,12,SMOOTH_BRICK:1,null,12,SMOOTH_BRICK:0,null,80,COBBLESTONE:0,null,100)
RandomBlock(-8,9,-1,MONSTER_EGGS:4,null,6,MONSTER_EGGS:2,null,18,MONSTER_EGGS:3,null,6,SMOOTH_BRICK:2,null,12,SMOOTH_BRICK:1,null,12,SMOOTH_BRICK:0,null,80,COBBLESTONE:0,null,100)
RandomBlock(-8,9,0,MONSTER_EGGS:4,null,6,MONSTER_EGGS:2,null,18,MONSTER_EGGS:3,null,6,SMOOTH_BRICK:2,null,12,SMOOTH_BRICK:1,null,12,SMOOTH_BRICK:0,null,80,COBBLESTONE:0,null,100)
RandomBlock(-8,9,1,MONSTER_EGGS:4,null,6,MONSTER_EGGS:2,null,18,MONSTER_EGGS:3,null,6,SMOOTH_BRICK:2,null,12,SMOOTH_BRICK:1,null,12,SMOOTH_BRICK:0,null,80,COBBLESTONE:0,null,100)
RandomBlock(-8,9,2,MONSTER_EGGS:4,null,6,MONSTER_EGGS:2,null,18,MONSTER_EGGS:3,null,6,SMOOTH_BRICK:2,null,12,SMOOTH_BRICK:1,null,12,SMOOTH_BRICK:0,null,80,COBBLESTONE:0,null,100)
RandomBlock(-8,9,3,MONSTER_EGGS:4,null,6,MONSTER_EGGS:2,null,18,MONSTER_EGGS:3,null,6,SMOOTH_BRICK:2,null,12,SMOOTH_BRICK:1,null,12,SMOOTH_BRICK:0,null,80,COBBLESTONE:0,null,100)
RandomBlock(-8,9,4,MONSTER_EGGS:4,null,6,MONSTER_EGGS:2,null,18,MONSTER_EGGS:3,null,6,SMOOTH_BRICK:2,null,12,SMOOTH_BRICK:1,null,12,SMOOTH_BRICK:0,null,80,COBBLESTONE:0,null,100)
Block(-7,0,-7,STONE:0)
Block(-7,0,-6,STONE:0)
Block(-7,0,-5,STONE:0)
Block(-7,0,-4,STONE:0)
Block(-7,0,-3,STONE:0)
Block(-7,0,-2,STONE:0)
Block(-7,0,-1,STONE:0)
Block(-7,0,0,STONE:0)
Block(-7,0,1,STONE:0)
Block(-7,0,2,STONE:0)
Block(-7,0,3,STONE:0)
Block(-7,0,4,STONE:0)
Block(-7,0,5,STONE:0)
Block(-7,0,6,STONE:0)
Block(-7,1,-7,STONE:0)
Block(-7,1,-6,STONE:0)
Block(-7,1,-5,STONE:0)
Block(-7,1,-4,STONE:0)
Block(-7,1,-3,STONE:0)
Block(-7,1,-2,STONE:0)
Block(-7,1,-1,STONE:0)
Block(-7,1,0,STONE:0)
Block(-7,1,1,STONE:0)
Block(-7,1,2,STONE:0)
Block(-7,1,3,STONE:0)
Block(-7,1,4,STONE:0)
Block(-7,1,5,STONE:0)
Block(-7,1,6,STONE:0)
Block(-7,2,-7,STONE:0)
Block(-7,2,-6,STONE:0)
Block(-7,2,-5,STONE:0)
Block(-7,2,-4,STONE:0)
Block(-7,2,-3,STONE:0)
Block(-7,2,-2,STONE:0)
Block(-7,2,-1,STONE:0)
Block(-7,2,0,STONE:0)
Block(-7,2,1,STONE:0)
Block(-7,2,2,STONE:0)
Block(-7,2,3,STONE:0)
Block(-7,2,4,STONE:0)
Block(-7,2,5,STONE:0)
Block(-7,2,6,STONE:0)
Block(-7,3,-7,STONE:0)
Block(-7,3,-6,STONE:0)
Block(-7,3,-5,STONE:0)
Block(-7,3,-4,STONE:0)
Block(-7,3,-3,STONE:0)
Block(-7,3,-2,STONE:0)
Block(-7,3,-1,STONE:0)
Block(-7,3,0,STONE:0)
Block(-7,3,1,STONE:0)
Block(-7,3,2,STONE:0)
Block(-7,3,3,STONE:0)
Block(-7,3,4,STONE:0)
Block(-7,3,5,STONE:0)
Block(-7,3,6,STONE:0)
Block(-7,4,-7,STONE:0)
Block(-7,4,-6,STONE:0)
Block(-7,4,-5,DIRT:0)
Block(-7,4,-4,DIRT:0)
Block(-7,4,-3,DIRT:0)
Block(-7,4,-2,DIRT:0)
Block(-7,4,-1,STONE:0)
Block(-7,4,0,STONE:0)
Block(-7,4,1,STONE:0)
Block(-7,4,2,STONE:0)
Block(-7,4,3,STONE:0)
Block(-7,4,4,STONE:0)
Block(-7,4,5,STONE:0)
Block(-7,4,6,STONE:0)
Block(-7,5,-7,DIRT:0)
Block(-7,5,-6,DIRT:0)
Block(-7,5,-5,DIRT:0)
Block(-7,5,-4,DIRT:0)
Block(-7,5,-3,DIRT:0)
Block(-7,5,-2,DIRT:0)
Block(-7,5,-1,DIRT:0)
Block(-7,5,0,DIRT:0)
Block(-7,5,1,DIRT:0)
Block(-7,5,2,DIRT:0)
Block(-7,5,3,DIRT:0)
Block(-7,5,4,DIRT:0)
Block(-7,5,5,DIRT:0)
Block(-7,5,6,DIRT:0)
Block(-7,6,-7,DIRT:0)
Block(-7,6,-6,DIRT:0)
Block(-7,6,-5,DIRT:0)
Block(-7,6,-4,DIRT:0)
Block(-7,6,-3,DIRT:0)
Block(-7,6,-2,DIRT:0)
Block(-7,6,-1,DIRT:0)
Block(-7,6,0,DIRT:0)
Block(-7,6,1,DIRT:0)
Block(-7,6,2,DIRT:0)
Block(-7,6,3,DIRT:0)
Block(-7,6,4,DIRT:0)
Block(-7,6,5,DIRT:0)
Block(-7,6,6,DIRT:0)
Block(-7,7,-7,DIRT:0)
Block(-7,7,-6,DIRT:0)
Block(-7,7,-5,DIRT:0)
Block(-7,7,-4,DIRT:0)
Block(-7,7,-3,DIRT:0)
Block(-7,7,-2,DIRT:0)
Block(-7,7,-1,DIRT:0)
Block(-7,7,0,DIRT:0)
Block(-7,7,1,DIRT:0)
Block(-7,7,2,DIRT:0)
Block(-7,7,3,DIRT:0)
Block(-7,7,4,DIRT:0)
Block(-7,7,5,DIRT:0)
Block(-7,7,6,DIRT:0)
RandomBlock(-7,8,-5,MONSTER_EGGS:4,null,6,MONSTER_EGGS:2,null,18,MONSTER_EGGS:3,null,6,SMOOTH_BRICK:2,null,12,SMOOTH_BRICK:1,null,12,SMOOTH_BRICK:0,null,80,COBBLESTONE:0,null,100)
RandomBlock(-7,8,-4,MONSTER_EGGS:4,null,6,MONSTER_EGGS:2,null,18,MONSTER_EGGS:3,null,6,SMOOTH_BRICK:2,null,12,SMOOTH_BRICK:1,null,12,SMOOTH_BRICK:0,null,80,COBBLESTONE:0,null,100)
RandomBlock(-7,8,-3,MONSTER_EGGS:4,null,6,MONSTER_EGGS:2,null,18,MONSTER_EGGS:3,null,6,SMOOTH_BRICK:2,null,12,SMOOTH_BRICK:1,null,12,SMOOTH_BRICK:0,null,80,COBBLESTONE:0,null,100)
RandomBlock(-7,8,-2,MONSTER_EGGS:4,null,6,MONSTER_EGGS:2,null,18,MONSTER_EGGS:3,null,6,SMOOTH_BRICK:2,null,12,SMOOTH_BRICK:1,null,12,SMOOTH_BRICK:0,null,80,COBBLESTONE:0,null,100)
RandomBlock(-7,8,-1,MONSTER_EGGS:4,null,6,MONSTER_EGGS:2,null,18,MONSTER_EGGS:3,null,6,SMOOTH_BRICK:2,null,12,SMOOTH_BRICK:1,null,12,SMOOTH_BRICK:0,null,80,COBBLESTONE:0,null,100)
RandomBlock(-7,8,0,MONSTER_EGGS:4,null,6,MONSTER_EGGS:2,null,18,MONSTER_EGGS:3,null,6,SMOOTH_BRICK:2,null,12,SMOOTH_BRICK:1,null,12,SMOOTH_BRICK:0,null,80,COBBLESTONE:0,null,100)
RandomBlock(-7,8,1,MONSTER_EGGS:4,null,6,MONSTER_EGGS:2,null,18,MONSTER_EGGS:3,null,6,SMOOTH_BRICK:2,null,12,SMOOTH_BRICK:1,null,12,SMOOTH_BRICK:0,null,80,COBBLESTONE:0,null,100)
RandomBlock(-7,8,2,MONSTER_EGGS:4,null,6,MONSTER_EGGS:2,null,18,MONSTER_EGGS:3,null,6,SMOOTH_BRICK:2,null,12,SMOOTH_BRICK:1,null,12,SMOOTH_BRICK:0,null,80,COBBLESTONE:0,null,100)
RandomBlock(-7,8,3,MONSTER_EGGS:4,null,6,MONSTER_EGGS:2,null,18,MONSTER_EGGS:3,null,6,SMOOTH_BRICK:2,null,12,SMOOTH_BRICK:1,null,12,SMOOTH_BRICK:0,null,80,COBBLESTONE:0,null,100)
RandomBlock(-7,8,4,MONSTER_EGGS:4,null,6,MONSTER_EGGS:2,null,18,MONSTER_EGGS:3,null,6,SMOOTH_BRICK:2,null,12,SMOOTH_BRICK:1,null,12,SMOOTH_BRICK:0,null,80,COBBLESTONE:0,null,100)
RandomBlock(-7,9,-5,MONSTER_EGGS:4,null,6,MONSTER_EGGS:2,null,18,MONSTER_EGGS:3,null,6,SMOOTH_BRICK:2,null,12,SMOOTH_BRICK:1,null,12,SMOOTH_BRICK:0,null,80,COBBLESTONE:0,null,100)
RandomBlock(-7,9,-4,MONSTER_EGGS:4,null,6,MONSTER_EGGS:2,null,18,MONSTER_EGGS:3,null,6,SMOOTH_BRICK:2,null,12,SMOOTH_BRICK:1,null,12,SMOOTH_BRICK:0,null,80,COBBLESTONE:0,null,100)
RandomBlock(-7,9,-3,MONSTER_EGGS:4,null,6,MONSTER_EGGS:2,null,18,MONSTER_EGGS:3,null,6,SMOOTH_BRICK:2,null,12,SMOOTH_BRICK:1,null,12,SMOOTH_BRICK:0,null,80,COBBLESTONE:0,null,100)
RandomBlock(-7,9,-2,MONSTER_EGGS:4,null,6,MONSTER_EGGS:2,null,18,MONSTER_EGGS:3,null,6,SMOOTH_BRICK:2,null,12,SMOOTH_BRICK:1,null,12,SMOOTH_BRICK:0,null,80,COBBLESTONE:0,null,100)
Block(-7,9,-1,AIR:0)
Block(-7,9,0,AIR:0)
RandomBlock(-7,9,1,MONSTER_EGGS:4,null,6,MONSTER_EGGS:2,null,18,MONSTER_EGGS:3,null,6,SMOOTH_BRICK:2,null,12,SMOOTH_BRICK:1,null,12,SMOOTH_BRICK:0,null,80,COBBLESTONE:0,null,100)
RandomBlock(-7,9,2,MONSTER_EGGS:4,null,6,MONSTER_EGGS:2,null,18,MONSTER_EGGS:3,null,6,SMOOTH_BRICK:2,null,12,SMOOTH_BRICK:1,null,12,SMOOTH_BRICK:0,null,80,COBBLESTONE:0,null,100)
RandomBlock(-7,9,3,MONSTER_EGGS:4,null,6,MONSTER_EGGS:2,null,18,MONSTER_EGGS:3,null,6,SMOOTH_BRICK:2,null,12,SMOOTH_BRICK:1,null,12,SMOOTH_BRICK:0,null,80,COBBLESTONE:0,null,100)
RandomBlock(-7,9,4,MONSTER_EGGS:4,null,6,MONSTER_EGGS:2,null,18,MONSTER_EGGS:3,null,6,SMOOTH_BRICK:2,null,12,SMOOTH_BRICK:1,null,12,SMOOTH_BRICK:0,null,80,COBBLESTONE:0,null,100)
Block(-7,10,-4,AIR:0)
Block(-7,10,-3,AIR:0)
Block(-7,10,-2,AIR:0)
Block(-7,10,-1,AIR:0)
Block(-7,10,0,AIR:0)
Block(-7,10,1,AIR:0)
Block(-7,10,2,AIR:0)
Block(-7,11,-4,AIR:0)
Block(-7,11,-3,AIR:0)
Block(-7,11,-2,AIR:0)
Block(-7,11,-1,AIR:0)
Block(-7,11,0,AIR:0)
Block(-7,11,1,AIR:0)
Block(-7,11,2,AIR:0)
Block(-6,0,-7,STONE:0)
Block(-6,0,-6,STONE:0)
Block(-6,0,-5,STONE:0)
Block(-6,0,-4,STONE:0)
Block(-6,0,-3,STONE:0)
Block(-6,0,-2,STONE:0)
Block(-6,0,-1,STONE:0)
Block(-6,0,0,STONE:0)
Block(-6,0,1,STONE:0)
Block(-6,0,2,STONE:0)
Block(-6,0,3,STONE:0)
Block(-6,0,4,STONE:0)
Block(-6,0,5,STONE:0)
Block(-6,0,6,STONE:0)
Block(-6,1,-7,STONE:0)
Block(-6,1,-6,STONE:0)
Block(-6,1,-5,STONE:0)
Block(-6,1,-4,STONE:0)
Block(-6,1,-3,STONE:0)
Block(-6,1,-2,STONE:0)
Block(-6,1,-1,STONE:0)
Block(-6,1,0,STONE:0)
Block(-6,1,1,STONE:0)
Block(-6,1,2,STONE:0)
Block(-6,1,3,STONE:0)
Block(-6,1,4,STONE:0)
Block(-6,1,5,STONE:0)
Block(-6,1,6,STONE:0)
Block(-6,2,-7,STONE:0)
Block(-6,2,-6,STONE:0)
Block(-6,2,-5,STONE:0)
Block(-6,2,-4,STONE:0)
Block(-6,2,-3,STONE:0)
Block(-6,2,-2,STONE:0)
Block(-6,2,-1,STONE:0)
Block(-6,2,0,STONE:0)
Block(-6,2,1,STONE:0)
Block(-6,2,2,STONE:0)
Block(-6,2,3,STONE:0)
Block(-6,2,4,STONE:0)
Block(-6,2,5,STONE:0)
Block(-6,2,6,STONE:0)
Block(-6,3,-7,STONE:0)
Block(-6,3,-6,STONE:0)
Block(-6,3,-5,STONE:0)
Block(-6,3,-4,STONE:0)
Block(-6,3,-3,STONE:0)
Block(-6,3,-2,STONE:0)
Block(-6,3,-1,STONE:0)
Block(-6,3,0,STONE:0)
Block(-6,3,1,STONE:0)
Block(-6,3,2,STONE:0)
Block(-6,3,3,STONE:0)
Block(-6,3,4,STONE:0)
Block(-6,3,5,STONE:0)
Block(-6,3,6,STONE:0)
Block(-6,4,-7,STONE:0)
Block(-6,4,-6,DIRT:0)
Block(-6,4,-5,DIRT:0)
Block(-6,4,-4,DIRT:0)
Block(-6,4,-3,STONE:0)
Block(-6,4,-2,STONE:0)
Block(-6,4,-1,STONE:0)
Block(-6,4,0,STONE:0)
Block(-6,4,1,STONE:0)
Block(-6,4,2,STONE:0)
Block(-6,4,3,STONE:0)
Block(-6,4,4,STONE:0)
Block(-6,4,5,STONE:0)
Block(-6,4,6,STONE:0)
Block(-6,5,-7,DIRT:0)
Block(-6,5,-6,DIRT:0)
Block(-6,5,-5,DIRT:0)
Block(-6,5,-4,DIRT:0)
Block(-6,5,-3,DIRT:0)
Block(-6,5,-2,DIRT:0)
Block(-6,5,-1,DIRT:0)
Block(-6,5,0,DIRT:0)
Block(-6,5,1,DIRT:0)
Block(-6,5,2,DIRT:0)
Block(-6,5,3,DIRT:0)
Block(-6,5,4,DIRT:0)
Block(-6,5,5,DIRT:0)
Block(-6,5,6,DIRT:0)
Block(-6,6,-7,DIRT:0)
Block(-6,6,-6,DIRT:0)
Block(-6,6,-5,DIRT:0)
Block(-6,6,-4,DIRT:0)
Block(-6,6,-3,DIRT:0)
Block(-6,6,-2,DIRT:0)
Block(-6,6,-1,DIRT:0)
Block(-6,6,0,DIRT:0)
Block(-6,6,1,DIRT:0)
Block(-6,6,2,DIRT:0)
Block(-6,6,3,DIRT:0)
Block(-6,6,4,DIRT:0)
Block(-6,6,5,DIRT:0)
Block(-6,6,6,DIRT:0)
Block(-6,7,-7,DIRT:0)
Block(-6,7,-6,DIRT:0)
Block(-6,7,-5,DIRT:0)
Block(-6,7,-4,DIRT:0)
Block(-6,7,-3,DIRT:0)
RandomBlock(-6,7,-2,MONSTER_EGGS:4,null,6,MONSTER_EGGS:2,null,18,MONSTER_EGGS:3,null,6,SMOOTH_BRICK:2,null,12,SMOOTH_BRICK:1,null,12,SMOOTH_BRICK:0,null,80,COBBLESTONE:0,null,100)
RandomBlock(-6,7,-1,MONSTER_EGGS:4,null,6,MONSTER_EGGS:2,null,18,MONSTER_EGGS:3,null,6,SMOOTH_BRICK:2,null,12,SMOOTH_BRICK:1,null,12,SMOOTH_BRICK:0,null,80,COBBLESTONE:0,null,100)
RandomBlock(-6,7,0,MONSTER_EGGS:4,null,6,MONSTER_EGGS:2,null,18,MONSTER_EGGS:3,null,6,SMOOTH_BRICK:2,null,12,SMOOTH_BRICK:1,null,12,SMOOTH_BRICK:0,null,80,COBBLESTONE:0,null,100)
Block(-6,7,1,DIRT:0)
Block(-6,7,2,DIRT:0)
Block(-6,7,3,DIRT:0)
Block(-6,7,4,DIRT:0)
Block(-6,7,5,DIRT:0)
Block(-6,7,6,DIRT:0)
RandomBlock(-6,8,-5,MONSTER_EGGS:4,null,6,MONSTER_EGGS:2,null,18,MONSTER_EGGS:3,null,6,SMOOTH_BRICK:2,null,12,SMOOTH_BRICK:1,null,12,SMOOTH_BRICK:0,null,80,COBBLESTONE:0,null,100)
RandomBlock(-6,8,-4,MONSTER_EGGS:4,null,6,MONSTER_EGGS:2,null,18,MONSTER_EGGS:3,null,6,SMOOTH_BRICK:2,null,12,SMOOTH_BRICK:1,null,12,SMOOTH_BRICK:0,null,80,COBBLESTONE:0,null,100)
RandomBlock(-6,8,-3,MONSTER_EGGS:4,null,6,MONSTER_EGGS:2,null,18,MONSTER_EGGS:3,null,6,SMOOTH_BRICK:2,null,12,SMOOTH_BRICK:1,null,12,SMOOTH_BRICK:0,null,80,COBBLESTONE:0,null,100)
RandomBlock(-6,8,-2,MONSTER_EGGS:4,null,6,MONSTER_EGGS:2,null,18,MONSTER_EGGS:3,null,6,SMOOTH_BRICK:2,null,12,SMOOTH_BRICK:1,null,12,SMOOTH_BRICK:0,null,80,COBBLESTONE:0,null,100)
Block(-6,8,-1,AIR:0)
Block(-6,8,0,AIR:0)
RandomBlock(-6,8,1,MONSTER_EGGS:4,null,6,MONSTER_EGGS:2,null,18,MONSTER_EGGS:3,null,6,SMOOTH_BRICK:2,null,12,SMOOTH_BRICK:1,null,12,SMOOTH_BRICK:0,null,80,COBBLESTONE:0,null,100)
RandomBlock(-6,8,2,MONSTER_EGGS:4,null,6,MONSTER_EGGS:2,null,18,MONSTER_EGGS:3,null,6,SMOOTH_BRICK:2,null,12,SMOOTH_BRICK:1,null,12,SMOOTH_BRICK:0,null,80,COBBLESTONE:0,null,100)
RandomBlock(-6,8,3,MONSTER_EGGS:4,null,6,MONSTER_EGGS:2,null,18,MONSTER_EGGS:3,null,6,SMOOTH_BRICK:2,null,12,SMOOTH_BRICK:1,null,12,SMOOTH_BRICK:0,null,80,COBBLESTONE:0,null,100)
RandomBlock(-6,8,4,MONSTER_EGGS:4,null,6,MONSTER_EGGS:2,null,18,MONSTER_EGGS:3,null,6,SMOOTH_BRICK:2,null,12,SMOOTH_BRICK:1,null,12,SMOOTH_BRICK:0,null,80,COBBLESTONE:0,null,100)
RandomBlock(-6,9,-5,MONSTER_EGGS:4,null,6,MONSTER_EGGS:2,null,18,MONSTER_EGGS:3,null,6,SMOOTH_BRICK:2,null,12,SMOOTH_BRICK:1,null,12,SMOOTH_BRICK:0,null,80,COBBLESTONE:0,null,100)
RandomBlock(-6,9,-4,MONSTER_EGGS:4,null,6,MONSTER_EGGS:2,null,18,MONSTER_EGGS:3,null,6,SMOOTH_BRICK:2,null,12,SMOOTH_BRICK:1,null,12,SMOOTH_BRICK:0,null,80,COBBLESTONE:0,null,100)
Block(-6,9,-3,AIR:0)
Block(-6,9,-2,AIR:0)
Block(-6,9,-1,AIR:0)
Block(-6,9,0,AIR:0)
Block(-6,9,1,AIR:0)
Block(-6,9,2,AIR:0)
RandomBlock(-6,9,3,MONSTER_EGGS:4,null,6,MONSTER_EGGS:2,null,18,MONSTER_EGGS:3,null,6,SMOOTH_BRICK:2,null,12,SMOOTH_BRICK:1,null,12,SMOOTH_BRICK:0,null,80,COBBLESTONE:0,null,100)
RandomBlock(-6,9,4,MONSTER_EGGS:4,null,6,MONSTER_EGGS:2,null,18,MONSTER_EGGS:3,null,6,SMOOTH_BRICK:2,null,12,SMOOTH_BRICK:1,null,12,SMOOTH_BRICK:0,null,80,COBBLESTONE:0,null,100)
Block(-6,10,-5,AIR:0)
Block(-6,10,-4,AIR:0)
Block(-6,10,-3,AIR:0)
Block(-6,10,-2,AIR:0)
Block(-6,10,-1,AIR:0)
Block(-6,10,0,AIR:0)
Block(-6,10,1,AIR:0)
Block(-6,10,2,AIR:0)
Block(-6,10,3,AIR:0)
Block(-6,11,-5,AIR:0)
Block(-6,11,-4,AIR:0)
Block(-6,11,-3,AIR:0)
Block(-6,11,-2,AIR:0)
Block(-6,11,-1,AIR:0)
Block(-6,11,0,AIR:0)
Block(-6,11,1,AIR:0)
Block(-6,11,2,AIR:0)
Block(-6,11,3,AIR:0)
Block(-5,0,-7,STONE:0)
Block(-5,0,-6,STONE:0)
Block(-5,0,-5,STONE:0)
Block(-5,0,-4,STONE:0)
Block(-5,0,-3,STONE:0)
Block(-5,0,-2,STONE:0)
Block(-5,0,-1,STONE:0)
Block(-5,0,0,STONE:0)
Block(-5,0,1,STONE:0)
Block(-5,0,2,STONE:0)
Block(-5,0,3,STONE:0)
Block(-5,0,4,STONE:0)
Block(-5,0,5,STONE:0)
Block(-5,0,6,STONE:0)
Block(-5,1,-7,STONE:0)
Block(-5,1,-6,STONE:0)
Block(-5,1,-5,STONE:0)
Block(-5,1,-4,STONE:0)
Block(-5,1,-3,STONE:0)
Block(-5,1,-2,STONE:0)
Block(-5,1,-1,STONE:0)
Block(-5,1,0,STONE:0)
Block(-5,1,1,STONE:0)
Block(-5,1,2,STONE:0)
Block(-5,1,3,STONE:0)
Block(-5,1,4,STONE:0)
Block(-5,1,5,STONE:0)
Block(-5,1,6,STONE:0)
Block(-5,2,-7,STONE:0)
Block(-5,2,-6,STONE:0)
Block(-5,2,-5,STONE:0)
Block(-5,2,-4,STONE:0)
Block(-5,2,-3,STONE:0)
Block(-5,2,-2,STONE:0)
Block(-5,2,-1,STONE:0)
Block(-5,2,0,STONE:0)
Block(-5,2,1,STONE:0)
Block(-5,2,2,STONE:0)
Block(-5,2,3,STONE:0)
Block(-5,2,4,STONE:0)
Block(-5,2,5,STONE:0)
Block(-5,2,6,STONE:0)
Block(-5,3,-7,STONE:0)
Block(-5,3,-6,STONE:0)
Block(-5,3,-5,STONE:0)
Block(-5,3,-4,STONE:0)
Block(-5,3,-3,DIRT:0)
Block(-5,3,-2,DIRT:0)
Block(-5,3,-1,STONE:0)
Block(-5,3,0,STONE:0)
Block(-5,3,1,STONE:0)
Block(-5,3,2,STONE:0)
Block(-5,3,3,STONE:0)
Block(-5,3,4,STONE:0)
Block(-5,3,5,STONE:0)
Block(-5,3,6,STONE:0)
Block(-5,4,-7,STONE:0)
Block(-5,4,-6,DIRT:0)
Block(-5,4,-5,DIRT:0)
Block(-5,4,-4,STONE:0)
Block(-5,4,-3,DIRT:0)
Block(-5,4,-2,DIRT:0)
Block(-5,4,-1,STONE:0)
Block(-5,4,0,STONE:0)
Block(-5,4,1,STONE:0)
Block(-5,4,2,STONE:0)
Block(-5,4,3,STONE:0)
Block(-5,4,4,STONE:0)
Block(-5,4,5,STONE:0)
Block(-5,4,6,STONE:0)
Block(-5,5,-7,DIRT:0)
Block(-5,5,-6,DIRT:0)
Block(-5,5,-5,DIRT:0)
Block(-5,5,-4,DIRT:0)
RandomBlock(-5,5,-3,MONSTER_EGGS:4,null,6,MONSTER_EGGS:2,null,18,MONSTER_EGGS:3,null,6,SMOOTH_BRICK:2,null,12,SMOOTH_BRICK:1,null,12,SMOOTH_BRICK:0,null,80,COBBLESTONE:0,null,100)
Block(-5,5,-2,DIRT:0)
Block(-5,5,-1,DIRT:0)
Block(-5,5,0,DIRT:0)
Block(-5,5,1,DIRT:0)
Block(-5,5,2,DIRT:0)
Block(-5,5,3,DIRT:0)
Block(-5,5,4,DIRT:0)
Block(-5,5,5,DIRT:0)
Block(-5,5,6,DIRT:0)
Block(-5,6,-7,DIRT:0)
Block(-5,6,-6,DIRT:0)
Block(-5,6,-5,DIRT:0)
Block(-5,6,-4,DIRT:0)
RandomBlock(-5,6,-3,MONSTER_EGGS:4,null,6,MONSTER_EGGS:2,null,18,MONSTER_EGGS:3,null,6,SMOOTH_BRICK:2,null,12,SMOOTH_BRICK:1,null,12,SMOOTH_BRICK:0,null,80,COBBLESTONE:0,null,100)
RandomBlock(-5,6,-2,MONSTER_EGGS:4,null,6,MONSTER_EGGS:2,null,18,MONSTER_EGGS:3,null,6,SMOOTH_BRICK:2,null,12,SMOOTH_BRICK:1,null,12,SMOOTH_BRICK:0,null,80,COBBLESTONE:0,null,100)
RandomBlock(-5,6,-1,MONSTER_EGGS:4,null,6,MONSTER_EGGS:2,null,18,MONSTER_EGGS:3,null,6,SMOOTH_BRICK:2,null,12,SMOOTH_BRICK:1,null,12,SMOOTH_BRICK:0,null,80,COBBLESTONE:0,null,100)
RandomBlock(-5,6,0,MONSTER_EGGS:4,null,6,MONSTER_EGGS:2,null,18,MONSTER_EGGS:3,null,6,SMOOTH_BRICK:2,null,12,SMOOTH_BRICK:1,null,12,SMOOTH_BRICK:0,null,80,COBBLESTONE:0,null,100)
RandomBlock(-5,6,1,MONSTER_EGGS:4,null,6,MONSTER_EGGS:2,null,18,MONSTER_EGGS:3,null,6,SMOOTH_BRICK:2,null,12,SMOOTH_BRICK:1,null,12,SMOOTH_BRICK:0,null,80,COBBLESTONE:0,null,100)
RandomBlock(-5,6,2,MONSTER_EGGS:4,null,6,MONSTER_EGGS:2,null,18,MONSTER_EGGS:3,null,6,SMOOTH_BRICK:2,null,12,SMOOTH_BRICK:1,null,12,SMOOTH_BRICK:0,null,80,COBBLESTONE:0,null,100)
Block(-5,6,3,DIRT:0)
Block(-5,6,4,DIRT:0)
Block(-5,6,5,DIRT:0)
Block(-5,6,6,DIRT:0)
Block(-5,7,-7,DIRT:0)
Block(-5,7,-6,DIRT:0)
Block(-5,7,-5,DIRT:0)
RandomBlock(-5,7,-4,MONSTER_EGGS:4,null,6,MONSTER_EGGS:2,null,18,MONSTER_EGGS:3,null,6,SMOOTH_BRICK:2,null,12,SMOOTH_BRICK:1,null,12,SMOOTH_BRICK:0,null,80,COBBLESTONE:0,null,100)
RandomBlock(-5,7,-3,MONSTER_EGGS:4,null,6,MONSTER_EGGS:2,null,18,MONSTER_EGGS:3,null,6,SMOOTH_BRICK:2,null,12,SMOOTH_BRICK:1,null,12,SMOOTH_BRICK:0,null,80,COBBLESTONE:0,null,100)
RandomBlock(-5,7,-2,MONSTER_EGGS:4,null,6,MONSTER_EGGS:2,null,18,MONSTER_EGGS:3,null,6,SMOOTH_BRICK:2,null,12,SMOOTH_BRICK:1,null,12,SMOOTH_BRICK:0,null,80,COBBLESTONE:0,null,100)
Block(-5,7,-1,AIR:0)
Block(-5,7,0,AIR:0)
RandomBlock(-5,7,1,MONSTER_EGGS:4,null,6,MONSTER_EGGS:2,null,18,MONSTER_EGGS:3,null,6,SMOOTH_BRICK:2,null,12,SMOOTH_BRICK:1,null,12,SMOOTH_BRICK:0,null,80,COBBLESTONE:0,null,100)
RandomBlock(-5,7,2,MONSTER_EGGS:4,null,6,MONSTER_EGGS:2,null,18,MONSTER_EGGS:3,null,6,SMOOTH_BRICK:2,null,12,SMOOTH_BRICK:1,null,12,SMOOTH_BRICK:0,null,80,COBBLESTONE:0,null,100)
RandomBlock(-5,7,3,MONSTER_EGGS:4,null,6,MONSTER_EGGS:2,null,18,MONSTER_EGGS:3,null,6,SMOOTH_BRICK:2,null,12,SMOOTH_BRICK:1,null,12,SMOOTH_BRICK:0,null,80,COBBLESTONE:0,null,100)
Block(-5,7,4,DIRT:0)
Block(-5,7,5,DIRT:0)
Block(-5,7,6,DIRT:0)
RandomBlock(-5,8,-5,MONSTER_EGGS:4,null,6,MONSTER_EGGS:2,null,18,MONSTER_EGGS:3,null,6,SMOOTH_BRICK:2,null,12,SMOOTH_BRICK:1,null,12,SMOOTH_BRICK:0,null,80,COBBLESTONE:0,null,100)
RandomBlock(-5,8,-4,MONSTER_EGGS:4,null,6,MONSTER_EGGS:2,null,18,MONSTER_EGGS:3,null,6,SMOOTH_BRICK:2,null,12,SMOOTH_BRICK:1,null,12,SMOOTH_BRICK:0,null,80,COBBLESTONE:0,null,100)
Block(-5,8,-3,AIR:0)
Block(-5,8,-2,AIR:0)
Block(-5,8,-1,AIR:0)
Block(-5,8,0,AIR:0)
Block(-5,8,1,AIR:0)
Block(-5,8,2,AIR:0)
RandomBlock(-5,8,3,MONSTER_EGGS:4,null,6,MONSTER_EGGS:2,null,18,MONSTER_EGGS:3,null,6,SMOOTH_BRICK:2,null,12,SMOOTH_BRICK:1,null,12,SMOOTH_BRICK:0,null,80,COBBLESTONE:0,null,100)
RandomBlock(-5,8,4,MONSTER_EGGS:4,null,6,MONSTER_EGGS:2,null,18,MONSTER_EGGS:3,null,6,SMOOTH_BRICK:2,null,12,SMOOTH_BRICK:1,null,12,SMOOTH_BRICK:0,null,80,COBBLESTONE:0,null,100)
RandomBlock(-5,9,-5,MONSTER_EGGS:4,null,6,MONSTER_EGGS:2,null,18,MONSTER_EGGS:3,null,6,SMOOTH_BRICK:2,null,12,SMOOTH_BRICK:1,null,12,SMOOTH_BRICK:0,null,80,COBBLESTONE:0,null,100)
Block(-5,9,-4,AIR:0)
Block(-5,9,-3,AIR:0)
Block(-5,9,-2,AIR:0)
Block(-5,9,-1,AIR:0)
Block(-5,9,0,AIR:0)
Block(-5,9,1,AIR:0)
Block(-5,9,2,AIR:0)
Block(-5,9,3,AIR:0)
RandomBlock(-5,9,4,MONSTER_EGGS:4,null,6,MONSTER_EGGS:2,null,18,MONSTER_EGGS:3,null,6,SMOOTH_BRICK:2,null,12,SMOOTH_BRICK:1,null,12,SMOOTH_BRICK:0,null,80,COBBLESTONE:0,null,100)
Block(-5,10,-5,AIR:0)
Block(-5,10,-4,AIR:0)
Block(-5,10,-3,AIR:0)
Block(-5,10,-2,AIR:0)
Block(-5,10,-1,AIR:0)
Block(-5,10,0,AIR:0)
Block(-5,10,1,AIR:0)
Block(-5,10,2,AIR:0)
Block(-5,10,3,AIR:0)
Block(-5,10,4,AIR:0)
Block(-5,11,-5,AIR:0)
Block(-5,11,-4,AIR:0)
Block(-5,11,-3,AIR:0)
Block(-5,11,-2,AIR:0)
Block(-5,11,-1,AIR:0)
Block(-5,11,0,AIR:0)
Block(-5,11,1,AIR:0)
Block(-5,11,2,AIR:0)
Block(-5,11,3,AIR:0)
Block(-5,11,4,AIR:0)
Block(-4,0,-7,STONE:0)
Block(-4,0,-6,STONE:0)
Block(-4,0,-5,STONE:0)
Block(-4,0,-4,STONE:0)
Block(-4,0,-3,STONE:0)
Block(-4,0,-2,STONE:0)
Block(-4,0,-1,STONE:0)
Block(-4,0,0,STONE:0)
Block(-4,0,1,STONE:0)
Block(-4,0,2,STONE:0)
Block(-4,0,3,STONE:0)
Block(-4,0,4,STONE:0)
Block(-4,0,5,STONE:0)
Block(-4,0,6,STONE:0)
Block(-4,1,-7,STONE:0)
Block(-4,1,-6,STONE:0)
Block(-4,1,-5,STONE:0)
Block(-4,1,-4,STONE:0)
Block(-4,1,-3,STONE:0)
Block(-4,1,-2,STONE:0)
Block(-4,1,-1,STONE:0)
Block(-4,1,0,STONE:0)
Block(-4,1,1,STONE:0)
Block(-4,1,2,STONE:0)
Block(-4,1,3,STONE:0)
Block(-4,1,4,STONE:0)
Block(-4,1,5,STONE:0)
Block(-4,1,6,STONE:0)
Block(-4,2,-7,STONE:0)
Block(-4,2,-6,STONE:0)
Block(-4,2,-5,STONE:0)
Block(-4,2,-4,DIRT:0)
Block(-4,2,-3,DIRT:0)
Block(-4,2,-2,STONE:0)
Block(-4,2,-1,STONE:0)
Block(-4,2,0,STONE:0)
Block(-4,2,1,STONE:0)
Block(-4,2,2,STONE:0)
Block(-4,2,3,STONE:0)
Block(-4,2,4,STONE:0)
Block(-4,2,5,STONE:0)
Block(-4,2,6,STONE:0)
Block(-4,3,-7,STONE:0)
Block(-4,3,-6,STONE:0)
Block(-4,3,-5,DIRT:0)
Block(-4,3,-4,DIRT:0)
RandomBlock(-4,3,-3,MONSTER_EGGS:4,null,6,MONSTER_EGGS:2,null,18,MONSTER_EGGS:3,null,6,SMOOTH_BRICK:2,null,12,SMOOTH_BRICK:1,null,12,SMOOTH_BRICK:0,null,80,COBBLESTONE:0,null,100)
Block(-4,3,-2,DIRT:0)
Block(-4,3,-1,STONE:0)
Block(-4,3,0,STONE:0)
Block(-4,3,1,STONE:0)
Block(-4,3,2,STONE:0)
Block(-4,3,3,STONE:0)
Block(-4,3,4,STONE:0)
Block(-4,3,5,STONE:0)
Block(-4,3,6,STONE:0)
Block(-4,4,-7,STONE:0)
Block(-4,4,-6,STONE:0)
Block(-4,4,-5,DIRT:0)
Block(-4,4,-4,DIRT:0)
RandomBlock(-4,4,-3,MONSTER_EGGS:4,null,6,MONSTER_EGGS:2,null,18,MONSTER_EGGS:3,null,6,SMOOTH_BRICK:2,null,12,SMOOTH_BRICK:1,null,12,SMOOTH_BRICK:0,null,80,COBBLESTONE:0,null,100)
Block(-4,4,-2,DIRT:0)
Block(-4,4,-1,STONE:0)
Block(-4,4,0,STONE:0)
Block(-4,4,1,STONE:0)
Block(-4,4,2,STONE:0)
Block(-4,4,3,STONE:0)
Block(-4,4,4,STONE:0)
Block(-4,4,5,STONE:0)
Block(-4,4,6,STONE:0)
Block(-4,5,-7,DIRT:0)
Block(-4,5,-6,DIRT:0)
Block(-4,5,-5,DIRT:0)
Block(-4,5,-4,DIRT:0)
RandomBlock(-4,5,-3,MONSTER_EGGS:4,null,6,MONSTER_EGGS:2,null,18,MONSTER_EGGS:3,null,6,SMOOTH_BRICK:2,null,12,SMOOTH_BRICK:1,null,12,SMOOTH_BRICK:0,null,80,COBBLESTONE:0,null,100)
RandomBlock(-4,5,-2,MONSTER_EGGS:4,null,6,MONSTER_EGGS:2,null,18,MONSTER_EGGS:3,null,6,SMOOTH_BRICK:2,null,12,SMOOTH_BRICK:1,null,12,SMOOTH_BRICK:0,null,80,COBBLESTONE:0,null,100)
RandomBlock(-4,5,-1,MONSTER_EGGS:4,null,6,MONSTER_EGGS:2,null,18,MONSTER_EGGS:3,null,6,SMOOTH_BRICK:2,null,12,SMOOTH_BRICK:1,null,12,SMOOTH_BRICK:0,null,80,COBBLESTONE:0,null,100)
RandomBlock(-4,5,0,MONSTER_EGGS:4,null,6,MONSTER_EGGS:2,null,18,MONSTER_EGGS:3,null,6,SMOOTH_BRICK:2,null,12,SMOOTH_BRICK:1,null,12,SMOOTH_BRICK:0,null,80,COBBLESTONE:0,null,100)
RandomBlock(-4,5,1,MONSTER_EGGS:4,null,6,MONSTER_EGGS:2,null,18,MONSTER_EGGS:3,null,6,SMOOTH_BRICK:2,null,12,SMOOTH_BRICK:1,null,12,SMOOTH_BRICK:0,null,80,COBBLESTONE:0,null,100)
Block(-4,5,2,DIRT:0)
Block(-4,5,3,DIRT:0)
Block(-4,5,4,DIRT:0)
Block(-4,5,5,DIRT:0)
Block(-4,5,6,DIRT:0)
Block(-4,6,-7,DIRT:0)
Block(-4,6,-6,DIRT:0)
Block(-4,6,-5,DIRT:0)
Block(-4,6,-4,DIRT:0)
RandomBlock(-4,6,-3,MONSTER_EGGS:4,null,6,MONSTER_EGGS:2,null,18,MONSTER_EGGS:3,null,6,SMOOTH_BRICK:2,null,12,SMOOTH_BRICK:1,null,12,SMOOTH_BRICK:0,null,80,COBBLESTONE:0,null,100)
Block(-4,6,-2,VINE:2)
Block(-4,6,-1,AIR:0)
Block(-4,6,0,AIR:0)
Block(-4,6,1,VINE:2)
RandomBlock(-4,6,2,MONSTER_EGGS:4,null,6,MONSTER_EGGS:2,null,18,MONSTER_EGGS:3,null,6,SMOOTH_BRICK:2,null,12,SMOOTH_BRICK:1,null,12,SMOOTH_BRICK:0,null,80,COBBLESTONE:0,null,100)
Block(-4,6,3,DIRT:0)
Block(-4,6,4,DIRT:0)
Block(-4,6,5,DIRT:0)
Block(-4,6,6,DIRT:0)
Block(-4,7,-7,DIRT:0)
Block(-4,7,-6,DIRT:0)
Block(-4,7,-5,DIRT:0)
RandomBlock(-4,7,-4,MONSTER_EGGS:4,null,6,MONSTER_EGGS:2,null,18,MONSTER_EGGS:3,null,6,SMOOTH_BRICK:2,null,12,SMOOTH_BRICK:1,null,12,SMOOTH_BRICK:0,null,80,COBBLESTONE:0,null,100)
RandomBlock(-4,7,-3,MONSTER_EGGS:4,null,6,MONSTER_EGGS:2,null,18,MONSTER_EGGS:3,null,6,SMOOTH_BRICK:2,null,12,SMOOTH_BRICK:1,null,12,SMOOTH_BRICK:0,null,80,COBBLESTONE:0,null,100)
Block(-4,7,-2,VINE:2)
Block(-4,7,-1,AIR:0)
Block(-4,7,0,AIR:0)
Block(-4,7,1,VINE:2)
RandomBlock(-4,7,2,MONSTER_EGGS:4,null,6,MONSTER_EGGS:2,null,18,MONSTER_EGGS:3,null,6,SMOOTH_BRICK:2,null,12,SMOOTH_BRICK:1,null,12,SMOOTH_BRICK:0,null,80,COBBLESTONE:0,null,100)
RandomBlock(-4,7,3,MONSTER_EGGS:4,null,6,MONSTER_EGGS:2,null,18,MONSTER_EGGS:3,null,6,SMOOTH_BRICK:2,null,12,SMOOTH_BRICK:1,null,12,SMOOTH_BRICK:0,null,80,COBBLESTONE:0,null,100)
Block(-4,7,4,DIRT:0)
Block(-4,7,5,DIRT:0)
Block(-4,7,6,DIRT:0)
RandomBlock(-4,8,-5,MONSTER_EGGS:4,null,6,MONSTER_EGGS:2,null,18,MONSTER_EGGS:3,null,6,SMOOTH_BRICK:2,null,12,SMOOTH_BRICK:1,null,12,SMOOTH_BRICK:0,null,80,COBBLESTONE:0,null,100)
Block(-4,8,-4,AIR:0)
Block(-4,8,-3,AIR:0)
Block(-4,8,-2,AIR:0)
Block(-4,8,-1,AIR:0)
Block(-4,8,0,AIR:0)
Block(-4,8,1,AIR:0)
Block(-4,8,2,AIR:0)
Block(-4,8,3,AIR:0)
RandomBlock(-4,8,4,MONSTER_EGGS:4,null,6,MONSTER_EGGS:2,null,18,MONSTER_EGGS:3,null,6,SMOOTH_BRICK:2,null,12,SMOOTH_BRICK:1,null,12,SMOOTH_BRICK:0,null,80,COBBLESTONE:0,null,100)
RandomBlock(-4,9,-5,MONSTER_EGGS:4,null,6,MONSTER_EGGS:2,null,18,MONSTER_EGGS:3,null,6,SMOOTH_BRICK:2,null,12,SMOOTH_BRICK:1,null,12,SMOOTH_BRICK:0,null,80,COBBLESTONE:0,null,100)
Block(-4,9,-4,AIR:0)
Block(-4,9,-3,AIR:0)
Block(-4,9,-2,AIR:0)
Block(-4,9,-1,AIR:0)
Block(-4,9,0,AIR:0)
Block(-4,9,1,AIR:0)
Block(-4,9,2,AIR:0)
Block(-4,9,3,AIR:0)
RandomBlock(-4,9,4,MONSTER_EGGS:4,null,6,MONSTER_EGGS:2,null,18,MONSTER_EGGS:3,null,6,SMOOTH_BRICK:2,null,12,SMOOTH_BRICK:1,null,12,SMOOTH_BRICK:0,null,80,COBBLESTONE:0,null,100)
Block(-4,10,-5,AIR:0)
Block(-4,10,-4,AIR:0)
Block(-4,10,-3,AIR:0)
Block(-4,10,-2,AIR:0)
Block(-4,10,-1,AIR:0)
Block(-4,10,0,AIR:0)
Block(-4,10,1,AIR:0)
Block(-4,10,2,AIR:0)
Block(-4,10,3,AIR:0)
Block(-4,10,4,AIR:0)
Block(-4,11,-5,AIR:0)
Block(-4,11,-4,AIR:0)
Block(-4,11,-3,AIR:0)
Block(-4,11,-2,AIR:0)
Block(-4,11,-1,AIR:0)
Block(-4,11,0,AIR:0)
Block(-4,11,1,AIR:0)
Block(-4,11,2,AIR:0)
Block(-4,11,3,AIR:0)
Block(-4,11,4,AIR:0)
Block(-3,0,-7,STONE:0)
Block(-3,0,-6,STONE:0)
Block(-3,0,-5,STONE:0)
Block(-3,0,-4,STONE:0)
Block(-3,0,-3,STONE:0)
Block(-3,0,-2,STONE:0)
Block(-3,0,-1,STONE:0)
Block(-3,0,0,STONE:0)
Block(-3,0,1,STONE:0)
Block(-3,0,2,STONE:0)
Block(-3,0,3,STONE:0)
Block(-3,0,4,STONE:0)
Block(-3,0,5,STONE:0)
Block(-3,0,6,STONE:0)
Block(-3,1,-7,STONE:0)
Block(-3,1,-6,STONE:0)
Block(-3,1,-5,STONE:0)
Block(-3,1,-4,STONE:0)
Block(-3,1,-3,STONE:0)
Block(-3,1,-2,STONE:0)
Block(-3,1,-1,STONE:0)
Block(-3,1,0,STONE:0)
Block(-3,1,1,STONE:0)
Block(-3,1,2,STONE:0)
Block(-3,1,3,STONE:0)
Block(-3,1,4,STONE:0)
Block(-3,1,5,STONE:0)
Block(-3,1,6,STONE:0)
Block(-3,2,-7,STONE:0)
Block(-3,2,-6,DIRT:0)
Block(-3,2,-5,DIRT:0)
Block(-3,2,-4,DIRT:0)
Block(-3,2,-3,DIRT:0)
Block(-3,2,-2,STONE:0)
Block(-3,2,-1,STONE:0)
Block(-3,2,0,STONE:0)
Block(-3,2,1,STONE:0)
Block(-3,2,2,STONE:0)
Block(-3,2,3,STONE:0)
Block(-3,2,4,STONE:0)
Block(-3,2,5,STONE:0)
Block(-3,2,6,STONE:0)
Block(-3,3,-7,STONE:0)
Block(-3,3,-6,DIRT:0)
Block(-3,3,-5,DIRT:0)
Block(-3,3,-4,DIRT:0)
Block(-3,3,-3,DIRT:0)
Block(-3,3,-2,DIRT:0)
Block(-3,3,-1,STONE:0)
Block(-3,3,0,STONE:0)
Block(-3,3,1,STONE:0)
Block(-3,3,2,STONE:0)
Block(-3,3,3,STONE:0)
Block(-3,3,4,STONE:0)
Block(-3,3,5,STONE:0)
Block(-3,3,6,STONE:0)
Block(-3,4,-7,STONE:0)
Block(-3,4,-6,DIRT:0)
Block(-3,4,-5,DIRT:0)
Block(-3,4,-4,DIRT:0)
RandomBlock(-3,4,-3,MONSTER_EGGS:4,null,6,MONSTER_EGGS:2,null,18,MONSTER_EGGS:3,null,6,SMOOTH_BRICK:2,null,12,SMOOTH_BRICK:1,null,12,SMOOTH_BRICK:0,null,80,COBBLESTONE:0,null,100)
RandomBlock(-3,4,-2,MONSTER_EGGS:4,null,6,MONSTER_EGGS:2,null,18,MONSTER_EGGS:3,null,6,SMOOTH_BRICK:2,null,12,SMOOTH_BRICK:1,null,12,SMOOTH_BRICK:0,null,80,COBBLESTONE:0,null,100)
RandomBlock(-3,4,-1,MONSTER_EGGS:4,null,6,MONSTER_EGGS:2,null,18,MONSTER_EGGS:3,null,6,SMOOTH_BRICK:2,null,12,SMOOTH_BRICK:1,null,12,SMOOTH_BRICK:0,null,80,COBBLESTONE:0,null,100)
RandomBlock(-3,4,0,MONSTER_EGGS:4,null,6,MONSTER_EGGS:2,null,18,MONSTER_EGGS:3,null,6,SMOOTH_BRICK:2,null,12,SMOOTH_BRICK:1,null,12,SMOOTH_BRICK:0,null,80,COBBLESTONE:0,null,100)
RandomBlock(-3,4,1,MONSTER_EGGS:4,null,6,MONSTER_EGGS:2,null,18,MONSTER_EGGS:3,null,6,SMOOTH_BRICK:2,null,12,SMOOTH_BRICK:1,null,12,SMOOTH_BRICK:0,null,80,COBBLESTONE:0,null,100)
RandomBlock(-3,4,2,MONSTER_EGGS:4,null,6,MONSTER_EGGS:2,null,18,MONSTER_EGGS:3,null,6,SMOOTH_BRICK:2,null,12,SMOOTH_BRICK:1,null,12,SMOOTH_BRICK:0,null,80,COBBLESTONE:0,null,100)
Block(-3,4,3,STONE:0)
Block(-3,4,4,STONE:0)
Block(-3,4,5,STONE:0)
Block(-3,4,6,STONE:0)
Block(-3,5,-7,DIRT:0)
Block(-3,5,-6,DIRT:0)
Block(-3,5,-5,DIRT:0)
Block(-3,5,-4,DIRT:0)
RandomBlock(-3,5,-3,MONSTER_EGGS:4,null,6,MONSTER_EGGS:2,null,18,MONSTER_EGGS:3,null,6,SMOOTH_BRICK:2,null,12,SMOOTH_BRICK:1,null,12,SMOOTH_BRICK:0,null,80,COBBLESTONE:0,null,100)
Block(-3,5,-2,VINE:4)
Block(-3,5,-1,AIR:0)
Block(-3,5,0,AIR:0)
Block(-3,5,1,AIR:0)
RandomBlock(-3,5,2,MONSTER_EGGS:4,null,6,MONSTER_EGGS:2,null,18,MONSTER_EGGS:3,null,6,SMOOTH_BRICK:2,null,12,SMOOTH_BRICK:1,null,12,SMOOTH_BRICK:0,null,80,COBBLESTONE:0,null,100)
Block(-3,5,3,DIRT:0)
Block(-3,5,4,DIRT:0)
Block(-3,5,5,DIRT:0)
Block(-3,5,6,DIRT:0)
Block(-3,6,-7,DIRT:0)
Block(-3,6,-6,DIRT:0)
Block(-3,6,-5,DIRT:0)
RandomBlock(-3,6,-4,MONSTER_EGGS:4,null,6,MONSTER_EGGS:2,null,18,MONSTER_EGGS:3,null,6,SMOOTH_BRICK:2,null,12,SMOOTH_BRICK:1,null,12,SMOOTH_BRICK:0,null,80,COBBLESTONE:0,null,100)
RandomBlock(-3,6,-3,MONSTER_EGGS:4,null,6,MONSTER_EGGS:2,null,18,MONSTER_EGGS:3,null,6,SMOOTH_BRICK:2,null,12,SMOOTH_BRICK:1,null,12,SMOOTH_BRICK:0,null,80,COBBLESTONE:0,null,100)
Block(-3,6,-2,VINE:4)
Block(-3,6,-1,AIR:0)
Block(-3,6,0,AIR:0)
Block(-3,6,1,AIR:0)
RandomBlock(-3,6,2,MONSTER_EGGS:4,null,6,MONSTER_EGGS:2,null,18,MONSTER_EGGS:3,null,6,SMOOTH_BRICK:2,null,12,SMOOTH_BRICK:1,null,12,SMOOTH_BRICK:0,null,80,COBBLESTONE:0,null,100)
Block(-3,6,3,DIRT:0)
Block(-3,6,4,DIRT:0)
Block(-3,6,5,DIRT:0)
Block(-3,6,6,DIRT:0)
Block(-3,7,-7,DIRT:0)
Block(-3,7,-6,DIRT:0)
Block(-3,7,-5,DIRT:0)
RandomBlock(-3,7,-4,MONSTER_EGGS:4,null,6,MONSTER_EGGS:2,null,18,MONSTER_EGGS:3,null,6,SMOOTH_BRICK:2,null,12,SMOOTH_BRICK:1,null,12,SMOOTH_BRICK:0,null,80,COBBLESTONE:0,null,100)
Block(-3,7,-3,VINE:4)
Block(-3,7,-2,AIR:0)
Block(-3,7,-1,AIR:0)
Block(-3,7,0,AIR:0)
Block(-3,7,1,AIR:0)
Block(-3,7,2,VINE:1)
RandomBlock(-3,7,3,MONSTER_EGGS:4,null,6,MONSTER_EGGS:2,null,18,MONSTER_EGGS:3,null,6,SMOOTH_BRICK:2,null,12,SMOOTH_BRICK:1,null,12,SMOOTH_BRICK:0,null,80,COBBLESTONE:0,null,100)
Block(-3,7,4,DIRT:0)
Block(-3,7,5,DIRT:0)
Block(-3,7,6,DIRT:0)
RandomBlock(-3,8,-5,MONSTER_EGGS:4,null,6,MONSTER_EGGS:2,null,18,MONSTER_EGGS:3,null,6,SMOOTH_BRICK:2,null,12,SMOOTH_BRICK:1,null,12,SMOOTH_BRICK:0,null,80,COBBLESTONE:0,null,100)
Block(-3,8,-4,AIR:0)
Block(-3,8,-3,AIR:0)
Block(-3,8,-2,AIR:0)
Block(-3,8,-1,AIR:0)
Block(-3,8,0,AIR:0)
Block(-3,8,1,AIR:0)
Block(-3,8,2,AIR:0)
Block(-3,8,3,AIR:0)
RandomBlock(-3,8,4,MONSTER_EGGS:4,null,6,MONSTER_EGGS:2,null,18,MONSTER_EGGS:3,null,6,SMOOTH_BRICK:2,null,12,SMOOTH_BRICK:1,null,12,SMOOTH_BRICK:0,null,80,COBBLESTONE:0,null,100)
RandomBlock(-3,9,-5,MONSTER_EGGS:4,null,6,MONSTER_EGGS:2,null,18,MONSTER_EGGS:3,null,6,SMOOTH_BRICK:2,null,12,SMOOTH_BRICK:1,null,12,SMOOTH_BRICK:0,null,80,COBBLESTONE:0,null,100)
Block(-3,9,-4,AIR:0)
Block(-3,9,-3,AIR:0)
Block(-3,9,-2,AIR:0)
Block(-3,9,-1,AIR:0)
Block(-3,9,0,AIR:0)
Block(-3,9,1,AIR:0)
Block(-3,9,2,AIR:0)
Block(-3,9,3,AIR:0)
RandomBlock(-3,9,4,MONSTER_EGGS:4,null,6,MONSTER_EGGS:2,null,18,MONSTER_EGGS:3,null,6,SMOOTH_BRICK:2,null,12,SMOOTH_BRICK:1,null,12,SMOOTH_BRICK:0,null,80,COBBLESTONE:0,null,100)
Block(-3,10,-5,AIR:0)
Block(-3,10,-4,AIR:0)
Block(-3,10,-3,AIR:0)
Block(-3,10,-2,AIR:0)
Block(-3,10,-1,AIR:0)
Block(-3,10,0,AIR:0)
Block(-3,10,1,AIR:0)
Block(-3,10,2,AIR:0)
Block(-3,10,3,AIR:0)
Block(-3,10,4,AIR:0)
Block(-3,11,-5,AIR:0)
Block(-3,11,-4,AIR:0)
Block(-3,11,-3,AIR:0)
Block(-3,11,-2,AIR:0)
Block(-3,11,-1,AIR:0)
Block(-3,11,0,AIR:0)
Block(-3,11,1,AIR:0)
Block(-3,11,2,AIR:0)
Block(-3,11,3,AIR:0)
Block(-3,11,4,AIR:0)
Block(-2,0,-7,DIRT:0)
Block(-2,0,-6,DIRT:0)
Block(-2,0,-5,DIRT:0)
Block(-2,0,-4,DIRT:0)
Block(-2,0,-3,DIRT:0)
Block(-2,0,-2,DIRT:0)
Block(-2,0,-1,DIRT:0)
Block(-2,0,0,DIRT:0)
Block(-2,0,1,DIRT:0)
Block(-2,0,2,DIRT:0)
Block(-2,0,3,DIRT:0)
Block(-2,0,4,DIRT:0)
Block(-2,0,5,DIRT:0)
Block(-2,0,6,DIRT:0)
Block(-2,1,-7,DIRT:0)
Block(-2,1,-6,DIRT:0)
Block(-2,1,-5,DIRT:0)
Block(-2,1,-4,DIRT:0)
Block(-2,1,-3,DIRT:0)
Block(-2,1,-2,DIRT:0)
Block(-2,1,-1,DIRT:0)
Block(-2,1,0,DIRT:0)
Block(-2,1,1,DIRT:0)
Block(-2,1,2,DIRT:0)
Block(-2,1,3,DIRT:0)
Block(-2,1,4,DIRT:0)
Block(-2,1,5,DIRT:0)
Block(-2,1,6,DIRT:0)
Block(-2,2,-7,DIRT:0)
Block(-2,2,-6,DIRT:0)
Block(-2,2,-5,DIRT:0)
Block(-2,2,-4,DIRT:0)
Block(-2,2,-3,DIRT:0)
Block(-2,2,-2,DIRT:0)
Block(-2,2,-1,DIRT:0)
Block(-2,2,0,DIRT:0)
Block(-2,2,1,DIRT:0)
Block(-2,2,2,DIRT:0)
Block(-2,2,3,DIRT:0)
Block(-2,2,4,DIRT:0)
Block(-2,2,5,DIRT:0)
Block(-2,2,6,DIRT:0)
Block(-2,3,-7,DIRT:0)
Block(-2,3,-6,DIRT:0)
Block(-2,3,-5,DIRT:0)
Block(-2,3,-4,DIRT:0)
RandomBlock(-2,3,-3,MONSTER_EGGS:4,null,6,MONSTER_EGGS:2,null,18,MONSTER_EGGS:3,null,6,SMOOTH_BRICK:2,null,12,SMOOTH_BRICK:1,null,12,SMOOTH_BRICK:0,null,80,COBBLESTONE:0,null,100)
RandomBlock(-2,3,-2,MONSTER_EGGS:4,null,6,MONSTER_EGGS:2,null,18,MONSTER_EGGS:3,null,6,SMOOTH_BRICK:2,null,12,SMOOTH_BRICK:1,null,12,SMOOTH_BRICK:0,null,80,COBBLESTONE:0,null,100)
RandomBlock(-2,3,-1,MONSTER_EGGS:4,null,6,MONSTER_EGGS:2,null,18,MONSTER_EGGS:3,null,6,SMOOTH_BRICK:2,null,12,SMOOTH_BRICK:1,null,12,SMOOTH_BRICK:0,null,80,COBBLESTONE:0,null,100)
RandomBlock(-2,3,0,MONSTER_EGGS:4,null,6,MONSTER_EGGS:2,null,18,MONSTER_EGGS:3,null,6,SMOOTH_BRICK:2,null,12,SMOOTH_BRICK:1,null,12,SMOOTH_BRICK:0,null,80,COBBLESTONE:0,null,100)
RandomBlock(-2,3,1,MONSTER_EGGS:4,null,6,MONSTER_EGGS:2,null,18,MONSTER_EGGS:3,null,6,SMOOTH_BRICK:2,null,12,SMOOTH_BRICK:1,null,12,SMOOTH_BRICK:0,null,80,COBBLESTONE:0,null,100)
RandomBlock(-2,3,2,MONSTER_EGGS:4,null,6,MONSTER_EGGS:2,null,18,MONSTER_EGGS:3,null,6,SMOOTH_BRICK:2,null,12,SMOOTH_BRICK:1,null,12,SMOOTH_BRICK:0,null,80,COBBLESTONE:0,null,100)
Block(-2,3,3,DIRT:0)
Block(-2,3,4,DIRT:0)
Block(-2,3,5,DIRT:0)
Block(-2,3,6,DIRT:0)
Block(-2,4,-7,DIRT:0)
Block(-2,4,-6,DIRT:0)
Block(-2,4,-5,DIRT:0)
RandomBlock(-2,4,-4,MONSTER_EGGS:4,null,6,MONSTER_EGGS:2,null,18,MONSTER_EGGS:3,null,6,SMOOTH_BRICK:2,null,12,SMOOTH_BRICK:1,null,12,SMOOTH_BRICK:0,null,80,COBBLESTONE:0,null,100)
Block(-2,4,-3,VINE:14)
Block(-2,4,-2,VINE:2)
Block(-2,4,-1,AIR:0)
Block(-2,4,0,AIR:0)
Block(-2,4,1,AIR:0)
Block(-2,4,2,VINE:9)
RandomBlock(-2,4,3,MONSTER_EGGS:4,null,6,MONSTER_EGGS:2,null,18,MONSTER_EGGS:3,null,6,SMOOTH_BRICK:2,null,12,SMOOTH_BRICK:1,null,12,SMOOTH_BRICK:0,null,80,COBBLESTONE:0,null,100)
Block(-2,4,4,DIRT:0)
Block(-2,4,5,DIRT:0)
Block(-2,4,6,DIRT:0)
Block(-2,5,-7,DIRT:0)
Block(-2,5,-6,DIRT:0)
Block(-2,5,-5,DIRT:0)
RandomBlock(-2,5,-4,MONSTER_EGGS:4,null,6,MONSTER_EGGS:2,null,18,MONSTER_EGGS:3,null,6,SMOOTH_BRICK:2,null,12,SMOOTH_BRICK:1,null,12,SMOOTH_BRICK:0,null,80,COBBLESTONE:0,null,100)
Block(-2,5,-3,VINE:12)
Block(-2,5,-2,AIR:0)
Block(-2,5,-1,VINE:8)
Block(-2,5,0,AIR:0)
Block(-2,5,1,AIR:0)
Block(-2,5,2,VINE:9)
RandomBlock(-2,5,3,MONSTER_EGGS:4,null,6,MONSTER_EGGS:2,null,18,MONSTER_EGGS:3,null,6,SMOOTH_BRICK:2,null,12,SMOOTH_BRICK:1,null,12,SMOOTH_BRICK:0,null,80,COBBLESTONE:0,null,100)
Block(-2,5,4,DIRT:0)
Block(-2,5,5,DIRT:0)
Block(-2,5,6,DIRT:0)
Block(-2,6,-7,DIRT:0)
Block(-2,6,-6,DIRT:0)
Block(-2,6,-5,DIRT:0)
RandomBlock(-2,6,-4,MONSTER_EGGS:4,null,6,MONSTER_EGGS:2,null,18,MONSTER_EGGS:3,null,6,SMOOTH_BRICK:2,null,12,SMOOTH_BRICK:1,null,12,SMOOTH_BRICK:0,null,80,COBBLESTONE:0,null,100)
Block(-2,6,-3,VINE:12)
Block(-2,6,-2,VINE:8)
Block(-2,6,-1,VINE:8)
Block(-2,6,0,AIR:0)
Block(-2,6,1,VINE:8)
Block(-2,6,2,VINE:9)
RandomBlock(-2,6,3,MONSTER_EGGS:4,null,6,MONSTER_EGGS:2,null,18,MONSTER_EGGS:3,null,6,SMOOTH_BRICK:2,null,12,SMOOTH_BRICK:1,null,12,SMOOTH_BRICK:0,null,80,COBBLESTONE:0,null,100)
Block(-2,6,4,DIRT:0)
Block(-2,6,5,DIRT:0)
Block(-2,6,6,DIRT:0)
Block(-2,7,-7,DIRT:0)
Block(-2,7,-6,DIRT:0)
Block(-2,7,-5,DIRT:0)
RandomBlock(-2,7,-4,MONSTER_EGGS:4,null,6,MONSTER_EGGS:2,null,18,MONSTER_EGGS:3,null,6,SMOOTH_BRICK:2,null,12,SMOOTH_BRICK:1,null,12,SMOOTH_BRICK:0,null,80,COBBLESTONE:0,null,100)
Block(-2,7,-3,VINE:8)
Block(-2,7,-2,VINE:8)
Block(-2,7,-1,VINE:8)
Block(-2,7,0,AIR:0)
Block(-2,7,1,VINE:8)
Block(-2,7,2,VINE:9)
RandomBlock(-2,7,3,MONSTER_EGGS:4,null,6,MONSTER_EGGS:2,null,18,MONSTER_EGGS:3,null,6,SMOOTH_BRICK:2,null,12,SMOOTH_BRICK:1,null,12,SMOOTH_BRICK:0,null,80,COBBLESTONE:0,null,100)
Block(-2,7,4,DIRT:0)
Block(-2,7,5,DIRT:0)
Block(-2,7,6,DIRT:0)
RandomBlock(-2,8,-5,MONSTER_EGGS:4,null,6,MONSTER_EGGS:2,null,18,MONSTER_EGGS:3,null,6,SMOOTH_BRICK:2,null,12,SMOOTH_BRICK:1,null,12,SMOOTH_BRICK:0,null,80,COBBLESTONE:0,null,100)
Block(-2,8,-4,AIR:0)
Block(-2,8,-3,VINE:8)
Block(-2,8,-2,VINE:8)
Block(-2,8,-1,VINE:8)
Block(-2,8,0,VINE:8)
Block(-2,8,1,VINE:8)
Block(-2,8,2,VINE:8)
Block(-2,8,3,VINE:8)
RandomBlock(-2,8,4,MONSTER_EGGS:4,null,6,MONSTER_EGGS:2,null,18,MONSTER_EGGS:3,null,6,SMOOTH_BRICK:2,null,12,SMOOTH_BRICK:1,null,12,SMOOTH_BRICK:0,null,80,COBBLESTONE:0,null,100)
RandomBlock(-2,9,-5,MONSTER_EGGS:4,null,6,MONSTER_EGGS:2,null,18,MONSTER_EGGS:3,null,6,SMOOTH_BRICK:2,null,12,SMOOTH_BRICK:1,null,12,SMOOTH_BRICK:0,null,80,COBBLESTONE:0,null,100)
Block(-2,9,-4,VINE:8)
Block(-2,9,-3,AIR:0)
Block(-2,9,-2,AIR:0)
Block(-2,9,-1,VINE:8)
Block(-2,9,0,VINE:8)
Block(-2,9,1,VINE:8)
Block(-2,9,2,VINE:8)
Block(-2,9,3,VINE:8)
RandomBlock(-2,9,4,MONSTER_EGGS:4,null,6,MONSTER_EGGS:2,null,18,MONSTER_EGGS:3,null,6,SMOOTH_BRICK:2,null,12,SMOOTH_BRICK:1,null,12,SMOOTH_BRICK:0,null,80,COBBLESTONE:0,null,100)
Block(-2,10,-5,VINE:8)
Block(-2,10,-4,VINE:8)
Block(-2,10,-3,VINE:8)
Block(-2,10,-2,AIR:0)
Block(-2,10,-1,VINE:8)
Block(-2,10,0,VINE:8)
Block(-2,10,1,VINE:8)
Block(-2,10,2,VINE:8)
Block(-2,10,3,VINE:8)
Block(-2,10,4,VINE:8)
Block(-2,11,-5,VINE:8)
Block(-2,11,-4,VINE:8)
Block(-2,11,-3,VINE:8)
Block(-2,11,-2,VINE:8)
Block(-2,11,-1,VINE:8)
Block(-2,11,0,VINE:8)
Block(-2,11,1,VINE:8)
Block(-2,11,2,VINE:8)
Block(-2,11,3,VINE:8)
Block(-2,11,4,VINE:9)
Block(-1,0,-7,DIRT:0)
Block(-1,0,-6,DIRT:0)
Block(-1,0,-5,DIRT:0)
Block(-1,0,-4,DIRT:0)
Block(-1,0,-3,DIRT:0)
Block(-1,0,-2,DIRT:0)
Block(-1,0,-1,DIRT:0)
Block(-1,0,0,DIRT:0)
Block(-1,0,1,DIRT:0)
Block(-1,0,2,DIRT:0)
Block(-1,0,3,DIRT:0)
Block(-1,0,4,DIRT:0)
Block(-1,0,5,DIRT:0)
Block(-1,0,6,DIRT:0)
Block(-1,1,-7,DIRT:0)
Block(-1,1,-6,GRASS:0)
Block(-1,1,-5,GRASS:0)
Block(-1,1,-4,GRASS:0)
Block(-1,1,-3,GRASS:0)
Block(-1,1,-2,GRASS:0)
Block(-1,1,-1,GRASS:0)
Block(-1,1,0,GRASS:0)
Block(-1,1,1,GRASS:0)
Block(-1,1,2,GRASS:0)
Block(-1,1,3,GRASS:0)
Block(-1,1,4,GRASS:0)
Block(-1,1,5,GRASS:0)
Block(-1,1,6,DIRT:0)
Block(-1,2,-7,DIRT:0)
Block(-1,2,-6,REDSTONE_WIRE:0)
Block(-1,2,-5,REDSTONE_WIRE:0)
Block(-1,2,-4,REDSTONE_WIRE:0)
Block(-1,2,-3,REDSTONE_WIRE:0)
Block(-1,2,-2,REDSTONE_WIRE:0)
Block(-1,2,-1,REDSTONE_WIRE:0)
Block(-1,2,0,REDSTONE_WIRE:0)
Block(-1,2,1,REDSTONE_WIRE:0)
Block(-1,2,2,REDSTONE_WIRE:0)
Block(-1,2,3,REDSTONE_WIRE:0)
Block(-1,2,4,REDSTONE_WIRE:0)
Block(-1,2,5,REDSTONE_WIRE:0)
Block(-1,2,6,DIRT:0)
Block(-1,3,-7,DIRT:0)
Block(-1,3,-6,DIRT:0)
Block(-1,3,-5,DIRT:0)
Block(-1,3,-4,DIRT:0)
Block(-1,3,-3,DIRT:0)
RandomBlock(-1,3,-2,MONSTER_EGGS:4,null,6,MONSTER_EGGS:2,null,18,MONSTER_EGGS:3,null,6,SMOOTH_BRICK:2,null,12,SMOOTH_BRICK:1,null,12,SMOOTH_BRICK:0,null,80,COBBLESTONE:0,null,100)
RandomBlock(-1,3,-1,MONSTER_EGGS:4,null,6,MONSTER_EGGS:2,null,18,MONSTER_EGGS:3,null,6,SMOOTH_BRICK:2,null,12,SMOOTH_BRICK:1,null,12,SMOOTH_BRICK:0,null,80,COBBLESTONE:0,null,100)
RandomBlock(-1,3,0,MONSTER_EGGS:4,null,6,MONSTER_EGGS:2,null,18,MONSTER_EGGS:3,null,6,SMOOTH_BRICK:2,null,12,SMOOTH_BRICK:1,null,12,SMOOTH_BRICK:0,null,80,COBBLESTONE:0,null,100)
RandomBlock(-1,3,1,MONSTER_EGGS:4,null,6,MONSTER_EGGS:2,null,18,MONSTER_EGGS:3,null,6,SMOOTH_BRICK:2,null,12,SMOOTH_BRICK:1,null,12,SMOOTH_BRICK:0,null,80,COBBLESTONE:0,null,100)
Block(-1,3,2,DIRT:0)
Block(-1,3,3,DIRT:0)
Block(-1,3,4,DIRT:0)
Block(-1,3,5,DIRT:0)
Block(-1,3,6,DIRT:0)
Block(-1,4,-7,DIRT:0)
Block(-1,4,-6,DIRT:0)
RandomBlock(-1,4,-5,MONSTER_EGGS:4,null,6,MONSTER_EGGS:2,null,18,MONSTER_EGGS:3,null,6,SMOOTH_BRICK:2,null,12,SMOOTH_BRICK:1,null,12,SMOOTH_BRICK:0,null,80,COBBLESTONE:0,null,100)
RandomBlock(-1,4,-4,MONSTER_EGGS:4,null,6,MONSTER_EGGS:2,null,18,MONSTER_EGGS:3,null,6,SMOOTH_BRICK:2,null,12,SMOOTH_BRICK:1,null,12,SMOOTH_BRICK:0,null,80,COBBLESTONE:0,null,100)
RandomBlock(-1,4,-3,MONSTER_EGGS:4,null,6,MONSTER_EGGS:2,null,18,MONSTER_EGGS:3,null,6,SMOOTH_BRICK:2,null,12,SMOOTH_BRICK:1,null,12,SMOOTH_BRICK:0,null,80,COBBLESTONE:0,null,100)
Block(-1,4,-2,VINE:4)
Block(-1,4,-1,AIR:0)
Block(-1,4,0,AIR:0)
Block(-1,4,1,AIR:0)
RandomBlock(-1,4,2,MONSTER_EGGS:4,null,6,MONSTER_EGGS:2,null,18,MONSTER_EGGS:3,null,6,SMOOTH_BRICK:2,null,12,SMOOTH_BRICK:1,null,12,SMOOTH_BRICK:0,null,80,COBBLESTONE:0,null,100)
Block(-1,4,3,SMOOTH_BRICK:2)
Block(-1,4,4,SMOOTH_BRICK:2)
Block(-1,4,5,DIRT:0)
Block(-1,4,6,DIRT:0)
Block(-1,5,-7,DIRT:0)
Block(-1,5,-6,DIRT:0)
RandomBlock(-1,5,-5,MONSTER_EGGS:4,null,6,MONSTER_EGGS:2,null,18,MONSTER_EGGS:3,null,6,SMOOTH_BRICK:2,null,12,SMOOTH_BRICK:1,null,12,SMOOTH_BRICK:0,null,80,COBBLESTONE:0,null,100)
RandomBlock(-1,5,-4,MONSTER_EGGS:4,null,6,MONSTER_EGGS:2,null,18,MONSTER_EGGS:3,null,6,SMOOTH_BRICK:2,null,12,SMOOTH_BRICK:1,null,12,SMOOTH_BRICK:0,null,80,COBBLESTONE:0,null,100)
RandomBlock(-1,5,-3,MONSTER_EGGS:4,null,6,MONSTER_EGGS:2,null,18,MONSTER_EGGS:3,null,6,SMOOTH_BRICK:2,null,12,SMOOTH_BRICK:1,null,12,SMOOTH_BRICK:0,null,80,COBBLESTONE:0,null,100)
Block(-1,5,-2,AIR:0)
Block(-1,5,-1,AIR:0)
Block(-1,5,0,AIR:0)
Block(-1,5,1,AIR:0)
RandomBlock(-1,5,2,MONSTER_EGGS:4,null,6,MONSTER_EGGS:2,null,18,MONSTER_EGGS:3,null,6,SMOOTH_BRICK:2,null,12,SMOOTH_BRICK:1,null,12,SMOOTH_BRICK:0,null,80,COBBLESTONE:0,null,100)
RandomBlock(-1,5,3,MONSTER_EGGS:4,null,6,MONSTER_EGGS:2,null,18,MONSTER_EGGS:3,null,6,SMOOTH_BRICK:2,null,12,SMOOTH_BRICK:1,null,12,SMOOTH_BRICK:0,null,80,COBBLESTONE:0,null,100)
Block(-1,5,4,SMOOTH_BRICK:2)
Block(-1,5,5,DIRT:0)
Block(-1,5,6,DIRT:0)
Block(-1,6,-7,DIRT:0)
Block(-1,6,-6,DIRT:0)
RandomBlock(-1,6,-5,MONSTER_EGGS:4,null,6,MONSTER_EGGS:2,null,18,MONSTER_EGGS:3,null,6,SMOOTH_BRICK:2,null,12,SMOOTH_BRICK:1,null,12,SMOOTH_BRICK:0,null,80,COBBLESTONE:0,null,100)
RandomBlock(-1,6,-4,MONSTER_EGGS:4,null,6,MONSTER_EGGS:2,null,18,MONSTER_EGGS:3,null,6,SMOOTH_BRICK:2,null,12,SMOOTH_BRICK:1,null,12,SMOOTH_BRICK:0,null,80,COBBLESTONE:0,null,100)
RandomBlock(-1,6,-3,MONSTER_EGGS:4,null,6,MONSTER_EGGS:2,null,18,MONSTER_EGGS:3,null,6,SMOOTH_BRICK:2,null,12,SMOOTH_BRICK:1,null,12,SMOOTH_BRICK:0,null,80,COBBLESTONE:0,null,100)
Block(-1,6,-2,AIR:0)
Block(-1,6,-1,AIR:0)
Block(-1,6,0,AIR:0)
Block(-1,6,1,AIR:0)
RandomBlock(-1,6,2,MONSTER_EGGS:4,null,6,MONSTER_EGGS:2,null,18,MONSTER_EGGS:3,null,6,SMOOTH_BRICK:2,null,12,SMOOTH_BRICK:1,null,12,SMOOTH_BRICK:0,null,80,COBBLESTONE:0,null,100)
Block(-1,6,3,SMOOTH_BRICK:2)
RandomBlock(-1,6,4,MONSTER_EGGS:4,null,6,MONSTER_EGGS:2,null,18,MONSTER_EGGS:3,null,6,SMOOTH_BRICK:2,null,12,SMOOTH_BRICK:1,null,12,SMOOTH_BRICK:0,null,80,COBBLESTONE:0,null,100)
Block(-1,6,5,DIRT:0)
Block(-1,6,6,DIRT:0)
Block(-1,7,-7,DIRT:0)
Block(-1,7,-6,DIRT:0)
RandomBlock(-1,7,-5,MONSTER_EGGS:4,null,6,MONSTER_EGGS:2,null,18,MONSTER_EGGS:3,null,6,SMOOTH_BRICK:2,null,12,SMOOTH_BRICK:1,null,12,SMOOTH_BRICK:0,null,80,COBBLESTONE:0,null,100)
Block(-1,7,-4,SMOOTH_BRICK:2)
RandomBlock(-1,7,-3,MONSTER_EGGS:4,null,6,MONSTER_EGGS:2,null,18,MONSTER_EGGS:3,null,6,SMOOTH_BRICK:2,null,12,SMOOTH_BRICK:1,null,12,SMOOTH_BRICK:0,null,80,COBBLESTONE:0,null,100)
Block(-1,7,-2,AIR:0)
Block(-1,7,-1,AIR:0)
Block(-1,7,0,AIR:0)
Block(-1,7,1,AIR:0)
RandomBlock(-1,7,2,MONSTER_EGGS:4,null,6,MONSTER_EGGS:2,null,18,MONSTER_EGGS:3,null,6,SMOOTH_BRICK:2,null,12,SMOOTH_BRICK:1,null,12,SMOOTH_BRICK:0,null,80,COBBLESTONE:0,null,100)
RandomBlock(-1,7,3,MONSTER_EGGS:4,null,6,MONSTER_EGGS:2,null,18,MONSTER_EGGS:3,null,6,SMOOTH_BRICK:2,null,12,SMOOTH_BRICK:1,null,12,SMOOTH_BRICK:0,null,80,COBBLESTONE:0,null,100)
RandomBlock(-1,7,4,MONSTER_EGGS:4,null,6,MONSTER_EGGS:2,null,18,MONSTER_EGGS:3,null,6,SMOOTH_BRICK:2,null,12,SMOOTH_BRICK:1,null,12,SMOOTH_BRICK:0,null,80,COBBLESTONE:0,null,100)
Block(-1,7,5,DIRT:0)
Block(-1,7,6,DIRT:0)
RandomBlock(-1,8,-5,MONSTER_EGGS:4,null,6,MONSTER_EGGS:2,null,18,MONSTER_EGGS:3,null,6,SMOOTH_BRICK:2,null,12,SMOOTH_BRICK:1,null,12,SMOOTH_BRICK:0,null,80,COBBLESTONE:0,null,100)
Block(-1,8,-4,SMOOTH_BRICK:2)
RandomBlock(-1,8,-3,MONSTER_EGGS:4,null,6,MONSTER_EGGS:2,null,18,MONSTER_EGGS:3,null,6,SMOOTH_BRICK:2,null,12,SMOOTH_BRICK:1,null,12,SMOOTH_BRICK:0,null,80,COBBLESTONE:0,null,100)
RandomBlock(-1,8,-2,MONSTER_EGGS:4,null,6,MONSTER_EGGS:2,null,18,MONSTER_EGGS:3,null,6,SMOOTH_BRICK:2,null,12,SMOOTH_BRICK:1,null,12,SMOOTH_BRICK:0,null,80,COBBLESTONE:0,null,100)
Block(-1,8,-1,AIR:0)
Block(-1,8,0,AIR:0)
Block(-1,8,1,SMOOTH_BRICK:2)
RandomBlock(-1,8,2,MONSTER_EGGS:4,null,6,MONSTER_EGGS:2,null,18,MONSTER_EGGS:3,null,6,SMOOTH_BRICK:2,null,12,SMOOTH_BRICK:1,null,12,SMOOTH_BRICK:0,null,80,COBBLESTONE:0,null,100)
RandomBlock(-1,8,3,MONSTER_EGGS:4,null,6,MONSTER_EGGS:2,null,18,MONSTER_EGGS:3,null,6,SMOOTH_BRICK:2,null,12,SMOOTH_BRICK:1,null,12,SMOOTH_BRICK:0,null,80,COBBLESTONE:0,null,100)
RandomBlock(-1,8,4,MONSTER_EGGS:4,null,6,MONSTER_EGGS:2,null,18,MONSTER_EGGS:3,null,6,SMOOTH_BRICK:2,null,12,SMOOTH_BRICK:1,null,12,SMOOTH_BRICK:0,null,80,COBBLESTONE:0,null,100)
Block(-1,9,-5,SMOOTH_BRICK:2)
RandomBlock(-1,9,-4,MONSTER_EGGS:4,null,6,MONSTER_EGGS:2,null,18,MONSTER_EGGS:3,null,6,SMOOTH_BRICK:2,null,12,SMOOTH_BRICK:1,null,12,SMOOTH_BRICK:0,null,80,COBBLESTONE:0,null,100)
Block(-1,9,-3,AIR:0)
Block(-1,9,-2,AIR:0)
RandomBlock(-1,9,-1,MONSTER_EGGS:4,null,6,MONSTER_EGGS:2,null,18,MONSTER_EGGS:3,null,6,SMOOTH_BRICK:2,null,12,SMOOTH_BRICK:1,null,12,SMOOTH_BRICK:0,null,80,COBBLESTONE:0,null,100)
RandomBlock(-1,9,0,MONSTER_EGGS:4,null,6,MONSTER_EGGS:2,null,18,MONSTER_EGGS:3,null,6,SMOOTH_BRICK:2,null,12,SMOOTH_BRICK:1,null,12,SMOOTH_BRICK:0,null,80,COBBLESTONE:0,null,100)
Block(-1,9,1,AIR:0)
Block(-1,9,2,AIR:0)
Block(-1,9,3,SMOOTH_BRICK:2)
RandomBlock(-1,9,4,MONSTER_EGGS:4,null,6,MONSTER_EGGS:2,null,18,MONSTER_EGGS:3,null,6,SMOOTH_BRICK:2,null,12,SMOOTH_BRICK:1,null,12,SMOOTH_BRICK:0,null,80,COBBLESTONE:0,null,100)
Block(-1,10,-6,VINE:1)
RandomBlock(-1,10,-5,MONSTER_EGGS:4,null,6,MONSTER_EGGS:2,null,18,MONSTER_EGGS:3,null,6,SMOOTH_BRICK:2,null,12,SMOOTH_BRICK:1,null,12,SMOOTH_BRICK:0,null,80,COBBLESTONE:0,null,100)
Block(-1,10,-4,SMOOTH_BRICK:2)
Block(-1,10,-3,AIR:0)
Block(-1,10,-2,AIR:0)
Block(-1,10,-1,SMOOTH_BRICK:2)
RandomBlock(-1,10,0,MONSTER_EGGS:4,null,6,MONSTER_EGGS:2,null,18,MONSTER_EGGS:3,null,6,SMOOTH_BRICK:2,null,12,SMOOTH_BRICK:1,null,12,SMOOTH_BRICK:0,null,80,COBBLESTONE:0,null,100)
Block(-1,10,1,AIR:0)
Block(-1,10,2,AIR:0)
RandomBlock(-1,10,3,MONSTER_EGGS:4,null,6,MONSTER_EGGS:2,null,18,MONSTER_EGGS:3,null,6,SMOOTH_BRICK:2,null,12,SMOOTH_BRICK:1,null,12,SMOOTH_BRICK:0,null,80,COBBLESTONE:0,null,100)
Block(-1,10,4,SMOOTH_BRICK:2)
Block(-1,10,5,VINE:4)
Block(-1,11,-6,VINE:1)
RandomBlock(-1,11,-5,MONSTER_EGGS:4,null,6,MONSTER_EGGS:2,null,18,MONSTER_EGGS:3,null,6,SMOOTH_BRICK:2,null,12,SMOOTH_BRICK:1,null,12,SMOOTH_BRICK:0,null,80,COBBLESTONE:0,null,100)
RandomBlock(-1,11,-4,MONSTER_EGGS:4,null,6,MONSTER_EGGS:2,null,18,MONSTER_EGGS:3,null,6,SMOOTH_BRICK:2,null,12,SMOOTH_BRICK:1,null,12,SMOOTH_BRICK:0,null,80,COBBLESTONE:0,null,100)
RandomBlock(-1,11,-3,MONSTER_EGGS:4,null,6,MONSTER_EGGS:2,null,18,MONSTER_EGGS:3,null,6,SMOOTH_BRICK:2,null,12,SMOOTH_BRICK:1,null,12,SMOOTH_BRICK:0,null,80,COBBLESTONE:0,null,100)
RandomBlock(-1,11,-2,MONSTER_EGGS:4,null,6,MONSTER_EGGS:2,null,18,MONSTER_EGGS:3,null,6,SMOOTH_BRICK:2,null,12,SMOOTH_BRICK:1,null,12,SMOOTH_BRICK:0,null,80,COBBLESTONE:0,null,100)
RandomBlock(-1,11,-1,MONSTER_EGGS:4,null,6,MONSTER_EGGS:2,null,18,MONSTER_EGGS:3,null,6,SMOOTH_BRICK:2,null,12,SMOOTH_BRICK:1,null,12,SMOOTH_BRICK:0,null,80,COBBLESTONE:0,null,100)
RandomBlock(-1,11,0,MONSTER_EGGS:4,null,6,MONSTER_EGGS:2,null,18,MONSTER_EGGS:3,null,6,SMOOTH_BRICK:2,null,12,SMOOTH_BRICK:1,null,12,SMOOTH_BRICK:0,null,80,COBBLESTONE:0,null,100)
RandomBlock(-1,11,1,MONSTER_EGGS:4,null,6,MONSTER_EGGS:2,null,18,MONSTER_EGGS:3,null,6,SMOOTH_BRICK:2,null,12,SMOOTH_BRICK:1,null,12,SMOOTH_BRICK:0,null,80,COBBLESTONE:0,null,100)
RandomBlock(-1,11,2,MONSTER_EGGS:4,null,6,MONSTER_EGGS:2,null,18,MONSTER_EGGS:3,null,6,SMOOTH_BRICK:2,null,12,SMOOTH_BRICK:1,null,12,SMOOTH_BRICK:0,null,80,COBBLESTONE:0,null,100)
RandomBlock(-1,11,3,MONSTER_EGGS:4,null,6,MONSTER_EGGS:2,null,18,MONSTER_EGGS:3,null,6,SMOOTH_BRICK:2,null,12,SMOOTH_BRICK:1,null,12,SMOOTH_BRICK:0,null,80,COBBLESTONE:0,null,100)
Block(-1,11,4,SMOOTH_BRICK:2)
Block(-1,11,5,VINE:4)
Block(0,0,-7,DIRT:0)
Block(0,0,-6,DIRT:0)
Block(0,0,-5,DIRT:0)
Block(0,0,-4,DIRT:0)
Block(0,0,-3,DIRT:0)
Block(0,0,-2,DIRT:0)
Block(0,0,-1,DIRT:0)
Block(0,0,0,DIRT:0)
Block(0,0,1,DIRT:0)
Block(0,0,2,DIRT:0)
Block(0,0,3,DIRT:0)
Block(0,0,4,DIRT:0)
Block(0,0,5,DIRT:0)
Block(0,0,6,DIRT:0)
Block(0,1,-7,DIRT:0)
Block(0,1,-6,GRASS:0)
Block(0,1,-5,GRASS:0)
Block(0,1,-4,GRASS:0)
Block(0,1,-3,GRASS:0)
Block(0,1,-2,GRASS:0)
Block(0,1,-1,GRASS:0)
Block(0,1,0,GRASS:0)
Block(0,1,1,GRASS:0)
Block(0,1,2,GRASS:0)
Block(0,1,3,GRASS:0)
Block(0,1,4,GRASS:0)
Block(0,1,5,GRASS:0)
Block(0,1,6,DIRT:0)
Block(0,2,-7,DIRT:0)
Block(0,2,-6,REDSTONE_WIRE:0)
Block(0,2,-5,AIR:0)
Block(0,2,-4,AIR:0)
Block(0,2,-3,AIR:0)
Block(0,2,-2,AIR:0)
Block(0,2,-1,REDSTONE_WIRE:0)
Block(0,2,0,REDSTONE_WIRE:0)
Block(0,2,1,AIR:0)
Block(0,2,2,AIR:0)
Block(0,2,3,AIR:0)
Block(0,2,4,AIR:0)
Block(0,2,5,REDSTONE_WIRE:0)
Block(0,2,6,DIRT:0)
Block(0,3,-7,DIRT:0)
Block(0,3,-6,DIRT:0)
Block(0,3,-5,DIRT:0)
Block(0,3,-4,DIRT:0)
Block(0,3,-3,DIRT:0)
Block(0,3,-2,DIRT:0)
Block(0,3,-1,STONE:0)
Block(0,3,0,STONE:0)
Block(0,3,1,DIRT:0)
Block(0,3,2,DIRT:0)
Block(0,3,3,DIRT:0)
Block(0,3,4,DIRT:0)
Block(0,3,5,DIRT:0)
Block(0,3,6,DIRT:0)
Block(0,4,-7,DIRT:0)
RandomBlock(0,4,-6,MONSTER_EGGS:4,null,6,MONSTER_EGGS:2,null,18,MONSTER_EGGS:3,null,6,SMOOTH_BRICK:2,null,12,SMOOTH_BRICK:1,null,12,SMOOTH_BRICK:0,null,80,COBBLESTONE:0,null,100)
Block(0,4,-5,STONE:0)
Block(0,4,-4,STONE:0)
Block(0,4,-3,STONE:0)
Block(0,4,-2,WOOL:15)
Block(0,4,-1,STONE_PLATE:0)
Block(0,4,0,STONE_PLATE:0)
Block(0,4,1,WOOL:15)
Block(0,4,2,STONE:0)
Block(0,4,3,STONE:0)
Block(0,4,4,STONE:0)
RandomBlock(0,4,5,MONSTER_EGGS:4,null,6,MONSTER_EGGS:2,null,18,MONSTER_EGGS:3,null,6,SMOOTH_BRICK:2,null,12,SMOOTH_BRICK:1,null,12,SMOOTH_BRICK:0,null,80,COBBLESTONE:0,null,100)
Block(0,4,6,DIRT:0)
Block(0,5,-7,DIRT:0)
RandomBlock(0,5,-6,MONSTER_EGGS:4,null,6,MONSTER_EGGS:2,null,18,MONSTER_EGGS:3,null,6,SMOOTH_BRICK:2,null,12,SMOOTH_BRICK:1,null,12,SMOOTH_BRICK:0,null,80,COBBLESTONE:0,null,100)
Block(0,5,-5,STONE:0)
Block(0,5,-4,STONE:0)
Block(0,5,-3,STONE:0)
Block(0,5,-2,WOOL:15)
Block(0,5,-1,AIR:0)
Block(0,5,0,AIR:0)
Block(0,5,1,WOOL:15)
Block(0,5,2,STONE:0)
Block(0,5,3,STONE:0)
Block(0,5,4,STONE:0)
Block(0,5,5,SMOOTH_BRICK:2)
Block(0,5,6,DIRT:0)
Block(0,6,-7,DIRT:0)
RandomBlock(0,6,-6,MONSTER_EGGS:4,null,6,MONSTER_EGGS:2,null,18,MONSTER_EGGS:3,null,6,SMOOTH_BRICK:2,null,12,SMOOTH_BRICK:1,null,12,SMOOTH_BRICK:0,null,80,COBBLESTONE:0,null,100)
Block(0,6,-5,STONE:0)
Block(0,6,-4,STONE:0)
Block(0,6,-3,STONE:0)
Block(0,6,-2,WOOL:15)
Block(0,6,-1,AIR:0)
Block(0,6,0,AIR:0)
Block(0,6,1,WOOL:15)
Block(0,6,2,STONE:0)
Block(0,6,3,STONE:0)
Block(0,6,4,STONE:0)
RandomBlock(0,6,5,MONSTER_EGGS:4,null,6,MONSTER_EGGS:2,null,18,MONSTER_EGGS:3,null,6,SMOOTH_BRICK:2,null,12,SMOOTH_BRICK:1,null,12,SMOOTH_BRICK:0,null,80,COBBLESTONE:0,null,100)
Block(0,6,6,DIRT:0)
Block(0,7,-7,DIRT:0)
RandomBlock(0,7,-6,MONSTER_EGGS:4,null,6,MONSTER_EGGS:2,null,18,MONSTER_EGGS:3,null,6,SMOOTH_BRICK:2,null,12,SMOOTH_BRICK:1,null,12,SMOOTH_BRICK:0,null,80,COBBLESTONE:0,null,100)
Block(0,7,-5,STONE:0)
Block(0,7,-4,STONE:0)
Block(0,7,-3,STONE:0)
Block(0,7,-2,WOOL:15)
Block(0,7,-1,WOOL:15)
Block(0,7,0,WOOL:15)
Block(0,7,1,WOOL:15)
Block(0,7,2,STONE:0)
Block(0,7,3,STONE:0)
Block(0,7,4,STONE:0)
RandomBlock(0,7,5,MONSTER_EGGS:4,null,6,MONSTER_EGGS:2,null,18,MONSTER_EGGS:3,null,6,SMOOTH_BRICK:2,null,12,SMOOTH_BRICK:1,null,12,SMOOTH_BRICK:0,null,80,COBBLESTONE:0,null,100)
Block(0,7,6,DIRT:0)
Block(0,8,-5,STONE:0)
Block(0,8,-4,STONE:0)
Block(0,8,-3,STONE:0)
Block(0,8,-2,STONE:0)
Block(0,8,-1,WOOL:15)
Block(0,8,0,WOOL:15)
Block(0,8,1,STONE:0)
Block(0,8,2,STONE:0)
Block(0,8,3,STONE:0)
Block(0,8,4,STONE:0)
RandomBlock(0,9,-5,MONSTER_EGGS:4,null,6,MONSTER_EGGS:2,null,18,MONSTER_EGGS:3,null,6,SMOOTH_BRICK:2,null,12,SMOOTH_BRICK:1,null,12,SMOOTH_BRICK:0,null,80,COBBLESTONE:0,null,100)
RandomBlock(0,9,-4,MONSTER_EGGS:4,null,6,MONSTER_EGGS:2,null,18,MONSTER_EGGS:3,null,6,SMOOTH_BRICK:2,null,12,SMOOTH_BRICK:1,null,12,SMOOTH_BRICK:0,null,80,COBBLESTONE:0,null,100)
Block(0,9,-3,WOOL:15)
Block(0,9,-2,WOOL:15)
Block(0,9,-1,AIR:0)
Block(0,9,0,AIR:0)
Block(0,9,1,WOOL:15)
Block(0,9,2,WOOL:15)
RandomBlock(0,9,3,MONSTER_EGGS:4,null,6,MONSTER_EGGS:2,null,18,MONSTER_EGGS:3,null,6,SMOOTH_BRICK:2,null,12,SMOOTH_BRICK:1,null,12,SMOOTH_BRICK:0,null,80,COBBLESTONE:0,null,100)
RandomBlock(0,9,4,MONSTER_EGGS:4,null,6,MONSTER_EGGS:2,null,18,MONSTER_EGGS:3,null,6,SMOOTH_BRICK:2,null,12,SMOOTH_BRICK:1,null,12,SMOOTH_BRICK:0,null,80,COBBLESTONE:0,null,100)
Block(0,10,-6,VINE:1)
RandomBlock(0,10,-5,MONSTER_EGGS:4,null,6,MONSTER_EGGS:2,null,18,MONSTER_EGGS:3,null,6,SMOOTH_BRICK:2,null,12,SMOOTH_BRICK:1,null,12,SMOOTH_BRICK:0,null,80,COBBLESTONE:0,null,100)
Block(0,10,-4,AIR:0)
Block(0,10,-3,WOOL:15)
Block(0,10,-2,WOOL:15)
Block(0,10,-1,AIR:0)
Block(0,10,0,AIR:0)
Block(0,10,1,WOOL:15)
Block(0,10,2,WOOL:15)
RandomBlock(0,10,3,MONSTER_EGGS:4,null,6,MONSTER_EGGS:2,null,18,MONSTER_EGGS:3,null,6,SMOOTH_BRICK:2,null,12,SMOOTH_BRICK:1,null,12,SMOOTH_BRICK:0,null,80,COBBLESTONE:0,null,100)
RandomBlock(0,10,4,MONSTER_EGGS:4,null,6,MONSTER_EGGS:2,null,18,MONSTER_EGGS:3,null,6,SMOOTH_BRICK:2,null,12,SMOOTH_BRICK:1,null,12,SMOOTH_BRICK:0,null,80,COBBLESTONE:0,null,100)
Block(0,10,5,VINE:4)
Block(0,11,-6,VINE:1)
RandomBlock(0,11,-5,MONSTER_EGGS:4,null,6,MONSTER_EGGS:2,null,18,MONSTER_EGGS:3,null,6,SMOOTH_BRICK:2,null,12,SMOOTH_BRICK:1,null,12,SMOOTH_BRICK:0,null,80,COBBLESTONE:0,null,100)
RandomBlock(0,11,-4,MONSTER_EGGS:4,null,6,MONSTER_EGGS:2,null,18,MONSTER_EGGS:3,null,6,SMOOTH_BRICK:2,null,12,SMOOTH_BRICK:1,null,12,SMOOTH_BRICK:0,null,80,COBBLESTONE:0,null,100)
RandomBlock(0,11,-3,MONSTER_EGGS:4,null,6,MONSTER_EGGS:2,null,18,MONSTER_EGGS:3,null,6,SMOOTH_BRICK:2,null,12,SMOOTH_BRICK:1,null,12,SMOOTH_BRICK:0,null,80,COBBLESTONE:0,null,100)
RandomBlock(0,11,-2,MONSTER_EGGS:4,null,6,MONSTER_EGGS:2,null,18,MONSTER_EGGS:3,null,6,SMOOTH_BRICK:2,null,12,SMOOTH_BRICK:1,null,12,SMOOTH_BRICK:0,null,80,COBBLESTONE:0,null,100)
RandomBlock(0,11,-1,MONSTER_EGGS:4,null,6,MONSTER_EGGS:2,null,18,MONSTER_EGGS:3,null,6,SMOOTH_BRICK:2,null,12,SMOOTH_BRICK:1,null,12,SMOOTH_BRICK:0,null,80,COBBLESTONE:0,null,100)
RandomBlock(0,11,0,MONSTER_EGGS:4,null,6,MONSTER_EGGS:2,null,18,MONSTER_EGGS:3,null,6,SMOOTH_BRICK:2,null,12,SMOOTH_BRICK:1,null,12,SMOOTH_BRICK:0,null,80,COBBLESTONE:0,null,100)
RandomBlock(0,11,1,MONSTER_EGGS:4,null,6,MONSTER_EGGS:2,null,18,MONSTER_EGGS:3,null,6,SMOOTH_BRICK:2,null,12,SMOOTH_BRICK:1,null,12,SMOOTH_BRICK:0,null,80,COBBLESTONE:0,null,100)
RandomBlock(0,11,2,MONSTER_EGGS:4,null,6,MONSTER_EGGS:2,null,18,MONSTER_EGGS:3,null,6,SMOOTH_BRICK:2,null,12,SMOOTH_BRICK:1,null,12,SMOOTH_BRICK:0,null,80,COBBLESTONE:0,null,100)
RandomBlock(0,11,3,MONSTER_EGGS:4,null,6,MONSTER_EGGS:2,null,18,MONSTER_EGGS:3,null,6,SMOOTH_BRICK:2,null,12,SMOOTH_BRICK:1,null,12,SMOOTH_BRICK:0,null,80,COBBLESTONE:0,null,100)
RandomBlock(0,11,4,MONSTER_EGGS:4,null,6,MONSTER_EGGS:2,null,18,MONSTER_EGGS:3,null,6,SMOOTH_BRICK:2,null,12,SMOOTH_BRICK:1,null,12,SMOOTH_BRICK:0,null,80,COBBLESTONE:0,null,100)
Block(0,11,5,VINE:4)
Block(1,0,-7,DIRT:0)
Block(1,0,-6,DIRT:0)
Block(1,0,-5,DIRT:0)
Block(1,0,-4,DIRT:0)
Block(1,0,-3,DIRT:0)
Block(1,0,-2,DIRT:0)
Block(1,0,-1,DIRT:0)
Block(1,0,0,DIRT:0)
Block(1,0,1,DIRT:0)
Block(1,0,2,DIRT:0)
Block(1,0,3,DIRT:0)
Block(1,0,4,DIRT:0)
Block(1,0,5,DIRT:0)
Block(1,0,6,DIRT:0)
Block(1,1,-7,DIRT:0)
Block(1,1,-6,DIRT:0)
Block(1,1,-5,DIRT:0)
Block(1,1,-4,DIRT:0)
Block(1,1,-3,DIRT:0)
Block(1,1,-2,DIRT:0)
Block(1,1,-1,DIRT:0)
Block(1,1,0,DIRT:0)
Block(1,1,1,DIRT:0)
Block(1,1,2,DIRT:0)
Block(1,1,3,DIRT:0)
Block(1,1,4,DIRT:0)
Block(1,1,5,DIRT:0)
Block(1,1,6,DIRT:0)
Block(1,2,-7,DIRT:0)
Block(1,2,-6,GRASS:0)
Block(1,2,-5,GRASS:0)
Block(1,2,-4,DIRT:0)
Block(1,2,-3,DIRT:0)
Block(1,2,-2,DIRT:0)
Block(1,2,-1,DIRT:0)
Block(1,2,0,DIRT:0)
Block(1,2,1,DIRT:0)
Block(1,2,2,DIRT:0)
Block(1,2,3,DIRT:0)
Block(1,2,4,GRASS:0)
Block(1,2,5,GRASS:0)
Block(1,2,6,DIRT:0)
Block(1,3,-7,DIRT:0)
Block(1,3,-6,REDSTONE_TORCH_ON:5)
Block(1,3,-5,REDSTONE_WIRE:15)
Block(1,3,-4,GRASS:0)
Block(1,3,-3,GRASS:0)
Block(1,3,-2,DIRT:0)
Block(1,3,-1,STONE:0)
Block(1,3,0,STONE:0)
Block(1,3,1,DIRT:0)
Block(1,3,2,GRASS:0)
Block(1,3,3,GRASS:0)
Block(1,3,4,REDSTONE_WIRE:15)
Block(1,3,5,REDSTONE_TORCH_ON:5)
Block(1,3,6,DIRT:0)
RandomBlock(1,4,-7,MONSTER_EGGS:4,null,6,MONSTER_EGGS:2,null,18,MONSTER_EGGS:3,null,6,SMOOTH_BRICK:2,null,12,SMOOTH_BRICK:1,null,12,SMOOTH_BRICK:0,null,80,COBBLESTONE:0,null,100)
Block(1,4,-6,STONE:0)
Block(1,4,-5,AIR:0)
Block(1,4,-4,REDSTONE_WIRE:14)
Block(1,4,-3,PISTON_STICKY_BASE:11)
Block(1,4,-2,PISTON_MOVING_PIECE:11)
RandomBlock(1,4,-1,MONSTER_EGGS:4,null,6,MONSTER_EGGS:2,null,18,MONSTER_EGGS:3,null,6,SMOOTH_BRICK:2,null,12,SMOOTH_BRICK:1,null,12,SMOOTH_BRICK:0,null,80,COBBLESTONE:0,null,100)
RandomBlock(1,4,0,MONSTER_EGGS:4,null,6,MONSTER_EGGS:2,null,18,MONSTER_EGGS:3,null,6,SMOOTH_BRICK:2,null,12,SMOOTH_BRICK:1,null,12,SMOOTH_BRICK:0,null,80,COBBLESTONE:0,null,100)
Block(1,4,1,PISTON_MOVING_PIECE:10)
Block(1,4,2,PISTON_STICKY_BASE:10)
Block(1,4,3,REDSTONE_WIRE:14)
Block(1,4,4,AIR:0)
Block(1,4,5,STONE:0)
RandomBlock(1,4,6,MONSTER_EGGS:4,null,6,MONSTER_EGGS:2,null,18,MONSTER_EGGS:3,null,6,SMOOTH_BRICK:2,null,12,SMOOTH_BRICK:1,null,12,SMOOTH_BRICK:0,null,80,COBBLESTONE:0,null,100)
RandomBlock(1,5,-7,MONSTER_EGGS:4,null,6,MONSTER_EGGS:2,null,18,MONSTER_EGGS:3,null,6,SMOOTH_BRICK:2,null,12,SMOOTH_BRICK:1,null,12,SMOOTH_BRICK:0,null,80,COBBLESTONE:0,null,100)
Block(1,5,-6,REDSTONE_WIRE:15)
Block(1,5,-5,STONE:0)
Block(1,5,-4,STONE:0)
Block(1,5,-3,PISTON_STICKY_BASE:11)
Block(1,5,-2,PISTON_MOVING_PIECE:11)
Block(1,5,-1,WOOL:15)
Block(1,5,0,WOOL:15)
Block(1,5,1,PISTON_MOVING_PIECE:10)
Block(1,5,2,PISTON_STICKY_BASE:10)
Block(1,5,3,STONE:0)
Block(1,5,4,STONE:0)
Block(1,5,5,REDSTONE_WIRE:15)
Block(1,5,6,SMOOTH_BRICK:2)
RandomBlock(1,6,-7,MONSTER_EGGS:4,null,6,MONSTER_EGGS:2,null,18,MONSTER_EGGS:3,null,6,SMOOTH_BRICK:2,null,12,SMOOTH_BRICK:1,null,12,SMOOTH_BRICK:0,null,80,COBBLESTONE:0,null,100)
Block(1,6,-6,AIR:0)
Block(1,6,-5,REDSTONE_WIRE:14)
Block(1,6,-4,REDSTONE_WIRE:13)
Block(1,6,-3,PISTON_STICKY_BASE:11)
Block(1,6,-2,PISTON_MOVING_PIECE:11)
Block(1,6,-1,WOOL:15)
Block(1,6,0,WOOL:15)
Block(1,6,1,PISTON_MOVING_PIECE:10)
Block(1,6,2,PISTON_STICKY_BASE:10)
Block(1,6,3,REDSTONE_WIRE:13)
Block(1,6,4,REDSTONE_WIRE:14)
Block(1,6,5,AIR:0)
Block(1,6,6,SMOOTH_BRICK:2)
RandomBlock(1,7,-7,MONSTER_EGGS:4,null,6,MONSTER_EGGS:2,null,18,MONSTER_EGGS:3,null,6,SMOOTH_BRICK:2,null,12,SMOOTH_BRICK:1,null,12,SMOOTH_BRICK:0,null,80,COBBLESTONE:0,null,100)
Block(1,7,-6,STONE:0)
Block(1,7,-5,STONE:0)
Block(1,7,-4,STONE:0)
Block(1,7,-3,STONE:0)
Block(1,7,-2,STONE:0)
Block(1,7,-1,STONE:0)
Block(1,7,0,STONE:0)
Block(1,7,1,STONE:0)
Block(1,7,2,STONE:0)
Block(1,7,3,STONE:0)
Block(1,7,4,STONE:0)
Block(1,7,5,STONE:0)
Block(1,7,6,SMOOTH_BRICK:2)
RandomBlock(1,8,-5,MONSTER_EGGS:4,null,6,MONSTER_EGGS:2,null,18,MONSTER_EGGS:3,null,6,SMOOTH_BRICK:2,null,12,SMOOTH_BRICK:1,null,12,SMOOTH_BRICK:0,null,80,COBBLESTONE:0,null,100)
RandomBlock(1,8,-4,MONSTER_EGGS:4,null,6,MONSTER_EGGS:2,null,18,MONSTER_EGGS:3,null,6,SMOOTH_BRICK:2,null,12,SMOOTH_BRICK:1,null,12,SMOOTH_BRICK:0,null,80,COBBLESTONE:0,null,100)
Block(1,8,-3,SMOOTH_BRICK:2)
RandomBlock(1,8,-2,MONSTER_EGGS:4,null,6,MONSTER_EGGS:2,null,18,MONSTER_EGGS:3,null,6,SMOOTH_BRICK:2,null,12,SMOOTH_BRICK:1,null,12,SMOOTH_BRICK:0,null,80,COBBLESTONE:0,null,100)
Block(1,8,-1,SMOOTH_BRICK:2)
RandomBlock(1,8,0,MONSTER_EGGS:4,null,6,MONSTER_EGGS:2,null,18,MONSTER_EGGS:3,null,6,SMOOTH_BRICK:2,null,12,SMOOTH_BRICK:1,null,12,SMOOTH_BRICK:0,null,80,COBBLESTONE:0,null,100)
RandomBlock(1,8,1,MONSTER_EGGS:4,null,6,MONSTER_EGGS:2,null,18,MONSTER_EGGS:3,null,6,SMOOTH_BRICK:2,null,12,SMOOTH_BRICK:1,null,12,SMOOTH_BRICK:0,null,80,COBBLESTONE:0,null,100)
RandomBlock(1,8,2,MONSTER_EGGS:4,null,6,MONSTER_EGGS:2,null,18,MONSTER_EGGS:3,null,6,SMOOTH_BRICK:2,null,12,SMOOTH_BRICK:1,null,12,SMOOTH_BRICK:0,null,80,COBBLESTONE:0,null,100)
RandomBlock(1,8,3,MONSTER_EGGS:4,null,6,MONSTER_EGGS:2,null,18,MONSTER_EGGS:3,null,6,SMOOTH_BRICK:2,null,12,SMOOTH_BRICK:1,null,12,SMOOTH_BRICK:0,null,80,COBBLESTONE:0,null,100)
RandomBlock(1,8,4,MONSTER_EGGS:4,null,6,MONSTER_EGGS:2,null,18,MONSTER_EGGS:3,null,6,SMOOTH_BRICK:2,null,12,SMOOTH_BRICK:1,null,12,SMOOTH_BRICK:0,null,80,COBBLESTONE:0,null,100)
RandomBlock(1,9,-5,MONSTER_EGGS:4,null,6,MONSTER_EGGS:2,null,18,MONSTER_EGGS:3,null,6,SMOOTH_BRICK:2,null,12,SMOOTH_BRICK:1,null,12,SMOOTH_BRICK:0,null,80,COBBLESTONE:0,null,100)
RandomBlock(1,9,-4,MONSTER_EGGS:4,null,6,MONSTER_EGGS:2,null,18,MONSTER_EGGS:3,null,6,SMOOTH_BRICK:2,null,12,SMOOTH_BRICK:1,null,12,SMOOTH_BRICK:0,null,80,COBBLESTONE:0,null,100)
Block(1,9,-3,SMOOTH_BRICK:2)
Block(1,9,-2,SMOOTH_BRICK:2)
Block(1,9,-1,SMOOTH_BRICK:2)
RandomBlock(1,9,0,MONSTER_EGGS:4,null,6,MONSTER_EGGS:2,null,18,MONSTER_EGGS:3,null,6,SMOOTH_BRICK:2,null,12,SMOOTH_BRICK:1,null,12,SMOOTH_BRICK:0,null,80,COBBLESTONE:0,null,100)
RandomBlock(1,9,1,MONSTER_EGGS:4,null,6,MONSTER_EGGS:2,null,18,MONSTER_EGGS:3,null,6,SMOOTH_BRICK:2,null,12,SMOOTH_BRICK:1,null,12,SMOOTH_BRICK:0,null,80,COBBLESTONE:0,null,100)
RandomBlock(1,9,2,MONSTER_EGGS:4,null,6,MONSTER_EGGS:2,null,18,MONSTER_EGGS:3,null,6,SMOOTH_BRICK:2,null,12,SMOOTH_BRICK:1,null,12,SMOOTH_BRICK:0,null,80,COBBLESTONE:0,null,100)
RandomBlock(1,9,3,MONSTER_EGGS:4,null,6,MONSTER_EGGS:2,null,18,MONSTER_EGGS:3,null,6,SMOOTH_BRICK:2,null,12,SMOOTH_BRICK:1,null,12,SMOOTH_BRICK:0,null,80,COBBLESTONE:0,null,100)
RandomBlock(1,9,4,MONSTER_EGGS:4,null,6,MONSTER_EGGS:2,null,18,MONSTER_EGGS:3,null,6,SMOOTH_BRICK:2,null,12,SMOOTH_BRICK:1,null,12,SMOOTH_BRICK:0,null,80,COBBLESTONE:0,null,100)
RandomBlock(1,10,-5,MONSTER_EGGS:4,null,6,MONSTER_EGGS:2,null,18,MONSTER_EGGS:3,null,6,SMOOTH_BRICK:2,null,12,SMOOTH_BRICK:1,null,12,SMOOTH_BRICK:0,null,80,COBBLESTONE:0,null,100)
RandomBlock(1,10,-4,MONSTER_EGGS:4,null,6,MONSTER_EGGS:2,null,18,MONSTER_EGGS:3,null,6,SMOOTH_BRICK:2,null,12,SMOOTH_BRICK:1,null,12,SMOOTH_BRICK:0,null,80,COBBLESTONE:0,null,100)
RandomBlock(1,10,-3,MONSTER_EGGS:4,null,6,MONSTER_EGGS:2,null,18,MONSTER_EGGS:3,null,6,SMOOTH_BRICK:2,null,12,SMOOTH_BRICK:1,null,12,SMOOTH_BRICK:0,null,80,COBBLESTONE:0,null,100)
RandomBlock(1,10,-2,MONSTER_EGGS:4,null,6,MONSTER_EGGS:2,null,18,MONSTER_EGGS:3,null,6,SMOOTH_BRICK:2,null,12,SMOOTH_BRICK:1,null,12,SMOOTH_BRICK:0,null,80,COBBLESTONE:0,null,100)
RandomBlock(1,10,-1,MONSTER_EGGS:4,null,6,MONSTER_EGGS:2,null,18,MONSTER_EGGS:3,null,6,SMOOTH_BRICK:2,null,12,SMOOTH_BRICK:1,null,12,SMOOTH_BRICK:0,null,80,COBBLESTONE:0,null,100)
RandomBlock(1,10,0,MONSTER_EGGS:4,null,6,MONSTER_EGGS:2,null,18,MONSTER_EGGS:3,null,6,SMOOTH_BRICK:2,null,12,SMOOTH_BRICK:1,null,12,SMOOTH_BRICK:0,null,80,COBBLESTONE:0,null,100)
RandomBlock(1,10,1,MONSTER_EGGS:4,null,6,MONSTER_EGGS:2,null,18,MONSTER_EGGS:3,null,6,SMOOTH_BRICK:2,null,12,SMOOTH_BRICK:1,null,12,SMOOTH_BRICK:0,null,80,COBBLESTONE:0,null,100)
RandomBlock(1,10,2,MONSTER_EGGS:4,null,6,MONSTER_EGGS:2,null,18,MONSTER_EGGS:3,null,6,SMOOTH_BRICK:2,null,12,SMOOTH_BRICK:1,null,12,SMOOTH_BRICK:0,null,80,COBBLESTONE:0,null,100)
RandomBlock(1,10,3,MONSTER_EGGS:4,null,6,MONSTER_EGGS:2,null,18,MONSTER_EGGS:3,null,6,SMOOTH_BRICK:2,null,12,SMOOTH_BRICK:1,null,12,SMOOTH_BRICK:0,null,80,COBBLESTONE:0,null,100)
RandomBlock(1,10,4,MONSTER_EGGS:4,null,6,MONSTER_EGGS:2,null,18,MONSTER_EGGS:3,null,6,SMOOTH_BRICK:2,null,12,SMOOTH_BRICK:1,null,12,SMOOTH_BRICK:0,null,80,COBBLESTONE:0,null,100)
RandomBlock(1,11,-5,MONSTER_EGGS:4,null,6,MONSTER_EGGS:2,null,18,MONSTER_EGGS:3,null,6,SMOOTH_BRICK:2,null,12,SMOOTH_BRICK:1,null,12,SMOOTH_BRICK:0,null,80,COBBLESTONE:0,null,100)
RandomBlock(1,11,-4,MONSTER_EGGS:4,null,6,MONSTER_EGGS:2,null,18,MONSTER_EGGS:3,null,6,SMOOTH_BRICK:2,null,12,SMOOTH_BRICK:1,null,12,SMOOTH_BRICK:0,null,80,COBBLESTONE:0,null,100)
RandomBlock(1,11,-3,MONSTER_EGGS:4,null,6,MONSTER_EGGS:2,null,18,MONSTER_EGGS:3,null,6,SMOOTH_BRICK:2,null,12,SMOOTH_BRICK:1,null,12,SMOOTH_BRICK:0,null,80,COBBLESTONE:0,null,100)
RandomBlock(1,11,-2,MONSTER_EGGS:4,null,6,MONSTER_EGGS:2,null,18,MONSTER_EGGS:3,null,6,SMOOTH_BRICK:2,null,12,SMOOTH_BRICK:1,null,12,SMOOTH_BRICK:0,null,80,COBBLESTONE:0,null,100)
RandomBlock(1,11,-1,MONSTER_EGGS:4,null,6,MONSTER_EGGS:2,null,18,MONSTER_EGGS:3,null,6,SMOOTH_BRICK:2,null,12,SMOOTH_BRICK:1,null,12,SMOOTH_BRICK:0,null,80,COBBLESTONE:0,null,100)
RandomBlock(1,11,0,MONSTER_EGGS:4,null,6,MONSTER_EGGS:2,null,18,MONSTER_EGGS:3,null,6,SMOOTH_BRICK:2,null,12,SMOOTH_BRICK:1,null,12,SMOOTH_BRICK:0,null,80,COBBLESTONE:0,null,100)
RandomBlock(1,11,1,MONSTER_EGGS:4,null,6,MONSTER_EGGS:2,null,18,MONSTER_EGGS:3,null,6,SMOOTH_BRICK:2,null,12,SMOOTH_BRICK:1,null,12,SMOOTH_BRICK:0,null,80,COBBLESTONE:0,null,100)
RandomBlock(1,11,2,MONSTER_EGGS:4,null,6,MONSTER_EGGS:2,null,18,MONSTER_EGGS:3,null,6,SMOOTH_BRICK:2,null,12,SMOOTH_BRICK:1,null,12,SMOOTH_BRICK:0,null,80,COBBLESTONE:0,null,100)
RandomBlock(1,11,3,MONSTER_EGGS:4,null,6,MONSTER_EGGS:2,null,18,MONSTER_EGGS:3,null,6,SMOOTH_BRICK:2,null,12,SMOOTH_BRICK:1,null,12,SMOOTH_BRICK:0,null,80,COBBLESTONE:0,null,100)
RandomBlock(1,11,4,MONSTER_EGGS:4,null,6,MONSTER_EGGS:2,null,18,MONSTER_EGGS:3,null,6,SMOOTH_BRICK:2,null,12,SMOOTH_BRICK:1,null,12,SMOOTH_BRICK:0,null,80,COBBLESTONE:0,null,100)
Block(2,0,-7,DIRT:0)
Block(2,0,-6,DIRT:0)
Block(2,0,-5,DIRT:0)
Block(2,0,-4,DIRT:0)
Block(2,0,-3,DIRT:0)
Block(2,0,-2,DIRT:0)
Block(2,0,-1,DIRT:0)
Block(2,0,0,DIRT:0)
Block(2,0,1,DIRT:0)
Block(2,0,2,DIRT:0)
Block(2,0,3,DIRT:0)
Block(2,0,4,DIRT:0)
Block(2,0,5,DIRT:0)
Block(2,0,6,DIRT:0)
Block(2,1,-7,DIRT:0)
Block(2,1,-6,DIRT:0)
Block(2,1,-5,DIRT:0)
Block(2,1,-4,DIRT:0)
Block(2,1,-3,DIRT:0)
Block(2,1,-2,DIRT:0)
Block(2,1,-1,DIRT:0)
Block(2,1,0,DIRT:0)
Block(2,1,1,DIRT:0)
Block(2,1,2,DIRT:0)
Block(2,1,3,DIRT:0)
Block(2,1,4,DIRT:0)
Block(2,1,5,DIRT:0)
Block(2,1,6,DIRT:0)
Block(2,2,-7,DIRT:0)
Block(2,2,-6,DIRT:0)
Block(2,2,-5,DIRT:0)
Block(2,2,-4,DIRT:0)
Block(2,2,-3,DIRT:0)
Block(2,2,-2,DIRT:0)
Block(2,2,-1,DIRT:0)
Block(2,2,0,DIRT:0)
Block(2,2,1,DIRT:0)
Block(2,2,2,DIRT:0)
Block(2,2,3,DIRT:0)
Block(2,2,4,DIRT:0)
Block(2,2,5,DIRT:0)
Block(2,2,6,DIRT:0)
Block(2,3,-7,DIRT:0)
Block(2,3,-6,DIRT:0)
Block(2,3,-5,DIRT:0)
Block(2,3,-4,DIRT:0)
Block(2,3,-3,DIRT:0)
Block(2,3,-2,DIRT:0)
RandomBlock(2,3,-1,MONSTER_EGGS:4,null,6,MONSTER_EGGS:2,null,18,MONSTER_EGGS:3,null,6,SMOOTH_BRICK:2,null,12,SMOOTH_BRICK:1,null,12,SMOOTH_BRICK:0,null,80,COBBLESTONE:0,null,100)
Block(2,3,0,SMOOTH_BRICK:2)
Block(2,3,1,DIRT:0)
Block(2,3,2,DIRT:0)
Block(2,3,3,DIRT:0)
Block(2,3,4,DIRT:0)
Block(2,3,5,DIRT:0)
Block(2,3,6,DIRT:0)
RandomBlock(2,4,-7,MONSTER_EGGS:4,null,6,MONSTER_EGGS:2,null,18,MONSTER_EGGS:3,null,6,SMOOTH_BRICK:2,null,12,SMOOTH_BRICK:1,null,12,SMOOTH_BRICK:0,null,80,COBBLESTONE:0,null,100)
RandomBlock(2,4,-6,MONSTER_EGGS:4,null,6,MONSTER_EGGS:2,null,18,MONSTER_EGGS:3,null,6,SMOOTH_BRICK:2,null,12,SMOOTH_BRICK:1,null,12,SMOOTH_BRICK:0,null,80,COBBLESTONE:0,null,100)
Block(2,4,-5,SMOOTH_BRICK:2)
RandomBlock(2,4,-4,MONSTER_EGGS:4,null,6,MONSTER_EGGS:2,null,18,MONSTER_EGGS:3,null,6,SMOOTH_BRICK:2,null,12,SMOOTH_BRICK:1,null,12,SMOOTH_BRICK:0,null,80,COBBLESTONE:0,null,100)
RandomBlock(2,4,-3,MONSTER_EGGS:4,null,6,MONSTER_EGGS:2,null,18,MONSTER_EGGS:3,null,6,SMOOTH_BRICK:2,null,12,SMOOTH_BRICK:1,null,12,SMOOTH_BRICK:0,null,80,COBBLESTONE:0,null,100)
RandomBlock(2,4,-2,MONSTER_EGGS:4,null,6,MONSTER_EGGS:2,null,18,MONSTER_EGGS:3,null,6,SMOOTH_BRICK:2,null,12,SMOOTH_BRICK:1,null,12,SMOOTH_BRICK:0,null,80,COBBLESTONE:0,null,100)
Block(2,4,-1,AIR:0)
Block(2,4,0,AIR:0)
RandomBlock(2,4,1,MONSTER_EGGS:4,null,6,MONSTER_EGGS:2,null,18,MONSTER_EGGS:3,null,6,SMOOTH_BRICK:2,null,12,SMOOTH_BRICK:1,null,12,SMOOTH_BRICK:0,null,80,COBBLESTONE:0,null,100)
RandomBlock(2,4,2,MONSTER_EGGS:4,null,6,MONSTER_EGGS:2,null,18,MONSTER_EGGS:3,null,6,SMOOTH_BRICK:2,null,12,SMOOTH_BRICK:1,null,12,SMOOTH_BRICK:0,null,80,COBBLESTONE:0,null,100)
RandomBlock(2,4,3,MONSTER_EGGS:4,null,6,MONSTER_EGGS:2,null,18,MONSTER_EGGS:3,null,6,SMOOTH_BRICK:2,null,12,SMOOTH_BRICK:1,null,12,SMOOTH_BRICK:0,null,80,COBBLESTONE:0,null,100)
RandomBlock(2,4,4,MONSTER_EGGS:4,null,6,MONSTER_EGGS:2,null,18,MONSTER_EGGS:3,null,6,SMOOTH_BRICK:2,null,12,SMOOTH_BRICK:1,null,12,SMOOTH_BRICK:0,null,80,COBBLESTONE:0,null,100)
RandomBlock(2,4,5,MONSTER_EGGS:4,null,6,MONSTER_EGGS:2,null,18,MONSTER_EGGS:3,null,6,SMOOTH_BRICK:2,null,12,SMOOTH_BRICK:1,null,12,SMOOTH_BRICK:0,null,80,COBBLESTONE:0,null,100)
RandomBlock(2,4,6,MONSTER_EGGS:4,null,6,MONSTER_EGGS:2,null,18,MONSTER_EGGS:3,null,6,SMOOTH_BRICK:2,null,12,SMOOTH_BRICK:1,null,12,SMOOTH_BRICK:0,null,80,COBBLESTONE:0,null,100)
RandomBlock(2,5,-7,MONSTER_EGGS:4,null,6,MONSTER_EGGS:2,null,18,MONSTER_EGGS:3,null,6,SMOOTH_BRICK:2,null,12,SMOOTH_BRICK:1,null,12,SMOOTH_BRICK:0,null,80,COBBLESTONE:0,null,100)
RandomBlock(2,5,-6,MONSTER_EGGS:4,null,6,MONSTER_EGGS:2,null,18,MONSTER_EGGS:3,null,6,SMOOTH_BRICK:2,null,12,SMOOTH_BRICK:1,null,12,SMOOTH_BRICK:0,null,80,COBBLESTONE:0,null,100)
RandomBlock(2,5,-5,MONSTER_EGGS:4,null,6,MONSTER_EGGS:2,null,18,MONSTER_EGGS:3,null,6,SMOOTH_BRICK:2,null,12,SMOOTH_BRICK:1,null,12,SMOOTH_BRICK:0,null,80,COBBLESTONE:0,null,100)
RandomBlock(2,5,-4,MONSTER_EGGS:4,null,6,MONSTER_EGGS:2,null,18,MONSTER_EGGS:3,null,6,SMOOTH_BRICK:2,null,12,SMOOTH_BRICK:1,null,12,SMOOTH_BRICK:0,null,80,COBBLESTONE:0,null,100)
Block(2,5,-3,SMOOTH_BRICK:2)
Block(2,5,-2,SMOOTH_BRICK:2)
Block(2,5,-1,AIR:0)
Block(2,5,0,AIR:0)
RandomBlock(2,5,1,MONSTER_EGGS:4,null,6,MONSTER_EGGS:2,null,18,MONSTER_EGGS:3,null,6,SMOOTH_BRICK:2,null,12,SMOOTH_BRICK:1,null,12,SMOOTH_BRICK:0,null,80,COBBLESTONE:0,null,100)
RandomBlock(2,5,2,MONSTER_EGGS:4,null,6,MONSTER_EGGS:2,null,18,MONSTER_EGGS:3,null,6,SMOOTH_BRICK:2,null,12,SMOOTH_BRICK:1,null,12,SMOOTH_BRICK:0,null,80,COBBLESTONE:0,null,100)
Block(2,5,3,SMOOTH_BRICK:2)
RandomBlock(2,5,4,MONSTER_EGGS:4,null,6,MONSTER_EGGS:2,null,18,MONSTER_EGGS:3,null,6,SMOOTH_BRICK:2,null,12,SMOOTH_BRICK:1,null,12,SMOOTH_BRICK:0,null,80,COBBLESTONE:0,null,100)
RandomBlock(2,5,5,MONSTER_EGGS:4,null,6,MONSTER_EGGS:2,null,18,MONSTER_EGGS:3,null,6,SMOOTH_BRICK:2,null,12,SMOOTH_BRICK:1,null,12,SMOOTH_BRICK:0,null,80,COBBLESTONE:0,null,100)
RandomBlock(2,5,6,MONSTER_EGGS:4,null,6,MONSTER_EGGS:2,null,18,MONSTER_EGGS:3,null,6,SMOOTH_BRICK:2,null,12,SMOOTH_BRICK:1,null,12,SMOOTH_BRICK:0,null,80,COBBLESTONE:0,null,100)
RandomBlock(2,6,-7,MONSTER_EGGS:4,null,6,MONSTER_EGGS:2,null,18,MONSTER_EGGS:3,null,6,SMOOTH_BRICK:2,null,12,SMOOTH_BRICK:1,null,12,SMOOTH_BRICK:0,null,80,COBBLESTONE:0,null,100)
RandomBlock(2,6,-6,MONSTER_EGGS:4,null,6,MONSTER_EGGS:2,null,18,MONSTER_EGGS:3,null,6,SMOOTH_BRICK:2,null,12,SMOOTH_BRICK:1,null,12,SMOOTH_BRICK:0,null,80,COBBLESTONE:0,null,100)
Block(2,6,-5,SMOOTH_BRICK:2)
RandomBlock(2,6,-4,MONSTER_EGGS:4,null,6,MONSTER_EGGS:2,null,18,MONSTER_EGGS:3,null,6,SMOOTH_BRICK:2,null,12,SMOOTH_BRICK:1,null,12,SMOOTH_BRICK:0,null,80,COBBLESTONE:0,null,100)
Block(2,6,-3,SMOOTH_BRICK:2)
Block(2,6,-2,SMOOTH_BRICK:2)
Block(2,6,-1,AIR:0)
Block(2,6,0,AIR:0)
RandomBlock(2,6,1,MONSTER_EGGS:4,null,6,MONSTER_EGGS:2,null,18,MONSTER_EGGS:3,null,6,SMOOTH_BRICK:2,null,12,SMOOTH_BRICK:1,null,12,SMOOTH_BRICK:0,null,80,COBBLESTONE:0,null,100)
Block(2,6,2,SMOOTH_BRICK:2)
Block(2,6,3,SMOOTH_BRICK:2)
RandomBlock(2,6,4,MONSTER_EGGS:4,null,6,MONSTER_EGGS:2,null,18,MONSTER_EGGS:3,null,6,SMOOTH_BRICK:2,null,12,SMOOTH_BRICK:1,null,12,SMOOTH_BRICK:0,null,80,COBBLESTONE:0,null,100)
Block(2,6,5,SMOOTH_BRICK:2)
RandomBlock(2,6,6,MONSTER_EGGS:4,null,6,MONSTER_EGGS:2,null,18,MONSTER_EGGS:3,null,6,SMOOTH_BRICK:2,null,12,SMOOTH_BRICK:1,null,12,SMOOTH_BRICK:0,null,80,COBBLESTONE:0,null,100)
RandomBlock(2,7,-7,MONSTER_EGGS:4,null,6,MONSTER_EGGS:2,null,18,MONSTER_EGGS:3,null,6,SMOOTH_BRICK:2,null,12,SMOOTH_BRICK:1,null,12,SMOOTH_BRICK:0,null,80,COBBLESTONE:0,null,100)
RandomBlock(2,7,-6,MONSTER_EGGS:4,null,6,MONSTER_EGGS:2,null,18,MONSTER_EGGS:3,null,6,SMOOTH_BRICK:2,null,12,SMOOTH_BRICK:1,null,12,SMOOTH_BRICK:0,null,80,COBBLESTONE:0,null,100)
RandomBlock(2,7,-5,MONSTER_EGGS:4,null,6,MONSTER_EGGS:2,null,18,MONSTER_EGGS:3,null,6,SMOOTH_BRICK:2,null,12,SMOOTH_BRICK:1,null,12,SMOOTH_BRICK:0,null,80,COBBLESTONE:0,null,100)
RandomBlock(2,7,-4,MONSTER_EGGS:4,null,6,MONSTER_EGGS:2,null,18,MONSTER_EGGS:3,null,6,SMOOTH_BRICK:2,null,12,SMOOTH_BRICK:1,null,12,SMOOTH_BRICK:0,null,80,COBBLESTONE:0,null,100)
Block(2,7,-3,SMOOTH_BRICK:2)
Block(2,7,-2,SMOOTH_BRICK:2)
RandomBlock(2,7,-1,MONSTER_EGGS:4,null,6,MONSTER_EGGS:2,null,18,MONSTER_EGGS:3,null,6,SMOOTH_BRICK:2,null,12,SMOOTH_BRICK:1,null,12,SMOOTH_BRICK:0,null,80,COBBLESTONE:0,null,100)
RandomBlock(2,7,0,MONSTER_EGGS:4,null,6,MONSTER_EGGS:2,null,18,MONSTER_EGGS:3,null,6,SMOOTH_BRICK:2,null,12,SMOOTH_BRICK:1,null,12,SMOOTH_BRICK:0,null,80,COBBLESTONE:0,null,100)
Block(2,7,1,SMOOTH_BRICK:2)
RandomBlock(2,7,2,MONSTER_EGGS:4,null,6,MONSTER_EGGS:2,null,18,MONSTER_EGGS:3,null,6,SMOOTH_BRICK:2,null,12,SMOOTH_BRICK:1,null,12,SMOOTH_BRICK:0,null,80,COBBLESTONE:0,null,100)
RandomBlock(2,7,3,MONSTER_EGGS:4,null,6,MONSTER_EGGS:2,null,18,MONSTER_EGGS:3,null,6,SMOOTH_BRICK:2,null,12,SMOOTH_BRICK:1,null,12,SMOOTH_BRICK:0,null,80,COBBLESTONE:0,null,100)
Block(2,7,4,SMOOTH_BRICK:2)
Block(2,7,5,SMOOTH_BRICK:2)
RandomBlock(2,7,6,MONSTER_EGGS:4,null,6,MONSTER_EGGS:2,null,18,MONSTER_EGGS:3,null,6,SMOOTH_BRICK:2,null,12,SMOOTH_BRICK:1,null,12,SMOOTH_BRICK:0,null,80,COBBLESTONE:0,null,100)
Block(2,10,-3,VINE:2)
Block(2,10,3,VINE:2)
Block(2,11,-3,VINE:2)
Block(2,11,3,VINE:2)
Block(3,0,-7,DIRT:0)
Block(3,0,-6,DIRT:0)
Block(3,0,-5,DIRT:0)
Block(3,0,-4,DIRT:0)
Block(3,0,-3,DIRT:0)
Block(3,0,-2,DIRT:0)
Block(3,0,-1,DIRT:0)
Block(3,0,0,DIRT:0)
Block(3,0,1,DIRT:0)
Block(3,0,2,DIRT:0)
Block(3,0,3,DIRT:0)
Block(3,0,4,DIRT:0)
Block(3,0,5,DIRT:0)
Block(3,0,6,DIRT:0)
Block(3,1,-7,DIRT:0)
Block(3,1,-6,DIRT:0)
Block(3,1,-5,DIRT:0)
Block(3,1,-4,DIRT:0)
Block(3,1,-3,DIRT:0)
Block(3,1,-2,DIRT:0)
Block(3,1,-1,DIRT:0)
Block(3,1,0,DIRT:0)
Block(3,1,1,DIRT:0)
Block(3,1,2,DIRT:0)
Block(3,1,3,DIRT:0)
Block(3,1,4,DIRT:0)
Block(3,1,5,DIRT:0)
Block(3,1,6,DIRT:0)
Block(3,2,-7,DIRT:0)
Block(3,2,-6,DIRT:0)
Block(3,2,-5,DIRT:0)
Block(3,2,-4,DIRT:0)
Block(3,2,-3,DIRT:0)
Block(3,2,-2,DIRT:0)
Block(3,2,-1,DIRT:0)
Block(3,2,0,DIRT:0)
Block(3,2,1,DIRT:0)
Block(3,2,2,DIRT:0)
Block(3,2,3,DIRT:0)
Block(3,2,4,DIRT:0)
Block(3,2,5,DIRT:0)
Block(3,2,6,DIRT:0)
Block(3,3,-7,DIRT:0)
Block(3,3,-6,DIRT:0)
RandomBlock(3,3,-5,MONSTER_EGGS:4,null,6,MONSTER_EGGS:2,null,18,MONSTER_EGGS:3,null,6,SMOOTH_BRICK:2,null,12,SMOOTH_BRICK:1,null,12,SMOOTH_BRICK:0,null,80,COBBLESTONE:0,null,100)
RandomBlock(3,3,-4,MONSTER_EGGS:4,null,6,MONSTER_EGGS:2,null,18,MONSTER_EGGS:3,null,6,SMOOTH_BRICK:2,null,12,SMOOTH_BRICK:1,null,12,SMOOTH_BRICK:0,null,80,COBBLESTONE:0,null,100)
RandomBlock(3,3,-3,MONSTER_EGGS:4,null,6,MONSTER_EGGS:2,null,18,MONSTER_EGGS:3,null,6,SMOOTH_BRICK:2,null,12,SMOOTH_BRICK:1,null,12,SMOOTH_BRICK:0,null,80,COBBLESTONE:0,null,100)
Block(3,3,-2,SMOOTH_BRICK:2)
RandomBlock(3,3,-1,MONSTER_EGGS:4,null,6,MONSTER_EGGS:2,null,18,MONSTER_EGGS:3,null,6,SMOOTH_BRICK:2,null,12,SMOOTH_BRICK:1,null,12,SMOOTH_BRICK:0,null,80,COBBLESTONE:0,null,100)
RandomBlock(3,3,0,MONSTER_EGGS:4,null,6,MONSTER_EGGS:2,null,18,MONSTER_EGGS:3,null,6,SMOOTH_BRICK:2,null,12,SMOOTH_BRICK:1,null,12,SMOOTH_BRICK:0,null,80,COBBLESTONE:0,null,100)
RandomBlock(3,3,1,MONSTER_EGGS:4,null,6,MONSTER_EGGS:2,null,18,MONSTER_EGGS:3,null,6,SMOOTH_BRICK:2,null,12,SMOOTH_BRICK:1,null,12,SMOOTH_BRICK:0,null,80,COBBLESTONE:0,null,100)
RandomBlock(3,3,2,MONSTER_EGGS:4,null,6,MONSTER_EGGS:2,null,18,MONSTER_EGGS:3,null,6,SMOOTH_BRICK:2,null,12,SMOOTH_BRICK:1,null,12,SMOOTH_BRICK:0,null,80,COBBLESTONE:0,null,100)
RandomBlock(3,3,3,MONSTER_EGGS:4,null,6,MONSTER_EGGS:2,null,18,MONSTER_EGGS:3,null,6,SMOOTH_BRICK:2,null,12,SMOOTH_BRICK:1,null,12,SMOOTH_BRICK:0,null,80,COBBLESTONE:0,null,100)
RandomBlock(3,3,4,MONSTER_EGGS:4,null,6,MONSTER_EGGS:2,null,18,MONSTER_EGGS:3,null,6,SMOOTH_BRICK:2,null,12,SMOOTH_BRICK:1,null,12,SMOOTH_BRICK:0,null,80,COBBLESTONE:0,null,100)
Block(3,3,5,DIRT:0)
Block(3,3,6,DIRT:0)
Block(3,4,-7,STONE:0)
RandomBlock(3,4,-6,MONSTER_EGGS:4,null,6,MONSTER_EGGS:2,null,18,MONSTER_EGGS:3,null,6,SMOOTH_BRICK:2,null,12,SMOOTH_BRICK:1,null,12,SMOOTH_BRICK:0,null,80,COBBLESTONE:0,null,100)
Block(3,4,-5,AIR:0)
Block(3,4,-4,AIR:0)
Block(3,4,-3,AIR:0)
Block(3,4,-2,AIR:0)
Block(3,4,-1,AIR:0)
Block(3,4,0,AIR:0)
Block(3,4,1,AIR:0)
Block(3,4,2,AIR:0)
Block(3,4,3,AIR:0)
Block(3,4,4,AIR:0)
RandomBlock(3,4,5,MONSTER_EGGS:4,null,6,MONSTER_EGGS:2,null,18,MONSTER_EGGS:3,null,6,SMOOTH_BRICK:2,null,12,SMOOTH_BRICK:1,null,12,SMOOTH_BRICK:0,null,80,COBBLESTONE:0,null,100)
RandomBlock(3,4,6,MONSTER_EGGS:4,null,6,MONSTER_EGGS:2,null,18,MONSTER_EGGS:3,null,6,SMOOTH_BRICK:2,null,12,SMOOTH_BRICK:1,null,12,SMOOTH_BRICK:0,null,80,COBBLESTONE:0,null,100)
Block(3,5,-7,STONE:0)
RandomBlock(3,5,-6,MONSTER_EGGS:4,null,6,MONSTER_EGGS:2,null,18,MONSTER_EGGS:3,null,6,SMOOTH_BRICK:2,null,12,SMOOTH_BRICK:1,null,12,SMOOTH_BRICK:0,null,80,COBBLESTONE:0,null,100)
Block(3,5,-5,AIR:0)
Block(3,5,-4,AIR:0)
Block(3,5,-3,AIR:0)
Block(3,5,-2,AIR:0)
Block(3,5,-1,AIR:0)
Block(3,5,0,AIR:0)
Block(3,5,1,AIR:0)
Block(3,5,2,AIR:0)
Block(3,5,3,AIR:0)
Block(3,5,4,AIR:0)
RandomBlock(3,5,5,MONSTER_EGGS:4,null,6,MONSTER_EGGS:2,null,18,MONSTER_EGGS:3,null,6,SMOOTH_BRICK:2,null,12,SMOOTH_BRICK:1,null,12,SMOOTH_BRICK:0,null,80,COBBLESTONE:0,null,100)
RandomBlock(3,5,6,MONSTER_EGGS:4,null,6,MONSTER_EGGS:2,null,18,MONSTER_EGGS:3,null,6,SMOOTH_BRICK:2,null,12,SMOOTH_BRICK:1,null,12,SMOOTH_BRICK:0,null,80,COBBLESTONE:0,null,100)
Block(3,6,-7,STONE:0)
RandomBlock(3,6,-6,MONSTER_EGGS:4,null,6,MONSTER_EGGS:2,null,18,MONSTER_EGGS:3,null,6,SMOOTH_BRICK:2,null,12,SMOOTH_BRICK:1,null,12,SMOOTH_BRICK:0,null,80,COBBLESTONE:0,null,100)
Block(3,6,-5,AIR:0)
Block(3,6,-4,AIR:0)
Block(3,6,-3,AIR:0)
Block(3,6,-2,AIR:0)
Block(3,6,-1,AIR:0)
Block(3,6,0,AIR:0)
Block(3,6,1,AIR:0)
Block(3,6,2,AIR:0)
Block(3,6,3,AIR:0)
Block(3,6,4,AIR:0)
RandomBlock(3,6,5,MONSTER_EGGS:4,null,6,MONSTER_EGGS:2,null,18,MONSTER_EGGS:3,null,6,SMOOTH_BRICK:2,null,12,SMOOTH_BRICK:1,null,12,SMOOTH_BRICK:0,null,80,COBBLESTONE:0,null,100)
RandomBlock(3,6,6,MONSTER_EGGS:4,null,6,MONSTER_EGGS:2,null,18,MONSTER_EGGS:3,null,6,SMOOTH_BRICK:2,null,12,SMOOTH_BRICK:1,null,12,SMOOTH_BRICK:0,null,80,COBBLESTONE:0,null,100)
RandomBlock(3,7,-7,MONSTER_EGGS:4,null,6,MONSTER_EGGS:2,null,18,MONSTER_EGGS:3,null,6,SMOOTH_BRICK:2,null,12,SMOOTH_BRICK:1,null,12,SMOOTH_BRICK:0,null,80,COBBLESTONE:0,null,100)
RandomBlock(3,7,-6,MONSTER_EGGS:4,null,6,MONSTER_EGGS:2,null,18,MONSTER_EGGS:3,null,6,SMOOTH_BRICK:2,null,12,SMOOTH_BRICK:1,null,12,SMOOTH_BRICK:0,null,80,COBBLESTONE:0,null,100)
RandomBlock(3,7,-5,MONSTER_EGGS:4,null,6,MONSTER_EGGS:2,null,18,MONSTER_EGGS:3,null,6,SMOOTH_BRICK:2,null,12,SMOOTH_BRICK:1,null,12,SMOOTH_BRICK:0,null,80,COBBLESTONE:0,null,100)
RandomBlock(3,7,-4,MONSTER_EGGS:4,null,6,MONSTER_EGGS:2,null,18,MONSTER_EGGS:3,null,6,SMOOTH_BRICK:2,null,12,SMOOTH_BRICK:1,null,12,SMOOTH_BRICK:0,null,80,COBBLESTONE:0,null,100)
RandomBlock(3,7,-3,MONSTER_EGGS:4,null,6,MONSTER_EGGS:2,null,18,MONSTER_EGGS:3,null,6,SMOOTH_BRICK:2,null,12,SMOOTH_BRICK:1,null,12,SMOOTH_BRICK:0,null,80,COBBLESTONE:0,null,100)
RandomBlock(3,7,-2,MONSTER_EGGS:4,null,6,MONSTER_EGGS:2,null,18,MONSTER_EGGS:3,null,6,SMOOTH_BRICK:2,null,12,SMOOTH_BRICK:1,null,12,SMOOTH_BRICK:0,null,80,COBBLESTONE:0,null,100)
RandomBlock(3,7,-1,MONSTER_EGGS:4,null,6,MONSTER_EGGS:2,null,18,MONSTER_EGGS:3,null,6,SMOOTH_BRICK:2,null,12,SMOOTH_BRICK:1,null,12,SMOOTH_BRICK:0,null,80,COBBLESTONE:0,null,100)
RandomBlock(3,7,0,MONSTER_EGGS:4,null,6,MONSTER_EGGS:2,null,18,MONSTER_EGGS:3,null,6,SMOOTH_BRICK:2,null,12,SMOOTH_BRICK:1,null,12,SMOOTH_BRICK:0,null,80,COBBLESTONE:0,null,100)
RandomBlock(3,7,1,MONSTER_EGGS:4,null,6,MONSTER_EGGS:2,null,18,MONSTER_EGGS:3,null,6,SMOOTH_BRICK:2,null,12,SMOOTH_BRICK:1,null,12,SMOOTH_BRICK:0,null,80,COBBLESTONE:0,null,100)
RandomBlock(3,7,2,MONSTER_EGGS:4,null,6,MONSTER_EGGS:2,null,18,MONSTER_EGGS:3,null,6,SMOOTH_BRICK:2,null,12,SMOOTH_BRICK:1,null,12,SMOOTH_BRICK:0,null,80,COBBLESTONE:0,null,100)
RandomBlock(3,7,3,MONSTER_EGGS:4,null,6,MONSTER_EGGS:2,null,18,MONSTER_EGGS:3,null,6,SMOOTH_BRICK:2,null,12,SMOOTH_BRICK:1,null,12,SMOOTH_BRICK:0,null,80,COBBLESTONE:0,null,100)
RandomBlock(3,7,4,MONSTER_EGGS:4,null,6,MONSTER_EGGS:2,null,18,MONSTER_EGGS:3,null,6,SMOOTH_BRICK:2,null,12,SMOOTH_BRICK:1,null,12,SMOOTH_BRICK:0,null,80,COBBLESTONE:0,null,100)
RandomBlock(3,7,5,MONSTER_EGGS:4,null,6,MONSTER_EGGS:2,null,18,MONSTER_EGGS:3,null,6,SMOOTH_BRICK:2,null,12,SMOOTH_BRICK:1,null,12,SMOOTH_BRICK:0,null,80,COBBLESTONE:0,null,100)
RandomBlock(3,7,6,MONSTER_EGGS:4,null,6,MONSTER_EGGS:2,null,18,MONSTER_EGGS:3,null,6,SMOOTH_BRICK:2,null,12,SMOOTH_BRICK:1,null,12,SMOOTH_BRICK:0,null,80,COBBLESTONE:0,null,100)
Block(4,0,-7,DIRT:0)
Block(4,0,-6,DIRT:0)
Block(4,0,-5,DIRT:0)
Block(4,0,-4,DIRT:0)
Block(4,0,-3,DIRT:0)
Block(4,0,-2,DIRT:0)
Block(4,0,-1,DIRT:0)
Block(4,0,0,DIRT:0)
Block(4,0,1,DIRT:0)
Block(4,0,2,DIRT:0)
Block(4,0,3,DIRT:0)
Block(4,0,4,DIRT:0)
Block(4,0,5,DIRT:0)
Block(4,0,6,DIRT:0)
Block(4,1,-7,DIRT:0)
Block(4,1,-6,DIRT:0)
Block(4,1,-5,DIRT:0)
RandomBlock(4,1,-4,MONSTER_EGGS:4,null,6,MONSTER_EGGS:2,null,18,MONSTER_EGGS:3,null,6,SMOOTH_BRICK:2,null,12,SMOOTH_BRICK:1,null,12,SMOOTH_BRICK:0,null,80,COBBLESTONE:0,null,100)
Block(4,1,-3,DIRT:0)
Block(4,1,-2,DIRT:0)
Block(4,1,-1,DIRT:0)
Block(4,1,0,DIRT:0)
Block(4,1,1,DIRT:0)
Block(4,1,2,DIRT:0)
RandomBlock(4,1,3,MONSTER_EGGS:4,null,6,MONSTER_EGGS:2,null,18,MONSTER_EGGS:3,null,6,SMOOTH_BRICK:2,null,12,SMOOTH_BRICK:1,null,12,SMOOTH_BRICK:0,null,80,COBBLESTONE:0,null,100)
Block(4,1,4,DIRT:0)
Block(4,1,5,DIRT:0)
Block(4,1,6,DIRT:0)
Block(4,2,-7,DIRT:0)
Block(4,2,-6,DIRT:0)
Block(4,2,-5,DIRT:0)
RandomBlock(4,2,-4,MONSTER_EGGS:4,null,6,MONSTER_EGGS:2,null,18,MONSTER_EGGS:3,null,6,SMOOTH_BRICK:2,null,12,SMOOTH_BRICK:1,null,12,SMOOTH_BRICK:0,null,80,COBBLESTONE:0,null,100)
Block(4,2,-3,DIRT:0)
Block(4,2,-2,DIRT:0)
Block(4,2,-1,DIRT:0)
Block(4,2,0,DIRT:0)
Block(4,2,1,DIRT:0)
Block(4,2,2,DIRT:0)
RandomBlock(4,2,3,MONSTER_EGGS:4,null,6,MONSTER_EGGS:2,null,18,MONSTER_EGGS:3,null,6,SMOOTH_BRICK:2,null,12,SMOOTH_BRICK:1,null,12,SMOOTH_BRICK:0,null,80,COBBLESTONE:0,null,100)
Block(4,2,4,DIRT:0)
Block(4,2,5,DIRT:0)
Block(4,2,6,DIRT:0)
Block(4,3,-7,DIRT:0)
Block(4,3,-6,SMOOTH_BRICK:2)
Block(4,3,-5,SMOOTH_BRICK:2)
Block(4,3,-4,SMOOTH_BRICK:2)
RandomBlock(4,3,-3,MONSTER_EGGS:4,null,6,MONSTER_EGGS:2,null,18,MONSTER_EGGS:3,null,6,SMOOTH_BRICK:2,null,12,SMOOTH_BRICK:1,null,12,SMOOTH_BRICK:0,null,80,COBBLESTONE:0,null,100)
Block(4,3,-2,SMOOTH_BRICK:2)
RandomBlock(4,3,-1,MONSTER_EGGS:4,null,6,MONSTER_EGGS:2,null,18,MONSTER_EGGS:3,null,6,SMOOTH_BRICK:2,null,12,SMOOTH_BRICK:1,null,12,SMOOTH_BRICK:0,null,80,COBBLESTONE:0,null,100)
RandomBlock(4,3,0,MONSTER_EGGS:4,null,6,MONSTER_EGGS:2,null,18,MONSTER_EGGS:3,null,6,SMOOTH_BRICK:2,null,12,SMOOTH_BRICK:1,null,12,SMOOTH_BRICK:0,null,80,COBBLESTONE:0,null,100)
RandomBlock(4,3,1,MONSTER_EGGS:4,null,6,MONSTER_EGGS:2,null,18,MONSTER_EGGS:3,null,6,SMOOTH_BRICK:2,null,12,SMOOTH_BRICK:1,null,12,SMOOTH_BRICK:0,null,80,COBBLESTONE:0,null,100)
Block(4,3,2,SMOOTH_BRICK:2)
RandomBlock(4,3,3,MONSTER_EGGS:4,null,6,MONSTER_EGGS:2,null,18,MONSTER_EGGS:3,null,6,SMOOTH_BRICK:2,null,12,SMOOTH_BRICK:1,null,12,SMOOTH_BRICK:0,null,80,COBBLESTONE:0,null,100)
RandomBlock(4,3,4,MONSTER_EGGS:4,null,6,MONSTER_EGGS:2,null,18,MONSTER_EGGS:3,null,6,SMOOTH_BRICK:2,null,12,SMOOTH_BRICK:1,null,12,SMOOTH_BRICK:0,null,80,COBBLESTONE:0,null,100)
RandomBlock(4,3,5,MONSTER_EGGS:4,null,6,MONSTER_EGGS:2,null,18,MONSTER_EGGS:3,null,6,SMOOTH_BRICK:2,null,12,SMOOTH_BRICK:1,null,12,SMOOTH_BRICK:0,null,80,COBBLESTONE:0,null,100)
Block(4,3,6,DIRT:0)
RandomBlock(4,4,-7,MONSTER_EGGS:4,null,6,MONSTER_EGGS:2,null,18,MONSTER_EGGS:3,null,6,SMOOTH_BRICK:2,null,12,SMOOTH_BRICK:1,null,12,SMOOTH_BRICK:0,null,80,COBBLESTONE:0,null,100)
Block(4,4,-6,AIR:0)
Block(4,4,-5,AIR:0)
Block(4,4,-4,AIR:0)
RandomBlock(4,4,-3,MONSTER_EGGS:4,null,6,MONSTER_EGGS:2,null,18,MONSTER_EGGS:3,null,6,SMOOTH_BRICK:2,null,12,SMOOTH_BRICK:1,null,12,SMOOTH_BRICK:0,null,80,COBBLESTONE:0,null,100)
Block(4,4,-2,AIR:0)
Block(4,4,-1,AIR:0)
Block(4,4,0,AIR:0)
Block(4,4,1,AIR:0)
RandomBlock(4,4,2,MONSTER_EGGS:4,null,6,MONSTER_EGGS:2,null,18,MONSTER_EGGS:3,null,6,SMOOTH_BRICK:2,null,12,SMOOTH_BRICK:1,null,12,SMOOTH_BRICK:0,null,80,COBBLESTONE:0,null,100)
Block(4,4,3,AIR:0)
Block(4,4,4,AIR:0)
Block(4,4,5,AIR:0)
RandomBlock(4,4,6,MONSTER_EGGS:4,null,6,MONSTER_EGGS:2,null,18,MONSTER_EGGS:3,null,6,SMOOTH_BRICK:2,null,12,SMOOTH_BRICK:1,null,12,SMOOTH_BRICK:0,null,80,COBBLESTONE:0,null,100)
RandomBlock(4,5,-7,MONSTER_EGGS:4,null,6,MONSTER_EGGS:2,null,18,MONSTER_EGGS:3,null,6,SMOOTH_BRICK:2,null,12,SMOOTH_BRICK:1,null,12,SMOOTH_BRICK:0,null,80,COBBLESTONE:0,null,100)
Block(4,5,-6,AIR:0)
Block(4,5,-5,AIR:0)
Block(4,5,-4,AIR:0)
Block(4,5,-3,AIR:0)
Block(4,5,-2,AIR:0)
Block(4,5,-1,AIR:0)
Block(4,5,0,AIR:0)
Block(4,5,1,AIR:0)
Block(4,5,2,AIR:0)
Block(4,5,3,AIR:0)
Block(4,5,4,AIR:0)
Block(4,5,5,AIR:0)
RandomBlock(4,5,6,MONSTER_EGGS:4,null,6,MONSTER_EGGS:2,null,18,MONSTER_EGGS:3,null,6,SMOOTH_BRICK:2,null,12,SMOOTH_BRICK:1,null,12,SMOOTH_BRICK:0,null,80,COBBLESTONE:0,null,100)
RandomBlock(4,6,-7,MONSTER_EGGS:4,null,6,MONSTER_EGGS:2,null,18,MONSTER_EGGS:3,null,6,SMOOTH_BRICK:2,null,12,SMOOTH_BRICK:1,null,12,SMOOTH_BRICK:0,null,80,COBBLESTONE:0,null,100)
Block(4,6,-6,AIR:0)
Block(4,6,-5,AIR:0)
Block(4,6,-4,AIR:0)
Block(4,6,-3,AIR:0)
Block(4,6,-2,AIR:0)
Block(4,6,-1,AIR:0)
Block(4,6,0,AIR:0)
Block(4,6,1,AIR:0)
Block(4,6,2,AIR:0)
Block(4,6,3,AIR:0)
Block(4,6,4,AIR:0)
Block(4,6,5,AIR:0)
RandomBlock(4,6,6,MONSTER_EGGS:4,null,6,MONSTER_EGGS:2,null,18,MONSTER_EGGS:3,null,6,SMOOTH_BRICK:2,null,12,SMOOTH_BRICK:1,null,12,SMOOTH_BRICK:0,null,80,COBBLESTONE:0,null,100)
RandomBlock(4,7,-7,MONSTER_EGGS:4,null,6,MONSTER_EGGS:2,null,18,MONSTER_EGGS:3,null,6,SMOOTH_BRICK:2,null,12,SMOOTH_BRICK:1,null,12,SMOOTH_BRICK:0,null,80,COBBLESTONE:0,null,100)
RandomBlock(4,7,-6,MONSTER_EGGS:4,null,6,MONSTER_EGGS:2,null,18,MONSTER_EGGS:3,null,6,SMOOTH_BRICK:2,null,12,SMOOTH_BRICK:1,null,12,SMOOTH_BRICK:0,null,80,COBBLESTONE:0,null,100)
RandomBlock(4,7,-5,MONSTER_EGGS:4,null,6,MONSTER_EGGS:2,null,18,MONSTER_EGGS:3,null,6,SMOOTH_BRICK:2,null,12,SMOOTH_BRICK:1,null,12,SMOOTH_BRICK:0,null,80,COBBLESTONE:0,null,100)
RandomBlock(4,7,-4,MONSTER_EGGS:4,null,6,MONSTER_EGGS:2,null,18,MONSTER_EGGS:3,null,6,SMOOTH_BRICK:2,null,12,SMOOTH_BRICK:1,null,12,SMOOTH_BRICK:0,null,80,COBBLESTONE:0,null,100)
RandomBlock(4,7,-3,MONSTER_EGGS:4,null,6,MONSTER_EGGS:2,null,18,MONSTER_EGGS:3,null,6,SMOOTH_BRICK:2,null,12,SMOOTH_BRICK:1,null,12,SMOOTH_BRICK:0,null,80,COBBLESTONE:0,null,100)
RandomBlock(4,7,-2,MONSTER_EGGS:4,null,6,MONSTER_EGGS:2,null,18,MONSTER_EGGS:3,null,6,SMOOTH_BRICK:2,null,12,SMOOTH_BRICK:1,null,12,SMOOTH_BRICK:0,null,80,COBBLESTONE:0,null,100)
RandomBlock(4,7,-1,MONSTER_EGGS:4,null,6,MONSTER_EGGS:2,null,18,MONSTER_EGGS:3,null,6,SMOOTH_BRICK:2,null,12,SMOOTH_BRICK:1,null,12,SMOOTH_BRICK:0,null,80,COBBLESTONE:0,null,100)
RandomBlock(4,7,0,MONSTER_EGGS:4,null,6,MONSTER_EGGS:2,null,18,MONSTER_EGGS:3,null,6,SMOOTH_BRICK:2,null,12,SMOOTH_BRICK:1,null,12,SMOOTH_BRICK:0,null,80,COBBLESTONE:0,null,100)
RandomBlock(4,7,1,MONSTER_EGGS:4,null,6,MONSTER_EGGS:2,null,18,MONSTER_EGGS:3,null,6,SMOOTH_BRICK:2,null,12,SMOOTH_BRICK:1,null,12,SMOOTH_BRICK:0,null,80,COBBLESTONE:0,null,100)
RandomBlock(4,7,2,MONSTER_EGGS:4,null,6,MONSTER_EGGS:2,null,18,MONSTER_EGGS:3,null,6,SMOOTH_BRICK:2,null,12,SMOOTH_BRICK:1,null,12,SMOOTH_BRICK:0,null,80,COBBLESTONE:0,null,100)
RandomBlock(4,7,3,MONSTER_EGGS:4,null,6,MONSTER_EGGS:2,null,18,MONSTER_EGGS:3,null,6,SMOOTH_BRICK:2,null,12,SMOOTH_BRICK:1,null,12,SMOOTH_BRICK:0,null,80,COBBLESTONE:0,null,100)
RandomBlock(4,7,4,MONSTER_EGGS:4,null,6,MONSTER_EGGS:2,null,18,MONSTER_EGGS:3,null,6,SMOOTH_BRICK:2,null,12,SMOOTH_BRICK:1,null,12,SMOOTH_BRICK:0,null,80,COBBLESTONE:0,null,100)
RandomBlock(4,7,5,MONSTER_EGGS:4,null,6,MONSTER_EGGS:2,null,18,MONSTER_EGGS:3,null,6,SMOOTH_BRICK:2,null,12,SMOOTH_BRICK:1,null,12,SMOOTH_BRICK:0,null,80,COBBLESTONE:0,null,100)
RandomBlock(4,7,6,MONSTER_EGGS:4,null,6,MONSTER_EGGS:2,null,18,MONSTER_EGGS:3,null,6,SMOOTH_BRICK:2,null,12,SMOOTH_BRICK:1,null,12,SMOOTH_BRICK:0,null,80,COBBLESTONE:0,null,100)
Block(5,0,-7,DIRT:0)
Block(5,0,-6,DIRT:0)
Block(5,0,-5,DIRT:0)
Block(5,0,-4,STATIONARY_LAVA:0)
Block(5,0,-3,DIRT:0)
Block(5,0,-2,DIRT:0)
Block(5,0,-1,DIRT:0)
Block(5,0,0,DIRT:0)
Block(5,0,1,DIRT:0)
Block(5,0,2,DIRT:0)
Block(5,0,3,STATIONARY_LAVA:0)
Block(5,0,4,DIRT:0)
Block(5,0,5,DIRT:0)
Block(5,0,6,DIRT:0)
Block(5,1,-7,DIRT:0)
Block(5,1,-6,DIRT:0)
RandomBlock(5,1,-5,MONSTER_EGGS:4,null,6,MONSTER_EGGS:2,null,18,MONSTER_EGGS:3,null,6,SMOOTH_BRICK:2,null,12,SMOOTH_BRICK:1,null,12,SMOOTH_BRICK:0,null,80,COBBLESTONE:0,null,100)
Block(5,1,-4,AIR:0)
RandomBlock(5,1,-3,MONSTER_EGGS:4,null,6,MONSTER_EGGS:2,null,18,MONSTER_EGGS:3,null,6,SMOOTH_BRICK:2,null,12,SMOOTH_BRICK:1,null,12,SMOOTH_BRICK:0,null,80,COBBLESTONE:0,null,100)
Block(5,1,-2,DIRT:0)
Block(5,1,-1,DIRT:0)
Block(5,1,0,DIRT:0)
Block(5,1,1,DIRT:0)
RandomBlock(5,1,2,MONSTER_EGGS:4,null,6,MONSTER_EGGS:2,null,18,MONSTER_EGGS:3,null,6,SMOOTH_BRICK:2,null,12,SMOOTH_BRICK:1,null,12,SMOOTH_BRICK:0,null,80,COBBLESTONE:0,null,100)
Block(5,1,3,AIR:0)
RandomBlock(5,1,4,MONSTER_EGGS:4,null,6,MONSTER_EGGS:2,null,18,MONSTER_EGGS:3,null,6,SMOOTH_BRICK:2,null,12,SMOOTH_BRICK:1,null,12,SMOOTH_BRICK:0,null,80,COBBLESTONE:0,null,100)
Block(5,1,5,DIRT:0)
Block(5,1,6,DIRT:0)
Block(5,2,-7,DIRT:0)
Block(5,2,-6,DIRT:0)
RandomBlock(5,2,-5,MONSTER_EGGS:4,null,6,MONSTER_EGGS:2,null,18,MONSTER_EGGS:3,null,6,SMOOTH_BRICK:2,null,12,SMOOTH_BRICK:1,null,12,SMOOTH_BRICK:0,null,80,COBBLESTONE:0,null,100)
Block(5,2,-4,AIR:0)
RandomBlock(5,2,-3,MONSTER_EGGS:4,null,6,MONSTER_EGGS:2,null,18,MONSTER_EGGS:3,null,6,SMOOTH_BRICK:2,null,12,SMOOTH_BRICK:1,null,12,SMOOTH_BRICK:0,null,80,COBBLESTONE:0,null,100)
Block(5,2,-2,DIRT:0)
Block(5,2,-1,DIRT:0)
Block(5,2,0,DIRT:0)
Block(5,2,1,DIRT:0)
RandomBlock(5,2,2,MONSTER_EGGS:4,null,6,MONSTER_EGGS:2,null,18,MONSTER_EGGS:3,null,6,SMOOTH_BRICK:2,null,12,SMOOTH_BRICK:1,null,12,SMOOTH_BRICK:0,null,80,COBBLESTONE:0,null,100)
Block(5,2,3,AIR:0)
RandomBlock(5,2,4,MONSTER_EGGS:4,null,6,MONSTER_EGGS:2,null,18,MONSTER_EGGS:3,null,6,SMOOTH_BRICK:2,null,12,SMOOTH_BRICK:1,null,12,SMOOTH_BRICK:0,null,80,COBBLESTONE:0,null,100)
Block(5,2,5,DIRT:0)
Block(5,2,6,DIRT:0)
Block(5,3,-7,DIRT:0)
Block(5,3,-6,SMOOTH_BRICK:2)
Block(5,3,-5,SMOOTH_BRICK:2)
Block(5,3,-4,GLASS:0)
Block(5,3,-3,MOB_SPAWNER:0,../../ruins_spawners/creeper.nbt)
Block(5,3,-2,SMOOTH_BRICK:2)
RandomBlock(5,3,-1,MONSTER_EGGS:4,null,6,MONSTER_EGGS:2,null,18,MONSTER_EGGS:3,null,6,SMOOTH_BRICK:2,null,12,SMOOTH_BRICK:1,null,12,SMOOTH_BRICK:0,null,80,COBBLESTONE:0,null,100)
RandomBlock(5,3,0,MONSTER_EGGS:4,null,6,MONSTER_EGGS:2,null,18,MONSTER_EGGS:3,null,6,SMOOTH_BRICK:2,null,12,SMOOTH_BRICK:1,null,12,SMOOTH_BRICK:0,null,80,COBBLESTONE:0,null,100)
Block(5,3,1,SMOOTH_BRICK:2)
Block(5,3,2,MOB_SPAWNER:0,../../ruins_spawners/creeper.nbt)
Block(5,3,3,GLASS:0)
Block(5,3,4,SMOOTH_BRICK:2)
RandomBlock(5,3,5,MONSTER_EGGS:4,null,6,MONSTER_EGGS:2,null,18,MONSTER_EGGS:3,null,6,SMOOTH_BRICK:2,null,12,SMOOTH_BRICK:1,null,12,SMOOTH_BRICK:0,null,80,COBBLESTONE:0,null,100)
Block(5,3,6,DIRT:0)
RandomBlock(5,4,-7,MONSTER_EGGS:4,null,6,MONSTER_EGGS:2,null,18,MONSTER_EGGS:3,null,6,SMOOTH_BRICK:2,null,12,SMOOTH_BRICK:1,null,12,SMOOTH_BRICK:0,null,80,COBBLESTONE:0,null,100)
Block(5,4,-6,AIR:0)
Block(5,4,-5,AIR:0)
Block(5,4,-4,AIR:0)
RandomBlock(5,4,-3,MONSTER_EGGS:4,null,6,MONSTER_EGGS:2,null,18,MONSTER_EGGS:3,null,6,SMOOTH_BRICK:2,null,12,SMOOTH_BRICK:1,null,12,SMOOTH_BRICK:0,null,80,COBBLESTONE:0,null,100)
Block(5,4,-2,AIR:0)
Block(5,4,-1,AIR:0)
Block(5,4,0,AIR:0)
Block(5,4,1,AIR:0)
RandomBlock(5,4,2,MONSTER_EGGS:4,null,6,MONSTER_EGGS:2,null,18,MONSTER_EGGS:3,null,6,SMOOTH_BRICK:2,null,12,SMOOTH_BRICK:1,null,12,SMOOTH_BRICK:0,null,80,COBBLESTONE:0,null,100)
Block(5,4,3,AIR:0)
Block(5,4,4,AIR:0)
Block(5,4,5,AIR:0)
RandomBlock(5,4,6,MONSTER_EGGS:4,null,6,MONSTER_EGGS:2,null,18,MONSTER_EGGS:3,null,6,SMOOTH_BRICK:2,null,12,SMOOTH_BRICK:1,null,12,SMOOTH_BRICK:0,null,80,COBBLESTONE:0,null,100)
RandomBlock(5,5,-7,MONSTER_EGGS:4,null,6,MONSTER_EGGS:2,null,18,MONSTER_EGGS:3,null,6,SMOOTH_BRICK:2,null,12,SMOOTH_BRICK:1,null,12,SMOOTH_BRICK:0,null,80,COBBLESTONE:0,null,100)
Block(5,5,-6,AIR:0)
Block(5,5,-5,AIR:0)
Block(5,5,-4,AIR:0)
Block(5,5,-3,AIR:0)
Block(5,5,-2,AIR:0)
Block(5,5,-1,AIR:0)
Block(5,5,0,AIR:0)
Block(5,5,1,AIR:0)
Block(5,5,2,AIR:0)
Block(5,5,3,AIR:0)
Block(5,5,4,AIR:0)
Block(5,5,5,AIR:0)
RandomBlock(5,5,6,MONSTER_EGGS:4,null,6,MONSTER_EGGS:2,null,18,MONSTER_EGGS:3,null,6,SMOOTH_BRICK:2,null,12,SMOOTH_BRICK:1,null,12,SMOOTH_BRICK:0,null,80,COBBLESTONE:0,null,100)
RandomBlock(5,6,-7,MONSTER_EGGS:4,null,6,MONSTER_EGGS:2,null,18,MONSTER_EGGS:3,null,6,SMOOTH_BRICK:2,null,12,SMOOTH_BRICK:1,null,12,SMOOTH_BRICK:0,null,80,COBBLESTONE:0,null,100)
Block(5,6,-6,AIR:0)
Block(5,6,-5,AIR:0)
Block(5,6,-4,AIR:0)
Block(5,6,-3,AIR:0)
Block(5,6,-2,AIR:0)
Block(5,6,-1,AIR:0)
Block(5,6,0,AIR:0)
Block(5,6,1,AIR:0)
Block(5,6,2,AIR:0)
Block(5,6,3,AIR:0)
Block(5,6,4,AIR:0)
Block(5,6,5,AIR:0)
RandomBlock(5,6,6,MONSTER_EGGS:4,null,6,MONSTER_EGGS:2,null,18,MONSTER_EGGS:3,null,6,SMOOTH_BRICK:2,null,12,SMOOTH_BRICK:1,null,12,SMOOTH_BRICK:0,null,80,COBBLESTONE:0,null,100)
RandomBlock(5,7,-7,MONSTER_EGGS:4,null,6,MONSTER_EGGS:2,null,18,MONSTER_EGGS:3,null,6,SMOOTH_BRICK:2,null,12,SMOOTH_BRICK:1,null,12,SMOOTH_BRICK:0,null,80,COBBLESTONE:0,null,100)
RandomBlock(5,7,-6,MONSTER_EGGS:4,null,6,MONSTER_EGGS:2,null,18,MONSTER_EGGS:3,null,6,SMOOTH_BRICK:2,null,12,SMOOTH_BRICK:1,null,12,SMOOTH_BRICK:0,null,80,COBBLESTONE:0,null,100)
RandomBlock(5,7,-5,MONSTER_EGGS:4,null,6,MONSTER_EGGS:2,null,18,MONSTER_EGGS:3,null,6,SMOOTH_BRICK:2,null,12,SMOOTH_BRICK:1,null,12,SMOOTH_BRICK:0,null,80,COBBLESTONE:0,null,100)
RandomBlock(5,7,-4,MONSTER_EGGS:4,null,6,MONSTER_EGGS:2,null,18,MONSTER_EGGS:3,null,6,SMOOTH_BRICK:2,null,12,SMOOTH_BRICK:1,null,12,SMOOTH_BRICK:0,null,80,COBBLESTONE:0,null,100)
RandomBlock(5,7,-3,MONSTER_EGGS:4,null,6,MONSTER_EGGS:2,null,18,MONSTER_EGGS:3,null,6,SMOOTH_BRICK:2,null,12,SMOOTH_BRICK:1,null,12,SMOOTH_BRICK:0,null,80,COBBLESTONE:0,null,100)
RandomBlock(5,7,-2,MONSTER_EGGS:4,null,6,MONSTER_EGGS:2,null,18,MONSTER_EGGS:3,null,6,SMOOTH_BRICK:2,null,12,SMOOTH_BRICK:1,null,12,SMOOTH_BRICK:0,null,80,COBBLESTONE:0,null,100)
