
#######################################################################
# +-----------------------------------------------------------------+ #
# |                            BO3 object                           | #
# +-----------------------------------------------------------------+ #
#######################################################################

Author: NLBlackEagle

Description: No description given

Version: 3

SettingsMode: WriteWithoutComments


#######################################################################
# +-----------------------------------------------------------------+ #
# |                          Main settings                          | #
# +-----------------------------------------------------------------+ #
#######################################################################

Tree: false

Frequency: 20

Rarity: 100.0

RotateRandomly: false

SpawnHeight: randomY

SpawnHeightOffset: 0

SpawnHeightVariance: 0

##############################
# Height Limits for the BO3. #
##############################

MinHeight: 0

MaxHeight: 66

######################
# Extrusion settings #
######################

ExtrudeMode: None

ExtrudeThroughBlocks: AIR

MaxBranchDepth: 10

ExcludedBiomes: All


#######################################################################
# +-----------------------------------------------------------------+ #
# |                      Source block settings                      | #
# +-----------------------------------------------------------------+ #
#######################################################################

SourceBlocks: AIR,STAINED_CLAY,dynamictreesbop:leaves2

MaxPercentageOutsideSourceBlock: 0

OutsideSourceBlock: dontPlace

DoReplaceBlocks: true

IsOTGPlus: false


#######################################################################
# +-----------------------------------------------------------------+ #
# |                              Blocks                             | #
# +-----------------------------------------------------------------+ #
#######################################################################

Block(-2,3,1,dynamictreesbop:leaves2:0)
Block(-2,3,2,dynamictreesbop:leaves2:0)
Block(-2,3,3,dynamictreesbop:leaves2:0)
Block(-2,3,4,dynamictreesbop:leaves2:0)
Block(-2,4,1,dynamictreesbop:leaves2:0)
Block(-2,4,2,dynamictreesbop:leaves2:0)
Block(-2,4,3,dynamictreesbop:leaves2:0)
Block(-1,2,1,dynamictreesbop:leaves2:0)
Block(-1,2,4,dynamictreesbop:leaves2:0)
Block(-1,3,0,dynamictreesbop:leaves2:0)
Block(-1,3,1,dynamictreesbop:leaves2:2)
Block(-1,3,2,dynamictreesbop:leaves2:3)
Block(-1,3,3,dynamictreesbop:leaves2:2)
Block(-1,3,4,dynamictreesbop:leaves2:1)
Block(-1,3,5,dynamictreesbop:leaves2:0)
Block(-1,4,0,dynamictreesbop:leaves2:0)
Block(-1,4,1,dynamictreesbop:leaves2:1)
Block(-1,4,2,dynamictreesbop:leaves2:2)
Block(-1,4,3,dynamictreesbop:leaves2:1)
Block(-1,4,4,dynamictreesbop:leaves2:0)
Block(-1,5,0,dynamictreesbop:leaves2:0)
Block(-1,5,1,dynamictreesbop:leaves2:0)
Block(-1,5,2,dynamictreesbop:leaves2:0)
Block(-1,5,3,dynamictreesbop:leaves2:0)
Block(-1,6,1,dynamictreesbop:leaves2:0)
Block(-1,6,2,dynamictreesbop:leaves2:0)
Block(0,3,0,dynamictreesbop:leaves2:0)
Block(0,3,1,dynamictreesbop:leaves2:3)
Block(0,3,2,dynamictreesbop:cherrybranch:0)
Block(0,3,3,dynamictreesbop:leaves2:3)
Block(0,3,4,dynamictreesbop:leaves2:2)
Block(0,3,5,dynamictreesbop:leaves2:0)
Block(0,4,-1,dynamictreesbop:leaves2:0)
Block(0,4,0,dynamictreesbop:leaves2:2)
Block(0,4,1,dynamictreesbop:leaves2:3)
Block(0,4,2,dynamictreesbop:leaves2:3)
Block(0,4,3,dynamictreesbop:leaves2:2)
Block(0,4,4,dynamictreesbop:leaves2:1)
Block(0,4,5,dynamictreesbop:leaves2:0)
Block(0,5,-1,dynamictreesbop:leaves2:0)
Block(0,5,0,dynamictreesbop:leaves2:1)
Block(0,5,1,dynamictreesbop:leaves2:2)
Block(0,5,2,dynamictreesbop:leaves2:3)
Block(0,5,3,dynamictreesbop:leaves2:0)
Block(0,5,4,dynamictreesbop:leaves2:0)
Block(0,6,0,dynamictreesbop:leaves2:0)
Block(0,6,1,dynamictreesbop:leaves2:2)
Block(0,6,2,dynamictreesbop:leaves2:3)
Block(0,6,3,dynamictreesbop:leaves2:0)
Block(0,6,4,dynamictreesbop:leaves2:0)
Block(0,7,1,dynamictreesbop:leaves2:0)
Block(0,7,2,dynamictreesbop:leaves2:0)
Block(0,7,3,dynamictreesbop:leaves2:0)
Block(1,0,2,dynamictrees:rootydirtspecies:5)
Block(1,1,2,dynamictreesbop:cherrybranch:3)
Block(1,2,2,dynamictreesbop:cherrybranch:3)
Block(1,3,0,dynamictreesbop:leaves2:0)
Block(1,3,2,dynamictreesbop:cherrybranch:3)
Block(1,3,3,dynamictreesbop:cherrybranch:0)
Block(1,3,4,dynamictreesbop:leaves2:3)
Block(1,3,5,dynamictreesbop:leaves2:0)
Block(1,4,-1,dynamictreesbop:leaves2:0)
Block(1,4,0,dynamictreesbop:leaves2:1)
Block(1,4,1,dynamictreesbop:cherrybranch:1)
Block(1,4,2,dynamictreesbop:cherrybranch:2)
Block(1,4,3,dynamictreesbop:leaves2:3)
Block(1,4,4,dynamictreesbop:leaves2:2)
Block(1,4,5,dynamictreesbop:leaves2:0)
Block(1,5,-1,dynamictreesbop:leaves2:0)
Block(1,5,0,dynamictreesbop:leaves2:0)
Block(1,5,1,dynamictreesbop:leaves2:2)
Block(1,5,2,dynamictreesbop:cherrybranch:1)
Block(1,5,3,dynamictreesbop:leaves2:1)
Block(1,5,4,dynamictreesbop:leaves2:0)
Block(1,6,0,dynamictreesbop:leaves2:0)
Block(1,6,1,dynamictreesbop:leaves2:3)
Block(1,6,2,dynamictreesbop:cherrybranch:0)
Block(1,6,3,dynamictreesbop:leaves2:2)
Block(1,6,4,dynamictreesbop:leaves2:0)
Block(1,7,1,dynamictreesbop:leaves2:0)
Block(1,7,2,dynamictreesbop:leaves2:3)
Block(1,7,3,dynamictreesbop:leaves2:0)
Block(1,8,2,dynamictreesbop:leaves2:0)
Block(2,3,-1,dynamictreesbop:leaves2:0)
Block(2,3,0,dynamictreesbop:leaves2:0)
Block(2,3,2,dynamictreesbop:cherrybranch:0)
Block(2,3,4,dynamictreesbop:leaves2:0)
Block(2,4,-1,dynamictreesbop:leaves2:0)
Block(2,4,0,dynamictreesbop:leaves2:2)
Block(2,4,1,dynamictreesbop:cherrybranch:0)
Block(2,4,2,dynamictreesbop:leaves2:3)
Block(2,4,3,dynamictreesbop:leaves2:2)
Block(2,4,4,dynamictreesbop:leaves2:1)
Block(2,4,5,dynamictreesbop:leaves2:0)
Block(2,5,-1,dynamictreesbop:leaves2:0)
Block(2,5,0,dynamictreesbop:leaves2:1)
Block(2,5,1,dynamictreesbop:leaves2:3)
Block(2,5,2,dynamictreesbop:leaves2:2)
Block(2,5,3,dynamictreesbop:leaves2:2)
Block(2,5,4,dynamictreesbop:leaves2:0)
Block(2,6,0,dynamictreesbop:leaves2:0)
Block(2,6,1,dynamictreesbop:leaves2:1)
Block(2,6,2,dynamictreesbop:leaves2:3)
Block(2,6,3,dynamictreesbop:leaves2:1)
Block(2,6,4,dynamictreesbop:leaves2:0)
Block(2,7,1,dynamictreesbop:leaves2:0)
Block(2,7,2,dynamictreesbop:leaves2:0)
Block(2,7,3,dynamictreesbop:leaves2:0)
Block(3,2,4,dynamictreesbop:leaves2:0)
Block(3,3,0,dynamictreesbop:leaves2:0)
Block(3,3,1,dynamictreesbop:leaves2:2)
Block(3,3,2,dynamictreesbop:leaves2:3)
Block(3,3,3,dynamictreesbop:leaves2:0)
Block(3,3,4,dynamictreesbop:leaves2:1)
Block(3,3,5,dynamictreesbop:leaves2:0)
Block(3,4,0,dynamictreesbop:leaves2:0)
Block(3,4,1,dynamictreesbop:leaves2:3)
Block(3,4,2,dynamictreesbop:leaves2:2)
Block(3,4,3,dynamictreesbop:leaves2:1)
Block(3,4,4,dynamictreesbop:leaves2:0)
Block(3,5,0,dynamictreesbop:leaves2:0)
Block(3,5,1,dynamictreesbop:leaves2:0)
Block(3,5,2,dynamictreesbop:leaves2:0)
Block(3,5,3,dynamictreesbop:leaves2:0)
Block(3,6,1,dynamictreesbop:leaves2:0)
Block(3,6,2,dynamictreesbop:leaves2:0)
Block(3,6,3,dynamictreesbop:leaves2:0)
Block(4,3,1,dynamictreesbop:leaves2:0)
Block(4,3,2,dynamictreesbop:leaves2:0)
Block(4,3,4,dynamictreesbop:leaves2:0)
Block(4,4,1,dynamictreesbop:leaves2:0)
Block(4,4,2,dynamictreesbop:leaves2:0)
Block(4,4,3,dynamictreesbop:leaves2:0)

#######################################################################
# +-----------------------------------------------------------------+ #
# |                            BO3 checks                           | #
# +-----------------------------------------------------------------+ #
#######################################################################

BlockCheck(1,0,2,STAINED_CLAY)

#######################################################################
# +-----------------------------------------------------------------+ #
# |                             Branches                            | #
# +-----------------------------------------------------------------+ #
#######################################################################


#######################################################################
# +-----------------------------------------------------------------+ #
# |                             Entities                            | #
# +-----------------------------------------------------------------+ #
#######################################################################


#######################################################################
# +-----------------------------------------------------------------+ #
# |                            Particles                            | #
# +-----------------------------------------------------------------+ #
#######################################################################


#######################################################################
# +-----------------------------------------------------------------+ #
# |                             Spawners                            | #
# +-----------------------------------------------------------------+ #
#######################################################################


#######################################################################
# +-----------------------------------------------------------------+ #
# |                             ModData                             | #
# +-----------------------------------------------------------------+ #
#######################################################################

