
#######################################################################
# +-----------------------------------------------------------------+ #
# |                            BO3 object                           | #
# +-----------------------------------------------------------------+ #
#######################################################################

Author: NLBlackHeavenNL

Description: No description given

Version: 3

SettingsMode: WriteWithoutComments


#######################################################################
# +-----------------------------------------------------------------+ #
# |                          Main settings                          | #
# +-----------------------------------------------------------------+ #
#######################################################################

Tree: true

Frequency: 1

Rarity: 100.0

RotateRandomly: false

SpawnHeight: highestSolidBlock

SpawnHeightOffset: -1

SpawnHeightVariance: 0

##############################
# Height Limits for the BO3. #
##############################

MinHeight: 0

MaxHeight: 255

######################
# Extrusion settings #
######################

ExtrudeMode: None

ExtrudeThroughBlocks: AIR

MaxBranchDepth: 10

ExcludedBiomes: All


#######################################################################
# +-----------------------------------------------------------------+ #
# |                      Source block settings                      | #
# +-----------------------------------------------------------------+ #
#######################################################################

SourceBlocks: AIR,GRASS,DIRT,biomesoplenty:dirt

MaxPercentageOutsideSourceBlock: 0

OutsideSourceBlock: placeAnyway

DoReplaceBlocks: true

IsOTGPlus: false


#######################################################################
# +-----------------------------------------------------------------+ #
# |                              Blocks                             | #
# +-----------------------------------------------------------------+ #
#######################################################################

Block(-4,11,0,dynamictrees:leaves0:8)
Block(-4,11,1,dynamictrees:leaves0:8)
Block(-4,11,2,dynamictrees:leaves0:8)
Block(-4,11,3,dynamictrees:leaves0:8)
Block(-4,12,1,dynamictrees:leaves0:8)
Block(-4,12,2,dynamictrees:leaves0:8)
Block(-4,12,3,dynamictrees:leaves0:8)
Block(-4,13,2,dynamictrees:leaves0:8)
Block(-3,10,0,dynamictrees:leaves0:8)
Block(-3,10,1,dynamictrees:leaves0:8)
Block(-3,10,2,dynamictrees:leaves0:8)
Block(-3,10,3,dynamictrees:leaves0:8)
Block(-3,11,-1,dynamictrees:leaves0:8)
Block(-3,11,0,dynamictrees:leaves0:9)
Block(-3,11,1,dynamictrees:leaves0:10)
Block(-3,11,2,dynamictrees:leaves0:11)
Block(-3,11,3,dynamictrees:leaves0:10)
Block(-3,11,4,dynamictrees:leaves0:8)
Block(-3,12,0,dynamictrees:leaves0:8)
Block(-3,12,1,dynamictrees:leaves0:9)
Block(-3,12,2,dynamictrees:leaves0:10)
Block(-3,12,3,dynamictrees:leaves0:9)
Block(-3,12,4,dynamictrees:leaves0:8)
Block(-3,13,1,dynamictrees:leaves0:8)
Block(-3,13,2,dynamictrees:leaves0:9)
Block(-3,13,3,dynamictrees:leaves0:8)
Block(-3,14,2,dynamictrees:leaves0:8)
Block(-2,10,-1,dynamictrees:leaves0:8)
Block(-2,10,0,dynamictrees:leaves0:8)
Block(-2,11,-2,dynamictrees:leaves0:8)
Block(-2,11,-1,dynamictrees:leaves0:9)
Block(-2,11,0,dynamictrees:leaves0:10)
Block(-2,11,1,dynamictrees:leaves0:11)
Block(-2,11,2,dynamictrees:birchbranch:0)
Block(-2,11,3,dynamictrees:leaves0:11)
Block(-2,11,4,dynamictrees:leaves0:8)
Block(-2,12,-1,dynamictrees:leaves0:8)
Block(-2,12,0,dynamictrees:leaves0:9)
Block(-2,12,1,dynamictrees:leaves0:10)
Block(-2,12,2,dynamictrees:leaves0:11)
Block(-2,12,3,dynamictrees:leaves0:10)
Block(-2,12,4,dynamictrees:leaves0:9)
Block(-2,12,5,dynamictrees:leaves0:8)
Block(-2,13,0,dynamictrees:leaves0:8)
Block(-2,13,1,dynamictrees:leaves0:9)
Block(-2,13,2,dynamictrees:leaves0:10)
Block(-2,13,3,dynamictrees:leaves0:9)
Block(-2,13,4,dynamictrees:leaves0:8)
Block(-2,14,1,dynamictrees:leaves0:8)
Block(-2,14,2,dynamictrees:leaves0:9)
Block(-2,14,3,dynamictrees:leaves0:8)
Block(-2,15,2,dynamictrees:leaves0:8)
Block(-1,10,-1,dynamictrees:leaves0:8)
Block(-1,11,-2,dynamictrees:leaves0:8)
Block(-1,11,-1,dynamictrees:leaves0:10)
Block(-1,11,0,dynamictrees:leaves0:11)
Block(-1,11,1,dynamictrees:birchbranch:0)
Block(-1,11,2,dynamictrees:birchbranch:1)
Block(-1,11,4,dynamictrees:leaves0:9)
Block(-1,11,5,dynamictrees:leaves0:8)
Block(-1,12,-2,dynamictrees:leaves0:8)
Block(-1,12,-1,dynamictrees:leaves0:9)
Block(-1,12,0,dynamictrees:leaves0:10)
Block(-1,12,1,dynamictrees:leaves0:11)
Block(-1,12,2,dynamictrees:leaves0:10)
Block(-1,12,3,dynamictrees:leaves0:11)
Block(-1,12,4,dynamictrees:leaves0:10)
Block(-1,12,5,dynamictrees:leaves0:8)
Block(-1,13,-1,dynamictrees:leaves0:8)
Block(-1,13,0,dynamictrees:leaves0:9)
Block(-1,13,1,dynamictrees:leaves0:10)
Block(-1,13,2,dynamictrees:leaves0:11)
Block(-1,13,3,dynamictrees:leaves0:10)
Block(-1,13,4,dynamictrees:leaves0:9)
Block(-1,13,5,dynamictrees:leaves0:8)
Block(-1,14,0,dynamictrees:leaves0:8)
Block(-1,14,1,dynamictrees:leaves0:9)
Block(-1,14,2,dynamictrees:leaves0:10)
Block(-1,14,3,dynamictrees:leaves0:9)
Block(-1,14,4,dynamictrees:leaves0:8)
Block(-1,15,1,dynamictrees:leaves0:8)
Block(-1,15,2,dynamictrees:leaves0:8)
Block(-1,15,3,dynamictrees:leaves0:8)
Block(0,0,2,dynamictrees:rootydirt:0)
Block(0,1,2,dynamictrees:birchbranch:3)
Block(0,2,2,dynamictrees:birchbranch:3)
Block(0,3,2,dynamictrees:birchbranch:3)
Block(0,4,2,dynamictrees:birchbranch:3)
Block(0,5,2,dynamictrees:birchbranch:3)
Block(0,6,2,dynamictrees:birchbranch:3)
Block(0,7,2,dynamictrees:birchbranch:3)
Block(0,8,0,dynamictrees:birchbranch:1)
Block(0,8,1,dynamictrees:birchbranch:2)
Block(0,8,2,dynamictrees:birchbranch:2)
Block(0,9,0,dynamictrees:birchbranch:1)
Block(0,9,2,dynamictrees:birchbranch:1)
Block(0,10,-1,dynamictrees:leaves0:8)
Block(0,10,0,dynamictrees:birchbranch:1)
Block(0,10,2,dynamictrees:birchbranch:1)
Block(0,10,3,dynamictrees:birchbranch:0)
Block(0,11,-2,dynamictrees:leaves0:8)
Block(0,11,-1,dynamictrees:leaves0:11)
Block(0,11,0,dynamictrees:birchbranch:0)
Block(0,11,2,dynamictrees:birchbranch:1)
Block(0,11,3,dynamictrees:leaves0:11)
Block(0,11,4,dynamictrees:leaves0:10)
Block(0,11,5,dynamictrees:leaves0:8)
Block(0,12,-2,dynamictrees:leaves0:8)
Block(0,12,-1,dynamictrees:leaves0:10)
Block(0,12,0,dynamictrees:leaves0:11)
Block(0,12,1,dynamictrees:birchbranch:0)
Block(0,12,2,dynamictrees:birchbranch:1)
Block(0,12,3,dynamictrees:birchbranch:0)
Block(0,12,4,dynamictrees:leaves0:11)
Block(0,12,5,dynamictrees:leaves0:8)
Block(0,13,-2,dynamictrees:leaves0:8)
Block(0,13,-1,dynamictrees:leaves0:9)
Block(0,13,0,dynamictrees:leaves0:10)
Block(0,13,1,dynamictrees:leaves0:11)
Block(0,13,2,dynamictrees:birchbranch:0)
Block(0,13,3,dynamictrees:leaves0:11)
Block(0,13,4,dynamictrees:leaves0:10)
Block(0,13,5,dynamictrees:leaves0:8)
Block(0,14,-1,dynamictrees:leaves0:8)
Block(0,14,0,dynamictrees:leaves0:9)
Block(0,14,1,dynamictrees:leaves0:10)
Block(0,14,2,dynamictrees:leaves0:11)
Block(0,14,3,dynamictrees:leaves0:10)
Block(0,14,4,dynamictrees:leaves0:9)
Block(0,14,5,dynamictrees:leaves0:8)
Block(0,15,0,dynamictrees:leaves0:8)
Block(0,15,1,dynamictrees:leaves0:8)
Block(0,15,2,dynamictrees:leaves0:8)
Block(0,15,3,dynamictrees:leaves0:8)
Block(0,15,4,dynamictrees:leaves0:8)
Block(1,8,1,dynamictrees:birchbranch:1)
Block(1,9,1,dynamictrees:birchbranch:1)
Block(1,10,-1,dynamictrees:leaves0:8)
Block(1,10,1,dynamictrees:birchbranch:1)
Block(1,11,-2,dynamictrees:leaves0:8)
Block(1,11,-1,dynamictrees:leaves0:10)
Block(1,11,0,dynamictrees:leaves0:11)
Block(1,11,1,dynamictrees:birchbranch:0)
Block(1,11,4,dynamictrees:leaves0:9)
Block(1,11,5,dynamictrees:leaves0:8)
Block(1,12,-2,dynamictrees:leaves0:8)
Block(1,12,-1,dynamictrees:leaves0:9)
Block(1,12,0,dynamictrees:leaves0:10)
Block(1,12,1,dynamictrees:leaves0:11)
Block(1,12,2,dynamictrees:birchbranch:0)
Block(1,12,3,dynamictrees:leaves0:11)
Block(1,12,4,dynamictrees:leaves0:10)
Block(1,12,5,dynamictrees:leaves0:8)
Block(1,13,-1,dynamictrees:leaves0:8)
Block(1,13,0,dynamictrees:leaves0:9)
Block(1,13,1,dynamictrees:leaves0:10)
Block(1,13,2,dynamictrees:leaves0:11)
Block(1,13,3,dynamictrees:leaves0:10)
Block(1,13,4,dynamictrees:leaves0:9)
Block(1,13,5,dynamictrees:leaves0:8)
Block(1,14,0,dynamictrees:leaves0:8)
Block(1,14,1,dynamictrees:leaves0:9)
Block(1,14,2,dynamictrees:leaves0:10)
Block(1,14,3,dynamictrees:leaves0:9)
Block(1,14,4,dynamictrees:leaves0:8)
Block(1,15,1,dynamictrees:leaves0:8)
Block(1,15,2,dynamictrees:leaves0:8)
Block(1,15,3,dynamictrees:leaves0:8)
Block(2,10,-1,dynamictrees:leaves0:8)
Block(2,10,0,dynamictrees:leaves0:8)
Block(2,11,-2,dynamictrees:leaves0:8)
Block(2,11,-1,dynamictrees:leaves0:9)
Block(2,11,0,dynamictrees:leaves0:10)
Block(2,11,1,dynamictrees:leaves0:11)
Block(2,11,3,dynamictrees:leaves0:8)
Block(2,11,4,dynamictrees:leaves0:8)
Block(2,12,-1,dynamictrees:leaves0:8)
Block(2,12,0,dynamictrees:leaves0:9)
Block(2,12,1,dynamictrees:leaves0:10)
Block(2,12,2,dynamictrees:leaves0:11)
Block(2,12,3,dynamictrees:leaves0:10)
Block(2,12,4,dynamictrees:leaves0:9)
Block(2,12,5,dynamictrees:leaves0:8)
Block(2,13,0,dynamictrees:leaves0:8)
Block(2,13,1,dynamictrees:leaves0:9)
Block(2,13,2,dynamictrees:leaves0:10)
Block(2,13,3,dynamictrees:leaves0:9)
Block(2,13,4,dynamictrees:leaves0:8)
Block(2,14,1,dynamictrees:leaves0:8)
Block(2,14,2,dynamictrees:leaves0:9)
Block(2,14,3,dynamictrees:leaves0:8)
Block(2,15,2,dynamictrees:leaves0:8)
Block(3,11,-1,dynamictrees:leaves0:8)
Block(3,11,0,dynamictrees:leaves0:8)
Block(3,11,1,dynamictrees:leaves0:8)
Block(3,11,2,dynamictrees:leaves0:8)
Block(3,11,3,dynamictrees:leaves0:8)
Block(3,12,0,dynamictrees:leaves0:8)
Block(3,12,1,dynamictrees:leaves0:8)
Block(3,12,2,dynamictrees:leaves0:8)
Block(3,12,3,dynamictrees:leaves0:8)
Block(3,12,4,dynamictrees:leaves0:8)
Block(3,13,1,dynamictrees:leaves0:8)
Block(3,13,2,dynamictrees:leaves0:8)
Block(3,13,3,dynamictrees:leaves0:8)
Block(3,14,2,dynamictrees:leaves0:8)

#######################################################################
# +-----------------------------------------------------------------+ #
# |                            BO3 checks                           | #
# +-----------------------------------------------------------------+ #
#######################################################################

BlockCheck(0,-1,2,GRASS,DIRT,biomesoplenty:grass)

#######################################################################
# +-----------------------------------------------------------------+ #
# |                             Branches                            | #
# +-----------------------------------------------------------------+ #
#######################################################################


#######################################################################
# +-----------------------------------------------------------------+ #
# |                             Entities                            | #
# +-----------------------------------------------------------------+ #
#######################################################################


#######################################################################
# +-----------------------------------------------------------------+ #
# |                            Particles                            | #
# +-----------------------------------------------------------------+ #
#######################################################################


#######################################################################
# +-----------------------------------------------------------------+ #
# |                             Spawners                            | #
# +-----------------------------------------------------------------+ #
#######################################################################


#######################################################################
# +-----------------------------------------------------------------+ #
# |                             ModData                             | #
# +-----------------------------------------------------------------+ #
#######################################################################

