
#######################################################################
# +-----------------------------------------------------------------+ #
# |                            BO4 object                           | #
# +-----------------------------------------------------------------+ #
#######################################################################

Author: NLBlackEagle

Description: No description given

SettingsMode: WriteWithoutComments


#######################################################################
# +-----------------------------------------------------------------+ #
# |                          Main settings                          | #
# +-----------------------------------------------------------------+ #
#######################################################################

FixedRotation: 

Frequency: 0

SpawnHeight: randomY

UseCenterForHighestBlock: true

##############################
# Height Limits for the BO4. #
##############################

MinHeight: 78

MaxHeight: 78

InheritBO3: 

InheritBO3Rotation: NORTH

OverrideChildSettings: true

OverrideParentHeight: false

CanOverride: true

BranchFrequency: 0

BranchFrequencyGroup: 

MustBeBelowOther: false

MustBeInside: 

CannotBeInside: 

ReplacesBO3: 

MustBeInsideWorldBorders: false

CanSpawnOnWater: true

SpawnOnWaterOnly: false

SpawnUnderWater: false

SpawnAtWaterLevel: false

HeightOffset: 0

RemoveAir: false

ReplaceAbove: 

ReplaceBelow: 

ReplaceWithBiomeBlocks: true

ReplaceWithSurfaceBlock: GRASS

ReplaceWithGroundBlock: DIRT

ReplaceWithStoneBlock: STONE

SmoothRadius: 0

SmoothHeightOffset: 0

SmoothStartTop: false

SmoothStartWood: false

SmoothingSurfaceBlock: 

SmoothingGroundBlock: 

BO3Group: 

IsSpawnPoint: false

DoReplaceBlocks: false


#######################################################################
# +-----------------------------------------------------------------+ #
# |                              Blocks                             | #
# +-----------------------------------------------------------------+ #
#######################################################################

Block(-8,6,-6,COBBLESTONE_STAIRS:6)
RandomBlock(-8,6,-5,quark:iron_plate:1,null,70,STAINED_CLAY:15,null,30,STAINED_CLAY:7,null,30,quark:iron_plate:1,null,100)
RandomBlock(-8,6,-4,quark:iron_plate:1,null,70,STAINED_CLAY:15,null,30,STAINED_CLAY:7,null,30,quark:iron_plate:1,null,100)
Block(-8,6,-3,COBBLESTONE_STAIRS:7)
RandomBlock(-8,7,-6,quark:iron_plate:1,null,70,STAINED_CLAY:15,null,30,STAINED_CLAY:7,null,30,quark:iron_plate:1,null,100)
Block(-8,7,-5,AIR:0)
Block(-8,7,-4,AIR:0)
RandomBlock(-8,7,-3,quark:iron_plate:1,null,70,STAINED_CLAY:15,null,30,STAINED_CLAY:7,null,30,quark:iron_plate:1,null,100)
Block(-8,7,2,COBBLESTONE_STAIRS:6)
Block(-8,7,3,COBBLESTONE_STAIRS:7)
RandomBlock(-8,8,-6,quark:iron_plate:1,null,70,STAINED_CLAY:15,null,30,STAINED_CLAY:7,null,30,quark:iron_plate:1,null,100)
Block(-8,8,-5,AIR:0)
Block(-8,8,-4,AIR:0)
RandomBlock(-8,8,-3,quark:iron_plate:1,null,70,STAINED_CLAY:15,null,30,STAINED_CLAY:7,null,30,quark:iron_plate:1,null,100)
Block(-8,8,2,COBBLESTONE_STAIRS:2)
Block(-8,8,3,COBBLESTONE_STAIRS:3)
Block(-8,9,-6,COBBLESTONE_STAIRS:2)
RandomBlock(-8,9,-5,rustic:iron_lattice:1,null,30,rustic:iron_lattice:1,null,30,biomesoplenty:leaves_2:7,null,30,quark:iron_plate_stairs:6,null,10,quark:iron_plate_stairs:0,null,10,quark:iron_plate_stairs:5,null,10,quark:iron_plate_stairs:3,null,10,quark:iron_plate_slab:8,null,10,quark:iron_plate_stairs:7,null,10,quark:iron_plate_stairs:1,null,10,quark:iron_plate_slab:0,null,10,quark:iron_plate_stairs:4,null,10,quark:iron_plate_stairs:2,null,10,rustic:iron_lattice:1,null,50,rustic:iron_lattice:1,null,50,biomesoplenty:leaves_2:7,null,100)
RandomBlock(-8,9,-4,rustic:iron_lattice:1,null,30,rustic:iron_lattice:1,null,30,biomesoplenty:leaves_2:7,null,30,quark:iron_plate_stairs:6,null,10,quark:iron_plate_stairs:0,null,10,quark:iron_plate_stairs:5,null,10,quark:iron_plate_stairs:3,null,10,quark:iron_plate_slab:8,null,10,quark:iron_plate_stairs:7,null,10,quark:iron_plate_stairs:1,null,10,quark:iron_plate_slab:0,null,10,quark:iron_plate_stairs:4,null,10,quark:iron_plate_stairs:2,null,10,rustic:iron_lattice:1,null,50,rustic:iron_lattice:1,null,50,biomesoplenty:leaves_2:7,null,100)
Block(-8,9,-3,COBBLESTONE_STAIRS:3)
Block(-7,6,-6,COBBLESTONE_STAIRS:6)
RandomBlock(-7,6,-5,quark:iron_plate:1,null,70,STAINED_CLAY:15,null,30,STAINED_CLAY:7,null,30,quark:iron_plate:1,null,100)
RandomBlock(-7,6,-4,quark:iron_plate:1,null,70,STAINED_CLAY:15,null,30,STAINED_CLAY:7,null,30,quark:iron_plate:1,null,100)
Block(-7,6,-3,COBBLESTONE_STAIRS:7)
RandomBlock(-7,7,-6,quark:iron_plate:1,null,70,STAINED_CLAY:15,null,30,STAINED_CLAY:7,null,30,quark:iron_plate:1,null,100)
Block(-7,7,-5,AIR:0)
Block(-7,7,-4,AIR:0)
RandomBlock(-7,7,-3,rustic:iron_lattice:1,null,30,rustic:iron_lattice:1,null,30,biomesoplenty:leaves_2:7,null,30,quark:iron_plate_stairs:6,null,10,quark:iron_plate_stairs:0,null,10,quark:iron_plate_stairs:5,null,10,quark:iron_plate_stairs:3,null,10,quark:iron_plate_slab:8,null,10,quark:iron_plate_stairs:7,null,10,quark:iron_plate_stairs:1,null,10,quark:iron_plate_slab:0,null,10,quark:iron_plate_stairs:4,null,10,quark:iron_plate_stairs:2,null,10,rustic:iron_lattice:1,null,50,rustic:iron_lattice:1,null,50,biomesoplenty:leaves_2:7,null,100)
Block(-7,7,2,COBBLESTONE_STAIRS:6)
Block(-7,7,3,COBBLESTONE_STAIRS:7)
RandomBlock(-7,8,-6,quark:iron_plate:1,null,70,STAINED_CLAY:15,null,30,STAINED_CLAY:7,null,30,quark:iron_plate:1,null,100)
Block(-7,8,-5,AIR:0)
Block(-7,8,-4,AIR:0)
RandomBlock(-7,8,-3,quark:iron_plate:1,null,70,STAINED_CLAY:15,null,30,STAINED_CLAY:7,null,30,quark:iron_plate:1,null,100)
Block(-7,8,2,COBBLESTONE_STAIRS:2)
Block(-7,8,3,COBBLESTONE_STAIRS:3)
Block(-7,9,-6,COBBLESTONE_STAIRS:2)
RandomBlock(-7,9,-5,quark:iron_plate:1,null,70,STAINED_CLAY:15,null,30,STAINED_CLAY:7,null,30,quark:iron_plate:1,null,100)
RandomBlock(-7,9,-4,rustic:iron_lattice:1,null,30,rustic:iron_lattice:1,null,30,biomesoplenty:leaves_2:7,null,30,quark:iron_plate_stairs:6,null,10,quark:iron_plate_stairs:0,null,10,quark:iron_plate_stairs:5,null,10,quark:iron_plate_stairs:3,null,10,quark:iron_plate_slab:8,null,10,quark:iron_plate_stairs:7,null,10,quark:iron_plate_stairs:1,null,10,quark:iron_plate_slab:0,null,10,quark:iron_plate_stairs:4,null,10,quark:iron_plate_stairs:2,null,10,rustic:iron_lattice:1,null,50,rustic:iron_lattice:1,null,50,biomesoplenty:leaves_2:7,null,100)
Block(-7,9,-3,COBBLESTONE_STAIRS:3)
Block(-6,6,-6,COBBLESTONE_STAIRS:6)
RandomBlock(-6,6,-5,quark:iron_plate:1,null,70,STAINED_CLAY:15,null,30,STAINED_CLAY:7,null,30,quark:iron_plate:1,null,100)
RandomBlock(-6,6,-4,quark:iron_plate:1,null,70,STAINED_CLAY:15,null,30,STAINED_CLAY:7,null,30,quark:iron_plate:1,null,100)
Block(-6,6,-3,COBBLESTONE_STAIRS:7)
RandomBlock(-6,7,-6,quark:iron_plate:1,null,70,STAINED_CLAY:15,null,30,STAINED_CLAY:7,null,30,quark:iron_plate:1,null,100)
Block(-6,7,-5,AIR:0)
Block(-6,7,-4,AIR:0)
RandomBlock(-6,7,-3,rustic:iron_lattice:1,null,30,rustic:iron_lattice:1,null,30,biomesoplenty:leaves_2:7,null,30,quark:iron_plate_stairs:6,null,10,quark:iron_plate_stairs:0,null,10,quark:iron_plate_stairs:5,null,10,quark:iron_plate_stairs:3,null,10,quark:iron_plate_slab:8,null,10,quark:iron_plate_stairs:7,null,10,quark:iron_plate_stairs:1,null,10,quark:iron_plate_slab:0,null,10,quark:iron_plate_stairs:4,null,10,quark:iron_plate_stairs:2,null,10,rustic:iron_lattice:1,null,50,rustic:iron_lattice:1,null,50,biomesoplenty:leaves_2:7,null,100)
Block(-6,7,2,COBBLESTONE_STAIRS:6)
Block(-6,7,3,COBBLESTONE_STAIRS:7)
RandomBlock(-6,8,-6,rustic:iron_lattice:1,null,30,rustic:iron_lattice:1,null,30,biomesoplenty:leaves_2:7,null,30,quark:iron_plate_stairs:6,null,10,quark:iron_plate_stairs:0,null,10,quark:iron_plate_stairs:5,null,10,quark:iron_plate_stairs:3,null,10,quark:iron_plate_slab:8,null,10,quark:iron_plate_stairs:7,null,10,quark:iron_plate_stairs:1,null,10,quark:iron_plate_slab:0,null,10,quark:iron_plate_stairs:4,null,10,quark:iron_plate_stairs:2,null,10,rustic:iron_lattice:1,null,50,rustic:iron_lattice:1,null,50,biomesoplenty:leaves_2:7,null,100)
Block(-6,8,-5,AIR:0)
Block(-6,8,-4,AIR:0)
RandomBlock(-6,8,-3,rustic:iron_lattice:1,null,30,rustic:iron_lattice:1,null,30,biomesoplenty:leaves_2:7,null,30,quark:iron_plate_stairs:6,null,10,quark:iron_plate_stairs:0,null,10,quark:iron_plate_stairs:5,null,10,quark:iron_plate_stairs:3,null,10,quark:iron_plate_slab:8,null,10,quark:iron_plate_stairs:7,null,10,quark:iron_plate_stairs:1,null,10,quark:iron_plate_slab:0,null,10,quark:iron_plate_stairs:4,null,10,quark:iron_plate_stairs:2,null,10,rustic:iron_lattice:1,null,50,rustic:iron_lattice:1,null,50,biomesoplenty:leaves_2:7,null,100)
Block(-6,8,2,COBBLESTONE_STAIRS:2)
Block(-6,8,3,COBBLESTONE_STAIRS:3)
Block(-6,9,-6,COBBLESTONE_STAIRS:2)
RandomBlock(-6,9,-5,rustic:iron_lattice:1,null,30,rustic:iron_lattice:1,null,30,biomesoplenty:leaves_2:7,null,30,quark:iron_plate_stairs:6,null,10,quark:iron_plate_stairs:0,null,10,quark:iron_plate_stairs:5,null,10,quark:iron_plate_stairs:3,null,10,quark:iron_plate_slab:8,null,10,quark:iron_plate_stairs:7,null,10,quark:iron_plate_stairs:1,null,10,quark:iron_plate_slab:0,null,10,quark:iron_plate_stairs:4,null,10,quark:iron_plate_stairs:2,null,10,rustic:iron_lattice:1,null,50,rustic:iron_lattice:1,null,50,biomesoplenty:leaves_2:7,null,100)
RandomBlock(-6,9,-4,quark:iron_plate:1,null,70,STAINED_CLAY:15,null,30,STAINED_CLAY:7,null,30,quark:iron_plate:1,null,100)
Block(-6,9,-3,COBBLESTONE_STAIRS:3)
Block(-5,6,-6,COBBLESTONE_STAIRS:6)
RandomBlock(-5,6,-5,quark:iron_plate:1,null,70,STAINED_CLAY:15,null,30,STAINED_CLAY:7,null,30,quark:iron_plate:1,null,100)
RandomBlock(-5,6,-4,quark:iron_plate:1,null,70,STAINED_CLAY:15,null,30,STAINED_CLAY:7,null,30,quark:iron_plate:1,null,100)
Block(-5,6,-3,COBBLESTONE_STAIRS:7)
RandomBlock(-5,7,-6,quark:iron_plate:1,null,70,STAINED_CLAY:15,null,30,STAINED_CLAY:7,null,30,quark:iron_plate:1,null,100)
Block(-5,7,-5,AIR:0)
Block(-5,7,-4,AIR:0)
RandomBlock(-5,7,-3,rustic:iron_lattice:1,null,30,rustic:iron_lattice:1,null,30,biomesoplenty:leaves_2:7,null,30,quark:iron_plate_stairs:6,null,10,quark:iron_plate_stairs:0,null,10,quark:iron_plate_stairs:5,null,10,quark:iron_plate_stairs:3,null,10,quark:iron_plate_slab:8,null,10,quark:iron_plate_stairs:7,null,10,quark:iron_plate_stairs:1,null,10,quark:iron_plate_slab:0,null,10,quark:iron_plate_stairs:4,null,10,quark:iron_plate_stairs:2,null,10,rustic:iron_lattice:1,null,50,rustic:iron_lattice:1,null,50,biomesoplenty:leaves_2:7,null,100)
Block(-5,7,2,COBBLESTONE_STAIRS:6)
Block(-5,7,3,COBBLESTONE_STAIRS:7)
RandomBlock(-5,8,-6,rustic:iron_lattice:1,null,30,rustic:iron_lattice:1,null,30,biomesoplenty:leaves_2:7,null,30,quark:iron_plate_stairs:6,null,10,quark:iron_plate_stairs:0,null,10,quark:iron_plate_stairs:5,null,10,quark:iron_plate_stairs:3,null,10,quark:iron_plate_slab:8,null,10,quark:iron_plate_stairs:7,null,10,quark:iron_plate_stairs:1,null,10,quark:iron_plate_slab:0,null,10,quark:iron_plate_stairs:4,null,10,quark:iron_plate_stairs:2,null,10,rustic:iron_lattice:1,null,50,rustic:iron_lattice:1,null,50,biomesoplenty:leaves_2:7,null,100)
Block(-5,8,-5,AIR:0)
Block(-5,8,-4,AIR:0)
RandomBlock(-5,8,-3,quark:iron_plate:1,null,70,STAINED_CLAY:15,null,30,STAINED_CLAY:7,null,30,quark:iron_plate:1,null,100)
Block(-5,8,2,COBBLESTONE_STAIRS:2)
Block(-5,8,3,COBBLESTONE_STAIRS:3)
Block(-5,9,-6,COBBLESTONE_STAIRS:2)
RandomBlock(-5,9,-5,quark:iron_plate:1,null,70,STAINED_CLAY:15,null,30,STAINED_CLAY:7,null,30,quark:iron_plate:1,null,100)
RandomBlock(-5,9,-4,quark:iron_plate:1,null,70,STAINED_CLAY:15,null,30,STAINED_CLAY:7,null,30,quark:iron_plate:1,null,100)
Block(-5,9,-3,COBBLESTONE_STAIRS:3)
Block(-4,6,-6,COBBLESTONE_STAIRS:6)
RandomBlock(-4,6,-5,quark:iron_plate:1,null,70,STAINED_CLAY:15,null,30,STAINED_CLAY:7,null,30,quark:iron_plate:1,null,100)
RandomBlock(-4,6,-4,quark:iron_plate:1,null,70,STAINED_CLAY:15,null,30,STAINED_CLAY:7,null,30,quark:iron_plate:1,null,100)
Block(-4,6,-3,COBBLESTONE_STAIRS:7)
RandomBlock(-4,7,-6,rustic:iron_lattice:1,null,30,rustic:iron_lattice:1,null,30,biomesoplenty:leaves_2:7,null,30,quark:iron_plate_stairs:6,null,10,quark:iron_plate_stairs:0,null,10,quark:iron_plate_stairs:5,null,10,quark:iron_plate_stairs:3,null,10,quark:iron_plate_slab:8,null,10,quark:iron_plate_stairs:7,null,10,quark:iron_plate_stairs:1,null,10,quark:iron_plate_slab:0,null,10,quark:iron_plate_stairs:4,null,10,quark:iron_plate_stairs:2,null,10,rustic:iron_lattice:1,null,50,rustic:iron_lattice:1,null,50,biomesoplenty:leaves_2:7,null,100)
Block(-4,7,-5,AIR:0)
Block(-4,7,-4,AIR:0)
RandomBlock(-4,7,-3,rustic:iron_lattice:1,null,30,rustic:iron_lattice:1,null,30,biomesoplenty:leaves_2:7,null,30,quark:iron_plate_stairs:6,null,10,quark:iron_plate_stairs:0,null,10,quark:iron_plate_stairs:5,null,10,quark:iron_plate_stairs:3,null,10,quark:iron_plate_slab:8,null,10,quark:iron_plate_stairs:7,null,10,quark:iron_plate_stairs:1,null,10,quark:iron_plate_slab:0,null,10,quark:iron_plate_stairs:4,null,10,quark:iron_plate_stairs:2,null,10,rustic:iron_lattice:1,null,50,rustic:iron_lattice:1,null,50,biomesoplenty:leaves_2:7,null,100)
Block(-4,7,2,COBBLESTONE_STAIRS:6)
Block(-4,7,3,COBBLESTONE_STAIRS:7)
RandomBlock(-4,8,-6,rustic:iron_lattice:1,null,30,rustic:iron_lattice:1,null,30,biomesoplenty:leaves_2:7,null,30,quark:iron_plate_stairs:6,null,10,quark:iron_plate_stairs:0,null,10,quark:iron_plate_stairs:5,null,10,quark:iron_plate_stairs:3,null,10,quark:iron_plate_slab:8,null,10,quark:iron_plate_stairs:7,null,10,quark:iron_plate_stairs:1,null,10,quark:iron_plate_slab:0,null,10,quark:iron_plate_stairs:4,null,10,quark:iron_plate_stairs:2,null,10,rustic:iron_lattice:1,null,50,rustic:iron_lattice:1,null,50,biomesoplenty:leaves_2:7,null,100)
Block(-4,8,-5,AIR:0)
Block(-4,8,-4,AIR:0)
RandomBlock(-4,8,-3,quark:iron_plate:1,null,70,STAINED_CLAY:15,null,30,STAINED_CLAY:7,null,30,quark:iron_plate:1,null,100)
Block(-4,8,2,COBBLESTONE_STAIRS:2)
Block(-4,8,3,COBBLESTONE_STAIRS:3)
Block(-4,9,-6,COBBLESTONE_STAIRS:2)
RandomBlock(-4,9,-5,quark:iron_plate:1,null,70,STAINED_CLAY:15,null,30,STAINED_CLAY:7,null,30,quark:iron_plate:1,null,100)
RandomBlock(-4,9,-4,quark:iron_plate:1,null,70,STAINED_CLAY:15,null,30,STAINED_CLAY:7,null,30,quark:iron_plate:1,null,100)
Block(-4,9,-3,COBBLESTONE_STAIRS:3)
Block(-3,6,-6,COBBLESTONE_STAIRS:6)
RandomBlock(-3,6,-5,quark:iron_plate:1,null,70,STAINED_CLAY:15,null,30,STAINED_CLAY:7,null,30,quark:iron_plate:1,null,100)
RandomBlock(-3,6,-4,quark:iron_plate:1,null,70,STAINED_CLAY:15,null,30,STAINED_CLAY:7,null,30,quark:iron_plate:1,null,100)
Block(-3,6,-3,COBBLESTONE_STAIRS:7)
RandomBlock(-3,7,-6,quark:iron_plate:1,null,70,STAINED_CLAY:15,null,30,STAINED_CLAY:7,null,30,quark:iron_plate:1,null,100)
Block(-3,7,-5,AIR:0)
Block(-3,7,-4,AIR:0)
RandomBlock(-3,7,-3,rustic:iron_lattice:1,null,30,rustic:iron_lattice:1,null,30,biomesoplenty:leaves_2:7,null,30,quark:iron_plate_stairs:6,null,10,quark:iron_plate_stairs:0,null,10,quark:iron_plate_stairs:5,null,10,quark:iron_plate_stairs:3,null,10,quark:iron_plate_slab:8,null,10,quark:iron_plate_stairs:7,null,10,quark:iron_plate_stairs:1,null,10,quark:iron_plate_slab:0,null,10,quark:iron_plate_stairs:4,null,10,quark:iron_plate_stairs:2,null,10,rustic:iron_lattice:1,null,50,rustic:iron_lattice:1,null,50,biomesoplenty:leaves_2:7,null,100)
Block(-3,7,2,COBBLESTONE_STAIRS:6)
Block(-3,7,3,COBBLESTONE_STAIRS:7)
RandomBlock(-3,8,-6,rustic:iron_lattice:1,null,30,rustic:iron_lattice:1,null,30,biomesoplenty:leaves_2:7,null,30,quark:iron_plate_stairs:6,null,10,quark:iron_plate_stairs:0,null,10,quark:iron_plate_stairs:5,null,10,quark:iron_plate_stairs:3,null,10,quark:iron_plate_slab:8,null,10,quark:iron_plate_stairs:7,null,10,quark:iron_plate_stairs:1,null,10,quark:iron_plate_slab:0,null,10,quark:iron_plate_stairs:4,null,10,quark:iron_plate_stairs:2,null,10,rustic:iron_lattice:1,null,50,rustic:iron_lattice:1,null,50,biomesoplenty:leaves_2:7,null,100)
Block(-3,8,-5,AIR:0)
Block(-3,8,-4,AIR:0)
RandomBlock(-3,8,-3,rustic:iron_lattice:1,null,30,rustic:iron_lattice:1,null,30,biomesoplenty:leaves_2:7,null,30,quark:iron_plate_stairs:6,null,10,quark:iron_plate_stairs:0,null,10,quark:iron_plate_stairs:5,null,10,quark:iron_plate_stairs:3,null,10,quark:iron_plate_slab:8,null,10,quark:iron_plate_stairs:7,null,10,quark:iron_plate_stairs:1,null,10,quark:iron_plate_slab:0,null,10,quark:iron_plate_stairs:4,null,10,quark:iron_plate_stairs:2,null,10,rustic:iron_lattice:1,null,50,rustic:iron_lattice:1,null,50,biomesoplenty:leaves_2:7,null,100)
Block(-3,8,2,COBBLESTONE_STAIRS:2)
Block(-3,8,3,COBBLESTONE_STAIRS:3)
Block(-3,9,-6,COBBLESTONE_STAIRS:2)
RandomBlock(-3,9,-5,quark:iron_plate:1,null,70,STAINED_CLAY:15,null,30,STAINED_CLAY:7,null,30,quark:iron_plate:1,null,100)
RandomBlock(-3,9,-4,rustic:iron_lattice:1,null,30,rustic:iron_lattice:1,null,30,biomesoplenty:leaves_2:7,null,30,quark:iron_plate_stairs:6,null,10,quark:iron_plate_stairs:0,null,10,quark:iron_plate_stairs:5,null,10,quark:iron_plate_stairs:3,null,10,quark:iron_plate_slab:8,null,10,quark:iron_plate_stairs:7,null,10,quark:iron_plate_stairs:1,null,10,quark:iron_plate_slab:0,null,10,quark:iron_plate_stairs:4,null,10,quark:iron_plate_stairs:2,null,10,rustic:iron_lattice:1,null,50,rustic:iron_lattice:1,null,50,biomesoplenty:leaves_2:7,null,100)
Block(-3,9,-3,COBBLESTONE_STAIRS:3)
Block(-2,0,0,quark:limestone:0)
Block(-2,0,1,quark:limestone:0)
Block(-2,0,2,quark:limestone:0)
Block(-2,0,3,quark:limestone:0)
Block(-2,0,4,quark:limestone:0)
Block(-2,0,5,quark:limestone:0)
Block(-2,1,0,COBBLESTONE_STAIRS:0)
Block(-2,1,1,COBBLESTONE_STAIRS:0)
Block(-2,1,2,COBBLESTONE_STAIRS:0)
Block(-2,1,3,COBBLESTONE_STAIRS:0)
Block(-2,1,4,COBBLESTONE_STAIRS:0)
Block(-2,1,5,COBBLESTONE_STAIRS:0)
Block(-2,6,-6,COBBLESTONE_STAIRS:6)
RandomBlock(-2,6,-5,quark:iron_plate:1,null,70,STAINED_CLAY:15,null,30,STAINED_CLAY:7,null,30,quark:iron_plate:1,null,100)
RandomBlock(-2,6,-4,quark:iron_plate:1,null,70,STAINED_CLAY:15,null,30,STAINED_CLAY:7,null,30,quark:iron_plate:1,null,100)
Block(-2,6,-3,COBBLESTONE_STAIRS:7)
RandomBlock(-2,7,-6,quark:iron_plate:1,null,70,STAINED_CLAY:15,null,30,STAINED_CLAY:7,null,30,quark:iron_plate:1,null,100)
Block(-2,7,-5,AIR:0)
Block(-2,7,-4,AIR:0)
RandomBlock(-2,7,-3,rustic:iron_lattice:1,null,30,rustic:iron_lattice:1,null,30,biomesoplenty:leaves_2:7,null,30,quark:iron_plate_stairs:6,null,10,quark:iron_plate_stairs:0,null,10,quark:iron_plate_stairs:5,null,10,quark:iron_plate_stairs:3,null,10,quark:iron_plate_slab:8,null,10,quark:iron_plate_stairs:7,null,10,quark:iron_plate_stairs:1,null,10,quark:iron_plate_slab:0,null,10,quark:iron_plate_stairs:4,null,10,quark:iron_plate_stairs:2,null,10,rustic:iron_lattice:1,null,50,rustic:iron_lattice:1,null,50,biomesoplenty:leaves_2:7,null,100)
Block(-2,7,2,COBBLESTONE_STAIRS:6)
Block(-2,7,3,COBBLESTONE_STAIRS:7)
RandomBlock(-2,8,-6,quark:iron_plate:1,null,70,STAINED_CLAY:15,null,30,STAINED_CLAY:7,null,30,quark:iron_plate:1,null,100)
Block(-2,8,-5,AIR:0)
Block(-2,8,-4,AIR:0)
RandomBlock(-2,8,-3,quark:iron_plate:1,null,70,STAINED_CLAY:15,null,30,STAINED_CLAY:7,null,30,quark:iron_plate:1,null,100)
Block(-2,8,2,COBBLESTONE_STAIRS:2)
Block(-2,8,3,COBBLESTONE_STAIRS:3)
Block(-2,9,-6,COBBLESTONE_STAIRS:2)
RandomBlock(-2,9,-5,rustic:iron_lattice:1,null,30,rustic:iron_lattice:1,null,30,biomesoplenty:leaves_2:7,null,30,quark:iron_plate_stairs:6,null,10,quark:iron_plate_stairs:0,null,10,quark:iron_plate_stairs:5,null,10,quark:iron_plate_stairs:3,null,10,quark:iron_plate_slab:8,null,10,quark:iron_plate_stairs:7,null,10,quark:iron_plate_stairs:1,null,10,quark:iron_plate_slab:0,null,10,quark:iron_plate_stairs:4,null,10,quark:iron_plate_stairs:2,null,10,rustic:iron_lattice:1,null,50,rustic:iron_lattice:1,null,50,biomesoplenty:leaves_2:7,null,100)
RandomBlock(-2,9,-4,rustic:iron_lattice:1,null,30,rustic:iron_lattice:1,null,30,biomesoplenty:leaves_2:7,null,30,quark:iron_plate_stairs:6,null,10,quark:iron_plate_stairs:0,null,10,quark:iron_plate_stairs:5,null,10,quark:iron_plate_stairs:3,null,10,quark:iron_plate_slab:8,null,10,quark:iron_plate_stairs:7,null,10,quark:iron_plate_stairs:1,null,10,quark:iron_plate_slab:0,null,10,quark:iron_plate_stairs:4,null,10,quark:iron_plate_stairs:2,null,10,rustic:iron_lattice:1,null,50,rustic:iron_lattice:1,null,50,biomesoplenty:leaves_2:7,null,100)
Block(-2,9,-3,COBBLESTONE_STAIRS:3)
Block(-1,0,-5,quark:limestone:0)
Block(-1,0,-4,quark:limestone:0)
Block(-1,0,0,quark:limestone:0)
RandomBlock(-1,0,1,quark:iron_plate:1,null,70,STAINED_CLAY:15,null,30,STAINED_CLAY:7,null,30,quark:iron_plate:1,null,100)
RandomBlock(-1,0,2,quark:iron_plate:1,null,70,STAINED_CLAY:15,null,30,STAINED_CLAY:7,null,30,quark:iron_plate:1,null,100)
RandomBlock(-1,0,3,quark:iron_plate:1,null,70,STAINED_CLAY:15,null,30,STAINED_CLAY:7,null,30,quark:iron_plate:1,null,100)
RandomBlock(-1,0,4,quark:iron_plate:1,null,70,STAINED_CLAY:15,null,30,STAINED_CLAY:7,null,30,quark:iron_plate:1,null,100)
Block(-1,0,5,quark:limestone:0)
Block(-1,1,-5,quark:basalt_wall:0)
Block(-1,1,-4,quark:basalt_wall:0)
Block(-1,1,0,COBBLESTONE_STAIRS:2)
RandomBlock(-1,1,1,quark:iron_plate:1,null,70,STAINED_CLAY:15,null,30,STAINED_CLAY:7,null,30,quark:iron_plate:1,null,100)
RandomBlock(-1,1,2,quark:iron_plate:1,null,70,STAINED_CLAY:15,null,30,STAINED_CLAY:7,null,30,quark:iron_plate:1,null,100)
RandomBlock(-1,1,3,rustic:iron_lattice:1,null,30,rustic:iron_lattice:1,null,30,biomesoplenty:leaves_2:7,null,30,quark:iron_plate_stairs:6,null,10,quark:iron_plate_stairs:0,null,10,quark:iron_plate_stairs:5,null,10,quark:iron_plate_stairs:3,null,10,quark:iron_plate_slab:8,null,10,quark:iron_plate_stairs:7,null,10,quark:iron_plate_stairs:1,null,10,quark:iron_plate_slab:0,null,10,quark:iron_plate_stairs:4,null,10,quark:iron_plate_stairs:2,null,10,rustic:iron_lattice:1,null,50,rustic:iron_lattice:1,null,50,biomesoplenty:leaves_2:7,null,100)
RandomBlock(-1,1,4,rustic:iron_lattice:1,null,30,rustic:iron_lattice:1,null,30,biomesoplenty:leaves_2:7,null,30,quark:iron_plate_stairs:6,null,10,quark:iron_plate_stairs:0,null,10,quark:iron_plate_stairs:5,null,10,quark:iron_plate_stairs:3,null,10,quark:iron_plate_slab:8,null,10,quark:iron_plate_stairs:7,null,10,quark:iron_plate_stairs:1,null,10,quark:iron_plate_slab:0,null,10,quark:iron_plate_stairs:4,null,10,quark:iron_plate_stairs:2,null,10,rustic:iron_lattice:1,null,50,rustic:iron_lattice:1,null,50,biomesoplenty:leaves_2:7,null,100)
Block(-1,1,5,COBBLESTONE_STAIRS:3)
Block(-1,2,-5,quark:basalt_wall:0)
Block(-1,2,-4,quark:basalt_wall:0)
RandomBlock(-1,2,1,quark:iron_plate:1,null,70,STAINED_CLAY:15,null,30,STAINED_CLAY:7,null,30,quark:iron_plate:1,null,100)
RandomBlock(-1,2,2,rustic:iron_lattice:1,null,30,rustic:iron_lattice:1,null,30,biomesoplenty:leaves_2:7,null,30,quark:iron_plate_stairs:6,null,10,quark:iron_plate_stairs:0,null,10,quark:iron_plate_stairs:5,null,10,quark:iron_plate_stairs:3,null,10,quark:iron_plate_slab:8,null,10,quark:iron_plate_stairs:7,null,10,quark:iron_plate_stairs:1,null,10,quark:iron_plate_slab:0,null,10,quark:iron_plate_stairs:4,null,10,quark:iron_plate_stairs:2,null,10,rustic:iron_lattice:1,null,50,rustic:iron_lattice:1,null,50,biomesoplenty:leaves_2:7,null,100)
RandomBlock(-1,2,3,rustic:iron_lattice:1,null,30,rustic:iron_lattice:1,null,30,biomesoplenty:leaves_2:7,null,30,quark:iron_plate_stairs:6,null,10,quark:iron_plate_stairs:0,null,10,quark:iron_plate_stairs:5,null,10,quark:iron_plate_stairs:3,null,10,quark:iron_plate_slab:8,null,10,quark:iron_plate_stairs:7,null,10,quark:iron_plate_stairs:1,null,10,quark:iron_plate_slab:0,null,10,quark:iron_plate_stairs:4,null,10,quark:iron_plate_stairs:2,null,10,rustic:iron_lattice:1,null,50,rustic:iron_lattice:1,null,50,biomesoplenty:leaves_2:7,null,100)
RandomBlock(-1,2,4,rustic:iron_lattice:1,null,30,rustic:iron_lattice:1,null,30,biomesoplenty:leaves_2:7,null,30,quark:iron_plate_stairs:6,null,10,quark:iron_plate_stairs:0,null,10,quark:iron_plate_stairs:5,null,10,quark:iron_plate_stairs:3,null,10,quark:iron_plate_slab:8,null,10,quark:iron_plate_stairs:7,null,10,quark:iron_plate_stairs:1,null,10,quark:iron_plate_slab:0,null,10,quark:iron_plate_stairs:4,null,10,quark:iron_plate_stairs:2,null,10,rustic:iron_lattice:1,null,50,rustic:iron_lattice:1,null,50,biomesoplenty:leaves_2:7,null,100)
Block(-1,3,-5,quark:basalt_wall:0)
Block(-1,3,-4,quark:basalt_wall:0)
RandomBlock(-1,3,1,rustic:iron_lattice:1,null,30,rustic:iron_lattice:1,null,30,biomesoplenty:leaves_2:7,null,30,quark:iron_plate_stairs:6,null,10,quark:iron_plate_stairs:0,null,10,quark:iron_plate_stairs:5,null,10,quark:iron_plate_stairs:3,null,10,quark:iron_plate_slab:8,null,10,quark:iron_plate_stairs:7,null,10,quark:iron_plate_stairs:1,null,10,quark:iron_plate_slab:0,null,10,quark:iron_plate_stairs:4,null,10,quark:iron_plate_stairs:2,null,10,rustic:iron_lattice:1,null,50,rustic:iron_lattice:1,null,50,biomesoplenty:leaves_2:7,null,100)
RandomBlock(-1,3,2,rustic:iron_lattice:1,null,30,rustic:iron_lattice:1,null,30,biomesoplenty:leaves_2:7,null,30,quark:iron_plate_stairs:6,null,10,quark:iron_plate_stairs:0,null,10,quark:iron_plate_stairs:5,null,10,quark:iron_plate_stairs:3,null,10,quark:iron_plate_slab:8,null,10,quark:iron_plate_stairs:7,null,10,quark:iron_plate_stairs:1,null,10,quark:iron_plate_slab:0,null,10,quark:iron_plate_stairs:4,null,10,quark:iron_plate_stairs:2,null,10,rustic:iron_lattice:1,null,50,rustic:iron_lattice:1,null,50,biomesoplenty:leaves_2:7,null,100)
RandomBlock(-1,3,3,rustic:iron_lattice:1,null,30,rustic:iron_lattice:1,null,30,biomesoplenty:leaves_2:7,null,30,quark:iron_plate_stairs:6,null,10,quark:iron_plate_stairs:0,null,10,quark:iron_plate_stairs:5,null,10,quark:iron_plate_stairs:3,null,10,quark:iron_plate_slab:8,null,10,quark:iron_plate_stairs:7,null,10,quark:iron_plate_stairs:1,null,10,quark:iron_plate_slab:0,null,10,quark:iron_plate_stairs:4,null,10,quark:iron_plate_stairs:2,null,10,rustic:iron_lattice:1,null,50,rustic:iron_lattice:1,null,50,biomesoplenty:leaves_2:7,null,100)
RandomBlock(-1,3,4,rustic:iron_lattice:1,null,30,rustic:iron_lattice:1,null,30,biomesoplenty:leaves_2:7,null,30,quark:iron_plate_stairs:6,null,10,quark:iron_plate_stairs:0,null,10,quark:iron_plate_stairs:5,null,10,quark:iron_plate_stairs:3,null,10,quark:iron_plate_slab:8,null,10,quark:iron_plate_stairs:7,null,10,quark:iron_plate_stairs:1,null,10,quark:iron_plate_slab:0,null,10,quark:iron_plate_stairs:4,null,10,quark:iron_plate_stairs:2,null,10,rustic:iron_lattice:1,null,50,rustic:iron_lattice:1,null,50,biomesoplenty:leaves_2:7,null,100)
Block(-1,4,-5,quark:basalt_wall:0)
Block(-1,4,-4,quark:basalt_wall:0)
RandomBlock(-1,4,1,quark:iron_plate:1,null,70,STAINED_CLAY:15,null,30,STAINED_CLAY:7,null,30,quark:iron_plate:1,null,100)
RandomBlock(-1,4,2,rustic:iron_lattice:1,null,30,rustic:iron_lattice:1,null,30,biomesoplenty:leaves_2:7,null,30,quark:iron_plate_stairs:6,null,10,quark:iron_plate_stairs:0,null,10,quark:iron_plate_stairs:5,null,10,quark:iron_plate_stairs:3,null,10,quark:iron_plate_slab:8,null,10,quark:iron_plate_stairs:7,null,10,quark:iron_plate_stairs:1,null,10,quark:iron_plate_slab:0,null,10,quark:iron_plate_stairs:4,null,10,quark:iron_plate_stairs:2,null,10,rustic:iron_lattice:1,null,50,rustic:iron_lattice:1,null,50,biomesoplenty:leaves_2:7,null,100)
RandomBlock(-1,4,3,quark:iron_plate:1,null,70,STAINED_CLAY:15,null,30,STAINED_CLAY:7,null,30,quark:iron_plate:1,null,100)
RandomBlock(-1,4,4,quark:iron_plate:1,null,70,STAINED_CLAY:15,null,30,STAINED_CLAY:7,null,30,quark:iron_plate:1,null,100)
Block(-1,5,-5,quark:basalt_wall:0)
Block(-1,5,-4,quark:basalt_wall:0)
RandomBlock(-1,5,1,rustic:iron_lattice:1,null,30,rustic:iron_lattice:1,null,30,biomesoplenty:leaves_2:7,null,30,quark:iron_plate_stairs:6,null,10,quark:iron_plate_stairs:0,null,10,quark:iron_plate_stairs:5,null,10,quark:iron_plate_stairs:3,null,10,quark:iron_plate_slab:8,null,10,quark:iron_plate_stairs:7,null,10,quark:iron_plate_stairs:1,null,10,quark:iron_plate_slab:0,null,10,quark:iron_plate_stairs:4,null,10,quark:iron_plate_stairs:2,null,10,rustic:iron_lattice:1,null,50,rustic:iron_lattice:1,null,50,biomesoplenty:leaves_2:7,null,100)
RandomBlock(-1,5,2,quark:iron_plate:1,null,70,STAINED_CLAY:15,null,30,STAINED_CLAY:7,null,30,quark:iron_plate:1,null,100)
RandomBlock(-1,5,3,quark:iron_plate:1,null,70,STAINED_CLAY:15,null,30,STAINED_CLAY:7,null,30,quark:iron_plate:1,null,100)
RandomBlock(-1,5,4,quark:iron_plate:1,null,70,STAINED_CLAY:15,null,30,STAINED_CLAY:7,null,30,quark:iron_plate:1,null,100)
Block(-1,6,-6,COBBLESTONE_STAIRS:6)
RandomBlock(-1,6,-5,quark:iron_plate:1,null,70,STAINED_CLAY:15,null,30,STAINED_CLAY:7,null,30,quark:iron_plate:1,null,100)
RandomBlock(-1,6,-4,quark:iron_plate:1,null,70,STAINED_CLAY:15,null,30,STAINED_CLAY:7,null,30,quark:iron_plate:1,null,100)
Block(-1,6,-3,COBBLESTONE_STAIRS:7)
Block(-1,6,-2,COBBLESTONE_STAIRS:4)
Block(-1,6,-1,COBBLESTONE_STAIRS:4)
Block(-1,6,0,COBBLESTONE_STAIRS:4)
RandomBlock(-1,6,1,rustic:iron_lattice:1,null,30,rustic:iron_lattice:1,null,30,biomesoplenty:leaves_2:7,null,30,quark:iron_plate_stairs:6,null,10,quark:iron_plate_stairs:0,null,10,quark:iron_plate_stairs:5,null,10,quark:iron_plate_stairs:3,null,10,quark:iron_plate_slab:8,null,10,quark:iron_plate_stairs:7,null,10,quark:iron_plate_stairs:1,null,10,quark:iron_plate_slab:0,null,10,quark:iron_plate_stairs:4,null,10,quark:iron_plate_stairs:2,null,10,rustic:iron_lattice:1,null,50,rustic:iron_lattice:1,null,50,biomesoplenty:leaves_2:7,null,100)
RandomBlock(-1,6,2,quark:iron_plate:1,null,70,STAINED_CLAY:15,null,30,STAINED_CLAY:7,null,30,quark:iron_plate:1,null,100)
RandomBlock(-1,6,3,quark:iron_plate:1,null,70,STAINED_CLAY:15,null,30,STAINED_CLAY:7,null,30,quark:iron_plate:1,null,100)
RandomBlock(-1,6,4,quark:iron_plate:1,null,70,STAINED_CLAY:15,null,30,STAINED_CLAY:7,null,30,quark:iron_plate:1,null,100)
RandomBlock(-1,7,-6,quark:iron_plate:1,null,70,STAINED_CLAY:15,null,30,STAINED_CLAY:7,null,30,quark:iron_plate:1,null,100)
Block(-1,7,-5,AIR:0)
Block(-1,7,-4,AIR:0)
RandomBlock(-1,7,-3,quark:iron_plate:1,null,70,STAINED_CLAY:15,null,30,STAINED_CLAY:7,null,30,quark:iron_plate:1,null,100)
RandomBlock(-1,7,-2,quark:iron_plate:1,null,70,STAINED_CLAY:15,null,30,STAINED_CLAY:7,null,30,quark:iron_plate:1,null,100)
RandomBlock(-1,7,-1,quark:iron_plate:1,null,70,STAINED_CLAY:15,null,30,STAINED_CLAY:7,null,30,quark:iron_plate:1,null,100)
RandomBlock(-1,7,0,rustic:iron_lattice:1,null,30,rustic:iron_lattice:1,null,30,biomesoplenty:leaves_2:7,null,30,quark:iron_plate_stairs:6,null,10,quark:iron_plate_stairs:0,null,10,quark:iron_plate_stairs:5,null,10,quark:iron_plate_stairs:3,null,10,quark:iron_plate_slab:8,null,10,quark:iron_plate_stairs:7,null,10,quark:iron_plate_stairs:1,null,10,quark:iron_plate_slab:0,null,10,quark:iron_plate_stairs:4,null,10,quark:iron_plate_stairs:2,null,10,rustic:iron_lattice:1,null,50,rustic:iron_lattice:1,null,50,biomesoplenty:leaves_2:7,null,100)
RandomBlock(-1,7,1,rustic:iron_lattice:1,null,30,rustic:iron_lattice:1,null,30,biomesoplenty:leaves_2:7,null,30,quark:iron_plate_stairs:6,null,10,quark:iron_plate_stairs:0,null,10,quark:iron_plate_stairs:5,null,10,quark:iron_plate_stairs:3,null,10,quark:iron_plate_slab:8,null,10,quark:iron_plate_stairs:7,null,10,quark:iron_plate_stairs:1,null,10,quark:iron_plate_slab:0,null,10,quark:iron_plate_stairs:4,null,10,quark:iron_plate_stairs:2,null,10,rustic:iron_lattice:1,null,50,rustic:iron_lattice:1,null,50,biomesoplenty:leaves_2:7,null,100)
RandomBlock(-1,7,2,quark:iron_plate:1,null,70,STAINED_CLAY:15,null,30,STAINED_CLAY:7,null,30,quark:iron_plate:1,null,100)
RandomBlock(-1,7,3,quark:iron_plate:1,null,70,STAINED_CLAY:15,null,30,STAINED_CLAY:7,null,30,quark:iron_plate:1,null,100)
RandomBlock(-1,7,4,quark:iron_plate:1,null,70,STAINED_CLAY:15,null,30,STAINED_CLAY:7,null,30,quark:iron_plate:1,null,100)
RandomBlock(-1,8,-6,quark:iron_plate:1,null,70,STAINED_CLAY:15,null,30,STAINED_CLAY:7,null,30,quark:iron_plate:1,null,100)
Block(-1,8,-5,AIR:0)
Block(-1,8,-4,AIR:0)
RandomBlock(-1,8,-3,quark:iron_plate:1,null,70,STAINED_CLAY:15,null,30,STAINED_CLAY:7,null,30,quark:iron_plate:1,null,100)
RandomBlock(-1,8,-2,quark:iron_plate:1,null,70,STAINED_CLAY:15,null,30,STAINED_CLAY:7,null,30,quark:iron_plate:1,null,100)
RandomBlock(-1,8,-1,rustic:iron_lattice:1,null,30,rustic:iron_lattice:1,null,30,biomesoplenty:leaves_2:7,null,30,quark:iron_plate_stairs:6,null,10,quark:iron_plate_stairs:0,null,10,quark:iron_plate_stairs:5,null,10,quark:iron_plate_stairs:3,null,10,quark:iron_plate_slab:8,null,10,quark:iron_plate_stairs:7,null,10,quark:iron_plate_stairs:1,null,10,quark:iron_plate_slab:0,null,10,quark:iron_plate_stairs:4,null,10,quark:iron_plate_stairs:2,null,10,rustic:iron_lattice:1,null,50,rustic:iron_lattice:1,null,50,biomesoplenty:leaves_2:7,null,100)
RandomBlock(-1,8,0,rustic:iron_lattice:1,null,30,rustic:iron_lattice:1,null,30,biomesoplenty:leaves_2:7,null,30,quark:iron_plate_stairs:6,null,10,quark:iron_plate_stairs:0,null,10,quark:iron_plate_stairs:5,null,10,quark:iron_plate_stairs:3,null,10,quark:iron_plate_slab:8,null,10,quark:iron_plate_stairs:7,null,10,quark:iron_plate_stairs:1,null,10,quark:iron_plate_slab:0,null,10,quark:iron_plate_stairs:4,null,10,quark:iron_plate_stairs:2,null,10,rustic:iron_lattice:1,null,50,rustic:iron_lattice:1,null,50,biomesoplenty:leaves_2:7,null,100)
RandomBlock(-1,8,1,rustic:iron_lattice:1,null,30,rustic:iron_lattice:1,null,30,biomesoplenty:leaves_2:7,null,30,quark:iron_plate_stairs:6,null,10,quark:iron_plate_stairs:0,null,10,quark:iron_plate_stairs:5,null,10,quark:iron_plate_stairs:3,null,10,quark:iron_plate_slab:8,null,10,quark:iron_plate_stairs:7,null,10,quark:iron_plate_stairs:1,null,10,quark:iron_plate_slab:0,null,10,quark:iron_plate_stairs:4,null,10,quark:iron_plate_stairs:2,null,10,rustic:iron_lattice:1,null,50,rustic:iron_lattice:1,null,50,biomesoplenty:leaves_2:7,null,100)
RandomBlock(-1,8,2,quark:iron_plate:1,null,70,STAINED_CLAY:15,null,30,STAINED_CLAY:7,null,30,quark:iron_plate:1,null,100)
RandomBlock(-1,8,3,quark:iron_plate:1,null,70,STAINED_CLAY:15,null,30,STAINED_CLAY:7,null,30,quark:iron_plate:1,null,100)
RandomBlock(-1,8,4,quark:iron_plate:1,null,70,STAINED_CLAY:15,null,30,STAINED_CLAY:7,null,30,quark:iron_plate:1,null,100)
Block(-1,9,-6,COBBLESTONE_STAIRS:2)
RandomBlock(-1,9,-5,quark:iron_plate:1,null,70,STAINED_CLAY:15,null,30,STAINED_CLAY:7,null,30,quark:iron_plate:1,null,100)
RandomBlock(-1,9,-4,rustic:iron_lattice:1,null,30,rustic:iron_lattice:1,null,30,biomesoplenty:leaves_2:7,null,30,quark:iron_plate_stairs:6,null,10,quark:iron_plate_stairs:0,null,10,quark:iron_plate_stairs:5,null,10,quark:iron_plate_stairs:3,null,10,quark:iron_plate_slab:8,null,10,quark:iron_plate_stairs:7,null,10,quark:iron_plate_stairs:1,null,10,quark:iron_plate_slab:0,null,10,quark:iron_plate_stairs:4,null,10,quark:iron_plate_stairs:2,null,10,rustic:iron_lattice:1,null,50,rustic:iron_lattice:1,null,50,biomesoplenty:leaves_2:7,null,100)
Block(-1,9,-3,COBBLESTONE_STAIRS:3)
Block(-1,9,-2,COBBLESTONE_STAIRS:0)
Block(-1,9,-1,COBBLESTONE_STAIRS:0)
Block(-1,9,0,COBBLESTONE_STAIRS:0)
RandomBlock(-1,9,1,quark:iron_plate:1,null,70,STAINED_CLAY:15,null,30,STAINED_CLAY:7,null,30,quark:iron_plate:1,null,100)
RandomBlock(-1,9,2,quark:iron_plate:1,null,70,STAINED_CLAY:15,null,30,STAINED_CLAY:7,null,30,quark:iron_plate:1,null,100)
RandomBlock(-1,9,3,quark:iron_plate:1,null,70,STAINED_CLAY:15,null,30,STAINED_CLAY:7,null,30,quark:iron_plate:1,null,100)
RandomBlock(-1,9,4,quark:iron_plate:1,null,70,STAINED_CLAY:15,null,30,STAINED_CLAY:7,null,30,quark:iron_plate:1,null,100)
Block(-1,10,1,rustic:iron_lattice:0)
Block(-1,10,2,rustic:iron_lattice:0)
Block(-1,10,3,rustic:iron_lattice:0)
Block(-1,10,4,rustic:iron_lattice:0)
Block(0,0,0,quark:limestone:0)
RandomBlock(0,0,1,quark:iron_plate:1,null,70,STAINED_CLAY:15,null,30,STAINED_CLAY:7,null,30,quark:iron_plate:1,null,100)
Block(0,0,2,AIR:0)
Block(0,0,3,AIR:0)
RandomBlock(0,0,4,quark:iron_plate:1,null,70,STAINED_CLAY:15,null,30,STAINED_CLAY:7,null,30,quark:iron_plate:1,null,100)
Block(0,0,5,quark:limestone:0)
Block(0,1,0,COBBLESTONE_STAIRS:2)
RandomBlock(0,1,1,quark:iron_plate:1,null,70,STAINED_CLAY:15,null,30,STAINED_CLAY:7,null,30,quark:iron_plate:1,null,100)
Block(0,1,2,AIR:0)
Block(0,1,3,AIR:0)
RandomBlock(0,1,4,quark:iron_plate:1,null,70,STAINED_CLAY:15,null,30,STAINED_CLAY:7,null,30,quark:iron_plate:1,null,100)
Block(0,1,5,COBBLESTONE_STAIRS:3)
RandomBlock(0,2,1,quark:iron_plate:1,null,70,STAINED_CLAY:15,null,30,STAINED_CLAY:7,null,30,quark:iron_plate:1,null,100)
Block(0,2,2,AIR:0)
Block(0,2,3,AIR:0)
RandomBlock(0,2,4,rustic:iron_lattice:1,null,30,rustic:iron_lattice:1,null,30,biomesoplenty:leaves_2:7,null,30,quark:iron_plate_stairs:6,null,10,quark:iron_plate_stairs:0,null,10,quark:iron_plate_stairs:5,null,10,quark:iron_plate_stairs:3,null,10,quark:iron_plate_slab:8,null,10,quark:iron_plate_stairs:7,null,10,quark:iron_plate_stairs:1,null,10,quark:iron_plate_slab:0,null,10,quark:iron_plate_stairs:4,null,10,quark:iron_plate_stairs:2,null,10,rustic:iron_lattice:1,null,50,rustic:iron_lattice:1,null,50,biomesoplenty:leaves_2:7,null,100)
RandomBlock(0,3,1,quark:iron_plate:1,null,70,STAINED_CLAY:15,null,30,STAINED_CLAY:7,null,30,quark:iron_plate:1,null,100)
Block(0,3,2,AIR:0)
Block(0,3,3,AIR:0)
RandomBlock(0,3,4,quark:iron_plate:1,null,70,STAINED_CLAY:15,null,30,STAINED_CLAY:7,null,30,quark:iron_plate:1,null,100)
RandomBlock(0,4,1,quark:iron_plate:1,null,70,STAINED_CLAY:15,null,30,STAINED_CLAY:7,null,30,quark:iron_plate:1,null,100)
Block(0,4,2,AIR:0)
Block(0,4,3,AIR:0)
RandomBlock(0,4,4,quark:iron_plate:1,null,70,STAINED_CLAY:15,null,30,STAINED_CLAY:7,null,30,quark:iron_plate:1,null,100)
RandomBlock(0,5,1,quark:iron_plate:1,null,70,STAINED_CLAY:15,null,30,STAINED_CLAY:7,null,30,quark:iron_plate:1,null,100)
Block(0,5,2,AIR:0)
Block(0,5,3,AIR:0)
RandomBlock(0,5,4,quark:iron_plate:1,null,70,STAINED_CLAY:15,null,30,STAINED_CLAY:7,null,30,quark:iron_plate:1,null,100)
Block(0,6,-6,COBBLESTONE_STAIRS:6)
RandomBlock(0,6,-5,quark:iron_plate:1,null,70,STAINED_CLAY:15,null,30,STAINED_CLAY:7,null,30,quark:iron_plate:1,null,100)
RandomBlock(0,6,-4,quark:iron_plate:1,null,70,STAINED_CLAY:15,null,30,STAINED_CLAY:7,null,30,quark:iron_plate:1,null,100)
RandomBlock(0,6,-3,quark:iron_plate:1,null,70,STAINED_CLAY:15,null,30,STAINED_CLAY:7,null,30,quark:iron_plate:1,null,100)
RandomBlock(0,6,-2,quark:iron_plate:1,null,70,STAINED_CLAY:15,null,30,STAINED_CLAY:7,null,30,quark:iron_plate:1,null,100)
RandomBlock(0,6,-1,quark:iron_plate:1,null,70,STAINED_CLAY:15,null,30,STAINED_CLAY:7,null,30,quark:iron_plate:1,null,100)
RandomBlock(0,6,0,quark:iron_plate:1,null,70,STAINED_CLAY:15,null,30,STAINED_CLAY:7,null,30,quark:iron_plate:1,null,100)
RandomBlock(0,6,1,rustic:iron_lattice:1,null,30,rustic:iron_lattice:1,null,30,biomesoplenty:leaves_2:7,null,30,quark:iron_plate_stairs:6,null,10,quark:iron_plate_stairs:0,null,10,quark:iron_plate_stairs:5,null,10,quark:iron_plate_stairs:3,null,10,quark:iron_plate_slab:8,null,10,quark:iron_plate_stairs:7,null,10,quark:iron_plate_stairs:1,null,10,quark:iron_plate_slab:0,null,10,quark:iron_plate_stairs:4,null,10,quark:iron_plate_stairs:2,null,10,rustic:iron_lattice:1,null,50,rustic:iron_lattice:1,null,50,biomesoplenty:leaves_2:7,null,100)
Block(0,6,2,AIR:0)
Block(0,6,3,AIR:0)
RandomBlock(0,6,4,quark:iron_plate:1,null,70,STAINED_CLAY:15,null,30,STAINED_CLAY:7,null,30,quark:iron_plate:1,null,100)
RandomBlock(0,7,-6,rustic:iron_lattice:1,null,30,rustic:iron_lattice:1,null,30,biomesoplenty:leaves_2:7,null,30,quark:iron_plate_stairs:6,null,10,quark:iron_plate_stairs:0,null,10,quark:iron_plate_stairs:5,null,10,quark:iron_plate_stairs:3,null,10,quark:iron_plate_slab:8,null,10,quark:iron_plate_stairs:7,null,10,quark:iron_plate_stairs:1,null,10,quark:iron_plate_slab:0,null,10,quark:iron_plate_stairs:4,null,10,quark:iron_plate_stairs:2,null,10,rustic:iron_lattice:1,null,50,rustic:iron_lattice:1,null,50,biomesoplenty:leaves_2:7,null,100)
Block(0,7,-5,AIR:0)
Block(0,7,-4,AIR:0)
Block(0,7,-3,AIR:0)
Block(0,7,-2,AIR:0)
Block(0,7,-1,AIR:0)
Block(0,7,0,AIR:0)
Block(0,7,1,AIR:0)
Block(0,7,2,AIR:0)
Block(0,7,3,AIR:0)
RandomBlock(0,7,4,quark:iron_plate:1,null,70,STAINED_CLAY:15,null,30,STAINED_CLAY:7,null,30,quark:iron_plate:1,null,100)
RandomBlock(0,8,-6,quark:iron_plate:1,null,70,STAINED_CLAY:15,null,30,STAINED_CLAY:7,null,30,quark:iron_plate:1,null,100)
Block(0,8,-5,AIR:0)
Block(0,8,-4,AIR:0)
Block(0,8,-3,AIR:0)
Block(0,8,-2,AIR:0)
Block(0,8,-1,AIR:0)
Block(0,8,0,AIR:0)
Block(0,8,1,AIR:0)
Block(0,8,2,AIR:0)
Block(0,8,3,AIR:0)
RandomBlock(0,8,4,quark:iron_plate:1,null,70,STAINED_CLAY:15,null,30,STAINED_CLAY:7,null,30,quark:iron_plate:1,null,100)
Block(0,9,-6,COBBLESTONE_STAIRS:2)
RandomBlock(0,9,-5,quark:iron_plate:1,null,70,STAINED_CLAY:15,null,30,STAINED_CLAY:7,null,30,quark:iron_plate:1,null,100)
RandomBlock(0,9,-4,rustic:iron_lattice:1,null,30,rustic:iron_lattice:1,null,30,biomesoplenty:leaves_2:7,null,30,quark:iron_plate_stairs:6,null,10,quark:iron_plate_stairs:0,null,10,quark:iron_plate_stairs:5,null,10,quark:iron_plate_stairs:3,null,10,quark:iron_plate_slab:8,null,10,quark:iron_plate_stairs:7,null,10,quark:iron_plate_stairs:1,null,10,quark:iron_plate_slab:0,null,10,quark:iron_plate_stairs:4,null,10,quark:iron_plate_stairs:2,null,10,rustic:iron_lattice:1,null,50,rustic:iron_lattice:1,null,50,biomesoplenty:leaves_2:7,null,100)
RandomBlock(0,9,-3,rustic:iron_lattice:1,null,30,rustic:iron_lattice:1,null,30,biomesoplenty:leaves_2:7,null,30,quark:iron_plate_stairs:6,null,10,quark:iron_plate_stairs:0,null,10,quark:iron_plate_stairs:5,null,10,quark:iron_plate_stairs:3,null,10,quark:iron_plate_slab:8,null,10,quark:iron_plate_stairs:7,null,10,quark:iron_plate_stairs:1,null,10,quark:iron_plate_slab:0,null,10,quark:iron_plate_stairs:4,null,10,quark:iron_plate_stairs:2,null,10,rustic:iron_lattice:1,null,50,rustic:iron_lattice:1,null,50,biomesoplenty:leaves_2:7,null,100)
RandomBlock(0,9,-2,rustic:iron_lattice:1,null,30,rustic:iron_lattice:1,null,30,biomesoplenty:leaves_2:7,null,30,quark:iron_plate_stairs:6,null,10,quark:iron_plate_stairs:0,null,10,quark:iron_plate_stairs:5,null,10,quark:iron_plate_stairs:3,null,10,quark:iron_plate_slab:8,null,10,quark:iron_plate_stairs:7,null,10,quark:iron_plate_stairs:1,null,10,quark:iron_plate_slab:0,null,10,quark:iron_plate_stairs:4,null,10,quark:iron_plate_stairs:2,null,10,rustic:iron_lattice:1,null,50,rustic:iron_lattice:1,null,50,biomesoplenty:leaves_2:7,null,100)
RandomBlock(0,9,-1,quark:iron_plate:1,null,70,STAINED_CLAY:15,null,30,STAINED_CLAY:7,null,30,quark:iron_plate:1,null,100)
RandomBlock(0,9,0,quark:iron_plate:1,null,70,STAINED_CLAY:15,null,30,STAINED_CLAY:7,null,30,quark:iron_plate:1,null,100)
RandomBlock(0,9,1,quark:iron_plate:1,null,70,STAINED_CLAY:15,null,30,STAINED_CLAY:7,null,30,quark:iron_plate:1,null,100)
RandomBlock(0,9,2,quark:iron_plate:1,null,70,STAINED_CLAY:15,null,30,STAINED_CLAY:7,null,30,quark:iron_plate:1,null,100)
RandomBlock(0,9,3,quark:iron_plate:1,null,70,STAINED_CLAY:15,null,30,STAINED_CLAY:7,null,30,quark:iron_plate:1,null,100)
RandomBlock(0,9,4,quark:iron_plate:1,null,70,STAINED_CLAY:15,null,30,STAINED_CLAY:7,null,30,quark:iron_plate:1,null,100)
Block(0,10,1,rustic:iron_lattice:0)
Block(0,10,2,COBBLESTONE_STAIRS:0)
Block(0,10,3,COBBLESTONE_STAIRS:3)
Block(0,10,4,rustic:iron_lattice:0)
Block(1,0,0,quark:limestone:0)
RandomBlock(1,0,1,quark:iron_plate:1,null,70,STAINED_CLAY:15,null,30,STAINED_CLAY:7,null,30,quark:iron_plate:1,null,100)
Block(1,0,2,AIR:0)
Block(1,0,3,AIR:0)
RandomBlock(1,0,4,quark:iron_plate:1,null,70,STAINED_CLAY:15,null,30,STAINED_CLAY:7,null,30,quark:iron_plate:1,null,100)
Block(1,0,5,quark:limestone:0)
Block(1,1,0,COBBLESTONE_STAIRS:2)
RandomBlock(1,1,1,quark:iron_plate:1,null,70,STAINED_CLAY:15,null,30,STAINED_CLAY:7,null,30,quark:iron_plate:1,null,100)
Block(1,1,2,AIR:0)
Block(1,1,3,AIR:0)
RandomBlock(1,1,4,quark:iron_plate:1,null,70,STAINED_CLAY:15,null,30,STAINED_CLAY:7,null,30,quark:iron_plate:1,null,100)
Block(1,1,5,COBBLESTONE_STAIRS:3)
RandomBlock(1,2,1,quark:iron_plate:1,null,70,STAINED_CLAY:15,null,30,STAINED_CLAY:7,null,30,quark:iron_plate:1,null,100)
Block(1,2,2,AIR:0)
Block(1,2,3,AIR:0)
RandomBlock(1,2,4,rustic:iron_lattice:1,null,30,rustic:iron_lattice:1,null,30,biomesoplenty:leaves_2:7,null,30,quark:iron_plate_stairs:6,null,10,quark:iron_plate_stairs:0,null,10,quark:iron_plate_stairs:5,null,10,quark:iron_plate_stairs:3,null,10,quark:iron_plate_slab:8,null,10,quark:iron_plate_stairs:7,null,10,quark:iron_plate_stairs:1,null,10,quark:iron_plate_slab:0,null,10,quark:iron_plate_stairs:4,null,10,quark:iron_plate_stairs:2,null,10,rustic:iron_lattice:1,null,50,rustic:iron_lattice:1,null,50,biomesoplenty:leaves_2:7,null,100)
RandomBlock(1,3,1,quark:iron_plate:1,null,70,STAINED_CLAY:15,null,30,STAINED_CLAY:7,null,30,quark:iron_plate:1,null,100)
Block(1,3,2,AIR:0)
Block(1,3,3,AIR:0)
RandomBlock(1,3,4,quark:iron_plate:1,null,70,STAINED_CLAY:15,null,30,STAINED_CLAY:7,null,30,quark:iron_plate:1,null,100)
RandomBlock(1,4,1,quark:iron_plate:1,null,70,STAINED_CLAY:15,null,30,STAINED_CLAY:7,null,30,quark:iron_plate:1,null,100)
Block(1,4,2,AIR:0)
Block(1,4,3,AIR:0)
RandomBlock(1,4,4,quark:iron_plate:1,null,70,STAINED_CLAY:15,null,30,STAINED_CLAY:7,null,30,quark:iron_plate:1,null,100)
RandomBlock(1,5,1,quark:iron_plate:1,null,70,STAINED_CLAY:15,null,30,STAINED_CLAY:7,null,30,quark:iron_plate:1,null,100)
Block(1,5,2,AIR:0)
Block(1,5,3,AIR:0)
RandomBlock(1,5,4,rustic:iron_lattice:1,null,30,rustic:iron_lattice:1,null,30,biomesoplenty:leaves_2:7,null,30,quark:iron_plate_stairs:6,null,10,quark:iron_plate_stairs:0,null,10,quark:iron_plate_stairs:5,null,10,quark:iron_plate_stairs:3,null,10,quark:iron_plate_slab:8,null,10,quark:iron_plate_stairs:7,null,10,quark:iron_plate_stairs:1,null,10,quark:iron_plate_slab:0,null,10,quark:iron_plate_stairs:4,null,10,quark:iron_plate_stairs:2,null,10,rustic:iron_lattice:1,null,50,rustic:iron_lattice:1,null,50,biomesoplenty:leaves_2:7,null,100)
Block(1,6,-6,COBBLESTONE_STAIRS:6)
RandomBlock(1,6,-5,quark:iron_plate:1,null,70,STAINED_CLAY:15,null,30,STAINED_CLAY:7,null,30,quark:iron_plate:1,null,100)
RandomBlock(1,6,-4,quark:iron_plate:1,null,70,STAINED_CLAY:15,null,30,STAINED_CLAY:7,null,30,quark:iron_plate:1,null,100)
RandomBlock(1,6,-3,quark:iron_plate:1,null,70,STAINED_CLAY:15,null,30,STAINED_CLAY:7,null,30,quark:iron_plate:1,null,100)
RandomBlock(1,6,-2,quark:iron_plate:1,null,70,STAINED_CLAY:15,null,30,STAINED_CLAY:7,null,30,quark:iron_plate:1,null,100)
RandomBlock(1,6,-1,quark:iron_plate:1,null,70,STAINED_CLAY:15,null,30,STAINED_CLAY:7,null,30,quark:iron_plate:1,null,100)
RandomBlock(1,6,0,quark:iron_plate:1,null,70,STAINED_CLAY:15,null,30,STAINED_CLAY:7,null,30,quark:iron_plate:1,null,100)
RandomBlock(1,6,1,quark:iron_plate:1,null,70,STAINED_CLAY:15,null,30,STAINED_CLAY:7,null,30,quark:iron_plate:1,null,100)
Block(1,6,2,AIR:0)
Block(1,6,3,AIR:0)
RandomBlock(1,6,4,quark:iron_plate:1,null,70,STAINED_CLAY:15,null,30,STAINED_CLAY:7,null,30,quark:iron_plate:1,null,100)
RandomBlock(1,7,-6,rustic:iron_lattice:1,null,30,rustic:iron_lattice:1,null,30,biomesoplenty:leaves_2:7,null,30,quark:iron_plate_stairs:6,null,10,quark:iron_plate_stairs:0,null,10,quark:iron_plate_stairs:5,null,10,quark:iron_plate_stairs:3,null,10,quark:iron_plate_slab:8,null,10,quark:iron_plate_stairs:7,null,10,quark:iron_plate_stairs:1,null,10,quark:iron_plate_slab:0,null,10,quark:iron_plate_stairs:4,null,10,quark:iron_plate_stairs:2,null,10,rustic:iron_lattice:1,null,50,rustic:iron_lattice:1,null,50,biomesoplenty:leaves_2:7,null,100)
Block(1,7,-5,AIR:0)
Block(1,7,-4,AIR:0)
Block(1,7,-3,AIR:0)
Block(1,7,-2,AIR:0)
Block(1,7,-1,AIR:0)
Block(1,7,0,AIR:0)
Block(1,7,1,AIR:0)
Block(1,7,2,AIR:0)
Block(1,7,3,AIR:0)
RandomBlock(1,7,4,rustic:iron_lattice:1,null,30,rustic:iron_lattice:1,null,30,biomesoplenty:leaves_2:7,null,30,quark:iron_plate_stairs:6,null,10,quark:iron_plate_stairs:0,null,10,quark:iron_plate_stairs:5,null,10,quark:iron_plate_stairs:3,null,10,quark:iron_plate_slab:8,null,10,quark:iron_plate_stairs:7,null,10,quark:iron_plate_stairs:1,null,10,quark:iron_plate_slab:0,null,10,quark:iron_plate_stairs:4,null,10,quark:iron_plate_stairs:2,null,10,rustic:iron_lattice:1,null,50,rustic:iron_lattice:1,null,50,biomesoplenty:leaves_2:7,null,100)
RandomBlock(1,8,-6,rustic:iron_lattice:1,null,30,rustic:iron_lattice:1,null,30,biomesoplenty:leaves_2:7,null,30,quark:iron_plate_stairs:6,null,10,quark:iron_plate_stairs:0,null,10,quark:iron_plate_stairs:5,null,10,quark:iron_plate_stairs:3,null,10,quark:iron_plate_slab:8,null,10,quark:iron_plate_stairs:7,null,10,quark:iron_plate_stairs:1,null,10,quark:iron_plate_slab:0,null,10,quark:iron_plate_stairs:4,null,10,quark:iron_plate_stairs:2,null,10,rustic:iron_lattice:1,null,50,rustic:iron_lattice:1,null,50,biomesoplenty:leaves_2:7,null,100)
Block(1,8,-5,AIR:0)
Block(1,8,-4,AIR:0)
Block(1,8,-3,AIR:0)
Block(1,8,-2,AIR:0)
Block(1,8,-1,AIR:0)
Block(1,8,0,AIR:0)
Block(1,8,1,AIR:0)
Block(1,8,2,AIR:0)
Block(1,8,3,AIR:0)
RandomBlock(1,8,4,rustic:iron_lattice:1,null,30,rustic:iron_lattice:1,null,30,biomesoplenty:leaves_2:7,null,30,quark:iron_plate_stairs:6,null,10,quark:iron_plate_stairs:0,null,10,quark:iron_plate_stairs:5,null,10,quark:iron_plate_stairs:3,null,10,quark:iron_plate_slab:8,null,10,quark:iron_plate_stairs:7,null,10,quark:iron_plate_stairs:1,null,10,quark:iron_plate_slab:0,null,10,quark:iron_plate_stairs:4,null,10,quark:iron_plate_stairs:2,null,10,rustic:iron_lattice:1,null,50,rustic:iron_lattice:1,null,50,biomesoplenty:leaves_2:7,null,100)
Block(1,9,-6,COBBLESTONE_STAIRS:2)
RandomBlock(1,9,-5,quark:iron_plate:1,null,70,STAINED_CLAY:15,null,30,STAINED_CLAY:7,null,30,quark:iron_plate:1,null,100)
RandomBlock(1,9,-4,quark:iron_plate:1,null,70,STAINED_CLAY:15,null,30,STAINED_CLAY:7,null,30,quark:iron_plate:1,null,100)
RandomBlock(1,9,-3,rustic:iron_lattice:1,null,30,rustic:iron_lattice:1,null,30,biomesoplenty:leaves_2:7,null,30,quark:iron_plate_stairs:6,null,10,quark:iron_plate_stairs:0,null,10,quark:iron_plate_stairs:5,null,10,quark:iron_plate_stairs:3,null,10,quark:iron_plate_slab:8,null,10,quark:iron_plate_stairs:7,null,10,quark:iron_plate_stairs:1,null,10,quark:iron_plate_slab:0,null,10,quark:iron_plate_stairs:4,null,10,quark:iron_plate_stairs:2,null,10,rustic:iron_lattice:1,null,50,rustic:iron_lattice:1,null,50,biomesoplenty:leaves_2:7,null,100)
RandomBlock(1,9,-2,rustic:iron_lattice:1,null,30,rustic:iron_lattice:1,null,30,biomesoplenty:leaves_2:7,null,30,quark:iron_plate_stairs:6,null,10,quark:iron_plate_stairs:0,null,10,quark:iron_plate_stairs:5,null,10,quark:iron_plate_stairs:3,null,10,quark:iron_plate_slab:8,null,10,quark:iron_plate_stairs:7,null,10,quark:iron_plate_stairs:1,null,10,quark:iron_plate_slab:0,null,10,quark:iron_plate_stairs:4,null,10,quark:iron_plate_stairs:2,null,10,rustic:iron_lattice:1,null,50,rustic:iron_lattice:1,null,50,biomesoplenty:leaves_2:7,null,100)
RandomBlock(1,9,-1,rustic:iron_lattice:1,null,30,rustic:iron_lattice:1,null,30,biomesoplenty:leaves_2:7,null,30,quark:iron_plate_stairs:6,null,10,quark:iron_plate_stairs:0,null,10,quark:iron_plate_stairs:5,null,10,quark:iron_plate_stairs:3,null,10,quark:iron_plate_slab:8,null,10,quark:iron_plate_stairs:7,null,10,quark:iron_plate_stairs:1,null,10,quark:iron_plate_slab:0,null,10,quark:iron_plate_stairs:4,null,10,quark:iron_plate_stairs:2,null,10,rustic:iron_lattice:1,null,50,rustic:iron_lattice:1,null,50,biomesoplenty:leaves_2:7,null,100)
RandomBlock(1,9,0,quark:iron_plate:1,null,70,STAINED_CLAY:15,null,30,STAINED_CLAY:7,null,30,quark:iron_plate:1,null,100)
RandomBlock(1,9,1,quark:iron_plate:1,null,70,STAINED_CLAY:15,null,30,STAINED_CLAY:7,null,30,quark:iron_plate:1,null,100)
RandomBlock(1,9,2,quark:iron_plate:1,null,70,STAINED_CLAY:15,null,30,STAINED_CLAY:7,null,30,quark:iron_plate:1,null,100)
RandomBlock(1,9,3,quark:iron_plate:1,null,70,STAINED_CLAY:15,null,30,STAINED_CLAY:7,null,30,quark:iron_plate:1,null,100)
RandomBlock(1,9,4,quark:iron_plate:1,null,70,STAINED_CLAY:15,null,30,STAINED_CLAY:7,null,30,quark:iron_plate:1,null,100)
Block(1,10,1,rustic:iron_lattice:0)
Block(1,10,2,COBBLESTONE_STAIRS:2)
Block(1,10,3,COBBLESTONE_STAIRS:1)
Block(1,10,4,rustic:iron_lattice:0)
Block(2,0,0,quark:limestone:0)
RandomBlock(2,0,1,quark:iron_plate:1,null,70,STAINED_CLAY:15,null,30,STAINED_CLAY:7,null,30,quark:iron_plate:1,null,100)
RandomBlock(2,0,2,quark:iron_plate:1,null,70,STAINED_CLAY:15,null,30,STAINED_CLAY:7,null,30,quark:iron_plate:1,null,100)
RandomBlock(2,0,3,quark:iron_plate:1,null,70,STAINED_CLAY:15,null,30,STAINED_CLAY:7,null,30,quark:iron_plate:1,null,100)
RandomBlock(2,0,4,quark:iron_plate:1,null,70,STAINED_CLAY:15,null,30,STAINED_CLAY:7,null,30,quark:iron_plate:1,null,100)
Block(2,0,5,quark:limestone:0)
Block(2,1,0,COBBLESTONE_STAIRS:2)
RandomBlock(2,1,1,quark:iron_plate:1,null,70,STAINED_CLAY:15,null,30,STAINED_CLAY:7,null,30,quark:iron_plate:1,null,100)
RandomBlock(2,1,2,quark:iron_plate:1,null,70,STAINED_CLAY:15,null,30,STAINED_CLAY:7,null,30,quark:iron_plate:1,null,100)
RandomBlock(2,1,3,rustic:iron_lattice:1,null,30,rustic:iron_lattice:1,null,30,biomesoplenty:leaves_2:7,null,30,quark:iron_plate_stairs:6,null,10,quark:iron_plate_stairs:0,null,10,quark:iron_plate_stairs:5,null,10,quark:iron_plate_stairs:3,null,10,quark:iron_plate_slab:8,null,10,quark:iron_plate_stairs:7,null,10,quark:iron_plate_stairs:1,null,10,quark:iron_plate_slab:0,null,10,quark:iron_plate_stairs:4,null,10,quark:iron_plate_stairs:2,null,10,rustic:iron_lattice:1,null,50,rustic:iron_lattice:1,null,50,biomesoplenty:leaves_2:7,null,100)
RandomBlock(2,1,4,rustic:iron_lattice:1,null,30,rustic:iron_lattice:1,null,30,biomesoplenty:leaves_2:7,null,30,quark:iron_plate_stairs:6,null,10,quark:iron_plate_stairs:0,null,10,quark:iron_plate_stairs:5,null,10,quark:iron_plate_stairs:3,null,10,quark:iron_plate_slab:8,null,10,quark:iron_plate_stairs:7,null,10,quark:iron_plate_stairs:1,null,10,quark:iron_plate_slab:0,null,10,quark:iron_plate_stairs:4,null,10,quark:iron_plate_stairs:2,null,10,rustic:iron_lattice:1,null,50,rustic:iron_lattice:1,null,50,biomesoplenty:leaves_2:7,null,100)
Block(2,1,5,COBBLESTONE_STAIRS:3)
RandomBlock(2,2,1,quark:iron_plate:1,null,70,STAINED_CLAY:15,null,30,STAINED_CLAY:7,null,30,quark:iron_plate:1,null,100)
RandomBlock(2,2,2,rustic:iron_lattice:1,null,30,rustic:iron_lattice:1,null,30,biomesoplenty:leaves_2:7,null,30,quark:iron_plate_stairs:6,null,10,quark:iron_plate_stairs:0,null,10,quark:iron_plate_stairs:5,null,10,quark:iron_plate_stairs:3,null,10,quark:iron_plate_slab:8,null,10,quark:iron_plate_stairs:7,null,10,quark:iron_plate_stairs:1,null,10,quark:iron_plate_slab:0,null,10,quark:iron_plate_stairs:4,null,10,quark:iron_plate_stairs:2,null,10,rustic:iron_lattice:1,null,50,rustic:iron_lattice:1,null,50,biomesoplenty:leaves_2:7,null,100)
RandomBlock(2,2,3,rustic:iron_lattice:1,null,30,rustic:iron_lattice:1,null,30,biomesoplenty:leaves_2:7,null,30,quark:iron_plate_stairs:6,null,10,quark:iron_plate_stairs:0,null,10,quark:iron_plate_stairs:5,null,10,quark:iron_plate_stairs:3,null,10,quark:iron_plate_slab:8,null,10,quark:iron_plate_stairs:7,null,10,quark:iron_plate_stairs:1,null,10,quark:iron_plate_slab:0,null,10,quark:iron_plate_stairs:4,null,10,quark:iron_plate_stairs:2,null,10,rustic:iron_lattice:1,null,50,rustic:iron_lattice:1,null,50,biomesoplenty:leaves_2:7,null,100)
RandomBlock(2,2,4,rustic:iron_lattice:1,null,30,rustic:iron_lattice:1,null,30,biomesoplenty:leaves_2:7,null,30,quark:iron_plate_stairs:6,null,10,quark:iron_plate_stairs:0,null,10,quark:iron_plate_stairs:5,null,10,quark:iron_plate_stairs:3,null,10,quark:iron_plate_slab:8,null,10,quark:iron_plate_stairs:7,null,10,quark:iron_plate_stairs:1,null,10,quark:iron_plate_slab:0,null,10,quark:iron_plate_stairs:4,null,10,quark:iron_plate_stairs:2,null,10,rustic:iron_lattice:1,null,50,rustic:iron_lattice:1,null,50,biomesoplenty:leaves_2:7,null,100)
RandomBlock(2,3,1,quark:iron_plate:1,null,70,STAINED_CLAY:15,null,30,STAINED_CLAY:7,null,30,quark:iron_plate:1,null,100)
RandomBlock(2,3,2,quark:iron_plate:1,null,70,STAINED_CLAY:15,null,30,STAINED_CLAY:7,null,30,quark:iron_plate:1,null,100)
RandomBlock(2,3,3,rustic:iron_lattice:1,null,30,rustic:iron_lattice:1,null,30,biomesoplenty:leaves_2:7,null,30,quark:iron_plate_stairs:6,null,10,quark:iron_plate_stairs:0,null,10,quark:iron_plate_stairs:5,null,10,quark:iron_plate_stairs:3,null,10,quark:iron_plate_slab:8,null,10,quark:iron_plate_stairs:7,null,10,quark:iron_plate_stairs:1,null,10,quark:iron_plate_slab:0,null,10,quark:iron_plate_stairs:4,null,10,quark:iron_plate_stairs:2,null,10,rustic:iron_lattice:1,null,50,rustic:iron_lattice:1,null,50,biomesoplenty:leaves_2:7,null,100)
RandomBlock(2,3,4,rustic:iron_lattice:1,null,30,rustic:iron_lattice:1,null,30,biomesoplenty:leaves_2:7,null,30,quark:iron_plate_stairs:6,null,10,quark:iron_plate_stairs:0,null,10,quark:iron_plate_stairs:5,null,10,quark:iron_plate_stairs:3,null,10,quark:iron_plate_slab:8,null,10,quark:iron_plate_stairs:7,null,10,quark:iron_plate_stairs:1,null,10,quark:iron_plate_slab:0,null,10,quark:iron_plate_stairs:4,null,10,quark:iron_plate_stairs:2,null,10,rustic:iron_lattice:1,null,50,rustic:iron_lattice:1,null,50,biomesoplenty:leaves_2:7,null,100)
RandomBlock(2,4,1,quark:iron_plate:1,null,70,STAINED_CLAY:15,null,30,STAINED_CLAY:7,null,30,quark:iron_plate:1,null,100)
RandomBlock(2,4,2,rustic:iron_lattice:1,null,30,rustic:iron_lattice:1,null,30,biomesoplenty:leaves_2:7,null,30,quark:iron_plate_stairs:6,null,10,quark:iron_plate_stairs:0,null,10,quark:iron_plate_stairs:5,null,10,quark:iron_plate_stairs:3,null,10,quark:iron_plate_slab:8,null,10,quark:iron_plate_stairs:7,null,10,quark:iron_plate_stairs:1,null,10,quark:iron_plate_slab:0,null,10,quark:iron_plate_stairs:4,null,10,quark:iron_plate_stairs:2,null,10,rustic:iron_lattice:1,null,50,rustic:iron_lattice:1,null,50,biomesoplenty:leaves_2:7,null,100)
RandomBlock(2,4,3,rustic:iron_lattice:1,null,30,rustic:iron_lattice:1,null,30,biomesoplenty:leaves_2:7,null,30,quark:iron_plate_stairs:6,null,10,quark:iron_plate_stairs:0,null,10,quark:iron_plate_stairs:5,null,10,quark:iron_plate_stairs:3,null,10,quark:iron_plate_slab:8,null,10,quark:iron_plate_stairs:7,null,10,quark:iron_plate_stairs:1,null,10,quark:iron_plate_slab:0,null,10,quark:iron_plate_stairs:4,null,10,quark:iron_plate_stairs:2,null,10,rustic:iron_lattice:1,null,50,rustic:iron_lattice:1,null,50,biomesoplenty:leaves_2:7,null,100)
RandomBlock(2,4,4,rustic:iron_lattice:1,null,30,rustic:iron_lattice:1,null,30,biomesoplenty:leaves_2:7,null,30,quark:iron_plate_stairs:6,null,10,quark:iron_plate_stairs:0,null,10,quark:iron_plate_stairs:5,null,10,quark:iron_plate_stairs:3,null,10,quark:iron_plate_slab:8,null,10,quark:iron_plate_stairs:7,null,10,quark:iron_plate_stairs:1,null,10,quark:iron_plate_slab:0,null,10,quark:iron_plate_stairs:4,null,10,quark:iron_plate_stairs:2,null,10,rustic:iron_lattice:1,null,50,rustic:iron_lattice:1,null,50,biomesoplenty:leaves_2:7,null,100)
RandomBlock(2,5,1,quark:iron_plate:1,null,70,STAINED_CLAY:15,null,30,STAINED_CLAY:7,null,30,quark:iron_plate:1,null,100)
RandomBlock(2,5,2,quark:iron_plate:1,null,70,STAINED_CLAY:15,null,30,STAINED_CLAY:7,null,30,quark:iron_plate:1,null,100)
RandomBlock(2,5,3,rustic:iron_lattice:1,null,30,rustic:iron_lattice:1,null,30,biomesoplenty:leaves_2:7,null,30,quark:iron_plate_stairs:6,null,10,quark:iron_plate_stairs:0,null,10,quark:iron_plate_stairs:5,null,10,quark:iron_plate_stairs:3,null,10,quark:iron_plate_slab:8,null,10,quark:iron_plate_stairs:7,null,10,quark:iron_plate_stairs:1,null,10,quark:iron_plate_slab:0,null,10,quark:iron_plate_stairs:4,null,10,quark:iron_plate_stairs:2,null,10,rustic:iron_lattice:1,null,50,rustic:iron_lattice:1,null,50,biomesoplenty:leaves_2:7,null,100)
RandomBlock(2,5,4,rustic:iron_lattice:1,null,30,rustic:iron_lattice:1,null,30,biomesoplenty:leaves_2:7,null,30,quark:iron_plate_stairs:6,null,10,quark:iron_plate_stairs:0,null,10,quark:iron_plate_stairs:5,null,10,quark:iron_plate_stairs:3,null,10,quark:iron_plate_slab:8,null,10,quark:iron_plate_stairs:7,null,10,quark:iron_plate_stairs:1,null,10,quark:iron_plate_slab:0,null,10,quark:iron_plate_stairs:4,null,10,quark:iron_plate_stairs:2,null,10,rustic:iron_lattice:1,null,50,rustic:iron_lattice:1,null,50,biomesoplenty:leaves_2:7,null,100)
Block(2,6,-6,COBBLESTONE_STAIRS:6)
Block(2,6,-5,COBBLESTONE_STAIRS:5)
Block(2,6,-4,COBBLESTONE_STAIRS:5)
Block(2,6,-3,COBBLESTONE_STAIRS:5)
RandomBlock(2,6,-2,quark:iron_plate:1,null,70,STAINED_CLAY:15,null,30,STAINED_CLAY:7,null,30,quark:iron_plate:1,null,100)
Block(2,6,-1,COBBLESTONE_STAIRS:5)
Block(2,6,0,COBBLESTONE_STAIRS:5)
RandomBlock(2,6,1,quark:iron_plate:1,null,70,STAINED_CLAY:15,null,30,STAINED_CLAY:7,null,30,quark:iron_plate:1,null,100)
RandomBlock(2,6,2,quark:iron_plate:1,null,70,STAINED_CLAY:15,null,30,STAINED_CLAY:7,null,30,quark:iron_plate:1,null,100)
RandomBlock(2,6,3,quark:iron_plate:1,null,70,STAINED_CLAY:15,null,30,STAINED_CLAY:7,null,30,quark:iron_plate:1,null,100)
RandomBlock(2,6,4,rustic:iron_lattice:1,null,30,rustic:iron_lattice:1,null,30,biomesoplenty:leaves_2:7,null,30,quark:iron_plate_stairs:6,null,10,quark:iron_plate_stairs:0,null,10,quark:iron_plate_stairs:5,null,10,quark:iron_plate_stairs:3,null,10,quark:iron_plate_slab:8,null,10,quark:iron_plate_stairs:7,null,10,quark:iron_plate_stairs:1,null,10,quark:iron_plate_slab:0,null,10,quark:iron_plate_stairs:4,null,10,quark:iron_plate_stairs:2,null,10,rustic:iron_lattice:1,null,50,rustic:iron_lattice:1,null,50,biomesoplenty:leaves_2:7,null,100)
RandomBlock(2,7,-6,rustic:iron_lattice:1,null,30,rustic:iron_lattice:1,null,30,biomesoplenty:leaves_2:7,null,30,quark:iron_plate_stairs:6,null,10,quark:iron_plate_stairs:0,null,10,quark:iron_plate_stairs:5,null,10,quark:iron_plate_stairs:3,null,10,quark:iron_plate_slab:8,null,10,quark:iron_plate_stairs:7,null,10,quark:iron_plate_stairs:1,null,10,quark:iron_plate_slab:0,null,10,quark:iron_plate_stairs:4,null,10,quark:iron_plate_stairs:2,null,10,rustic:iron_lattice:1,null,50,rustic:iron_lattice:1,null,50,biomesoplenty:leaves_2:7,null,100)
RandomBlock(2,7,-5,quark:iron_plate:1,null,70,STAINED_CLAY:15,null,30,STAINED_CLAY:7,null,30,quark:iron_plate:1,null,100)
RandomBlock(2,7,-4,quark:iron_plate:1,null,70,STAINED_CLAY:15,null,30,STAINED_CLAY:7,null,30,quark:iron_plate:1,null,100)
RandomBlock(2,7,-3,rustic:iron_lattice:1,null,30,rustic:iron_lattice:1,null,30,biomesoplenty:leaves_2:7,null,30,quark:iron_plate_stairs:6,null,10,quark:iron_plate_stairs:0,null,10,quark:iron_plate_stairs:5,null,10,quark:iron_plate_stairs:3,null,10,quark:iron_plate_slab:8,null,10,quark:iron_plate_stairs:7,null,10,quark:iron_plate_stairs:1,null,10,quark:iron_plate_slab:0,null,10,quark:iron_plate_stairs:4,null,10,quark:iron_plate_stairs:2,null,10,rustic:iron_lattice:1,null,50,rustic:iron_lattice:1,null,50,biomesoplenty:leaves_2:7,null,100)
Block(2,7,-2,AIR:0)
RandomBlock(2,7,-1,quark:iron_plate:1,null,70,STAINED_CLAY:15,null,30,STAINED_CLAY:7,null,30,quark:iron_plate:1,null,100)
RandomBlock(2,7,0,quark:iron_plate:1,null,70,STAINED_CLAY:15,null,30,STAINED_CLAY:7,null,30,quark:iron_plate:1,null,100)
RandomBlock(2,7,1,quark:iron_plate:1,null,70,STAINED_CLAY:15,null,30,STAINED_CLAY:7,null,30,quark:iron_plate:1,null,100)
RandomBlock(2,7,2,quark:iron_plate:1,null,70,STAINED_CLAY:15,null,30,STAINED_CLAY:7,null,30,quark:iron_plate:1,null,100)
RandomBlock(2,7,3,rustic:iron_lattice:1,null,30,rustic:iron_lattice:1,null,30,biomesoplenty:leaves_2:7,null,30,quark:iron_plate_stairs:6,null,10,quark:iron_plate_stairs:0,null,10,quark:iron_plate_stairs:5,null,10,quark:iron_plate_stairs:3,null,10,quark:iron_plate_slab:8,null,10,quark:iron_plate_stairs:7,null,10,quark:iron_plate_stairs:1,null,10,quark:iron_plate_slab:0,null,10,quark:iron_plate_stairs:4,null,10,quark:iron_plate_stairs:2,null,10,rustic:iron_lattice:1,null,50,rustic:iron_lattice:1,null,50,biomesoplenty:leaves_2:7,null,100)
RandomBlock(2,7,4,rustic:iron_lattice:1,null,30,rustic:iron_lattice:1,null,30,biomesoplenty:leaves_2:7,null,30,quark:iron_plate_stairs:6,null,10,quark:iron_plate_stairs:0,null,10,quark:iron_plate_stairs:5,null,10,quark:iron_plate_stairs:3,null,10,quark:iron_plate_slab:8,null,10,quark:iron_plate_stairs:7,null,10,quark:iron_plate_stairs:1,null,10,quark:iron_plate_slab:0,null,10,quark:iron_plate_stairs:4,null,10,quark:iron_plate_stairs:2,null,10,rustic:iron_lattice:1,null,50,rustic:iron_lattice:1,null,50,biomesoplenty:leaves_2:7,null,100)
RandomBlock(2,8,-6,rustic:iron_lattice:1,null,30,rustic:iron_lattice:1,null,30,biomesoplenty:leaves_2:7,null,30,quark:iron_plate_stairs:6,null,10,quark:iron_plate_stairs:0,null,10,quark:iron_plate_stairs:5,null,10,quark:iron_plate_stairs:3,null,10,quark:iron_plate_slab:8,null,10,quark:iron_plate_stairs:7,null,10,quark:iron_plate_stairs:1,null,10,quark:iron_plate_slab:0,null,10,quark:iron_plate_stairs:4,null,10,quark:iron_plate_stairs:2,null,10,rustic:iron_lattice:1,null,50,rustic:iron_lattice:1,null,50,biomesoplenty:leaves_2:7,null,100)
RandomBlock(2,8,-5,rustic:iron_lattice:1,null,30,rustic:iron_lattice:1,null,30,biomesoplenty:leaves_2:7,null,30,quark:iron_plate_stairs:6,null,10,quark:iron_plate_stairs:0,null,10,quark:iron_plate_stairs:5,null,10,quark:iron_plate_stairs:3,null,10,quark:iron_plate_slab:8,null,10,quark:iron_plate_stairs:7,null,10,quark:iron_plate_stairs:1,null,10,quark:iron_plate_slab:0,null,10,quark:iron_plate_stairs:4,null,10,quark:iron_plate_stairs:2,null,10,rustic:iron_lattice:1,null,50,rustic:iron_lattice:1,null,50,biomesoplenty:leaves_2:7,null,100)
RandomBlock(2,8,-4,quark:iron_plate:1,null,70,STAINED_CLAY:15,null,30,STAINED_CLAY:7,null,30,quark:iron_plate:1,null,100)
RandomBlock(2,8,-3,quark:iron_plate:1,null,70,STAINED_CLAY:15,null,30,STAINED_CLAY:7,null,30,quark:iron_plate:1,null,100)
Block(2,8,-2,AIR:0)
RandomBlock(2,8,-1,quark:iron_plate:1,null,70,STAINED_CLAY:15,null,30,STAINED_CLAY:7,null,30,quark:iron_plate:1,null,100)
RandomBlock(2,8,0,quark:iron_plate:1,null,70,STAINED_CLAY:15,null,30,STAINED_CLAY:7,null,30,quark:iron_plate:1,null,100)
RandomBlock(2,8,1,quark:iron_plate:1,null,70,STAINED_CLAY:15,null,30,STAINED_CLAY:7,null,30,quark:iron_plate:1,null,100)
RandomBlock(2,8,2,quark:iron_plate:1,null,70,STAINED_CLAY:15,null,30,STAINED_CLAY:7,null,30,quark:iron_plate:1,null,100)
RandomBlock(2,8,3,rustic:iron_lattice:1,null,30,rustic:iron_lattice:1,null,30,biomesoplenty:leaves_2:7,null,30,quark:iron_plate_stairs:6,null,10,quark:iron_plate_stairs:0,null,10,quark:iron_plate_stairs:5,null,10,quark:iron_plate_stairs:3,null,10,quark:iron_plate_slab:8,null,10,quark:iron_plate_stairs:7,null,10,quark:iron_plate_stairs:1,null,10,quark:iron_plate_slab:0,null,10,quark:iron_plate_stairs:4,null,10,quark:iron_plate_stairs:2,null,10,rustic:iron_lattice:1,null,50,rustic:iron_lattice:1,null,50,biomesoplenty:leaves_2:7,null,100)
RandomBlock(2,8,4,rustic:iron_lattice:1,null,30,rustic:iron_lattice:1,null,30,biomesoplenty:leaves_2:7,null,30,quark:iron_plate_stairs:6,null,10,quark:iron_plate_stairs:0,null,10,quark:iron_plate_stairs:5,null,10,quark:iron_plate_stairs:3,null,10,quark:iron_plate_slab:8,null,10,quark:iron_plate_stairs:7,null,10,quark:iron_plate_stairs:1,null,10,quark:iron_plate_slab:0,null,10,quark:iron_plate_stairs:4,null,10,quark:iron_plate_stairs:2,null,10,rustic:iron_lattice:1,null,50,rustic:iron_lattice:1,null,50,biomesoplenty:leaves_2:7,null,100)
Block(2,9,-6,COBBLESTONE_STAIRS:2)
Block(2,9,-5,COBBLESTONE_STAIRS:1)
Block(2,9,-4,COBBLESTONE_STAIRS:1)
Block(2,9,-3,COBBLESTONE_STAIRS:1)
RandomBlock(2,9,-2,rustic:iron_lattice:1,null,30,rustic:iron_lattice:1,null,30,biomesoplenty:leaves_2:7,null,30,quark:iron_plate_stairs:6,null,10,quark:iron_plate_stairs:0,null,10,quark:iron_plate_stairs:5,null,10,quark:iron_plate_stairs:3,null,10,quark:iron_plate_slab:8,null,10,quark:iron_plate_stairs:7,null,10,quark:iron_plate_stairs:1,null,10,quark:iron_plate_slab:0,null,10,quark:iron_plate_stairs:4,null,10,quark:iron_plate_stairs:2,null,10,rustic:iron_lattice:1,null,50,rustic:iron_lattice:1,null,50,biomesoplenty:leaves_2:7,null,100)
Block(2,9,-1,COBBLESTONE_STAIRS:1)
Block(2,9,0,COBBLESTONE_STAIRS:1)
RandomBlock(2,9,1,quark:iron_plate:1,null,70,STAINED_CLAY:15,null,30,STAINED_CLAY:7,null,30,quark:iron_plate:1,null,100)
RandomBlock(2,9,2,quark:iron_plate:1,null,70,STAINED_CLAY:15,null,30,STAINED_CLAY:7,null,30,quark:iron_plate:1,null,100)
RandomBlock(2,9,3,quark:iron_plate:1,null,70,STAINED_CLAY:15,null,30,STAINED_CLAY:7,null,30,quark:iron_plate:1,null,100)
RandomBlock(2,9,4,rustic:iron_lattice:1,null,30,rustic:iron_lattice:1,null,30,biomesoplenty:leaves_2:7,null,30,quark:iron_plate_stairs:6,null,10,quark:iron_plate_stairs:0,null,10,quark:iron_plate_stairs:5,null,10,quark:iron_plate_stairs:3,null,10,quark:iron_plate_slab:8,null,10,quark:iron_plate_stairs:7,null,10,quark:iron_plate_stairs:1,null,10,quark:iron_plate_slab:0,null,10,quark:iron_plate_stairs:4,null,10,quark:iron_plate_stairs:2,null,10,rustic:iron_lattice:1,null,50,rustic:iron_lattice:1,null,50,biomesoplenty:leaves_2:7,null,100)
Block(2,10,1,rustic:iron_lattice:0)
Block(2,10,2,rustic:iron_lattice:0)
Block(2,10,3,rustic:iron_lattice:0)
Block(2,10,4,rustic:iron_lattice:0)
Block(3,0,0,quark:limestone:0)
Block(3,0,1,quark:limestone:0)
Block(3,0,2,quark:limestone:0)
Block(3,0,3,quark:limestone:0)
Block(3,0,4,quark:limestone:0)
Block(3,0,5,quark:limestone:0)
Block(3,1,0,COBBLESTONE_STAIRS:2)
Block(3,1,1,COBBLESTONE_STAIRS:1)
Block(3,1,2,COBBLESTONE_STAIRS:1)
Block(3,1,3,COBBLESTONE_STAIRS:1)
Block(3,1,4,COBBLESTONE_STAIRS:1)
Block(3,1,5,COBBLESTONE_STAIRS:3)
Block(3,6,-3,COBBLESTONE_STAIRS:6)
RandomBlock(3,6,-2,quark:iron_plate:1,null,70,STAINED_CLAY:15,null,30,STAINED_CLAY:7,null,30,quark:iron_plate:1,null,100)
Block(3,6,-1,COBBLESTONE_STAIRS:7)
RandomBlock(3,7,-3,rustic:iron_lattice:1,null,30,rustic:iron_lattice:1,null,30,biomesoplenty:leaves_2:7,null,30,quark:iron_plate_stairs:6,null,10,quark:iron_plate_stairs:0,null,10,quark:iron_plate_stairs:5,null,10,quark:iron_plate_stairs:3,null,10,quark:iron_plate_slab:8,null,10,quark:iron_plate_stairs:7,null,10,quark:iron_plate_stairs:1,null,10,quark:iron_plate_slab:0,null,10,quark:iron_plate_stairs:4,null,10,quark:iron_plate_stairs:2,null,10,rustic:iron_lattice:1,null,50,rustic:iron_lattice:1,null,50,biomesoplenty:leaves_2:7,null,100)
Block(3,7,-2,AIR:0)
RandomBlock(3,7,-1,quark:iron_plate:1,null,70,STAINED_CLAY:15,null,30,STAINED_CLAY:7,null,30,quark:iron_plate:1,null,100)
RandomBlock(3,8,-3,rustic:iron_lattice:1,null,30,rustic:iron_lattice:1,null,30,biomesoplenty:leaves_2:7,null,30,quark:iron_plate_stairs:6,null,10,quark:iron_plate_stairs:0,null,10,quark:iron_plate_stairs:5,null,10,quark:iron_plate_stairs:3,null,10,quark:iron_plate_slab:8,null,10,quark:iron_plate_stairs:7,null,10,quark:iron_plate_stairs:1,null,10,quark:iron_plate_slab:0,null,10,quark:iron_plate_stairs:4,null,10,quark:iron_plate_stairs:2,null,10,rustic:iron_lattice:1,null,50,rustic:iron_lattice:1,null,50,biomesoplenty:leaves_2:7,null,100)
Block(3,8,-2,AIR:0)
RandomBlock(3,8,-1,quark:iron_plate:1,null,70,STAINED_CLAY:15,null,30,STAINED_CLAY:7,null,30,quark:iron_plate:1,null,100)
Block(3,9,-3,COBBLESTONE_STAIRS:2)
RandomBlock(3,9,-2,rustic:iron_lattice:1,null,30,rustic:iron_lattice:1,null,30,biomesoplenty:leaves_2:7,null,30,quark:iron_plate_stairs:6,null,10,quark:iron_plate_stairs:0,null,10,quark:iron_plate_stairs:5,null,10,quark:iron_plate_stairs:3,null,10,quark:iron_plate_slab:8,null,10,quark:iron_plate_stairs:7,null,10,quark:iron_plate_stairs:1,null,10,quark:iron_plate_slab:0,null,10,quark:iron_plate_stairs:4,null,10,quark:iron_plate_stairs:2,null,10,rustic:iron_lattice:1,null,50,rustic:iron_lattice:1,null,50,biomesoplenty:leaves_2:7,null,100)
Block(3,9,-1,COBBLESTONE_STAIRS:3)
Block(4,6,-3,COBBLESTONE_STAIRS:6)
RandomBlock(4,6,-2,quark:iron_plate:1,null,70,STAINED_CLAY:15,null,30,STAINED_CLAY:7,null,30,quark:iron_plate:1,null,100)
Block(4,6,-1,COBBLESTONE_STAIRS:7)
RandomBlock(4,7,-3,rustic:iron_lattice:1,null,30,rustic:iron_lattice:1,null,30,biomesoplenty:leaves_2:7,null,30,quark:iron_plate_stairs:6,null,10,quark:iron_plate_stairs:0,null,10,quark:iron_plate_stairs:5,null,10,quark:iron_plate_stairs:3,null,10,quark:iron_plate_slab:8,null,10,quark:iron_plate_stairs:7,null,10,quark:iron_plate_stairs:1,null,10,quark:iron_plate_slab:0,null,10,quark:iron_plate_stairs:4,null,10,quark:iron_plate_stairs:2,null,10,rustic:iron_lattice:1,null,50,rustic:iron_lattice:1,null,50,biomesoplenty:leaves_2:7,null,100)
Block(4,7,-2,AIR:0)
RandomBlock(4,7,-1,quark:iron_plate:1,null,70,STAINED_CLAY:15,null,30,STAINED_CLAY:7,null,30,quark:iron_plate:1,null,100)
RandomBlock(4,8,-3,quark:iron_plate:1,null,70,STAINED_CLAY:15,null,30,STAINED_CLAY:7,null,30,quark:iron_plate:1,null,100)
Block(4,8,-2,AIR:0)
RandomBlock(4,8,-1,quark:iron_plate:1,null,70,STAINED_CLAY:15,null,30,STAINED_CLAY:7,null,30,quark:iron_plate:1,null,100)
Block(4,9,-3,COBBLESTONE_STAIRS:2)
RandomBlock(4,9,-2,rustic:iron_lattice:1,null,30,rustic:iron_lattice:1,null,30,biomesoplenty:leaves_2:7,null,30,quark:iron_plate_stairs:6,null,10,quark:iron_plate_stairs:0,null,10,quark:iron_plate_stairs:5,null,10,quark:iron_plate_stairs:3,null,10,quark:iron_plate_slab:8,null,10,quark:iron_plate_stairs:7,null,10,quark:iron_plate_stairs:1,null,10,quark:iron_plate_slab:0,null,10,quark:iron_plate_stairs:4,null,10,quark:iron_plate_stairs:2,null,10,rustic:iron_lattice:1,null,50,rustic:iron_lattice:1,null,50,biomesoplenty:leaves_2:7,null,100)
Block(4,9,-1,COBBLESTONE_STAIRS:3)
Block(5,6,-3,COBBLESTONE_STAIRS:6)
RandomBlock(5,6,-2,quark:iron_plate:1,null,70,STAINED_CLAY:15,null,30,STAINED_CLAY:7,null,30,quark:iron_plate:1,null,100)
Block(5,6,-1,COBBLESTONE_STAIRS:7)
RandomBlock(5,7,-3,rustic:iron_lattice:1,null,30,rustic:iron_lattice:1,null,30,biomesoplenty:leaves_2:7,null,30,quark:iron_plate_stairs:6,null,10,quark:iron_plate_stairs:0,null,10,quark:iron_plate_stairs:5,null,10,quark:iron_plate_stairs:3,null,10,quark:iron_plate_slab:8,null,10,quark:iron_plate_stairs:7,null,10,quark:iron_plate_stairs:1,null,10,quark:iron_plate_slab:0,null,10,quark:iron_plate_stairs:4,null,10,quark:iron_plate_stairs:2,null,10,rustic:iron_lattice:1,null,50,rustic:iron_lattice:1,null,50,biomesoplenty:leaves_2:7,null,100)
Block(5,7,-2,AIR:0)
RandomBlock(5,7,-1,quark:iron_plate:1,null,70,STAINED_CLAY:15,null,30,STAINED_CLAY:7,null,30,quark:iron_plate:1,null,100)
RandomBlock(5,8,-3,rustic:iron_lattice:1,null,30,rustic:iron_lattice:1,null,30,biomesoplenty:leaves_2:7,null,30,quark:iron_plate_stairs:6,null,10,quark:iron_plate_stairs:0,null,10,quark:iron_plate_stairs:5,null,10,quark:iron_plate_stairs:3,null,10,quark:iron_plate_slab:8,null,10,quark:iron_plate_stairs:7,null,10,quark:iron_plate_stairs:1,null,10,quark:iron_plate_slab:0,null,10,quark:iron_plate_stairs:4,null,10,quark:iron_plate_stairs:2,null,10,rustic:iron_lattice:1,null,50,rustic:iron_lattice:1,null,50,biomesoplenty:leaves_2:7,null,100)
Block(5,8,-2,AIR:0)
RandomBlock(5,8,-1,quark:iron_plate:1,null,70,STAINED_CLAY:15,null,30,STAINED_CLAY:7,null,30,quark:iron_plate:1,null,100)
Block(5,9,-3,COBBLESTONE_STAIRS:2)
RandomBlock(5,9,-2,quark:iron_plate:1,null,70,STAINED_CLAY:15,null,30,STAINED_CLAY:7,null,30,quark:iron_plate:1,null,100)
Block(5,9,-1,COBBLESTONE_STAIRS:3)
Block(6,0,-4,quark:limestone:0)
Block(6,0,-3,quark:limestone:0)
Block(6,0,-2,quark:limestone:0)
Block(6,0,-1,quark:limestone:0)
Block(6,0,0,quark:limestone:0)
Block(6,1,-4,COBBLESTONE_STAIRS:2)
Block(6,1,-3,COBBLESTONE_STAIRS:0)
Block(6,1,-2,COBBLESTONE_STAIRS:0)
Block(6,1,-1,COBBLESTONE_STAIRS:0)
Block(6,1,0,COBBLESTONE_STAIRS:3)
Block(6,6,-3,COBBLESTONE_STAIRS:6)
RandomBlock(6,6,-2,quark:iron_plate:1,null,70,STAINED_CLAY:15,null,30,STAINED_CLAY:7,null,30,quark:iron_plate:1,null,100)
Block(6,6,-1,COBBLESTONE_STAIRS:7)
RandomBlock(6,7,-3,rustic:iron_lattice:1,null,30,rustic:iron_lattice:1,null,30,biomesoplenty:leaves_2:7,null,30,quark:iron_plate_stairs:6,null,10,quark:iron_plate_stairs:0,null,10,quark:iron_plate_stairs:5,null,10,quark:iron_plate_stairs:3,null,10,quark:iron_plate_slab:8,null,10,quark:iron_plate_stairs:7,null,10,quark:iron_plate_stairs:1,null,10,quark:iron_plate_slab:0,null,10,quark:iron_plate_stairs:4,null,10,quark:iron_plate_stairs:2,null,10,rustic:iron_lattice:1,null,50,rustic:iron_lattice:1,null,50,biomesoplenty:leaves_2:7,null,100)
Block(6,7,-2,AIR:0)
RandomBlock(6,7,-1,quark:iron_plate:1,null,70,STAINED_CLAY:15,null,30,STAINED_CLAY:7,null,30,quark:iron_plate:1,null,100)
RandomBlock(6,8,-3,rustic:iron_lattice:1,null,30,rustic:iron_lattice:1,null,30,biomesoplenty:leaves_2:7,null,30,quark:iron_plate_stairs:6,null,10,quark:iron_plate_stairs:0,null,10,quark:iron_plate_stairs:5,null,10,quark:iron_plate_stairs:3,null,10,quark:iron_plate_slab:8,null,10,quark:iron_plate_stairs:7,null,10,quark:iron_plate_stairs:1,null,10,quark:iron_plate_slab:0,null,10,quark:iron_plate_stairs:4,null,10,quark:iron_plate_stairs:2,null,10,rustic:iron_lattice:1,null,50,rustic:iron_lattice:1,null,50,biomesoplenty:leaves_2:7,null,100)
Block(6,8,-2,AIR:0)
RandomBlock(6,8,-1,quark:iron_plate:1,null,70,STAINED_CLAY:15,null,30,STAINED_CLAY:7,null,30,quark:iron_plate:1,null,100)
Block(6,9,-3,COBBLESTONE_STAIRS:2)
RandomBlock(6,9,-2,quark:iron_plate:1,null,70,STAINED_CLAY:15,null,30,STAINED_CLAY:7,null,30,quark:iron_plate:1,null,100)
Block(6,9,-1,COBBLESTONE_STAIRS:3)
Block(7,0,-4,quark:limestone:0)
RandomBlock(7,0,-3,quark:iron_plate:1,null,70,STAINED_CLAY:15,null,30,STAINED_CLAY:7,null,30,quark:iron_plate:1,null,100)
RandomBlock(7,0,-2,quark:iron_plate:1,null,70,STAINED_CLAY:15,null,30,STAINED_CLAY:7,null,30,quark:iron_plate:1,null,100)
RandomBlock(7,0,-1,quark:iron_plate:1,null,70,STAINED_CLAY:15,null,30,STAINED_CLAY:7,null,30,quark:iron_plate:1,null,100)
Block(7,0,0,quark:limestone:0)
Block(7,1,-4,COBBLESTONE_STAIRS:2)
RandomBlock(7,1,-3,quark:iron_plate:1,null,70,STAINED_CLAY:15,null,30,STAINED_CLAY:7,null,30,quark:iron_plate:1,null,100)
RandomBlock(7,1,-2,quark:iron_plate:1,null,70,STAINED_CLAY:15,null,30,STAINED_CLAY:7,null,30,quark:iron_plate:1,null,100)
RandomBlock(7,1,-1,quark:iron_plate:1,null,70,STAINED_CLAY:15,null,30,STAINED_CLAY:7,null,30,quark:iron_plate:1,null,100)
Block(7,1,0,COBBLESTONE_STAIRS:3)
RandomBlock(7,2,-3,quark:iron_plate:1,null,70,STAINED_CLAY:15,null,30,STAINED_CLAY:7,null,30,quark:iron_plate:1,null,100)
RandomBlock(7,2,-2,quark:iron_plate:1,null,70,STAINED_CLAY:15,null,30,STAINED_CLAY:7,null,30,quark:iron_plate:1,null,100)
RandomBlock(7,2,-1,quark:iron_plate:1,null,70,STAINED_CLAY:15,null,30,STAINED_CLAY:7,null,30,quark:iron_plate:1,null,100)
RandomBlock(7,3,-3,quark:iron_plate:1,null,70,STAINED_CLAY:15,null,30,STAINED_CLAY:7,null,30,quark:iron_plate:1,null,100)
RandomBlock(7,3,-2,quark:iron_plate:1,null,70,STAINED_CLAY:15,null,30,STAINED_CLAY:7,null,30,quark:iron_plate:1,null,100)
RandomBlock(7,3,-1,quark:iron_plate:1,null,70,STAINED_CLAY:15,null,30,STAINED_CLAY:7,null,30,quark:iron_plate:1,null,100)
RandomBlock(7,4,-3,quark:iron_plate:1,null,70,STAINED_CLAY:15,null,30,STAINED_CLAY:7,null,30,quark:iron_plate:1,null,100)
RandomBlock(7,4,-2,quark:iron_plate:1,null,70,STAINED_CLAY:15,null,30,STAINED_CLAY:7,null,30,quark:iron_plate:1,null,100)
RandomBlock(7,4,-1,quark:iron_plate:1,null,70,STAINED_CLAY:15,null,30,STAINED_CLAY:7,null,30,quark:iron_plate:1,null,100)
RandomBlock(7,5,-3,quark:iron_plate:1,null,70,STAINED_CLAY:15,null,30,STAINED_CLAY:7,null,30,quark:iron_plate:1,null,100)
RandomBlock(7,5,-2,quark:iron_plate:1,null,70,STAINED_CLAY:15,null,30,STAINED_CLAY:7,null,30,quark:iron_plate:1,null,100)
RandomBlock(7,5,-1,quark:iron_plate:1,null,70,STAINED_CLAY:15,null,30,STAINED_CLAY:7,null,30,quark:iron_plate:1,null,100)
RandomBlock(7,6,-3,quark:iron_plate:1,null,70,STAINED_CLAY:15,null,30,STAINED_CLAY:7,null,30,quark:iron_plate:1,null,100)
RandomBlock(7,6,-2,quark:iron_plate:1,null,70,STAINED_CLAY:15,null,30,STAINED_CLAY:7,null,30,quark:iron_plate:1,null,100)
RandomBlock(7,6,-1,quark:iron_plate:1,null,70,STAINED_CLAY:15,null,30,STAINED_CLAY:7,null,30,quark:iron_plate:1,null,100)
RandomBlock(7,7,-3,rustic:iron_lattice:1,null,30,rustic:iron_lattice:1,null,30,biomesoplenty:leaves_2:7,null,30,quark:iron_plate_stairs:6,null,10,quark:iron_plate_stairs:0,null,10,quark:iron_plate_stairs:5,null,10,quark:iron_plate_stairs:3,null,10,quark:iron_plate_slab:8,null,10,quark:iron_plate_stairs:7,null,10,quark:iron_plate_stairs:1,null,10,quark:iron_plate_slab:0,null,10,quark:iron_plate_stairs:4,null,10,quark:iron_plate_stairs:2,null,10,rustic:iron_lattice:1,null,50,rustic:iron_lattice:1,null,50,biomesoplenty:leaves_2:7,null,100)
Block(7,7,-2,AIR:0)
RandomBlock(7,7,-1,quark:iron_plate:1,null,70,STAINED_CLAY:15,null,30,STAINED_CLAY:7,null,30,quark:iron_plate:1,null,100)
RandomBlock(7,8,-3,rustic:iron_lattice:1,null,30,rustic:iron_lattice:1,null,30,biomesoplenty:leaves_2:7,null,30,quark:iron_plate_stairs:6,null,10,quark:iron_plate_stairs:0,null,10,quark:iron_plate_stairs:5,null,10,quark:iron_plate_stairs:3,null,10,quark:iron_plate_slab:8,null,10,quark:iron_plate_stairs:7,null,10,quark:iron_plate_stairs:1,null,10,quark:iron_plate_slab:0,null,10,quark:iron_plate_stairs:4,null,10,quark:iron_plate_stairs:2,null,10,rustic:iron_lattice:1,null,50,rustic:iron_lattice:1,null,50,biomesoplenty:leaves_2:7,null,100)
Block(7,8,-2,AIR:0)
RandomBlock(7,8,-1,quark:iron_plate:1,null,70,STAINED_CLAY:15,null,30,STAINED_CLAY:7,null,30,quark:iron_plate:1,null,100)
RandomBlock(7,9,-3,rustic:iron_lattice:1,null,30,rustic:iron_lattice:1,null,30,biomesoplenty:leaves_2:7,null,30,quark:iron_plate_stairs:6,null,10,quark:iron_plate_stairs:0,null,10,quark:iron_plate_stairs:5,null,10,quark:iron_plate_stairs:3,null,10,quark:iron_plate_slab:8,null,10,quark:iron_plate_stairs:7,null,10,quark:iron_plate_stairs:1,null,10,quark:iron_plate_slab:0,null,10,quark:iron_plate_stairs:4,null,10,quark:iron_plate_stairs:2,null,10,rustic:iron_lattice:1,null,50,rustic:iron_lattice:1,null,50,biomesoplenty:leaves_2:7,null,100)
RandomBlock(7,9,-2,quark:iron_plate:1,null,70,STAINED_CLAY:15,null,30,STAINED_CLAY:7,null,30,quark:iron_plate:1,null,100)
RandomBlock(7,9,-1,quark:iron_plate:1,null,70,STAINED_CLAY:15,null,30,STAINED_CLAY:7,null,30,quark:iron_plate:1,null,100)
Block(7,10,-3,quark:iron_plate_slab:0)
Block(7,10,-2,quark:iron_plate_slab:0)
Block(7,10,-1,quark:iron_plate_slab:0)

#######################################################################
# +-----------------------------------------------------------------+ #
# |                             Branches                            | #
# +-----------------------------------------------------------------+ #
#######################################################################

Branch(16,0,0,true,brutal_pipebig_04C2R0,NORTH,100.0,0)

#######################################################################
# +-----------------------------------------------------------------+ #
# |                             Entities                            | #
# +-----------------------------------------------------------------+ #
#######################################################################


#######################################################################
# +-----------------------------------------------------------------+ #
# |                            Particles                            | #
# +-----------------------------------------------------------------+ #
#######################################################################


#######################################################################
# +-----------------------------------------------------------------+ #
# |                             Spawners                            | #
# +-----------------------------------------------------------------+ #
#######################################################################


#######################################################################
# +-----------------------------------------------------------------+ #
# |                             ModData                             | #
# +-----------------------------------------------------------------+ #
#######################################################################

