
#######################################################################
# +-----------------------------------------------------------------+ #
# |                            BO4 object                           | #
# +-----------------------------------------------------------------+ #
#######################################################################

Author: NLBlackEagle

Description: No description given

SettingsMode: WriteWithoutComments


#######################################################################
# +-----------------------------------------------------------------+ #
# |                          Main settings                          | #
# +-----------------------------------------------------------------+ #
#######################################################################

FixedRotation: 

Frequency: 0

SpawnHeight: randomY

UseCenterForHighestBlock: true

##############################
# Height Limits for the BO4. #
##############################

MinHeight: 78

MaxHeight: 78

InheritBO3: 

InheritBO3Rotation: NORTH

OverrideChildSettings: true

OverrideParentHeight: false

CanOverride: true

BranchFrequency: 0

BranchFrequencyGroup: 

MustBeBelowOther: false

MustBeInside: 

CannotBeInside: 

ReplacesBO3: 

MustBeInsideWorldBorders: false

CanSpawnOnWater: true

SpawnOnWaterOnly: false

SpawnUnderWater: false

SpawnAtWaterLevel: false

HeightOffset: 0

RemoveAir: false

ReplaceAbove: 

ReplaceBelow: 

ReplaceWithBiomeBlocks: true

ReplaceWithSurfaceBlock: GRASS

ReplaceWithGroundBlock: DIRT

ReplaceWithStoneBlock: STONE

SmoothRadius: 0

SmoothHeightOffset: 0

SmoothStartTop: false

SmoothStartWood: false

SmoothingSurfaceBlock: 

SmoothingGroundBlock: 

BO3Group: 

IsSpawnPoint: false

DoReplaceBlocks: false


#######################################################################
# +-----------------------------------------------------------------+ #
# |                              Blocks                             | #
# +-----------------------------------------------------------------+ #
#######################################################################

Block(-8,4,5,COBBLESTONE_STAIRS:6)
RandomBlock(-8,4,6,quark:iron_plate:1,null,70,STAINED_CLAY:15,null,30,STAINED_CLAY:7,null,30,quark:iron_plate:1,null,100)
RandomBlock(-8,4,7,quark:iron_plate:1,null,70,STAINED_CLAY:15,null,30,STAINED_CLAY:7,null,30,quark:iron_plate:1,null,100)
Block(-8,4,8,COBBLESTONE_STAIRS:7)
RandomBlock(-8,5,5,quark:iron_plate:1,null,70,STAINED_CLAY:15,null,30,STAINED_CLAY:7,null,30,quark:iron_plate:1,null,100)
Block(-8,5,6,AIR:0)
Block(-8,5,7,AIR:0)
RandomBlock(-8,5,8,quark:iron_plate:1,null,70,STAINED_CLAY:15,null,30,STAINED_CLAY:7,null,30,quark:iron_plate:1,null,100)
RandomBlock(-8,6,5,rustic:iron_lattice:1,null,30,rustic:iron_lattice:1,null,30,biomesoplenty:leaves_2:7,null,30,quark:iron_plate_stairs:6,null,10,quark:iron_plate_stairs:0,null,10,quark:iron_plate_stairs:5,null,10,quark:iron_plate_stairs:3,null,10,quark:iron_plate_slab:8,null,10,quark:iron_plate_stairs:7,null,10,quark:iron_plate_stairs:1,null,10,quark:iron_plate_slab:0,null,10,quark:iron_plate_stairs:4,null,10,quark:iron_plate_stairs:2,null,10,rustic:iron_lattice:1,null,50,rustic:iron_lattice:1,null,50,biomesoplenty:leaves_2:7,null,100)
Block(-8,6,6,AIR:0)
Block(-8,6,7,AIR:0)
RandomBlock(-8,6,8,quark:iron_plate:1,null,70,STAINED_CLAY:15,null,30,STAINED_CLAY:7,null,30,quark:iron_plate:1,null,100)
Block(-8,7,5,COBBLESTONE_STAIRS:2)
RandomBlock(-8,7,6,rustic:iron_lattice:1,null,30,rustic:iron_lattice:1,null,30,biomesoplenty:leaves_2:7,null,30,quark:iron_plate_stairs:6,null,10,quark:iron_plate_stairs:0,null,10,quark:iron_plate_stairs:5,null,10,quark:iron_plate_stairs:3,null,10,quark:iron_plate_slab:8,null,10,quark:iron_plate_stairs:7,null,10,quark:iron_plate_stairs:1,null,10,quark:iron_plate_slab:0,null,10,quark:iron_plate_stairs:4,null,10,quark:iron_plate_stairs:2,null,10,rustic:iron_lattice:1,null,50,rustic:iron_lattice:1,null,50,biomesoplenty:leaves_2:7,null,100)
RandomBlock(-8,7,7,rustic:iron_lattice:1,null,30,rustic:iron_lattice:1,null,30,biomesoplenty:leaves_2:7,null,30,quark:iron_plate_stairs:6,null,10,quark:iron_plate_stairs:0,null,10,quark:iron_plate_stairs:5,null,10,quark:iron_plate_stairs:3,null,10,quark:iron_plate_slab:8,null,10,quark:iron_plate_stairs:7,null,10,quark:iron_plate_stairs:1,null,10,quark:iron_plate_slab:0,null,10,quark:iron_plate_stairs:4,null,10,quark:iron_plate_stairs:2,null,10,rustic:iron_lattice:1,null,50,rustic:iron_lattice:1,null,50,biomesoplenty:leaves_2:7,null,100)
Block(-8,7,8,COBBLESTONE_STAIRS:3)
Block(-7,4,-1,COBBLESTONE_STAIRS:6)
Block(-7,4,0,COBBLESTONE_STAIRS:4)
Block(-7,4,1,COBBLESTONE_STAIRS:4)
Block(-7,4,2,COBBLESTONE_STAIRS:4)
Block(-7,4,3,COBBLESTONE_STAIRS:4)
Block(-7,4,4,COBBLESTONE_STAIRS:4)
Block(-7,4,5,COBBLESTONE_STAIRS:6)
RandomBlock(-7,4,6,quark:iron_plate:1,null,70,STAINED_CLAY:15,null,30,STAINED_CLAY:7,null,30,quark:iron_plate:1,null,100)
RandomBlock(-7,4,7,quark:iron_plate:1,null,70,STAINED_CLAY:15,null,30,STAINED_CLAY:7,null,30,quark:iron_plate:1,null,100)
Block(-7,4,8,COBBLESTONE_STAIRS:7)
RandomBlock(-7,5,-1,rustic:iron_lattice:1,null,30,rustic:iron_lattice:1,null,30,biomesoplenty:leaves_2:7,null,30,quark:iron_plate_stairs:6,null,10,quark:iron_plate_stairs:0,null,10,quark:iron_plate_stairs:5,null,10,quark:iron_plate_stairs:3,null,10,quark:iron_plate_slab:8,null,10,quark:iron_plate_stairs:7,null,10,quark:iron_plate_stairs:1,null,10,quark:iron_plate_slab:0,null,10,quark:iron_plate_stairs:4,null,10,quark:iron_plate_stairs:2,null,10,rustic:iron_lattice:1,null,50,rustic:iron_lattice:1,null,50,biomesoplenty:leaves_2:7,null,100)
RandomBlock(-7,5,0,quark:iron_plate:1,null,70,STAINED_CLAY:15,null,30,STAINED_CLAY:7,null,30,quark:iron_plate:1,null,100)
RandomBlock(-7,5,1,quark:iron_plate:1,null,70,STAINED_CLAY:15,null,30,STAINED_CLAY:7,null,30,quark:iron_plate:1,null,100)
RandomBlock(-7,5,2,quark:iron_plate:1,null,70,STAINED_CLAY:15,null,30,STAINED_CLAY:7,null,30,quark:iron_plate:1,null,100)
RandomBlock(-7,5,3,quark:iron_plate:1,null,70,STAINED_CLAY:15,null,30,STAINED_CLAY:7,null,30,quark:iron_plate:1,null,100)
RandomBlock(-7,5,4,quark:iron_plate:1,null,70,STAINED_CLAY:15,null,30,STAINED_CLAY:7,null,30,quark:iron_plate:1,null,100)
RandomBlock(-7,5,5,quark:iron_plate:1,null,70,STAINED_CLAY:15,null,30,STAINED_CLAY:7,null,30,quark:iron_plate:1,null,100)
Block(-7,5,6,AIR:0)
Block(-7,5,7,AIR:0)
RandomBlock(-7,5,8,quark:iron_plate:1,null,70,STAINED_CLAY:15,null,30,STAINED_CLAY:7,null,30,quark:iron_plate:1,null,100)
RandomBlock(-7,6,-1,quark:iron_plate:1,null,70,STAINED_CLAY:15,null,30,STAINED_CLAY:7,null,30,quark:iron_plate:1,null,100)
RandomBlock(-7,6,0,quark:iron_plate:1,null,70,STAINED_CLAY:15,null,30,STAINED_CLAY:7,null,30,quark:iron_plate:1,null,100)
RandomBlock(-7,6,1,quark:iron_plate:1,null,70,STAINED_CLAY:15,null,30,STAINED_CLAY:7,null,30,quark:iron_plate:1,null,100)
RandomBlock(-7,6,2,quark:iron_plate:1,null,70,STAINED_CLAY:15,null,30,STAINED_CLAY:7,null,30,quark:iron_plate:1,null,100)
RandomBlock(-7,6,3,quark:iron_plate:1,null,70,STAINED_CLAY:15,null,30,STAINED_CLAY:7,null,30,quark:iron_plate:1,null,100)
RandomBlock(-7,6,4,quark:iron_plate:1,null,70,STAINED_CLAY:15,null,30,STAINED_CLAY:7,null,30,quark:iron_plate:1,null,100)
RandomBlock(-7,6,5,quark:iron_plate:1,null,70,STAINED_CLAY:15,null,30,STAINED_CLAY:7,null,30,quark:iron_plate:1,null,100)
Block(-7,6,6,AIR:0)
Block(-7,6,7,AIR:0)
RandomBlock(-7,6,8,quark:iron_plate:1,null,70,STAINED_CLAY:15,null,30,STAINED_CLAY:7,null,30,quark:iron_plate:1,null,100)
Block(-7,7,-1,COBBLESTONE_STAIRS:2)
Block(-7,7,0,COBBLESTONE_STAIRS:0)
Block(-7,7,1,COBBLESTONE_STAIRS:0)
Block(-7,7,2,COBBLESTONE_STAIRS:0)
Block(-7,7,3,COBBLESTONE_STAIRS:0)
Block(-7,7,4,COBBLESTONE_STAIRS:0)
Block(-7,7,5,COBBLESTONE_STAIRS:2)
RandomBlock(-7,7,6,quark:iron_plate:1,null,70,STAINED_CLAY:15,null,30,STAINED_CLAY:7,null,30,quark:iron_plate:1,null,100)
RandomBlock(-7,7,7,rustic:iron_lattice:1,null,30,rustic:iron_lattice:1,null,30,biomesoplenty:leaves_2:7,null,30,quark:iron_plate_stairs:6,null,10,quark:iron_plate_stairs:0,null,10,quark:iron_plate_stairs:5,null,10,quark:iron_plate_stairs:3,null,10,quark:iron_plate_slab:8,null,10,quark:iron_plate_stairs:7,null,10,quark:iron_plate_stairs:1,null,10,quark:iron_plate_slab:0,null,10,quark:iron_plate_stairs:4,null,10,quark:iron_plate_stairs:2,null,10,rustic:iron_lattice:1,null,50,rustic:iron_lattice:1,null,50,biomesoplenty:leaves_2:7,null,100)
Block(-7,7,8,COBBLESTONE_STAIRS:3)
Block(-6,4,-1,COBBLESTONE_STAIRS:6)
RandomBlock(-6,4,0,quark:iron_plate:1,null,70,STAINED_CLAY:15,null,30,STAINED_CLAY:7,null,30,quark:iron_plate:1,null,100)
RandomBlock(-6,4,1,quark:iron_plate:1,null,70,STAINED_CLAY:15,null,30,STAINED_CLAY:7,null,30,quark:iron_plate:1,null,100)
RandomBlock(-6,4,2,quark:iron_plate:1,null,70,STAINED_CLAY:15,null,30,STAINED_CLAY:7,null,30,quark:iron_plate:1,null,100)
RandomBlock(-6,4,3,quark:iron_plate:1,null,70,STAINED_CLAY:15,null,30,STAINED_CLAY:7,null,30,quark:iron_plate:1,null,100)
RandomBlock(-6,4,4,quark:iron_plate:1,null,70,STAINED_CLAY:15,null,30,STAINED_CLAY:7,null,30,quark:iron_plate:1,null,100)
RandomBlock(-6,4,5,quark:iron_plate:1,null,70,STAINED_CLAY:15,null,30,STAINED_CLAY:7,null,30,quark:iron_plate:1,null,100)
RandomBlock(-6,4,6,quark:iron_plate:1,null,70,STAINED_CLAY:15,null,30,STAINED_CLAY:7,null,30,quark:iron_plate:1,null,100)
RandomBlock(-6,4,7,quark:iron_plate:1,null,70,STAINED_CLAY:15,null,30,STAINED_CLAY:7,null,30,quark:iron_plate:1,null,100)
Block(-6,4,8,COBBLESTONE_STAIRS:7)
RandomBlock(-6,5,-1,rustic:iron_lattice:1,null,30,rustic:iron_lattice:1,null,30,biomesoplenty:leaves_2:7,null,30,quark:iron_plate_stairs:6,null,10,quark:iron_plate_stairs:0,null,10,quark:iron_plate_stairs:5,null,10,quark:iron_plate_stairs:3,null,10,quark:iron_plate_slab:8,null,10,quark:iron_plate_stairs:7,null,10,quark:iron_plate_stairs:1,null,10,quark:iron_plate_slab:0,null,10,quark:iron_plate_stairs:4,null,10,quark:iron_plate_stairs:2,null,10,rustic:iron_lattice:1,null,50,rustic:iron_lattice:1,null,50,biomesoplenty:leaves_2:7,null,100)
Block(-6,5,0,AIR:0)
Block(-6,5,1,AIR:0)
Block(-6,5,2,AIR:0)
Block(-6,5,3,AIR:0)
Block(-6,5,4,AIR:0)
Block(-6,5,5,AIR:0)
Block(-6,5,6,AIR:0)
Block(-6,5,7,AIR:0)
RandomBlock(-6,5,8,quark:iron_plate:1,null,70,STAINED_CLAY:15,null,30,STAINED_CLAY:7,null,30,quark:iron_plate:1,null,100)
RandomBlock(-6,6,-1,rustic:iron_lattice:1,null,30,rustic:iron_lattice:1,null,30,biomesoplenty:leaves_2:7,null,30,quark:iron_plate_stairs:6,null,10,quark:iron_plate_stairs:0,null,10,quark:iron_plate_stairs:5,null,10,quark:iron_plate_stairs:3,null,10,quark:iron_plate_slab:8,null,10,quark:iron_plate_stairs:7,null,10,quark:iron_plate_stairs:1,null,10,quark:iron_plate_slab:0,null,10,quark:iron_plate_stairs:4,null,10,quark:iron_plate_stairs:2,null,10,rustic:iron_lattice:1,null,50,rustic:iron_lattice:1,null,50,biomesoplenty:leaves_2:7,null,100)
Block(-6,6,0,AIR:0)
Block(-6,6,1,AIR:0)
Block(-6,6,2,AIR:0)
Block(-6,6,3,AIR:0)
Block(-6,6,4,AIR:0)
Block(-6,6,5,AIR:0)
Block(-6,6,6,AIR:0)
Block(-6,6,7,AIR:0)
RandomBlock(-6,6,8,quark:iron_plate:1,null,70,STAINED_CLAY:15,null,30,STAINED_CLAY:7,null,30,quark:iron_plate:1,null,100)
Block(-6,7,-1,COBBLESTONE_STAIRS:2)
RandomBlock(-6,7,0,quark:iron_plate:1,null,70,STAINED_CLAY:15,null,30,STAINED_CLAY:7,null,30,quark:iron_plate:1,null,100)
RandomBlock(-6,7,1,quark:iron_plate:1,null,70,STAINED_CLAY:15,null,30,STAINED_CLAY:7,null,30,quark:iron_plate:1,null,100)
RandomBlock(-6,7,2,quark:iron_plate:1,null,70,STAINED_CLAY:15,null,30,STAINED_CLAY:7,null,30,quark:iron_plate:1,null,100)
RandomBlock(-6,7,3,quark:iron_plate:1,null,70,STAINED_CLAY:15,null,30,STAINED_CLAY:7,null,30,quark:iron_plate:1,null,100)
RandomBlock(-6,7,4,quark:iron_plate:1,null,70,STAINED_CLAY:15,null,30,STAINED_CLAY:7,null,30,quark:iron_plate:1,null,100)
RandomBlock(-6,7,5,quark:iron_plate:1,null,70,STAINED_CLAY:15,null,30,STAINED_CLAY:7,null,30,quark:iron_plate:1,null,100)
RandomBlock(-6,7,6,quark:iron_plate:1,null,70,STAINED_CLAY:15,null,30,STAINED_CLAY:7,null,30,quark:iron_plate:1,null,100)
RandomBlock(-6,7,7,quark:iron_plate:1,null,70,STAINED_CLAY:15,null,30,STAINED_CLAY:7,null,30,quark:iron_plate:1,null,100)
Block(-6,7,8,COBBLESTONE_STAIRS:3)
Block(-5,4,-1,COBBLESTONE_STAIRS:6)
RandomBlock(-5,4,0,quark:iron_plate:1,null,70,STAINED_CLAY:15,null,30,STAINED_CLAY:7,null,30,quark:iron_plate:1,null,100)
RandomBlock(-5,4,1,quark:iron_plate:1,null,70,STAINED_CLAY:15,null,30,STAINED_CLAY:7,null,30,quark:iron_plate:1,null,100)
RandomBlock(-5,4,2,quark:iron_plate:1,null,70,STAINED_CLAY:15,null,30,STAINED_CLAY:7,null,30,quark:iron_plate:1,null,100)
RandomBlock(-5,4,3,quark:iron_plate:1,null,70,STAINED_CLAY:15,null,30,STAINED_CLAY:7,null,30,quark:iron_plate:1,null,100)
RandomBlock(-5,4,4,quark:iron_plate:1,null,70,STAINED_CLAY:15,null,30,STAINED_CLAY:7,null,30,quark:iron_plate:1,null,100)
RandomBlock(-5,4,5,quark:iron_plate:1,null,70,STAINED_CLAY:15,null,30,STAINED_CLAY:7,null,30,quark:iron_plate:1,null,100)
RandomBlock(-5,4,6,quark:iron_plate:1,null,70,STAINED_CLAY:15,null,30,STAINED_CLAY:7,null,30,quark:iron_plate:1,null,100)
RandomBlock(-5,4,7,quark:iron_plate:1,null,70,STAINED_CLAY:15,null,30,STAINED_CLAY:7,null,30,quark:iron_plate:1,null,100)
Block(-5,4,8,COBBLESTONE_STAIRS:7)
RandomBlock(-5,5,-1,rustic:iron_lattice:1,null,30,rustic:iron_lattice:1,null,30,biomesoplenty:leaves_2:7,null,30,quark:iron_plate_stairs:6,null,10,quark:iron_plate_stairs:0,null,10,quark:iron_plate_stairs:5,null,10,quark:iron_plate_stairs:3,null,10,quark:iron_plate_slab:8,null,10,quark:iron_plate_stairs:7,null,10,quark:iron_plate_stairs:1,null,10,quark:iron_plate_slab:0,null,10,quark:iron_plate_stairs:4,null,10,quark:iron_plate_stairs:2,null,10,rustic:iron_lattice:1,null,50,rustic:iron_lattice:1,null,50,biomesoplenty:leaves_2:7,null,100)
Block(-5,5,0,AIR:0)
Block(-5,5,1,AIR:0)
Block(-5,5,2,AIR:0)
Block(-5,5,3,AIR:0)
Block(-5,5,4,AIR:0)
Block(-5,5,5,AIR:0)
Block(-5,5,6,AIR:0)
Block(-5,5,7,AIR:0)
RandomBlock(-5,5,8,quark:iron_plate:1,null,70,STAINED_CLAY:15,null,30,STAINED_CLAY:7,null,30,quark:iron_plate:1,null,100)
RandomBlock(-5,6,-1,rustic:iron_lattice:1,null,30,rustic:iron_lattice:1,null,30,biomesoplenty:leaves_2:7,null,30,quark:iron_plate_stairs:6,null,10,quark:iron_plate_stairs:0,null,10,quark:iron_plate_stairs:5,null,10,quark:iron_plate_stairs:3,null,10,quark:iron_plate_slab:8,null,10,quark:iron_plate_stairs:7,null,10,quark:iron_plate_stairs:1,null,10,quark:iron_plate_slab:0,null,10,quark:iron_plate_stairs:4,null,10,quark:iron_plate_stairs:2,null,10,rustic:iron_lattice:1,null,50,rustic:iron_lattice:1,null,50,biomesoplenty:leaves_2:7,null,100)
Block(-5,6,0,AIR:0)
Block(-5,6,1,AIR:0)
Block(-5,6,2,AIR:0)
Block(-5,6,3,AIR:0)
Block(-5,6,4,AIR:0)
Block(-5,6,5,AIR:0)
Block(-5,6,6,AIR:0)
Block(-5,6,7,AIR:0)
RandomBlock(-5,6,8,quark:iron_plate:1,null,70,STAINED_CLAY:15,null,30,STAINED_CLAY:7,null,30,quark:iron_plate:1,null,100)
Block(-5,7,-1,COBBLESTONE_STAIRS:2)
RandomBlock(-5,7,0,quark:iron_plate:1,null,70,STAINED_CLAY:15,null,30,STAINED_CLAY:7,null,30,quark:iron_plate:1,null,100)
RandomBlock(-5,7,1,quark:iron_plate:1,null,70,STAINED_CLAY:15,null,30,STAINED_CLAY:7,null,30,quark:iron_plate:1,null,100)
RandomBlock(-5,7,2,quark:iron_plate:1,null,70,STAINED_CLAY:15,null,30,STAINED_CLAY:7,null,30,quark:iron_plate:1,null,100)
RandomBlock(-5,7,3,quark:iron_plate:1,null,70,STAINED_CLAY:15,null,30,STAINED_CLAY:7,null,30,quark:iron_plate:1,null,100)
RandomBlock(-5,7,4,quark:iron_plate:1,null,70,STAINED_CLAY:15,null,30,STAINED_CLAY:7,null,30,quark:iron_plate:1,null,100)
RandomBlock(-5,7,5,quark:iron_plate:1,null,70,STAINED_CLAY:15,null,30,STAINED_CLAY:7,null,30,quark:iron_plate:1,null,100)
RandomBlock(-5,7,6,quark:iron_plate:1,null,70,STAINED_CLAY:15,null,30,STAINED_CLAY:7,null,30,quark:iron_plate:1,null,100)
RandomBlock(-5,7,7,quark:iron_plate:1,null,70,STAINED_CLAY:15,null,30,STAINED_CLAY:7,null,30,quark:iron_plate:1,null,100)
Block(-5,7,8,COBBLESTONE_STAIRS:3)
Block(-4,0,0,quark:limestone:0)
Block(-4,0,1,quark:limestone:0)
Block(-4,1,0,quark:basalt_wall:0)
Block(-4,1,1,quark:basalt_wall:0)
Block(-4,2,0,quark:basalt_wall:0)
Block(-4,2,1,quark:basalt_wall:0)
Block(-4,3,0,quark:basalt_wall:0)
Block(-4,3,1,quark:basalt_wall:0)
Block(-4,4,-1,COBBLESTONE_STAIRS:6)
RandomBlock(-4,4,0,quark:iron_plate:1,null,70,STAINED_CLAY:15,null,30,STAINED_CLAY:7,null,30,quark:iron_plate:1,null,100)
RandomBlock(-4,4,1,quark:iron_plate:1,null,70,STAINED_CLAY:15,null,30,STAINED_CLAY:7,null,30,quark:iron_plate:1,null,100)
Block(-4,4,2,COBBLESTONE_STAIRS:7)
Block(-4,4,3,COBBLESTONE_STAIRS:5)
Block(-4,4,4,COBBLESTONE_STAIRS:5)
Block(-4,4,5,COBBLESTONE_STAIRS:5)
Block(-4,4,6,COBBLESTONE_STAIRS:5)
Block(-4,4,7,COBBLESTONE_STAIRS:5)
Block(-4,4,8,COBBLESTONE_STAIRS:7)
RandomBlock(-4,5,-1,rustic:iron_lattice:1,null,30,rustic:iron_lattice:1,null,30,biomesoplenty:leaves_2:7,null,30,quark:iron_plate_stairs:6,null,10,quark:iron_plate_stairs:0,null,10,quark:iron_plate_stairs:5,null,10,quark:iron_plate_stairs:3,null,10,quark:iron_plate_slab:8,null,10,quark:iron_plate_stairs:7,null,10,quark:iron_plate_stairs:1,null,10,quark:iron_plate_slab:0,null,10,quark:iron_plate_stairs:4,null,10,quark:iron_plate_stairs:2,null,10,rustic:iron_lattice:1,null,50,rustic:iron_lattice:1,null,50,biomesoplenty:leaves_2:7,null,100)
Block(-4,5,0,AIR:0)
Block(-4,5,1,AIR:0)
RandomBlock(-4,5,2,quark:iron_plate:1,null,70,STAINED_CLAY:15,null,30,STAINED_CLAY:7,null,30,quark:iron_plate:1,null,100)
RandomBlock(-4,5,3,quark:iron_plate:1,null,70,STAINED_CLAY:15,null,30,STAINED_CLAY:7,null,30,quark:iron_plate:1,null,100)
RandomBlock(-4,5,4,quark:iron_plate:1,null,70,STAINED_CLAY:15,null,30,STAINED_CLAY:7,null,30,quark:iron_plate:1,null,100)
RandomBlock(-4,5,5,quark:iron_plate:1,null,70,STAINED_CLAY:15,null,30,STAINED_CLAY:7,null,30,quark:iron_plate:1,null,100)
RandomBlock(-4,5,6,quark:iron_plate:1,null,70,STAINED_CLAY:15,null,30,STAINED_CLAY:7,null,30,quark:iron_plate:1,null,100)
RandomBlock(-4,5,7,quark:iron_plate:1,null,70,STAINED_CLAY:15,null,30,STAINED_CLAY:7,null,30,quark:iron_plate:1,null,100)
RandomBlock(-4,5,8,quark:iron_plate:1,null,70,STAINED_CLAY:15,null,30,STAINED_CLAY:7,null,30,quark:iron_plate:1,null,100)
RandomBlock(-4,6,-1,rustic:iron_lattice:1,null,30,rustic:iron_lattice:1,null,30,biomesoplenty:leaves_2:7,null,30,quark:iron_plate_stairs:6,null,10,quark:iron_plate_stairs:0,null,10,quark:iron_plate_stairs:5,null,10,quark:iron_plate_stairs:3,null,10,quark:iron_plate_slab:8,null,10,quark:iron_plate_stairs:7,null,10,quark:iron_plate_stairs:1,null,10,quark:iron_plate_slab:0,null,10,quark:iron_plate_stairs:4,null,10,quark:iron_plate_stairs:2,null,10,rustic:iron_lattice:1,null,50,rustic:iron_lattice:1,null,50,biomesoplenty:leaves_2:7,null,100)
Block(-4,6,0,AIR:0)
Block(-4,6,1,AIR:0)
RandomBlock(-4,6,2,quark:iron_plate:1,null,70,STAINED_CLAY:15,null,30,STAINED_CLAY:7,null,30,quark:iron_plate:1,null,100)
RandomBlock(-4,6,3,quark:iron_plate:1,null,70,STAINED_CLAY:15,null,30,STAINED_CLAY:7,null,30,quark:iron_plate:1,null,100)
RandomBlock(-4,6,4,quark:iron_plate:1,null,70,STAINED_CLAY:15,null,30,STAINED_CLAY:7,null,30,quark:iron_plate:1,null,100)
RandomBlock(-4,6,5,quark:iron_plate:1,null,70,STAINED_CLAY:15,null,30,STAINED_CLAY:7,null,30,quark:iron_plate:1,null,100)
RandomBlock(-4,6,6,quark:iron_plate:1,null,70,STAINED_CLAY:15,null,30,STAINED_CLAY:7,null,30,quark:iron_plate:1,null,100)
RandomBlock(-4,6,7,quark:iron_plate:1,null,70,STAINED_CLAY:15,null,30,STAINED_CLAY:7,null,30,quark:iron_plate:1,null,100)
RandomBlock(-4,6,8,quark:iron_plate:1,null,70,STAINED_CLAY:15,null,30,STAINED_CLAY:7,null,30,quark:iron_plate:1,null,100)
Block(-4,7,-1,COBBLESTONE_STAIRS:2)
RandomBlock(-4,7,0,quark:iron_plate:1,null,70,STAINED_CLAY:15,null,30,STAINED_CLAY:7,null,30,quark:iron_plate:1,null,100)
RandomBlock(-4,7,1,quark:iron_plate:1,null,70,STAINED_CLAY:15,null,30,STAINED_CLAY:7,null,30,quark:iron_plate:1,null,100)
Block(-4,7,2,COBBLESTONE_STAIRS:1)
Block(-4,7,3,COBBLESTONE_STAIRS:1)
Block(-4,7,4,COBBLESTONE_STAIRS:1)
Block(-4,7,5,COBBLESTONE_STAIRS:1)
Block(-4,7,6,COBBLESTONE_STAIRS:1)
Block(-4,7,7,COBBLESTONE_STAIRS:1)
Block(-4,7,8,COBBLESTONE_STAIRS:3)
Block(-3,4,-1,COBBLESTONE_STAIRS:6)
RandomBlock(-3,4,0,quark:iron_plate:1,null,70,STAINED_CLAY:15,null,30,STAINED_CLAY:7,null,30,quark:iron_plate:1,null,100)
RandomBlock(-3,4,1,quark:iron_plate:1,null,70,STAINED_CLAY:15,null,30,STAINED_CLAY:7,null,30,quark:iron_plate:1,null,100)
Block(-3,4,2,COBBLESTONE_STAIRS:7)
RandomBlock(-3,5,-1,quark:iron_plate:1,null,70,STAINED_CLAY:15,null,30,STAINED_CLAY:7,null,30,quark:iron_plate:1,null,100)
Block(-3,5,0,AIR:0)
Block(-3,5,1,AIR:0)
RandomBlock(-3,5,2,quark:iron_plate:1,null,70,STAINED_CLAY:15,null,30,STAINED_CLAY:7,null,30,quark:iron_plate:1,null,100)
RandomBlock(-3,6,-1,rustic:iron_lattice:1,null,30,rustic:iron_lattice:1,null,30,biomesoplenty:leaves_2:7,null,30,quark:iron_plate_stairs:6,null,10,quark:iron_plate_stairs:0,null,10,quark:iron_plate_stairs:5,null,10,quark:iron_plate_stairs:3,null,10,quark:iron_plate_slab:8,null,10,quark:iron_plate_stairs:7,null,10,quark:iron_plate_stairs:1,null,10,quark:iron_plate_slab:0,null,10,quark:iron_plate_stairs:4,null,10,quark:iron_plate_stairs:2,null,10,rustic:iron_lattice:1,null,50,rustic:iron_lattice:1,null,50,biomesoplenty:leaves_2:7,null,100)
Block(-3,6,0,AIR:0)
Block(-3,6,1,AIR:0)
RandomBlock(-3,6,2,quark:iron_plate:1,null,70,STAINED_CLAY:15,null,30,STAINED_CLAY:7,null,30,quark:iron_plate:1,null,100)
Block(-3,7,-1,COBBLESTONE_STAIRS:2)
RandomBlock(-3,7,0,quark:iron_plate:1,null,70,STAINED_CLAY:15,null,30,STAINED_CLAY:7,null,30,quark:iron_plate:1,null,100)
RandomBlock(-3,7,1,quark:iron_plate:1,null,70,STAINED_CLAY:15,null,30,STAINED_CLAY:7,null,30,quark:iron_plate:1,null,100)
Block(-3,7,2,COBBLESTONE_STAIRS:3)
Block(-2,4,-1,COBBLESTONE_STAIRS:6)
RandomBlock(-2,4,0,quark:iron_plate:1,null,70,STAINED_CLAY:15,null,30,STAINED_CLAY:7,null,30,quark:iron_plate:1,null,100)
RandomBlock(-2,4,1,quark:iron_plate:1,null,70,STAINED_CLAY:15,null,30,STAINED_CLAY:7,null,30,quark:iron_plate:1,null,100)
Block(-2,4,2,COBBLESTONE_STAIRS:7)
RandomBlock(-2,5,-1,quark:iron_plate:1,null,70,STAINED_CLAY:15,null,30,STAINED_CLAY:7,null,30,quark:iron_plate:1,null,100)
Block(-2,5,0,AIR:0)
Block(-2,5,1,AIR:0)
RandomBlock(-2,5,2,quark:iron_plate:1,null,70,STAINED_CLAY:15,null,30,STAINED_CLAY:7,null,30,quark:iron_plate:1,null,100)
RandomBlock(-2,6,-1,rustic:iron_lattice:1,null,30,rustic:iron_lattice:1,null,30,biomesoplenty:leaves_2:7,null,30,quark:iron_plate_stairs:6,null,10,quark:iron_plate_stairs:0,null,10,quark:iron_plate_stairs:5,null,10,quark:iron_plate_stairs:3,null,10,quark:iron_plate_slab:8,null,10,quark:iron_plate_stairs:7,null,10,quark:iron_plate_stairs:1,null,10,quark:iron_plate_slab:0,null,10,quark:iron_plate_stairs:4,null,10,quark:iron_plate_stairs:2,null,10,rustic:iron_lattice:1,null,50,rustic:iron_lattice:1,null,50,biomesoplenty:leaves_2:7,null,100)
Block(-2,6,0,AIR:0)
Block(-2,6,1,AIR:0)
RandomBlock(-2,6,2,quark:iron_plate:1,null,70,STAINED_CLAY:15,null,30,STAINED_CLAY:7,null,30,quark:iron_plate:1,null,100)
Block(-2,7,-1,COBBLESTONE_STAIRS:2)
RandomBlock(-2,7,0,rustic:iron_lattice:1,null,30,rustic:iron_lattice:1,null,30,biomesoplenty:leaves_2:7,null,30,quark:iron_plate_stairs:6,null,10,quark:iron_plate_stairs:0,null,10,quark:iron_plate_stairs:5,null,10,quark:iron_plate_stairs:3,null,10,quark:iron_plate_slab:8,null,10,quark:iron_plate_stairs:7,null,10,quark:iron_plate_stairs:1,null,10,quark:iron_plate_slab:0,null,10,quark:iron_plate_stairs:4,null,10,quark:iron_plate_stairs:2,null,10,rustic:iron_lattice:1,null,50,rustic:iron_lattice:1,null,50,biomesoplenty:leaves_2:7,null,100)
RandomBlock(-2,7,1,rustic:iron_lattice:1,null,30,rustic:iron_lattice:1,null,30,biomesoplenty:leaves_2:7,null,30,quark:iron_plate_stairs:6,null,10,quark:iron_plate_stairs:0,null,10,quark:iron_plate_stairs:5,null,10,quark:iron_plate_stairs:3,null,10,quark:iron_plate_slab:8,null,10,quark:iron_plate_stairs:7,null,10,quark:iron_plate_stairs:1,null,10,quark:iron_plate_slab:0,null,10,quark:iron_plate_stairs:4,null,10,quark:iron_plate_stairs:2,null,10,rustic:iron_lattice:1,null,50,rustic:iron_lattice:1,null,50,biomesoplenty:leaves_2:7,null,100)
Block(-2,7,2,COBBLESTONE_STAIRS:3)
Block(-1,4,-1,COBBLESTONE_STAIRS:6)
RandomBlock(-1,4,0,quark:iron_plate:1,null,70,STAINED_CLAY:15,null,30,STAINED_CLAY:7,null,30,quark:iron_plate:1,null,100)
RandomBlock(-1,4,1,quark:iron_plate:1,null,70,STAINED_CLAY:15,null,30,STAINED_CLAY:7,null,30,quark:iron_plate:1,null,100)
Block(-1,4,2,COBBLESTONE_STAIRS:7)
RandomBlock(-1,5,-1,quark:iron_plate:1,null,70,STAINED_CLAY:15,null,30,STAINED_CLAY:7,null,30,quark:iron_plate:1,null,100)
Block(-1,5,0,AIR:0)
Block(-1,5,1,AIR:0)
RandomBlock(-1,5,2,quark:iron_plate:1,null,70,STAINED_CLAY:15,null,30,STAINED_CLAY:7,null,30,quark:iron_plate:1,null,100)
RandomBlock(-1,6,-1,quark:iron_plate:1,null,70,STAINED_CLAY:15,null,30,STAINED_CLAY:7,null,30,quark:iron_plate:1,null,100)
Block(-1,6,0,AIR:0)
Block(-1,6,1,AIR:0)
RandomBlock(-1,6,2,rustic:iron_lattice:1,null,30,rustic:iron_lattice:1,null,30,biomesoplenty:leaves_2:7,null,30,quark:iron_plate_stairs:6,null,10,quark:iron_plate_stairs:0,null,10,quark:iron_plate_stairs:5,null,10,quark:iron_plate_stairs:3,null,10,quark:iron_plate_slab:8,null,10,quark:iron_plate_stairs:7,null,10,quark:iron_plate_stairs:1,null,10,quark:iron_plate_slab:0,null,10,quark:iron_plate_stairs:4,null,10,quark:iron_plate_stairs:2,null,10,rustic:iron_lattice:1,null,50,rustic:iron_lattice:1,null,50,biomesoplenty:leaves_2:7,null,100)
Block(-1,7,-1,COBBLESTONE_STAIRS:2)
RandomBlock(-1,7,0,rustic:iron_lattice:1,null,30,rustic:iron_lattice:1,null,30,biomesoplenty:leaves_2:7,null,30,quark:iron_plate_stairs:6,null,10,quark:iron_plate_stairs:0,null,10,quark:iron_plate_stairs:5,null,10,quark:iron_plate_stairs:3,null,10,quark:iron_plate_slab:8,null,10,quark:iron_plate_stairs:7,null,10,quark:iron_plate_stairs:1,null,10,quark:iron_plate_slab:0,null,10,quark:iron_plate_stairs:4,null,10,quark:iron_plate_stairs:2,null,10,rustic:iron_lattice:1,null,50,rustic:iron_lattice:1,null,50,biomesoplenty:leaves_2:7,null,100)
RandomBlock(-1,7,1,rustic:iron_lattice:1,null,30,rustic:iron_lattice:1,null,30,biomesoplenty:leaves_2:7,null,30,quark:iron_plate_stairs:6,null,10,quark:iron_plate_stairs:0,null,10,quark:iron_plate_stairs:5,null,10,quark:iron_plate_stairs:3,null,10,quark:iron_plate_slab:8,null,10,quark:iron_plate_stairs:7,null,10,quark:iron_plate_stairs:1,null,10,quark:iron_plate_slab:0,null,10,quark:iron_plate_stairs:4,null,10,quark:iron_plate_stairs:2,null,10,rustic:iron_lattice:1,null,50,rustic:iron_lattice:1,null,50,biomesoplenty:leaves_2:7,null,100)
Block(-1,7,2,COBBLESTONE_STAIRS:3)
Block(0,4,-1,COBBLESTONE_STAIRS:6)
RandomBlock(0,4,0,quark:iron_plate:1,null,70,STAINED_CLAY:15,null,30,STAINED_CLAY:7,null,30,quark:iron_plate:1,null,100)
RandomBlock(0,4,1,quark:iron_plate:1,null,70,STAINED_CLAY:15,null,30,STAINED_CLAY:7,null,30,quark:iron_plate:1,null,100)
Block(0,4,2,COBBLESTONE_STAIRS:7)
RandomBlock(0,5,-1,quark:iron_plate:1,null,70,STAINED_CLAY:15,null,30,STAINED_CLAY:7,null,30,quark:iron_plate:1,null,100)
Block(0,5,0,AIR:0)
Block(0,5,1,AIR:0)
RandomBlock(0,5,2,rustic:iron_lattice:1,null,30,rustic:iron_lattice:1,null,30,biomesoplenty:leaves_2:7,null,30,quark:iron_plate_stairs:6,null,10,quark:iron_plate_stairs:0,null,10,quark:iron_plate_stairs:5,null,10,quark:iron_plate_stairs:3,null,10,quark:iron_plate_slab:8,null,10,quark:iron_plate_stairs:7,null,10,quark:iron_plate_stairs:1,null,10,quark:iron_plate_slab:0,null,10,quark:iron_plate_stairs:4,null,10,quark:iron_plate_stairs:2,null,10,rustic:iron_lattice:1,null,50,rustic:iron_lattice:1,null,50,biomesoplenty:leaves_2:7,null,100)
RandomBlock(0,6,-1,quark:iron_plate:1,null,70,STAINED_CLAY:15,null,30,STAINED_CLAY:7,null,30,quark:iron_plate:1,null,100)
Block(0,6,0,AIR:0)
Block(0,6,1,AIR:0)
RandomBlock(0,6,2,rustic:iron_lattice:1,null,30,rustic:iron_lattice:1,null,30,biomesoplenty:leaves_2:7,null,30,quark:iron_plate_stairs:6,null,10,quark:iron_plate_stairs:0,null,10,quark:iron_plate_stairs:5,null,10,quark:iron_plate_stairs:3,null,10,quark:iron_plate_slab:8,null,10,quark:iron_plate_stairs:7,null,10,quark:iron_plate_stairs:1,null,10,quark:iron_plate_slab:0,null,10,quark:iron_plate_stairs:4,null,10,quark:iron_plate_stairs:2,null,10,rustic:iron_lattice:1,null,50,rustic:iron_lattice:1,null,50,biomesoplenty:leaves_2:7,null,100)
Block(0,7,-1,COBBLESTONE_STAIRS:2)
RandomBlock(0,7,0,quark:iron_plate:1,null,70,STAINED_CLAY:15,null,30,STAINED_CLAY:7,null,30,quark:iron_plate:1,null,100)
RandomBlock(0,7,1,rustic:iron_lattice:1,null,30,rustic:iron_lattice:1,null,30,biomesoplenty:leaves_2:7,null,30,quark:iron_plate_stairs:6,null,10,quark:iron_plate_stairs:0,null,10,quark:iron_plate_stairs:5,null,10,quark:iron_plate_stairs:3,null,10,quark:iron_plate_slab:8,null,10,quark:iron_plate_stairs:7,null,10,quark:iron_plate_stairs:1,null,10,quark:iron_plate_slab:0,null,10,quark:iron_plate_stairs:4,null,10,quark:iron_plate_stairs:2,null,10,rustic:iron_lattice:1,null,50,rustic:iron_lattice:1,null,50,biomesoplenty:leaves_2:7,null,100)
Block(0,7,2,COBBLESTONE_STAIRS:3)
Block(1,4,-1,COBBLESTONE_STAIRS:6)
RandomBlock(1,4,0,quark:iron_plate:1,null,70,STAINED_CLAY:15,null,30,STAINED_CLAY:7,null,30,quark:iron_plate:1,null,100)
RandomBlock(1,4,1,quark:iron_plate:1,null,70,STAINED_CLAY:15,null,30,STAINED_CLAY:7,null,30,quark:iron_plate:1,null,100)
Block(1,4,2,COBBLESTONE_STAIRS:7)
RandomBlock(1,5,-1,quark:iron_plate:1,null,70,STAINED_CLAY:15,null,30,STAINED_CLAY:7,null,30,quark:iron_plate:1,null,100)
Block(1,5,0,AIR:0)
Block(1,5,1,AIR:0)
RandomBlock(1,5,2,rustic:iron_lattice:1,null,30,rustic:iron_lattice:1,null,30,biomesoplenty:leaves_2:7,null,30,quark:iron_plate_stairs:6,null,10,quark:iron_plate_stairs:0,null,10,quark:iron_plate_stairs:5,null,10,quark:iron_plate_stairs:3,null,10,quark:iron_plate_slab:8,null,10,quark:iron_plate_stairs:7,null,10,quark:iron_plate_stairs:1,null,10,quark:iron_plate_slab:0,null,10,quark:iron_plate_stairs:4,null,10,quark:iron_plate_stairs:2,null,10,rustic:iron_lattice:1,null,50,rustic:iron_lattice:1,null,50,biomesoplenty:leaves_2:7,null,100)
RandomBlock(1,6,-1,quark:iron_plate:1,null,70,STAINED_CLAY:15,null,30,STAINED_CLAY:7,null,30,quark:iron_plate:1,null,100)
Block(1,6,0,AIR:0)
Block(1,6,1,AIR:0)
RandomBlock(1,6,2,rustic:iron_lattice:1,null,30,rustic:iron_lattice:1,null,30,biomesoplenty:leaves_2:7,null,30,quark:iron_plate_stairs:6,null,10,quark:iron_plate_stairs:0,null,10,quark:iron_plate_stairs:5,null,10,quark:iron_plate_stairs:3,null,10,quark:iron_plate_slab:8,null,10,quark:iron_plate_stairs:7,null,10,quark:iron_plate_stairs:1,null,10,quark:iron_plate_slab:0,null,10,quark:iron_plate_stairs:4,null,10,quark:iron_plate_stairs:2,null,10,rustic:iron_lattice:1,null,50,rustic:iron_lattice:1,null,50,biomesoplenty:leaves_2:7,null,100)
Block(1,7,-1,COBBLESTONE_STAIRS:2)
RandomBlock(1,7,0,quark:iron_plate:1,null,70,STAINED_CLAY:15,null,30,STAINED_CLAY:7,null,30,quark:iron_plate:1,null,100)
RandomBlock(1,7,1,quark:iron_plate:1,null,70,STAINED_CLAY:15,null,30,STAINED_CLAY:7,null,30,quark:iron_plate:1,null,100)
Block(1,7,2,COBBLESTONE_STAIRS:3)
Block(2,4,-1,COBBLESTONE_STAIRS:6)
RandomBlock(2,4,0,quark:iron_plate:1,null,70,STAINED_CLAY:15,null,30,STAINED_CLAY:7,null,30,quark:iron_plate:1,null,100)
RandomBlock(2,4,1,quark:iron_plate:1,null,70,STAINED_CLAY:15,null,30,STAINED_CLAY:7,null,30,quark:iron_plate:1,null,100)
Block(2,4,2,COBBLESTONE_STAIRS:7)
RandomBlock(2,5,-1,quark:iron_plate:1,null,70,STAINED_CLAY:15,null,30,STAINED_CLAY:7,null,30,quark:iron_plate:1,null,100)
Block(2,5,0,AIR:0)
Block(2,5,1,AIR:0)
RandomBlock(2,5,2,rustic:iron_lattice:1,null,30,rustic:iron_lattice:1,null,30,biomesoplenty:leaves_2:7,null,30,quark:iron_plate_stairs:6,null,10,quark:iron_plate_stairs:0,null,10,quark:iron_plate_stairs:5,null,10,quark:iron_plate_stairs:3,null,10,quark:iron_plate_slab:8,null,10,quark:iron_plate_stairs:7,null,10,quark:iron_plate_stairs:1,null,10,quark:iron_plate_slab:0,null,10,quark:iron_plate_stairs:4,null,10,quark:iron_plate_stairs:2,null,10,rustic:iron_lattice:1,null,50,rustic:iron_lattice:1,null,50,biomesoplenty:leaves_2:7,null,100)
RandomBlock(2,6,-1,quark:iron_plate:1,null,70,STAINED_CLAY:15,null,30,STAINED_CLAY:7,null,30,quark:iron_plate:1,null,100)
Block(2,6,0,AIR:0)
Block(2,6,1,AIR:0)
RandomBlock(2,6,2,rustic:iron_lattice:1,null,30,rustic:iron_lattice:1,null,30,biomesoplenty:leaves_2:7,null,30,quark:iron_plate_stairs:6,null,10,quark:iron_plate_stairs:0,null,10,quark:iron_plate_stairs:5,null,10,quark:iron_plate_stairs:3,null,10,quark:iron_plate_slab:8,null,10,quark:iron_plate_stairs:7,null,10,quark:iron_plate_stairs:1,null,10,quark:iron_plate_slab:0,null,10,quark:iron_plate_stairs:4,null,10,quark:iron_plate_stairs:2,null,10,rustic:iron_lattice:1,null,50,rustic:iron_lattice:1,null,50,biomesoplenty:leaves_2:7,null,100)
Block(2,7,-1,COBBLESTONE_STAIRS:2)
RandomBlock(2,7,0,quark:iron_plate:1,null,70,STAINED_CLAY:15,null,30,STAINED_CLAY:7,null,30,quark:iron_plate:1,null,100)
RandomBlock(2,7,1,quark:iron_plate:1,null,70,STAINED_CLAY:15,null,30,STAINED_CLAY:7,null,30,quark:iron_plate:1,null,100)
Block(2,7,2,COBBLESTONE_STAIRS:3)
Block(3,0,-2,quark:limestone:0)
Block(3,0,-1,quark:limestone:0)
Block(3,0,0,quark:limestone:0)
Block(3,0,1,quark:limestone:0)
Block(3,0,2,quark:limestone:0)
Block(3,0,3,quark:limestone:0)
Block(3,1,-2,COBBLESTONE_STAIRS:2)
Block(3,1,-1,COBBLESTONE_STAIRS:0)
Block(3,1,0,COBBLESTONE_STAIRS:0)
Block(3,1,1,COBBLESTONE_STAIRS:0)
Block(3,1,2,COBBLESTONE_STAIRS:0)
Block(3,1,3,COBBLESTONE_STAIRS:0)
Block(3,4,-1,COBBLESTONE_STAIRS:6)
RandomBlock(3,4,0,quark:iron_plate:1,null,70,STAINED_CLAY:15,null,30,STAINED_CLAY:7,null,30,quark:iron_plate:1,null,100)
RandomBlock(3,4,1,quark:iron_plate:1,null,70,STAINED_CLAY:15,null,30,STAINED_CLAY:7,null,30,quark:iron_plate:1,null,100)
Block(3,4,2,COBBLESTONE_STAIRS:7)
RandomBlock(3,5,-1,quark:iron_plate:1,null,70,STAINED_CLAY:15,null,30,STAINED_CLAY:7,null,30,quark:iron_plate:1,null,100)
Block(3,5,0,AIR:0)
Block(3,5,1,AIR:0)
RandomBlock(3,5,2,rustic:iron_lattice:1,null,30,rustic:iron_lattice:1,null,30,biomesoplenty:leaves_2:7,null,30,quark:iron_plate_stairs:6,null,10,quark:iron_plate_stairs:0,null,10,quark:iron_plate_stairs:5,null,10,quark:iron_plate_stairs:3,null,10,quark:iron_plate_slab:8,null,10,quark:iron_plate_stairs:7,null,10,quark:iron_plate_stairs:1,null,10,quark:iron_plate_slab:0,null,10,quark:iron_plate_stairs:4,null,10,quark:iron_plate_stairs:2,null,10,rustic:iron_lattice:1,null,50,rustic:iron_lattice:1,null,50,biomesoplenty:leaves_2:7,null,100)
RandomBlock(3,6,-1,quark:iron_plate:1,null,70,STAINED_CLAY:15,null,30,STAINED_CLAY:7,null,30,quark:iron_plate:1,null,100)
Block(3,6,0,AIR:0)
Block(3,6,1,AIR:0)
RandomBlock(3,6,2,rustic:iron_lattice:1,null,30,rustic:iron_lattice:1,null,30,biomesoplenty:leaves_2:7,null,30,quark:iron_plate_stairs:6,null,10,quark:iron_plate_stairs:0,null,10,quark:iron_plate_stairs:5,null,10,quark:iron_plate_stairs:3,null,10,quark:iron_plate_slab:8,null,10,quark:iron_plate_stairs:7,null,10,quark:iron_plate_stairs:1,null,10,quark:iron_plate_slab:0,null,10,quark:iron_plate_stairs:4,null,10,quark:iron_plate_stairs:2,null,10,rustic:iron_lattice:1,null,50,rustic:iron_lattice:1,null,50,biomesoplenty:leaves_2:7,null,100)
Block(3,7,-1,COBBLESTONE_STAIRS:2)
RandomBlock(3,7,0,quark:iron_plate:1,null,70,STAINED_CLAY:15,null,30,STAINED_CLAY:7,null,30,quark:iron_plate:1,null,100)
RandomBlock(3,7,1,quark:iron_plate:1,null,70,STAINED_CLAY:15,null,30,STAINED_CLAY:7,null,30,quark:iron_plate:1,null,100)
Block(3,7,2,COBBLESTONE_STAIRS:3)
Block(4,0,-2,quark:limestone:0)
RandomBlock(4,0,-1,quark:iron_plate:1,null,70,STAINED_CLAY:15,null,30,STAINED_CLAY:7,null,30,quark:iron_plate:1,null,100)
RandomBlock(4,0,0,quark:iron_plate:1,null,70,STAINED_CLAY:15,null,30,STAINED_CLAY:7,null,30,quark:iron_plate:1,null,100)
RandomBlock(4,0,1,quark:iron_plate:1,null,70,STAINED_CLAY:15,null,30,STAINED_CLAY:7,null,30,quark:iron_plate:1,null,100)
RandomBlock(4,0,2,quark:iron_plate:1,null,70,STAINED_CLAY:15,null,30,STAINED_CLAY:7,null,30,quark:iron_plate:1,null,100)
Block(4,0,3,quark:limestone:0)
Block(4,1,-2,COBBLESTONE_STAIRS:2)
RandomBlock(4,1,-1,quark:iron_plate:1,null,70,STAINED_CLAY:15,null,30,STAINED_CLAY:7,null,30,quark:iron_plate:1,null,100)
RandomBlock(4,1,0,quark:iron_plate:1,null,70,STAINED_CLAY:15,null,30,STAINED_CLAY:7,null,30,quark:iron_plate:1,null,100)
RandomBlock(4,1,1,quark:iron_plate:1,null,70,STAINED_CLAY:15,null,30,STAINED_CLAY:7,null,30,quark:iron_plate:1,null,100)
RandomBlock(4,1,2,quark:iron_plate:1,null,70,STAINED_CLAY:15,null,30,STAINED_CLAY:7,null,30,quark:iron_plate:1,null,100)
Block(4,1,3,COBBLESTONE_STAIRS:3)
RandomBlock(4,2,-1,quark:iron_plate:1,null,70,STAINED_CLAY:15,null,30,STAINED_CLAY:7,null,30,quark:iron_plate:1,null,100)
RandomBlock(4,2,0,quark:iron_plate:1,null,70,STAINED_CLAY:15,null,30,STAINED_CLAY:7,null,30,quark:iron_plate:1,null,100)
RandomBlock(4,2,1,quark:iron_plate:1,null,70,STAINED_CLAY:15,null,30,STAINED_CLAY:7,null,30,quark:iron_plate:1,null,100)
RandomBlock(4,2,2,quark:iron_plate:1,null,70,STAINED_CLAY:15,null,30,STAINED_CLAY:7,null,30,quark:iron_plate:1,null,100)
RandomBlock(4,3,-1,quark:iron_plate:1,null,70,STAINED_CLAY:15,null,30,STAINED_CLAY:7,null,30,quark:iron_plate:1,null,100)
RandomBlock(4,3,0,quark:iron_plate:1,null,70,STAINED_CLAY:15,null,30,STAINED_CLAY:7,null,30,quark:iron_plate:1,null,100)
RandomBlock(4,3,1,quark:iron_plate:1,null,70,STAINED_CLAY:15,null,30,STAINED_CLAY:7,null,30,quark:iron_plate:1,null,100)
RandomBlock(4,3,2,quark:iron_plate:1,null,70,STAINED_CLAY:15,null,30,STAINED_CLAY:7,null,30,quark:iron_plate:1,null,100)
RandomBlock(4,4,-1,quark:iron_plate:1,null,70,STAINED_CLAY:15,null,30,STAINED_CLAY:7,null,30,quark:iron_plate:1,null,100)
RandomBlock(4,4,0,quark:iron_plate:1,null,70,STAINED_CLAY:15,null,30,STAINED_CLAY:7,null,30,quark:iron_plate:1,null,100)
RandomBlock(4,4,1,quark:iron_plate:1,null,70,STAINED_CLAY:15,null,30,STAINED_CLAY:7,null,30,quark:iron_plate:1,null,100)
RandomBlock(4,4,2,quark:iron_plate:1,null,70,STAINED_CLAY:15,null,30,STAINED_CLAY:7,null,30,quark:iron_plate:1,null,100)
RandomBlock(4,5,-1,quark:iron_plate:1,null,70,STAINED_CLAY:15,null,30,STAINED_CLAY:7,null,30,quark:iron_plate:1,null,100)
Block(4,5,0,AIR:0)
Block(4,5,1,AIR:0)
RandomBlock(4,5,2,rustic:iron_lattice:1,null,30,rustic:iron_lattice:1,null,30,biomesoplenty:leaves_2:7,null,30,quark:iron_plate_stairs:6,null,10,quark:iron_plate_stairs:0,null,10,quark:iron_plate_stairs:5,null,10,quark:iron_plate_stairs:3,null,10,quark:iron_plate_slab:8,null,10,quark:iron_plate_stairs:7,null,10,quark:iron_plate_stairs:1,null,10,quark:iron_plate_slab:0,null,10,quark:iron_plate_stairs:4,null,10,quark:iron_plate_stairs:2,null,10,rustic:iron_lattice:1,null,50,rustic:iron_lattice:1,null,50,biomesoplenty:leaves_2:7,null,100)
RandomBlock(4,6,-1,quark:iron_plate:1,null,70,STAINED_CLAY:15,null,30,STAINED_CLAY:7,null,30,quark:iron_plate:1,null,100)
Block(4,6,0,AIR:0)
Block(4,6,1,AIR:0)
RandomBlock(4,6,2,quark:iron_plate:1,null,70,STAINED_CLAY:15,null,30,STAINED_CLAY:7,null,30,quark:iron_plate:1,null,100)
Block(4,7,-1,COBBLESTONE_STAIRS:2)
RandomBlock(4,7,0,quark:iron_plate:1,null,70,STAINED_CLAY:15,null,30,STAINED_CLAY:7,null,30,quark:iron_plate:1,null,100)
RandomBlock(4,7,1,quark:iron_plate:1,null,70,STAINED_CLAY:15,null,30,STAINED_CLAY:7,null,30,quark:iron_plate:1,null,100)
Block(4,7,2,COBBLESTONE_STAIRS:3)
Block(5,0,-2,quark:limestone:0)
RandomBlock(5,0,-1,quark:iron_plate:1,null,70,STAINED_CLAY:15,null,30,STAINED_CLAY:7,null,30,quark:iron_plate:1,null,100)
Block(5,0,0,AIR:0)
Block(5,0,1,AIR:0)
RandomBlock(5,0,2,quark:iron_plate:1,null,70,STAINED_CLAY:15,null,30,STAINED_CLAY:7,null,30,quark:iron_plate:1,null,100)
Block(5,0,3,quark:limestone:0)
Block(5,1,-2,COBBLESTONE_STAIRS:2)
RandomBlock(5,1,-1,quark:iron_plate:1,null,70,STAINED_CLAY:15,null,30,STAINED_CLAY:7,null,30,quark:iron_plate:1,null,100)
Block(5,1,0,AIR:0)
Block(5,1,1,AIR:0)
RandomBlock(5,1,2,quark:iron_plate:1,null,70,STAINED_CLAY:15,null,30,STAINED_CLAY:7,null,30,quark:iron_plate:1,null,100)
Block(5,1,3,COBBLESTONE_STAIRS:3)
RandomBlock(5,2,-1,quark:iron_plate:1,null,70,STAINED_CLAY:15,null,30,STAINED_CLAY:7,null,30,quark:iron_plate:1,null,100)
Block(5,2,0,AIR:0)
Block(5,2,1,AIR:0)
RandomBlock(5,2,2,quark:iron_plate:1,null,70,STAINED_CLAY:15,null,30,STAINED_CLAY:7,null,30,quark:iron_plate:1,null,100)
RandomBlock(5,3,-1,quark:iron_plate:1,null,70,STAINED_CLAY:15,null,30,STAINED_CLAY:7,null,30,quark:iron_plate:1,null,100)
Block(5,3,0,AIR:0)
Block(5,3,1,AIR:0)
RandomBlock(5,3,2,quark:iron_plate:1,null,70,STAINED_CLAY:15,null,30,STAINED_CLAY:7,null,30,quark:iron_plate:1,null,100)
RandomBlock(5,4,-1,quark:iron_plate:1,null,70,STAINED_CLAY:15,null,30,STAINED_CLAY:7,null,30,quark:iron_plate:1,null,100)
Block(5,4,0,AIR:0)
Block(5,4,1,AIR:0)
RandomBlock(5,4,2,rustic:iron_lattice:1,null,30,rustic:iron_lattice:1,null,30,biomesoplenty:leaves_2:7,null,30,quark:iron_plate_stairs:6,null,10,quark:iron_plate_stairs:0,null,10,quark:iron_plate_stairs:5,null,10,quark:iron_plate_stairs:3,null,10,quark:iron_plate_slab:8,null,10,quark:iron_plate_stairs:7,null,10,quark:iron_plate_stairs:1,null,10,quark:iron_plate_slab:0,null,10,quark:iron_plate_stairs:4,null,10,quark:iron_plate_stairs:2,null,10,rustic:iron_lattice:1,null,50,rustic:iron_lattice:1,null,50,biomesoplenty:leaves_2:7,null,100)
RandomBlock(5,5,-1,quark:iron_plate:1,null,70,STAINED_CLAY:15,null,30,STAINED_CLAY:7,null,30,quark:iron_plate:1,null,100)
Block(5,5,0,AIR:0)
Block(5,5,1,AIR:0)
RandomBlock(5,5,2,rustic:iron_lattice:1,null,30,rustic:iron_lattice:1,null,30,biomesoplenty:leaves_2:7,null,30,quark:iron_plate_stairs:6,null,10,quark:iron_plate_stairs:0,null,10,quark:iron_plate_stairs:5,null,10,quark:iron_plate_stairs:3,null,10,quark:iron_plate_slab:8,null,10,quark:iron_plate_stairs:7,null,10,quark:iron_plate_stairs:1,null,10,quark:iron_plate_slab:0,null,10,quark:iron_plate_stairs:4,null,10,quark:iron_plate_stairs:2,null,10,rustic:iron_lattice:1,null,50,rustic:iron_lattice:1,null,50,biomesoplenty:leaves_2:7,null,100)
RandomBlock(5,6,-1,quark:iron_plate:1,null,70,STAINED_CLAY:15,null,30,STAINED_CLAY:7,null,30,quark:iron_plate:1,null,100)
Block(5,6,0,AIR:0)
Block(5,6,1,AIR:0)
RandomBlock(5,6,2,rustic:iron_lattice:1,null,30,rustic:iron_lattice:1,null,30,biomesoplenty:leaves_2:7,null,30,quark:iron_plate_stairs:6,null,10,quark:iron_plate_stairs:0,null,10,quark:iron_plate_stairs:5,null,10,quark:iron_plate_stairs:3,null,10,quark:iron_plate_slab:8,null,10,quark:iron_plate_stairs:7,null,10,quark:iron_plate_stairs:1,null,10,quark:iron_plate_slab:0,null,10,quark:iron_plate_stairs:4,null,10,quark:iron_plate_stairs:2,null,10,rustic:iron_lattice:1,null,50,rustic:iron_lattice:1,null,50,biomesoplenty:leaves_2:7,null,100)
Block(5,7,-1,COBBLESTONE_STAIRS:2)
RandomBlock(5,7,0,quark:iron_plate:1,null,70,STAINED_CLAY:15,null,30,STAINED_CLAY:7,null,30,quark:iron_plate:1,null,100)
RandomBlock(5,7,1,quark:iron_plate:1,null,70,STAINED_CLAY:15,null,30,STAINED_CLAY:7,null,30,quark:iron_plate:1,null,100)
Block(5,7,2,COBBLESTONE_STAIRS:3)
Block(6,0,-2,quark:limestone:0)
RandomBlock(6,0,-1,quark:iron_plate:1,null,70,STAINED_CLAY:15,null,30,STAINED_CLAY:7,null,30,quark:iron_plate:1,null,100)
Block(6,0,0,AIR:0)
Block(6,0,1,AIR:0)
RandomBlock(6,0,2,quark:iron_plate:1,null,70,STAINED_CLAY:15,null,30,STAINED_CLAY:7,null,30,quark:iron_plate:1,null,100)
Block(6,0,3,quark:limestone:0)
RandomBlock(6,0,6,quark:iron_plate:1,null,70,STAINED_CLAY:15,null,30,STAINED_CLAY:7,null,30,quark:iron_plate:1,null,100)
Block(6,1,-2,COBBLESTONE_STAIRS:2)
RandomBlock(6,1,-1,quark:iron_plate:1,null,70,STAINED_CLAY:15,null,30,STAINED_CLAY:7,null,30,quark:iron_plate:1,null,100)
Block(6,1,0,AIR:0)
Block(6,1,1,AIR:0)
RandomBlock(6,1,2,quark:iron_plate:1,null,70,STAINED_CLAY:15,null,30,STAINED_CLAY:7,null,30,quark:iron_plate:1,null,100)
Block(6,1,3,COBBLESTONE_STAIRS:3)
RandomBlock(6,1,6,quark:iron_plate:1,null,70,STAINED_CLAY:15,null,30,STAINED_CLAY:7,null,30,quark:iron_plate:1,null,100)
RandomBlock(6,2,-1,quark:iron_plate:1,null,70,STAINED_CLAY:15,null,30,STAINED_CLAY:7,null,30,quark:iron_plate:1,null,100)
Block(6,2,0,AIR:0)
Block(6,2,1,AIR:0)
RandomBlock(6,2,2,quark:iron_plate:1,null,70,STAINED_CLAY:15,null,30,STAINED_CLAY:7,null,30,quark:iron_plate:1,null,100)
RandomBlock(6,2,6,quark:iron_plate:1,null,70,STAINED_CLAY:15,null,30,STAINED_CLAY:7,null,30,quark:iron_plate:1,null,100)
RandomBlock(6,3,-1,quark:iron_plate:1,null,70,STAINED_CLAY:15,null,30,STAINED_CLAY:7,null,30,quark:iron_plate:1,null,100)
Block(6,3,0,AIR:0)
Block(6,3,1,AIR:0)
RandomBlock(6,3,2,rustic:iron_lattice:1,null,30,rustic:iron_lattice:1,null,30,biomesoplenty:leaves_2:7,null,30,quark:iron_plate_stairs:6,null,10,quark:iron_plate_stairs:0,null,10,quark:iron_plate_stairs:5,null,10,quark:iron_plate_stairs:3,null,10,quark:iron_plate_slab:8,null,10,quark:iron_plate_stairs:7,null,10,quark:iron_plate_stairs:1,null,10,quark:iron_plate_slab:0,null,10,quark:iron_plate_stairs:4,null,10,quark:iron_plate_stairs:2,null,10,rustic:iron_lattice:1,null,50,rustic:iron_lattice:1,null,50,biomesoplenty:leaves_2:7,null,100)
RandomBlock(6,3,6,quark:iron_plate:1,null,70,STAINED_CLAY:15,null,30,STAINED_CLAY:7,null,30,quark:iron_plate:1,null,100)
RandomBlock(6,4,-1,quark:iron_plate:1,null,70,STAINED_CLAY:15,null,30,STAINED_CLAY:7,null,30,quark:iron_plate:1,null,100)
Block(6,4,0,AIR:0)
Block(6,4,1,AIR:0)
RandomBlock(6,4,2,rustic:iron_lattice:1,null,30,rustic:iron_lattice:1,null,30,biomesoplenty:leaves_2:7,null,30,quark:iron_plate_stairs:6,null,10,quark:iron_plate_stairs:0,null,10,quark:iron_plate_stairs:5,null,10,quark:iron_plate_stairs:3,null,10,quark:iron_plate_slab:8,null,10,quark:iron_plate_stairs:7,null,10,quark:iron_plate_stairs:1,null,10,quark:iron_plate_slab:0,null,10,quark:iron_plate_stairs:4,null,10,quark:iron_plate_stairs:2,null,10,rustic:iron_lattice:1,null,50,rustic:iron_lattice:1,null,50,biomesoplenty:leaves_2:7,null,100)
RandomBlock(6,4,6,quark:iron_plate:1,null,70,STAINED_CLAY:15,null,30,STAINED_CLAY:7,null,30,quark:iron_plate:1,null,100)
RandomBlock(6,5,-1,quark:iron_plate:1,null,70,STAINED_CLAY:15,null,30,STAINED_CLAY:7,null,30,quark:iron_plate:1,null,100)
Block(6,5,0,AIR:0)
Block(6,5,1,AIR:0)
RandomBlock(6,5,2,quark:iron_plate:1,null,70,STAINED_CLAY:15,null,30,STAINED_CLAY:7,null,30,quark:iron_plate:1,null,100)
RandomBlock(6,5,3,quark:iron_plate:1,null,70,STAINED_CLAY:15,null,30,STAINED_CLAY:7,null,30,quark:iron_plate:1,null,100)
RandomBlock(6,5,4,quark:iron_plate:1,null,70,STAINED_CLAY:15,null,30,STAINED_CLAY:7,null,30,quark:iron_plate:1,null,100)
RandomBlock(6,5,5,quark:iron_plate:1,null,70,STAINED_CLAY:15,null,30,STAINED_CLAY:7,null,30,quark:iron_plate:1,null,100)
RandomBlock(6,5,6,quark:iron_plate:1,null,70,STAINED_CLAY:15,null,30,STAINED_CLAY:7,null,30,quark:iron_plate:1,null,100)
RandomBlock(6,6,-1,quark:iron_plate:1,null,70,STAINED_CLAY:15,null,30,STAINED_CLAY:7,null,30,quark:iron_plate:1,null,100)
Block(6,6,0,AIR:0)
Block(6,6,1,AIR:0)
RandomBlock(6,6,2,quark:iron_plate:1,null,70,STAINED_CLAY:15,null,30,STAINED_CLAY:7,null,30,quark:iron_plate:1,null,100)
Block(6,7,-1,COBBLESTONE_STAIRS:2)
RandomBlock(6,7,0,quark:iron_plate:1,null,70,STAINED_CLAY:15,null,30,STAINED_CLAY:7,null,30,quark:iron_plate:1,null,100)
RandomBlock(6,7,1,quark:iron_plate:1,null,70,STAINED_CLAY:15,null,30,STAINED_CLAY:7,null,30,quark:iron_plate:1,null,100)
Block(6,7,2,COBBLESTONE_STAIRS:3)
Block(7,0,-2,quark:limestone:0)
RandomBlock(7,0,-1,quark:iron_plate:1,null,70,STAINED_CLAY:15,null,30,STAINED_CLAY:7,null,30,quark:iron_plate:1,null,100)
RandomBlock(7,0,0,quark:iron_plate:1,null,70,STAINED_CLAY:15,null,30,STAINED_CLAY:7,null,30,quark:iron_plate:1,null,100)
RandomBlock(7,0,1,quark:iron_plate:1,null,70,STAINED_CLAY:15,null,30,STAINED_CLAY:7,null,30,quark:iron_plate:1,null,100)
RandomBlock(7,0,2,quark:iron_plate:1,null,70,STAINED_CLAY:15,null,30,STAINED_CLAY:7,null,30,quark:iron_plate:1,null,100)
Block(7,0,3,quark:limestone:0)
Block(7,1,-2,COBBLESTONE_STAIRS:2)
RandomBlock(7,1,-1,quark:iron_plate:1,null,70,STAINED_CLAY:15,null,30,STAINED_CLAY:7,null,30,quark:iron_plate:1,null,100)
RandomBlock(7,1,0,quark:iron_plate:1,null,70,STAINED_CLAY:15,null,30,STAINED_CLAY:7,null,30,quark:iron_plate:1,null,100)
RandomBlock(7,1,1,quark:iron_plate:1,null,70,STAINED_CLAY:15,null,30,STAINED_CLAY:7,null,30,quark:iron_plate:1,null,100)
RandomBlock(7,1,2,rustic:iron_lattice:1,null,30,rustic:iron_lattice:1,null,30,biomesoplenty:leaves_2:7,null,30,quark:iron_plate_stairs:6,null,10,quark:iron_plate_stairs:0,null,10,quark:iron_plate_stairs:5,null,10,quark:iron_plate_stairs:3,null,10,quark:iron_plate_slab:8,null,10,quark:iron_plate_stairs:7,null,10,quark:iron_plate_stairs:1,null,10,quark:iron_plate_slab:0,null,10,quark:iron_plate_stairs:4,null,10,quark:iron_plate_stairs:2,null,10,rustic:iron_lattice:1,null,50,rustic:iron_lattice:1,null,50,biomesoplenty:leaves_2:7,null,100)
Block(7,1,3,COBBLESTONE_STAIRS:3)
RandomBlock(7,2,-1,quark:iron_plate:1,null,70,STAINED_CLAY:15,null,30,STAINED_CLAY:7,null,30,quark:iron_plate:1,null,100)
RandomBlock(7,2,0,quark:iron_plate:1,null,70,STAINED_CLAY:15,null,30,STAINED_CLAY:7,null,30,quark:iron_plate:1,null,100)
RandomBlock(7,2,1,quark:iron_plate:1,null,70,STAINED_CLAY:15,null,30,STAINED_CLAY:7,null,30,quark:iron_plate:1,null,100)
RandomBlock(7,2,2,quark:iron_plate:1,null,70,STAINED_CLAY:15,null,30,STAINED_CLAY:7,null,30,quark:iron_plate:1,null,100)
RandomBlock(7,3,-1,quark:iron_plate:1,null,70,STAINED_CLAY:15,null,30,STAINED_CLAY:7,null,30,quark:iron_plate:1,null,100)
RandomBlock(7,3,0,quark:iron_plate:1,null,70,STAINED_CLAY:15,null,30,STAINED_CLAY:7,null,30,quark:iron_plate:1,null,100)
RandomBlock(7,3,1,quark:iron_plate:1,null,70,STAINED_CLAY:15,null,30,STAINED_CLAY:7,null,30,quark:iron_plate:1,null,100)
RandomBlock(7,3,2,quark:iron_plate:1,null,70,STAINED_CLAY:15,null,30,STAINED_CLAY:7,null,30,quark:iron_plate:1,null,100)
RandomBlock(7,4,-1,quark:iron_plate:1,null,70,STAINED_CLAY:15,null,30,STAINED_CLAY:7,null,30,quark:iron_plate:1,null,100)
RandomBlock(7,4,0,quark:iron_plate:1,null,70,STAINED_CLAY:15,null,30,STAINED_CLAY:7,null,30,quark:iron_plate:1,null,100)
RandomBlock(7,4,1,quark:iron_plate:1,null,70,STAINED_CLAY:15,null,30,STAINED_CLAY:7,null,30,quark:iron_plate:1,null,100)
RandomBlock(7,4,2,rustic:iron_lattice:1,null,30,rustic:iron_lattice:1,null,30,biomesoplenty:leaves_2:7,null,30,quark:iron_plate_stairs:6,null,10,quark:iron_plate_stairs:0,null,10,quark:iron_plate_stairs:5,null,10,quark:iron_plate_stairs:3,null,10,quark:iron_plate_slab:8,null,10,quark:iron_plate_stairs:7,null,10,quark:iron_plate_stairs:1,null,10,quark:iron_plate_slab:0,null,10,quark:iron_plate_stairs:4,null,10,quark:iron_plate_stairs:2,null,10,rustic:iron_lattice:1,null,50,rustic:iron_lattice:1,null,50,biomesoplenty:leaves_2:7,null,100)
RandomBlock(7,5,-1,quark:iron_plate:1,null,70,STAINED_CLAY:15,null,30,STAINED_CLAY:7,null,30,quark:iron_plate:1,null,100)
RandomBlock(7,5,0,quark:iron_plate:1,null,70,STAINED_CLAY:15,null,30,STAINED_CLAY:7,null,30,quark:iron_plate:1,null,100)
RandomBlock(7,5,1,quark:iron_plate:1,null,70,STAINED_CLAY:15,null,30,STAINED_CLAY:7,null,30,quark:iron_plate:1,null,100)
RandomBlock(7,5,2,quark:iron_plate:1,null,70,STAINED_CLAY:15,null,30,STAINED_CLAY:7,null,30,quark:iron_plate:1,null,100)
RandomBlock(7,6,-1,quark:iron_plate:1,null,70,STAINED_CLAY:15,null,30,STAINED_CLAY:7,null,30,quark:iron_plate:1,null,100)
RandomBlock(7,6,0,quark:iron_plate:1,null,70,STAINED_CLAY:15,null,30,STAINED_CLAY:7,null,30,quark:iron_plate:1,null,100)
RandomBlock(7,6,1,quark:iron_plate:1,null,70,STAINED_CLAY:15,null,30,STAINED_CLAY:7,null,30,quark:iron_plate:1,null,100)
RandomBlock(7,6,2,quark:iron_plate:1,null,70,STAINED_CLAY:15,null,30,STAINED_CLAY:7,null,30,quark:iron_plate:1,null,100)
Block(7,7,-1,COBBLESTONE_STAIRS:2)
Block(7,7,0,COBBLESTONE_STAIRS:1)
Block(7,7,1,COBBLESTONE_STAIRS:1)
Block(7,7,2,COBBLESTONE_STAIRS:1)

#######################################################################
# +-----------------------------------------------------------------+ #
# |                             Branches                            | #
# +-----------------------------------------------------------------+ #
#######################################################################

Branch(16,0,0,true,brutal_pipebig_03C3R0,NORTH,100.0,0)

#######################################################################
# +-----------------------------------------------------------------+ #
# |                             Entities                            | #
# +-----------------------------------------------------------------+ #
#######################################################################


#######################################################################
# +-----------------------------------------------------------------+ #
# |                            Particles                            | #
# +-----------------------------------------------------------------+ #
#######################################################################


#######################################################################
# +-----------------------------------------------------------------+ #
# |                             Spawners                            | #
# +-----------------------------------------------------------------+ #
#######################################################################


#######################################################################
# +-----------------------------------------------------------------+ #
# |                             ModData                             | #
# +-----------------------------------------------------------------+ #
#######################################################################

