
#######################################################################
# +-----------------------------------------------------------------+ #
# |                            BO4 object                           | #
# +-----------------------------------------------------------------+ #
#######################################################################

Author: NLBlackEagle

Description: No description given

SettingsMode: WriteWithoutComments


#######################################################################
# +-----------------------------------------------------------------+ #
# |                          Main settings                          | #
# +-----------------------------------------------------------------+ #
#######################################################################

FixedRotation: 

Frequency: 0

SpawnHeight: randomY

UseCenterForHighestBlock: true

##############################
# Height Limits for the BO4. #
##############################

MinHeight: 78

MaxHeight: 78

InheritBO3: 

InheritBO3Rotation: NORTH

OverrideChildSettings: true

OverrideParentHeight: false

CanOverride: true

BranchFrequency: 0

BranchFrequencyGroup: 

MustBeBelowOther: false

MustBeInside: 

CannotBeInside: 

ReplacesBO3: 

MustBeInsideWorldBorders: false

CanSpawnOnWater: true

SpawnOnWaterOnly: false

SpawnUnderWater: false

SpawnAtWaterLevel: false

HeightOffset: 0

RemoveAir: false

ReplaceAbove: 

ReplaceBelow: 

ReplaceWithBiomeBlocks: true

ReplaceWithSurfaceBlock: GRASS

ReplaceWithGroundBlock: DIRT

ReplaceWithStoneBlock: STONE

SmoothRadius: 0

SmoothHeightOffset: 0

SmoothStartTop: false

SmoothStartWood: false

SmoothingSurfaceBlock: 

SmoothingGroundBlock: 

BO3Group: 

IsSpawnPoint: false

DoReplaceBlocks: false


#######################################################################
# +-----------------------------------------------------------------+ #
# |                              Blocks                             | #
# +-----------------------------------------------------------------+ #
#######################################################################

Block(-8,0,-6,quark:limestone:0)
Block(-8,0,-5,quark:limestone:0)
Block(-8,0,-4,quark:limestone:0)
Block(-8,0,-3,quark:limestone:0)
Block(-8,0,-2,quark:limestone:0)
Block(-8,1,-6,quark:world_stone_pavement:2)
Block(-8,1,-5,quark:world_stone_pavement:2)
Block(-8,1,-4,quark:world_stone_pavement:2)
Block(-8,1,-3,quark:world_stone_pavement:2)
Block(-8,1,-2,quark:world_stone_pavement:2)
Block(-8,2,-6,quark:world_stone_pavement:2)
Block(-8,2,-5,quark:basalt_wall:0)
Block(-8,2,-4,quark:basalt_wall:0)
Block(-8,2,-3,quark:basalt_wall:0)
Block(-8,2,-2,quark:world_stone_pavement:2)
Block(-8,3,-6,quark:basalt_wall:0)
Block(-8,3,-5,quark:basalt_wall:0)
Block(-8,3,-4,quark:world_stone_pavement:2)
Block(-8,3,-3,quark:basalt_wall:0)
Block(-8,3,-2,quark:basalt_wall:0)
Block(-8,4,-6,quark:basalt_wall:0)
Block(-8,4,-5,quark:world_stone_pavement:2)
Block(-8,4,-4,quark:world_stone_pavement:2)
Block(-8,4,-3,quark:world_stone_pavement:2)
Block(-8,4,-2,quark:basalt_wall:0)
Block(-8,4,5,COBBLESTONE_STAIRS:6)
RandomBlock(-8,4,6,quark:iron_plate:1,null,70,STAINED_CLAY:15,null,30,STAINED_CLAY:7,null,30,quark:iron_plate:1,null,100)
RandomBlock(-8,4,7,quark:iron_plate:1,null,70,STAINED_CLAY:15,null,30,STAINED_CLAY:7,null,30,quark:iron_plate:1,null,100)
Block(-8,4,8,COBBLESTONE_STAIRS:7)
Block(-8,5,-6,quark:basalt_wall:0)
Block(-8,5,-5,quark:world_stone_pavement:2)
Block(-8,5,-4,quark:framed_glass:0)
Block(-8,5,-3,quark:world_stone_pavement:2)
Block(-8,5,-2,quark:basalt_wall:0)
RandomBlock(-8,5,5,quark:iron_plate:1,null,70,STAINED_CLAY:15,null,30,STAINED_CLAY:7,null,30,quark:iron_plate:1,null,100)
Block(-8,5,6,AIR:0)
Block(-8,5,7,AIR:0)
RandomBlock(-8,5,8,quark:iron_plate:1,null,70,STAINED_CLAY:15,null,30,STAINED_CLAY:7,null,30,quark:iron_plate:1,null,100)
Block(-8,6,-6,quark:basalt_wall:0)
Block(-8,6,-5,quark:world_stone_pavement:2)
Block(-8,6,-4,quark:framed_glass:0)
Block(-8,6,-3,quark:world_stone_pavement:2)
Block(-8,6,-2,quark:basalt_wall:0)
RandomBlock(-8,6,5,quark:iron_plate:1,null,70,STAINED_CLAY:15,null,30,STAINED_CLAY:7,null,30,quark:iron_plate:1,null,100)
Block(-8,6,6,AIR:0)
Block(-8,6,7,AIR:0)
RandomBlock(-8,6,8,quark:iron_plate:1,null,70,STAINED_CLAY:15,null,30,STAINED_CLAY:7,null,30,quark:iron_plate:1,null,100)
Block(-8,7,-6,quark:basalt_wall:0)
Block(-8,7,-5,quark:world_stone_pavement:2)
Block(-8,7,-4,quark:framed_glass:0)
Block(-8,7,-3,quark:world_stone_pavement:2)
Block(-8,7,-2,quark:basalt_wall:0)
Block(-8,7,5,COBBLESTONE_STAIRS:2)
RandomBlock(-8,7,6,rustic:iron_lattice:1,null,30,rustic:iron_lattice:1,null,30,biomesoplenty:leaves_2:7,null,30,quark:iron_plate_stairs:6,null,10,quark:iron_plate_stairs:0,null,10,quark:iron_plate_stairs:5,null,10,quark:iron_plate_stairs:3,null,10,quark:iron_plate_slab:8,null,10,quark:iron_plate_stairs:7,null,10,quark:iron_plate_stairs:1,null,10,quark:iron_plate_slab:0,null,10,quark:iron_plate_stairs:4,null,10,quark:iron_plate_stairs:2,null,10,rustic:iron_lattice:1,null,50,rustic:iron_lattice:1,null,50,biomesoplenty:leaves_2:7,null,100)
RandomBlock(-8,7,7,quark:iron_plate:1,null,70,STAINED_CLAY:15,null,30,STAINED_CLAY:7,null,30,quark:iron_plate:1,null,100)
Block(-8,7,8,COBBLESTONE_STAIRS:3)
Block(-8,8,-6,quark:basalt_wall:0)
Block(-8,8,-5,quark:world_stone_pavement:2)
Block(-8,8,-4,quark:framed_glass:0)
Block(-8,8,-3,quark:world_stone_pavement:2)
Block(-8,8,-2,quark:basalt_wall:0)
Block(-8,9,-6,quark:basalt_wall:0)
Block(-8,9,-5,quark:world_stone_pavement:2)
Block(-8,9,-4,quark:framed_glass:0)
Block(-8,9,-3,quark:world_stone_pavement:2)
Block(-8,9,-2,quark:basalt_wall:0)
Block(-8,10,-6,quark:basalt_wall:0)
Block(-8,10,-5,quark:world_stone_pavement:2)
Block(-8,10,-4,quark:framed_glass:0)
Block(-8,10,-3,quark:world_stone_pavement:2)
Block(-8,10,-2,quark:basalt_wall:0)
Block(-8,11,-6,quark:basalt_wall:0)
Block(-8,11,-5,quark:world_stone_pavement:2)
Block(-8,11,-4,quark:world_stone_pavement:2)
Block(-8,11,-3,quark:world_stone_pavement:2)
Block(-8,11,-2,quark:basalt_wall:0)
Block(-8,12,-6,quark:basalt_wall:0)
Block(-8,12,-5,quark:basalt_wall:0)
Block(-8,12,-4,quark:world_stone_pavement:2)
Block(-8,12,-3,quark:basalt_wall:0)
Block(-8,12,-2,quark:basalt_wall:0)
Block(-8,13,-6,quark:world_stone_pavement:2)
Block(-8,13,-5,quark:basalt_wall:0)
Block(-8,13,-4,quark:basalt_wall:0)
Block(-8,13,-3,quark:basalt_wall:0)
Block(-8,13,-2,quark:world_stone_pavement:2)
Block(-8,14,-6,quark:world_stone_pavement:2)
Block(-8,14,-5,quark:world_stone_pavement:2)
Block(-8,14,-4,quark:world_stone_pavement:2)
Block(-8,14,-3,quark:world_stone_pavement:2)
Block(-8,14,-2,quark:world_stone_pavement:2)
Block(-7,0,-7,quark:limestone:0)
RandomBlock(-7,0,-6,quark:iron_plate:1,null,70,STAINED_CLAY:15,null,30,STAINED_CLAY:7,null,30,quark:iron_plate:1,null,100)
RandomBlock(-7,0,-5,quark:iron_plate:1,null,70,STAINED_CLAY:15,null,30,STAINED_CLAY:7,null,30,quark:iron_plate:1,null,100)
RandomBlock(-7,0,-4,quark:iron_plate:1,null,70,STAINED_CLAY:15,null,30,STAINED_CLAY:7,null,30,quark:iron_plate:1,null,100)
RandomBlock(-7,0,-3,quark:iron_plate:1,null,70,STAINED_CLAY:15,null,30,STAINED_CLAY:7,null,30,quark:iron_plate:1,null,100)
RandomBlock(-7,0,-2,quark:iron_plate:1,null,70,STAINED_CLAY:15,null,30,STAINED_CLAY:7,null,30,quark:iron_plate:1,null,100)
Block(-7,0,-1,quark:limestone:0)
Block(-7,1,-7,quark:world_stone_pavement:2)
RandomBlock(-7,1,-6,quark:iron_plate:1,null,70,STAINED_CLAY:15,null,30,STAINED_CLAY:7,null,30,quark:iron_plate:1,null,100)
RandomBlock(-7,1,-5,quark:iron_plate:1,null,70,STAINED_CLAY:15,null,30,STAINED_CLAY:7,null,30,quark:iron_plate:1,null,100)
RandomBlock(-7,1,-4,quark:iron_plate:1,null,70,STAINED_CLAY:15,null,30,STAINED_CLAY:7,null,30,quark:iron_plate:1,null,100)
RandomBlock(-7,1,-3,quark:iron_plate:1,null,70,STAINED_CLAY:15,null,30,STAINED_CLAY:7,null,30,quark:iron_plate:1,null,100)
RandomBlock(-7,1,-2,quark:iron_plate:1,null,70,STAINED_CLAY:15,null,30,STAINED_CLAY:7,null,30,quark:iron_plate:1,null,100)
Block(-7,1,-1,quark:world_stone_pavement:2)
Block(-7,2,-7,quark:world_stone_pavement:2)
RandomBlock(-7,2,-6,quark:iron_plate:1,null,70,STAINED_CLAY:15,null,30,STAINED_CLAY:7,null,30,quark:iron_plate:1,null,100)
RandomBlock(-7,2,-5,quark:iron_plate:1,null,70,STAINED_CLAY:15,null,30,STAINED_CLAY:7,null,30,quark:iron_plate:1,null,100)
RandomBlock(-7,2,-4,quark:iron_plate:1,null,70,STAINED_CLAY:15,null,30,STAINED_CLAY:7,null,30,quark:iron_plate:1,null,100)
RandomBlock(-7,2,-3,quark:iron_plate:1,null,70,STAINED_CLAY:15,null,30,STAINED_CLAY:7,null,30,quark:iron_plate:1,null,100)
RandomBlock(-7,2,-2,quark:iron_plate:1,null,70,STAINED_CLAY:15,null,30,STAINED_CLAY:7,null,30,quark:iron_plate:1,null,100)
Block(-7,2,-1,quark:world_stone_pavement:2)
Block(-7,3,-7,quark:basalt_wall:0)
RandomBlock(-7,3,-6,quark:iron_plate:1,null,70,STAINED_CLAY:15,null,30,STAINED_CLAY:7,null,30,quark:iron_plate:1,null,100)
RandomBlock(-7,3,-5,quark:iron_plate:1,null,70,STAINED_CLAY:15,null,30,STAINED_CLAY:7,null,30,quark:iron_plate:1,null,100)
Block(-7,3,-4,srparasites:deadblood:1)
RandomBlock(-7,3,-3,quark:iron_plate:1,null,70,STAINED_CLAY:15,null,30,STAINED_CLAY:7,null,30,quark:iron_plate:1,null,100)
RandomBlock(-7,3,-2,quark:iron_plate:1,null,70,STAINED_CLAY:15,null,30,STAINED_CLAY:7,null,30,quark:iron_plate:1,null,100)
Block(-7,3,-1,quark:basalt_wall:0)
Block(-7,4,-7,quark:basalt_wall:0)
RandomBlock(-7,4,-6,quark:iron_plate:1,null,70,STAINED_CLAY:15,null,30,STAINED_CLAY:7,null,30,quark:iron_plate:1,null,100)
Block(-7,4,-5,srparasites:deadblood:1)
Block(-7,4,-4,srparasites:deadblood:1)
Block(-7,4,-3,srparasites:deadblood:1)
RandomBlock(-7,4,-2,quark:iron_plate:1,null,70,STAINED_CLAY:15,null,30,STAINED_CLAY:7,null,30,quark:iron_plate:1,null,100)
Block(-7,4,-1,quark:basalt_wall:0)
Block(-7,4,5,COBBLESTONE_STAIRS:6)
RandomBlock(-7,4,6,quark:iron_plate:1,null,70,STAINED_CLAY:15,null,30,STAINED_CLAY:7,null,30,quark:iron_plate:1,null,100)
RandomBlock(-7,4,7,quark:iron_plate:1,null,70,STAINED_CLAY:15,null,30,STAINED_CLAY:7,null,30,quark:iron_plate:1,null,100)
Block(-7,4,8,COBBLESTONE_STAIRS:7)
Block(-7,5,-7,quark:basalt_wall:0)
RandomBlock(-7,5,-6,quark:iron_plate:1,null,70,STAINED_CLAY:15,null,30,STAINED_CLAY:7,null,30,quark:iron_plate:1,null,100)
Block(-7,5,-5,srparasites:deadblood:1)
Block(-7,5,-4,srparasites:deadblood:1)
Block(-7,5,-3,srparasites:deadblood:1)
RandomBlock(-7,5,-2,quark:iron_plate:1,null,70,STAINED_CLAY:15,null,30,STAINED_CLAY:7,null,30,quark:iron_plate:1,null,100)
Block(-7,5,-1,quark:basalt_wall:0)
RandomBlock(-7,5,5,quark:iron_plate:1,null,70,STAINED_CLAY:15,null,30,STAINED_CLAY:7,null,30,quark:iron_plate:1,null,100)
Block(-7,5,6,AIR:0)
Block(-7,5,7,AIR:0)
RandomBlock(-7,5,8,quark:iron_plate:1,null,70,STAINED_CLAY:15,null,30,STAINED_CLAY:7,null,30,quark:iron_plate:1,null,100)
Block(-7,6,-7,quark:basalt_wall:0)
RandomBlock(-7,6,-6,quark:iron_plate:1,null,70,STAINED_CLAY:15,null,30,STAINED_CLAY:7,null,30,quark:iron_plate:1,null,100)
Block(-7,6,-5,srparasites:deadblood:1)
Block(-7,6,-4,srparasites:deadblood:1)
Block(-7,6,-3,srparasites:deadblood:1)
RandomBlock(-7,6,-2,quark:iron_plate:1,null,70,STAINED_CLAY:15,null,30,STAINED_CLAY:7,null,30,quark:iron_plate:1,null,100)
Block(-7,6,-1,quark:basalt_wall:0)
RandomBlock(-7,6,5,rustic:iron_lattice:1,null,30,rustic:iron_lattice:1,null,30,biomesoplenty:leaves_2:7,null,30,quark:iron_plate_stairs:6,null,10,quark:iron_plate_stairs:0,null,10,quark:iron_plate_stairs:5,null,10,quark:iron_plate_stairs:3,null,10,quark:iron_plate_slab:8,null,10,quark:iron_plate_stairs:7,null,10,quark:iron_plate_stairs:1,null,10,quark:iron_plate_slab:0,null,10,quark:iron_plate_stairs:4,null,10,quark:iron_plate_stairs:2,null,10,rustic:iron_lattice:1,null,50,rustic:iron_lattice:1,null,50,biomesoplenty:leaves_2:7,null,100)
Block(-7,6,6,AIR:0)
Block(-7,6,7,AIR:0)
RandomBlock(-7,6,8,quark:iron_plate:1,null,70,STAINED_CLAY:15,null,30,STAINED_CLAY:7,null,30,quark:iron_plate:1,null,100)
Block(-7,7,-7,quark:basalt_wall:0)
RandomBlock(-7,7,-6,quark:iron_plate:1,null,70,STAINED_CLAY:15,null,30,STAINED_CLAY:7,null,30,quark:iron_plate:1,null,100)
Block(-7,7,-5,srparasites:deadblood:1)
Block(-7,7,-4,srparasites:deadblood:1)
Block(-7,7,-3,srparasites:deadblood:1)
RandomBlock(-7,7,-2,quark:iron_plate:1,null,70,STAINED_CLAY:15,null,30,STAINED_CLAY:7,null,30,quark:iron_plate:1,null,100)
Block(-7,7,-1,quark:basalt_wall:0)
Block(-7,7,5,COBBLESTONE_STAIRS:2)
RandomBlock(-7,7,6,rustic:iron_lattice:1,null,30,rustic:iron_lattice:1,null,30,biomesoplenty:leaves_2:7,null,30,quark:iron_plate_stairs:6,null,10,quark:iron_plate_stairs:0,null,10,quark:iron_plate_stairs:5,null,10,quark:iron_plate_stairs:3,null,10,quark:iron_plate_slab:8,null,10,quark:iron_plate_stairs:7,null,10,quark:iron_plate_stairs:1,null,10,quark:iron_plate_slab:0,null,10,quark:iron_plate_stairs:4,null,10,quark:iron_plate_stairs:2,null,10,rustic:iron_lattice:1,null,50,rustic:iron_lattice:1,null,50,biomesoplenty:leaves_2:7,null,100)
RandomBlock(-7,7,7,quark:iron_plate:1,null,70,STAINED_CLAY:15,null,30,STAINED_CLAY:7,null,30,quark:iron_plate:1,null,100)
Block(-7,7,8,COBBLESTONE_STAIRS:3)
Block(-7,8,-7,quark:basalt_wall:0)
RandomBlock(-7,8,-6,quark:iron_plate:1,null,70,STAINED_CLAY:15,null,30,STAINED_CLAY:7,null,30,quark:iron_plate:1,null,100)
Block(-7,8,-5,srparasites:deadblood:1)
Block(-7,8,-4,srparasites:deadblood:1)
Block(-7,8,-3,srparasites:deadblood:1)
RandomBlock(-7,8,-2,quark:iron_plate:1,null,70,STAINED_CLAY:15,null,30,STAINED_CLAY:7,null,30,quark:iron_plate:1,null,100)
Block(-7,8,-1,quark:basalt_wall:0)
Block(-7,9,-7,quark:basalt_wall:0)
RandomBlock(-7,9,-6,quark:iron_plate:1,null,70,STAINED_CLAY:15,null,30,STAINED_CLAY:7,null,30,quark:iron_plate:1,null,100)
Block(-7,9,-5,srparasites:deadblood:0)
Block(-7,9,-4,srparasites:deadblood:0)
Block(-7,9,-3,srparasites:deadblood:0)
RandomBlock(-7,9,-2,quark:iron_plate:1,null,70,STAINED_CLAY:15,null,30,STAINED_CLAY:7,null,30,quark:iron_plate:1,null,100)
Block(-7,9,-1,quark:basalt_wall:0)
Block(-7,10,-7,quark:basalt_wall:0)
RandomBlock(-7,10,-6,quark:iron_plate:1,null,70,STAINED_CLAY:15,null,30,STAINED_CLAY:7,null,30,quark:iron_plate:1,null,100)
Block(-7,10,-5,AIR:0)
Block(-7,10,-4,AIR:0)
Block(-7,10,-3,AIR:0)
RandomBlock(-7,10,-2,quark:iron_plate:1,null,70,STAINED_CLAY:15,null,30,STAINED_CLAY:7,null,30,quark:iron_plate:1,null,100)
Block(-7,10,-1,quark:basalt_wall:0)
Block(-7,11,-7,quark:basalt_wall:0)
RandomBlock(-7,11,-6,quark:iron_plate:1,null,70,STAINED_CLAY:15,null,30,STAINED_CLAY:7,null,30,quark:iron_plate:1,null,100)
Block(-7,11,-5,AIR:0)
Block(-7,11,-4,AIR:0)
Block(-7,11,-3,AIR:0)
RandomBlock(-7,11,-2,quark:iron_plate:1,null,70,STAINED_CLAY:15,null,30,STAINED_CLAY:7,null,30,quark:iron_plate:1,null,100)
Block(-7,11,-1,quark:basalt_wall:0)
Block(-7,12,-7,quark:basalt_wall:0)
RandomBlock(-7,12,-6,quark:iron_plate:1,null,70,STAINED_CLAY:15,null,30,STAINED_CLAY:7,null,30,quark:iron_plate:1,null,100)
RandomBlock(-7,12,-5,quark:iron_plate:1,null,70,STAINED_CLAY:15,null,30,STAINED_CLAY:7,null,30,quark:iron_plate:1,null,100)
Block(-7,12,-4,AIR:0)
RandomBlock(-7,12,-3,quark:iron_plate:1,null,70,STAINED_CLAY:15,null,30,STAINED_CLAY:7,null,30,quark:iron_plate:1,null,100)
RandomBlock(-7,12,-2,quark:iron_plate:1,null,70,STAINED_CLAY:15,null,30,STAINED_CLAY:7,null,30,quark:iron_plate:1,null,100)
Block(-7,12,-1,quark:basalt_wall:0)
Block(-7,13,-7,quark:world_stone_pavement:2)
RandomBlock(-7,13,-6,quark:iron_plate:1,null,70,STAINED_CLAY:15,null,30,STAINED_CLAY:7,null,30,quark:iron_plate:1,null,100)
RandomBlock(-7,13,-5,quark:iron_plate:1,null,70,STAINED_CLAY:15,null,30,STAINED_CLAY:7,null,30,quark:iron_plate:1,null,100)
RandomBlock(-7,13,-4,quark:iron_plate:1,null,70,STAINED_CLAY:15,null,30,STAINED_CLAY:7,null,30,quark:iron_plate:1,null,100)
RandomBlock(-7,13,-3,quark:iron_plate:1,null,70,STAINED_CLAY:15,null,30,STAINED_CLAY:7,null,30,quark:iron_plate:1,null,100)
RandomBlock(-7,13,-2,quark:iron_plate:1,null,70,STAINED_CLAY:15,null,30,STAINED_CLAY:7,null,30,quark:iron_plate:1,null,100)
Block(-7,13,-1,quark:world_stone_pavement:2)
Block(-7,14,-7,quark:world_stone_pavement:2)
RandomBlock(-7,14,-6,quark:iron_plate:1,null,70,STAINED_CLAY:15,null,30,STAINED_CLAY:7,null,30,quark:iron_plate:1,null,100)
RandomBlock(-7,14,-5,quark:iron_plate:1,null,70,STAINED_CLAY:15,null,30,STAINED_CLAY:7,null,30,quark:iron_plate:1,null,100)
RandomBlock(-7,14,-4,quark:iron_plate:1,null,70,STAINED_CLAY:15,null,30,STAINED_CLAY:7,null,30,quark:iron_plate:1,null,100)
RandomBlock(-7,14,-3,quark:iron_plate:1,null,70,STAINED_CLAY:15,null,30,STAINED_CLAY:7,null,30,quark:iron_plate:1,null,100)
RandomBlock(-7,14,-2,quark:iron_plate:1,null,70,STAINED_CLAY:15,null,30,STAINED_CLAY:7,null,30,quark:iron_plate:1,null,100)
Block(-7,14,-1,quark:world_stone_pavement:2)
Block(-7,15,-6,COBBLESTONE_STAIRS:0)
Block(-7,15,-5,COBBLESTONE_STAIRS:0)
Block(-7,15,-4,COBBLESTONE_STAIRS:0)
Block(-7,15,-3,COBBLESTONE_STAIRS:0)
Block(-7,15,-2,COBBLESTONE_STAIRS:3)
Block(-6,0,-7,quark:limestone:0)
RandomBlock(-6,0,-6,quark:iron_plate:1,null,70,STAINED_CLAY:15,null,30,STAINED_CLAY:7,null,30,quark:iron_plate:1,null,100)
RandomBlock(-6,0,-5,quark:iron_plate:1,null,70,STAINED_CLAY:15,null,30,STAINED_CLAY:7,null,30,quark:iron_plate:1,null,100)
RandomBlock(-6,0,-4,quark:iron_plate:1,null,70,STAINED_CLAY:15,null,30,STAINED_CLAY:7,null,30,quark:iron_plate:1,null,100)
RandomBlock(-6,0,-3,quark:iron_plate:1,null,70,STAINED_CLAY:15,null,30,STAINED_CLAY:7,null,30,quark:iron_plate:1,null,100)
RandomBlock(-6,0,-2,quark:iron_plate:1,null,70,STAINED_CLAY:15,null,30,STAINED_CLAY:7,null,30,quark:iron_plate:1,null,100)
Block(-6,0,-1,quark:limestone:0)
Block(-6,1,-7,quark:world_stone_pavement:2)
RandomBlock(-6,1,-6,quark:iron_plate:1,null,70,STAINED_CLAY:15,null,30,STAINED_CLAY:7,null,30,quark:iron_plate:1,null,100)
Block(-6,1,-5,srparasites:deadblood:1)
Block(-6,1,-4,srparasites:deadblood:1)
Block(-6,1,-3,srparasites:deadblood:1)
RandomBlock(-6,1,-2,quark:iron_plate:1,null,70,STAINED_CLAY:15,null,30,STAINED_CLAY:7,null,30,quark:iron_plate:1,null,100)
Block(-6,1,-1,quark:world_stone_pavement:2)
Block(-6,2,-7,quark:basalt_wall:0)
RandomBlock(-6,2,-6,quark:iron_plate:1,null,70,STAINED_CLAY:15,null,30,STAINED_CLAY:7,null,30,quark:iron_plate:1,null,100)
Block(-6,2,-5,srparasites:deadblood:1)
Block(-6,2,-4,srparasites:deadblood:1)
Block(-6,2,-3,srparasites:deadblood:1)
RandomBlock(-6,2,-2,quark:iron_plate:1,null,70,STAINED_CLAY:15,null,30,STAINED_CLAY:7,null,30,quark:iron_plate:1,null,100)
Block(-6,2,-1,quark:world_stone_pavement:2)
Block(-6,3,-7,quark:basalt_wall:0)
RandomBlock(-6,3,-6,quark:iron_plate:1,null,70,STAINED_CLAY:15,null,30,STAINED_CLAY:7,null,30,quark:iron_plate:1,null,100)
Block(-6,3,-5,srparasites:deadblood:1)
Block(-6,3,-4,srparasites:deadblood:1)
Block(-6,3,-3,srparasites:deadblood:1)
RandomBlock(-6,3,-2,quark:iron_plate:1,null,70,STAINED_CLAY:15,null,30,STAINED_CLAY:7,null,30,quark:iron_plate:1,null,100)
Block(-6,3,-1,quark:world_stone_pavement:2)
Block(-6,4,-7,quark:world_stone_pavement:2)
Block(-6,4,-6,srparasites:deadblood:1)
Block(-6,4,-5,srparasites:deadblood:1)
Block(-6,4,-4,srparasites:deadblood:1)
Block(-6,4,-3,srparasites:deadblood:1)
RandomBlock(-6,4,-2,quark:iron_plate:1,null,70,STAINED_CLAY:15,null,30,STAINED_CLAY:7,null,30,quark:iron_plate:1,null,100)
Block(-6,4,-1,quark:world_stone_pavement:2)
Block(-6,4,0,COBBLESTONE_STAIRS:4)
Block(-6,4,1,COBBLESTONE_STAIRS:4)
Block(-6,4,2,COBBLESTONE_STAIRS:4)
Block(-6,4,3,COBBLESTONE_STAIRS:4)
Block(-6,4,4,COBBLESTONE_STAIRS:4)
Block(-6,4,5,COBBLESTONE_STAIRS:6)
RandomBlock(-6,4,6,quark:iron_plate:1,null,70,STAINED_CLAY:15,null,30,STAINED_CLAY:7,null,30,quark:iron_plate:1,null,100)
RandomBlock(-6,4,7,quark:iron_plate:1,null,70,STAINED_CLAY:15,null,30,STAINED_CLAY:7,null,30,quark:iron_plate:1,null,100)
Block(-6,4,8,COBBLESTONE_STAIRS:7)
Block(-6,5,-7,quark:world_stone_pavement:2)
Block(-6,5,-6,srparasites:deadblood:1)
Block(-6,5,-5,srparasites:deadblood:1)
Block(-6,5,-4,srparasites:deadblood:1)
Block(-6,5,-3,srparasites:deadblood:1)
RandomBlock(-6,5,-2,quark:iron_plate:1,null,70,STAINED_CLAY:15,null,30,STAINED_CLAY:7,null,30,quark:iron_plate:1,null,100)
RandomBlock(-6,5,-1,quark:iron_plate:1,null,70,STAINED_CLAY:15,null,30,STAINED_CLAY:7,null,30,quark:iron_plate:1,null,100)
RandomBlock(-6,5,0,quark:iron_plate:1,null,70,STAINED_CLAY:15,null,30,STAINED_CLAY:7,null,30,quark:iron_plate:1,null,100)
RandomBlock(-6,5,1,quark:iron_plate:1,null,70,STAINED_CLAY:15,null,30,STAINED_CLAY:7,null,30,quark:iron_plate:1,null,100)
RandomBlock(-6,5,2,quark:iron_plate:1,null,70,STAINED_CLAY:15,null,30,STAINED_CLAY:7,null,30,quark:iron_plate:1,null,100)
RandomBlock(-6,5,3,quark:iron_plate:1,null,70,STAINED_CLAY:15,null,30,STAINED_CLAY:7,null,30,quark:iron_plate:1,null,100)
RandomBlock(-6,5,4,quark:iron_plate:1,null,70,STAINED_CLAY:15,null,30,STAINED_CLAY:7,null,30,quark:iron_plate:1,null,100)
RandomBlock(-6,5,5,quark:iron_plate:1,null,70,STAINED_CLAY:15,null,30,STAINED_CLAY:7,null,30,quark:iron_plate:1,null,100)
Block(-6,5,6,AIR:0)
Block(-6,5,7,AIR:0)
RandomBlock(-6,5,8,rustic:iron_lattice:1,null,30,rustic:iron_lattice:1,null,30,biomesoplenty:leaves_2:7,null,30,quark:iron_plate_stairs:6,null,10,quark:iron_plate_stairs:0,null,10,quark:iron_plate_stairs:5,null,10,quark:iron_plate_stairs:3,null,10,quark:iron_plate_slab:8,null,10,quark:iron_plate_stairs:7,null,10,quark:iron_plate_stairs:1,null,10,quark:iron_plate_slab:0,null,10,quark:iron_plate_stairs:4,null,10,quark:iron_plate_stairs:2,null,10,rustic:iron_lattice:1,null,50,rustic:iron_lattice:1,null,50,biomesoplenty:leaves_2:7,null,100)
Block(-6,6,-7,quark:world_stone_pavement:2)
Block(-6,6,-6,srparasites:deadblood:1)
Block(-6,6,-5,srparasites:deadblood:1)
Block(-6,6,-4,srparasites:deadblood:1)
Block(-6,6,-3,srparasites:deadblood:1)
RandomBlock(-6,6,-2,quark:iron_plate:1,null,70,STAINED_CLAY:15,null,30,STAINED_CLAY:7,null,30,quark:iron_plate:1,null,100)
RandomBlock(-6,6,-1,quark:iron_plate:1,null,70,STAINED_CLAY:15,null,30,STAINED_CLAY:7,null,30,quark:iron_plate:1,null,100)
RandomBlock(-6,6,0,quark:iron_plate:1,null,70,STAINED_CLAY:15,null,30,STAINED_CLAY:7,null,30,quark:iron_plate:1,null,100)
RandomBlock(-6,6,1,quark:iron_plate:1,null,70,STAINED_CLAY:15,null,30,STAINED_CLAY:7,null,30,quark:iron_plate:1,null,100)
RandomBlock(-6,6,2,quark:iron_plate:1,null,70,STAINED_CLAY:15,null,30,STAINED_CLAY:7,null,30,quark:iron_plate:1,null,100)
RandomBlock(-6,6,3,quark:iron_plate:1,null,70,STAINED_CLAY:15,null,30,STAINED_CLAY:7,null,30,quark:iron_plate:1,null,100)
RandomBlock(-6,6,4,quark:iron_plate:1,null,70,STAINED_CLAY:15,null,30,STAINED_CLAY:7,null,30,quark:iron_plate:1,null,100)
RandomBlock(-6,6,5,quark:iron_plate:1,null,70,STAINED_CLAY:15,null,30,STAINED_CLAY:7,null,30,quark:iron_plate:1,null,100)
Block(-6,6,6,AIR:0)
Block(-6,6,7,AIR:0)
RandomBlock(-6,6,8,quark:iron_plate:1,null,70,STAINED_CLAY:15,null,30,STAINED_CLAY:7,null,30,quark:iron_plate:1,null,100)
Block(-6,7,-7,quark:world_stone_pavement:2)
Block(-6,7,-6,srparasites:deadblood:1)
Block(-6,7,-5,srparasites:deadblood:1)
Block(-6,7,-4,srparasites:deadblood:1)
Block(-6,7,-3,srparasites:deadblood:1)
RandomBlock(-6,7,-2,quark:iron_plate:1,null,70,STAINED_CLAY:15,null,30,STAINED_CLAY:7,null,30,quark:iron_plate:1,null,100)
Block(-6,7,-1,quark:world_stone_pavement:2)
Block(-6,7,0,COBBLESTONE_STAIRS:0)
RandomBlock(-6,7,1,quark:iron_plate:1,null,70,STAINED_CLAY:15,null,30,STAINED_CLAY:7,null,30,quark:iron_plate:1,null,100)
RandomBlock(-6,7,2,quark:iron_plate:1,null,70,STAINED_CLAY:15,null,30,STAINED_CLAY:7,null,30,quark:iron_plate:1,null,100)
RandomBlock(-6,7,3,quark:iron_plate:1,null,70,STAINED_CLAY:15,null,30,STAINED_CLAY:7,null,30,quark:iron_plate:1,null,100)
Block(-6,7,4,COBBLESTONE_STAIRS:0)
Block(-6,7,5,COBBLESTONE_STAIRS:2)
RandomBlock(-6,7,6,rustic:iron_lattice:1,null,30,rustic:iron_lattice:1,null,30,biomesoplenty:leaves_2:7,null,30,quark:iron_plate_stairs:6,null,10,quark:iron_plate_stairs:0,null,10,quark:iron_plate_stairs:5,null,10,quark:iron_plate_stairs:3,null,10,quark:iron_plate_slab:8,null,10,quark:iron_plate_stairs:7,null,10,quark:iron_plate_stairs:1,null,10,quark:iron_plate_slab:0,null,10,quark:iron_plate_stairs:4,null,10,quark:iron_plate_stairs:2,null,10,rustic:iron_lattice:1,null,50,rustic:iron_lattice:1,null,50,biomesoplenty:leaves_2:7,null,100)
RandomBlock(-6,7,7,quark:iron_plate:1,null,70,STAINED_CLAY:15,null,30,STAINED_CLAY:7,null,30,quark:iron_plate:1,null,100)
Block(-6,7,8,COBBLESTONE_STAIRS:3)
Block(-6,8,-7,quark:world_stone_pavement:2)
Block(-6,8,-6,srparasites:deadblood:1)
Block(-6,8,-5,srparasites:deadblood:1)
Block(-6,8,-4,srparasites:deadblood:1)
Block(-6,8,-3,srparasites:deadblood:1)
Block(-6,8,-2,srparasites:deadblood:1)
Block(-6,8,-1,quark:world_stone_pavement:2)
Block(-6,8,1,quark:iron_plate_slab:0)
Block(-6,8,2,quark:iron_plate_slab:0)
Block(-6,8,3,quark:iron_plate_slab:0)
Block(-6,9,-7,quark:world_stone_pavement:2)
Block(-6,9,-6,srparasites:deadblood:0)
Block(-6,9,-5,srparasites:deadblood:1)
Block(-6,9,-4,srparasites:deadblood:1)
Block(-6,9,-3,srparasites:deadblood:1)
Block(-6,9,-2,srparasites:deadblood:0)
Block(-6,9,-1,quark:world_stone_pavement:2)
Block(-6,9,1,rustic:iron_lattice:0)
Block(-6,9,2,rustic:iron_lattice:0)
Block(-6,9,3,rustic:iron_lattice:0)
Block(-6,10,-7,quark:world_stone_pavement:2)
Block(-6,10,-6,AIR:0)
Block(-6,10,-5,AIR:0)
Block(-6,10,-4,AIR:0)
Block(-6,10,-3,AIR:0)
Block(-6,10,-2,AIR:0)
Block(-6,10,-1,quark:world_stone_pavement:2)
Block(-6,11,-7,quark:world_stone_pavement:2)
Block(-6,11,-6,AIR:0)
Block(-6,11,-5,AIR:0)
Block(-6,11,-4,AIR:0)
Block(-6,11,-3,AIR:0)
Block(-6,11,-2,AIR:0)
Block(-6,11,-1,quark:world_stone_pavement:2)
Block(-6,12,-7,quark:basalt_wall:0)
RandomBlock(-6,12,-6,quark:iron_plate:1,null,70,STAINED_CLAY:15,null,30,STAINED_CLAY:7,null,30,quark:iron_plate:1,null,100)
Block(-6,12,-5,AIR:0)
Block(-6,12,-4,AIR:0)
Block(-6,12,-3,AIR:0)
RandomBlock(-6,12,-2,quark:iron_plate:1,null,70,STAINED_CLAY:15,null,30,STAINED_CLAY:7,null,30,quark:iron_plate:1,null,100)
Block(-6,12,-1,quark:basalt_wall:0)
Block(-6,13,-7,quark:basalt_wall:0)
RandomBlock(-6,13,-6,quark:iron_plate:1,null,70,STAINED_CLAY:15,null,30,STAINED_CLAY:7,null,30,quark:iron_plate:1,null,100)
Block(-6,13,-5,AIR:0)
Block(-6,13,-4,AIR:0)
Block(-6,13,-3,AIR:0)
RandomBlock(-6,13,-2,quark:iron_plate:1,null,70,STAINED_CLAY:15,null,30,STAINED_CLAY:7,null,30,quark:iron_plate:1,null,100)
Block(-6,13,-1,quark:basalt_wall:0)
Block(-6,14,-7,quark:world_stone_pavement:2)
RandomBlock(-6,14,-6,quark:iron_plate:1,null,70,STAINED_CLAY:15,null,30,STAINED_CLAY:7,null,30,quark:iron_plate:1,null,100)
RandomBlock(-6,14,-5,quark:iron_plate:1,null,70,STAINED_CLAY:15,null,30,STAINED_CLAY:7,null,30,quark:iron_plate:1,null,100)
RandomBlock(-6,14,-4,quark:iron_plate:1,null,70,STAINED_CLAY:15,null,30,STAINED_CLAY:7,null,30,quark:iron_plate:1,null,100)
RandomBlock(-6,14,-3,quark:iron_plate:1,null,70,STAINED_CLAY:15,null,30,STAINED_CLAY:7,null,30,quark:iron_plate:1,null,100)
RandomBlock(-6,14,-2,quark:iron_plate:1,null,70,STAINED_CLAY:15,null,30,STAINED_CLAY:7,null,30,quark:iron_plate:1,null,100)
Block(-6,14,-1,quark:world_stone_pavement:2)
Block(-6,15,-6,COBBLESTONE_STAIRS:2)
RandomBlock(-6,15,-5,quark:iron_plate:1,null,70,STAINED_CLAY:15,null,30,STAINED_CLAY:7,null,30,quark:iron_plate:1,null,100)
RandomBlock(-6,15,-4,quark:iron_plate:1,null,70,STAINED_CLAY:15,null,30,STAINED_CLAY:7,null,30,quark:iron_plate:1,null,100)
RandomBlock(-6,15,-3,quark:iron_plate:1,null,70,STAINED_CLAY:15,null,30,STAINED_CLAY:7,null,30,quark:iron_plate:1,null,100)
Block(-6,15,-2,COBBLESTONE_STAIRS:3)
Block(-5,0,-7,quark:limestone:0)
RandomBlock(-5,0,-6,quark:iron_plate:1,null,70,STAINED_CLAY:15,null,30,STAINED_CLAY:7,null,30,quark:iron_plate:1,null,100)
RandomBlock(-5,0,-5,quark:iron_plate:1,null,70,STAINED_CLAY:15,null,30,STAINED_CLAY:7,null,30,quark:iron_plate:1,null,100)
RandomBlock(-5,0,-4,quark:iron_plate:1,null,70,STAINED_CLAY:15,null,30,STAINED_CLAY:7,null,30,quark:iron_plate:1,null,100)
RandomBlock(-5,0,-3,quark:iron_plate:1,null,70,STAINED_CLAY:15,null,30,STAINED_CLAY:7,null,30,quark:iron_plate:1,null,100)
RandomBlock(-5,0,-2,quark:iron_plate:1,null,70,STAINED_CLAY:15,null,30,STAINED_CLAY:7,null,30,quark:iron_plate:1,null,100)
Block(-5,0,-1,quark:limestone:0)
Block(-5,1,-7,quark:world_stone_pavement:2)
RandomBlock(-5,1,-6,quark:iron_plate:1,null,70,STAINED_CLAY:15,null,30,STAINED_CLAY:7,null,30,quark:iron_plate:1,null,100)
Block(-5,1,-5,srparasites:deadblood:1)
Block(-5,1,-4,srparasites:deadblood:1)
Block(-5,1,-3,srparasites:deadblood:1)
RandomBlock(-5,1,-2,quark:iron_plate:1,null,70,STAINED_CLAY:15,null,30,STAINED_CLAY:7,null,30,quark:iron_plate:1,null,100)
Block(-5,1,-1,quark:world_stone_pavement:2)
Block(-5,2,-7,quark:basalt_wall:0)
RandomBlock(-5,2,-6,quark:iron_plate:1,null,70,STAINED_CLAY:15,null,30,STAINED_CLAY:7,null,30,quark:iron_plate:1,null,100)
Block(-5,2,-5,srparasites:deadblood:1)
Block(-5,2,-4,srparasites:deadblood:1)
Block(-5,2,-3,srparasites:deadblood:1)
RandomBlock(-5,2,-2,quark:iron_plate:1,null,70,STAINED_CLAY:15,null,30,STAINED_CLAY:7,null,30,quark:iron_plate:1,null,100)
Block(-5,2,-1,quark:world_stone_pavement:2)
Block(-5,3,-7,quark:world_stone_pavement:2)
Block(-5,3,-6,srparasites:deadblood:1)
Block(-5,3,-5,srparasites:deadblood:1)
Block(-5,3,-4,srparasites:deadblood:1)
Block(-5,3,-3,srparasites:deadblood:1)
RandomBlock(-5,3,-2,quark:iron_plate:1,null,70,STAINED_CLAY:15,null,30,STAINED_CLAY:7,null,30,quark:iron_plate:1,null,100)
Block(-5,3,-1,quark:world_stone_pavement:2)
Block(-5,4,-7,quark:world_stone_pavement:2)
Block(-5,4,-6,srparasites:deadblood:1)
Block(-5,4,-5,srparasites:deadblood:1)
Block(-5,4,-4,srparasites:deadblood:1)
Block(-5,4,-3,srparasites:deadblood:1)
RandomBlock(-5,4,-2,quark:iron_plate:1,null,70,STAINED_CLAY:15,null,30,STAINED_CLAY:7,null,30,quark:iron_plate:1,null,100)
RandomBlock(-5,4,-1,quark:iron_plate:1,null,70,STAINED_CLAY:15,null,30,STAINED_CLAY:7,null,30,quark:iron_plate:1,null,100)
RandomBlock(-5,4,0,quark:iron_plate:1,null,70,STAINED_CLAY:15,null,30,STAINED_CLAY:7,null,30,quark:iron_plate:1,null,100)
RandomBlock(-5,4,1,quark:iron_plate:1,null,70,STAINED_CLAY:15,null,30,STAINED_CLAY:7,null,30,quark:iron_plate:1,null,100)
RandomBlock(-5,4,2,quark:iron_plate:1,null,70,STAINED_CLAY:15,null,30,STAINED_CLAY:7,null,30,quark:iron_plate:1,null,100)
RandomBlock(-5,4,3,quark:iron_plate:1,null,70,STAINED_CLAY:15,null,30,STAINED_CLAY:7,null,30,quark:iron_plate:1,null,100)
RandomBlock(-5,4,4,quark:iron_plate:1,null,70,STAINED_CLAY:15,null,30,STAINED_CLAY:7,null,30,quark:iron_plate:1,null,100)
RandomBlock(-5,4,5,quark:iron_plate:1,null,70,STAINED_CLAY:15,null,30,STAINED_CLAY:7,null,30,quark:iron_plate:1,null,100)
RandomBlock(-5,4,6,quark:iron_plate:1,null,70,STAINED_CLAY:15,null,30,STAINED_CLAY:7,null,30,quark:iron_plate:1,null,100)
RandomBlock(-5,4,7,quark:iron_plate:1,null,70,STAINED_CLAY:15,null,30,STAINED_CLAY:7,null,30,quark:iron_plate:1,null,100)
Block(-5,4,8,COBBLESTONE_STAIRS:7)
Block(-5,5,-7,quark:framed_glass:0)
Block(-5,5,-6,srparasites:deadblood:1)
Block(-5,5,-5,srparasites:deadblood:1)
Block(-5,5,-4,srparasites:deadblood:1)
Block(-5,5,-3,srparasites:deadblood:1)
Block(-5,5,-2,srparasites:deadblood:1)
Block(-5,5,-1,srparasites:deadblood:1)
Block(-5,5,0,srparasites:deadblood:1)
Block(-5,5,1,srparasites:deadblood:1)
Block(-5,5,2,SMOOTH_STAIRS:3)
Block(-5,5,3,AIR:0)
Block(-5,5,4,AIR:0)
Block(-5,5,5,AIR:0)
Block(-5,5,6,AIR:0)
Block(-5,5,7,AIR:0)
RandomBlock(-5,5,8,rustic:iron_lattice:1,null,30,rustic:iron_lattice:1,null,30,biomesoplenty:leaves_2:7,null,30,quark:iron_plate_stairs:6,null,10,quark:iron_plate_stairs:0,null,10,quark:iron_plate_stairs:5,null,10,quark:iron_plate_stairs:3,null,10,quark:iron_plate_slab:8,null,10,quark:iron_plate_stairs:7,null,10,quark:iron_plate_stairs:1,null,10,quark:iron_plate_slab:0,null,10,quark:iron_plate_stairs:4,null,10,quark:iron_plate_stairs:2,null,10,rustic:iron_lattice:1,null,50,rustic:iron_lattice:1,null,50,biomesoplenty:leaves_2:7,null,100)
Block(-5,6,-7,quark:framed_glass:0)
Block(-5,6,-6,srparasites:deadblood:1)
Block(-5,6,-5,srparasites:deadblood:1)
Block(-5,6,-4,srparasites:deadblood:1)
Block(-5,6,-3,srparasites:deadblood:1)
Block(-5,6,-2,srparasites:deadblood:0)
Block(-5,6,-1,srparasites:deadblood:0)
Block(-5,6,0,srparasites:deadblood:0)
Block(-5,6,1,srparasites:deadblood:0)
Block(-5,6,2,SMOOTH_STAIRS:7)
Block(-5,6,3,AIR:0)
Block(-5,6,4,AIR:0)
Block(-5,6,5,AIR:0)
Block(-5,6,6,AIR:0)
Block(-5,6,7,AIR:0)
RandomBlock(-5,6,8,rustic:iron_lattice:1,null,30,rustic:iron_lattice:1,null,30,biomesoplenty:leaves_2:7,null,30,quark:iron_plate_stairs:6,null,10,quark:iron_plate_stairs:0,null,10,quark:iron_plate_stairs:5,null,10,quark:iron_plate_stairs:3,null,10,quark:iron_plate_slab:8,null,10,quark:iron_plate_stairs:7,null,10,quark:iron_plate_stairs:1,null,10,quark:iron_plate_slab:0,null,10,quark:iron_plate_stairs:4,null,10,quark:iron_plate_stairs:2,null,10,rustic:iron_lattice:1,null,50,rustic:iron_lattice:1,null,50,biomesoplenty:leaves_2:7,null,100)
Block(-5,7,-7,quark:framed_glass:0)
Block(-5,7,-6,srparasites:deadblood:1)
Block(-5,7,-5,srparasites:deadblood:1)
Block(-5,7,-4,srparasites:deadblood:1)
Block(-5,7,-3,srparasites:deadblood:1)
Block(-5,7,-2,srparasites:deadblood:1)
Block(-5,7,-1,quark:world_stone_pavement:2)
RandomBlock(-5,7,0,quark:iron_plate:1,null,70,STAINED_CLAY:15,null,30,STAINED_CLAY:7,null,30,quark:iron_plate:1,null,100)
RandomBlock(-5,7,1,quark:iron_plate:1,null,70,STAINED_CLAY:15,null,30,STAINED_CLAY:7,null,30,quark:iron_plate:1,null,100)
RandomBlock(-5,7,2,quark:iron_plate:1,null,70,STAINED_CLAY:15,null,30,STAINED_CLAY:7,null,30,quark:iron_plate:1,null,100)
RandomBlock(-5,7,3,quark:iron_plate:1,null,70,STAINED_CLAY:15,null,30,STAINED_CLAY:7,null,30,quark:iron_plate:1,null,100)
RandomBlock(-5,7,4,quark:iron_plate:1,null,70,STAINED_CLAY:15,null,30,STAINED_CLAY:7,null,30,quark:iron_plate:1,null,100)
RandomBlock(-5,7,5,rustic:iron_lattice:1,null,30,rustic:iron_lattice:1,null,30,biomesoplenty:leaves_2:7,null,30,quark:iron_plate_stairs:6,null,10,quark:iron_plate_stairs:0,null,10,quark:iron_plate_stairs:5,null,10,quark:iron_plate_stairs:3,null,10,quark:iron_plate_slab:8,null,10,quark:iron_plate_stairs:7,null,10,quark:iron_plate_stairs:1,null,10,quark:iron_plate_slab:0,null,10,quark:iron_plate_stairs:4,null,10,quark:iron_plate_stairs:2,null,10,rustic:iron_lattice:1,null,50,rustic:iron_lattice:1,null,50,biomesoplenty:leaves_2:7,null,100)
RandomBlock(-5,7,6,rustic:iron_lattice:1,null,30,rustic:iron_lattice:1,null,30,biomesoplenty:leaves_2:7,null,30,quark:iron_plate_stairs:6,null,10,quark:iron_plate_stairs:0,null,10,quark:iron_plate_stairs:5,null,10,quark:iron_plate_stairs:3,null,10,quark:iron_plate_slab:8,null,10,quark:iron_plate_stairs:7,null,10,quark:iron_plate_stairs:1,null,10,quark:iron_plate_slab:0,null,10,quark:iron_plate_stairs:4,null,10,quark:iron_plate_stairs:2,null,10,rustic:iron_lattice:1,null,50,rustic:iron_lattice:1,null,50,biomesoplenty:leaves_2:7,null,100)
RandomBlock(-5,7,7,rustic:iron_lattice:1,null,30,rustic:iron_lattice:1,null,30,biomesoplenty:leaves_2:7,null,30,quark:iron_plate_stairs:6,null,10,quark:iron_plate_stairs:0,null,10,quark:iron_plate_stairs:5,null,10,quark:iron_plate_stairs:3,null,10,quark:iron_plate_slab:8,null,10,quark:iron_plate_stairs:7,null,10,quark:iron_plate_stairs:1,null,10,quark:iron_plate_slab:0,null,10,quark:iron_plate_stairs:4,null,10,quark:iron_plate_stairs:2,null,10,rustic:iron_lattice:1,null,50,rustic:iron_lattice:1,null,50,biomesoplenty:leaves_2:7,null,100)
Block(-5,7,8,COBBLESTONE_STAIRS:3)
Block(-5,8,-7,quark:framed_glass:0)
Block(-5,8,-6,srparasites:deadblood:1)
Block(-5,8,-5,srparasites:deadblood:1)
Block(-5,8,-4,srparasites:deadblood:1)
Block(-5,8,-3,srparasites:deadblood:1)
Block(-5,8,-2,srparasites:deadblood:1)
Block(-5,8,-1,quark:world_stone_pavement:2)
Block(-5,8,1,quark:iron_plate_slab:0)
Block(-5,8,2,quark:basalt_wall:0)
Block(-5,8,3,quark:iron_plate_slab:0)
Block(-5,9,-7,quark:framed_glass:0)
Block(-5,9,-6,srparasites:deadblood:0)
Block(-5,9,-5,srparasites:deadblood:0)
Block(-5,9,-4,srparasites:deadblood:1)
Block(-5,9,-3,srparasites:deadblood:1)
Block(-5,9,-2,srparasites:deadblood:1)
Block(-5,9,-1,quark:framed_glass:0)
Block(-5,9,1,rustic:iron_lattice:0)
Block(-5,9,2,rustic:iron_lattice:0)
Block(-5,9,3,rustic:iron_lattice:0)
Block(-5,10,-7,quark:framed_glass:0)
Block(-5,10,-6,AIR:0)
Block(-5,10,-5,AIR:0)
Block(-5,10,-4,AIR:0)
Block(-5,10,-3,AIR:0)
Block(-5,10,-2,AIR:0)
Block(-5,10,-1,quark:framed_glass:0)
Block(-5,11,-7,quark:world_stone_pavement:2)
Block(-5,11,-6,AIR:0)
Block(-5,11,-5,AIR:0)
Block(-5,11,-4,AIR:0)
Block(-5,11,-3,AIR:0)
Block(-5,11,-2,AIR:0)
Block(-5,11,-1,quark:world_stone_pavement:2)
Block(-5,12,-7,quark:world_stone_pavement:2)
Block(-5,12,-6,AIR:0)
Block(-5,12,-5,AIR:0)
Block(-5,12,-4,AIR:0)
Block(-5,12,-3,AIR:0)
Block(-5,12,-2,AIR:0)
Block(-5,12,-1,quark:world_stone_pavement:2)
Block(-5,13,-7,quark:basalt_wall:0)
RandomBlock(-5,13,-6,quark:iron_plate:1,null,70,STAINED_CLAY:15,null,30,STAINED_CLAY:7,null,30,quark:iron_plate:1,null,100)
Block(-5,13,-5,AIR:0)
Block(-5,13,-4,AIR:0)
Block(-5,13,-3,AIR:0)
RandomBlock(-5,13,-2,quark:iron_plate:1,null,70,STAINED_CLAY:15,null,30,STAINED_CLAY:7,null,30,quark:iron_plate:1,null,100)
Block(-5,13,-1,quark:basalt_wall:0)
Block(-5,14,-7,quark:world_stone_pavement:2)
RandomBlock(-5,14,-6,quark:iron_plate:1,null,70,STAINED_CLAY:15,null,30,STAINED_CLAY:7,null,30,quark:iron_plate:1,null,100)
RandomBlock(-5,14,-5,quark:iron_plate:1,null,70,STAINED_CLAY:15,null,30,STAINED_CLAY:7,null,30,quark:iron_plate:1,null,100)
RandomBlock(-5,14,-4,quark:iron_plate:1,null,70,STAINED_CLAY:15,null,30,STAINED_CLAY:7,null,30,quark:iron_plate:1,null,100)
RandomBlock(-5,14,-3,quark:iron_plate:1,null,70,STAINED_CLAY:15,null,30,STAINED_CLAY:7,null,30,quark:iron_plate:1,null,100)
RandomBlock(-5,14,-2,quark:iron_plate:1,null,70,STAINED_CLAY:15,null,30,STAINED_CLAY:7,null,30,quark:iron_plate:1,null,100)
Block(-5,14,-1,quark:world_stone_pavement:2)
Block(-5,15,-6,COBBLESTONE_STAIRS:2)
RandomBlock(-5,15,-5,quark:iron_plate:1,null,70,STAINED_CLAY:15,null,30,STAINED_CLAY:7,null,30,quark:iron_plate:1,null,100)
RandomBlock(-5,15,-4,quark:iron_plate:1,null,70,STAINED_CLAY:15,null,30,STAINED_CLAY:7,null,30,quark:iron_plate:1,null,100)
RandomBlock(-5,15,-3,quark:iron_plate:1,null,70,STAINED_CLAY:15,null,30,STAINED_CLAY:7,null,30,quark:iron_plate:1,null,100)
Block(-5,15,-2,COBBLESTONE_STAIRS:3)
Block(-4,0,-7,quark:limestone:0)
RandomBlock(-4,0,-6,quark:iron_plate:1,null,70,STAINED_CLAY:15,null,30,STAINED_CLAY:7,null,30,quark:iron_plate:1,null,100)
RandomBlock(-4,0,-5,quark:iron_plate:1,null,70,STAINED_CLAY:15,null,30,STAINED_CLAY:7,null,30,quark:iron_plate:1,null,100)
RandomBlock(-4,0,-4,quark:iron_plate:1,null,70,STAINED_CLAY:15,null,30,STAINED_CLAY:7,null,30,quark:iron_plate:1,null,100)
RandomBlock(-4,0,-3,quark:iron_plate:1,null,70,STAINED_CLAY:15,null,30,STAINED_CLAY:7,null,30,quark:iron_plate:1,null,100)
RandomBlock(-4,0,-2,quark:iron_plate:1,null,70,STAINED_CLAY:15,null,30,STAINED_CLAY:7,null,30,quark:iron_plate:1,null,100)
Block(-4,0,-1,quark:limestone:0)
Block(-4,1,-7,quark:world_stone_pavement:2)
RandomBlock(-4,1,-6,quark:iron_plate:1,null,70,STAINED_CLAY:15,null,30,STAINED_CLAY:7,null,30,quark:iron_plate:1,null,100)
Block(-4,1,-5,srparasites:deadblood:1)
Block(-4,1,-4,srparasites:deadblood:1)
Block(-4,1,-3,srparasites:deadblood:1)
RandomBlock(-4,1,-2,quark:iron_plate:1,null,70,STAINED_CLAY:15,null,30,STAINED_CLAY:7,null,30,quark:iron_plate:1,null,100)
Block(-4,1,-1,quark:world_stone_pavement:2)
Block(-4,2,-7,quark:basalt_wall:0)
RandomBlock(-4,2,-6,quark:iron_plate:1,null,70,STAINED_CLAY:15,null,30,STAINED_CLAY:7,null,30,quark:iron_plate:1,null,100)
Block(-4,2,-5,srparasites:deadblood:1)
Block(-4,2,-4,srparasites:deadblood:1)
Block(-4,2,-3,srparasites:deadblood:1)
RandomBlock(-4,2,-2,quark:iron_plate:1,null,70,STAINED_CLAY:15,null,30,STAINED_CLAY:7,null,30,quark:iron_plate:1,null,100)
Block(-4,2,-1,quark:world_stone_pavement:2)
Block(-4,3,-7,quark:basalt_wall:0)
RandomBlock(-4,3,-6,quark:iron_plate:1,null,70,STAINED_CLAY:15,null,30,STAINED_CLAY:7,null,30,quark:iron_plate:1,null,100)
Block(-4,3,-5,srparasites:deadblood:1)
Block(-4,3,-4,srparasites:deadblood:1)
Block(-4,3,-3,srparasites:deadblood:1)
RandomBlock(-4,3,-2,quark:iron_plate:1,null,70,STAINED_CLAY:15,null,30,STAINED_CLAY:7,null,30,quark:iron_plate:1,null,100)
Block(-4,3,-1,quark:world_stone_pavement:2)
Block(-4,4,-7,quark:world_stone_pavement:2)
Block(-4,4,-6,srparasites:deadblood:1)
Block(-4,4,-5,srparasites:deadblood:1)
Block(-4,4,-4,srparasites:deadblood:1)
Block(-4,4,-3,srparasites:deadblood:1)
RandomBlock(-4,4,-2,quark:iron_plate:1,null,70,STAINED_CLAY:15,null,30,STAINED_CLAY:7,null,30,quark:iron_plate:1,null,100)
Block(-4,4,-1,quark:world_stone_pavement:2)
Block(-4,4,0,COBBLESTONE_STAIRS:5)
Block(-4,4,1,COBBLESTONE_STAIRS:5)
Block(-4,4,2,COBBLESTONE_STAIRS:5)
Block(-4,4,3,COBBLESTONE_STAIRS:5)
Block(-4,4,4,COBBLESTONE_STAIRS:5)
Block(-4,4,5,COBBLESTONE_STAIRS:6)
RandomBlock(-4,4,6,quark:iron_plate:1,null,70,STAINED_CLAY:15,null,30,STAINED_CLAY:7,null,30,quark:iron_plate:1,null,100)
RandomBlock(-4,4,7,quark:iron_plate:1,null,70,STAINED_CLAY:15,null,30,STAINED_CLAY:7,null,30,quark:iron_plate:1,null,100)
Block(-4,4,8,COBBLESTONE_STAIRS:7)
Block(-4,5,-7,quark:world_stone_pavement:2)
Block(-4,5,-6,srparasites:deadblood:1)
Block(-4,5,-5,srparasites:deadblood:1)
Block(-4,5,-4,srparasites:deadblood:1)
Block(-4,5,-3,srparasites:deadblood:1)
RandomBlock(-4,5,-2,quark:iron_plate:1,null,70,STAINED_CLAY:15,null,30,STAINED_CLAY:7,null,30,quark:iron_plate:1,null,100)
RandomBlock(-4,5,-1,quark:iron_plate:1,null,70,STAINED_CLAY:15,null,30,STAINED_CLAY:7,null,30,quark:iron_plate:1,null,100)
RandomBlock(-4,5,0,quark:iron_plate:1,null,70,STAINED_CLAY:15,null,30,STAINED_CLAY:7,null,30,quark:iron_plate:1,null,100)
RandomBlock(-4,5,1,quark:iron_plate:1,null,70,STAINED_CLAY:15,null,30,STAINED_CLAY:7,null,30,quark:iron_plate:1,null,100)
RandomBlock(-4,5,2,quark:iron_plate:1,null,70,STAINED_CLAY:15,null,30,STAINED_CLAY:7,null,30,quark:iron_plate:1,null,100)
RandomBlock(-4,5,3,quark:iron_plate:1,null,70,STAINED_CLAY:15,null,30,STAINED_CLAY:7,null,30,quark:iron_plate:1,null,100)
RandomBlock(-4,5,4,quark:iron_plate:1,null,70,STAINED_CLAY:15,null,30,STAINED_CLAY:7,null,30,quark:iron_plate:1,null,100)
RandomBlock(-4,5,5,quark:iron_plate:1,null,70,STAINED_CLAY:15,null,30,STAINED_CLAY:7,null,30,quark:iron_plate:1,null,100)
Block(-4,5,6,AIR:0)
Block(-4,5,7,AIR:0)
RandomBlock(-4,5,8,rustic:iron_lattice:1,null,30,rustic:iron_lattice:1,null,30,biomesoplenty:leaves_2:7,null,30,quark:iron_plate_stairs:6,null,10,quark:iron_plate_stairs:0,null,10,quark:iron_plate_stairs:5,null,10,quark:iron_plate_stairs:3,null,10,quark:iron_plate_slab:8,null,10,quark:iron_plate_stairs:7,null,10,quark:iron_plate_stairs:1,null,10,quark:iron_plate_slab:0,null,10,quark:iron_plate_stairs:4,null,10,quark:iron_plate_stairs:2,null,10,rustic:iron_lattice:1,null,50,rustic:iron_lattice:1,null,50,biomesoplenty:leaves_2:7,null,100)
Block(-4,6,-7,quark:world_stone_pavement:2)
Block(-4,6,-6,srparasites:deadblood:1)
Block(-4,6,-5,srparasites:deadblood:1)
Block(-4,6,-4,srparasites:deadblood:1)
Block(-4,6,-3,srparasites:deadblood:1)
RandomBlock(-4,6,-2,quark:iron_plate:1,null,70,STAINED_CLAY:15,null,30,STAINED_CLAY:7,null,30,quark:iron_plate:1,null,100)
RandomBlock(-4,6,-1,quark:iron_plate:1,null,70,STAINED_CLAY:15,null,30,STAINED_CLAY:7,null,30,quark:iron_plate:1,null,100)
RandomBlock(-4,6,0,quark:iron_plate:1,null,70,STAINED_CLAY:15,null,30,STAINED_CLAY:7,null,30,quark:iron_plate:1,null,100)
RandomBlock(-4,6,1,quark:iron_plate:1,null,70,STAINED_CLAY:15,null,30,STAINED_CLAY:7,null,30,quark:iron_plate:1,null,100)
RandomBlock(-4,6,2,quark:iron_plate:1,null,70,STAINED_CLAY:15,null,30,STAINED_CLAY:7,null,30,quark:iron_plate:1,null,100)
RandomBlock(-4,6,3,quark:iron_plate:1,null,70,STAINED_CLAY:15,null,30,STAINED_CLAY:7,null,30,quark:iron_plate:1,null,100)
RandomBlock(-4,6,4,quark:iron_plate:1,null,70,STAINED_CLAY:15,null,30,STAINED_CLAY:7,null,30,quark:iron_plate:1,null,100)
RandomBlock(-4,6,5,quark:iron_plate:1,null,70,STAINED_CLAY:15,null,30,STAINED_CLAY:7,null,30,quark:iron_plate:1,null,100)
Block(-4,6,6,AIR:0)
Block(-4,6,7,AIR:0)
RandomBlock(-4,6,8,quark:iron_plate:1,null,70,STAINED_CLAY:15,null,30,STAINED_CLAY:7,null,30,quark:iron_plate:1,null,100)
Block(-4,7,-7,quark:world_stone_pavement:2)
Block(-4,7,-6,srparasites:deadblood:1)
Block(-4,7,-5,srparasites:deadblood:1)
Block(-4,7,-4,srparasites:deadblood:1)
Block(-4,7,-3,srparasites:deadblood:1)
RandomBlock(-4,7,-2,quark:iron_plate:1,null,70,STAINED_CLAY:15,null,30,STAINED_CLAY:7,null,30,quark:iron_plate:1,null,100)
Block(-4,7,-1,quark:world_stone_pavement:2)
Block(-4,7,0,COBBLESTONE_STAIRS:1)
RandomBlock(-4,7,1,quark:iron_plate:1,null,70,STAINED_CLAY:15,null,30,STAINED_CLAY:7,null,30,quark:iron_plate:1,null,100)
RandomBlock(-4,7,2,quark:iron_plate:1,null,70,STAINED_CLAY:15,null,30,STAINED_CLAY:7,null,30,quark:iron_plate:1,null,100)
RandomBlock(-4,7,3,quark:iron_plate:1,null,70,STAINED_CLAY:15,null,30,STAINED_CLAY:7,null,30,quark:iron_plate:1,null,100)
Block(-4,7,4,COBBLESTONE_STAIRS:1)
Block(-4,7,5,COBBLESTONE_STAIRS:2)
RandomBlock(-4,7,6,rustic:iron_lattice:1,null,30,rustic:iron_lattice:1,null,30,biomesoplenty:leaves_2:7,null,30,quark:iron_plate_stairs:6,null,10,quark:iron_plate_stairs:0,null,10,quark:iron_plate_stairs:5,null,10,quark:iron_plate_stairs:3,null,10,quark:iron_plate_slab:8,null,10,quark:iron_plate_stairs:7,null,10,quark:iron_plate_stairs:1,null,10,quark:iron_plate_slab:0,null,10,quark:iron_plate_stairs:4,null,10,quark:iron_plate_stairs:2,null,10,rustic:iron_lattice:1,null,50,rustic:iron_lattice:1,null,50,biomesoplenty:leaves_2:7,null,100)
RandomBlock(-4,7,7,quark:iron_plate:1,null,70,STAINED_CLAY:15,null,30,STAINED_CLAY:7,null,30,quark:iron_plate:1,null,100)
Block(-4,7,8,COBBLESTONE_STAIRS:3)
Block(-4,8,-7,quark:world_stone_pavement:2)
Block(-4,8,-6,srparasites:deadblood:1)
Block(-4,8,-5,srparasites:deadblood:1)
Block(-4,8,-4,srparasites:deadblood:1)
Block(-4,8,-3,srparasites:deadblood:1)
Block(-4,8,-2,srparasites:deadblood:1)
Block(-4,8,-1,quark:world_stone_pavement:2)
Block(-4,8,1,quark:iron_plate_slab:0)
Block(-4,8,2,quark:iron_plate_slab:0)
Block(-4,8,3,quark:iron_plate_slab:0)
Block(-4,9,-7,quark:world_stone_pavement:2)
Block(-4,9,-6,srparasites:deadblood:0)
Block(-4,9,-5,srparasites:deadblood:1)
Block(-4,9,-4,srparasites:deadblood:0)
Block(-4,9,-3,srparasites:deadblood:0)
Block(-4,9,-2,srparasites:deadblood:0)
Block(-4,9,-1,quark:world_stone_pavement:2)
Block(-4,9,1,rustic:iron_lattice:0)
Block(-4,9,2,rustic:iron_lattice:0)
Block(-4,9,3,rustic:iron_lattice:0)
Block(-4,10,-7,quark:world_stone_pavement:2)
Block(-4,10,-6,AIR:0)
Block(-4,10,-5,AIR:0)
Block(-4,10,-4,AIR:0)
Block(-4,10,-3,AIR:0)
Block(-4,10,-2,AIR:0)
Block(-4,10,-1,quark:world_stone_pavement:2)
Block(-4,11,-7,quark:world_stone_pavement:2)
Block(-4,11,-6,AIR:0)
Block(-4,11,-5,AIR:0)
Block(-4,11,-4,AIR:0)
Block(-4,11,-3,AIR:0)
Block(-4,11,-2,AIR:0)
Block(-4,11,-1,quark:world_stone_pavement:2)
Block(-4,12,-7,quark:basalt_wall:0)
RandomBlock(-4,12,-6,quark:iron_plate:1,null,70,STAINED_CLAY:15,null,30,STAINED_CLAY:7,null,30,quark:iron_plate:1,null,100)
Block(-4,12,-5,AIR:0)
Block(-4,12,-4,AIR:0)
Block(-4,12,-3,AIR:0)
RandomBlock(-4,12,-2,quark:iron_plate:1,null,70,STAINED_CLAY:15,null,30,STAINED_CLAY:7,null,30,quark:iron_plate:1,null,100)
Block(-4,12,-1,quark:basalt_wall:0)
Block(-4,13,-7,quark:basalt_wall:0)
RandomBlock(-4,13,-6,quark:iron_plate:1,null,70,STAINED_CLAY:15,null,30,STAINED_CLAY:7,null,30,quark:iron_plate:1,null,100)
Block(-4,13,-5,AIR:0)
Block(-4,13,-4,AIR:0)
Block(-4,13,-3,AIR:0)
RandomBlock(-4,13,-2,quark:iron_plate:1,null,70,STAINED_CLAY:15,null,30,STAINED_CLAY:7,null,30,quark:iron_plate:1,null,100)
Block(-4,13,-1,quark:basalt_wall:0)
Block(-4,14,-7,quark:world_stone_pavement:2)
RandomBlock(-4,14,-6,quark:iron_plate:1,null,70,STAINED_CLAY:15,null,30,STAINED_CLAY:7,null,30,quark:iron_plate:1,null,100)
RandomBlock(-4,14,-5,quark:iron_plate:1,null,70,STAINED_CLAY:15,null,30,STAINED_CLAY:7,null,30,quark:iron_plate:1,null,100)
RandomBlock(-4,14,-4,quark:iron_plate:1,null,70,STAINED_CLAY:15,null,30,STAINED_CLAY:7,null,30,quark:iron_plate:1,null,100)
RandomBlock(-4,14,-3,quark:iron_plate:1,null,70,STAINED_CLAY:15,null,30,STAINED_CLAY:7,null,30,quark:iron_plate:1,null,100)
RandomBlock(-4,14,-2,quark:iron_plate:1,null,70,STAINED_CLAY:15,null,30,STAINED_CLAY:7,null,30,quark:iron_plate:1,null,100)
Block(-4,14,-1,quark:world_stone_pavement:2)
Block(-4,15,-6,COBBLESTONE_STAIRS:2)
RandomBlock(-4,15,-5,quark:iron_plate:1,null,70,STAINED_CLAY:15,null,30,STAINED_CLAY:7,null,30,quark:iron_plate:1,null,100)
RandomBlock(-4,15,-4,quark:iron_plate:1,null,70,STAINED_CLAY:15,null,30,STAINED_CLAY:7,null,30,quark:iron_plate:1,null,100)
RandomBlock(-4,15,-3,quark:iron_plate:1,null,70,STAINED_CLAY:15,null,30,STAINED_CLAY:7,null,30,quark:iron_plate:1,null,100)
Block(-4,15,-2,COBBLESTONE_STAIRS:3)
Block(-3,0,-7,quark:limestone:0)
RandomBlock(-3,0,-6,quark:iron_plate:1,null,70,STAINED_CLAY:15,null,30,STAINED_CLAY:7,null,30,quark:iron_plate:1,null,100)
RandomBlock(-3,0,-5,quark:iron_plate:1,null,70,STAINED_CLAY:15,null,30,STAINED_CLAY:7,null,30,quark:iron_plate:1,null,100)
RandomBlock(-3,0,-4,quark:iron_plate:1,null,70,STAINED_CLAY:15,null,30,STAINED_CLAY:7,null,30,quark:iron_plate:1,null,100)
RandomBlock(-3,0,-3,quark:iron_plate:1,null,70,STAINED_CLAY:15,null,30,STAINED_CLAY:7,null,30,quark:iron_plate:1,null,100)
RandomBlock(-3,0,-2,quark:iron_plate:1,null,70,STAINED_CLAY:15,null,30,STAINED_CLAY:7,null,30,quark:iron_plate:1,null,100)
Block(-3,0,-1,quark:limestone:0)
Block(-3,1,-7,quark:world_stone_pavement:2)
RandomBlock(-3,1,-6,quark:iron_plate:1,null,70,STAINED_CLAY:15,null,30,STAINED_CLAY:7,null,30,quark:iron_plate:1,null,100)
RandomBlock(-3,1,-5,quark:iron_plate:1,null,70,STAINED_CLAY:15,null,30,STAINED_CLAY:7,null,30,quark:iron_plate:1,null,100)
RandomBlock(-3,1,-4,quark:iron_plate:1,null,70,STAINED_CLAY:15,null,30,STAINED_CLAY:7,null,30,quark:iron_plate:1,null,100)
RandomBlock(-3,1,-3,quark:iron_plate:1,null,70,STAINED_CLAY:15,null,30,STAINED_CLAY:7,null,30,quark:iron_plate:1,null,100)
RandomBlock(-3,1,-2,quark:iron_plate:1,null,70,STAINED_CLAY:15,null,30,STAINED_CLAY:7,null,30,quark:iron_plate:1,null,100)
Block(-3,1,-1,quark:world_stone_pavement:2)
Block(-3,2,-7,quark:world_stone_pavement:2)
RandomBlock(-3,2,-6,quark:iron_plate:1,null,70,STAINED_CLAY:15,null,30,STAINED_CLAY:7,null,30,quark:iron_plate:1,null,100)
RandomBlock(-3,2,-5,quark:iron_plate:1,null,70,STAINED_CLAY:15,null,30,STAINED_CLAY:7,null,30,quark:iron_plate:1,null,100)
RandomBlock(-3,2,-4,quark:iron_plate:1,null,70,STAINED_CLAY:15,null,30,STAINED_CLAY:7,null,30,quark:iron_plate:1,null,100)
RandomBlock(-3,2,-3,quark:iron_plate:1,null,70,STAINED_CLAY:15,null,30,STAINED_CLAY:7,null,30,quark:iron_plate:1,null,100)
RandomBlock(-3,2,-2,quark:iron_plate:1,null,70,STAINED_CLAY:15,null,30,STAINED_CLAY:7,null,30,quark:iron_plate:1,null,100)
Block(-3,2,-1,quark:world_stone_pavement:2)
Block(-3,3,-7,quark:basalt_wall:0)
RandomBlock(-3,3,-6,quark:iron_plate:1,null,70,STAINED_CLAY:15,null,30,STAINED_CLAY:7,null,30,quark:iron_plate:1,null,100)
RandomBlock(-3,3,-5,quark:iron_plate:1,null,70,STAINED_CLAY:15,null,30,STAINED_CLAY:7,null,30,quark:iron_plate:1,null,100)
Block(-3,3,-4,srparasites:deadblood:1)
RandomBlock(-3,3,-3,quark:iron_plate:1,null,70,STAINED_CLAY:15,null,30,STAINED_CLAY:7,null,30,quark:iron_plate:1,null,100)
RandomBlock(-3,3,-2,quark:iron_plate:1,null,70,STAINED_CLAY:15,null,30,STAINED_CLAY:7,null,30,quark:iron_plate:1,null,100)
Block(-3,3,-1,quark:basalt_wall:0)
Block(-3,4,-7,quark:basalt_wall:0)
RandomBlock(-3,4,-6,quark:iron_plate:1,null,70,STAINED_CLAY:15,null,30,STAINED_CLAY:7,null,30,quark:iron_plate:1,null,100)
Block(-3,4,-5,srparasites:deadblood:1)
Block(-3,4,-4,srparasites:deadblood:1)
Block(-3,4,-3,srparasites:deadblood:1)
RandomBlock(-3,4,-2,quark:iron_plate:1,null,70,STAINED_CLAY:15,null,30,STAINED_CLAY:7,null,30,quark:iron_plate:1,null,100)
Block(-3,4,-1,quark:basalt_wall:0)
Block(-3,4,5,COBBLESTONE_STAIRS:6)
RandomBlock(-3,4,6,quark:iron_plate:1,null,70,STAINED_CLAY:15,null,30,STAINED_CLAY:7,null,30,quark:iron_plate:1,null,100)
RandomBlock(-3,4,7,quark:iron_plate:1,null,70,STAINED_CLAY:15,null,30,STAINED_CLAY:7,null,30,quark:iron_plate:1,null,100)
Block(-3,4,8,COBBLESTONE_STAIRS:7)
Block(-3,5,-7,quark:basalt_wall:0)
RandomBlock(-3,5,-6,quark:iron_plate:1,null,70,STAINED_CLAY:15,null,30,STAINED_CLAY:7,null,30,quark:iron_plate:1,null,100)
Block(-3,5,-5,srparasites:deadblood:1)
Block(-3,5,-4,srparasites:deadblood:1)
Block(-3,5,-3,srparasites:deadblood:1)
RandomBlock(-3,5,-2,quark:iron_plate:1,null,70,STAINED_CLAY:15,null,30,STAINED_CLAY:7,null,30,quark:iron_plate:1,null,100)
Block(-3,5,-1,quark:basalt_wall:0)
RandomBlock(-3,5,5,quark:iron_plate:1,null,70,STAINED_CLAY:15,null,30,STAINED_CLAY:7,null,30,quark:iron_plate:1,null,100)
Block(-3,5,6,AIR:0)
Block(-3,5,7,AIR:0)
RandomBlock(-3,5,8,rustic:iron_lattice:1,null,30,rustic:iron_lattice:1,null,30,biomesoplenty:leaves_2:7,null,30,quark:iron_plate_stairs:6,null,10,quark:iron_plate_stairs:0,null,10,quark:iron_plate_stairs:5,null,10,quark:iron_plate_stairs:3,null,10,quark:iron_plate_slab:8,null,10,quark:iron_plate_stairs:7,null,10,quark:iron_plate_stairs:1,null,10,quark:iron_plate_slab:0,null,10,quark:iron_plate_stairs:4,null,10,quark:iron_plate_stairs:2,null,10,rustic:iron_lattice:1,null,50,rustic:iron_lattice:1,null,50,biomesoplenty:leaves_2:7,null,100)
Block(-3,6,-7,quark:basalt_wall:0)
RandomBlock(-3,6,-6,quark:iron_plate:1,null,70,STAINED_CLAY:15,null,30,STAINED_CLAY:7,null,30,quark:iron_plate:1,null,100)
Block(-3,6,-5,srparasites:deadblood:1)
Block(-3,6,-4,srparasites:deadblood:1)
Block(-3,6,-3,srparasites:deadblood:1)
RandomBlock(-3,6,-2,quark:iron_plate:1,null,70,STAINED_CLAY:15,null,30,STAINED_CLAY:7,null,30,quark:iron_plate:1,null,100)
Block(-3,6,-1,quark:basalt_wall:0)
RandomBlock(-3,6,5,quark:iron_plate:1,null,70,STAINED_CLAY:15,null,30,STAINED_CLAY:7,null,30,quark:iron_plate:1,null,100)
Block(-3,6,6,AIR:0)
Block(-3,6,7,AIR:0)
RandomBlock(-3,6,8,rustic:iron_lattice:1,null,30,rustic:iron_lattice:1,null,30,biomesoplenty:leaves_2:7,null,30,quark:iron_plate_stairs:6,null,10,quark:iron_plate_stairs:0,null,10,quark:iron_plate_stairs:5,null,10,quark:iron_plate_stairs:3,null,10,quark:iron_plate_slab:8,null,10,quark:iron_plate_stairs:7,null,10,quark:iron_plate_stairs:1,null,10,quark:iron_plate_slab:0,null,10,quark:iron_plate_stairs:4,null,10,quark:iron_plate_stairs:2,null,10,rustic:iron_lattice:1,null,50,rustic:iron_lattice:1,null,50,biomesoplenty:leaves_2:7,null,100)
Block(-3,7,-7,quark:basalt_wall:0)
RandomBlock(-3,7,-6,quark:iron_plate:1,null,70,STAINED_CLAY:15,null,30,STAINED_CLAY:7,null,30,quark:iron_plate:1,null,100)
Block(-3,7,-5,srparasites:deadblood:1)
Block(-3,7,-4,srparasites:deadblood:1)
Block(-3,7,-3,srparasites:deadblood:1)
RandomBlock(-3,7,-2,quark:iron_plate:1,null,70,STAINED_CLAY:15,null,30,STAINED_CLAY:7,null,30,quark:iron_plate:1,null,100)
Block(-3,7,-1,quark:basalt_wall:0)
Block(-3,7,5,COBBLESTONE_STAIRS:2)
RandomBlock(-3,7,6,quark:iron_plate:1,null,70,STAINED_CLAY:15,null,30,STAINED_CLAY:7,null,30,quark:iron_plate:1,null,100)
RandomBlock(-3,7,7,quark:iron_plate:1,null,70,STAINED_CLAY:15,null,30,STAINED_CLAY:7,null,30,quark:iron_plate:1,null,100)
Block(-3,7,8,COBBLESTONE_STAIRS:3)
Block(-3,8,-7,quark:basalt_wall:0)
RandomBlock(-3,8,-6,quark:iron_plate:1,null,70,STAINED_CLAY:15,null,30,STAINED_CLAY:7,null,30,quark:iron_plate:1,null,100)
Block(-3,8,-5,srparasites:deadblood:1)
Block(-3,8,-4,srparasites:deadblood:1)
Block(-3,8,-3,srparasites:deadblood:1)
RandomBlock(-3,8,-2,quark:iron_plate:1,null,70,STAINED_CLAY:15,null,30,STAINED_CLAY:7,null,30,quark:iron_plate:1,null,100)
Block(-3,8,-1,quark:basalt_wall:0)
Block(-3,9,-7,quark:basalt_wall:0)
RandomBlock(-3,9,-6,quark:iron_plate:1,null,70,STAINED_CLAY:15,null,30,STAINED_CLAY:7,null,30,quark:iron_plate:1,null,100)
Block(-3,9,-5,srparasites:deadblood:0)
Block(-3,9,-4,srparasites:deadblood:0)
Block(-3,9,-3,srparasites:deadblood:0)
RandomBlock(-3,9,-2,quark:iron_plate:1,null,70,STAINED_CLAY:15,null,30,STAINED_CLAY:7,null,30,quark:iron_plate:1,null,100)
Block(-3,9,-1,quark:basalt_wall:0)
Block(-3,10,-7,quark:basalt_wall:0)
RandomBlock(-3,10,-6,quark:iron_plate:1,null,70,STAINED_CLAY:15,null,30,STAINED_CLAY:7,null,30,quark:iron_plate:1,null,100)
Block(-3,10,-5,AIR:0)
Block(-3,10,-4,AIR:0)
Block(-3,10,-3,AIR:0)
RandomBlock(-3,10,-2,quark:iron_plate:1,null,70,STAINED_CLAY:15,null,30,STAINED_CLAY:7,null,30,quark:iron_plate:1,null,100)
Block(-3,10,-1,quark:basalt_wall:0)
Block(-3,11,-7,quark:basalt_wall:0)
RandomBlock(-3,11,-6,quark:iron_plate:1,null,70,STAINED_CLAY:15,null,30,STAINED_CLAY:7,null,30,quark:iron_plate:1,null,100)
Block(-3,11,-5,AIR:0)
Block(-3,11,-4,AIR:0)
Block(-3,11,-3,AIR:0)
RandomBlock(-3,11,-2,quark:iron_plate:1,null,70,STAINED_CLAY:15,null,30,STAINED_CLAY:7,null,30,quark:iron_plate:1,null,100)
Block(-3,11,-1,quark:basalt_wall:0)
Block(-3,12,-7,quark:basalt_wall:0)
RandomBlock(-3,12,-6,quark:iron_plate:1,null,70,STAINED_CLAY:15,null,30,STAINED_CLAY:7,null,30,quark:iron_plate:1,null,100)
RandomBlock(-3,12,-5,quark:iron_plate:1,null,70,STAINED_CLAY:15,null,30,STAINED_CLAY:7,null,30,quark:iron_plate:1,null,100)
Block(-3,12,-4,AIR:0)
RandomBlock(-3,12,-3,quark:iron_plate:1,null,70,STAINED_CLAY:15,null,30,STAINED_CLAY:7,null,30,quark:iron_plate:1,null,100)
RandomBlock(-3,12,-2,quark:iron_plate:1,null,70,STAINED_CLAY:15,null,30,STAINED_CLAY:7,null,30,quark:iron_plate:1,null,100)
Block(-3,12,-1,quark:basalt_wall:0)
Block(-3,13,-7,quark:world_stone_pavement:2)
RandomBlock(-3,13,-6,quark:iron_plate:1,null,70,STAINED_CLAY:15,null,30,STAINED_CLAY:7,null,30,quark:iron_plate:1,null,100)
RandomBlock(-3,13,-5,quark:iron_plate:1,null,70,STAINED_CLAY:15,null,30,STAINED_CLAY:7,null,30,quark:iron_plate:1,null,100)
RandomBlock(-3,13,-4,quark:iron_plate:1,null,70,STAINED_CLAY:15,null,30,STAINED_CLAY:7,null,30,quark:iron_plate:1,null,100)
RandomBlock(-3,13,-3,quark:iron_plate:1,null,70,STAINED_CLAY:15,null,30,STAINED_CLAY:7,null,30,quark:iron_plate:1,null,100)
RandomBlock(-3,13,-2,quark:iron_plate:1,null,70,STAINED_CLAY:15,null,30,STAINED_CLAY:7,null,30,quark:iron_plate:1,null,100)
Block(-3,13,-1,quark:world_stone_pavement:2)
Block(-3,14,-7,quark:world_stone_pavement:2)
RandomBlock(-3,14,-6,quark:iron_plate:1,null,70,STAINED_CLAY:15,null,30,STAINED_CLAY:7,null,30,quark:iron_plate:1,null,100)
RandomBlock(-3,14,-5,quark:iron_plate:1,null,70,STAINED_CLAY:15,null,30,STAINED_CLAY:7,null,30,quark:iron_plate:1,null,100)
RandomBlock(-3,14,-4,quark:iron_plate:1,null,70,STAINED_CLAY:15,null,30,STAINED_CLAY:7,null,30,quark:iron_plate:1,null,100)
RandomBlock(-3,14,-3,quark:iron_plate:1,null,70,STAINED_CLAY:15,null,30,STAINED_CLAY:7,null,30,quark:iron_plate:1,null,100)
RandomBlock(-3,14,-2,quark:iron_plate:1,null,70,STAINED_CLAY:15,null,30,STAINED_CLAY:7,null,30,quark:iron_plate:1,null,100)
Block(-3,14,-1,quark:world_stone_pavement:2)
Block(-3,15,-6,COBBLESTONE_STAIRS:1)
Block(-3,15,-5,COBBLESTONE_STAIRS:1)
Block(-3,15,-4,COBBLESTONE_STAIRS:1)
Block(-3,15,-3,COBBLESTONE_STAIRS:1)
Block(-3,15,-2,COBBLESTONE_STAIRS:3)
Block(-2,0,-6,quark:limestone:0)
Block(-2,0,-5,quark:limestone:0)
Block(-2,0,-4,quark:limestone:0)
Block(-2,0,-3,quark:limestone:0)
Block(-2,0,-2,quark:limestone:0)
Block(-2,1,-6,quark:world_stone_pavement:2)
Block(-2,1,-5,quark:world_stone_pavement:2)
Block(-2,1,-4,quark:world_stone_pavement:2)
Block(-2,1,-3,quark:world_stone_pavement:2)
Block(-2,1,-2,quark:world_stone_pavement:2)
Block(-2,2,-6,quark:world_stone_pavement:2)
Block(-2,2,-5,quark:basalt_wall:0)
Block(-2,2,-4,quark:basalt_wall:0)
Block(-2,2,-3,quark:basalt_wall:0)
Block(-2,2,-2,quark:world_stone_pavement:2)
Block(-2,3,-6,quark:basalt_wall:0)
Block(-2,3,-5,quark:basalt_wall:0)
Block(-2,3,-4,quark:world_stone_pavement:2)
Block(-2,3,-3,quark:basalt_wall:0)
Block(-2,3,-2,quark:basalt_wall:0)
Block(-2,4,-6,quark:basalt_wall:0)
Block(-2,4,-5,quark:world_stone_pavement:2)
Block(-2,4,-4,quark:world_stone_pavement:2)
Block(-2,4,-3,quark:world_stone_pavement:2)
Block(-2,4,-2,quark:basalt_wall:0)
Block(-2,4,5,COBBLESTONE_STAIRS:6)
RandomBlock(-2,4,6,quark:iron_plate:1,null,70,STAINED_CLAY:15,null,30,STAINED_CLAY:7,null,30,quark:iron_plate:1,null,100)
RandomBlock(-2,4,7,quark:iron_plate:1,null,70,STAINED_CLAY:15,null,30,STAINED_CLAY:7,null,30,quark:iron_plate:1,null,100)
Block(-2,4,8,COBBLESTONE_STAIRS:7)
Block(-2,5,-6,quark:basalt_wall:0)
Block(-2,5,-5,quark:world_stone_pavement:2)
Block(-2,5,-4,quark:framed_glass:0)
Block(-2,5,-3,quark:world_stone_pavement:2)
Block(-2,5,-2,quark:basalt_wall:0)
RandomBlock(-2,5,5,quark:iron_plate:1,null,70,STAINED_CLAY:15,null,30,STAINED_CLAY:7,null,30,quark:iron_plate:1,null,100)
Block(-2,5,6,AIR:0)
Block(-2,5,7,AIR:0)
RandomBlock(-2,5,8,rustic:iron_lattice:1,null,30,rustic:iron_lattice:1,null,30,biomesoplenty:leaves_2:7,null,30,quark:iron_plate_stairs:6,null,10,quark:iron_plate_stairs:0,null,10,quark:iron_plate_stairs:5,null,10,quark:iron_plate_stairs:3,null,10,quark:iron_plate_slab:8,null,10,quark:iron_plate_stairs:7,null,10,quark:iron_plate_stairs:1,null,10,quark:iron_plate_slab:0,null,10,quark:iron_plate_stairs:4,null,10,quark:iron_plate_stairs:2,null,10,rustic:iron_lattice:1,null,50,rustic:iron_lattice:1,null,50,biomesoplenty:leaves_2:7,null,100)
Block(-2,6,-6,quark:basalt_wall:0)
Block(-2,6,-5,quark:world_stone_pavement:2)
Block(-2,6,-4,quark:framed_glass:0)
Block(-2,6,-3,quark:world_stone_pavement:2)
Block(-2,6,-2,quark:basalt_wall:0)
RandomBlock(-2,6,5,quark:iron_plate:1,null,70,STAINED_CLAY:15,null,30,STAINED_CLAY:7,null,30,quark:iron_plate:1,null,100)
Block(-2,6,6,AIR:0)
Block(-2,6,7,AIR:0)
RandomBlock(-2,6,8,quark:iron_plate:1,null,70,STAINED_CLAY:15,null,30,STAINED_CLAY:7,null,30,quark:iron_plate:1,null,100)
Block(-2,7,-6,quark:basalt_wall:0)
Block(-2,7,-5,quark:world_stone_pavement:2)
Block(-2,7,-4,quark:framed_glass:0)
Block(-2,7,-3,quark:world_stone_pavement:2)
Block(-2,7,-2,quark:basalt_wall:0)
Block(-2,7,5,COBBLESTONE_STAIRS:2)
RandomBlock(-2,7,6,quark:iron_plate:1,null,70,STAINED_CLAY:15,null,30,STAINED_CLAY:7,null,30,quark:iron_plate:1,null,100)
RandomBlock(-2,7,7,quark:iron_plate:1,null,70,STAINED_CLAY:15,null,30,STAINED_CLAY:7,null,30,quark:iron_plate:1,null,100)
Block(-2,7,8,COBBLESTONE_STAIRS:3)
Block(-2,8,-6,quark:basalt_wall:0)
Block(-2,8,-5,quark:world_stone_pavement:2)
Block(-2,8,-4,quark:framed_glass:0)
Block(-2,8,-3,quark:world_stone_pavement:2)
Block(-2,8,-2,quark:basalt_wall:0)
Block(-2,9,-6,quark:basalt_wall:0)
Block(-2,9,-5,quark:world_stone_pavement:2)
Block(-2,9,-4,quark:framed_glass:0)
Block(-2,9,-3,quark:world_stone_pavement:2)
Block(-2,9,-2,quark:basalt_wall:0)
Block(-2,10,-6,quark:basalt_wall:0)
Block(-2,10,-5,quark:world_stone_pavement:2)
Block(-2,10,-4,quark:framed_glass:0)
Block(-2,10,-3,quark:world_stone_pavement:2)
Block(-2,10,-2,quark:basalt_wall:0)
Block(-2,11,-6,quark:basalt_wall:0)
Block(-2,11,-5,quark:world_stone_pavement:2)
Block(-2,11,-4,quark:world_stone_pavement:2)
Block(-2,11,-3,quark:world_stone_pavement:2)
Block(-2,11,-2,quark:basalt_wall:0)
Block(-2,12,-6,quark:basalt_wall:0)
Block(-2,12,-5,quark:basalt_wall:0)
Block(-2,12,-4,quark:world_stone_pavement:2)
Block(-2,12,-3,quark:basalt_wall:0)
Block(-2,12,-2,quark:basalt_wall:0)
Block(-2,13,-6,quark:world_stone_pavement:2)
Block(-2,13,-5,quark:basalt_wall:0)
Block(-2,13,-4,quark:basalt_wall:0)
Block(-2,13,-3,quark:basalt_wall:0)
Block(-2,13,-2,quark:world_stone_pavement:2)
Block(-2,14,-6,quark:world_stone_pavement:2)
Block(-2,14,-5,quark:world_stone_pavement:2)
Block(-2,14,-4,quark:world_stone_pavement:2)
Block(-2,14,-3,quark:world_stone_pavement:2)
Block(-2,14,-2,quark:world_stone_pavement:2)
Block(-1,0,6,quark:limestone:0)
Block(-1,0,7,quark:limestone:0)
Block(-1,1,6,quark:basalt_wall:0)
Block(-1,1,7,quark:basalt_wall:0)
Block(-1,2,6,quark:basalt_wall:0)
Block(-1,2,7,quark:basalt_wall:0)
Block(-1,3,6,quark:basalt_wall:0)
Block(-1,3,7,quark:basalt_wall:0)
Block(-1,4,5,COBBLESTONE_STAIRS:6)
RandomBlock(-1,4,6,quark:iron_plate:1,null,70,STAINED_CLAY:15,null,30,STAINED_CLAY:7,null,30,quark:iron_plate:1,null,100)
RandomBlock(-1,4,7,quark:iron_plate:1,null,70,STAINED_CLAY:15,null,30,STAINED_CLAY:7,null,30,quark:iron_plate:1,null,100)
Block(-1,4,8,COBBLESTONE_STAIRS:7)
RandomBlock(-1,5,5,quark:iron_plate:1,null,70,STAINED_CLAY:15,null,30,STAINED_CLAY:7,null,30,quark:iron_plate:1,null,100)
Block(-1,5,6,AIR:0)
Block(-1,5,7,AIR:0)
RandomBlock(-1,5,8,rustic:iron_lattice:1,null,30,rustic:iron_lattice:1,null,30,biomesoplenty:leaves_2:7,null,30,quark:iron_plate_stairs:6,null,10,quark:iron_plate_stairs:0,null,10,quark:iron_plate_stairs:5,null,10,quark:iron_plate_stairs:3,null,10,quark:iron_plate_slab:8,null,10,quark:iron_plate_stairs:7,null,10,quark:iron_plate_stairs:1,null,10,quark:iron_plate_slab:0,null,10,quark:iron_plate_stairs:4,null,10,quark:iron_plate_stairs:2,null,10,rustic:iron_lattice:1,null,50,rustic:iron_lattice:1,null,50,biomesoplenty:leaves_2:7,null,100)
RandomBlock(-1,6,5,quark:iron_plate:1,null,70,STAINED_CLAY:15,null,30,STAINED_CLAY:7,null,30,quark:iron_plate:1,null,100)
Block(-1,6,6,AIR:0)
Block(-1,6,7,AIR:0)
RandomBlock(-1,6,8,rustic:iron_lattice:1,null,30,rustic:iron_lattice:1,null,30,biomesoplenty:leaves_2:7,null,30,quark:iron_plate_stairs:6,null,10,quark:iron_plate_stairs:0,null,10,quark:iron_plate_stairs:5,null,10,quark:iron_plate_stairs:3,null,10,quark:iron_plate_slab:8,null,10,quark:iron_plate_stairs:7,null,10,quark:iron_plate_stairs:1,null,10,quark:iron_plate_slab:0,null,10,quark:iron_plate_stairs:4,null,10,quark:iron_plate_stairs:2,null,10,rustic:iron_lattice:1,null,50,rustic:iron_lattice:1,null,50,biomesoplenty:leaves_2:7,null,100)
Block(-1,7,5,COBBLESTONE_STAIRS:2)
RandomBlock(-1,7,6,quark:iron_plate:1,null,70,STAINED_CLAY:15,null,30,STAINED_CLAY:7,null,30,quark:iron_plate:1,null,100)
RandomBlock(-1,7,7,quark:iron_plate:1,null,70,STAINED_CLAY:15,null,30,STAINED_CLAY:7,null,30,quark:iron_plate:1,null,100)
Block(-1,7,8,COBBLESTONE_STAIRS:3)
Block(0,4,5,COBBLESTONE_STAIRS:6)
RandomBlock(0,4,6,quark:iron_plate:1,null,70,STAINED_CLAY:15,null,30,STAINED_CLAY:7,null,30,quark:iron_plate:1,null,100)
RandomBlock(0,4,7,quark:iron_plate:1,null,70,STAINED_CLAY:15,null,30,STAINED_CLAY:7,null,30,quark:iron_plate:1,null,100)
Block(0,4,8,COBBLESTONE_STAIRS:7)
RandomBlock(0,5,5,quark:iron_plate:1,null,70,STAINED_CLAY:15,null,30,STAINED_CLAY:7,null,30,quark:iron_plate:1,null,100)
Block(0,5,6,AIR:0)
Block(0,5,7,AIR:0)
RandomBlock(0,5,8,rustic:iron_lattice:1,null,30,rustic:iron_lattice:1,null,30,biomesoplenty:leaves_2:7,null,30,quark:iron_plate_stairs:6,null,10,quark:iron_plate_stairs:0,null,10,quark:iron_plate_stairs:5,null,10,quark:iron_plate_stairs:3,null,10,quark:iron_plate_slab:8,null,10,quark:iron_plate_stairs:7,null,10,quark:iron_plate_stairs:1,null,10,quark:iron_plate_slab:0,null,10,quark:iron_plate_stairs:4,null,10,quark:iron_plate_stairs:2,null,10,rustic:iron_lattice:1,null,50,rustic:iron_lattice:1,null,50,biomesoplenty:leaves_2:7,null,100)
RandomBlock(0,6,5,quark:iron_plate:1,null,70,STAINED_CLAY:15,null,30,STAINED_CLAY:7,null,30,quark:iron_plate:1,null,100)
Block(0,6,6,AIR:0)
Block(0,6,7,AIR:0)
RandomBlock(0,6,8,rustic:iron_lattice:1,null,30,rustic:iron_lattice:1,null,30,biomesoplenty:leaves_2:7,null,30,quark:iron_plate_stairs:6,null,10,quark:iron_plate_stairs:0,null,10,quark:iron_plate_stairs:5,null,10,quark:iron_plate_stairs:3,null,10,quark:iron_plate_slab:8,null,10,quark:iron_plate_stairs:7,null,10,quark:iron_plate_stairs:1,null,10,quark:iron_plate_slab:0,null,10,quark:iron_plate_stairs:4,null,10,quark:iron_plate_stairs:2,null,10,rustic:iron_lattice:1,null,50,rustic:iron_lattice:1,null,50,biomesoplenty:leaves_2:7,null,100)
Block(0,7,5,COBBLESTONE_STAIRS:2)
RandomBlock(0,7,6,quark:iron_plate:1,null,70,STAINED_CLAY:15,null,30,STAINED_CLAY:7,null,30,quark:iron_plate:1,null,100)
RandomBlock(0,7,7,quark:iron_plate:1,null,70,STAINED_CLAY:15,null,30,STAINED_CLAY:7,null,30,quark:iron_plate:1,null,100)
Block(0,7,8,COBBLESTONE_STAIRS:3)
Block(1,0,-6,quark:limestone:0)
Block(1,0,-5,quark:limestone:0)
Block(1,0,-4,quark:limestone:0)
Block(1,0,-3,quark:limestone:0)
Block(1,0,-2,quark:limestone:0)
Block(1,1,-6,quark:world_stone_pavement:2)
Block(1,1,-5,quark:world_stone_pavement:2)
Block(1,1,-4,quark:world_stone_pavement:2)
Block(1,1,-3,quark:world_stone_pavement:2)
Block(1,1,-2,quark:world_stone_pavement:2)
Block(1,2,-6,quark:world_stone_pavement:2)
Block(1,2,-5,quark:basalt_wall:0)
Block(1,2,-4,quark:basalt_wall:0)
Block(1,2,-3,quark:basalt_wall:0)
Block(1,2,-2,quark:world_stone_pavement:2)
Block(1,3,-6,quark:basalt_wall:0)
Block(1,3,-5,quark:basalt_wall:0)
Block(1,3,-4,quark:world_stone_pavement:2)
Block(1,3,-3,quark:basalt_wall:0)
Block(1,3,-2,quark:basalt_wall:0)
Block(1,4,-6,quark:basalt_wall:0)
Block(1,4,-5,quark:world_stone_pavement:2)
Block(1,4,-4,quark:world_stone_pavement:2)
Block(1,4,-3,quark:world_stone_pavement:2)
Block(1,4,-2,quark:basalt_wall:0)
Block(1,4,5,COBBLESTONE_STAIRS:6)
RandomBlock(1,4,6,quark:iron_plate:1,null,70,STAINED_CLAY:15,null,30,STAINED_CLAY:7,null,30,quark:iron_plate:1,null,100)
RandomBlock(1,4,7,quark:iron_plate:1,null,70,STAINED_CLAY:15,null,30,STAINED_CLAY:7,null,30,quark:iron_plate:1,null,100)
Block(1,4,8,COBBLESTONE_STAIRS:7)
Block(1,5,-6,quark:basalt_wall:0)
Block(1,5,-5,quark:world_stone_pavement:2)
Block(1,5,-4,quark:framed_glass:0)
Block(1,5,-3,quark:world_stone_pavement:2)
Block(1,5,-2,quark:basalt_wall:0)
RandomBlock(1,5,5,quark:iron_plate:1,null,70,STAINED_CLAY:15,null,30,STAINED_CLAY:7,null,30,quark:iron_plate:1,null,100)
Block(1,5,6,AIR:0)
Block(1,5,7,AIR:0)
RandomBlock(1,5,8,rustic:iron_lattice:1,null,30,rustic:iron_lattice:1,null,30,biomesoplenty:leaves_2:7,null,30,quark:iron_plate_stairs:6,null,10,quark:iron_plate_stairs:0,null,10,quark:iron_plate_stairs:5,null,10,quark:iron_plate_stairs:3,null,10,quark:iron_plate_slab:8,null,10,quark:iron_plate_stairs:7,null,10,quark:iron_plate_stairs:1,null,10,quark:iron_plate_slab:0,null,10,quark:iron_plate_stairs:4,null,10,quark:iron_plate_stairs:2,null,10,rustic:iron_lattice:1,null,50,rustic:iron_lattice:1,null,50,biomesoplenty:leaves_2:7,null,100)
Block(1,6,-6,quark:basalt_wall:0)
Block(1,6,-5,quark:world_stone_pavement:2)
Block(1,6,-4,quark:framed_glass:0)
Block(1,6,-3,quark:world_stone_pavement:2)
Block(1,6,-2,quark:basalt_wall:0)
RandomBlock(1,6,5,quark:iron_plate:1,null,70,STAINED_CLAY:15,null,30,STAINED_CLAY:7,null,30,quark:iron_plate:1,null,100)
Block(1,6,6,AIR:0)
Block(1,6,7,AIR:0)
RandomBlock(1,6,8,rustic:iron_lattice:1,null,30,rustic:iron_lattice:1,null,30,biomesoplenty:leaves_2:7,null,30,quark:iron_plate_stairs:6,null,10,quark:iron_plate_stairs:0,null,10,quark:iron_plate_stairs:5,null,10,quark:iron_plate_stairs:3,null,10,quark:iron_plate_slab:8,null,10,quark:iron_plate_stairs:7,null,10,quark:iron_plate_stairs:1,null,10,quark:iron_plate_slab:0,null,10,quark:iron_plate_stairs:4,null,10,quark:iron_plate_stairs:2,null,10,rustic:iron_lattice:1,null,50,rustic:iron_lattice:1,null,50,biomesoplenty:leaves_2:7,null,100)
Block(1,7,-6,quark:basalt_wall:0)
Block(1,7,-5,quark:world_stone_pavement:2)
Block(1,7,-4,quark:framed_glass:0)
Block(1,7,-3,quark:world_stone_pavement:2)
Block(1,7,-2,quark:basalt_wall:0)
Block(1,7,5,COBBLESTONE_STAIRS:2)
RandomBlock(1,7,6,quark:iron_plate:1,null,70,STAINED_CLAY:15,null,30,STAINED_CLAY:7,null,30,quark:iron_plate:1,null,100)
RandomBlock(1,7,7,quark:iron_plate:1,null,70,STAINED_CLAY:15,null,30,STAINED_CLAY:7,null,30,quark:iron_plate:1,null,100)
Block(1,7,8,COBBLESTONE_STAIRS:3)
Block(1,8,-6,quark:basalt_wall:0)
Block(1,8,-5,quark:world_stone_pavement:2)
Block(1,8,-4,quark:framed_glass:0)
Block(1,8,-3,quark:world_stone_pavement:2)
Block(1,8,-2,quark:basalt_wall:0)
Block(1,9,-6,quark:basalt_wall:0)
Block(1,9,-5,quark:world_stone_pavement:2)
Block(1,9,-4,quark:framed_glass:0)
Block(1,9,-3,quark:world_stone_pavement:2)
Block(1,9,-2,quark:basalt_wall:0)
Block(1,10,-6,quark:basalt_wall:0)
Block(1,10,-5,quark:world_stone_pavement:2)
Block(1,10,-4,quark:framed_glass:0)
Block(1,10,-3,quark:world_stone_pavement:2)
Block(1,10,-2,quark:basalt_wall:0)
Block(1,11,-6,quark:basalt_wall:0)
Block(1,11,-5,quark:world_stone_pavement:2)
Block(1,11,-4,quark:world_stone_pavement:2)
Block(1,11,-3,quark:world_stone_pavement:2)
Block(1,11,-2,quark:basalt_wall:0)
Block(1,12,-6,quark:basalt_wall:0)
Block(1,12,-5,quark:basalt_wall:0)
Block(1,12,-4,quark:world_stone_pavement:2)
Block(1,12,-3,quark:basalt_wall:0)
Block(1,12,-2,quark:basalt_wall:0)
Block(1,13,-6,quark:world_stone_pavement:2)
Block(1,13,-5,quark:basalt_wall:0)
Block(1,13,-4,quark:basalt_wall:0)
Block(1,13,-3,quark:basalt_wall:0)
Block(1,13,-2,quark:world_stone_pavement:2)
Block(1,14,-6,quark:world_stone_pavement:2)
Block(1,14,-5,quark:world_stone_pavement:2)
Block(1,14,-4,quark:world_stone_pavement:2)
Block(1,14,-3,quark:world_stone_pavement:2)
Block(1,14,-2,quark:world_stone_pavement:2)
Block(2,0,-7,quark:limestone:0)
RandomBlock(2,0,-6,quark:iron_plate:1,null,70,STAINED_CLAY:15,null,30,STAINED_CLAY:7,null,30,quark:iron_plate:1,null,100)
RandomBlock(2,0,-5,quark:iron_plate:1,null,70,STAINED_CLAY:15,null,30,STAINED_CLAY:7,null,30,quark:iron_plate:1,null,100)
RandomBlock(2,0,-4,quark:iron_plate:1,null,70,STAINED_CLAY:15,null,30,STAINED_CLAY:7,null,30,quark:iron_plate:1,null,100)
RandomBlock(2,0,-3,quark:iron_plate:1,null,70,STAINED_CLAY:15,null,30,STAINED_CLAY:7,null,30,quark:iron_plate:1,null,100)
RandomBlock(2,0,-2,quark:iron_plate:1,null,70,STAINED_CLAY:15,null,30,STAINED_CLAY:7,null,30,quark:iron_plate:1,null,100)
Block(2,0,-1,quark:limestone:0)
Block(2,1,-7,quark:world_stone_pavement:2)
RandomBlock(2,1,-6,quark:iron_plate:1,null,70,STAINED_CLAY:15,null,30,STAINED_CLAY:7,null,30,quark:iron_plate:1,null,100)
RandomBlock(2,1,-5,quark:iron_plate:1,null,70,STAINED_CLAY:15,null,30,STAINED_CLAY:7,null,30,quark:iron_plate:1,null,100)
RandomBlock(2,1,-4,quark:iron_plate:1,null,70,STAINED_CLAY:15,null,30,STAINED_CLAY:7,null,30,quark:iron_plate:1,null,100)
RandomBlock(2,1,-3,quark:iron_plate:1,null,70,STAINED_CLAY:15,null,30,STAINED_CLAY:7,null,30,quark:iron_plate:1,null,100)
RandomBlock(2,1,-2,quark:iron_plate:1,null,70,STAINED_CLAY:15,null,30,STAINED_CLAY:7,null,30,quark:iron_plate:1,null,100)
Block(2,1,-1,quark:world_stone_pavement:2)
Block(2,2,-7,quark:world_stone_pavement:2)
RandomBlock(2,2,-6,quark:iron_plate:1,null,70,STAINED_CLAY:15,null,30,STAINED_CLAY:7,null,30,quark:iron_plate:1,null,100)
RandomBlock(2,2,-5,quark:iron_plate:1,null,70,STAINED_CLAY:15,null,30,STAINED_CLAY:7,null,30,quark:iron_plate:1,null,100)
RandomBlock(2,2,-4,quark:iron_plate:1,null,70,STAINED_CLAY:15,null,30,STAINED_CLAY:7,null,30,quark:iron_plate:1,null,100)
RandomBlock(2,2,-3,quark:iron_plate:1,null,70,STAINED_CLAY:15,null,30,STAINED_CLAY:7,null,30,quark:iron_plate:1,null,100)
RandomBlock(2,2,-2,quark:iron_plate:1,null,70,STAINED_CLAY:15,null,30,STAINED_CLAY:7,null,30,quark:iron_plate:1,null,100)
Block(2,2,-1,quark:world_stone_pavement:2)
Block(2,3,-7,quark:basalt_wall:0)
RandomBlock(2,3,-6,quark:iron_plate:1,null,70,STAINED_CLAY:15,null,30,STAINED_CLAY:7,null,30,quark:iron_plate:1,null,100)
RandomBlock(2,3,-5,quark:iron_plate:1,null,70,STAINED_CLAY:15,null,30,STAINED_CLAY:7,null,30,quark:iron_plate:1,null,100)
Block(2,3,-4,srparasites:deadblood:1)
RandomBlock(2,3,-3,quark:iron_plate:1,null,70,STAINED_CLAY:15,null,30,STAINED_CLAY:7,null,30,quark:iron_plate:1,null,100)
RandomBlock(2,3,-2,quark:iron_plate:1,null,70,STAINED_CLAY:15,null,30,STAINED_CLAY:7,null,30,quark:iron_plate:1,null,100)
Block(2,3,-1,quark:basalt_wall:0)
Block(2,4,-7,quark:basalt_wall:0)
RandomBlock(2,4,-6,quark:iron_plate:1,null,70,STAINED_CLAY:15,null,30,STAINED_CLAY:7,null,30,quark:iron_plate:1,null,100)
Block(2,4,-5,srparasites:deadblood:1)
Block(2,4,-4,srparasites:deadblood:1)
Block(2,4,-3,srparasites:deadblood:1)
RandomBlock(2,4,-2,quark:iron_plate:1,null,70,STAINED_CLAY:15,null,30,STAINED_CLAY:7,null,30,quark:iron_plate:1,null,100)
Block(2,4,-1,quark:basalt_wall:0)
Block(2,4,5,COBBLESTONE_STAIRS:6)
RandomBlock(2,4,6,quark:iron_plate:1,null,70,STAINED_CLAY:15,null,30,STAINED_CLAY:7,null,30,quark:iron_plate:1,null,100)
RandomBlock(2,4,7,quark:iron_plate:1,null,70,STAINED_CLAY:15,null,30,STAINED_CLAY:7,null,30,quark:iron_plate:1,null,100)
Block(2,4,8,COBBLESTONE_STAIRS:7)
Block(2,5,-7,quark:basalt_wall:0)
RandomBlock(2,5,-6,quark:iron_plate:1,null,70,STAINED_CLAY:15,null,30,STAINED_CLAY:7,null,30,quark:iron_plate:1,null,100)
Block(2,5,-5,srparasites:deadblood:1)
Block(2,5,-4,srparasites:deadblood:1)
Block(2,5,-3,srparasites:deadblood:1)
RandomBlock(2,5,-2,quark:iron_plate:1,null,70,STAINED_CLAY:15,null,30,STAINED_CLAY:7,null,30,quark:iron_plate:1,null,100)
Block(2,5,-1,quark:basalt_wall:0)
RandomBlock(2,5,5,quark:iron_plate:1,null,70,STAINED_CLAY:15,null,30,STAINED_CLAY:7,null,30,quark:iron_plate:1,null,100)
Block(2,5,6,AIR:0)
Block(2,5,7,AIR:0)
RandomBlock(2,5,8,quark:iron_plate:1,null,70,STAINED_CLAY:15,null,30,STAINED_CLAY:7,null,30,quark:iron_plate:1,null,100)
Block(2,6,-7,quark:basalt_wall:0)
RandomBlock(2,6,-6,quark:iron_plate:1,null,70,STAINED_CLAY:15,null,30,STAINED_CLAY:7,null,30,quark:iron_plate:1,null,100)
Block(2,6,-5,srparasites:deadblood:1)
Block(2,6,-4,srparasites:deadblood:1)
Block(2,6,-3,srparasites:deadblood:1)
RandomBlock(2,6,-2,quark:iron_plate:1,null,70,STAINED_CLAY:15,null,30,STAINED_CLAY:7,null,30,quark:iron_plate:1,null,100)
Block(2,6,-1,quark:basalt_wall:0)
RandomBlock(2,6,5,quark:iron_plate:1,null,70,STAINED_CLAY:15,null,30,STAINED_CLAY:7,null,30,quark:iron_plate:1,null,100)
Block(2,6,6,AIR:0)
Block(2,6,7,AIR:0)
RandomBlock(2,6,8,rustic:iron_lattice:1,null,30,rustic:iron_lattice:1,null,30,biomesoplenty:leaves_2:7,null,30,quark:iron_plate_stairs:6,null,10,quark:iron_plate_stairs:0,null,10,quark:iron_plate_stairs:5,null,10,quark:iron_plate_stairs:3,null,10,quark:iron_plate_slab:8,null,10,quark:iron_plate_stairs:7,null,10,quark:iron_plate_stairs:1,null,10,quark:iron_plate_slab:0,null,10,quark:iron_plate_stairs:4,null,10,quark:iron_plate_stairs:2,null,10,rustic:iron_lattice:1,null,50,rustic:iron_lattice:1,null,50,biomesoplenty:leaves_2:7,null,100)
Block(2,7,-7,quark:basalt_wall:0)
RandomBlock(2,7,-6,quark:iron_plate:1,null,70,STAINED_CLAY:15,null,30,STAINED_CLAY:7,null,30,quark:iron_plate:1,null,100)
Block(2,7,-5,srparasites:deadblood:1)
Block(2,7,-4,srparasites:deadblood:1)
Block(2,7,-3,srparasites:deadblood:1)
RandomBlock(2,7,-2,quark:iron_plate:1,null,70,STAINED_CLAY:15,null,30,STAINED_CLAY:7,null,30,quark:iron_plate:1,null,100)
Block(2,7,-1,quark:basalt_wall:0)
Block(2,7,5,COBBLESTONE_STAIRS:2)
RandomBlock(2,7,6,quark:iron_plate:1,null,70,STAINED_CLAY:15,null,30,STAINED_CLAY:7,null,30,quark:iron_plate:1,null,100)
RandomBlock(2,7,7,rustic:iron_lattice:1,null,30,rustic:iron_lattice:1,null,30,biomesoplenty:leaves_2:7,null,30,quark:iron_plate_stairs:6,null,10,quark:iron_plate_stairs:0,null,10,quark:iron_plate_stairs:5,null,10,quark:iron_plate_stairs:3,null,10,quark:iron_plate_slab:8,null,10,quark:iron_plate_stairs:7,null,10,quark:iron_plate_stairs:1,null,10,quark:iron_plate_slab:0,null,10,quark:iron_plate_stairs:4,null,10,quark:iron_plate_stairs:2,null,10,rustic:iron_lattice:1,null,50,rustic:iron_lattice:1,null,50,biomesoplenty:leaves_2:7,null,100)
Block(2,7,8,COBBLESTONE_STAIRS:3)
Block(2,8,-7,quark:basalt_wall:0)
RandomBlock(2,8,-6,quark:iron_plate:1,null,70,STAINED_CLAY:15,null,30,STAINED_CLAY:7,null,30,quark:iron_plate:1,null,100)
Block(2,8,-5,srparasites:deadblood:1)
Block(2,8,-4,srparasites:deadblood:1)
Block(2,8,-3,srparasites:deadblood:1)
RandomBlock(2,8,-2,quark:iron_plate:1,null,70,STAINED_CLAY:15,null,30,STAINED_CLAY:7,null,30,quark:iron_plate:1,null,100)
Block(2,8,-1,quark:basalt_wall:0)
Block(2,9,-7,quark:basalt_wall:0)
RandomBlock(2,9,-6,quark:iron_plate:1,null,70,STAINED_CLAY:15,null,30,STAINED_CLAY:7,null,30,quark:iron_plate:1,null,100)
Block(2,9,-5,srparasites:deadblood:0)
Block(2,9,-4,srparasites:deadblood:0)
Block(2,9,-3,srparasites:deadblood:0)
RandomBlock(2,9,-2,quark:iron_plate:1,null,70,STAINED_CLAY:15,null,30,STAINED_CLAY:7,null,30,quark:iron_plate:1,null,100)
Block(2,9,-1,quark:basalt_wall:0)
Block(2,10,-7,quark:basalt_wall:0)
RandomBlock(2,10,-6,quark:iron_plate:1,null,70,STAINED_CLAY:15,null,30,STAINED_CLAY:7,null,30,quark:iron_plate:1,null,100)
Block(2,10,-5,AIR:0)
Block(2,10,-4,AIR:0)
Block(2,10,-3,AIR:0)
RandomBlock(2,10,-2,quark:iron_plate:1,null,70,STAINED_CLAY:15,null,30,STAINED_CLAY:7,null,30,quark:iron_plate:1,null,100)
Block(2,10,-1,quark:basalt_wall:0)
Block(2,11,-7,quark:basalt_wall:0)
RandomBlock(2,11,-6,quark:iron_plate:1,null,70,STAINED_CLAY:15,null,30,STAINED_CLAY:7,null,30,quark:iron_plate:1,null,100)
Block(2,11,-5,AIR:0)
Block(2,11,-4,AIR:0)
Block(2,11,-3,AIR:0)
RandomBlock(2,11,-2,quark:iron_plate:1,null,70,STAINED_CLAY:15,null,30,STAINED_CLAY:7,null,30,quark:iron_plate:1,null,100)
Block(2,11,-1,quark:basalt_wall:0)
Block(2,12,-7,quark:basalt_wall:0)
RandomBlock(2,12,-6,quark:iron_plate:1,null,70,STAINED_CLAY:15,null,30,STAINED_CLAY:7,null,30,quark:iron_plate:1,null,100)
RandomBlock(2,12,-5,quark:iron_plate:1,null,70,STAINED_CLAY:15,null,30,STAINED_CLAY:7,null,30,quark:iron_plate:1,null,100)
Block(2,12,-4,AIR:0)
RandomBlock(2,12,-3,quark:iron_plate:1,null,70,STAINED_CLAY:15,null,30,STAINED_CLAY:7,null,30,quark:iron_plate:1,null,100)
RandomBlock(2,12,-2,quark:iron_plate:1,null,70,STAINED_CLAY:15,null,30,STAINED_CLAY:7,null,30,quark:iron_plate:1,null,100)
Block(2,12,-1,quark:basalt_wall:0)
Block(2,13,-7,quark:world_stone_pavement:2)
RandomBlock(2,13,-6,quark:iron_plate:1,null,70,STAINED_CLAY:15,null,30,STAINED_CLAY:7,null,30,quark:iron_plate:1,null,100)
RandomBlock(2,13,-5,quark:iron_plate:1,null,70,STAINED_CLAY:15,null,30,STAINED_CLAY:7,null,30,quark:iron_plate:1,null,100)
RandomBlock(2,13,-4,quark:iron_plate:1,null,70,STAINED_CLAY:15,null,30,STAINED_CLAY:7,null,30,quark:iron_plate:1,null,100)
RandomBlock(2,13,-3,quark:iron_plate:1,null,70,STAINED_CLAY:15,null,30,STAINED_CLAY:7,null,30,quark:iron_plate:1,null,100)
RandomBlock(2,13,-2,quark:iron_plate:1,null,70,STAINED_CLAY:15,null,30,STAINED_CLAY:7,null,30,quark:iron_plate:1,null,100)
Block(2,13,-1,quark:world_stone_pavement:2)
Block(2,14,-7,quark:world_stone_pavement:2)
RandomBlock(2,14,-6,quark:iron_plate:1,null,70,STAINED_CLAY:15,null,30,STAINED_CLAY:7,null,30,quark:iron_plate:1,null,100)
RandomBlock(2,14,-5,quark:iron_plate:1,null,70,STAINED_CLAY:15,null,30,STAINED_CLAY:7,null,30,quark:iron_plate:1,null,100)
RandomBlock(2,14,-4,quark:iron_plate:1,null,70,STAINED_CLAY:15,null,30,STAINED_CLAY:7,null,30,quark:iron_plate:1,null,100)
RandomBlock(2,14,-3,quark:iron_plate:1,null,70,STAINED_CLAY:15,null,30,STAINED_CLAY:7,null,30,quark:iron_plate:1,null,100)
RandomBlock(2,14,-2,quark:iron_plate:1,null,70,STAINED_CLAY:15,null,30,STAINED_CLAY:7,null,30,quark:iron_plate:1,null,100)
Block(2,14,-1,quark:world_stone_pavement:2)
Block(2,15,-6,COBBLESTONE_STAIRS:0)
Block(2,15,-5,COBBLESTONE_STAIRS:0)
Block(2,15,-4,COBBLESTONE_STAIRS:0)
Block(2,15,-3,COBBLESTONE_STAIRS:0)
Block(2,15,-2,COBBLESTONE_STAIRS:3)
Block(3,0,-7,quark:limestone:0)
RandomBlock(3,0,-6,quark:iron_plate:1,null,70,STAINED_CLAY:15,null,30,STAINED_CLAY:7,null,30,quark:iron_plate:1,null,100)
RandomBlock(3,0,-5,quark:iron_plate:1,null,70,STAINED_CLAY:15,null,30,STAINED_CLAY:7,null,30,quark:iron_plate:1,null,100)
RandomBlock(3,0,-4,quark:iron_plate:1,null,70,STAINED_CLAY:15,null,30,STAINED_CLAY:7,null,30,quark:iron_plate:1,null,100)
RandomBlock(3,0,-3,quark:iron_plate:1,null,70,STAINED_CLAY:15,null,30,STAINED_CLAY:7,null,30,quark:iron_plate:1,null,100)
RandomBlock(3,0,-2,quark:iron_plate:1,null,70,STAINED_CLAY:15,null,30,STAINED_CLAY:7,null,30,quark:iron_plate:1,null,100)
Block(3,0,-1,quark:limestone:0)
Block(3,1,-7,quark:world_stone_pavement:2)
RandomBlock(3,1,-6,quark:iron_plate:1,null,70,STAINED_CLAY:15,null,30,STAINED_CLAY:7,null,30,quark:iron_plate:1,null,100)
Block(3,1,-5,srparasites:deadblood:1)
Block(3,1,-4,srparasites:deadblood:1)
Block(3,1,-3,srparasites:deadblood:1)
RandomBlock(3,1,-2,quark:iron_plate:1,null,70,STAINED_CLAY:15,null,30,STAINED_CLAY:7,null,30,quark:iron_plate:1,null,100)
Block(3,1,-1,quark:world_stone_pavement:2)
Block(3,2,-7,quark:basalt_wall:0)
RandomBlock(3,2,-6,quark:iron_plate:1,null,70,STAINED_CLAY:15,null,30,STAINED_CLAY:7,null,30,quark:iron_plate:1,null,100)
Block(3,2,-5,srparasites:deadblood:1)
Block(3,2,-4,srparasites:deadblood:1)
Block(3,2,-3,srparasites:deadblood:1)
RandomBlock(3,2,-2,quark:iron_plate:1,null,70,STAINED_CLAY:15,null,30,STAINED_CLAY:7,null,30,quark:iron_plate:1,null,100)
Block(3,2,-1,quark:world_stone_pavement:2)
Block(3,3,-7,quark:basalt_wall:0)
RandomBlock(3,3,-6,quark:iron_plate:1,null,70,STAINED_CLAY:15,null,30,STAINED_CLAY:7,null,30,quark:iron_plate:1,null,100)
Block(3,3,-5,srparasites:deadblood:1)
Block(3,3,-4,srparasites:deadblood:1)
Block(3,3,-3,srparasites:deadblood:1)
RandomBlock(3,3,-2,quark:iron_plate:1,null,70,STAINED_CLAY:15,null,30,STAINED_CLAY:7,null,30,quark:iron_plate:1,null,100)
Block(3,3,-1,quark:world_stone_pavement:2)
Block(3,4,-7,quark:world_stone_pavement:2)
Block(3,4,-6,srparasites:deadblood:1)
Block(3,4,-5,srparasites:deadblood:1)
Block(3,4,-4,srparasites:deadblood:1)
Block(3,4,-3,srparasites:deadblood:1)
RandomBlock(3,4,-2,quark:iron_plate:1,null,70,STAINED_CLAY:15,null,30,STAINED_CLAY:7,null,30,quark:iron_plate:1,null,100)
Block(3,4,-1,quark:world_stone_pavement:2)
Block(3,4,0,COBBLESTONE_STAIRS:4)
Block(3,4,1,COBBLESTONE_STAIRS:4)
Block(3,4,2,COBBLESTONE_STAIRS:4)
Block(3,4,3,COBBLESTONE_STAIRS:4)
Block(3,4,4,COBBLESTONE_STAIRS:4)
Block(3,4,5,COBBLESTONE_STAIRS:6)
RandomBlock(3,4,6,quark:iron_plate:1,null,70,STAINED_CLAY:15,null,30,STAINED_CLAY:7,null,30,quark:iron_plate:1,null,100)
RandomBlock(3,4,7,quark:iron_plate:1,null,70,STAINED_CLAY:15,null,30,STAINED_CLAY:7,null,30,quark:iron_plate:1,null,100)
Block(3,4,8,COBBLESTONE_STAIRS:7)
Block(3,5,-7,quark:world_stone_pavement:2)
Block(3,5,-6,srparasites:deadblood:1)
Block(3,5,-5,srparasites:deadblood:1)
Block(3,5,-4,srparasites:deadblood:1)
Block(3,5,-3,srparasites:deadblood:1)
RandomBlock(3,5,-2,quark:iron_plate:1,null,70,STAINED_CLAY:15,null,30,STAINED_CLAY:7,null,30,quark:iron_plate:1,null,100)
RandomBlock(3,5,-1,quark:iron_plate:1,null,70,STAINED_CLAY:15,null,30,STAINED_CLAY:7,null,30,quark:iron_plate:1,null,100)
RandomBlock(3,5,0,quark:iron_plate:1,null,70,STAINED_CLAY:15,null,30,STAINED_CLAY:7,null,30,quark:iron_plate:1,null,100)
RandomBlock(3,5,1,quark:iron_plate:1,null,70,STAINED_CLAY:15,null,30,STAINED_CLAY:7,null,30,quark:iron_plate:1,null,100)
RandomBlock(3,5,2,quark:iron_plate:1,null,70,STAINED_CLAY:15,null,30,STAINED_CLAY:7,null,30,quark:iron_plate:1,null,100)
RandomBlock(3,5,3,quark:iron_plate:1,null,70,STAINED_CLAY:15,null,30,STAINED_CLAY:7,null,30,quark:iron_plate:1,null,100)
RandomBlock(3,5,4,quark:iron_plate:1,null,70,STAINED_CLAY:15,null,30,STAINED_CLAY:7,null,30,quark:iron_plate:1,null,100)
RandomBlock(3,5,5,quark:iron_plate:1,null,70,STAINED_CLAY:15,null,30,STAINED_CLAY:7,null,30,quark:iron_plate:1,null,100)
Block(3,5,6,AIR:0)
Block(3,5,7,AIR:0)
RandomBlock(3,5,8,quark:iron_plate:1,null,70,STAINED_CLAY:15,null,30,STAINED_CLAY:7,null,30,quark:iron_plate:1,null,100)
Block(3,6,-7,quark:world_stone_pavement:2)
Block(3,6,-6,srparasites:deadblood:1)
Block(3,6,-5,srparasites:deadblood:1)
Block(3,6,-4,srparasites:deadblood:1)
Block(3,6,-3,srparasites:deadblood:1)
RandomBlock(3,6,-2,quark:iron_plate:1,null,70,STAINED_CLAY:15,null,30,STAINED_CLAY:7,null,30,quark:iron_plate:1,null,100)
RandomBlock(3,6,-1,quark:iron_plate:1,null,70,STAINED_CLAY:15,null,30,STAINED_CLAY:7,null,30,quark:iron_plate:1,null,100)
RandomBlock(3,6,0,quark:iron_plate:1,null,70,STAINED_CLAY:15,null,30,STAINED_CLAY:7,null,30,quark:iron_plate:1,null,100)
RandomBlock(3,6,1,quark:iron_plate:1,null,70,STAINED_CLAY:15,null,30,STAINED_CLAY:7,null,30,quark:iron_plate:1,null,100)
RandomBlock(3,6,2,quark:iron_plate:1,null,70,STAINED_CLAY:15,null,30,STAINED_CLAY:7,null,30,quark:iron_plate:1,null,100)
RandomBlock(3,6,3,quark:iron_plate:1,null,70,STAINED_CLAY:15,null,30,STAINED_CLAY:7,null,30,quark:iron_plate:1,null,100)
RandomBlock(3,6,4,quark:iron_plate:1,null,70,STAINED_CLAY:15,null,30,STAINED_CLAY:7,null,30,quark:iron_plate:1,null,100)
RandomBlock(3,6,5,quark:iron_plate:1,null,70,STAINED_CLAY:15,null,30,STAINED_CLAY:7,null,30,quark:iron_plate:1,null,100)
Block(3,6,6,AIR:0)
Block(3,6,7,AIR:0)
RandomBlock(3,6,8,quark:iron_plate:1,null,70,STAINED_CLAY:15,null,30,STAINED_CLAY:7,null,30,quark:iron_plate:1,null,100)
Block(3,7,-7,quark:world_stone_pavement:2)
Block(3,7,-6,srparasites:deadblood:1)
Block(3,7,-5,srparasites:deadblood:1)
Block(3,7,-4,srparasites:deadblood:1)
Block(3,7,-3,srparasites:deadblood:1)
RandomBlock(3,7,-2,quark:iron_plate:1,null,70,STAINED_CLAY:15,null,30,STAINED_CLAY:7,null,30,quark:iron_plate:1,null,100)
Block(3,7,-1,quark:world_stone_pavement:2)
Block(3,7,0,COBBLESTONE_STAIRS:0)
RandomBlock(3,7,1,quark:iron_plate:1,null,70,STAINED_CLAY:15,null,30,STAINED_CLAY:7,null,30,quark:iron_plate:1,null,100)
RandomBlock(3,7,2,quark:iron_plate:1,null,70,STAINED_CLAY:15,null,30,STAINED_CLAY:7,null,30,quark:iron_plate:1,null,100)
RandomBlock(3,7,3,quark:iron_plate:1,null,70,STAINED_CLAY:15,null,30,STAINED_CLAY:7,null,30,quark:iron_plate:1,null,100)
Block(3,7,4,COBBLESTONE_STAIRS:0)
Block(3,7,5,COBBLESTONE_STAIRS:2)
RandomBlock(3,7,6,quark:iron_plate:1,null,70,STAINED_CLAY:15,null,30,STAINED_CLAY:7,null,30,quark:iron_plate:1,null,100)
RandomBlock(3,7,7,quark:iron_plate:1,null,70,STAINED_CLAY:15,null,30,STAINED_CLAY:7,null,30,quark:iron_plate:1,null,100)
Block(3,7,8,COBBLESTONE_STAIRS:3)
Block(3,8,-7,quark:world_stone_pavement:2)
Block(3,8,-6,srparasites:deadblood:1)
Block(3,8,-5,srparasites:deadblood:1)
Block(3,8,-4,srparasites:deadblood:1)
Block(3,8,-3,srparasites:deadblood:1)
Block(3,8,-2,srparasites:deadblood:1)
Block(3,8,-1,quark:world_stone_pavement:2)
Block(3,8,1,quark:iron_plate_slab:0)
Block(3,8,2,quark:iron_plate_slab:0)
Block(3,8,3,quark:iron_plate_slab:0)
Block(3,9,-7,quark:world_stone_pavement:2)
Block(3,9,-6,srparasites:deadblood:0)
Block(3,9,-5,srparasites:deadblood:1)
Block(3,9,-4,srparasites:deadblood:1)
Block(3,9,-3,srparasites:deadblood:1)
Block(3,9,-2,srparasites:deadblood:0)
Block(3,9,-1,quark:world_stone_pavement:2)
Block(3,9,1,rustic:iron_lattice:0)
Block(3,9,2,rustic:iron_lattice:0)
Block(3,9,3,rustic:iron_lattice:0)
Block(3,10,-7,quark:world_stone_pavement:2)
Block(3,10,-6,AIR:0)
Block(3,10,-5,AIR:0)
Block(3,10,-4,AIR:0)
Block(3,10,-3,AIR:0)
Block(3,10,-2,AIR:0)
Block(3,10,-1,quark:world_stone_pavement:2)
Block(3,11,-7,quark:world_stone_pavement:2)
Block(3,11,-6,AIR:0)
Block(3,11,-5,AIR:0)
Block(3,11,-4,AIR:0)
Block(3,11,-3,AIR:0)
Block(3,11,-2,AIR:0)
Block(3,11,-1,quark:world_stone_pavement:2)
Block(3,12,-7,quark:basalt_wall:0)
RandomBlock(3,12,-6,quark:iron_plate:1,null,70,STAINED_CLAY:15,null,30,STAINED_CLAY:7,null,30,quark:iron_plate:1,null,100)
Block(3,12,-5,AIR:0)
Block(3,12,-4,AIR:0)
Block(3,12,-3,AIR:0)
RandomBlock(3,12,-2,quark:iron_plate:1,null,70,STAINED_CLAY:15,null,30,STAINED_CLAY:7,null,30,quark:iron_plate:1,null,100)
Block(3,12,-1,quark:basalt_wall:0)
Block(3,13,-7,quark:basalt_wall:0)
RandomBlock(3,13,-6,quark:iron_plate:1,null,70,STAINED_CLAY:15,null,30,STAINED_CLAY:7,null,30,quark:iron_plate:1,null,100)
Block(3,13,-5,AIR:0)
Block(3,13,-4,AIR:0)
Block(3,13,-3,AIR:0)
RandomBlock(3,13,-2,quark:iron_plate:1,null,70,STAINED_CLAY:15,null,30,STAINED_CLAY:7,null,30,quark:iron_plate:1,null,100)
Block(3,13,-1,quark:basalt_wall:0)
Block(3,14,-7,quark:world_stone_pavement:2)
RandomBlock(3,14,-6,quark:iron_plate:1,null,70,STAINED_CLAY:15,null,30,STAINED_CLAY:7,null,30,quark:iron_plate:1,null,100)
RandomBlock(3,14,-5,quark:iron_plate:1,null,70,STAINED_CLAY:15,null,30,STAINED_CLAY:7,null,30,quark:iron_plate:1,null,100)
RandomBlock(3,14,-4,quark:iron_plate:1,null,70,STAINED_CLAY:15,null,30,STAINED_CLAY:7,null,30,quark:iron_plate:1,null,100)
RandomBlock(3,14,-3,quark:iron_plate:1,null,70,STAINED_CLAY:15,null,30,STAINED_CLAY:7,null,30,quark:iron_plate:1,null,100)
RandomBlock(3,14,-2,quark:iron_plate:1,null,70,STAINED_CLAY:15,null,30,STAINED_CLAY:7,null,30,quark:iron_plate:1,null,100)
Block(3,14,-1,quark:world_stone_pavement:2)
Block(3,15,-6,COBBLESTONE_STAIRS:2)
RandomBlock(3,15,-5,quark:iron_plate:1,null,70,STAINED_CLAY:15,null,30,STAINED_CLAY:7,null,30,quark:iron_plate:1,null,100)
RandomBlock(3,15,-4,quark:iron_plate:1,null,70,STAINED_CLAY:15,null,30,STAINED_CLAY:7,null,30,quark:iron_plate:1,null,100)
RandomBlock(3,15,-3,quark:iron_plate:1,null,70,STAINED_CLAY:15,null,30,STAINED_CLAY:7,null,30,quark:iron_plate:1,null,100)
Block(3,15,-2,COBBLESTONE_STAIRS:3)
Block(4,0,-7,quark:limestone:0)
RandomBlock(4,0,-6,quark:iron_plate:1,null,70,STAINED_CLAY:15,null,30,STAINED_CLAY:7,null,30,quark:iron_plate:1,null,100)
RandomBlock(4,0,-5,quark:iron_plate:1,null,70,STAINED_CLAY:15,null,30,STAINED_CLAY:7,null,30,quark:iron_plate:1,null,100)
RandomBlock(4,0,-4,quark:iron_plate:1,null,70,STAINED_CLAY:15,null,30,STAINED_CLAY:7,null,30,quark:iron_plate:1,null,100)
RandomBlock(4,0,-3,quark:iron_plate:1,null,70,STAINED_CLAY:15,null,30,STAINED_CLAY:7,null,30,quark:iron_plate:1,null,100)
RandomBlock(4,0,-2,quark:iron_plate:1,null,70,STAINED_CLAY:15,null,30,STAINED_CLAY:7,null,30,quark:iron_plate:1,null,100)
Block(4,0,-1,quark:limestone:0)
Block(4,1,-7,quark:world_stone_pavement:2)
RandomBlock(4,1,-6,quark:iron_plate:1,null,70,STAINED_CLAY:15,null,30,STAINED_CLAY:7,null,30,quark:iron_plate:1,null,100)
Block(4,1,-5,srparasites:deadblood:1)
Block(4,1,-4,srparasites:deadblood:1)
Block(4,1,-3,srparasites:deadblood:1)
RandomBlock(4,1,-2,quark:iron_plate:1,null,70,STAINED_CLAY:15,null,30,STAINED_CLAY:7,null,30,quark:iron_plate:1,null,100)
Block(4,1,-1,quark:world_stone_pavement:2)
Block(4,2,-7,quark:basalt_wall:0)
RandomBlock(4,2,-6,quark:iron_plate:1,null,70,STAINED_CLAY:15,null,30,STAINED_CLAY:7,null,30,quark:iron_plate:1,null,100)
Block(4,2,-5,srparasites:deadblood:1)
Block(4,2,-4,srparasites:deadblood:1)
Block(4,2,-3,srparasites:deadblood:1)
RandomBlock(4,2,-2,quark:iron_plate:1,null,70,STAINED_CLAY:15,null,30,STAINED_CLAY:7,null,30,quark:iron_plate:1,null,100)
Block(4,2,-1,quark:world_stone_pavement:2)
Block(4,3,-7,quark:world_stone_pavement:2)
Block(4,3,-6,srparasites:deadblood:1)
Block(4,3,-5,srparasites:deadblood:1)
Block(4,3,-4,srparasites:deadblood:1)
Block(4,3,-3,srparasites:deadblood:1)
RandomBlock(4,3,-2,quark:iron_plate:1,null,70,STAINED_CLAY:15,null,30,STAINED_CLAY:7,null,30,quark:iron_plate:1,null,100)
Block(4,3,-1,quark:world_stone_pavement:2)
Block(4,4,-7,quark:world_stone_pavement:2)
Block(4,4,-6,srparasites:deadblood:1)
Block(4,4,-5,srparasites:deadblood:1)
Block(4,4,-4,srparasites:deadblood:1)
Block(4,4,-3,srparasites:deadblood:1)
RandomBlock(4,4,-2,quark:iron_plate:1,null,70,STAINED_CLAY:15,null,30,STAINED_CLAY:7,null,30,quark:iron_plate:1,null,100)
RandomBlock(4,4,-1,quark:iron_plate:1,null,70,STAINED_CLAY:15,null,30,STAINED_CLAY:7,null,30,quark:iron_plate:1,null,100)
RandomBlock(4,4,0,quark:iron_plate:1,null,70,STAINED_CLAY:15,null,30,STAINED_CLAY:7,null,30,quark:iron_plate:1,null,100)
RandomBlock(4,4,1,quark:iron_plate:1,null,70,STAINED_CLAY:15,null,30,STAINED_CLAY:7,null,30,quark:iron_plate:1,null,100)
RandomBlock(4,4,2,quark:iron_plate:1,null,70,STAINED_CLAY:15,null,30,STAINED_CLAY:7,null,30,quark:iron_plate:1,null,100)
RandomBlock(4,4,3,quark:iron_plate:1,null,70,STAINED_CLAY:15,null,30,STAINED_CLAY:7,null,30,quark:iron_plate:1,null,100)
RandomBlock(4,4,4,quark:iron_plate:1,null,70,STAINED_CLAY:15,null,30,STAINED_CLAY:7,null,30,quark:iron_plate:1,null,100)
RandomBlock(4,4,5,quark:iron_plate:1,null,70,STAINED_CLAY:15,null,30,STAINED_CLAY:7,null,30,quark:iron_plate:1,null,100)
RandomBlock(4,4,6,quark:iron_plate:1,null,70,STAINED_CLAY:15,null,30,STAINED_CLAY:7,null,30,quark:iron_plate:1,null,100)
RandomBlock(4,4,7,quark:iron_plate:1,null,70,STAINED_CLAY:15,null,30,STAINED_CLAY:7,null,30,quark:iron_plate:1,null,100)
Block(4,4,8,COBBLESTONE_STAIRS:7)
Block(4,5,-7,quark:framed_glass:0)
Block(4,5,-6,srparasites:deadblood:1)
Block(4,5,-5,srparasites:deadblood:1)
Block(4,5,-4,srparasites:deadblood:1)
Block(4,5,-3,srparasites:deadblood:1)
Block(4,5,-2,srparasites:deadblood:1)
Block(4,5,-1,srparasites:deadblood:1)
Block(4,5,0,srparasites:deadblood:1)
Block(4,5,1,srparasites:deadblood:1)
Block(4,5,2,SMOOTH_STAIRS:3)
Block(4,5,3,AIR:0)
Block(4,5,4,AIR:0)
Block(4,5,5,AIR:0)
Block(4,5,6,AIR:0)
Block(4,5,7,AIR:0)
RandomBlock(4,5,8,quark:iron_plate:1,null,70,STAINED_CLAY:15,null,30,STAINED_CLAY:7,null,30,quark:iron_plate:1,null,100)
Block(4,6,-7,quark:framed_glass:0)
Block(4,6,-6,srparasites:deadblood:1)
Block(4,6,-5,srparasites:deadblood:1)
Block(4,6,-4,srparasites:deadblood:1)
Block(4,6,-3,srparasites:deadblood:1)
Block(4,6,-2,srparasites:deadblood:1)
Block(4,6,-1,srparasites:deadblood:0)
Block(4,6,0,srparasites:deadblood:0)
Block(4,6,1,srparasites:deadblood:0)
Block(4,6,2,SMOOTH_STAIRS:7)
Block(4,6,3,AIR:0)
Block(4,6,4,AIR:0)
Block(4,6,5,AIR:0)
Block(4,6,6,AIR:0)
Block(4,6,7,AIR:0)
RandomBlock(4,6,8,quark:iron_plate:1,null,70,STAINED_CLAY:15,null,30,STAINED_CLAY:7,null,30,quark:iron_plate:1,null,100)
Block(4,7,-7,quark:framed_glass:0)
Block(4,7,-6,srparasites:deadblood:1)
Block(4,7,-5,srparasites:deadblood:1)
Block(4,7,-4,srparasites:deadblood:1)
Block(4,7,-3,srparasites:deadblood:1)
Block(4,7,-2,srparasites:deadblood:1)
Block(4,7,-1,quark:world_stone_pavement:2)
RandomBlock(4,7,0,quark:iron_plate:1,null,70,STAINED_CLAY:15,null,30,STAINED_CLAY:7,null,30,quark:iron_plate:1,null,100)
RandomBlock(4,7,1,quark:iron_plate:1,null,70,STAINED_CLAY:15,null,30,STAINED_CLAY:7,null,30,quark:iron_plate:1,null,100)
RandomBlock(4,7,2,quark:iron_plate:1,null,70,STAINED_CLAY:15,null,30,STAINED_CLAY:7,null,30,quark:iron_plate:1,null,100)
RandomBlock(4,7,3,quark:iron_plate:1,null,70,STAINED_CLAY:15,null,30,STAINED_CLAY:7,null,30,quark:iron_plate:1,null,100)
RandomBlock(4,7,4,quark:iron_plate:1,null,70,STAINED_CLAY:15,null,30,STAINED_CLAY:7,null,30,quark:iron_plate:1,null,100)
RandomBlock(4,7,5,quark:iron_plate:1,null,70,STAINED_CLAY:15,null,30,STAINED_CLAY:7,null,30,quark:iron_plate:1,null,100)
RandomBlock(4,7,6,quark:iron_plate:1,null,70,STAINED_CLAY:15,null,30,STAINED_CLAY:7,null,30,quark:iron_plate:1,null,100)
RandomBlock(4,7,7,quark:iron_plate:1,null,70,STAINED_CLAY:15,null,30,STAINED_CLAY:7,null,30,quark:iron_plate:1,null,100)
Block(4,7,8,COBBLESTONE_STAIRS:3)
Block(4,8,-7,quark:framed_glass:0)
Block(4,8,-6,srparasites:deadblood:1)
Block(4,8,-5,srparasites:deadblood:1)
Block(4,8,-4,srparasites:deadblood:1)
Block(4,8,-3,srparasites:deadblood:1)
Block(4,8,-2,srparasites:deadblood:1)
Block(4,8,-1,quark:world_stone_pavement:2)
Block(4,8,1,quark:iron_plate_slab:0)
Block(4,8,2,quark:basalt_wall:0)
Block(4,8,3,quark:iron_plate_slab:0)
Block(4,9,-7,quark:framed_glass:0)
Block(4,9,-6,srparasites:deadblood:0)
Block(4,9,-5,srparasites:deadblood:0)
Block(4,9,-4,srparasites:deadblood:1)
Block(4,9,-3,srparasites:deadblood:1)
Block(4,9,-2,srparasites:deadblood:1)
Block(4,9,-1,quark:framed_glass:0)
Block(4,9,1,rustic:iron_lattice:0)
Block(4,9,2,rustic:iron_lattice:0)
Block(4,9,3,rustic:iron_lattice:0)
Block(4,10,-7,quark:framed_glass:0)
Block(4,10,-6,AIR:0)
Block(4,10,-5,AIR:0)
Block(4,10,-4,AIR:0)
Block(4,10,-3,AIR:0)
Block(4,10,-2,AIR:0)
Block(4,10,-1,quark:framed_glass:0)
Block(4,11,-7,quark:world_stone_pavement:2)
Block(4,11,-6,AIR:0)
Block(4,11,-5,AIR:0)
Block(4,11,-4,AIR:0)
Block(4,11,-3,AIR:0)
Block(4,11,-2,AIR:0)
Block(4,11,-1,quark:world_stone_pavement:2)
Block(4,12,-7,quark:world_stone_pavement:2)
Block(4,12,-6,AIR:0)
Block(4,12,-5,AIR:0)
