
#######################################################################
# +-----------------------------------------------------------------+ #
# |                            BO4 object                           | #
# +-----------------------------------------------------------------+ #
#######################################################################

# This is the config file of a custom object.
# If you add this object correctly to your BiomeConfigs, it will spawn in the world.

# This is the creator of this BO4 object
Author: NLBlackEagle

# A short description of this BO4 object
Description: No description given

# The settings mode, WriteAll, WriteWithoutComments or WriteDisable. See WorldConfig.
SettingsMode: WriteAll


#######################################################################
# +-----------------------------------------------------------------+ #
# |                          Main settings                          | #
# +-----------------------------------------------------------------+ #
#######################################################################

# If this BO4 should spawn with a fixed rotation, set it here.
# For example: NORTH, EAST, SOUTH or WEST. Empty by default
FixedRotation: 

# This BO4 can only spawn at least Frequency chunks distance away from any other BO4 with the exact same name.
# You can use this to make this BO4 spawn in groups or make sure that this BO4 only spawns once every X chunks.
Frequency: 0

# The spawn height of the BO4: randomY, highestBlock or highestSolidBlock.
SpawnHeight: highestBlock

# When set to true, uses the center of the structure (determined by minimum structure size) when checking the highestBlock to spawn at.
UseCenterForHighestBlock: true

##############################
# Height Limits for the BO4. #
##############################

# When in randomY mode used as the minimum Y or in atMinY mode as the actual Y to spawn this BO4 at.
MinHeight: 0

# When in randomY mode used as the maximum Y to spawn this BO4 at.
MaxHeight: 255

# Copies the blocks and branches of an existing BO4 into this BO4. You can still add blocks and branches in this BO4, they will be added on top of the inherited blocks and branches.
InheritBO3: 

# Rotates the inheritedBO3's resources (blocks, spawners, checks etc) and branches, defaults to NORTH (no rotation).
InheritBO3Rotation: NORTH

# Defaults to true, if true and this is the starting BO4 for this branching structure then this BO4's smoothing and height settings are used for all children (branches).
OverrideChildSettings: true

# Defaults to false, if true then this branch uses it's own height settings (SpawnHeight, minHeight, maxHeight, spawnAtWaterLevel) instead of those defined in the starting BO4 for this branching structure.
OverrideParentHeight: false

# If this is set to true then this BO4 can spawn on top of or inside an existing BO4. If this is set to false then this BO4 will use a bounding box to detect collisions with other BO4's, if a collision is detected then this BO4 won't spawn and the current branch is rolled back.
CanOverride: false

# This branch can only spawn at least branchFrequency chunks (x,z) distance away from any other branch with the exact same name.
BranchFrequency: 0

# Define groups that this branch belongs to along with a minimum (x,z) range in chunks that this branch must have between it and any other members of this group if it is to be allowed to spawn. Syntax is "GroupName:Frequency, GoupName2:Frequency2" etc so for example a branch that belongs to 3 groups: "BranchFrequencyGroup: Ships:10, Vehicles:5, FloatingThings:3".
BranchFrequencyGroup: 

# If this is set to true then this BO4 can only spawn underneath an existing BO4. Used to make sure that dungeons only appear underneath buildings.
MustBeBelowOther: false

# Used with CanOverride: true. A comma-seperated list of BO4s, this BO4's bounding box must collide with one of the BO4's in the list or this BO4 fails to spawn and the current branch is rolled back. AND/OR is supported, comma is OR, space is AND, f.e: branch1, branch2 branch3, branch 4.
MustBeInside: 

# Used with CanOverride: true. A comma-seperated list of BO4s, this BO4's bounding box cannot collide with any of the BO4's in the list or this BO4 fails to spawn and the current branch is rolled back.
CannotBeInside: 

# Used with CanOverride: true. A comma-seperated list of BO4s, if this BO4's bounding box collides with any of the BO4's in the list then those BO4's won't spawn any blocks. This does not remove or roll back any BO4's.
ReplacesBO3: 

# If this is set to true then this BO4 can only spawn inside world borders. Used to make sure that dungeons only appear inside the world borders.
MustBeInsideWorldBorders: false

# Defaults to true. Set to false if the BO4 is not allowed to spawn on a water block
CanSpawnOnWater: true

# Defaults to false. Set to true if the BO4 is allowed to spawn only on a water block
SpawnOnWaterOnly: false

# Defaults to false. Set to true if the BO4 and its smoothing area should ignore water when looking for the highest block to spawn on. Defaults to false (things spawn on top of water)
SpawnUnderWater: false

# Defaults to false. Set to true if the BO4 should spawn at water level
SpawnAtWaterLevel: false

# Spawns the BO4 at a Y offset of this value. Handy when using highestBlock for lowering BO4s into the surrounding terrain when there are layers of ground included in the BO4, also handy when using SpawnAtWaterLevel to lower objects like ships into the water.
HeightOffset: 0

# If set to true removes all AIR blocks from the BO4 so that it can be flooded or buried.
RemoveAir: false

# Replaces all the non-air blocks that are above this BO4 or its smoothing area with the given block material (should be WATER or AIR or NONE), also applies to smoothing areas although OTG intentionally leaves some of the terrain above them intact. WATER can be used in combination with SpawnUnderWater to fill any air blocks underneath waterlevel with water (and any above waterlevel with air).
ReplaceAbove: 

# Replaces all air blocks underneath the BO4 (but not its smoothing area) with the specified material until a solid block is found.
ReplaceBelow: 

# Defaults to true. If set to true then every block in the BO4 of the materials defined in ReplaceWithGroundBlock or ReplaceWithSurfaceBlock will be replaced by the GroundBlock or SurfaceBlock materials configured for the biome the block is spawned in.
ReplaceWithBiomeBlocks: true

# Defaults to GRASS, Replaces all the blocks of the given material in the BO4 with the SurfaceBlock configured for the biome it spawns in.
ReplaceWithSurfaceBlock: GRASS

# Defaults to DIRT, Replaces all the blocks of the given material in the BO4 with the GroundBlock configured for the biome it spawns in.
ReplaceWithGroundBlock: DIRT

# Defaults to STONE, Replaces all the blocks of the given material in the BO4 with the StoneBlock configured for the biome it spawns in.
ReplaceWithStoneBlock: STONE

# Makes the terrain around the BO4 slope evenly towards the edges of the BO4. The given value is the distance in blocks around the BO4 from where the slope should start and can be any positive number.
SmoothRadius: 0

# Moves the smoothing area up or down relative to the BO4 (at the points where the smoothing area is connected to the BO4). Handy when using SmoothStartTop: false and the BO4 has some layers of ground included, in that case we can set the HeightOffset to a negative value to lower the BO4 into the ground and we can set the SmoothHeightOffset to a positive value to move the smoothing area starting height up.
SmoothHeightOffset: 0

# Should the smoothing area be attached at the bottom or the top of the edges of the BO4? Defaults to false (bottom). Using this setting can make things slower so try to avoid using it and use SmoothHeightOffset instead if for instance you have a BO4 with some ground layers included. The only reason you should need to use this setting is if you have a BO4 with edges that have an irregular height (like some hills).
SmoothStartTop: false

# Should the smoothing area attach itself to "log" block or ignore them? Defaults to false (ignore logs).
SmoothStartWood: false

# The block used for smoothing area surface blocks, defaults to biome SurfaceBlock.
SmoothingSurfaceBlock: 

# The block used for smoothing area ground blocks, defaults to biome GroundBlock.
SmoothingGroundBlock: 

# Define groups that this BO4 belongs to along with a minimum range in chunks that this BO4 must have between it and any other members of this group if it is to be allowed to spawn. Syntax is "GroupName:Frequency, GoupName2:Frequency2" etc so for example a BO4 that belongs to 3 groups: "BO4Group: Ships:10, Vehicles:5, FloatingThings:3".
BO3Group: 

# Defaults to false. Set to true if this BO4 should spawn at the player spawn point. When the server starts the spawn point is determined and the BO4's for the biome it is in are loaded, one of these BO4s that has IsSpawnPoint set to true (if any) is selected randomly and is spawned at the spawn point regardless of its rarity (so even Rarity:0, IsSpawnPoint: true BO4's can get spawned as the spawn point!).
IsSpawnPoint: false

# Defaults to true. Set to false to make the BO4 ignore any ReplacedBlocks settings in Biome Configs.
DoReplaceBlocks: true


#######################################################################
# +-----------------------------------------------------------------+ #
# |                              Blocks                             | #
# +-----------------------------------------------------------------+ #
#######################################################################

# All the blocks used in the BO4 are listed here. Possible blocks:
# Block(x,y,z,id[.data][,nbtfile.nbt)
# RandomBlock(x,y,z,id[:data][,nbtfile.nbt],chance[,id[:data][,nbtfile.nbt],chance[,...]])
#  So RandomBlock(0,0,0,CHEST,chest.nbt,50,CHEST,anotherchest.nbt,100) will spawn a chest at
#  the BO4 origin, and give it a 50% chance to have the contents of chest.nbt, or, if that
#  fails, a 100% percent chance to have the contents of anotherchest.nbt.
# MinecraftObject(x,y,z,name) (TODO: This may not work anymore and needs to be tested.
#  Spawns an object in the Mojang NBT structure format. For example, 
#  MinecraftObject(0,0,0,minecraft:igloo/igloo_bottom)
#  spawns the bottom part of an igloo.
Block(-7,0,-6,contenttweaker:reinforced_concrete:0)
Block(-7,0,-2,contenttweaker:reinforced_concrete:0)
Block(-7,0,2,contenttweaker:reinforced_concrete:0)
Block(-7,0,5,contenttweaker:reinforced_concrete:0)
Block(-7,0,9,contenttweaker:reinforced_concrete:0)
Block(-7,1,-6,contenttweaker:reinforced_concrete:0)
Block(-7,1,-2,contenttweaker:reinforced_concrete:0)
Block(-7,1,2,contenttweaker:reinforced_concrete:0)
Block(-7,1,5,contenttweaker:reinforced_concrete:0)
Block(-7,1,9,contenttweaker:reinforced_concrete:0)
Block(-7,2,-6,contenttweaker:reinforced_concrete:0)
Block(-7,2,-2,contenttweaker:reinforced_concrete:0)
Block(-7,2,2,contenttweaker:reinforced_concrete:0)
Block(-7,2,5,contenttweaker:reinforced_concrete:0)
Block(-7,2,9,contenttweaker:reinforced_concrete:0)
Block(-7,3,-6,contenttweaker:reinforced_concrete:0)
Block(-7,3,-5,contenttweaker:reinforced_concrete:0)
Block(-7,3,-4,contenttweaker:reinforced_concrete:0)
Block(-7,3,-3,contenttweaker:reinforced_concrete:0)
Block(-7,3,-2,contenttweaker:reinforced_concrete:0)
Block(-7,3,-1,contenttweaker:reinforced_concrete:0)
Block(-7,3,0,contenttweaker:reinforced_concrete:0)
Block(-7,3,1,contenttweaker:reinforced_concrete:0)
Block(-7,3,2,contenttweaker:reinforced_concrete:0)
Block(-7,3,3,contenttweaker:reinforced_concrete:0)
Block(-7,3,4,contenttweaker:reinforced_concrete:0)
Block(-7,3,5,contenttweaker:reinforced_concrete:0)
Block(-7,3,6,contenttweaker:reinforced_concrete:0)
Block(-7,3,7,contenttweaker:reinforced_concrete:0)
Block(-7,3,8,contenttweaker:reinforced_concrete:0)
Block(-7,3,9,contenttweaker:reinforced_concrete:0)
Block(-7,4,-6,contenttweaker:reinforced_concrete:0)
Block(-7,4,-5,contenttweaker:reinforced_concrete:0)
Block(-7,4,-4,contenttweaker:reinforced_concrete:0)
Block(-7,4,-3,contenttweaker:reinforced_concrete:0)
Block(-7,4,-2,contenttweaker:reinforced_concrete:0)
Block(-7,4,-1,contenttweaker:reinforced_concrete:0)
Block(-7,4,0,contenttweaker:reinforced_concrete:0)
Block(-7,4,1,contenttweaker:reinforced_concrete:0)
Block(-7,4,2,contenttweaker:reinforced_concrete:0)
Block(-7,4,3,contenttweaker:reinforced_concrete:0)
Block(-7,4,4,contenttweaker:reinforced_concrete:0)
Block(-7,4,5,contenttweaker:reinforced_concrete:0)
Block(-7,4,6,contenttweaker:reinforced_concrete:0)
Block(-7,4,7,contenttweaker:reinforced_concrete:0)
Block(-7,4,8,contenttweaker:reinforced_concrete:0)
Block(-7,4,9,contenttweaker:reinforced_concrete:0)
Block(-7,5,-6,contenttweaker:reinforced_concrete:0)
Block(-7,5,-5,contenttweaker:reinforced_concrete:0)
Block(-7,5,-4,contenttweaker:reinforced_concrete:0)
Block(-7,5,-3,contenttweaker:reinforced_concrete:0)
Block(-7,5,-2,contenttweaker:reinforced_concrete:0)
Block(-7,5,-1,contenttweaker:reinforced_concrete:0)
Block(-7,5,0,contenttweaker:reinforced_concrete:0)
Block(-7,5,1,contenttweaker:reinforced_concrete:0)
Block(-7,5,2,contenttweaker:reinforced_concrete:0)
Block(-7,5,3,contenttweaker:reinforced_concrete:0)
Block(-7,5,4,contenttweaker:reinforced_concrete:0)
Block(-7,5,5,contenttweaker:reinforced_concrete:0)
Block(-7,5,6,contenttweaker:reinforced_concrete:0)
Block(-7,5,7,contenttweaker:reinforced_concrete:0)
Block(-7,5,8,contenttweaker:reinforced_concrete:0)
Block(-7,5,9,contenttweaker:reinforced_concrete:0)
Block(-7,6,-6,contenttweaker:reinforced_concrete:0)
Block(-7,6,-5,contenttweaker:reinforced_concrete:0)
Block(-7,6,-4,contenttweaker:reinforced_concrete:0)
Block(-7,6,-3,contenttweaker:reinforced_concrete:0)
Block(-7,6,-2,contenttweaker:reinforced_concrete:0)
Block(-7,6,-1,contenttweaker:reinforced_concrete:0)
Block(-7,6,0,contenttweaker:reinforced_concrete:0)
Block(-7,6,1,contenttweaker:reinforced_concrete:0)
Block(-7,6,2,contenttweaker:reinforced_concrete:0)
Block(-7,6,3,contenttweaker:reinforced_concrete:0)
Block(-7,6,4,contenttweaker:reinforced_concrete:0)
Block(-7,6,5,contenttweaker:reinforced_concrete:0)
Block(-7,6,6,contenttweaker:reinforced_concrete:0)
Block(-7,6,7,contenttweaker:reinforced_concrete:0)
Block(-7,6,8,contenttweaker:reinforced_concrete:0)
Block(-7,6,9,contenttweaker:reinforced_concrete:0)
Block(-7,7,-6,contenttweaker:reinforced_concrete:0)
Block(-7,7,-5,contenttweaker:reinforced_concrete:0)
Block(-7,7,-4,contenttweaker:reinforced_concrete:0)
Block(-7,7,-3,contenttweaker:reinforced_concrete:0)
Block(-7,7,-2,contenttweaker:reinforced_concrete:0)
Block(-7,7,-1,contenttweaker:reinforced_concrete:0)
Block(-7,7,0,contenttweaker:reinforced_concrete:0)
Block(-7,7,1,contenttweaker:reinforced_concrete:0)
Block(-7,7,2,contenttweaker:reinforced_concrete:0)
Block(-7,7,3,contenttweaker:reinforced_concrete:0)
Block(-7,7,4,contenttweaker:reinforced_concrete:0)
Block(-7,7,5,contenttweaker:reinforced_concrete:0)
Block(-7,7,6,contenttweaker:reinforced_concrete:0)
Block(-7,7,7,contenttweaker:reinforced_concrete:0)
Block(-7,7,8,contenttweaker:reinforced_concrete:0)
Block(-7,7,9,contenttweaker:reinforced_concrete:0)
Block(-7,8,-6,contenttweaker:reinforced_concrete:0)
Block(-7,8,-5,contenttweaker:reinforced_concrete:0)
Block(-7,8,-4,contenttweaker:reinforced_concrete:0)
Block(-7,8,-3,contenttweaker:reinforced_concrete:0)
Block(-7,8,-2,contenttweaker:reinforced_concrete:0)
Block(-7,8,-1,contenttweaker:reinforced_concrete:0)
Block(-7,8,0,contenttweaker:reinforced_concrete:0)
Block(-7,8,1,contenttweaker:reinforced_concrete:0)
Block(-7,8,2,contenttweaker:reinforced_concrete:0)
Block(-7,8,3,contenttweaker:reinforced_concrete:0)
Block(-7,8,4,contenttweaker:reinforced_concrete:0)
Block(-7,8,5,contenttweaker:reinforced_concrete:0)
Block(-7,8,6,contenttweaker:reinforced_concrete:0)
Block(-7,8,7,contenttweaker:reinforced_concrete:0)
Block(-7,8,8,contenttweaker:reinforced_concrete:0)
Block(-7,8,9,contenttweaker:reinforced_concrete:0)
Block(-7,9,-6,contenttweaker:reinforced_concrete:0)
Block(-7,9,-5,contenttweaker:reinforced_concrete:0)
Block(-7,9,-4,contenttweaker:reinforced_concrete:0)
Block(-7,9,-3,contenttweaker:reinforced_concrete:0)
Block(-7,9,-2,contenttweaker:reinforced_concrete:0)
Block(-7,9,-1,contenttweaker:reinforced_concrete:0)
Block(-7,9,0,contenttweaker:reinforced_concrete:0)
Block(-7,9,1,contenttweaker:reinforced_concrete:0)
Block(-7,9,2,contenttweaker:reinforced_concrete:0)
Block(-7,9,3,contenttweaker:reinforced_concrete:0)
Block(-7,9,4,contenttweaker:reinforced_concrete:0)
Block(-7,9,5,contenttweaker:reinforced_concrete:0)
Block(-7,9,6,contenttweaker:reinforced_concrete:0)
Block(-7,9,7,contenttweaker:reinforced_concrete:0)
Block(-7,9,8,contenttweaker:reinforced_concrete:0)
Block(-7,9,9,contenttweaker:reinforced_concrete:0)
Block(-7,10,-6,contenttweaker:reinforced_concrete:0)
Block(-7,10,-5,contenttweaker:reinforced_concrete:0)
Block(-7,10,-4,contenttweaker:reinforced_concrete:0)
Block(-7,10,-3,contenttweaker:reinforced_concrete:0)
Block(-7,10,-2,contenttweaker:reinforced_concrete:0)
Block(-7,10,-1,contenttweaker:reinforced_concrete:0)
Block(-7,10,0,contenttweaker:reinforced_concrete:0)
Block(-7,10,1,contenttweaker:reinforced_concrete:0)
Block(-7,10,2,contenttweaker:reinforced_concrete:0)
Block(-7,10,3,contenttweaker:reinforced_concrete:0)
Block(-7,10,4,contenttweaker:reinforced_concrete:0)
Block(-7,10,5,contenttweaker:reinforced_concrete:0)
Block(-7,10,6,contenttweaker:reinforced_concrete:0)
Block(-7,10,7,contenttweaker:reinforced_concrete:0)
Block(-7,10,8,contenttweaker:reinforced_concrete:0)
Block(-7,10,9,contenttweaker:reinforced_concrete:0)
Block(-7,11,-6,contenttweaker:reinforced_concrete:0)
Block(-7,11,-5,contenttweaker:reinforced_concrete:0)
Block(-7,11,-4,contenttweaker:reinforced_concrete:0)
Block(-7,11,-3,contenttweaker:reinforced_concrete:0)
Block(-7,11,-2,contenttweaker:reinforced_concrete:0)
Block(-7,11,-1,contenttweaker:reinforced_concrete:0)
Block(-7,11,0,contenttweaker:reinforced_concrete:0)
Block(-7,11,1,contenttweaker:reinforced_concrete:0)
Block(-7,11,2,contenttweaker:reinforced_concrete:0)
Block(-7,11,3,contenttweaker:reinforced_concrete:0)
Block(-7,11,4,contenttweaker:reinforced_concrete:0)
Block(-7,11,5,contenttweaker:reinforced_concrete:0)
Block(-7,11,6,contenttweaker:reinforced_concrete:0)
Block(-7,11,7,contenttweaker:reinforced_concrete:0)
Block(-7,11,8,contenttweaker:reinforced_concrete:0)
Block(-7,11,9,contenttweaker:reinforced_concrete:0)
Block(-7,12,-6,contenttweaker:reinforced_concrete:0)
Block(-7,12,-5,contenttweaker:reinforced_concrete:0)
Block(-7,12,-4,contenttweaker:reinforced_concrete:0)
Block(-7,12,-3,contenttweaker:reinforced_concrete:0)
Block(-7,12,-2,contenttweaker:reinforced_concrete:0)
Block(-7,12,-1,contenttweaker:reinforced_concrete:0)
Block(-7,12,0,contenttweaker:reinforced_concrete:0)
Block(-7,12,1,contenttweaker:reinforced_concrete:0)
Block(-7,12,2,contenttweaker:reinforced_concrete:0)
Block(-7,12,3,contenttweaker:reinforced_concrete:0)
Block(-7,12,4,contenttweaker:reinforced_concrete:0)
Block(-7,12,5,contenttweaker:reinforced_concrete:0)
Block(-7,12,6,contenttweaker:reinforced_concrete:0)
Block(-7,12,7,contenttweaker:reinforced_concrete:0)
Block(-7,12,8,contenttweaker:reinforced_concrete:0)
Block(-7,12,9,contenttweaker:reinforced_concrete:0)
Block(-7,13,-6,contenttweaker:reinforced_concrete:0)
Block(-7,13,-5,contenttweaker:reinforced_concrete:0)
Block(-7,13,-4,contenttweaker:reinforced_concrete:0)
Block(-7,13,-3,contenttweaker:reinforced_concrete:0)
Block(-7,13,-2,contenttweaker:reinforced_concrete:0)
Block(-7,13,-1,contenttweaker:reinforced_concrete:0)
Block(-7,13,0,contenttweaker:reinforced_concrete:0)
Block(-7,13,1,contenttweaker:reinforced_concrete:0)
Block(-7,13,2,contenttweaker:reinforced_concrete:0)
Block(-7,13,3,contenttweaker:reinforced_concrete:0)
Block(-7,13,4,contenttweaker:reinforced_concrete:0)
Block(-7,13,5,contenttweaker:reinforced_concrete:0)
Block(-7,13,6,contenttweaker:reinforced_concrete:0)
Block(-7,13,7,contenttweaker:reinforced_concrete:0)
Block(-7,13,8,contenttweaker:reinforced_concrete:0)
Block(-7,13,9,contenttweaker:reinforced_concrete:0)
Block(-7,14,-6,contenttweaker:reinforced_concrete:0)
Block(-7,14,-5,contenttweaker:reinforced_concrete:0)
Block(-7,14,-4,contenttweaker:reinforced_concrete:0)
Block(-7,14,-3,contenttweaker:reinforced_concrete:0)
Block(-7,14,-2,contenttweaker:reinforced_concrete:0)
Block(-7,14,-1,contenttweaker:reinforced_concrete:0)
Block(-7,14,0,contenttweaker:reinforced_concrete:0)
Block(-7,14,1,contenttweaker:reinforced_concrete:0)
Block(-7,14,2,contenttweaker:reinforced_concrete:0)
Block(-7,14,3,contenttweaker:reinforced_concrete:0)
Block(-7,14,4,contenttweaker:reinforced_concrete:0)
Block(-7,14,5,contenttweaker:reinforced_concrete:0)
Block(-7,14,6,contenttweaker:reinforced_concrete:0)
Block(-7,14,7,contenttweaker:reinforced_concrete:0)
Block(-7,14,8,contenttweaker:reinforced_concrete:0)
Block(-7,14,9,contenttweaker:reinforced_concrete:0)
Block(-7,15,-6,contenttweaker:reinforced_concrete:0)
Block(-7,15,-5,contenttweaker:reinforced_concrete:0)
Block(-7,15,-4,contenttweaker:reinforced_concrete:0)
Block(-7,15,-3,contenttweaker:reinforced_concrete:0)
Block(-7,15,-2,contenttweaker:reinforced_concrete:0)
Block(-7,15,-1,contenttweaker:reinforced_concrete:0)
Block(-7,15,0,contenttweaker:reinforced_concrete:0)
Block(-7,15,1,contenttweaker:reinforced_concrete:0)
Block(-7,15,2,contenttweaker:reinforced_concrete:0)
Block(-7,15,3,contenttweaker:reinforced_concrete:0)
Block(-7,15,4,contenttweaker:reinforced_concrete:0)
Block(-7,15,5,contenttweaker:reinforced_concrete:0)
Block(-7,15,6,contenttweaker:reinforced_concrete:0)
Block(-7,15,7,contenttweaker:reinforced_concrete:0)
Block(-7,15,8,contenttweaker:reinforced_concrete:0)
Block(-7,15,9,contenttweaker:reinforced_concrete:0)
Block(-7,16,-6,contenttweaker:reinforced_concrete:0)
Block(-7,16,-5,contenttweaker:reinforced_concrete:0)
Block(-7,16,-4,contenttweaker:reinforced_concrete:0)
Block(-7,16,-3,contenttweaker:reinforced_concrete:0)
Block(-7,16,-2,contenttweaker:reinforced_concrete:0)
Block(-7,16,-1,contenttweaker:reinforced_concrete:0)
Block(-7,16,0,contenttweaker:reinforced_concrete:0)
Block(-7,16,1,contenttweaker:reinforced_concrete:0)
Block(-7,16,2,contenttweaker:reinforced_concrete:0)
Block(-6,0,5,contenttweaker:reinforced_concrete:0)
Block(-6,0,6,contenttweaker:reinforced_concrete:0)
Block(-6,0,7,contenttweaker:reinforced_concrete:0)
Block(-6,0,8,contenttweaker:reinforced_concrete:0)
Block(-6,0,9,contenttweaker:reinforced_concrete:0)
Block(-6,1,5,contenttweaker:reinforced_concrete:0)
Block(-6,1,6,contenttweaker:reinforced_concrete:0)
Block(-6,1,7,contenttweaker:reinforced_concrete:0)
Block(-6,1,8,contenttweaker:reinforced_concrete:0)
Block(-6,1,9,contenttweaker:reinforced_concrete:0)
Block(-6,2,5,contenttweaker:reinforced_concrete:0)
Block(-6,2,6,contenttweaker:reinforced_concrete:0)
Block(-6,2,7,contenttweaker:reinforced_concrete:0)
Block(-6,2,8,contenttweaker:reinforced_concrete:0)
Block(-6,2,9,contenttweaker:reinforced_concrete:0)
Block(-6,3,-6,contenttweaker:reinforced_concrete:0)
Block(-6,3,-5,contenttweaker:reinforced_concrete:0)
Block(-6,3,-4,contenttweaker:reinforced_concrete:0)
Block(-6,3,-3,contenttweaker:reinforced_concrete:0)
Block(-6,3,-2,contenttweaker:reinforced_concrete:0)
Block(-6,3,-1,contenttweaker:reinforced_concrete:0)
Block(-6,3,0,contenttweaker:reinforced_concrete:0)
Block(-6,3,1,contenttweaker:reinforced_concrete:0)
Block(-6,3,2,contenttweaker:reinforced_concrete:0)
Block(-6,3,3,contenttweaker:reinforced_concrete:0)
Block(-6,3,4,contenttweaker:reinforced_concrete:0)
Block(-6,3,5,contenttweaker:reinforced_concrete:0)
Block(-6,3,6,contenttweaker:reinforced_concrete:0)
Block(-6,3,7,contenttweaker:reinforced_concrete:0)
Block(-6,3,8,contenttweaker:reinforced_concrete:0)
Block(-6,3,9,contenttweaker:reinforced_concrete:0)
Block(-6,4,-6,contenttweaker:reinforced_concrete:0)
Block(-6,4,-5,comforts:sleeping_bag_black:10)
Block(-6,4,-4,comforts:sleeping_bag_black:2)
Block(-6,4,-3,contenttweaker:reinforced_concrete:0)
Block(-6,4,-2,comforts:sleeping_bag_black:0)
Block(-6,4,-1,comforts:sleeping_bag_black:8)
Block(-6,4,0,contenttweaker:reinforced_concrete:0)
Block(-6,4,1,inspirations:path:0)
Block(-6,4,2,AIR:0)
Block(-6,4,3,notreepunching:loose_rock/stone:0)
Block(-6,4,4,inspirations:path:0)
Block(-6,4,5,AIR:0)
Block(-6,4,6,quark:iron_plate_stairs:2)
Block(-6,4,7,contenttweaker:reinforced_concrete:0)
Block(-6,4,8,contenttweaker:reinforced_concrete:0)
Block(-6,4,9,contenttweaker:reinforced_concrete:0)
Block(-6,5,-6,contenttweaker:reinforced_concrete:0)
Block(-6,5,-5,WOOD_STEP:13)
Block(-6,5,-4,WOOD_STEP:13)
Block(-6,5,-3,contenttweaker:reinforced_concrete:0)
Block(-6,5,-2,WOOD_STEP:13)
Block(-6,5,-1,WOOD_STEP:13)
Block(-6,5,0,CONCRETE:0)
Block(-6,5,1,AIR:0)
Block(-6,5,2,AIR:0)
Block(-6,5,3,AIR:0)
Block(-6,5,4,AIR:0)
Block(-6,5,5,AIR:0)
Block(-6,5,6,AIR:0)
Block(-6,5,7,quark:iron_plate_stairs:2)
Block(-6,5,8,contenttweaker:reinforced_concrete:0)
Block(-6,5,9,contenttweaker:reinforced_concrete:0)
Block(-6,6,-6,contenttweaker:reinforced_concrete:0)
RandomBlock(-6,6,-5,variedcommodities:crate:5,5,charm:crate_sealed:5,100)
Block(-6,6,-4,AIR:0)
Block(-6,6,-3,contenttweaker:reinforced_concrete:0)
Block(-6,6,-2,WEB:0)
Block(-6,6,-1,WEB:0)
Block(-6,6,0,contenttweaker:reinforced_concrete:0)
Block(-6,6,1,WALL_BANNER:5,f_bunker_mid/2-banner.nbt)
Block(-6,6,2,WALL_BANNER:5,f_bunker_mid/3-banner.nbt)
Block(-6,6,3,WALL_BANNER:5,f_bunker_mid/4-banner.nbt)
Block(-6,6,4,WALL_BANNER:5,f_bunker_mid/5-banner.nbt)
Block(-6,6,5,AIR:0)
Block(-6,6,6,AIR:0)
Block(-6,6,7,AIR:0)
Block(-6,6,8,AIR:0)
Block(-6,6,9,contenttweaker:reinforced_concrete:0)
Block(-6,7,-6,contenttweaker:reinforced_concrete:0)
Block(-6,7,-5,contenttweaker:reinforced_concrete:0)
Block(-6,7,-4,contenttweaker:reinforced_concrete:0)
Block(-6,7,-3,contenttweaker:reinforced_concrete:0)
Block(-6,7,-2,contenttweaker:reinforced_concrete:0)
Block(-6,7,-1,contenttweaker:reinforced_concrete:0)
Block(-6,7,0,contenttweaker:reinforced_concrete:0)
Block(-6,7,1,WEB:0)
Block(-6,7,2,WEB:0)
Block(-6,7,3,AIR:0)
Block(-6,7,4,AIR:0)
Block(-6,7,5,AIR:0)
Block(-6,7,6,AIR:0)
Block(-6,7,7,AIR:0)
Block(-6,7,8,AIR:0)
Block(-6,7,9,contenttweaker:reinforced_concrete:0)
Block(-6,8,-6,contenttweaker:reinforced_concrete:0)
Block(-6,8,-5,contenttweaker:reinforced_concrete:0)
Block(-6,8,-4,contenttweaker:reinforced_concrete:0)
Block(-6,8,-3,contenttweaker:reinforced_concrete:0)
Block(-6,8,-2,contenttweaker:reinforced_concrete:0)
Block(-6,8,-1,contenttweaker:reinforced_concrete:0)
Block(-6,8,0,contenttweaker:reinforced_concrete:0)
Block(-6,8,1,contenttweaker:reinforced_concrete:0)
Block(-6,8,2,contenttweaker:reinforced_concrete:0)
Block(-6,8,3,contenttweaker:reinforced_concrete:0)
Block(-6,8,4,contenttweaker:reinforced_concrete:0)
Block(-6,8,5,contenttweaker:reinforced_concrete:0)
Block(-6,8,6,AIR:0)
Block(-6,8,7,AIR:0)
Block(-6,8,8,AIR:0)
Block(-6,8,9,contenttweaker:reinforced_concrete:0)
Block(-6,9,-6,contenttweaker:reinforced_concrete:0)
Block(-6,9,-5,contenttweaker:reinforced_concrete:0)
Block(-6,9,-4,contenttweaker:reinforced_concrete:0)
Block(-6,9,-3,contenttweaker:reinforced_concrete:0)
Block(-6,9,-2,contenttweaker:reinforced_concrete:0)
Block(-6,9,-1,contenttweaker:reinforced_concrete:0)
Block(-6,9,0,REDSTONE_WIRE:6)
Block(-6,9,1,REDSTONE_WIRE:5)
Block(-6,9,2,PISTON_STICKY_BASE:9)
Block(-6,9,3,contenttweaker:reinforced_concrete:0)
Block(-6,9,4,contenttweaker:reinforced_concrete:0)
Block(-6,9,5,contenttweaker:reinforced_concrete:0)
Block(-6,9,6,WEB:0)
Block(-6,9,7,AIR:0)
Block(-6,9,8,AIR:0)
Block(-6,9,9,contenttweaker:reinforced_concrete:0)
Block(-6,10,-6,contenttweaker:reinforced_concrete:0)
Block(-6,10,-5,contenttweaker:reinforced_concrete:0)
Block(-6,10,-4,contenttweaker:reinforced_concrete:0)
Block(-6,10,-3,contenttweaker:reinforced_concrete:0)
Block(-6,10,-2,contenttweaker:reinforced_concrete:0)
Block(-6,10,-1,contenttweaker:reinforced_concrete:0)
Block(-6,10,0,contenttweaker:reinforced_concrete:0)
Block(-6,10,1,contenttweaker:reinforced_concrete:0)
Block(-6,10,2,PISTON_MOVING_PIECE:9)
Block(-6,10,3,contenttweaker:reinforced_concrete:0)
Block(-6,10,4,contenttweaker:reinforced_concrete:0)
Block(-6,10,5,contenttweaker:reinforced_concrete:0)
Block(-6,10,6,contenttweaker:reinforced_concrete:0)
Block(-6,10,7,contenttweaker:reinforced_concrete:0)
Block(-6,10,8,contenttweaker:reinforced_concrete:0)
Block(-6,10,9,contenttweaker:reinforced_concrete:0)
Block(-6,11,-6,contenttweaker:reinforced_concrete:0)
Block(-6,11,-5,contenttweaker:reinforced_concrete:0)
Block(-6,11,-4,contenttweaker:reinforced_concrete:0)
Block(-6,11,-3,contenttweaker:reinforced_concrete:0)
Block(-6,11,-2,WEB:0)
Block(-6,11,-1,inspirations:path:0)
Block(-6,11,0,AIR:0)
Block(-6,11,1,AIR:0)
Block(-6,11,2,contenttweaker:iron_plate_reinforced:0)
Block(-6,11,3,AIR:0)
Block(-6,11,4,AIR:0)
Block(-6,11,5,inspirations:path:0)
Block(-6,11,6,AIR:0)
Block(-6,11,7,AIR:0)
Block(-6,11,8,WEB:0)
Block(-6,11,9,contenttweaker:reinforced_concrete:0)
Block(-6,12,-6,contenttweaker:reinforced_concrete:0)
Block(-6,12,-5,REDSTONE_WIRE:13)
Block(-6,12,-4,contenttweaker:reinforced_concrete:0)
Block(-6,12,-3,contenttweaker:reinforced_concrete:0)
Block(-6,12,-2,WEB:0)
Block(-6,12,-1,variedcommodities:wall_banner,f_bunker_mid/6-variedcommodities_wall_banner.nbt)
Block(-6,12,0,AIR:0)
Block(-6,12,1,AIR:0)
Block(-6,12,2,contenttweaker:iron_plate_reinforced:0)
Block(-6,12,3,AIR:0)
Block(-6,12,4,AIR:0)
Block(-6,12,5,AIR:0)
Block(-6,12,6,AIR:0)
Block(-6,12,7,AIR:0)
Block(-6,12,8,AIR:0)
Block(-6,12,9,contenttweaker:reinforced_concrete:0)
Block(-6,13,-6,contenttweaker:reinforced_concrete:0)
Block(-6,13,-5,AIR:0)
Block(-6,13,-4,REDSTONE_WIRE:14)
Block(-6,13,-3,contenttweaker:reinforced_concrete:0)
Block(-6,13,-2,quark:grate:0)
Block(-6,13,-1,quark:grate:0)
Block(-6,13,0,quark:grate:0)
Block(-6,13,1,contenttweaker:reinforced_concrete:0)
Block(-6,13,2,PISTON_MOVING_PIECE:8)
Block(-6,13,3,contenttweaker:reinforced_concrete:0)
Block(-6,13,4,quark:grate:0)
Block(-6,13,5,contenttweaker:reinforced_concrete:0)
Block(-6,13,6,quark:grate:0)
Block(-6,13,7,quark:grate:0)
Block(-6,13,8,quark:grate:0)
Block(-6,13,9,contenttweaker:reinforced_concrete:0)
Block(-6,14,-6,contenttweaker:reinforced_concrete:0)
Block(-6,14,-5,AIR:0)
Block(-6,14,-4,AIR:0)
Block(-6,14,-3,REDSTONE_WIRE:15)
Block(-6,14,-2,contenttweaker:reinforced_concrete:0)
Block(-6,14,-1,contenttweaker:reinforced_concrete:0)
Block(-6,14,0,contenttweaker:reinforced_concrete:0)
Block(-6,14,1,contenttweaker:reinforced_concrete:0)
Block(-6,14,2,PISTON_STICKY_BASE:8)
Block(-6,14,3,contenttweaker:reinforced_concrete:0)
Block(-6,14,4,lycanitesmobs:ashencrystal:0)
Block(-6,14,5,contenttweaker:reinforced_concrete:0)
Block(-6,14,6,contenttweaker:reinforced_concrete:0)
Block(-6,14,7,contenttweaker:reinforced_concrete:0)
Block(-6,14,8,contenttweaker:reinforced_concrete:0)
Block(-6,14,9,contenttweaker:reinforced_concrete:0)
Block(-6,15,-6,contenttweaker:reinforced_concrete:0)
Block(-6,15,-5,contenttweaker:reinforced_concrete:0)
Block(-6,15,-4,AIR:0)
Block(-6,15,-3,AIR:0)
Block(-6,15,-2,REDSTONE_WIRE:14)
Block(-6,15,-1,REDSTONE_WIRE:13)
Block(-6,15,0,REDSTONE_WIRE:12)
Block(-6,15,1,REDSTONE_WIRE:11)
Block(-6,15,2,contenttweaker:reinforced_concrete:0)
Block(-6,15,3,contenttweaker:reinforced_concrete:0)
Block(-6,15,4,contenttweaker:reinforced_concrete:0)
Block(-6,15,5,contenttweaker:reinforced_concrete:0)
Block(-6,15,6,contenttweaker:reinforced_concrete:0)
Block(-6,15,7,contenttweaker:reinforced_concrete:0)
Block(-6,15,8,contenttweaker:reinforced_concrete:0)
Block(-6,15,9,contenttweaker:reinforced_concrete:0)
Block(-6,16,-6,contenttweaker:reinforced_concrete:0)
Block(-6,16,-5,contenttweaker:reinforced_concrete:0)
Block(-6,16,-4,contenttweaker:reinforced_concrete:0)
Block(-6,16,-3,contenttweaker:reinforced_concrete:0)
Block(-6,16,-2,contenttweaker:reinforced_concrete:0)
Block(-6,16,-1,contenttweaker:reinforced_concrete:0)
Block(-6,16,0,contenttweaker:reinforced_concrete:0)
Block(-6,16,1,contenttweaker:reinforced_concrete:0)
Block(-6,16,2,contenttweaker:reinforced_concrete:0)
Block(-5,0,5,contenttweaker:reinforced_concrete:0)
Block(-5,0,6,contenttweaker:reinforced_concrete:0)
Block(-5,0,7,contenttweaker:reinforced_concrete:0)
Block(-5,0,8,contenttweaker:reinforced_concrete:0)
Block(-5,0,9,contenttweaker:reinforced_concrete:0)
Block(-5,1,5,contenttweaker:reinforced_concrete:0)
Block(-5,1,6,contenttweaker:reinforced_concrete:0)
Block(-5,1,7,contenttweaker:reinforced_concrete:0)
Block(-5,1,8,contenttweaker:reinforced_concrete:0)
Block(-5,1,9,contenttweaker:reinforced_concrete:0)
Block(-5,2,5,contenttweaker:reinforced_concrete:0)
Block(-5,2,6,contenttweaker:reinforced_concrete:0)
Block(-5,2,7,contenttweaker:reinforced_concrete:0)
Block(-5,2,8,contenttweaker:reinforced_concrete:0)
Block(-5,2,9,contenttweaker:reinforced_concrete:0)
Block(-5,3,-6,contenttweaker:reinforced_concrete:0)
Block(-5,3,-5,contenttweaker:reinforced_concrete:0)
Block(-5,3,-4,contenttweaker:reinforced_concrete:0)
Block(-5,3,-3,contenttweaker:reinforced_concrete:0)
Block(-5,3,-2,contenttweaker:reinforced_concrete:0)
Block(-5,3,-1,contenttweaker:reinforced_concrete:0)
Block(-5,3,0,contenttweaker:reinforced_concrete:0)
Block(-5,3,1,contenttweaker:reinforced_concrete:0)
Block(-5,3,2,contenttweaker:reinforced_concrete:0)
Block(-5,3,3,contenttweaker:reinforced_concrete:0)
Block(-5,3,4,contenttweaker:reinforced_concrete:0)
Block(-5,3,5,contenttweaker:reinforced_concrete:0)
Block(-5,3,6,contenttweaker:reinforced_concrete:0)
Block(-5,3,7,contenttweaker:reinforced_concrete:0)
Block(-5,3,8,contenttweaker:reinforced_concrete:0)
Block(-5,3,9,contenttweaker:reinforced_concrete:0)
Block(-5,4,-6,contenttweaker:reinforced_concrete:0)
Block(-5,4,-5,AIR:0)
Block(-5,4,-4,AIR:0)
Block(-5,4,-3,AIR:0)
Block(-5,4,-2,AIR:0)
Block(-5,4,-1,AIR:0)
Block(-5,4,0,DARK_OAK_DOOR:3)
Block(-5,4,1,AIR:0)
Block(-5,4,2,CARPET:14)
Block(-5,4,3,CARPET:14)
Block(-5,4,4,CARPET:14)
Block(-5,4,5,contenttweaker:reinforced_concrete:0)
Block(-5,4,6,contenttweaker:reinforced_concrete:0)
Block(-5,4,7,contenttweaker:reinforced_concrete:0)
Block(-5,4,8,contenttweaker:reinforced_concrete:0)
Block(-5,4,9,contenttweaker:reinforced_concrete:0)
Block(-5,5,-6,contenttweaker:reinforced_concrete:0)
Block(-5,5,-5,WALL_BANNER:5,f_bunker_mid/7-banner.nbt)
Block(-5,5,-4,WALL_BANNER:4,f_bunker_mid/8-banner.nbt)
Block(-5,5,-3,AIR:0)
Block(-5,5,-2,WALL_BANNER:4,f_bunker_mid/9-banner.nbt)
Block(-5,5,-1,WALL_BANNER:5,f_bunker_mid/10-banner.nbt)
Block(-5,5,0,DARK_OAK_DOOR:8)
Block(-5,5,1,AIR:0)
Block(-5,5,2,AIR:0)
Block(-5,5,3,AIR:0)
Block(-5,5,4,AIR:0)
Block(-5,5,5,CONCRETE:0)
Block(-5,5,6,CONCRETE:0)
Block(-5,5,7,CONCRETE:0)
Block(-5,5,8,CONCRETE:0)
Block(-5,5,9,contenttweaker:reinforced_concrete:0)
Block(-5,6,-6,contenttweaker:reinforced_concrete:0)
Block(-5,6,-5,variedcommodities:lamp_unlit,f_bunker_mid/11-variedcommodities_lamp.nbt)
Block(-5,6,-4,AIR:0)
Block(-5,6,-3,quark:grate:0)
Block(-5,6,-2,AIR:0)
Block(-5,6,-1,AIR:0)
Block(-5,6,0,contenttweaker:reinforced_concrete:0)
Block(-5,6,1,AIR:0)
Block(-5,6,2,AIR:0)
Block(-5,6,3,AIR:0)
Block(-5,6,4,AIR:0)
Block(-5,6,5,contenttweaker:reinforced_concrete:0)
Block(-5,6,6,contenttweaker:reinforced_concrete:0)
Block(-5,6,7,contenttweaker:reinforced_concrete:0)
Block(-5,6,8,quark:iron_plate_stairs:0)
Block(-5,6,9,contenttweaker:reinforced_concrete:0)
Block(-5,7,-6,contenttweaker:reinforced_concrete:0)
Block(-5,7,-5,AIR:0)
Block(-5,7,-4,AIR:0)
Block(-5,7,-3,DISPENSER:8,f_bunker_mid/12-dispenser.nbt)
Block(-5,7,-2,STEP:8)
Block(-5,7,-1,STEP:8)
Block(-5,7,0,STEP:8)
Block(-5,7,1,STEP:8)
Block(-5,7,2,AIR:0)
Block(-5,7,3,rustic:iron_lattice:0)
Block(-5,7,4,AIR:0)
Block(-5,7,5,contenttweaker:reinforced_concrete:0)
Block(-5,7,6,contenttweaker:reinforced_concrete:0)
Block(-5,7,7,contenttweaker:reinforced_concrete:0)
Block(-5,7,8,AIR:0)
Block(-5,7,9,contenttweaker:reinforced_concrete:0)
Block(-5,8,-6,contenttweaker:reinforced_concrete:0)
Block(-5,8,-5,contenttweaker:reinforced_concrete:0)
Block(-5,8,-4,contenttweaker:reinforced_concrete:0)
Block(-5,8,-3,contenttweaker:reinforced_concrete:0)
Block(-5,8,-2,contenttweaker:reinforced_concrete:0)
Block(-5,8,-1,contenttweaker:reinforced_concrete:0)
Block(-5,8,0,contenttweaker:reinforced_concrete:0)
Block(-5,8,1,contenttweaker:reinforced_concrete:0)
Block(-5,8,2,contenttweaker:reinforced_concrete:0)
Block(-5,8,3,contenttweaker:reinforced_concrete:0)
Block(-5,8,4,contenttweaker:reinforced_concrete:0)
Block(-5,8,5,contenttweaker:reinforced_concrete:0)
Block(-5,8,6,contenttweaker:reinforced_concrete:0)
Block(-5,8,7,contenttweaker:reinforced_concrete:0)
Block(-5,8,8,AIR:0)
Block(-5,8,9,contenttweaker:reinforced_concrete:0)
Block(-5,9,-6,contenttweaker:reinforced_concrete:0)
Block(-5,9,-5,contenttweaker:reinforced_concrete:0)
Block(-5,9,-4,contenttweaker:reinforced_concrete:0)
Block(-5,9,-3,REDSTONE_WIRE:10)
Block(-5,9,-2,REDSTONE_WIRE:9)
Block(-5,9,-1,REDSTONE_WIRE:8)
Block(-5,9,0,REDSTONE_WIRE:7)
Block(-5,9,1,contenttweaker:reinforced_concrete:0)
Block(-5,9,2,PISTON_STICKY_BASE:9)
Block(-5,9,3,contenttweaker:reinforced_concrete:0)
Block(-5,9,4,contenttweaker:reinforced_concrete:0)
Block(-5,9,5,contenttweaker:reinforced_concrete:0)
Block(-5,9,6,contenttweaker:reinforced_concrete:0)
Block(-5,9,7,contenttweaker:reinforced_concrete:0)
Block(-5,9,8,AIR:0)
Block(-5,9,9,contenttweaker:reinforced_concrete:0)
Block(-5,10,-6,contenttweaker:reinforced_concrete:0)
Block(-5,10,-5,contenttweaker:reinforced_concrete:0)
Block(-5,10,-4,REDSTONE_WIRE:11)
Block(-5,10,-3,AIR:0)
Block(-5,10,-2,contenttweaker:reinforced_concrete:0)
Block(-5,10,-1,contenttweaker:reinforced_concrete:0)
Block(-5,10,0,contenttweaker:reinforced_concrete:0)
Block(-5,10,1,contenttweaker:reinforced_concrete:0)
Block(-5,10,2,PISTON_MOVING_PIECE:9)
Block(-5,10,3,contenttweaker:reinforced_concrete:0)
Block(-5,10,4,contenttweaker:reinforced_concrete:0)
Block(-5,10,5,contenttweaker:reinforced_concrete:0)
Block(-5,10,6,contenttweaker:reinforced_concrete:0)
Block(-5,10,7,contenttweaker:reinforced_concrete:0)
Block(-5,10,8,contenttweaker:reinforced_concrete:0)
Block(-5,10,9,contenttweaker:reinforced_concrete:0)
Block(-5,11,-6,contenttweaker:reinforced_concrete:0)
Block(-5,11,-5,REDSTONE_WIRE:12)
Block(-5,11,-4,AIR:0)
Block(-5,11,-3,contenttweaker:reinforced_concrete:0)
Block(-5,11,-2,AIR:0)
Block(-5,11,-1,AIR:0)
Block(-5,11,0,AIR:0)
Block(-5,11,1,AIR:0)
Block(-5,11,2,contenttweaker:iron_plate_reinforced:0)
Block(-5,11,3,AIR:0)
Block(-5,11,4,inspirations:path:0)
Block(-5,11,5,AIR:0)
Block(-5,11,6,notreepunching:loose_rock/stone:0)
Block(-5,11,7,AIR:0)
Block(-5,11,8,AIR:0)
Block(-5,11,9,contenttweaker:reinforced_concrete:0)
Block(-5,12,-6,contenttweaker:reinforced_concrete:0)
Block(-5,12,-5,AIR:0)
Block(-5,12,-4,AIR:0)
Block(-5,12,-3,contenttweaker:reinforced_concrete:0)
Block(-5,12,-2,AIR:0)
Block(-5,12,-1,AIR:0)
Block(-5,12,0,AIR:0)
Block(-5,12,1,AIR:0)
Block(-5,12,2,contenttweaker:iron_plate_reinforced:0)
Block(-5,12,3,AIR:0)
Block(-5,12,4,AIR:0)
Block(-5,12,5,AIR:0)
Block(-5,12,6,AIR:0)
Block(-5,12,7,AIR:0)
Block(-5,12,8,AIR:0)
Block(-5,12,9,contenttweaker:reinforced_concrete:0)
Block(-5,13,-6,contenttweaker:reinforced_concrete:0)
Block(-5,13,-5,AIR:0)
Block(-5,13,-4,AIR:0)
Block(-5,13,-3,contenttweaker:reinforced_concrete:0)
Block(-5,13,-2,quark:grate:0)
Block(-5,13,-1,quark:grate:0)
Block(-5,13,0,quark:grate:0)
Block(-5,13,1,contenttweaker:reinforced_concrete:0)
Block(-5,13,2,PISTON_MOVING_PIECE:8)
Block(-5,13,3,contenttweaker:reinforced_concrete:0)
Block(-5,13,4,quark:grate:0)
Block(-5,13,5,contenttweaker:reinforced_concrete:0)
Block(-5,13,6,quark:grate:0)
Block(-5,13,7,quark:grate:0)
Block(-5,13,8,quark:grate:0)
Block(-5,13,9,contenttweaker:reinforced_concrete:0)
Block(-5,14,-6,contenttweaker:reinforced_concrete:0)
Block(-5,14,-5,AIR:0)
Block(-5,14,-4,AIR:0)
Block(-5,14,-3,REDSTONE_TORCH_ON:2)
Block(-5,14,-2,contenttweaker:reinforced_concrete:0)
Block(-5,14,-1,contenttweaker:reinforced_concrete:0)
Block(-5,14,0,contenttweaker:reinforced_concrete:0)
Block(-5,14,1,contenttweaker:reinforced_concrete:0)
Block(-5,14,2,PISTON_STICKY_BASE:8)
Block(-5,14,3,contenttweaker:reinforced_concrete:0)
Block(-5,14,4,lycanitesmobs:ashencrystal:0)
Block(-5,14,5,contenttweaker:reinforced_concrete:0)
Block(-5,14,6,contenttweaker:reinforced_concrete:0)
Block(-5,14,7,contenttweaker:reinforced_concrete:0)
Block(-5,14,8,contenttweaker:reinforced_concrete:0)
Block(-5,14,9,contenttweaker:reinforced_concrete:0)
Block(-5,15,-6,contenttweaker:reinforced_concrete:0)
Block(-5,15,-5,contenttweaker:reinforced_concrete:0)
Block(-5,15,-4,AIR:0)
Block(-5,15,-3,contenttweaker:reinforced_concrete:0)
Block(-5,15,-2,contenttweaker:reinforced_concrete:0)
Block(-5,15,-1,contenttweaker:reinforced_concrete:0)
Block(-5,15,0,REDSTONE_WIRE:11)
Block(-5,15,1,REDSTONE_WIRE:10)
Block(-5,15,2,contenttweaker:reinforced_concrete:0)
Block(-5,15,3,contenttweaker:reinforced_concrete:0)
Block(-5,15,4,contenttweaker:reinforced_concrete:0)
Block(-5,15,5,contenttweaker:reinforced_concrete:0)
Block(-5,15,6,contenttweaker:reinforced_concrete:0)
Block(-5,15,7,contenttweaker:reinforced_concrete:0)
Block(-5,15,8,contenttweaker:reinforced_concrete:0)
Block(-5,15,9,contenttweaker:reinforced_concrete:0)
Block(-5,16,-6,contenttweaker:reinforced_concrete:0)
Block(-5,16,-5,contenttweaker:reinforced_concrete:0)
Block(-5,16,-4,contenttweaker:reinforced_concrete:0)
Block(-5,16,-3,contenttweaker:reinforced_concrete:0)
Block(-5,16,-2,contenttweaker:reinforced_concrete:0)
Block(-5,16,-1,contenttweaker:reinforced_concrete:0)
Block(-5,16,0,contenttweaker:reinforced_concrete:0)
Block(-5,16,1,contenttweaker:reinforced_concrete:0)
Block(-5,16,2,contenttweaker:reinforced_concrete:0)
Block(-4,0,5,contenttweaker:reinforced_concrete:0)
Block(-4,0,6,contenttweaker:reinforced_concrete:0)
Block(-4,0,7,contenttweaker:reinforced_concrete:0)
Block(-4,0,8,contenttweaker:reinforced_concrete:0)
Block(-4,0,9,contenttweaker:reinforced_concrete:0)
Block(-4,1,5,contenttweaker:reinforced_concrete:0)
Block(-4,1,6,contenttweaker:reinforced_concrete:0)
Block(-4,1,7,contenttweaker:reinforced_concrete:0)
Block(-4,1,8,contenttweaker:reinforced_concrete:0)
Block(-4,1,9,contenttweaker:reinforced_concrete:0)
Block(-4,2,5,contenttweaker:reinforced_concrete:0)
Block(-4,2,6,contenttweaker:reinforced_concrete:0)
Block(-4,2,7,contenttweaker:reinforced_concrete:0)
Block(-4,2,8,contenttweaker:reinforced_concrete:0)
Block(-4,2,9,contenttweaker:reinforced_concrete:0)
Block(-4,3,-6,contenttweaker:reinforced_concrete:0)
Block(-4,3,-5,contenttweaker:reinforced_concrete:0)
Block(-4,3,-4,contenttweaker:reinforced_concrete:0)
Block(-4,3,-3,contenttweaker:reinforced_concrete:0)
Block(-4,3,-2,contenttweaker:reinforced_concrete:0)
Block(-4,3,-1,contenttweaker:reinforced_concrete:0)
Block(-4,3,0,contenttweaker:reinforced_concrete:0)
Block(-4,3,1,contenttweaker:reinforced_concrete:0)
Block(-4,3,2,contenttweaker:reinforced_concrete:0)
Block(-4,3,3,contenttweaker:reinforced_concrete:0)
Block(-4,3,4,contenttweaker:reinforced_concrete:0)
Block(-4,3,5,contenttweaker:reinforced_concrete:0)
Block(-4,3,6,contenttweaker:reinforced_concrete:0)
Block(-4,3,7,contenttweaker:reinforced_concrete:0)
Block(-4,3,8,contenttweaker:reinforced_concrete:0)
Block(-4,3,9,contenttweaker:reinforced_concrete:0)
Block(-4,4,-6,contenttweaker:reinforced_concrete:0)
Block(-4,4,-5,comforts:sleeping_bag_black:10)
Block(-4,4,-4,comforts:sleeping_bag_black:2)
Block(-4,4,-3,contenttweaker:reinforced_concrete:0)
Block(-4,4,-2,comforts:sleeping_bag_black:10)
Block(-4,4,-1,comforts:sleeping_bag_black:2)
Block(-4,4,0,contenttweaker:reinforced_concrete:0)
Block(-4,4,1,AIR:0)
Block(-4,4,2,CARPET:14)
Block(-4,4,3,CARPET:14)
Block(-4,4,4,CARPET:14)
Block(-4,4,5,DARK_OAK_DOOR:1)
Block(-4,4,6,AIR:0)
Block(-4,4,7,inspirations:path:0)
Block(-4,4,8,variedcommodities:stool:5,f_bunker_mid/13-variedcommodities_stool.nbt)
Block(-4,4,9,contenttweaker:reinforced_concrete:0)
Block(-4,5,-6,contenttweaker:reinforced_concrete:0)
Block(-4,5,-5,WOOD_STEP:13)
Block(-4,5,-4,WOOD_STEP:13)
Block(-4,5,-3,contenttweaker:reinforced_concrete:0)
Block(-4,5,-2,WOOD_STEP:13)
Block(-4,5,-1,WOOD_STEP:13)
Block(-4,5,0,CONCRETE:0)
Block(-4,5,1,AIR:0)
Block(-4,5,2,AIR:0)
Block(-4,5,3,AIR:0)
Block(-4,5,4,AIR:0)
Block(-4,5,5,DARK_OAK_DOOR:9)
Block(-4,5,6,AIR:0)
Block(-4,5,7,AIR:0)
Block(-4,5,8,AIR:0)
Block(-4,5,9,contenttweaker:reinforced_concrete:0)
Block(-4,6,-6,contenttweaker:reinforced_concrete:0)
Block(-4,6,-5,WEB:0)
RandomBlock(-4,6,-4,variedcommodities:crate:5,5,charm:crate_sealed:5,100)
Block(-4,6,-3,contenttweaker:reinforced_concrete:0)
Block(-4,6,-2,WEB:0)
RandomBlock(-4,6,-1,variedcommodities:crate:5,5,charm:crate_sealed:5,100)
Block(-4,6,0,contenttweaker:reinforced_concrete:0)
Block(-4,6,1,AIR:0)
Block(-4,6,2,AIR:0)
Block(-4,6,3,AIR:0)
Block(-4,6,4,AIR:0)
Block(-4,6,5,contenttweaker:reinforced_concrete:0)
Block(-4,6,6,contenttweaker:reinforced_concrete:0)
Block(-4,6,7,contenttweaker:reinforced_concrete:0)
Block(-4,6,8,contenttweaker:reinforced_concrete:0)
Block(-4,6,9,contenttweaker:reinforced_concrete:0)
Block(-4,7,-6,contenttweaker:reinforced_concrete:0)
Block(-4,7,-5,contenttweaker:reinforced_concrete:0)
Block(-4,7,-4,contenttweaker:reinforced_concrete:0)
Block(-4,7,-3,contenttweaker:reinforced_concrete:0)
Block(-4,7,-2,contenttweaker:reinforced_concrete:0)
Block(-4,7,-1,contenttweaker:reinforced_concrete:0)
Block(-4,7,0,contenttweaker:reinforced_concrete:0)
Block(-4,7,1,STEP:8)
Block(-4,7,2,AIR:0)
Block(-4,7,3,AIR:0)
Block(-4,7,4,WEB:0)
Block(-4,7,5,contenttweaker:reinforced_concrete:0)
Block(-4,7,6,contenttweaker:reinforced_concrete:0)
Block(-4,7,7,contenttweaker:reinforced_concrete:0)
Block(-4,7,8,quark:iron_plate_stairs:0)
Block(-4,7,9,contenttweaker:reinforced_concrete:0)
Block(-4,8,-6,contenttweaker:reinforced_concrete:0)
Block(-4,8,-5,contenttweaker:reinforced_concrete:0)
Block(-4,8,-4,contenttweaker:reinforced_concrete:0)
Block(-4,8,-3,contenttweaker:reinforced_concrete:0)
Block(-4,8,-2,contenttweaker:reinforced_concrete:0)
Block(-4,8,-1,contenttweaker:reinforced_concrete:0)
Block(-4,8,0,contenttweaker:reinforced_concrete:0)
Block(-4,8,1,contenttweaker:reinforced_concrete:0)
Block(-4,8,2,contenttweaker:reinforced_concrete:0)
Block(-4,8,3,contenttweaker:reinforced_concrete:0)
Block(-4,8,4,contenttweaker:reinforced_concrete:0)
Block(-4,8,5,contenttweaker:reinforced_concrete:0)
Block(-4,8,6,contenttweaker:reinforced_concrete:0)
Block(-4,8,7,contenttweaker:reinforced_concrete:0)
Block(-4,8,8,AIR:0)
Block(-4,8,9,contenttweaker:reinforced_concrete:0)
Block(-4,9,-6,contenttweaker:reinforced_concrete:0)
Block(-4,9,-5,contenttweaker:reinforced_concrete:0)
Block(-4,9,-4,contenttweaker:reinforced_concrete:0)
Block(-4,9,-3,contenttweaker:reinforced_concrete:0)
Block(-4,9,-2,contenttweaker:reinforced_concrete:0)
Block(-4,9,-1,contenttweaker:reinforced_concrete:0)
Block(-4,9,0,REDSTONE_WIRE:6)
Block(-4,9,1,contenttweaker:reinforced_concrete:0)
Block(-4,9,2,REDSTONE_WIRE:2)
Block(-4,9,3,contenttweaker:reinforced_concrete:0)
Block(-4,9,4,contenttweaker:reinforced_concrete:0)
Block(-4,9,5,contenttweaker:reinforced_concrete:0)
Block(-4,9,6,contenttweaker:reinforced_concrete:0)
Block(-4,9,7,contenttweaker:reinforced_concrete:0)
Block(-4,9,8,AIR:0)
Block(-4,9,9,contenttweaker:reinforced_concrete:0)
Block(-4,10,-6,contenttweaker:reinforced_concrete:0)
Block(-4,10,-5,contenttweaker:reinforced_concrete:0)
Block(-4,10,-4,contenttweaker:reinforced_concrete:0)
Block(-4,10,-3,contenttweaker:reinforced_concrete:0)
Block(-4,10,-2,contenttweaker:reinforced_concrete:0)
Block(-4,10,-1,contenttweaker:reinforced_concrete:0)
Block(-4,10,0,contenttweaker:reinforced_concrete:0)
Block(-4,10,1,contenttweaker:reinforced_concrete:0)
Block(-4,10,2,contenttweaker:reinforced_concrete:0)
Block(-4,10,3,contenttweaker:reinforced_concrete:0)
Block(-4,10,4,contenttweaker:reinforced_concrete:0)
Block(-4,10,5,contenttweaker:reinforced_concrete:0)
Block(-4,10,6,contenttweaker:reinforced_concrete:0)
Block(-4,10,7,contenttweaker:reinforced_concrete:0)
Block(-4,10,8,contenttweaker:reinforced_concrete:0)
Block(-4,10,9,contenttweaker:reinforced_concrete:0)
Block(-4,11,-6,contenttweaker:reinforced_concrete:0)
Block(-4,11,-5,contenttweaker:reinforced_concrete:0)
Block(-4,11,-4,CONCRETE:14)
Block(-4,11,-3,CONCRETE:14)
Block(-4,11,-2,AIR:0)
Block(-4,11,-1,notreepunching:loose_rock/stone:0)
Block(-4,11,0,inspirations:path:0)
Block(-4,11,1,contenttweaker:reinforced_concrete:0)
Block(-4,11,2,contenttweaker:reinforced_concrete:0)
Block(-4,11,3,contenttweaker:reinforced_concrete:0)
Block(-4,11,4,contenttweaker:reinforced_concrete:0)
Block(-4,11,5,contenttweaker:reinforced_concrete:0)
Block(-4,11,6,AIR:0)
Block(-4,11,7,AIR:0)
Block(-4,11,8,AIR:0)
Block(-4,11,9,contenttweaker:reinforced_concrete:0)
Block(-4,12,-6,contenttweaker:reinforced_concrete:0)
Block(-4,12,-5,contenttweaker:reinforced_concrete:0)
Block(-4,12,-4,REDSTONE_TORCH_ON:4)
Block(-4,12,-3,contenttweaker:iron_plate_reinforced:0)
Block(-4,12,-2,quark:iron_button:3)
Block(-4,12,-1,AIR:0)
Block(-4,12,0,AIR:0)
Block(-4,12,1,contenttweaker:reinforced_concrete:0)
Block(-4,12,2,contenttweaker:reinforced_concrete:0)
Block(-4,12,3,contenttweaker:reinforced_concrete:0)
Block(-4,12,4,contenttweaker:reinforced_concrete:0)
Block(-4,12,5,contenttweaker:reinforced_concrete:0)
Block(-4,12,6,AIR:0)
Block(-4,12,7,AIR:0)
Block(-4,12,8,AIR:0)
Block(-4,12,9,contenttweaker:reinforced_concrete:0)
Block(-4,13,-6,contenttweaker:reinforced_concrete:0)
Block(-4,13,-5,contenttweaker:reinforced_concrete:0)
Block(-4,13,-4,contenttweaker:reinforced_concrete:0)
Block(-4,13,-3,contenttweaker:reinforced_concrete:0)
Block(-4,13,-2,contentcreator:iron_plate_slab_reinforced:1)
Block(-4,13,-1,contentcreator:iron_plate_slab_reinforced:1)
Block(-4,13,0,contentcreator:iron_plate_slab_reinforced:1)
Block(-4,13,1,contenttweaker:reinforced_concrete:0)
Block(-4,13,2,contenttweaker:reinforced_concrete:0)
Block(-4,13,3,contenttweaker:reinforced_concrete:0)
Block(-4,13,4,contenttweaker:reinforced_concrete:0)
Block(-4,13,5,contenttweaker:reinforced_concrete:0)
Block(-4,13,6,contentcreator:iron_plate_slab_reinforced:1)
Block(-4,13,7,contentcreator:iron_plate_slab_reinforced:1)
Block(-4,13,8,contentcreator:iron_plate_slab_reinforced:1)
Block(-4,13,9,contenttweaker:reinforced_concrete:0)
Block(-4,14,-6,contenttweaker:reinforced_concrete:0)
Block(-4,14,-5,AIR:0)
Block(-4,14,-4,REDSTONE_TORCH_OFF:5)
Block(-4,14,-3,contenttweaker:reinforced_concrete:0)
Block(-4,14,-2,contenttweaker:reinforced_concrete:0)
Block(-4,14,-1,contenttweaker:reinforced_concrete:0)
Block(-4,14,0,contenttweaker:reinforced_concrete:0)
Block(-4,14,1,contenttweaker:reinforced_concrete:0)
Block(-4,14,2,contenttweaker:reinforced_concrete:0)
Block(-4,14,3,contenttweaker:reinforced_concrete:0)
Block(-4,14,4,contenttweaker:reinforced_concrete:0)
Block(-4,14,5,contenttweaker:reinforced_concrete:0)
Block(-4,14,6,contenttweaker:reinforced_concrete:0)
Block(-4,14,7,contenttweaker:reinforced_concrete:0)
Block(-4,14,8,contenttweaker:reinforced_concrete:0)
Block(-4,14,9,contenttweaker:reinforced_concrete:0)
Block(-4,15,-6,contenttweaker:reinforced_concrete:0)
Block(-4,15,-5,contenttweaker:reinforced_concrete:0)
Block(-4,15,-4,AIR:0)
Block(-4,15,-3,contenttweaker:reinforced_concrete:0)
Block(-4,15,-2,contenttweaker:reinforced_concrete:0)
Block(-4,15,-1,contenttweaker:reinforced_concrete:0)
Block(-4,15,0,contenttweaker:reinforced_concrete:0)
Block(-4,15,1,contenttweaker:reinforced_concrete:0)
Block(-4,15,2,contenttweaker:reinforced_concrete:0)
Block(-4,15,3,contenttweaker:reinforced_concrete:0)
Block(-4,15,4,contenttweaker:reinforced_concrete:0)
Block(-4,15,5,contenttweaker:reinforced_concrete:0)
Block(-4,15,6,contenttweaker:reinforced_concrete:0)
Block(-4,15,7,contenttweaker:reinforced_concrete:0)
Block(-4,15,8,contenttweaker:reinforced_concrete:0)
Block(-4,15,9,contenttweaker:reinforced_concrete:0)
Block(-4,16,-6,contenttweaker:reinforced_concrete:0)
Block(-4,16,-5,contenttweaker:reinforced_concrete:0)
Block(-4,16,-4,contenttweaker:reinforced_concrete:0)
Block(-4,16,-3,contenttweaker:reinforced_concrete:0)
Block(-4,16,-2,contenttweaker:reinforced_concrete:0)
Block(-4,16,-1,contenttweaker:reinforced_concrete:0)
Block(-4,16,0,contenttweaker:reinforced_concrete:0)
Block(-4,16,1,contenttweaker:reinforced_concrete:0)
Block(-4,16,2,contenttweaker:reinforced_concrete:0)
Block(-4,16,3,contenttweaker:reinforced_concrete:0)
Block(-4,16,4,contenttweaker:reinforced_concrete:0)
Block(-4,16,5,contenttweaker:reinforced_concrete:0)
Block(-4,16,7,contenttweaker:reinforced_concrete:0)
Block(-4,17,1,contenttweaker:reinforced_concrete:0)
Block(-4,17,2,contenttweaker:reinforced_concrete:0)
Block(-4,17,3,contenttweaker:reinforced_concrete:0)
Block(-4,17,4,contenttweaker:reinforced_concrete:0)
Block(-4,17,5,contenttweaker:reinforced_concrete:0)
Block(-4,17,7,contenttweaker:reinforced_concrete:0)
Block(-4,18,1,contenttweaker:reinforced_concrete:0)
Block(-4,18,2,contenttweaker:reinforced_concrete:0)
Block(-4,18,3,contenttweaker:reinforced_concrete:0)
Block(-4,18,4,contenttweaker:reinforced_concrete:0)
Block(-4,18,5,contenttweaker:reinforced_concrete:0)
Block(-4,18,7,contenttweaker:reinforced_concrete:0)
Block(-4,19,1,contenttweaker:reinforced_concrete:0)
Block(-4,19,2,contenttweaker:reinforced_concrete:0)
Block(-4,19,3,contenttweaker:reinforced_concrete:0)
Block(-4,19,4,contenttweaker:reinforced_concrete:0)
Block(-4,19,5,contenttweaker:reinforced_concrete:0)
Block(-4,19,7,contenttweaker:reinforced_concrete:0)
Block(-4,20,1,contenttweaker:reinforced_concrete:0)
Block(-4,20,2,contenttweaker:reinforced_concrete:0)
Block(-4,20,3,contenttweaker:reinforced_concrete:0)
Block(-4,20,4,contenttweaker:reinforced_concrete:0)
Block(-4,20,5,contenttweaker:reinforced_concrete:0)
Block(-4,20,7,contenttweaker:reinforced_concrete:0)
Block(-4,21,1,contenttweaker:reinforced_concrete:0)
Block(-4,21,2,contenttweaker:reinforced_concrete:0)
Block(-4,21,3,contenttweaker:reinforced_concrete:0)
Block(-4,21,4,contenttweaker:reinforced_concrete:0)
Block(-4,21,5,contenttweaker:reinforced_concrete:0)
Block(-4,21,7,contenttweaker:reinforced_concrete:0)
Block(-4,22,1,contenttweaker:reinforced_concrete:0)
Block(-4,22,2,contenttweaker:reinforced_concrete:0)
Block(-4,22,3,contenttweaker:reinforced_concrete:0)
Block(-4,22,4,contenttweaker:reinforced_concrete:0)
Block(-4,22,5,contenttweaker:reinforced_concrete:0)
Block(-4,22,7,contenttweaker:reinforced_concrete:0)
Block(-4,23,1,contenttweaker:reinforced_concrete:0)
Block(-4,23,2,contenttweaker:reinforced_concrete:0)
Block(-4,23,3,contenttweaker:reinforced_concrete:0)
Block(-4,23,4,contenttweaker:reinforced_concrete:0)
Block(-4,23,5,contenttweaker:reinforced_concrete:0)
Block(-4,23,6,contenttweaker:reinforced_concrete:0)
Block(-4,23,7,contenttweaker:reinforced_concrete:0)
Block(-4,24,1,contenttweaker:reinforced_concrete:0)
Block(-4,24,2,contenttweaker:reinforced_concrete:0)
Block(-4,24,3,contenttweaker:reinforced_concrete:0)
Block(-4,24,4,contenttweaker:reinforced_concrete:0)
Block(-4,24,5,contenttweaker:reinforced_concrete:0)
Block(-4,24,6,contenttweaker:reinforced_concrete:0)
Block(-4,24,7,contenttweaker:reinforced_concrete:0)
Block(-4,25,1,contenttweaker:reinforced_concrete:0)
Block(-4,25,2,contentcreator:iron_plate_stairs_reinforced:0)
Block(-4,25,3,contenttweaker:reinforced_concrete:0)
Block(-4,25,4,contentcreator:iron_plate_stairs_reinforced:0)
Block(-4,25,5,contenttweaker:reinforced_concrete:0)
Block(-4,25,6,contentcreator:iron_plate_stairs_reinforced:0)
Block(-4,25,7,contenttweaker:reinforced_concrete:0)
Block(-4,26,1,contenttweaker:reinforced_concrete:0)
Block(-4,26,2,contentcreator:iron_plate_stairs_reinforced:0)
Block(-4,26,3,contenttweaker:reinforced_concrete:0)
Block(-4,26,4,contentcreator:iron_plate_stairs_reinforced:0)
Block(-4,26,5,contenttweaker:reinforced_concrete:0)
Block(-4,26,6,contentcreator:iron_plate_stairs_reinforced:0)
Block(-4,26,7,contenttweaker:reinforced_concrete:0)
Block(-4,27,1,contenttweaker:reinforced_concrete:0)
Block(-4,27,2,contentcreator:concrete_stairs_reinforced:0)
Block(-4,27,3,contenttweaker:reinforced_concrete:0)
Block(-4,27,4,contentcreator:concrete_stairs_reinforced:0)
Block(-4,27,5,contenttweaker:reinforced_concrete:0)
Block(-4,27,6,contentcreator:concrete_stairs_reinforced:0)
Block(-4,27,7,contenttweaker:reinforced_concrete:0)
Block(-3,0,-6,contenttweaker:reinforced_concrete:0)
Block(-3,0,-2,contenttweaker:reinforced_concrete:0)
Block(-3,0,5,contenttweaker:reinforced_concrete:0)
Block(-3,0,6,contenttweaker:reinforced_concrete:0)
Block(-3,0,7,contenttweaker:reinforced_concrete:0)
Block(-3,0,8,contenttweaker:reinforced_concrete:0)
Block(-3,0,9,contenttweaker:reinforced_concrete:0)
Block(-3,1,-6,contenttweaker:reinforced_concrete:0)
Block(-3,1,-2,contenttweaker:reinforced_concrete:0)
Block(-3,1,5,contenttweaker:reinforced_concrete:0)
Block(-3,1,6,contenttweaker:reinforced_concrete:0)
Block(-3,1,7,contenttweaker:reinforced_concrete:0)
Block(-3,1,8,contenttweaker:reinforced_concrete:0)
Block(-3,1,9,contenttweaker:reinforced_concrete:0)
Block(-3,2,-6,contenttweaker:reinforced_concrete:0)
Block(-3,2,-2,contenttweaker:reinforced_concrete:0)
Block(-3,2,5,contenttweaker:reinforced_concrete:0)
Block(-3,2,6,contenttweaker:reinforced_concrete:0)
Block(-3,2,7,contenttweaker:reinforced_concrete:0)
Block(-3,2,8,contenttweaker:reinforced_concrete:0)
Block(-3,2,9,contenttweaker:reinforced_concrete:0)
Block(-3,3,-6,contenttweaker:reinforced_concrete:0)
Block(-3,3,-5,contenttweaker:reinforced_concrete:0)
Block(-3,3,-4,contenttweaker:reinforced_concrete:0)
Block(-3,3,-3,contenttweaker:reinforced_concrete:0)
Block(-3,3,-2,contenttweaker:reinforced_concrete:0)
Block(-3,3,-1,contenttweaker:reinforced_concrete:0)
Block(-3,3,0,contenttweaker:reinforced_concrete:0)
Block(-3,3,1,contenttweaker:reinforced_concrete:0)
Block(-3,3,2,contenttweaker:reinforced_concrete:0)
Block(-3,3,3,contenttweaker:reinforced_concrete:0)
Block(-3,3,4,contenttweaker:reinforced_concrete:0)
Block(-3,3,5,contenttweaker:reinforced_concrete:0)
Block(-3,3,6,STATIONARY_WATER:0)
Block(-3,3,7,biomesoplenty:mud:0)
Block(-3,3,8,biomesoplenty:sand:0)
Block(-3,3,9,contenttweaker:reinforced_concrete:0)
Block(-3,4,-6,contenttweaker:reinforced_concrete:0)
Block(-3,4,-5,contenttweaker:reinforced_concrete:0)
Block(-3,4,-4,contenttweaker:reinforced_concrete:0)
Block(-3,4,-3,contenttweaker:reinforced_concrete:0)
Block(-3,4,-2,contenttweaker:reinforced_concrete:0)
Block(-3,4,-1,contenttweaker:reinforced_concrete:0)
Block(-3,4,0,contenttweaker:reinforced_concrete:0)
Block(-3,4,1,notreepunching:loose_rock/stone:0)
Block(-3,4,2,variedcommodities:couch_wool:5,f_bunker_mid/16-variedcommodities_couch_wool.nbt)
Block(-3,4,3,variedcommodities:couch_wool:5,f_bunker_mid/17-variedcommodities_couch_wool.nbt)
Block(-3,4,4,variedcommodities:couch_wool:5,f_bunker_mid/18-variedcommodities_couch_wool.nbt)
Block(-3,4,5,contenttweaker:reinforced_concrete:0)
Block(-3,4,6,AIR:0)
Block(-3,4,7,AIR:0)
Block(-3,4,8,AIR:0)
Block(-3,4,9,contenttweaker:reinforced_concrete:0)
Block(-3,5,-6,contenttweaker:reinforced_concrete:0)
Block(-3,5,-5,CONCRETE:0)
Block(-3,5,-4,CONCRETE:0)
Block(-3,5,-3,CONCRETE:0)
Block(-3,5,-2,CONCRETE:0)
Block(-3,5,-1,CONCRETE:0)
Block(-3,5,0,CONCRETE:0)
Block(-3,5,1,AIR:0)
Block(-3,5,2,AIR:0)
Block(-3,5,3,AIR:0)
Block(-3,5,4,AIR:0)
Block(-3,5,5,CONCRETE:0)
Block(-3,5,6,AIR:0)
Block(-3,5,7,AIR:0)
Block(-3,5,8,AIR:0)
Block(-3,5,9,contenttweaker:reinforced_concrete:0)
Block(-3,6,-6,contenttweaker:reinforced_concrete:0)
Block(-3,6,-5,contenttweaker:reinforced_concrete:0)
Block(-3,6,-4,contenttweaker:reinforced_concrete:0)
Block(-3,6,-3,contenttweaker:reinforced_concrete:0)
Block(-3,6,-2,contenttweaker:reinforced_concrete:0)
Block(-3,6,-1,contenttweaker:reinforced_concrete:0)
Block(-3,6,0,contenttweaker:reinforced_concrete:0)
Block(-3,6,1,AIR:0)
Block(-3,6,2,AIR:0)
Block(-3,6,3,lycanitesmobs:ashenstone_slab:1)
Block(-3,6,4,WEB:0)
Block(-3,6,5,contenttweaker:reinforced_concrete:0)
Block(-3,6,6,contenttweaker:reinforced_concrete:0)
Block(-3,6,7,contenttweaker:reinforced_concrete:0)
Block(-3,6,8,contenttweaker:reinforced_concrete:0)
Block(-3,6,9,contenttweaker:reinforced_concrete:0)
Block(-3,7,-6,contenttweaker:reinforced_concrete:0)
Block(-3,7,-5,contenttweaker:reinforced_concrete:0)
Block(-3,7,-4,contenttweaker:reinforced_concrete:0)
Block(-3,7,-3,contenttweaker:reinforced_concrete:0)
Block(-3,7,-2,contenttweaker:reinforced_concrete:0)
Block(-3,7,-1,contenttweaker:reinforced_concrete:0)
Block(-3,7,0,contenttweaker:reinforced_concrete:0)
Block(-3,7,1,STEP:8)
Block(-3,7,2,AIR:0)
Block(-3,7,3,rustic:iron_lattice:0)
Block(-3,7,4,WEB:0)
Block(-3,7,5,contenttweaker:reinforced_concrete:0)
Block(-3,7,6,contenttweaker:reinforced_concrete:0)
Block(-3,7,7,contenttweaker:reinforced_concrete:0)
Block(-3,7,8,contenttweaker:reinforced_concrete:0)
Block(-3,7,9,contenttweaker:reinforced_concrete:0)
Block(-3,8,-6,contenttweaker:reinforced_concrete:0)
Block(-3,8,-5,contenttweaker:reinforced_concrete:0)
Block(-3,8,-4,contenttweaker:reinforced_concrete:0)
Block(-3,8,-3,contenttweaker:reinforced_concrete:0)
Block(-3,8,-2,contenttweaker:reinforced_concrete:0)
Block(-3,8,-1,contenttweaker:reinforced_concrete:0)
Block(-3,8,0,contenttweaker:reinforced_concrete:0)
Block(-3,8,1,contenttweaker:reinforced_concrete:0)
Block(-3,8,2,contenttweaker:reinforced_concrete:0)
Block(-3,8,3,contenttweaker:reinforced_concrete:0)
Block(-3,8,4,contenttweaker:reinforced_concrete:0)
Block(-3,8,5,contenttweaker:reinforced_concrete:0)
Block(-3,8,6,WEB:0)
Block(-3,8,7,inspirations:path:0)
Block(-3,8,8,AIR:0)
Block(-3,8,9,contenttweaker:reinforced_concrete:0)
Block(-3,9,-6,contenttweaker:reinforced_concrete:0)
Block(-3,9,-5,contenttweaker:reinforced_concrete:0)
Block(-3,9,-4,contenttweaker:reinforced_concrete:0)
Block(-3,9,-3,contenttweaker:reinforced_concrete:0)
Block(-3,9,-2,contenttweaker:reinforced_concrete:0)
Block(-3,9,-1,contenttweaker:reinforced_concrete:0)
Block(-3,9,0,REDSTONE_WIRE:5)
Block(-3,9,1,REDSTONE_WIRE:4)
Block(-3,9,2,REDSTONE_WIRE:3)
Block(-3,9,3,contenttweaker:reinforced_concrete:0)
Block(-3,9,4,contenttweaker:reinforced_concrete:0)
Block(-3,9,5,contenttweaker:reinforced_concrete:0)
Block(-3,9,6,WEB:0)
Block(-3,9,7,AIR:0)
Block(-3,9,8,AIR:0)
Block(-3,9,9,contenttweaker:reinforced_concrete:0)
Block(-3,10,-6,contenttweaker:reinforced_concrete:0)
Block(-3,10,-5,contenttweaker:reinforced_concrete:0)
Block(-3,10,-4,contenttweaker:reinforced_concrete:0)
Block(-3,10,-3,contenttweaker:reinforced_concrete:0)
Block(-3,10,-2,contenttweaker:reinforced_concrete:0)
Block(-3,10,-1,contenttweaker:reinforced_concrete:0)
Block(-3,10,0,contenttweaker:reinforced_concrete:0)
Block(-3,10,1,contenttweaker:reinforced_concrete:0)
Block(-3,10,2,contentcreator:iron_plate_slab_reinforced:0)
Block(-3,10,3,WEB:0)
Block(-3,10,4,contentcreator:iron_plate_slab_reinforced:0)
Block(-3,10,5,contenttweaker:reinforced_concrete:0)
Block(-3,10,6,contenttweaker:reinforced_concrete:0)
Block(-3,10,7,contenttweaker:reinforced_concrete:0)
Block(-3,10,8,contenttweaker:reinforced_concrete:0)
Block(-3,10,9,contenttweaker:reinforced_concrete:0)
Block(-3,11,-6,contenttweaker:reinforced_concrete:0)
Block(-3,11,-5,contenttweaker:reinforced_concrete:0)
Block(-3,11,-4,contenttweaker:reinforced_concrete:0)
Block(-3,11,-3,contenttweaker:reinforced_concrete:0)
Block(-3,11,-2,AIR:0)
Block(-3,11,-1,inspirations:path:0)
Block(-3,11,0,inspirations:path:0)
Block(-3,11,1,quark:framed_glass:0)
Block(-3,11,2,AIR:0)
Block(-3,11,3,AIR:0)
Block(-3,11,4,AIR:0)
Block(-3,11,5,AIR:0)
Block(-3,11,6,AIR:0)
Block(-3,11,7,inspirations:path:0)
Block(-3,11,8,inspirations:path:0)
Block(-3,11,9,contenttweaker:reinforced_concrete:0)
Block(-3,12,-6,contenttweaker:reinforced_concrete:0)
Block(-3,12,-5,contenttweaker:reinforced_concrete:0)
Block(-3,12,-4,AIR:0)
Block(-3,12,-3,contenttweaker:reinforced_concrete:0)
Block(-3,12,-2,AIR:0)
Block(-3,12,-1,AIR:0)
Block(-3,12,0,AIR:0)
Block(-3,12,1,quark:framed_glass:0)
Block(-3,12,2,AIR:0)
Block(-3,12,3,AIR:0)
Block(-3,12,4,AIR:0)
Block(-3,12,5,AIR:0)
Block(-3,12,6,AIR:0)
Block(-3,12,7,AIR:0)
Block(-3,12,8,AIR:0)
Block(-3,12,9,contenttweaker:reinforced_concrete:0)
Block(-3,13,-6,contenttweaker:reinforced_concrete:0)
Block(-3,13,-5,contenttweaker:reinforced_concrete:0)
Block(-3,13,-4,contenttweaker:reinforced_concrete:0)
Block(-3,13,-3,contenttweaker:reinforced_concrete:0)
Block(-3,13,-2,quark:grate:0)
Block(-3,13,-1,quark:grate:0)
Block(-3,13,0,quark:grate:0)
Block(-3,13,1,contenttweaker:reinforced_concrete:0)
Block(-3,13,2,WEB:0)
Block(-3,13,3,AIR:0)
Block(-3,13,4,AIR:0)
Block(-3,13,5,contenttweaker:reinforced_concrete:0)
Block(-3,13,6,quark:grate:0)
Block(-3,13,7,quark:grate:0)
Block(-3,13,8,quark:grate:0)
Block(-3,13,9,contenttweaker:reinforced_concrete:0)
Block(-3,14,-6,contenttweaker:reinforced_concrete:0)
Block(-3,14,-5,AIR:0)
Block(-3,14,-4,REDSTONE_WIRE:0)
Block(-3,14,-3,DIODE_BLOCK_OFF:3)
Block(-3,14,-2,contenttweaker:reinforced_concrete:0)
Block(-3,14,-1,lycanitesmobs:ashencrystal:0)
Block(-3,14,0,contenttweaker:reinforced_concrete:0)
Block(-3,14,1,contenttweaker:reinforced_concrete:0)
Block(-3,14,2,AIR:0)
Block(-3,14,3,inspirations:rope:1)
Block(-3,14,4,AIR:0)
Block(-3,14,5,contenttweaker:reinforced_concrete:0)
Block(-3,14,6,contenttweaker:reinforced_concrete:0)
Block(-3,14,7,lycanitesmobs:ashencrystal:0)
Block(-3,14,8,contenttweaker:reinforced_concrete:0)
Block(-3,14,9,contenttweaker:reinforced_concrete:0)
Block(-3,15,-6,contenttweaker:reinforced_concrete:0)
Block(-3,15,-5,contenttweaker:reinforced_concrete:0)
Block(-3,15,-4,AIR:0)
Block(-3,15,-3,AIR:0)
Block(-3,15,-2,contenttweaker:reinforced_concrete:0)
Block(-3,15,-1,contenttweaker:reinforced_concrete:0)
Block(-3,15,0,contenttweaker:reinforced_concrete:0)
Block(-3,15,1,contenttweaker:reinforced_concrete:0)
Block(-3,15,2,AIR:0)
Block(-3,15,3,inspirations:rope:1)
Block(-3,15,4,AIR:0)
Block(-3,15,5,contenttweaker:reinforced_concrete:0)
Block(-3,15,6,contenttweaker:reinforced_concrete:0)
Block(-3,15,7,contenttweaker:reinforced_concrete:0)
Block(-3,15,8,contenttweaker:reinforced_concrete:0)
Block(-3,15,9,contenttweaker:reinforced_concrete:0)
Block(-3,16,-6,contenttweaker:reinforced_concrete:0)
Block(-3,16,-5,contenttweaker:reinforced_concrete:0)
Block(-3,16,-4,contenttweaker:reinforced_concrete:0)
Block(-3,16,-3,contenttweaker:reinforced_concrete:0)
Block(-3,16,-2,contenttweaker:reinforced_concrete:0)
Block(-3,16,-1,contenttweaker:reinforced_concrete:0)
Block(-3,16,0,contenttweaker:reinforced_concrete:0)
Block(-3,16,1,contenttweaker:reinforced_concrete:0)
Block(-3,16,2,AIR:0)
Block(-3,16,3,inspirations:rope:1)
Block(-3,16,4,AIR:0)
Block(-3,16,5,contenttweaker:reinforced_concrete:0)
Block(-3,17,1,contenttweaker:reinforced_concrete:0)
Block(-3,17,2,AIR:0)
Block(-3,17,3,inspirations:rope:1)
Block(-3,17,4,AIR:0)
Block(-3,17,5,contenttweaker:reinforced_concrete:0)
Block(-3,18,1,contenttweaker:reinforced_concrete:0)
Block(-3,18,2,AIR:0)
Block(-3,18,3,inspirations:rope:1)
Block(-3,18,4,AIR:0)
Block(-3,18,5,contenttweaker:reinforced_concrete:0)
Block(-3,19,1,contenttweaker:reinforced_concrete:0)
Block(-3,19,2,AIR:0)
Block(-3,19,3,inspirations:rope:1)
Block(-3,19,4,AIR:0)
Block(-3,19,5,contenttweaker:reinforced_concrete:0)
Block(-3,20,1,contenttweaker:reinforced_concrete:0)
Block(-3,20,2,AIR:0)
Block(-3,20,3,inspirations:rope:1)
Block(-3,20,4,AIR:0)
Block(-3,20,5,contenttweaker:reinforced_concrete:0)
Block(-3,21,1,contenttweaker:reinforced_concrete:0)
Block(-3,21,2,AIR:0)
Block(-3,21,3,inspirations:rope:1)
Block(-3,21,4,AIR:0)
Block(-3,21,5,contenttweaker:reinforced_concrete:0)
Block(-3,22,1,contenttweaker:reinforced_concrete:0)
Block(-3,22,2,AIR:0)
Block(-3,22,3,inspirations:rope:1)
Block(-3,22,4,AIR:0)
Block(-3,22,5,contenttweaker:reinforced_concrete:0)
Block(-3,23,1,contenttweaker:reinforced_concrete:0)
Block(-3,23,2,AIR:0)
Block(-3,23,3,inspirations:rope:1)
Block(-3,23,4,AIR:0)
Block(-3,23,5,contenttweaker:reinforced_concrete:0)
Block(-3,23,6,contenttweaker:reinforced_concrete:0)
Block(-3,23,7,contenttweaker:reinforced_concrete:0)
Block(-3,24,1,contenttweaker:reinforced_concrete:0)
Block(-3,24,2,AIR:0)
Block(-3,24,3,inspirations:rope:1)
Block(-3,24,4,AIR:0)
Block(-3,24,5,rustic:iron_lattice:0)
Block(-3,24,6,OBSERVER:4)
Block(-3,24,7,contenttweaker:reinforced_concrete:0)
Block(-3,25,1,contentcreator:iron_plate_stairs_reinforced:2)
Block(-3,25,2,WEB:0)
Block(-3,25,3,inspirations:rope:1)
Block(-3,25,4,AIR:0)
Block(-3,25,5,rustic:iron_lattice:0)
Block(-3,25,6,OBSERVER:4)
Block(-3,25,7,contentcreator:iron_plate_stairs_reinforced:3)
Block(-3,26,1,contentcreator:iron_plate_stairs_reinforced:2)
Block(-3,26,2,contentcreator:iron_plate_slab_reinforced_double:1)
Block(-3,26,3,CONCRETE:14)
Block(-3,26,4,contentcreator:iron_plate_stairs_reinforced:7)
Block(-3,26,5,contentcreator:iron_plate_slab_reinforced:1)
Block(-3,26,6,contentcreator:iron_plate_slab_reinforced_double:1)
Block(-3,26,7,contentcreator:iron_plate_stairs_reinforced:3)
Block(-3,27,1,contentcreator:concrete_stairs_reinforced:2)
Block(-3,27,2,contentcreator:concrete_slab_reinforced:0)
Block(-3,27,3,contenttweaker:reinforced_concrete:0)
Block(-3,27,4,contenttweaker:reinforced_concrete:0)
Block(-3,27,5,contentcreator:concrete_slab_reinforced:0)
Block(-3,27,6,contenttweaker:reinforced_concrete:0)
Block(-3,27,7,contentcreator:concrete_stairs_reinforced:3)
Block(-2,0,5,contenttweaker:reinforced_concrete:0)
Block(-2,0,6,contenttweaker:reinforced_concrete:0)
Block(-2,0,7,contenttweaker:reinforced_concrete:0)
Block(-2,0,8,contenttweaker:reinforced_concrete:0)
Block(-2,0,9,contenttweaker:reinforced_concrete:0)
Block(-2,1,5,contenttweaker:reinforced_concrete:0)
Block(-2,1,6,SEA_LANTERN:0)
Block(-2,1,7,contenttweaker:reinforced_concrete:0)
Block(-2,1,8,SEA_LANTERN:0)
Block(-2,1,9,contenttweaker:reinforced_concrete:0)
Block(-2,2,5,contenttweaker:reinforced_concrete:0)
Block(-2,2,6,STATIONARY_WATER:8)
Block(-2,2,7,STATIONARY_WATER:0)
Block(-2,2,8,STATIONARY_WATER:0)
Block(-2,2,9,contenttweaker:reinforced_concrete:0)
Block(-2,3,-6,contenttweaker:reinforced_concrete:0)
Block(-2,3,-5,contenttweaker:reinforced_concrete:0)
Block(-2,3,-4,contenttweaker:reinforced_concrete:0)
Block(-2,3,-3,contenttweaker:reinforced_concrete:0)
Block(-2,3,-2,contenttweaker:reinforced_concrete:0)
Block(-2,3,-1,contenttweaker:reinforced_concrete:0)
Block(-2,3,0,contenttweaker:reinforced_concrete:0)
Block(-2,3,1,contenttweaker:reinforced_concrete:0)
Block(-2,3,2,contenttweaker:reinforced_concrete:0)
Block(-2,3,3,contenttweaker:reinforced_concrete:0)
Block(-2,3,4,contenttweaker:reinforced_concrete:0)
Block(-2,3,5,contenttweaker:reinforced_concrete:0)
Block(-2,3,6,STATIONARY_WATER:0)
Block(-2,3,7,STATIONARY_WATER:0)
Block(-2,3,8,biomesoplenty:mud:0)
Block(-2,3,9,contenttweaker:reinforced_concrete:0)
Block(-2,4,-6,contenttweaker:reinforced_concrete:0)
Block(-2,4,-5,contenttweaker:reinforced_concrete:0)
RandomBlock(-2,4,-4,variedcommodities:crate:5,5,charm:crate_sealed:5,100)
Block(-2,4,-3,variedcommodities:chair:5,f_bunker_mid/20-variedcommodities_chair.nbt)
Block(-2,4,-2,inspirations:carpeted_trapdoor_gray:11)
Block(-2,4,-1,variedcommodities:chair:5,f_bunker_mid/21-variedcommodities_chair.nbt)
Block(-2,4,0,BOOKSHELF:0)
Block(-2,4,1,inspirations:path:0)
Block(-2,4,2,inspirations:bookshelf:12,f_bunker_mid/22-inspirations_bookshelf.nbt)
Block(-2,4,3,inspirations:bookshelf:12,f_bunker_mid/23-inspirations_bookshelf.nbt)
Block(-2,4,4,inspirations:bookshelf:12,f_bunker_mid/24-inspirations_bookshelf.nbt)
Block(-2,4,5,contenttweaker:reinforced_concrete:0)
Block(-2,4,6,AIR:0)
Block(-2,4,7,AIR:0)
Block(-2,4,8,contenttweaker:bone_pile:0)
Block(-2,4,9,contenttweaker:reinforced_concrete:0)
Block(-2,5,-6,contenttweaker:reinforced_concrete:0)
Block(-2,5,-5,CONCRETE:0)
RandomBlock(-2,5,-4,variedcommodities:crate:5,5,charm:crate_sealed:5,100)
Block(-2,5,-3,AIR:0)
Block(-2,5,-2,AIR:0)
Block(-2,5,-1,AIR:0)
Block(-2,5,0,inspirations:carpeted_trapdoor_gray:11)
Block(-2,5,1,AIR:0)
Block(-2,5,2,AIR:0)
Block(-2,5,3,AIR:0)
Block(-2,5,4,AIR:0)
Block(-2,5,5,CONCRETE:0)
Block(-2,5,6,AIR:0)
Block(-2,5,7,AIR:0)
Block(-2,5,8,AIR:0)
Block(-2,5,9,contenttweaker:reinforced_concrete:0)
Block(-2,6,-6,contenttweaker:reinforced_concrete:0)
Block(-2,6,-5,contenttweaker:reinforced_concrete:0)
RandomBlock(-2,6,-4,variedcommodities:crate:5,5,charm:crate_sealed:5,100)
Block(-2,6,-3,AIR:0)
Block(-2,6,-2,quark:grate:0)
Block(-2,6,-1,WEB:0)
Block(-2,6,0,rustic:brewing_barrel:0,f_bunker_mid/27-rustic_tileentitybrewingbarrel.nbt)
Block(-2,6,1,AIR:0)
Block(-2,6,2,AIR:0)
Block(-2,6,3,quark:grate:0)
Block(-2,6,4,AIR:0)
Block(-2,6,5,contenttweaker:reinforced_concrete:0)
Block(-2,6,6,contenttweaker:reinforced_concrete:0)
Block(-2,6,7,contenttweaker:reinforced_concrete:0)
Block(-2,6,8,contenttweaker:reinforced_concrete:0)
Block(-2,6,9,contenttweaker:reinforced_concrete:0)
Block(-2,7,-6,contenttweaker:reinforced_concrete:0)
Block(-2,7,-5,contenttweaker:reinforced_concrete:0)
Block(-2,7,-4,AIR:0)
Block(-2,7,-3,STEP:8)
Block(-2,7,-2,DISPENSER:0,f_bunker_mid/28-dispenser.nbt)
Block(-2,7,-1,STEP:8)
Block(-2,7,0,STEP:8)
Block(-2,7,1,STEP:8)
Block(-2,7,2,STEP:8)
Block(-2,7,3,DISPENSER:0,f_bunker_mid/29-dispenser.nbt)
Block(-2,7,4,AIR:0)
Block(-2,7,5,contenttweaker:reinforced_concrete:0)
Block(-2,7,6,contenttweaker:reinforced_concrete:0)
Block(-2,7,7,contenttweaker:reinforced_concrete:0)
Block(-2,7,8,contenttweaker:reinforced_concrete:0)
Block(-2,7,9,contenttweaker:reinforced_concrete:0)
Block(-2,8,-6,contenttweaker:reinforced_concrete:0)
Block(-2,8,-5,contenttweaker:reinforced_concrete:0)
Block(-2,8,-4,contenttweaker:reinforced_concrete:0)
Block(-2,8,-3,contenttweaker:reinforced_concrete:0)
Block(-2,8,-2,contenttweaker:reinforced_concrete:0)
Block(-2,8,-1,contenttweaker:reinforced_concrete:0)
Block(-2,8,0,contenttweaker:reinforced_concrete:0)
Block(-2,8,1,contenttweaker:reinforced_concrete:0)
Block(-2,8,2,contenttweaker:reinforced_concrete:0)
Block(-2,8,3,contenttweaker:reinforced_concrete:0)
Block(-2,8,4,contenttweaker:reinforced_concrete:0)
Block(-2,8,5,contenttweaker:reinforced_concrete:0)
Block(-2,8,6,CHEST:3,../../../Chests/RLCraft/Ruins/starter.nbt)
Block(-2,8,7,AIR:0)
Block(-2,8,8,inspirations:path:0)
Block(-2,8,9,contenttweaker:reinforced_concrete:0)
Block(-2,9,-1,contenttweaker:reinforced_concrete:0)
Block(-2,9,0,contenttweaker:reinforced_concrete:0)
Block(-2,9,1,contenttweaker:reinforced_concrete:0)
Block(-2,9,2,contenttweaker:reinforced_concrete:0)
Block(-2,9,3,contenttweaker:reinforced_concrete:0)
Block(-2,9,4,contenttweaker:reinforced_concrete:0)
Block(-2,9,5,contenttweaker:reinforced_concrete:0)
Block(-2,9,6,AIR:0)
Block(-2,9,7,AIR:0)
Block(-2,9,8,AIR:0)
Block(-2,9,9,contenttweaker:reinforced_concrete:0)
Block(-2,10,-6,contenttweaker:reinforced_concrete:0)
Block(-2,10,-5,contenttweaker:reinforced_concrete:0)
Block(-2,10,-4,contenttweaker:reinforced_concrete:0)
Block(-2,10,-3,contenttweaker:reinforced_concrete:0)
Block(-2,10,-2,contenttweaker:reinforced_concrete:0)
Block(-2,10,-1,contenttweaker:reinforced_concrete:0)
Block(-2,10,0,contenttweaker:reinforced_concrete:0)
Block(-2,10,1,contenttweaker:reinforced_concrete:0)
Block(-2,10,2,AIR:0)
Block(-2,10,3,AIR:0)
Block(-2,10,4,AIR:0)
Block(-2,10,5,contenttweaker:reinforced_concrete:0)
Block(-2,10,6,contenttweaker:reinforced_concrete:0)
Block(-2,10,7,contenttweaker:reinforced_concrete:0)
Block(-2,10,8,contenttweaker:reinforced_concrete:0)
Block(-2,10,9,contenttweaker:reinforced_concrete:0)
Block(-2,11,-6,contenttweaker:reinforced_concrete:0)
Block(-2,11,-5,contenttweaker:reinforced_concrete:0)
Block(-2,11,-4,contenttweaker:reinforced_concrete:0)
Block(-2,11,-3,CONCRETE:14)
Block(-2,11,-2,AIR:0)
Block(-2,11,-1,AIR:0)
Block(-2,11,0,AIR:0)
Block(-2,11,1,quark:framed_glass:0)
Block(-2,11,2,AIR:0)
Block(-2,11,3,AIR:0)
Block(-2,11,4,AIR:0)
Block(-2,11,5,AIR:0)
Block(-2,11,6,AIR:0)
Block(-2,11,7,notreepunching:loose_rock/stone:0)
Block(-2,11,8,AIR:0)
Block(-2,11,9,contenttweaker:reinforced_concrete:0)
Block(-2,12,-6,contenttweaker:reinforced_concrete:0)
Block(-2,12,-5,contenttweaker:reinforced_concrete:0)
Block(-2,12,-4,REDSTONE_WIRE:0)
Block(-2,12,-3,contenttweaker:iron_plate_reinforced:0)
Block(-2,12,-2,quark:iron_button:3)
Block(-2,12,-1,AIR:0)
Block(-2,12,0,AIR:0)
Block(-2,12,1,quark:framed_glass:0)
Block(-2,12,2,AIR:0)
Block(-2,12,3,AIR:0)
Block(-2,12,4,AIR:0)
Block(-2,12,5,AIR:0)
Block(-2,12,6,AIR:0)
Block(-2,12,7,AIR:0)
Block(-2,12,8,AIR:0)
Block(-2,12,9,contenttweaker:reinforced_concrete:0)
Block(-2,13,-6,contenttweaker:reinforced_concrete:0)
Block(-2,13,-5,REDSTONE_WIRE:0)
Block(-2,13,-4,quark:sandstone_smooth_slab:8)
Block(-2,13,-3,contenttweaker:reinforced_concrete:0)
Block(-2,13,-2,contentcreator:iron_plate_slab_reinforced:1)
Block(-2,13,-1,contentcreator:iron_plate_slab_reinforced:1)
Block(-2,13,0,contentcreator:iron_plate_slab_reinforced:1)
Block(-2,13,1,contenttweaker:reinforced_concrete:0)
Block(-2,13,2,AIR:0)
Block(-2,13,3,AIR:0)
Block(-2,13,4,AIR:0)
Block(-2,13,5,contenttweaker:reinforced_concrete:0)
Block(-2,13,6,contentcreator:iron_plate_slab_reinforced:1)
Block(-2,13,7,contentcreator:iron_plate_slab_reinforced:1)
Block(-2,13,8,contentcreator:iron_plate_slab_reinforced:1)
Block(-2,13,9,contenttweaker:reinforced_concrete:0)
Block(-2,14,-6,contenttweaker:reinforced_concrete:0)
Block(-2,14,-5,contenttweaker:reinforced_concrete:0)
Block(-2,14,-4,REDSTONE_WIRE:0)
Block(-2,14,-3,REDSTONE_WIRE:0)
Block(-2,14,-2,contenttweaker:reinforced_concrete:0)
Block(-2,14,-1,contenttweaker:reinforced_concrete:0)
Block(-2,14,0,contenttweaker:reinforced_concrete:0)
Block(-2,14,1,contenttweaker:reinforced_concrete:0)
Block(-2,14,2,mcwbridges:most1:3)
Block(-2,14,3,mcwbridges:most1:3)
Block(-2,14,4,mcwbridges:most1:3)
Block(-2,14,5,contenttweaker:reinforced_concrete:0)
Block(-2,14,6,contenttweaker:reinforced_concrete:0)
Block(-2,14,7,contenttweaker:reinforced_concrete:0)
Block(-2,14,8,contenttweaker:reinforced_concrete:0)
Block(-2,14,9,contenttweaker:reinforced_concrete:0)
Block(-2,15,-6,contenttweaker:reinforced_concrete:0)
Block(-2,15,-5,contenttweaker:reinforced_concrete:0)
Block(-2,15,-4,AIR:0)
Block(-2,15,-3,contenttweaker:reinforced_concrete:0)
Block(-2,15,-2,contenttweaker:reinforced_concrete:0)
Block(-2,15,-1,contenttweaker:reinforced_concrete:0)
Block(-2,15,0,contenttweaker:reinforced_concrete:0)
Block(-2,15,1,contenttweaker:reinforced_concrete:0)
Block(-2,15,2,AIR:0)
Block(-2,15,3,AIR:0)
Block(-2,15,4,AIR:0)
Block(-2,15,5,contenttweaker:reinforced_concrete:0)
Block(-2,15,6,contenttweaker:reinforced_concrete:0)
Block(-2,15,7,contenttweaker:reinforced_concrete:0)
Block(-2,15,8,contenttweaker:reinforced_concrete:0)
Block(-2,15,9,contenttweaker:reinforced_concrete:0)
Block(-2,16,-6,contenttweaker:reinforced_concrete:0)
Block(-2,16,-5,contenttweaker:reinforced_concrete:0)
Block(-2,16,-4,contenttweaker:reinforced_concrete:0)
Block(-2,16,-3,contenttweaker:reinforced_concrete:0)
Block(-2,16,-2,contenttweaker:reinforced_concrete:0)
Block(-2,16,-1,contenttweaker:reinforced_concrete:0)
Block(-2,16,0,contenttweaker:reinforced_concrete:0)
Block(-2,16,1,contenttweaker:reinforced_concrete:0)
Block(-2,16,2,AIR:0)
Block(-2,16,3,AIR:0)
Block(-2,16,4,AIR:0)
Block(-2,16,5,contenttweaker:reinforced_concrete:0)
Block(-2,17,1,contenttweaker:reinforced_concrete:0)
Block(-2,17,2,AIR:0)
Block(-2,17,3,AIR:0)
Block(-2,17,4,AIR:0)
Block(-2,17,5,contenttweaker:reinforced_concrete:0)
Block(-2,18,1,contenttweaker:reinforced_concrete:0)
Block(-2,18,2,AIR:0)
Block(-2,18,3,AIR:0)
Block(-2,18,4,AIR:0)
Block(-2,18,5,contenttweaker:reinforced_concrete:0)
Block(-2,19,1,contenttweaker:reinforced_concrete:0)
Block(-2,19,2,AIR:0)
Block(-2,19,3,AIR:0)
Block(-2,19,4,AIR:0)
Block(-2,19,5,contenttweaker:reinforced_concrete:0)
Block(-2,20,1,contenttweaker:reinforced_concrete:0)
Block(-2,20,2,AIR:0)
Block(-2,20,3,AIR:0)
Block(-2,20,4,AIR:0)
Block(-2,20,5,contenttweaker:reinforced_concrete:0)
Block(-2,21,1,contenttweaker:reinforced_concrete:0)
Block(-2,21,2,AIR:0)
Block(-2,21,3,AIR:0)
Block(-2,21,4,AIR:0)
Block(-2,21,5,contenttweaker:reinforced_concrete:0)
Block(-2,22,1,contenttweaker:reinforced_concrete:0)
Block(-2,22,2,AIR:0)
Block(-2,22,3,AIR:0)
Block(-2,22,4,AIR:0)
Block(-2,22,5,contenttweaker:reinforced_concrete:0)
Block(-2,23,1,contenttweaker:reinforced_concrete:0)
Block(-2,23,2,AIR:0)
Block(-2,23,3,AIR:0)
Block(-2,23,4,AIR:0)
Block(-2,23,5,contenttweaker:reinforced_concrete:0)
Block(-2,23,6,contenttweaker:reinforced_concrete:0)
Block(-2,23,7,contenttweaker:reinforced_concrete:0)
Block(-2,24,1,contenttweaker:reinforced_concrete:0)
Block(-2,24,2,AIR:0)
Block(-2,24,3,AIR:0)
Block(-2,24,4,AIR:0)
Block(-2,24,5,AIR:0)
Block(-2,24,6,contenttweaker:bone_pile:0)
Block(-2,24,7,contenttweaker:reinforced_concrete:0)
Block(-2,25,1,contenttweaker:reinforced_concrete:0)
Block(-2,25,2,AIR:0)
Block(-2,25,3,AIR:0)
Block(-2,25,4,AIR:0)
Block(-2,25,5,AIR:0)
Block(-2,25,6,AIR:0)
Block(-2,25,7,contenttweaker:reinforced_concrete:0)
Block(-2,26,1,contenttweaker:reinforced_concrete:0)
Block(-2,26,2,AIR:0)
Block(-2,26,3,AIR:0)
Block(-2,26,4,AIR:0)
Block(-2,26,5,AIR:0)
Block(-2,26,6,WEB:0)
Block(-2,26,7,contenttweaker:reinforced_concrete:0)
Block(-2,27,1,contenttweaker:reinforced_concrete:0)
Block(-2,27,2,contenttweaker:reinforced_concrete:0)
Block(-2,27,3,contentcreator:concrete_slab_reinforced:1)
Block(-2,27,4,contenttweaker:reinforced_concrete:0)
Block(-2,27,5,contentcreator:concrete_slab_reinforced:0)
Block(-2,27,6,contentcreator:concrete_slab_reinforced:0)
Block(-2,27,7,contentcreator:concrete_slab_reinforced:0)
Block(-1,0,2,contenttweaker:reinforced_concrete:0)
Block(-1,0,5,contenttweaker:reinforced_concrete:0)
Block(-1,0,6,contenttweaker:reinforced_concrete:0)
Block(-1,0,7,contenttweaker:reinforced_concrete:0)
Block(-1,0,8,contenttweaker:reinforced_concrete:0)
Block(-1,0,9,contenttweaker:reinforced_concrete:0)
Block(-1,1,2,contenttweaker:reinforced_concrete:0)
Block(-1,1,5,contenttweaker:reinforced_concrete:0)
Block(-1,1,6,contenttweaker:reinforced_concrete:0)
Block(-1,1,7,contenttweaker:reinforced_concrete:0)
Block(-1,1,8,contenttweaker:reinforced_concrete:0)
Block(-1,1,9,contenttweaker:reinforced_concrete:0)
Block(-1,2,2,contenttweaker:reinforced_concrete:0)
Block(-1,2,3,contenttweaker:reinforced_concrete:0)
Block(-1,2,4,contenttweaker:reinforced_concrete:0)
Block(-1,2,5,contenttweaker:reinforced_concrete:0)
Block(-1,2,6,biomesoplenty:mud:0)
Block(-1,2,7,biomesoplenty:mud:0)
Block(-1,2,8,STATIONARY_WATER:0)
Block(-1,2,9,contenttweaker:reinforced_concrete:0)
Block(-1,3,-6,contenttweaker:reinforced_concrete:0)
Block(-1,3,-5,contenttweaker:reinforced_concrete:0)
Block(-1,3,-4,contenttweaker:reinforced_concrete:0)
Block(-1,3,-3,contenttweaker:reinforced_concrete:0)
Block(-1,3,-2,contenttweaker:reinforced_concrete:0)
Block(-1,3,-1,contenttweaker:reinforced_concrete:0)
Block(-1,3,0,contenttweaker:reinforced_concrete:0)
Block(-1,3,1,contenttweaker:reinforced_concrete:0)
Block(-1,3,2,cookingforblockheads:kitchen_floor:0)
Block(-1,3,3,cookingforblockheads:kitchen_floor:0)
Block(-1,3,4,cookingforblockheads:kitchen_floor:0)
Block(-1,3,5,contenttweaker:reinforced_concrete:0)
Block(-1,3,6,biomesoplenty:mud:0)
Block(-1,3,7,STATIONARY_WATER:0)
Block(-1,3,8,STATIONARY_WATER:0)
Block(-1,3,9,contenttweaker:reinforced_concrete:0)
Block(-1,4,-6,contenttweaker:reinforced_concrete:0)
Block(-1,4,-5,contenttweaker:reinforced_concrete:0)
RandomBlock(-1,4,-4,variedcommodities:crate:5,5,charm:crate_sealed:5,100)
Block(-1,4,-3,variedcommodities:chair:5,f_bunker_mid/32-variedcommodities_chair.nbt)
Block(-1,4,-2,inspirations:carpeted_trapdoor_gray:11)
Block(-1,4,-1,AIR:0)
Block(-1,4,0,BOOKSHELF:0)
Block(-1,4,1,AIR:0)
Block(-1,4,2,rustic:iron_lattice:0)
Block(-1,4,3,AIR:0)
Block(-1,4,4,contenttweaker:bone_pile:0)
Block(-1,4,5,contenttweaker:reinforced_concrete:0)
Block(-1,4,6,AIR:0)
Block(-1,4,7,biomesoplenty:waterlily:2)
Block(-1,4,8,AIR:0)
Block(-1,4,9,contenttweaker:reinforced_concrete:0)
Block(-1,5,-6,contenttweaker:reinforced_concrete:0)
Block(-1,5,-5,CONCRETE:0)
RandomBlock(-1,5,-4,variedcommodities:crate:5,5,charm:crate_sealed:5,100)
Block(-1,5,-3,AIR:0)
Block(-1,5,-2,cookingforblockheads:fruit_basket:4,f_bunker_mid/34-cookingforblockheads_fruit_basket.nbt)
Block(-1,5,-1,AIR:0)
Block(-1,5,0,inspirations:carpeted_trapdoor_gray:11)
Block(-1,5,1,AIR:0)
Block(-1,5,2,rustic:iron_lattice:0)
Block(-1,5,3,AIR:0)
Block(-1,5,4,AIR:0)
Block(-1,5,5,CONCRETE:0)
Block(-1,5,6,AIR:0)
Block(-1,5,7,AIR:0)
Block(-1,5,8,AIR:0)
Block(-1,5,9,contenttweaker:reinforced_concrete:0)
Block(-1,6,-6,contenttweaker:reinforced_concrete:0)
Block(-1,6,-5,contenttweaker:reinforced_concrete:0)
RandomBlock(-1,6,-4,variedcommodities:crate:5,5,charm:crate_sealed:5,100)
Block(-1,6,-3,AIR:0)
Block(-1,6,-2,AIR:0)
Block(-1,6,-1,AIR:0)
Block(-1,6,0,rustic:brewing_barrel:0,f_bunker_mid/36-rustic_tileentitybrewingbarrel.nbt)
Block(-1,6,1,AIR:0)
Block(-1,6,2,contentcreator:iron_plate_slab_reinforced:0)
Block(-1,6,3,contentcreator:iron_plate_slab_reinforced:0)
Block(-1,6,4,contentcreator:iron_plate_slab_reinforced:0)
Block(-1,6,5,contenttweaker:reinforced_concrete:0)
Block(-1,6,6,contenttweaker:reinforced_concrete:0)
Block(-1,6,7,quark:paper_lantern:0)
Block(-1,6,8,contenttweaker:reinforced_concrete:0)
Block(-1,6,9,contenttweaker:reinforced_concrete:0)
Block(-1,7,-6,contenttweaker:reinforced_concrete:0)
Block(-1,7,-5,contenttweaker:reinforced_concrete:0)
Block(-1,7,-4,AIR:0)
Block(-1,7,-3,STEP:8)
Block(-1,7,-2,WEB:0)
Block(-1,7,-1,WEB:0)
Block(-1,7,0,AIR:0)
Block(-1,7,1,AIR:0)
Block(-1,7,2,AIR:0)
Block(-1,7,3,AIR:0)
Block(-1,7,4,AIR:0)
Block(-1,7,5,contenttweaker:reinforced_concrete:0)
Block(-1,7,6,contenttweaker:reinforced_concrete:0)
Block(-1,7,7,contenttweaker:reinforced_concrete:0)
Block(-1,7,8,contenttweaker:reinforced_concrete:0)
Block(-1,7,9,contenttweaker:reinforced_concrete:0)
Block(-1,8,-6,contenttweaker:reinforced_concrete:0)
Block(-1,8,-5,contenttweaker:reinforced_concrete:0)
Block(-1,8,-4,contenttweaker:reinforced_concrete:0)
Block(-1,8,-3,contenttweaker:reinforced_concrete:0)
Block(-1,8,-2,contenttweaker:reinforced_concrete:0)
Block(-1,8,-1,contenttweaker:reinforced_concrete:0)
Block(-1,8,0,contenttweaker:reinforced_concrete:0)
Block(-1,8,1,contenttweaker:reinforced_concrete:0)
Block(-1,8,2,contenttweaker:reinforced_concrete:0)
Block(-1,8,3,contenttweaker:reinforced_concrete:0)
Block(-1,8,4,contenttweaker:reinforced_concrete:0)
Block(-1,8,5,contenttweaker:reinforced_concrete:0)
Block(-1,8,6,inspirations:bookshelf:2,f_bunker_mid/37-inspirations_bookshelf.nbt)
Block(-1,8,7,AIR:0)
Block(-1,8,8,inspirations:path:0)
Block(-1,8,9,contenttweaker:reinforced_concrete:0)
Block(-1,9,-1,contenttweaker:reinforced_concrete:0)
Block(-1,9,0,contenttweaker:reinforced_concrete:0)
Block(-1,9,1,contenttweaker:reinforced_concrete:0)
Block(-1,9,2,contenttweaker:reinforced_concrete:0)
Block(-1,9,3,contenttweaker:reinforced_concrete:0)
Block(-1,9,4,contenttweaker:reinforced_concrete:0)
Block(-1,9,5,contenttweaker:reinforced_concrete:0)
Block(-1,9,6,inspirations:bookshelf:2,f_bunker_mid/38-inspirations_bookshelf.nbt)
Block(-1,9,7,AIR:0)
Block(-1,9,8,AIR:0)
Block(-1,9,9,contenttweaker:reinforced_concrete:0)
Block(-1,10,-6,contenttweaker:reinforced_concrete:0)
Block(-1,10,-5,contenttweaker:reinforced_concrete:0)
Block(-1,10,-4,contenttweaker:reinforced_concrete:0)
Block(-1,10,-3,contenttweaker:reinforced_concrete:0)
Block(-1,10,-2,contenttweaker:reinforced_concrete:0)
Block(-1,10,-1,contenttweaker:reinforced_concrete:0)
Block(-1,10,0,contenttweaker:reinforced_concrete:0)
Block(-1,10,1,contenttweaker:reinforced_concrete:0)
Block(-1,10,2,contentcreator:iron_plate_slab_reinforced:0)
Block(-1,10,3,WEB:0)
Block(-1,10,4,contentcreator:iron_plate_slab_reinforced:0)
Block(-1,10,5,contenttweaker:reinforced_concrete:0)
Block(-1,10,6,contenttweaker:reinforced_concrete:0)
Block(-1,10,7,contenttweaker:reinforced_concrete:0)
Block(-1,10,8,contenttweaker:reinforced_concrete:0)
Block(-1,10,9,contenttweaker:reinforced_concrete:0)
Block(-1,11,-6,contenttweaker:reinforced_concrete:0)
Block(-1,11,-5,contenttweaker:reinforced_concrete:0)
Block(-1,11,-4,REDSTONE_WIRE:0)
Block(-1,11,-3,contenttweaker:reinforced_concrete:0)
Block(-1,11,-2,AIR:0)
Block(-1,11,-1,AIR:0)
Block(-1,11,0,notreepunching:loose_rock/stone:0)
Block(-1,11,1,quark:framed_glass:0)
Block(-1,11,2,AIR:0)
Block(-1,11,3,AIR:0)
Block(-1,11,4,AIR:0)
Block(-1,11,5,AIR:0)
Block(-1,11,6,inspirations:path:0)
Block(-1,11,7,AIR:0)
Block(-1,11,8,AIR:0)
Block(-1,11,9,contenttweaker:reinforced_concrete:0)
Block(-1,12,-6,contenttweaker:reinforced_concrete:0)
Block(-1,12,-5,contenttweaker:reinforced_concrete:0)
Block(-1,12,-4,AIR:0)
Block(-1,12,-3,contenttweaker:reinforced_concrete:0)
Block(-1,12,-2,WEB:0)
Block(-1,12,-1,AIR:0)
Block(-1,12,0,AIR:0)
Block(-1,12,1,quark:framed_glass:0)
Block(-1,12,2,AIR:0)
Block(-1,12,3,AIR:0)
Block(-1,12,4,AIR:0)
Block(-1,12,5,AIR:0)
Block(-1,12,6,AIR:0)
Block(-1,12,7,AIR:0)
Block(-1,12,8,AIR:0)
Block(-1,12,9,contenttweaker:reinforced_concrete:0)
Block(-1,13,-6,contenttweaker:reinforced_concrete:0)
Block(-1,13,-5,REDSTONE_WIRE:0)
Block(-1,13,-4,contenttweaker:reinforced_concrete:0)
Block(-1,13,-3,contenttweaker:reinforced_concrete:0)
Block(-1,13,-2,WEB:0)
Block(-1,13,-1,quark:grate:0)
Block(-1,13,0,quark:grate:0)
Block(-1,13,1,contenttweaker:reinforced_concrete:0)
Block(-1,13,2,AIR:0)
Block(-1,13,3,AIR:0)
Block(-1,13,4,AIR:0)
Block(-1,13,5,contenttweaker:reinforced_concrete:0)
Block(-1,13,6,quark:grate:0)
Block(-1,13,7,quark:grate:0)
Block(-1,13,8,quark:grate:0)
Block(-1,13,9,contenttweaker:reinforced_concrete:0)
Block(-1,14,-6,contenttweaker:reinforced_concrete:0)
Block(-1,14,-5,contenttweaker:reinforced_concrete:0)
Block(-1,14,-4,REDSTONE_WIRE:0)
Block(-1,14,-3,contenttweaker:reinforced_concrete:0)
Block(-1,14,-2,contenttweaker:reinforced_concrete:0)
Block(-1,14,-1,lycanitesmobs:ashencrystal:0)
Block(-1,14,0,contenttweaker:reinforced_concrete:0)
Block(-1,14,1,contenttweaker:reinforced_concrete:0)
Block(-1,14,2,AIR:0)
Block(-1,14,3,inspirations:rope:1)
Block(-1,14,4,AIR:0)
Block(-1,14,5,contenttweaker:reinforced_concrete:0)
Block(-1,14,6,contenttweaker:reinforced_concrete:0)
Block(-1,14,7,lycanitesmobs:ashencrystal:0)
Block(-1,14,8,contenttweaker:reinforced_concrete:0)
Block(-1,14,9,contenttweaker:reinforced_concrete:0)
Block(-1,15,-6,contenttweaker:reinforced_concrete:0)
Block(-1,15,-5,contenttweaker:reinforced_concrete:0)
Block(-1,15,-4,AIR:0)
Block(-1,15,-3,contenttweaker:reinforced_concrete:0)
Block(-1,15,-2,contenttweaker:reinforced_concrete:0)
Block(-1,15,-1,contenttweaker:reinforced_concrete:0)
Block(-1,15,0,contenttweaker:reinforced_concrete:0)
Block(-1,15,1,contenttweaker:reinforced_concrete:0)
Block(-1,15,2,AIR:0)
Block(-1,15,3,inspirations:rope:1)
Block(-1,15,4,AIR:0)
Block(-1,15,5,contenttweaker:reinforced_concrete:0)
Block(-1,15,6,contenttweaker:reinforced_concrete:0)
Block(-1,15,7,contenttweaker:reinforced_concrete:0)
Block(-1,15,8,contenttweaker:reinforced_concrete:0)
Block(-1,15,9,contenttweaker:reinforced_concrete:0)
Block(-1,16,-6,contenttweaker:reinforced_concrete:0)
Block(-1,16,-5,contenttweaker:reinforced_concrete:0)
Block(-1,16,-4,contenttweaker:reinforced_concrete:0)
Block(-1,16,-3,contenttweaker:reinforced_concrete:0)
Block(-1,16,-2,contenttweaker:reinforced_concrete:0)
Block(-1,16,-1,contenttweaker:reinforced_concrete:0)
Block(-1,16,0,contenttweaker:reinforced_concrete:0)
Block(-1,16,1,contenttweaker:reinforced_concrete:0)
Block(-1,16,2,AIR:0)
Block(-1,16,3,inspirations:rope:1)
Block(-1,16,4,AIR:0)
Block(-1,16,5,contenttweaker:reinforced_concrete:0)
Block(-1,17,1,contenttweaker:reinforced_concrete:0)
Block(-1,17,2,AIR:0)
Block(-1,17,3,inspirations:rope:1)
Block(-1,17,4,AIR:0)
Block(-1,17,5,contenttweaker:reinforced_concrete:0)
Block(-1,18,1,contenttweaker:reinforced_concrete:0)
Block(-1,18,2,AIR:0)
Block(-1,18,3,inspirations:rope:1)
Block(-1,18,4,AIR:0)
Block(-1,18,5,contenttweaker:reinforced_concrete:0)
Block(-1,19,1,contenttweaker:reinforced_concrete:0)
Block(-1,19,2,AIR:0)
Block(-1,19,3,inspirations:rope:1)
Block(-1,19,4,AIR:0)
Block(-1,19,5,contenttweaker:reinforced_concrete:0)
Block(-1,20,1,contenttweaker:reinforced_concrete:0)
Block(-1,20,2,AIR:0)
Block(-1,20,3,inspirations:rope:1)
Block(-1,20,4,AIR:0)
Block(-1,20,5,contenttweaker:reinforced_concrete:0)
Block(-1,21,1,contenttweaker:reinforced_concrete:0)
Block(-1,21,2,AIR:0)
Block(-1,21,3,inspirations:rope:1)
Block(-1,21,4,AIR:0)
Block(-1,21,5,contenttweaker:reinforced_concrete:0)
Block(-1,22,1,contenttweaker:reinforced_concrete:0)
Block(-1,22,2,AIR:0)
Block(-1,22,3,inspirations:rope:1)
Block(-1,22,4,AIR:0)
Block(-1,22,5,contenttweaker:reinforced_concrete:0)
Block(-1,23,1,contenttweaker:reinforced_concrete:0)
Block(-1,23,2,AIR:0)
Block(-1,23,3,inspirations:rope:1)
Block(-1,23,4,AIR:0)
Block(-1,23,5,contenttweaker:reinforced_concrete:0)
Block(-1,23,6,contenttweaker:reinforced_concrete:0)
Block(-1,23,7,contenttweaker:reinforced_concrete:0)
Block(-1,24,1,contenttweaker:reinforced_concrete:0)
Block(-1,24,2,AIR:0)
Block(-1,24,3,inspirations:rope:1)
Block(-1,24,4,AIR:0)
Block(-1,24,5,rustic:iron_lattice:0)
Block(-1,24,6,AIR:0)
Block(-1,24,7,contenttweaker:reinforced_concrete:0)
Block(-1,25,1,contentcreator:iron_plate_stairs_reinforced:2)
Block(-1,25,2,AIR:0)
Block(-1,25,3,inspirations:rope:1)
Block(-1,25,4,AIR:0)
Block(-1,25,5,rustic:iron_lattice:0)
Block(-1,25,6,AIR:0)
Block(-1,25,7,contentcreator:iron_plate_stairs_reinforced:3)
Block(-1,26,1,contentcreator:iron_plate_stairs_reinforced:2)
Block(-1,26,2,contentcreator:iron_plate_slab_reinforced_double:1)
Block(-1,26,3,CONCRETE:14)
Block(-1,26,4,contentcreator:iron_plate_stairs_reinforced:7)
Block(-1,26,5,contentcreator:iron_plate_slab_reinforced:1)
Block(-1,26,6,contentcreator:iron_plate_slab_reinforced:1)
Block(-1,26,7,contentcreator:iron_plate_stairs_reinforced:3)
Block(-1,27,1,contentcreator:concrete_stairs_reinforced:2)
Block(-1,27,2,contentcreator:concrete_slab_reinforced:1)
Block(-1,27,3,contenttweaker:reinforced_concrete:0)
Block(-1,27,4,contenttweaker:reinforced_concrete:0)
Block(-1,27,5,contenttweaker:reinforced_concrete:0)
Block(-1,27,6,contenttweaker:reinforced_concrete:0)
Block(-1,27,7,contentcreator:concrete_stairs_reinforced:3)
Block(-1,28,2,contentcreator:concrete_slab_reinforced:0)
Block(-1,28,3,contentcreator:concrete_slab_reinforced:0)
Block(0,0,5,contenttweaker:reinforced_concrete:0)
Block(0,0,6,contenttweaker:reinforced_concrete:0)
Block(0,0,7,contenttweaker:reinforced_concrete:0)
Block(0,0,8,contenttweaker:reinforced_concrete:0)
Block(0,0,9,contenttweaker:reinforced_concrete:0)
Block(0,1,5,contenttweaker:reinforced_concrete:0)
Block(0,1,6,contenttweaker:reinforced_concrete:0)
Block(0,1,7,contenttweaker:reinforced_concrete:0)
Block(0,1,8,contenttweaker:reinforced_concrete:0)
Block(0,1,9,contenttweaker:reinforced_concrete:0)
Block(0,2,2,contenttweaker:reinforced_concrete:0)
Block(0,2,3,contenttweaker:reinforced_concrete:0)
Block(0,2,4,contenttweaker:reinforced_concrete:0)
Block(0,2,5,contenttweaker:reinforced_concrete:0)
Block(0,2,6,biomesoplenty:mud:0)
Block(0,2,7,biomesoplenty:mud:0)
Block(0,2,8,biomesoplenty:mud:0)
Block(0,2,9,contenttweaker:reinforced_concrete:0)
Block(0,3,-6,contenttweaker:reinforced_concrete:0)
Block(0,3,-5,contenttweaker:reinforced_concrete:0)
Block(0,3,-4,contenttweaker:reinforced_concrete:0)
Block(0,3,-3,contenttweaker:reinforced_concrete:0)
Block(0,3,-2,contenttweaker:reinforced_concrete:0)
Block(0,3,-1,contenttweaker:reinforced_concrete:0)
Block(0,3,0,contenttweaker:reinforced_concrete:0)
Block(0,3,1,contenttweaker:reinforced_concrete:0)
Block(0,3,2,cookingforblockheads:kitchen_floor:0)
Block(0,3,3,cookingforblockheads:kitchen_floor:0)
Block(0,3,4,cookingforblockheads:kitchen_floor:0)
Block(0,3,5,contenttweaker:reinforced_concrete:0)
Block(0,3,6,biomesoplenty:sand:0)
Block(0,3,7,biomesoplenty:mud:0)
Block(0,3,8,STATIONARY_WATER:0)
Block(0,3,9,contenttweaker:reinforced_concrete:0)
Block(0,4,-6,contenttweaker:reinforced_concrete:0)
Block(0,4,-5,contenttweaker:reinforced_concrete:0)
RandomBlock(0,4,-4,variedcommodities:crate:5,5,charm:crate_sealed:5,100)
Block(0,4,-3,AIR:0)
Block(0,4,-2,inspirations:carpeted_trapdoor_gray:11)
Block(0,4,-1,variedcommodities:chair:5,f_bunker_mid/40-variedcommodities_chair.nbt)
Block(0,4,0,BOOKSHELF:0)
Block(0,4,1,AIR:0)
Block(0,4,2,cookingforblockheads:cooking_table:3,f_bunker_mid/41-cookingforblockheads_cooking_table.nbt)
Block(0,4,3,AIR:0)
Block(0,4,4,cookingforblockheads:fridge,f_bunker_mid/42-cookingforblockheads_fridge.nbt)
Block(0,4,5,contenttweaker:reinforced_concrete:0)
Block(0,4,6,AIR:0)
Block(0,4,7,AIR:0)
Block(0,4,8,AIR:0)
Block(0,4,9,contenttweaker:reinforced_concrete:0)
Block(0,5,-6,contenttweaker:reinforced_concrete:0)
Block(0,5,-5,CONCRETE:0)
RandomBlock(0,5,-4,variedcommodities:crate:5,5,charm:crate_sealed:5,100)
Block(0,5,-3,AIR:0)
Block(0,5,-2,AIR:0)
Block(0,5,-1,AIR:0)
Block(0,5,0,inspirations:carpeted_trapdoor_gray:11)
Block(0,5,1,AIR:0)
Block(0,5,2,AIR:0)
Block(0,5,3,AIR:0)
Block(0,5,4,cookingforblockheads:fridge,f_bunker_mid/44-cookingforblockheads_fridge.nbt)
Block(0,5,5,CONCRETE:0)
Block(0,5,6,AIR:0)
Block(0,5,7,AIR:0)
Block(0,5,8,AIR:0)
Block(0,5,9,contenttweaker:reinforced_concrete:0)
Block(0,6,-6,contenttweaker:reinforced_concrete:0)
Block(0,6,-5,contenttweaker:reinforced_concrete:0)
RandomBlock(0,6,-4,variedcommodities:crate:5,5,charm:crate_sealed:5,100)
Block(0,6,-3,AIR:0)
Block(0,6,-2,AIR:0)
Block(0,6,-1,AIR:0)
Block(0,6,0,variedcommodities:lamp_unlit,f_bunker_mid/46-variedcommodities_lamp.nbt)
Block(0,6,1,AIR:0)
Block(0,6,2,contentcreator:iron_plate_slab_reinforced:0)
Block(0,6,3,AIR:0)
Block(0,6,4,cookingforblockheads:cabinet_darkoak,../../../Chests/RLCraft/Containers/cooking_cabinet.nbt)
Block(0,6,5,contenttweaker:reinforced_concrete:0)
Block(0,6,6,contenttweaker:reinforced_concrete:0)
Block(0,6,7,contenttweaker:reinforced_concrete:0)
Block(0,6,8,contenttweaker:reinforced_concrete:0)
Block(0,6,9,contenttweaker:reinforced_concrete:0)
Block(0,7,-6,contenttweaker:reinforced_concrete:0)
Block(0,7,-5,contenttweaker:reinforced_concrete:0)
Block(0,7,-4,AIR:0)
Block(0,7,-3,STEP:8)
Block(0,7,-2,WEB:0)
Block(0,7,-1,AIR:0)
Block(0,7,0,AIR:0)
Block(0,7,1,AIR:0)
Block(0,7,2,AIR:0)
Block(0,7,3,AIR:0)
Block(0,7,4,AIR:0)
Block(0,7,5,contenttweaker:reinforced_concrete:0)
Block(0,7,6,contenttweaker:reinforced_concrete:0)
Block(0,7,7,contenttweaker:reinforced_concrete:0)
Block(0,7,8,contenttweaker:reinforced_concrete:0)
Block(0,7,9,contenttweaker:reinforced_concrete:0)
Block(0,8,-6,contenttweaker:reinforced_concrete:0)
Block(0,8,-5,contenttweaker:reinforced_concrete:0)
Block(0,8,-4,contenttweaker:reinforced_concrete:0)
Block(0,8,-3,contenttweaker:reinforced_concrete:0)
Block(0,8,-2,contenttweaker:reinforced_concrete:0)
Block(0,8,-1,contenttweaker:reinforced_concrete:0)
Block(0,8,0,contenttweaker:reinforced_concrete:0)
Block(0,8,1,contenttweaker:reinforced_concrete:0)
Block(0,8,2,contenttweaker:reinforced_concrete:0)
Block(0,8,3,contenttweaker:reinforced_concrete:0)
Block(0,8,4,contenttweaker:reinforced_concrete:0)
Block(0,8,5,contenttweaker:reinforced_concrete:0)
Block(0,8,6,WEB:0)
Block(0,8,7,variedcommodities:chair:5,f_bunker_mid/48-variedcommodities_chair.nbt)
Block(0,8,8,AIR:0)
Block(0,8,9,contenttweaker:reinforced_concrete:0)
Block(0,9,-6,contenttweaker:reinforced_concrete:0)
Block(0,9,-3,contenttweaker:reinforced_concrete:0)
Block(0,9,-1,contenttweaker:reinforced_concrete:0)
Block(0,9,0,contenttweaker:reinforced_concrete:0)
Block(0,9,1,contenttweaker:reinforced_concrete:0)
Block(0,9,2,contenttweaker:reinforced_concrete:0)
Block(0,9,3,contenttweaker:reinforced_concrete:0)
