
#######################################################################
# +-----------------------------------------------------------------+ #
# |                            BO4 object                           | #
# +-----------------------------------------------------------------+ #
#######################################################################

Author: NLBlackEagle

Description: No description given

SettingsMode: WriteWithoutComments


#######################################################################
# +-----------------------------------------------------------------+ #
# |                          Main settings                          | #
# +-----------------------------------------------------------------+ #
#######################################################################

FixedRotation: 

Frequency: 0

SpawnHeight: highestBlock

UseCenterForHighestBlock: true

##############################
# Height Limits for the BO4. #
##############################

MinHeight: 0

MaxHeight: 255

InheritBO3: 

InheritBO3Rotation: NORTH

OverrideChildSettings: true

OverrideParentHeight: false

CanOverride: false

BranchFrequency: 0

BranchFrequencyGroup: 

MustBeBelowOther: false

MustBeInside: 

CannotBeInside: 

ReplacesBO3: 

MustBeInsideWorldBorders: false

CanSpawnOnWater: true

SpawnOnWaterOnly: false

SpawnUnderWater: false

SpawnAtWaterLevel: false

HeightOffset: 0

RemoveAir: false

ReplaceAbove: 

ReplaceBelow: 

ReplaceWithBiomeBlocks: true

ReplaceWithSurfaceBlock: GRASS

ReplaceWithGroundBlock: DIRT

ReplaceWithStoneBlock: STONE

SmoothRadius: 0

SmoothHeightOffset: 0

SmoothStartTop: false

SmoothStartWood: false

SmoothingSurfaceBlock: 

SmoothingGroundBlock: 

BO3Group: 

IsSpawnPoint: false

DoReplaceBlocks: true


#######################################################################
# +-----------------------------------------------------------------+ #
# |                              Blocks                             | #
# +-----------------------------------------------------------------+ #
#######################################################################

Block(-7,0,-6,contenttweaker:reinforced_concrete:0)
Block(-7,0,-5,contenttweaker:reinforced_concrete:0)
Block(-7,0,-4,contenttweaker:reinforced_concrete:0)
Block(-7,0,-3,contenttweaker:reinforced_concrete:0)
Block(-7,0,-2,contenttweaker:reinforced_concrete:0)
Block(-7,0,-1,contenttweaker:reinforced_concrete:0)
Block(-7,0,0,contenttweaker:reinforced_concrete:0)
Block(-7,0,1,contenttweaker:reinforced_concrete:0)
Block(-7,0,2,contenttweaker:reinforced_concrete:0)
Block(-7,0,3,contenttweaker:reinforced_concrete:0)
Block(-7,0,4,contenttweaker:reinforced_concrete:0)
Block(-7,0,5,contenttweaker:reinforced_concrete:0)
Block(-7,0,6,contenttweaker:reinforced_concrete:0)
Block(-7,0,7,contenttweaker:reinforced_concrete:0)
Block(-7,0,8,contenttweaker:reinforced_concrete:0)
Block(-7,0,9,contenttweaker:reinforced_concrete:0)
Block(-7,1,-6,contenttweaker:reinforced_concrete:0)
Block(-7,1,-5,contenttweaker:reinforced_concrete:0)
Block(-7,1,-4,contenttweaker:reinforced_concrete:0)
Block(-7,1,-3,contenttweaker:reinforced_concrete:0)
Block(-7,1,-2,contenttweaker:reinforced_concrete:0)
Block(-7,1,-1,contenttweaker:reinforced_concrete:0)
Block(-7,1,0,contenttweaker:reinforced_concrete:0)
Block(-7,1,1,contenttweaker:reinforced_concrete:0)
Block(-7,1,2,contenttweaker:reinforced_concrete:0)
Block(-7,1,3,contenttweaker:reinforced_concrete:0)
Block(-7,1,4,contenttweaker:reinforced_concrete:0)
Block(-7,1,5,contenttweaker:reinforced_concrete:0)
Block(-7,1,6,contenttweaker:reinforced_concrete:0)
Block(-7,1,7,contenttweaker:reinforced_concrete:0)
Block(-7,1,8,contenttweaker:reinforced_concrete:0)
Block(-7,1,9,contenttweaker:reinforced_concrete:0)
Block(-7,2,-6,contenttweaker:reinforced_concrete:0)
Block(-7,2,-5,contenttweaker:reinforced_concrete:0)
Block(-7,2,-4,contenttweaker:reinforced_concrete:0)
Block(-7,2,-3,contenttweaker:reinforced_concrete:0)
Block(-7,2,-2,contenttweaker:reinforced_concrete:0)
Block(-7,2,-1,contenttweaker:reinforced_concrete:0)
Block(-7,2,0,contenttweaker:reinforced_concrete:0)
Block(-7,2,1,contenttweaker:reinforced_concrete:0)
Block(-7,2,2,contenttweaker:reinforced_concrete:0)
Block(-7,2,3,contenttweaker:reinforced_concrete:0)
Block(-7,2,4,contenttweaker:reinforced_concrete:0)
Block(-7,2,5,contenttweaker:reinforced_concrete:0)
Block(-7,2,6,contenttweaker:reinforced_concrete:0)
Block(-7,2,7,contenttweaker:reinforced_concrete:0)
Block(-7,2,8,contenttweaker:reinforced_concrete:0)
Block(-7,2,9,contenttweaker:reinforced_concrete:0)
Block(-7,3,-6,contenttweaker:reinforced_concrete:0)
Block(-7,3,-5,contenttweaker:reinforced_concrete:0)
Block(-7,3,-4,contenttweaker:reinforced_concrete:0)
Block(-7,3,-3,contenttweaker:reinforced_concrete:0)
Block(-7,3,-2,contenttweaker:reinforced_concrete:0)
Block(-7,3,-1,contenttweaker:reinforced_concrete:0)
Block(-7,3,0,contenttweaker:reinforced_concrete:0)
Block(-7,3,1,contenttweaker:reinforced_concrete:0)
Block(-7,3,2,contenttweaker:reinforced_concrete:0)
Block(-7,3,3,contenttweaker:reinforced_concrete:0)
Block(-7,3,4,contenttweaker:reinforced_concrete:0)
Block(-7,3,5,contenttweaker:reinforced_concrete:0)
Block(-7,3,6,contenttweaker:reinforced_concrete:0)
Block(-7,3,7,contenttweaker:reinforced_concrete:0)
Block(-7,3,8,contenttweaker:reinforced_concrete:0)
Block(-7,3,9,contenttweaker:reinforced_concrete:0)
Block(-7,4,-6,contenttweaker:reinforced_concrete:0)
Block(-7,4,-5,contenttweaker:reinforced_concrete:0)
Block(-7,4,-4,contenttweaker:reinforced_concrete:0)
Block(-7,4,-3,contenttweaker:reinforced_concrete:0)
Block(-7,4,-2,contenttweaker:reinforced_concrete:0)
Block(-7,4,-1,contenttweaker:reinforced_concrete:0)
Block(-7,4,0,contenttweaker:reinforced_concrete:0)
Block(-7,4,1,contenttweaker:reinforced_concrete:0)
Block(-7,4,2,contenttweaker:reinforced_concrete:0)
Block(-7,4,3,contenttweaker:reinforced_concrete:0)
Block(-7,4,4,contenttweaker:reinforced_concrete:0)
Block(-7,4,5,contenttweaker:reinforced_concrete:0)
Block(-7,4,6,contenttweaker:reinforced_concrete:0)
Block(-7,4,7,contenttweaker:reinforced_concrete:0)
Block(-7,4,8,contenttweaker:reinforced_concrete:0)
Block(-7,4,9,contenttweaker:reinforced_concrete:0)
Block(-7,5,-6,contenttweaker:reinforced_concrete:0)
Block(-7,5,-5,contenttweaker:reinforced_concrete:0)
Block(-7,5,-4,contenttweaker:reinforced_concrete:0)
Block(-7,5,-3,contenttweaker:reinforced_concrete:0)
Block(-7,5,-2,contenttweaker:reinforced_concrete:0)
Block(-7,5,-1,contenttweaker:reinforced_concrete:0)
Block(-7,5,0,contenttweaker:reinforced_concrete:0)
Block(-7,5,1,contenttweaker:reinforced_concrete:0)
Block(-7,5,2,contenttweaker:reinforced_concrete:0)
Block(-7,5,3,contenttweaker:reinforced_concrete:0)
Block(-7,5,4,contenttweaker:reinforced_concrete:0)
Block(-7,5,5,contenttweaker:reinforced_concrete:0)
Block(-7,5,6,contenttweaker:reinforced_concrete:0)
Block(-7,5,7,contenttweaker:reinforced_concrete:0)
Block(-7,5,8,contenttweaker:reinforced_concrete:0)
Block(-7,5,9,contenttweaker:reinforced_concrete:0)
Block(-7,6,-6,contenttweaker:reinforced_concrete:0)
Block(-7,6,-5,contenttweaker:reinforced_concrete:0)
Block(-7,6,-4,contenttweaker:reinforced_concrete:0)
Block(-7,6,-3,contenttweaker:reinforced_concrete:0)
Block(-7,6,-2,contenttweaker:reinforced_concrete:0)
Block(-7,6,-1,contenttweaker:reinforced_concrete:0)
Block(-7,6,0,contenttweaker:reinforced_concrete:0)
Block(-7,6,1,contenttweaker:reinforced_concrete:0)
Block(-7,6,2,contenttweaker:reinforced_concrete:0)
Block(-7,6,3,contenttweaker:reinforced_concrete:0)
Block(-7,6,4,contenttweaker:reinforced_concrete:0)
Block(-7,6,5,contenttweaker:reinforced_concrete:0)
Block(-7,6,6,contenttweaker:reinforced_concrete:0)
Block(-7,6,7,contenttweaker:reinforced_concrete:0)
Block(-7,6,8,contenttweaker:reinforced_concrete:0)
Block(-7,6,9,contenttweaker:reinforced_concrete:0)
Block(-7,7,-6,contenttweaker:reinforced_concrete:0)
Block(-7,7,-5,contenttweaker:reinforced_concrete:0)
Block(-7,7,-4,contenttweaker:reinforced_concrete:0)
Block(-7,7,-3,contenttweaker:reinforced_concrete:0)
Block(-7,7,-2,contenttweaker:reinforced_concrete:0)
Block(-7,7,-1,contenttweaker:reinforced_concrete:0)
Block(-7,7,0,contenttweaker:reinforced_concrete:0)
Block(-7,7,1,contenttweaker:reinforced_concrete:0)
Block(-7,7,2,contenttweaker:reinforced_concrete:0)
Block(-7,7,3,contenttweaker:reinforced_concrete:0)
Block(-7,7,4,contenttweaker:reinforced_concrete:0)
Block(-7,7,5,contenttweaker:reinforced_concrete:0)
Block(-7,7,6,contenttweaker:reinforced_concrete:0)
Block(-7,7,7,contenttweaker:reinforced_concrete:0)
Block(-7,7,8,contenttweaker:reinforced_concrete:0)
Block(-7,7,9,contenttweaker:reinforced_concrete:0)
Block(-7,8,-6,contenttweaker:reinforced_concrete:0)
Block(-7,8,-5,contenttweaker:reinforced_concrete:0)
Block(-7,8,-4,contenttweaker:reinforced_concrete:0)
Block(-7,8,-3,contenttweaker:reinforced_concrete:0)
Block(-7,8,-2,contenttweaker:reinforced_concrete:0)
Block(-7,8,-1,contenttweaker:reinforced_concrete:0)
Block(-7,8,0,contenttweaker:reinforced_concrete:0)
Block(-7,8,1,contenttweaker:reinforced_concrete:0)
Block(-7,8,2,contenttweaker:reinforced_concrete:0)
Block(-7,8,3,contenttweaker:reinforced_concrete:0)
Block(-7,8,4,contenttweaker:reinforced_concrete:0)
Block(-7,8,5,contenttweaker:reinforced_concrete:0)
Block(-7,8,6,contenttweaker:reinforced_concrete:0)
Block(-7,8,7,contenttweaker:reinforced_concrete:0)
Block(-7,8,8,contenttweaker:reinforced_concrete:0)
Block(-7,8,9,contenttweaker:reinforced_concrete:0)
Block(-7,9,-6,contenttweaker:reinforced_concrete:0)
Block(-7,9,-5,contenttweaker:reinforced_concrete:0)
Block(-7,9,-4,contenttweaker:reinforced_concrete:0)
Block(-7,9,-3,contenttweaker:reinforced_concrete:0)
Block(-7,9,-2,contenttweaker:reinforced_concrete:0)
Block(-7,9,-1,contenttweaker:reinforced_concrete:0)
Block(-7,9,0,contenttweaker:reinforced_concrete:0)
Block(-7,9,1,contenttweaker:reinforced_concrete:0)
Block(-7,9,2,contenttweaker:reinforced_concrete:0)
Block(-7,9,3,contenttweaker:reinforced_concrete:0)
Block(-7,9,4,contenttweaker:reinforced_concrete:0)
Block(-7,9,5,contenttweaker:reinforced_concrete:0)
Block(-7,9,6,contenttweaker:reinforced_concrete:0)
Block(-7,9,7,contenttweaker:reinforced_concrete:0)
Block(-7,9,8,contenttweaker:reinforced_concrete:0)
Block(-7,9,9,contenttweaker:reinforced_concrete:0)
Block(-7,10,-6,contenttweaker:reinforced_concrete:0)
Block(-7,10,-5,contenttweaker:reinforced_concrete:0)
Block(-7,10,-4,contenttweaker:reinforced_concrete:0)
Block(-7,10,-3,contenttweaker:reinforced_concrete:0)
Block(-7,10,-2,contenttweaker:reinforced_concrete:0)
Block(-7,10,-1,contenttweaker:reinforced_concrete:0)
Block(-7,10,0,contenttweaker:reinforced_concrete:0)
Block(-7,10,1,contenttweaker:reinforced_concrete:0)
Block(-7,10,2,contenttweaker:reinforced_concrete:0)
Block(-7,10,3,contenttweaker:reinforced_concrete:0)
Block(-7,10,4,contenttweaker:reinforced_concrete:0)
Block(-7,10,5,contenttweaker:reinforced_concrete:0)
Block(-7,10,6,contenttweaker:reinforced_concrete:0)
Block(-7,10,7,contenttweaker:reinforced_concrete:0)
Block(-7,10,8,contenttweaker:reinforced_concrete:0)
Block(-7,10,9,contenttweaker:reinforced_concrete:0)
Block(-7,11,-6,contenttweaker:reinforced_concrete:0)
Block(-7,11,-5,contenttweaker:reinforced_concrete:0)
Block(-7,11,-4,contenttweaker:reinforced_concrete:0)
Block(-7,11,-3,contenttweaker:reinforced_concrete:0)
Block(-7,11,-2,contenttweaker:reinforced_concrete:0)
Block(-7,11,-1,contenttweaker:reinforced_concrete:0)
Block(-7,11,0,contenttweaker:reinforced_concrete:0)
Block(-7,11,1,contenttweaker:reinforced_concrete:0)
Block(-7,11,2,contenttweaker:reinforced_concrete:0)
Block(-7,11,3,contenttweaker:reinforced_concrete:0)
Block(-7,11,4,contenttweaker:reinforced_concrete:0)
Block(-7,11,5,contenttweaker:reinforced_concrete:0)
Block(-7,11,6,contenttweaker:reinforced_concrete:0)
Block(-7,11,7,contenttweaker:reinforced_concrete:0)
Block(-7,11,8,contenttweaker:reinforced_concrete:0)
Block(-7,11,9,contenttweaker:reinforced_concrete:0)
Block(-7,12,-6,contenttweaker:reinforced_concrete:0)
Block(-7,12,-5,contenttweaker:reinforced_concrete:0)
Block(-7,12,-4,contenttweaker:reinforced_concrete:0)
Block(-7,12,-3,contenttweaker:reinforced_concrete:0)
Block(-7,12,-2,contenttweaker:reinforced_concrete:0)
Block(-7,12,-1,contenttweaker:reinforced_concrete:0)
Block(-7,12,0,contenttweaker:reinforced_concrete:0)
Block(-7,12,1,contenttweaker:reinforced_concrete:0)
Block(-7,12,2,contenttweaker:reinforced_concrete:0)
Block(-7,12,3,contenttweaker:reinforced_concrete:0)
Block(-7,12,4,contenttweaker:reinforced_concrete:0)
Block(-7,12,5,contenttweaker:reinforced_concrete:0)
Block(-7,12,6,contenttweaker:reinforced_concrete:0)
Block(-7,12,7,contenttweaker:reinforced_concrete:0)
Block(-7,12,8,contenttweaker:reinforced_concrete:0)
Block(-7,12,9,contenttweaker:reinforced_concrete:0)
Block(-7,13,-6,contenttweaker:reinforced_concrete:0)
Block(-7,13,-5,contenttweaker:reinforced_concrete:0)
Block(-7,13,-4,contenttweaker:reinforced_concrete:0)
Block(-7,13,-3,contenttweaker:reinforced_concrete:0)
Block(-7,13,-2,contenttweaker:reinforced_concrete:0)
Block(-7,13,-1,contenttweaker:reinforced_concrete:0)
Block(-7,13,0,contenttweaker:reinforced_concrete:0)
Block(-7,13,1,contenttweaker:reinforced_concrete:0)
Block(-7,13,2,contenttweaker:reinforced_concrete:0)
Block(-7,13,3,contenttweaker:reinforced_concrete:0)
Block(-7,13,4,contenttweaker:reinforced_concrete:0)
Block(-7,13,5,contenttweaker:reinforced_concrete:0)
Block(-7,13,6,contenttweaker:reinforced_concrete:0)
Block(-7,13,7,contenttweaker:reinforced_concrete:0)
Block(-7,13,8,contenttweaker:reinforced_concrete:0)
Block(-7,13,9,contenttweaker:reinforced_concrete:0)
Block(-7,14,-6,contenttweaker:reinforced_concrete:0)
Block(-7,14,-5,contenttweaker:reinforced_concrete:0)
Block(-7,14,-4,contenttweaker:reinforced_concrete:0)
Block(-7,14,-3,contenttweaker:reinforced_concrete:0)
Block(-7,14,-2,contenttweaker:reinforced_concrete:0)
Block(-7,14,-1,contenttweaker:reinforced_concrete:0)
Block(-7,14,0,contenttweaker:reinforced_concrete:0)
Block(-7,14,1,contenttweaker:reinforced_concrete:0)
Block(-7,14,2,contenttweaker:reinforced_concrete:0)
Block(-7,14,3,contenttweaker:reinforced_concrete:0)
Block(-7,14,4,contenttweaker:reinforced_concrete:0)
Block(-7,14,5,contenttweaker:reinforced_concrete:0)
Block(-7,14,6,contenttweaker:reinforced_concrete:0)
Block(-7,14,7,contenttweaker:reinforced_concrete:0)
Block(-7,14,8,contenttweaker:reinforced_concrete:0)
Block(-7,14,9,contenttweaker:reinforced_concrete:0)
Block(-7,15,-6,contenttweaker:reinforced_concrete:0)
Block(-7,15,-5,contenttweaker:reinforced_concrete:0)
Block(-7,15,-4,contenttweaker:reinforced_concrete:0)
Block(-7,15,-3,contenttweaker:reinforced_concrete:0)
Block(-7,15,-2,contenttweaker:reinforced_concrete:0)
Block(-7,15,-1,contenttweaker:reinforced_concrete:0)
Block(-7,15,0,contenttweaker:reinforced_concrete:0)
Block(-7,15,1,contenttweaker:reinforced_concrete:0)
Block(-7,15,2,contenttweaker:reinforced_concrete:0)
Block(-7,15,3,contenttweaker:reinforced_concrete:0)
Block(-7,15,4,contenttweaker:reinforced_concrete:0)
Block(-7,15,5,contenttweaker:reinforced_concrete:0)
Block(-7,15,6,contenttweaker:reinforced_concrete:0)
Block(-7,15,7,contenttweaker:reinforced_concrete:0)
Block(-7,15,8,contenttweaker:reinforced_concrete:0)
Block(-7,15,9,contenttweaker:reinforced_concrete:0)
Block(-7,16,-6,contenttweaker:reinforced_concrete:0)
Block(-7,16,-5,contenttweaker:reinforced_concrete:0)
Block(-7,16,-4,contenttweaker:reinforced_concrete:0)
Block(-7,16,-3,contenttweaker:reinforced_concrete:0)
Block(-7,16,-2,contenttweaker:reinforced_concrete:0)
Block(-7,16,-1,contenttweaker:reinforced_concrete:0)
Block(-7,16,0,contenttweaker:reinforced_concrete:0)
Block(-7,16,1,contenttweaker:reinforced_concrete:0)
Block(-7,16,2,contenttweaker:reinforced_concrete:0)
Block(-7,16,3,contenttweaker:reinforced_concrete:0)
Block(-7,16,4,contenttweaker:reinforced_concrete:0)
Block(-7,16,5,contenttweaker:reinforced_concrete:0)
Block(-7,16,6,contenttweaker:reinforced_concrete:0)
Block(-7,16,7,contenttweaker:reinforced_concrete:0)
Block(-7,16,8,contenttweaker:reinforced_concrete:0)
Block(-7,16,9,contenttweaker:reinforced_concrete:0)
Block(-7,17,-6,contenttweaker:reinforced_concrete:0)
Block(-7,17,-5,contenttweaker:reinforced_concrete:0)
Block(-7,17,-4,contenttweaker:reinforced_concrete:0)
Block(-7,17,-3,contenttweaker:reinforced_concrete:0)
Block(-7,17,-2,contenttweaker:reinforced_concrete:0)
Block(-7,17,-1,contenttweaker:reinforced_concrete:0)
Block(-7,17,0,contenttweaker:reinforced_concrete:0)
Block(-7,17,1,contenttweaker:reinforced_concrete:0)
Block(-7,17,2,contenttweaker:reinforced_concrete:0)
Block(-7,17,3,contenttweaker:reinforced_concrete:0)
Block(-7,17,4,contenttweaker:reinforced_concrete:0)
Block(-7,17,5,contenttweaker:reinforced_concrete:0)
Block(-7,17,6,contenttweaker:reinforced_concrete:0)
Block(-7,17,7,contenttweaker:reinforced_concrete:0)
Block(-7,17,8,contenttweaker:reinforced_concrete:0)
Block(-7,17,9,contenttweaker:reinforced_concrete:0)
Block(-7,18,-6,contenttweaker:reinforced_concrete:0)
Block(-7,18,-5,contenttweaker:reinforced_concrete:0)
Block(-7,18,-4,contenttweaker:reinforced_concrete:0)
Block(-7,18,-3,contenttweaker:reinforced_concrete:0)
Block(-7,18,-2,contenttweaker:reinforced_concrete:0)
Block(-7,18,-1,contenttweaker:reinforced_concrete:0)
Block(-7,18,0,contenttweaker:reinforced_concrete:0)
Block(-7,18,1,contenttweaker:reinforced_concrete:0)
Block(-7,18,2,contenttweaker:reinforced_concrete:0)
Block(-7,18,3,contenttweaker:reinforced_concrete:0)
Block(-7,18,4,contenttweaker:reinforced_concrete:0)
Block(-7,18,5,contenttweaker:reinforced_concrete:0)
Block(-7,18,6,contenttweaker:reinforced_concrete:0)
Block(-7,18,7,contenttweaker:reinforced_concrete:0)
Block(-7,18,8,contenttweaker:reinforced_concrete:0)
Block(-7,18,9,contenttweaker:reinforced_concrete:0)
Block(-7,19,-6,contenttweaker:reinforced_concrete:0)
Block(-7,19,-5,contenttweaker:reinforced_concrete:0)
Block(-7,19,-4,contenttweaker:reinforced_concrete:0)
Block(-7,19,-3,contenttweaker:reinforced_concrete:0)
Block(-7,19,-2,contenttweaker:reinforced_concrete:0)
Block(-7,19,-1,contenttweaker:reinforced_concrete:0)
Block(-7,19,0,contenttweaker:reinforced_concrete:0)
Block(-7,19,1,contenttweaker:reinforced_concrete:0)
Block(-7,19,2,contenttweaker:reinforced_concrete:0)
Block(-7,19,3,contenttweaker:reinforced_concrete:0)
Block(-7,19,4,contenttweaker:reinforced_concrete:0)
Block(-7,19,5,contenttweaker:reinforced_concrete:0)
Block(-7,19,6,contenttweaker:reinforced_concrete:0)
Block(-7,19,7,contenttweaker:reinforced_concrete:0)
Block(-7,19,8,contenttweaker:reinforced_concrete:0)
Block(-7,19,9,contenttweaker:reinforced_concrete:0)
Block(-7,20,-6,contenttweaker:reinforced_concrete:0)
Block(-7,20,-5,contenttweaker:reinforced_concrete:0)
Block(-7,20,-4,contenttweaker:reinforced_concrete:0)
Block(-7,20,-3,contenttweaker:reinforced_concrete:0)
Block(-7,20,-2,contenttweaker:reinforced_concrete:0)
Block(-7,20,-1,contenttweaker:reinforced_concrete:0)
Block(-7,20,0,contenttweaker:reinforced_concrete:0)
Block(-7,20,1,contenttweaker:reinforced_concrete:0)
Block(-7,20,2,contenttweaker:reinforced_concrete:0)
Block(-7,20,3,contenttweaker:reinforced_concrete:0)
Block(-7,20,4,contenttweaker:reinforced_concrete:0)
Block(-7,20,5,contenttweaker:reinforced_concrete:0)
Block(-7,20,6,contenttweaker:reinforced_concrete:0)
Block(-7,20,7,contenttweaker:reinforced_concrete:0)
Block(-7,20,8,contenttweaker:reinforced_concrete:0)
Block(-7,20,9,contenttweaker:reinforced_concrete:0)
Block(-7,21,-6,contenttweaker:reinforced_concrete:0)
Block(-7,21,-5,contenttweaker:reinforced_concrete:0)
Block(-7,21,-4,contenttweaker:reinforced_concrete:0)
Block(-7,21,-3,contenttweaker:reinforced_concrete:0)
Block(-7,21,-2,contenttweaker:reinforced_concrete:0)
Block(-7,21,-1,contenttweaker:reinforced_concrete:0)
Block(-7,21,0,contenttweaker:reinforced_concrete:0)
Block(-7,21,1,contenttweaker:reinforced_concrete:0)
Block(-7,21,2,contenttweaker:reinforced_concrete:0)
Block(-7,21,3,contenttweaker:reinforced_concrete:0)
Block(-7,21,4,contenttweaker:reinforced_concrete:0)
Block(-7,21,5,contenttweaker:reinforced_concrete:0)
Block(-7,21,6,contenttweaker:reinforced_concrete:0)
Block(-7,21,7,contenttweaker:reinforced_concrete:0)
Block(-7,21,8,contenttweaker:reinforced_concrete:0)
Block(-7,21,9,contenttweaker:reinforced_concrete:0)
Block(-7,22,-6,contenttweaker:reinforced_concrete:0)
Block(-7,22,-5,contenttweaker:reinforced_concrete:0)
Block(-7,22,-4,contenttweaker:reinforced_concrete:0)
Block(-7,22,-3,contenttweaker:reinforced_concrete:0)
Block(-7,22,-2,contenttweaker:reinforced_concrete:0)
Block(-7,22,-1,contenttweaker:reinforced_concrete:0)
Block(-7,22,0,contenttweaker:reinforced_concrete:0)
Block(-7,22,1,contenttweaker:reinforced_concrete:0)
Block(-7,22,2,contenttweaker:reinforced_concrete:0)
Block(-7,22,3,contenttweaker:reinforced_concrete:0)
Block(-7,22,4,contenttweaker:reinforced_concrete:0)
Block(-7,22,5,contenttweaker:reinforced_concrete:0)
Block(-7,22,6,contenttweaker:reinforced_concrete:0)
Block(-7,22,7,contenttweaker:reinforced_concrete:0)
Block(-7,22,8,contenttweaker:reinforced_concrete:0)
Block(-7,22,9,contenttweaker:reinforced_concrete:0)
Block(-7,23,-6,contenttweaker:reinforced_concrete:0)
Block(-7,23,-5,contenttweaker:reinforced_concrete:0)
Block(-7,23,-4,contenttweaker:reinforced_concrete:0)
Block(-7,23,-3,contenttweaker:reinforced_concrete:0)
Block(-7,23,-2,contenttweaker:reinforced_concrete:0)
Block(-7,23,-1,contenttweaker:reinforced_concrete:0)
Block(-7,23,0,contenttweaker:reinforced_concrete:0)
Block(-7,23,1,contenttweaker:reinforced_concrete:0)
Block(-7,23,2,contenttweaker:reinforced_concrete:0)
Block(-7,23,3,contenttweaker:reinforced_concrete:0)
Block(-7,23,4,contenttweaker:reinforced_concrete:0)
Block(-7,23,5,contenttweaker:reinforced_concrete:0)
Block(-7,23,6,contenttweaker:reinforced_concrete:0)
Block(-7,23,7,contenttweaker:reinforced_concrete:0)
Block(-7,23,8,contenttweaker:reinforced_concrete:0)
Block(-7,23,9,contenttweaker:reinforced_concrete:0)
Block(-7,24,-6,contenttweaker:reinforced_concrete:0)
Block(-7,24,-5,contenttweaker:reinforced_concrete:0)
Block(-7,24,-4,contenttweaker:reinforced_concrete:0)
Block(-7,24,-3,contenttweaker:reinforced_concrete:0)
Block(-7,24,-2,contenttweaker:reinforced_concrete:0)
Block(-7,24,-1,contenttweaker:reinforced_concrete:0)
Block(-7,24,0,contenttweaker:reinforced_concrete:0)
Block(-7,24,1,contenttweaker:reinforced_concrete:0)
Block(-7,24,2,contenttweaker:reinforced_concrete:0)
Block(-7,24,3,contenttweaker:reinforced_concrete:0)
Block(-7,24,4,contenttweaker:reinforced_concrete:0)
Block(-7,24,5,contenttweaker:reinforced_concrete:0)
Block(-7,24,6,contenttweaker:reinforced_concrete:0)
Block(-7,24,7,contenttweaker:reinforced_concrete:0)
Block(-7,24,8,contenttweaker:reinforced_concrete:0)
Block(-7,24,9,contenttweaker:reinforced_concrete:0)
Block(-7,25,-6,contenttweaker:reinforced_concrete:0)
Block(-7,25,-5,contenttweaker:reinforced_concrete:0)
Block(-7,25,-4,contenttweaker:reinforced_concrete:0)
Block(-7,25,-3,contenttweaker:reinforced_concrete:0)
Block(-7,25,-2,contenttweaker:reinforced_concrete:0)
Block(-7,25,-1,contenttweaker:reinforced_concrete:0)
Block(-7,25,0,contenttweaker:reinforced_concrete:0)
Block(-7,25,1,contenttweaker:reinforced_concrete:0)
Block(-7,25,2,contenttweaker:reinforced_concrete:0)
Block(-7,25,3,contenttweaker:reinforced_concrete:0)
Block(-7,25,4,contenttweaker:reinforced_concrete:0)
Block(-7,25,5,contenttweaker:reinforced_concrete:0)
Block(-7,25,6,contenttweaker:reinforced_concrete:0)
Block(-7,25,7,contenttweaker:reinforced_concrete:0)
Block(-7,25,8,contenttweaker:reinforced_concrete:0)
Block(-7,25,9,contenttweaker:reinforced_concrete:0)
Block(-7,26,-6,contenttweaker:reinforced_concrete:0)
Block(-7,26,-5,contenttweaker:reinforced_concrete:0)
Block(-7,26,-4,contenttweaker:reinforced_concrete:0)
Block(-7,26,-3,contenttweaker:reinforced_concrete:0)
Block(-7,26,-2,contenttweaker:reinforced_concrete:0)
Block(-7,26,-1,contenttweaker:reinforced_concrete:0)
Block(-7,26,0,contenttweaker:reinforced_concrete:0)
Block(-7,26,1,contenttweaker:reinforced_concrete:0)
Block(-7,26,2,contenttweaker:reinforced_concrete:0)
Block(-7,26,3,contenttweaker:reinforced_concrete:0)
Block(-7,26,4,contenttweaker:reinforced_concrete:0)
Block(-7,26,5,contenttweaker:reinforced_concrete:0)
Block(-7,26,6,contenttweaker:reinforced_concrete:0)
Block(-7,26,7,contenttweaker:reinforced_concrete:0)
Block(-7,26,8,contenttweaker:reinforced_concrete:0)
Block(-7,26,9,contenttweaker:reinforced_concrete:0)
Block(-7,27,-6,contenttweaker:reinforced_concrete:0)
Block(-7,27,-5,contenttweaker:reinforced_concrete:0)
Block(-7,27,-4,contenttweaker:reinforced_concrete:0)
Block(-7,27,-3,contenttweaker:reinforced_concrete:0)
Block(-7,27,-2,contenttweaker:reinforced_concrete:0)
Block(-7,27,-1,contenttweaker:reinforced_concrete:0)
Block(-7,27,0,contenttweaker:reinforced_concrete:0)
Block(-7,27,1,contenttweaker:reinforced_concrete:0)
Block(-7,27,2,contenttweaker:reinforced_concrete:0)
Block(-7,27,3,contenttweaker:reinforced_concrete:0)
Block(-7,27,4,contenttweaker:reinforced_concrete:0)
Block(-7,27,5,contenttweaker:reinforced_concrete:0)
Block(-7,27,6,contenttweaker:reinforced_concrete:0)
Block(-7,27,7,contenttweaker:reinforced_concrete:0)
Block(-7,27,8,contenttweaker:reinforced_concrete:0)
Block(-7,27,9,contenttweaker:reinforced_concrete:0)
Block(-7,28,-6,contenttweaker:reinforced_concrete:0)
Block(-7,28,-5,contenttweaker:reinforced_concrete:0)
Block(-7,28,-4,contenttweaker:reinforced_concrete:0)
Block(-7,28,-3,contenttweaker:reinforced_concrete:0)
Block(-7,28,-2,contenttweaker:reinforced_concrete:0)
Block(-7,28,-1,contenttweaker:reinforced_concrete:0)
Block(-7,28,0,contenttweaker:reinforced_concrete:0)
Block(-7,28,1,contenttweaker:reinforced_concrete:0)
Block(-7,28,2,contenttweaker:reinforced_concrete:0)
Block(-7,28,3,contenttweaker:reinforced_concrete:0)
Block(-7,28,4,contenttweaker:reinforced_concrete:0)
Block(-7,28,5,contenttweaker:reinforced_concrete:0)
Block(-7,28,6,contenttweaker:reinforced_concrete:0)
Block(-7,28,7,contenttweaker:reinforced_concrete:0)
Block(-7,28,8,contenttweaker:reinforced_concrete:0)
Block(-7,28,9,contenttweaker:reinforced_concrete:0)
Block(-7,29,-6,contenttweaker:reinforced_concrete:0)
Block(-7,29,-5,contenttweaker:reinforced_concrete:0)
Block(-7,29,-4,contenttweaker:reinforced_concrete:0)
Block(-7,29,-3,contenttweaker:reinforced_concrete:0)
Block(-7,29,-2,contenttweaker:reinforced_concrete:0)
Block(-7,29,-1,contenttweaker:reinforced_concrete:0)
Block(-7,29,0,contenttweaker:reinforced_concrete:0)
Block(-7,29,1,contenttweaker:reinforced_concrete:0)
Block(-7,29,2,contenttweaker:reinforced_concrete:0)
Block(-7,29,3,contenttweaker:reinforced_concrete:0)
Block(-7,29,4,contenttweaker:reinforced_concrete:0)
Block(-7,29,5,contenttweaker:reinforced_concrete:0)
Block(-7,29,6,contenttweaker:reinforced_concrete:0)
Block(-7,29,7,contenttweaker:reinforced_concrete:0)
Block(-7,29,8,contenttweaker:reinforced_concrete:0)
Block(-7,29,9,contenttweaker:reinforced_concrete:0)
Block(-7,30,-6,contenttweaker:reinforced_concrete:0)
Block(-7,30,-5,contenttweaker:reinforced_concrete:0)
Block(-7,30,-4,contenttweaker:reinforced_concrete:0)
Block(-7,30,-3,contenttweaker:reinforced_concrete:0)
Block(-7,30,-2,contenttweaker:reinforced_concrete:0)
Block(-7,30,-1,contenttweaker:reinforced_concrete:0)
Block(-7,30,0,contenttweaker:reinforced_concrete:0)
Block(-7,30,1,contenttweaker:reinforced_concrete:0)
Block(-7,30,2,contenttweaker:reinforced_concrete:0)
Block(-7,30,3,contenttweaker:reinforced_concrete:0)
Block(-7,31,-6,contenttweaker:reinforced_concrete:0)
Block(-7,31,-5,contenttweaker:reinforced_concrete:0)
Block(-7,31,-4,contenttweaker:reinforced_concrete:0)
Block(-7,31,-3,contenttweaker:reinforced_concrete:0)
Block(-7,31,-2,contenttweaker:reinforced_concrete:0)
Block(-7,31,-1,contenttweaker:reinforced_concrete:0)
Block(-7,31,0,contenttweaker:reinforced_concrete:0)
Block(-7,31,1,contenttweaker:reinforced_concrete:0)
Block(-7,31,2,contenttweaker:reinforced_concrete:0)
Block(-7,31,3,contenttweaker:reinforced_concrete:0)
Block(-7,32,-6,contenttweaker:reinforced_concrete:0)
Block(-7,32,-5,contenttweaker:reinforced_concrete:0)
Block(-7,32,-4,contenttweaker:reinforced_concrete:0)
Block(-7,32,-3,contenttweaker:reinforced_concrete:0)
Block(-7,32,-2,contenttweaker:reinforced_concrete:0)
Block(-7,32,-1,contenttweaker:reinforced_concrete:0)
Block(-7,32,0,contenttweaker:reinforced_concrete:0)
Block(-7,32,1,contenttweaker:reinforced_concrete:0)
Block(-7,32,2,contenttweaker:reinforced_concrete:0)
Block(-7,32,3,contenttweaker:reinforced_concrete:0)
Block(-7,33,-6,contenttweaker:reinforced_concrete:0)
Block(-7,33,-5,contenttweaker:reinforced_concrete:0)
Block(-7,33,-4,contenttweaker:reinforced_concrete:0)
Block(-7,33,-3,contenttweaker:reinforced_concrete:0)
Block(-7,33,-2,contenttweaker:reinforced_concrete:0)
Block(-7,33,-1,contenttweaker:reinforced_concrete:0)
Block(-7,33,0,contenttweaker:reinforced_concrete:0)
Block(-7,33,1,contenttweaker:reinforced_concrete:0)
Block(-7,33,2,contenttweaker:reinforced_concrete:0)
Block(-7,33,3,contenttweaker:reinforced_concrete:0)
Block(-6,0,-6,contenttweaker:reinforced_concrete:0)
Block(-6,0,-5,contenttweaker:reinforced_concrete:0)
Block(-6,0,-4,contenttweaker:reinforced_concrete:0)
Block(-6,0,-3,contenttweaker:reinforced_concrete:0)
Block(-6,0,-2,contenttweaker:reinforced_concrete:0)
Block(-6,0,-1,contenttweaker:reinforced_concrete:0)
Block(-6,0,0,contenttweaker:reinforced_concrete:0)
Block(-6,0,1,contenttweaker:reinforced_concrete:0)
Block(-6,0,2,contenttweaker:reinforced_concrete:0)
Block(-6,0,3,contenttweaker:reinforced_concrete:0)
Block(-6,0,4,contenttweaker:reinforced_concrete:0)
Block(-6,0,5,contenttweaker:reinforced_concrete:0)
Block(-6,0,6,contenttweaker:reinforced_concrete:0)
Block(-6,0,7,contenttweaker:reinforced_concrete:0)
Block(-6,0,8,contenttweaker:reinforced_concrete:0)
Block(-6,0,9,contenttweaker:reinforced_concrete:0)
Block(-6,1,-6,contenttweaker:reinforced_concrete:0)
Block(-6,1,-5,contenttweaker:reinforced_concrete:0)
Block(-6,1,-4,contenttweaker:reinforced_concrete:0)
Block(-6,1,-3,contenttweaker:reinforced_concrete:0)
Block(-6,1,-2,contenttweaker:reinforced_concrete:0)
Block(-6,1,-1,STATIONARY_WATER:0)
Block(-6,1,0,STATIONARY_WATER:0)
Block(-6,1,1,STATIONARY_WATER:0)
Block(-6,1,2,STATIONARY_WATER:0)
Block(-6,1,3,STATIONARY_WATER:0)
Block(-6,1,4,STATIONARY_WATER:0)
Block(-6,1,5,STATIONARY_WATER:0)
Block(-6,1,6,STATIONARY_WATER:0)
Block(-6,1,7,STATIONARY_WATER:0)
Block(-6,1,8,STATIONARY_WATER:0)
Block(-6,1,9,contenttweaker:reinforced_concrete:0)
Block(-6,2,-6,contenttweaker:reinforced_concrete:0)
Block(-6,2,-5,contentcreator:iron_plate_slab_reinforced:1)
Block(-6,2,-4,inspirations:path:0)
Block(-6,2,-3,AIR:0)
Block(-6,2,-2,contentcreator:iron_plate_stairs_reinforced:2)
Block(-6,2,-1,contentcreator:iron_plate_stairs_reinforced:7)
Block(-6,2,0,contentcreator:iron_plate_slab_reinforced:1)
Block(-6,2,1,contentcreator:iron_plate_slab_reinforced:1)
Block(-6,2,2,contentcreator:iron_plate_slab_reinforced:1)
Block(-6,2,3,contentcreator:iron_plate_slab_reinforced:1)
Block(-6,2,4,contentcreator:iron_plate_slab_reinforced:1)
Block(-6,2,5,contentcreator:iron_plate_slab_reinforced:1)
Block(-6,2,6,contentcreator:iron_plate_slab_reinforced:1)
Block(-6,2,7,contentcreator:iron_plate_slab_reinforced:1)
Block(-6,2,8,contentcreator:iron_plate_slab_reinforced:1)
Block(-6,2,9,contenttweaker:reinforced_concrete:0)
Block(-6,3,-6,contenttweaker:reinforced_concrete:0)
Block(-6,3,-5,cookingforblockheads:tool_rack:3,f_bunker_apartements/1-cookingforblockheads_tool_rack.nbt)
Block(-6,3,-4,AIR:0)
Block(-6,3,-3,AIR:0)
Block(-6,3,-2,AIR:0)
Block(-6,3,-1,AIR:0)
Block(-6,3,0,rustic:deathstalk_mushroom:0)
Block(-6,3,1,AIR:0)
Block(-6,3,2,AIR:0)
Block(-6,3,3,AIR:0)
Block(-6,3,4,AIR:0)
Block(-6,3,5,AIR:0)
Block(-6,3,6,AIR:0)
Block(-6,3,7,rustic:deathstalk_mushroom:0)
Block(-6,3,8,AIR:0)
Block(-6,3,9,contenttweaker:reinforced_concrete:0)
Block(-6,4,-6,contenttweaker:reinforced_concrete:0)
Block(-6,4,-5,WEB:0)
Block(-6,4,-4,AIR:0)
Block(-6,4,-3,AIR:0)
Block(-6,4,-2,AIR:0)
Block(-6,4,-1,AIR:0)
Block(-6,4,0,AIR:0)
Block(-6,4,1,AIR:0)
Block(-6,4,2,AIR:0)
Block(-6,4,3,AIR:0)
Block(-6,4,4,AIR:0)
Block(-6,4,5,AIR:0)
Block(-6,4,6,AIR:0)
Block(-6,4,7,AIR:0)
Block(-6,4,8,AIR:0)
Block(-6,4,9,contenttweaker:reinforced_concrete:0)
Block(-6,5,-6,contenttweaker:reinforced_concrete:0)
Block(-6,5,-5,contenttweaker:reinforced_concrete:0)
Block(-6,5,-4,contenttweaker:reinforced_concrete:0)
Block(-6,5,-3,contenttweaker:reinforced_concrete:0)
Block(-6,5,-2,contenttweaker:reinforced_concrete:0)
Block(-6,5,-1,contenttweaker:reinforced_concrete:0)
Block(-6,5,0,contenttweaker:reinforced_concrete:0)
Block(-6,5,1,contenttweaker:reinforced_concrete:0)
Block(-6,5,2,contenttweaker:reinforced_concrete:0)
Block(-6,5,3,contenttweaker:reinforced_concrete:0)
Block(-6,5,4,contenttweaker:reinforced_concrete:0)
Block(-6,5,5,contenttweaker:reinforced_concrete:0)
Block(-6,5,6,contenttweaker:reinforced_concrete:0)
Block(-6,5,7,contenttweaker:reinforced_concrete:0)
Block(-6,5,8,contenttweaker:reinforced_concrete:0)
Block(-6,5,9,contenttweaker:reinforced_concrete:0)
Block(-6,6,-6,contenttweaker:reinforced_concrete:0)
Block(-6,6,-5,cookingforblockheads:counter:8,../../../Chests/RLCraft/Containers/cooking_counter.nbt)
Block(-6,6,-4,contentcreator:iron_plate_stairs_reinforced:7)
Block(-6,6,-3,contentcreator:iron_plate_slab_reinforced:1)
Block(-6,6,-2,contentcreator:iron_plate_slab_reinforced:1)
Block(-6,6,-1,contentcreator:iron_plate_stairs_reinforced:6)
Block(-6,6,0,AIR:0)
Block(-6,6,1,notreepunching:loose_rock/stone:0)
Block(-6,6,2,contentcreator:iron_plate_stairs_reinforced:2)
Block(-6,6,3,quark:grate:0)
Block(-6,6,4,quark:grate:0)
Block(-6,6,5,contenttweaker:iron_plate_reinforced:0)
Block(-6,6,6,quark:grate:0)
Block(-6,6,7,quark:grate:0)
Block(-6,6,8,quark:grate:0)
Block(-6,6,9,contenttweaker:reinforced_concrete:0)
Block(-6,7,-6,contenttweaker:reinforced_concrete:0)
Block(-6,7,-5,cookingforblockheads:cabinet:8,../../../Chests/RLCraft/Containers/cooking_cabinet.nbt)
Block(-6,7,-4,cookingforblockheads:cabinet:8,../../../Chests/RLCraft/Containers/cooking_cabinet.nbt)
Block(-6,7,-3,cookingforblockheads:cabinet:0,../../../Chests/RLCraft/Containers/cooking_cabinet.nbt)
Block(-6,7,-2,cookingforblockheads:tool_rack:5,f_bunker_apartements/6-cookingforblockheads_tool_rack.nbt)
Block(-6,7,-1,cookingforblockheads:tool_rack:5,f_bunker_apartements/7-cookingforblockheads_tool_rack.nbt)
Block(-6,7,0,AIR:0)
Block(-6,7,1,AIR:0)
Block(-6,7,2,AIR:0)
Block(-6,7,3,AIR:0)
Block(-6,7,4,AIR:0)
Block(-6,7,5,AIR:0)
Block(-6,7,6,AIR:0)
Block(-6,7,7,AIR:0)
Block(-6,7,8,WEB:0)
Block(-6,7,9,contenttweaker:reinforced_concrete:0)
Block(-6,8,-6,contenttweaker:reinforced_concrete:0)
Block(-6,8,-5,cookingforblockheads:cabinet:8,../../../Chests/RLCraft/Containers/cooking_cabinet.nbt)
Block(-6,8,-4,cookingforblockheads:cabinet:8,../../../Chests/RLCraft/Containers/cooking_cabinet.nbt)
Block(-6,8,-3,cookingforblockheads:cabinet:0,../../../Chests/RLCraft/Containers/cooking_cabinet.nbt)
Block(-6,8,-2,cookingforblockheads:tool_rack:5,f_bunker_apartements/11-cookingforblockheads_tool_rack.nbt)
Block(-6,8,-1,cookingforblockheads:tool_rack:5,f_bunker_apartements/12-cookingforblockheads_tool_rack.nbt)
Block(-6,8,0,AIR:0)
Block(-6,8,1,AIR:0)
Block(-6,8,2,AIR:0)
Block(-6,8,3,AIR:0)
Block(-6,8,4,AIR:0)
Block(-6,8,5,contentcreator:iron_plate_slab_reinforced:1)
Block(-6,8,6,AIR:0)
Block(-6,8,7,AIR:0)
Block(-6,8,8,AIR:0)
Block(-6,8,9,contenttweaker:reinforced_concrete:0)
Block(-6,9,-6,contenttweaker:reinforced_concrete:0)
Block(-6,9,-5,contenttweaker:reinforced_concrete:0)
Block(-6,9,-4,contenttweaker:reinforced_concrete:0)
Block(-6,9,-3,contenttweaker:reinforced_concrete:0)
Block(-6,9,-2,contenttweaker:reinforced_concrete:0)
Block(-6,9,-1,contenttweaker:reinforced_concrete:0)
Block(-6,9,0,contenttweaker:reinforced_concrete:0)
Block(-6,9,1,contenttweaker:reinforced_concrete:0)
Block(-6,9,2,contenttweaker:reinforced_concrete:0)
Block(-6,9,3,contenttweaker:reinforced_concrete:0)
Block(-6,9,4,contenttweaker:reinforced_concrete:0)
Block(-6,9,5,contenttweaker:reinforced_concrete:0)
Block(-6,9,6,contenttweaker:reinforced_concrete:0)
Block(-6,9,7,contenttweaker:reinforced_concrete:0)
Block(-6,9,8,contenttweaker:reinforced_concrete:0)
Block(-6,9,9,contenttweaker:reinforced_concrete:0)
Block(-6,10,-6,contenttweaker:reinforced_concrete:0)
Block(-6,10,-5,contenttweaker:reinforced_concrete:0)
Block(-6,10,-4,contenttweaker:resource_crate:0)
RandomBlock(-6,10,-3,variedcommodities:crate:5,5,charm:crate_sealed:1,100)
Block(-6,10,-2,cookingforblockheads:spice_rack:5,f_bunker_apartements/14-cookingforblockheads_spice_rack.nbt)
Block(-6,10,-1,contenttweaker:reinforced_concrete:0)
RandomBlock(-6,10,0,variedcommodities:crate:5,5,charm:crate_sealed:5,100)
RandomBlock(-6,10,1,variedcommodities:crate:5,5,charm:crate_sealed:5,100)
Block(-6,10,2,cookingforblockheads:cabinet_spruce:0,../../../Chests/RLCraft/Containers/cooking_cabinet.nbt)
Block(-6,10,3,contenttweaker:reinforced_concrete:0)
Block(-6,10,4,contenttweaker:resource_crate:0)
Block(-6,10,5,contenttweaker:reinforced_concrete:0)
Block(-6,10,6,contenttweaker:iron_plate_reinforced:0)
Block(-6,10,7,contenttweaker:iron_plate_reinforced:0)
Block(-6,10,8,contenttweaker:reinforced_concrete:0)
Block(-6,10,9,contenttweaker:reinforced_concrete:0)
Block(-6,11,-6,contenttweaker:reinforced_concrete:0)
Block(-6,11,-5,contenttweaker:reinforced_concrete:0)
RandomBlock(-6,11,-4,variedcommodities:crate:5,5,charm:crate_sealed:1,100)
Block(-6,11,-3,CHEST:5,../../../Chests/RLCraft/Ruins/starter.nbt)
Block(-6,11,-2,cookingforblockheads:spice_rack:5,f_bunker_apartements/20-cookingforblockheads_spice_rack.nbt)
Block(-6,11,-1,contenttweaker:reinforced_concrete:0)
RandomBlock(-6,11,0,variedcommodities:crate:5,5,charm:crate_sealed:5,100)
Block(-6,11,1,inspirations:bookshelf:15,f_bunker_apartements/22-inspirations_bookshelf.nbt)
Block(-6,11,2,variedcommodities:shelf:1,f_bunker_apartements/23-variedcommodities_shelf.nbt)
Block(-6,11,3,contenttweaker:reinforced_concrete:0)
Block(-6,11,4,inspirations:bookshelf:15,f_bunker_apartements/24-inspirations_bookshelf.nbt)
Block(-6,11,5,contenttweaker:reinforced_concrete:0)
Block(-6,11,6,contenttweaker:iron_plate_reinforced:0)
Block(-6,11,7,contenttweaker:iron_plate_reinforced:0)
Block(-6,11,8,contenttweaker:reinforced_concrete:0)
Block(-6,11,9,contenttweaker:reinforced_concrete:0)
Block(-6,12,-6,contenttweaker:reinforced_concrete:0)
Block(-6,12,-5,contenttweaker:reinforced_concrete:0)
Block(-6,12,-4,AIR:0)
Block(-6,12,-3,AIR:0)
Block(-6,12,-2,AIR:0)
Block(-6,12,-1,contenttweaker:reinforced_concrete:0)
Block(-6,12,0,cookingforblockheads:cabinet_spruce:8,../../../Chests/RLCraft/Containers/cooking_cabinet.nbt)
Block(-6,12,1,AIR:0)
Block(-6,12,2,AIR:0)
Block(-6,12,3,contenttweaker:reinforced_concrete:0)
Block(-6,12,4,inspirations:bookshelf:15,f_bunker_apartements/26-inspirations_bookshelf.nbt)
Block(-6,12,5,contenttweaker:reinforced_concrete:0)
Block(-6,12,6,contenttweaker:iron_plate_reinforced:0)
Block(-6,12,7,contenttweaker:iron_plate_reinforced:0)
Block(-6,12,8,contenttweaker:reinforced_concrete:0)
Block(-6,12,9,contenttweaker:reinforced_concrete:0)
Block(-6,13,-6,contenttweaker:reinforced_concrete:0)
Block(-6,13,-5,contenttweaker:reinforced_concrete:0)
Block(-6,13,-4,contenttweaker:reinforced_concrete:0)
Block(-6,13,-3,contenttweaker:reinforced_concrete:0)
Block(-6,13,-2,contenttweaker:reinforced_concrete:0)
Block(-6,13,-1,contenttweaker:reinforced_concrete:0)
Block(-6,13,0,contenttweaker:reinforced_concrete:0)
Block(-6,13,1,contenttweaker:reinforced_concrete:0)
Block(-6,13,2,contenttweaker:reinforced_concrete:0)
Block(-6,13,3,contenttweaker:reinforced_concrete:0)
Block(-6,13,4,contenttweaker:reinforced_concrete:0)
Block(-6,13,5,contenttweaker:reinforced_concrete:0)
Block(-6,13,6,contenttweaker:reinforced_concrete:0)
Block(-6,13,7,contenttweaker:reinforced_concrete:0)
Block(-6,13,8,contenttweaker:reinforced_concrete:0)
Block(-6,13,9,contenttweaker:reinforced_concrete:0)
Block(-6,14,-6,contenttweaker:reinforced_concrete:0)
Block(-6,14,-5,inspirations:bookshelf:0,f_bunker_apartements/27-inspirations_bookshelf.nbt)
Block(-6,14,-4,inspirations:path:0)
Block(-6,14,-3,contenttweaker:reinforced_concrete:0)
Block(-6,14,-2,cookingforblockheads:sink_spruce:8,f_bunker_apartements/28-cookingforblockheads_sink.nbt)
Block(-6,14,-1,cookingforblockheads:counter_darkoak:0,../../../Chests/RLCraft/Containers/cooking_counter.nbt)
Block(-6,14,0,cookingforblockheads:oven:5,f_bunker_apartements/30-cookingforblockheads_oven.nbt)
Block(-6,14,1,cookingforblockheads:counter_darkoak:0,../../../Chests/RLCraft/Containers/cooking_counter.nbt)
Block(-6,14,2,cookingforblockheads:cooking_table_darkoak:5,f_bunker_apartements/32-cookingforblockheads_cooking_table.nbt)
Block(-6,14,3,cookingforblockheads:fridge:0,f_bunker_apartements/33-cookingforblockheads_fridge.nbt)
Block(-6,14,4,contenttweaker:reinforced_concrete:0)
Block(-6,14,5,inspirations:path:0)
Block(-6,14,6,variedcommodities:chair:1,f_bunker_apartements/34-variedcommodities_chair.nbt)
Block(-6,14,7,variedcommodities:chair:1,f_bunker_apartements/35-variedcommodities_chair.nbt)
Block(-6,14,8,variedcommodities:chair:5,f_bunker_apartements/36-variedcommodities_chair.nbt)
Block(-6,14,9,contenttweaker:reinforced_concrete:0)
Block(-6,15,-6,contenttweaker:reinforced_concrete:0)
Block(-6,15,-5,inspirations:bookshelf:0,f_bunker_apartements/37-inspirations_bookshelf.nbt)
Block(-6,15,-4,AIR:0)
Block(-6,15,-3,contenttweaker:reinforced_concrete:0)
Block(-6,15,-2,cookingforblockheads:spice_rack:5,f_bunker_apartements/38-cookingforblockheads_spice_rack.nbt)
Block(-6,15,-1,AIR:0)
Block(-6,15,0,quark:grate:0)
Block(-6,15,1,cookingforblockheads:spice_rack:5,f_bunker_apartements/39-cookingforblockheads_spice_rack.nbt)
Block(-6,15,2,cookingforblockheads:tool_rack:5,f_bunker_apartements/40-cookingforblockheads_tool_rack.nbt)
Block(-6,15,3,cookingforblockheads:fridge:0,f_bunker_apartements/41-cookingforblockheads_fridge.nbt)
Block(-6,15,4,contenttweaker:reinforced_concrete:0)
Block(-6,15,5,AIR:0)
Block(-6,15,6,AIR:0)
Block(-6,15,7,AIR:0)
Block(-6,15,8,AIR:0)
Block(-6,15,9,contenttweaker:reinforced_concrete:0)
Block(-6,16,-6,contenttweaker:reinforced_concrete:0)
Block(-6,16,-5,inspirations:bookshelf:0,f_bunker_apartements/42-inspirations_bookshelf.nbt)
Block(-6,16,-4,WEB:0)
Block(-6,16,-3,contenttweaker:reinforced_concrete:0)
Block(-6,16,-2,cookingforblockheads:cabinet_darkoak:8,../../../Chests/RLCraft/Containers/cooking_cabinet.nbt)
Block(-6,16,-1,cookingforblockheads:cabinet_darkoak:0,../../../Chests/RLCraft/Containers/cooking_cabinet.nbt)
Block(-6,16,0,contentcreator:iron_plate_stairs_reinforced:1)
Block(-6,16,1,cookingforblockheads:cabinet_darkoak:8,../../../Chests/RLCraft/Containers/cooking_cabinet.nbt)
Block(-6,16,2,cookingforblockheads:cabinet_darkoak:0,../../../Chests/RLCraft/Containers/cooking_cabinet.nbt)
Block(-6,16,3,rustic:brewing_barrel:3,f_bunker_apartements/47-rustic_tileentitybrewingbarrel.nbt)
Block(-6,16,4,contenttweaker:reinforced_concrete:0)
Block(-6,16,5,AIR:0)
Block(-6,16,6,AIR:0)
Block(-6,16,7,AIR:0)
Block(-6,16,8,AIR:0)
Block(-6,16,9,contenttweaker:reinforced_concrete:0)
Block(-6,17,-6,contenttweaker:reinforced_concrete:0)
Block(-6,17,-5,contenttweaker:reinforced_concrete:0)
Block(-6,17,-4,contenttweaker:reinforced_concrete:0)
Block(-6,17,-3,contenttweaker:reinforced_concrete:0)
Block(-6,17,-2,contenttweaker:reinforced_concrete:0)
Block(-6,17,-1,contenttweaker:reinforced_concrete:0)
Block(-6,17,0,contenttweaker:reinforced_concrete:0)
Block(-6,17,1,contenttweaker:reinforced_concrete:0)
Block(-6,17,2,contenttweaker:reinforced_concrete:0)
Block(-6,17,3,contenttweaker:reinforced_concrete:0)
Block(-6,17,4,contenttweaker:reinforced_concrete:0)
Block(-6,17,5,contenttweaker:reinforced_concrete:0)
Block(-6,17,6,contenttweaker:reinforced_concrete:0)
Block(-6,17,7,contenttweaker:reinforced_concrete:0)
Block(-6,17,8,contenttweaker:reinforced_concrete:0)
Block(-6,17,9,contenttweaker:reinforced_concrete:0)
Block(-6,18,-6,contenttweaker:reinforced_concrete:0)
Block(-6,18,-5,cookingforblockheads:counter_spruce:8,../../../Chests/RLCraft/Containers/cooking_counter.nbt)
Block(-6,18,-4,cookingforblockheads:counter_spruce:0,../../../Chests/RLCraft/Containers/cooking_counter.nbt)
Block(-6,18,-3,contenttweaker:reinforced_concrete:0)
Block(-6,18,-2,cookingforblockheads:sink_spruce:8,f_bunker_apartements/50-cookingforblockheads_sink.nbt)
Block(-6,18,-1,cookingforblockheads:counter_spruce:0,../../../Chests/RLCraft/Containers/cooking_counter.nbt)
Block(-6,18,0,cookingforblockheads:oven:5,f_bunker_apartements/52-cookingforblockheads_oven.nbt)
Block(-6,18,1,cookingforblockheads:counter_spruce:8,../../../Chests/RLCraft/Containers/cooking_counter.nbt)
Block(-6,18,2,cookingforblockheads:cooking_table_spruce:5,f_bunker_apartements/54-cookingforblockheads_cooking_table.nbt)
Block(-6,18,3,cookingforblockheads:fridge:0,f_bunker_apartements/55-cookingforblockheads_fridge.nbt)
Block(-6,18,4,contenttweaker:reinforced_concrete:0)
Block(-6,18,5,AIR:0)
Block(-6,18,6,variedcommodities:chair:1,f_bunker_apartements/56-variedcommodities_chair.nbt)
Block(-6,18,7,variedcommodities:chair:1,f_bunker_apartements/57-variedcommodities_chair.nbt)
Block(-6,18,8,variedcommodities:chair:5,f_bunker_apartements/58-variedcommodities_chair.nbt)
Block(-6,18,9,contenttweaker:reinforced_concrete:0)
Block(-6,19,-6,contenttweaker:reinforced_concrete:0)
Block(-6,19,-5,variedcommodities:lamp,f_bunker_apartements/59-variedcommodities_lamp.nbt)
Block(-6,19,-4,inspirations:bookshelf:15,f_bunker_apartements/60-inspirations_bookshelf.nbt)
Block(-6,19,-3,contenttweaker:reinforced_concrete:0)
Block(-6,19,-2,cookingforblockheads:spice_rack:5,f_bunker_apartements/61-cookingforblockheads_spice_rack.nbt)
Block(-6,19,-1,AIR:0)
Block(-6,19,0,quark:grate:0)
Block(-6,19,1,cookingforblockheads:spice_rack:5,f_bunker_apartements/62-cookingforblockheads_spice_rack.nbt)
Block(-6,19,2,cookingforblockheads:tool_rack:5,f_bunker_apartements/63-cookingforblockheads_tool_rack.nbt)
Block(-6,19,3,cookingforblockheads:fridge:0,f_bunker_apartements/64-cookingforblockheads_fridge.nbt)
Block(-6,19,4,contenttweaker:reinforced_concrete:0)
Block(-6,19,5,AIR:0)
Block(-6,19,6,AIR:0)
Block(-6,19,7,AIR:0)
Block(-6,19,8,AIR:0)
Block(-6,19,9,contenttweaker:reinforced_concrete:0)
Block(-6,20,-6,contenttweaker:reinforced_concrete:0)
Block(-6,20,-5,WEB:0)
Block(-6,20,-4,inspirations:bookshelf:15,f_bunker_apartements/65-inspirations_bookshelf.nbt)
Block(-6,20,-3,contenttweaker:reinforced_concrete:0)
Block(-6,20,-2,cookingforblockheads:cabinet_spruce:8,../../../Chests/RLCraft/Containers/cooking_cabinet.nbt)
Block(-6,20,-1,cookingforblockheads:cabinet_spruce:8,../../../Chests/RLCraft/Containers/cooking_cabinet.nbt)
Block(-6,20,0,contentcreator:iron_plate_stairs_reinforced:1)
Block(-6,20,1,cookingforblockheads:cabinet_spruce:8,../../../Chests/RLCraft/Containers/cooking_cabinet.nbt)
Block(-6,20,2,cookingforblockheads:cabinet_spruce:8,../../../Chests/RLCraft/Containers/cooking_cabinet.nbt)
Block(-6,20,3,cookingforblockheads:milk_jar,f_bunker_apartements/70-cookingforblockheads_milk_jar.nbt)
Block(-6,20,4,contenttweaker:reinforced_concrete:0)
Block(-6,20,5,WEB:0)
Block(-6,20,6,AIR:0)
Block(-6,20,7,AIR:0)
Block(-6,20,8,AIR:0)
Block(-6,20,9,contenttweaker:reinforced_concrete:0)
Block(-6,21,-6,contenttweaker:reinforced_concrete:0)
Block(-6,21,-5,contenttweaker:reinforced_concrete:0)
Block(-6,21,-4,contenttweaker:reinforced_concrete:0)
Block(-6,21,-3,contenttweaker:reinforced_concrete:0)
Block(-6,21,-2,contenttweaker:reinforced_concrete:0)
Block(-6,21,-1,contenttweaker:reinforced_concrete:0)
Block(-6,21,0,contenttweaker:reinforced_concrete:0)
Block(-6,21,1,contenttweaker:reinforced_concrete:0)
Block(-6,21,2,contenttweaker:reinforced_concrete:0)
Block(-6,21,3,contenttweaker:reinforced_concrete:0)
Block(-6,21,4,contenttweaker:reinforced_concrete:0)
Block(-6,21,5,contenttweaker:reinforced_concrete:0)
Block(-6,21,6,contenttweaker:reinforced_concrete:0)
Block(-6,21,7,contenttweaker:reinforced_concrete:0)
Block(-6,21,8,contenttweaker:reinforced_concrete:0)
Block(-6,21,9,contenttweaker:reinforced_concrete:0)
Block(-6,22,-6,contenttweaker:reinforced_concrete:0)
Block(-6,22,-5,cookingforblockheads:counter_spruce:8,../../../Chests/RLCraft/Containers/cooking_counter.nbt)
Block(-6,22,-4,cookingforblockheads:counter_spruce:0,../../../Chests/RLCraft/Containers/cooking_counter.nbt)
Block(-6,22,-3,contenttweaker:reinforced_concrete:0)
Block(-6,22,-2,cookingforblockheads:sink_spruce:8,f_bunker_apartements/73-cookingforblockheads_sink.nbt)
Block(-6,22,-1,cookingforblockheads:counter_spruce:0,../../../Chests/RLCraft/Containers/cooking_counter.nbt)
Block(-6,22,0,cookingforblockheads:oven:5,f_bunker_apartements/75-cookingforblockheads_oven.nbt)
Block(-6,22,1,cookingforblockheads:counter_spruce:8,../../../Chests/RLCraft/Containers/cooking_counter.nbt)
Block(-6,22,2,cookingforblockheads:cooking_table_spruce:5,f_bunker_apartements/77-cookingforblockheads_cooking_table.nbt)
Block(-6,22,3,cookingforblockheads:fridge:0,f_bunker_apartements/78-cookingforblockheads_fridge.nbt)
Block(-6,22,4,contenttweaker:reinforced_concrete:0)
Block(-6,22,5,AIR:0)
Block(-6,22,6,variedcommodities:chair:1,f_bunker_apartements/79-variedcommodities_chair.nbt)
Block(-6,22,7,variedcommodities:chair:1,f_bunker_apartements/80-variedcommodities_chair.nbt)
Block(-6,22,8,variedcommodities:chair:5,f_bunker_apartements/81-variedcommodities_chair.nbt)
Block(-6,22,9,contenttweaker:reinforced_concrete:0)
Block(-6,23,-6,contenttweaker:reinforced_concrete:0)
Block(-6,23,-5,inspirations:bookshelf:15,f_bunker_apartements/82-inspirations_bookshelf.nbt)
Block(-6,23,-4,inspirations:bookshelf:15,f_bunker_apartements/83-inspirations_bookshelf.nbt)
Block(-6,23,-3,contenttweaker:reinforced_concrete:0)
Block(-6,23,-2,cookingforblockheads:spice_rack:5,f_bunker_apartements/84-cookingforblockheads_spice_rack.nbt)
Block(-6,23,-1,AIR:0)
Block(-6,23,0,quark:grate:0)
Block(-6,23,1,cookingforblockheads:spice_rack:5,f_bunker_apartements/85-cookingforblockheads_spice_rack.nbt)
Block(-6,23,2,cookingforblockheads:tool_rack:5,f_bunker_apartements/86-cookingforblockheads_tool_rack.nbt)
Block(-6,23,3,cookingforblockheads:fridge:0,f_bunker_apartements/87-cookingforblockheads_fridge.nbt)
Block(-6,23,4,contenttweaker:reinforced_concrete:0)
Block(-6,23,5,AIR:0)
Block(-6,23,6,AIR:0)
Block(-6,23,7,AIR:0)
Block(-6,23,8,AIR:0)
Block(-6,23,9,contenttweaker:reinforced_concrete:0)
Block(-6,24,-6,contenttweaker:reinforced_concrete:0)
Block(-6,24,-5,inspirations:bookshelf:15,f_bunker_apartements/88-inspirations_bookshelf.nbt)
Block(-6,24,-4,inspirations:bookshelf:15,f_bunker_apartements/89-inspirations_bookshelf.nbt)
Block(-6,24,-3,contenttweaker:reinforced_concrete:0)
Block(-6,24,-2,cookingforblockheads:cabinet_spruce:8,../../../Chests/RLCraft/Containers/cooking_cabinet.nbt)
Block(-6,24,-1,cookingforblockheads:cabinet_spruce:8,../../../Chests/RLCraft/Containers/cooking_cabinet.nbt)
Block(-6,24,0,contentcreator:iron_plate_stairs_reinforced:1)
Block(-6,24,1,cookingforblockheads:cabinet_spruce:8,../../../Chests/RLCraft/Containers/cooking_cabinet.nbt)
Block(-6,24,2,cookingforblockheads:cabinet_spruce:8,../../../Chests/RLCraft/Containers/cooking_cabinet.nbt)
Block(-6,24,3,rustic:vase:5,f_bunker_apartements/94-rustic_tileentityvase.nbt)
Block(-6,24,4,contenttweaker:reinforced_concrete:0)
Block(-6,24,5,AIR:0)
Block(-6,24,6,AIR:0)
Block(-6,24,7,AIR:0)
Block(-6,24,8,WEB:0)
Block(-6,24,9,contenttweaker:reinforced_concrete:0)
Block(-6,25,-6,contenttweaker:reinforced_concrete:0)
Block(-6,25,-5,contenttweaker:reinforced_concrete:0)
Block(-6,25,-4,contenttweaker:reinforced_concrete:0)
Block(-6,25,-3,contenttweaker:reinforced_concrete:0)
Block(-6,25,-2,contenttweaker:reinforced_concrete:0)
Block(-6,25,-1,contenttweaker:reinforced_concrete:0)
Block(-6,25,0,contenttweaker:reinforced_concrete:0)
Block(-6,25,1,contenttweaker:reinforced_concrete:0)
Block(-6,25,2,contenttweaker:reinforced_concrete:0)
Block(-6,25,3,contenttweaker:reinforced_concrete:0)
Block(-6,25,4,contenttweaker:reinforced_concrete:0)
Block(-6,25,5,contenttweaker:reinforced_concrete:0)
Block(-6,25,6,contenttweaker:reinforced_concrete:0)
Block(-6,25,7,contenttweaker:reinforced_concrete:0)
Block(-6,25,8,contenttweaker:reinforced_concrete:0)
Block(-6,25,9,contenttweaker:reinforced_concrete:0)
Block(-6,26,-6,contenttweaker:reinforced_concrete:0)
Block(-6,26,-5,cookingforblockheads:counter_spruce:8,../../../Chests/RLCraft/Containers/cooking_counter.nbt)
Block(-6,26,-4,cookingforblockheads:counter_spruce:0,../../../Chests/RLCraft/Containers/cooking_counter.nbt)
Block(-6,26,-3,contenttweaker:reinforced_concrete:0)
Block(-6,26,-2,cookingforblockheads:sink_spruce:8,f_bunker_apartements/97-cookingforblockheads_sink.nbt)
Block(-6,26,-1,cookingforblockheads:counter_spruce:0,../../../Chests/RLCraft/Containers/cooking_counter.nbt)
Block(-6,26,0,cookingforblockheads:oven:5,f_bunker_apartements/99-cookingforblockheads_oven.nbt)
Block(-6,26,1,cookingforblockheads:counter_spruce:8,../../../Chests/RLCraft/Containers/cooking_counter.nbt)
Block(-6,26,2,cookingforblockheads:cooking_table_spruce:5,f_bunker_apartements/101-cookingforblockheads_cooking_table.nbt)
Block(-6,26,3,cookingforblockheads:fridge:0,f_bunker_apartements/102-cookingforblockheads_fridge.nbt)
Block(-6,26,4,contenttweaker:reinforced_concrete:0)
Block(-6,26,5,WEB:0)
Block(-6,26,6,variedcommodities:chair:1,f_bunker_apartements/103-variedcommodities_chair.nbt)
Block(-6,26,7,variedcommodities:chair:1,f_bunker_apartements/104-variedcommodities_chair.nbt)
Block(-6,26,8,variedcommodities:chair:5,f_bunker_apartements/105-variedcommodities_chair.nbt)
Block(-6,26,9,contenttweaker:reinforced_concrete:0)
Block(-6,27,-6,contenttweaker:reinforced_concrete:0)
Block(-6,27,-5,inspirations:bookshelf:15,f_bunker_apartements/106-inspirations_bookshelf.nbt)
Block(-6,27,-4,inspirations:bookshelf:15,f_bunker_apartements/107-inspirations_bookshelf.nbt)
Block(-6,27,-3,contenttweaker:reinforced_concrete:0)
Block(-6,27,-2,cookingforblockheads:spice_rack:5,f_bunker_apartements/108-cookingforblockheads_spice_rack.nbt)
Block(-6,27,-1,cookingforblockheads:toaster:3,f_bunker_apartements/109-cookingforblockheads_toaster.nbt)
Block(-6,27,0,quark:grate:0)
Block(-6,27,1,cookingforblockheads:spice_rack:5,f_bunker_apartements/110-cookingforblockheads_spice_rack.nbt)
Block(-6,27,2,cookingforblockheads:tool_rack:5,f_bunker_apartements/111-cookingforblockheads_tool_rack.nbt)
Block(-6,27,3,cookingforblockheads:fridge:0,f_bunker_apartements/112-cookingforblockheads_fridge.nbt)
Block(-6,27,4,contenttweaker:reinforced_concrete:0)
Block(-6,27,5,AIR:0)
Block(-6,27,6,AIR:0)
Block(-6,27,7,AIR:0)
Block(-6,27,8,AIR:0)
Block(-6,27,9,contenttweaker:reinforced_concrete:0)
Block(-6,28,-6,contenttweaker:reinforced_concrete:0)
Block(-6,28,-5,inspirations:bookshelf:15,f_bunker_apartements/113-inspirations_bookshelf.nbt)
Block(-6,28,-4,inspirations:bookshelf:15,f_bunker_apartements/114-inspirations_bookshelf.nbt)
Block(-6,28,-3,contenttweaker:reinforced_concrete:0)
Block(-6,28,-2,cookingforblockheads:cabinet_spruce:8,../../../Chests/RLCraft/Containers/cooking_cabinet.nbt)
Block(-6,28,-1,cookingforblockheads:cabinet_spruce:8,../../../Chests/RLCraft/Containers/cooking_cabinet.nbt)
Block(-6,28,0,contentcreator:iron_plate_stairs_reinforced:1)
Block(-6,28,1,cookingforblockheads:cabinet_spruce:8,../../../Chests/RLCraft/Containers/cooking_cabinet.nbt)
Block(-6,28,2,cookingforblockheads:cabinet_spruce:8,../../../Chests/RLCraft/Containers/cooking_cabinet.nbt)
Block(-6,28,3,cookingforblockheads:milk_jar:5,f_bunker_apartements/119-cookingforblockheads_milk_jar.nbt)
Block(-6,28,4,contenttweaker:reinforced_concrete:0)
Block(-6,28,5,AIR:0)
Block(-6,28,6,AIR:0)
Block(-6,28,7,AIR:0)
Block(-6,28,8,WEB:0)
Block(-6,28,9,contenttweaker:reinforced_concrete:0)
Block(-6,29,-6,contenttweaker:reinforced_concrete:0)
Block(-6,29,-5,contenttweaker:reinforced_concrete:0)
Block(-6,29,-4,contenttweaker:reinforced_concrete:0)
Block(-6,29,-3,contenttweaker:reinforced_concrete:0)
Block(-6,29,-2,contenttweaker:reinforced_concrete:0)
Block(-6,29,-1,contenttweaker:reinforced_concrete:0)
Block(-6,29,0,contenttweaker:reinforced_concrete:0)
Block(-6,29,1,contenttweaker:reinforced_concrete:0)
Block(-6,29,2,contenttweaker:reinforced_concrete:0)
Block(-6,29,3,contenttweaker:reinforced_concrete:0)
Block(-6,29,4,contenttweaker:reinforced_concrete:0)
Block(-6,29,5,contenttweaker:reinforced_concrete:0)
Block(-6,29,6,contenttweaker:reinforced_concrete:0)
Block(-6,29,7,contenttweaker:reinforced_concrete:0)
Block(-6,29,8,contenttweaker:reinforced_concrete:0)
Block(-6,29,9,contenttweaker:reinforced_concrete:0)
Block(-6,30,-6,contenttweaker:reinforced_concrete:0)
Block(-6,30,-5,contenttweaker:resource_crate:0)
Block(-6,30,-4,contenttweaker:resource_crate:0)
RandomBlock(-6,30,-3,variedcommodities:crate:5,5,charm:crate_sealed:5,100)
Block(-6,30,-2,cookingforblockheads:cabinet_spruce:0,../../../Chests/RLCraft/Containers/cooking_cabinet.nbt)
Block(-6,30,-1,variedcommodities:table:1,f_bunker_apartements/122-variedcommodities_table.nbt)
Block(-6,30,0,contenttweaker:resource_crate:0)
RandomBlock(-6,30,1,variedcommodities:crate:5,5,charm:crate_sealed:5,100)
Block(-6,30,2,contenttweaker:resource_crate:0)
Block(-6,30,3,contenttweaker:reinforced_concrete:0)
Block(-6,31,-6,contenttweaker:reinforced_concrete:0)
Block(-6,31,-5,contenttweaker:resource_crate:0)
Block(-6,31,-4,variedcommodities:chair:1,f_bunker_apartements/124-variedcommodities_chair.nbt)
Block(-6,31,-3,cookingforblockheads:cabinet_spruce:8,../../../Chests/RLCraft/Containers/cooking_cabinet.nbt)
Block(-6,31,-2,cookingforblockheads:cabinet_spruce:0,../../../Chests/RLCraft/Containers/cooking_cabinet.nbt)
Block(-6,31,-1,variedcommodities:shelf:5,f_bunker_apartements/127-variedcommodities_shelf.nbt)
Block(-6,31,0,variedcommodities:chair:5,f_bunker_apartements/128-variedcommodities_chair.nbt)
Block(-6,31,1,variedcommodities:shelf:5,f_bunker_apartements/129-variedcommodities_shelf.nbt)
Block(-6,31,2,contenttweaker:resource_crate:0)
Block(-6,31,3,contenttweaker:reinforced_concrete:0)
Block(-6,32,-6,contenttweaker:reinforced_concrete:0)
RandomBlock(-6,32,-5,variedcommodities:crate:5,5,charm:crate_sealed:1,100)
Block(-6,32,-4,AIR:0)
Block(-6,32,-3,AIR:0)
Block(-6,32,-2,AIR:0)
Block(-6,32,-1,AIR:0)
Block(-6,32,0,AIR:0)
Block(-6,32,1,AIR:0)
RandomBlock(-6,32,2,variedcommodities:crate:5,5,charm:crate_sealed:1,100)
Block(-6,32,3,contenttweaker:reinforced_concrete:0)
Block(-6,33,-6,contenttweaker:reinforced_concrete:0)
Block(-6,33,-5,contenttweaker:reinforced_concrete:0)
Block(-6,33,-4,contenttweaker:reinforced_concrete:0)
Block(-6,33,-3,contenttweaker:reinforced_concrete:0)
Block(-6,33,-2,contenttweaker:reinforced_concrete:0)
Block(-6,33,-1,contenttweaker:reinforced_concrete:0)
Block(-6,33,0,contenttweaker:reinforced_concrete:0)
Block(-6,33,1,contenttweaker:reinforced_concrete:0)
Block(-6,33,2,contenttweaker:reinforced_concrete:0)
Block(-6,33,3,contenttweaker:reinforced_concrete:0)
Block(-5,0,-6,contenttweaker:reinforced_concrete:0)
Block(-5,0,-5,contenttweaker:reinforced_concrete:0)
Block(-5,0,-4,contenttweaker:reinforced_concrete:0)
Block(-5,0,-3,contenttweaker:reinforced_concrete:0)
Block(-5,0,-2,contenttweaker:reinforced_concrete:0)
Block(-5,0,-1,contenttweaker:reinforced_concrete:0)
Block(-5,0,0,contenttweaker:reinforced_concrete:0)
Block(-5,0,1,contenttweaker:reinforced_concrete:0)
Block(-5,0,2,contenttweaker:reinforced_concrete:0)
Block(-5,0,3,contenttweaker:reinforced_concrete:0)
Block(-5,0,4,contenttweaker:reinforced_concrete:0)
Block(-5,0,5,contenttweaker:reinforced_concrete:0)
Block(-5,0,6,contenttweaker:reinforced_concrete:0)
Block(-5,0,7,contenttweaker:reinforced_concrete:0)
Block(-5,0,8,contenttweaker:reinforced_concrete:0)
Block(-5,0,9,contenttweaker:reinforced_concrete:0)
Block(-5,1,-6,contenttweaker:reinforced_concrete:0)
Block(-5,1,-5,contenttweaker:reinforced_concrete:0)
Block(-5,1,-4,contenttweaker:reinforced_concrete:0)
Block(-5,1,-3,contenttweaker:reinforced_concrete:0)
Block(-5,1,-2,contenttweaker:reinforced_concrete:0)
Block(-5,1,-1,STATIONARY_WATER:0)
Block(-5,1,0,STATIONARY_WATER:0)
Block(-5,1,1,STATIONARY_WATER:0)
Block(-5,1,2,STATIONARY_WATER:0)
Block(-5,1,3,STATIONARY_WATER:0)
Block(-5,1,4,STATIONARY_WATER:0)
Block(-5,1,5,STATIONARY_WATER:0)
Block(-5,1,6,STATIONARY_WATER:0)
Block(-5,1,7,STATIONARY_WATER:0)
Block(-5,1,8,STATIONARY_WATER:0)
Block(-5,1,9,contenttweaker:reinforced_concrete:0)
Block(-5,2,-6,contenttweaker:reinforced_concrete:0)
Block(-5,2,-5,contentcreator:iron_plate_slab_reinforced:1)
Block(-5,2,-4,AIR:0)
Block(-5,2,-3,AIR:0)
Block(-5,2,-2,rustic:iron_lattice:0)
Block(-5,2,-1,AIR:0)
Block(-5,2,0,AIR:0)
Block(-5,2,1,AIR:0)
Block(-5,2,2,AIR:0)
Block(-5,2,3,AIR:0)
Block(-5,2,4,AIR:0)
Block(-5,2,5,AIR:0)
Block(-5,2,6,AIR:0)
Block(-5,2,7,AIR:0)
Block(-5,2,8,contentcreator:iron_plate_slab_reinforced:1)
Block(-5,2,9,contenttweaker:reinforced_concrete:0)
Block(-5,3,-6,contenttweaker:reinforced_concrete:0)
Block(-5,3,-5,cookingforblockheads:tool_rack:3,f_bunker_apartements/132-cookingforblockheads_tool_rack.nbt)
Block(-5,3,-4,AIR:0)
Block(-5,3,-3,AIR:0)
Block(-5,3,-2,rustic:iron_lattice:0)
Block(-5,3,-1,AIR:0)
Block(-5,3,0,AIR:0)
Block(-5,3,1,AIR:0)
Block(-5,3,2,AIR:0)
Block(-5,3,3,AIR:0)
Block(-5,3,4,AIR:0)
Block(-5,3,5,AIR:0)
Block(-5,3,6,AIR:0)
Block(-5,3,7,AIR:0)
Block(-5,3,8,AIR:0)
Block(-5,3,9,contenttweaker:reinforced_concrete:0)
Block(-5,4,-6,contenttweaker:reinforced_concrete:0)
Block(-5,4,-5,AIR:0)
Block(-5,4,-4,AIR:0)
Block(-5,4,-3,AIR:0)
Block(-5,4,-2,rustic:iron_lattice:0)
Block(-5,4,-1,AIR:0)
Block(-5,4,0,AIR:0)
Block(-5,4,1,AIR:0)
Block(-5,4,2,AIR:0)
Block(-5,4,3,AIR:0)
Block(-5,4,4,AIR:0)
Block(-5,4,5,AIR:0)
Block(-5,4,6,AIR:0)
Block(-5,4,7,AIR:0)
Block(-5,4,8,AIR:0)
Block(-5,4,9,contenttweaker:reinforced_concrete:0)
Block(-5,5,-6,contenttweaker:reinforced_concrete:0)
Block(-5,5,-5,contenttweaker:reinforced_concrete:0)
Block(-5,5,-4,contenttweaker:reinforced_concrete:0)
Block(-5,5,-3,contenttweaker:reinforced_concrete:0)
Block(-5,5,-2,contenttweaker:reinforced_concrete:0)
Block(-5,5,-1,contenttweaker:reinforced_concrete:0)
Block(-5,5,0,contenttweaker:reinforced_concrete:0)
Block(-5,5,1,contenttweaker:reinforced_concrete:0)
Block(-5,5,2,contenttweaker:reinforced_concrete:0)
Block(-5,5,3,contenttweaker:reinforced_concrete:0)
Block(-5,5,4,contenttweaker:reinforced_concrete:0)
Block(-5,5,5,contenttweaker:reinforced_concrete:0)
Block(-5,5,6,contenttweaker:reinforced_concrete:0)
Block(-5,5,7,contenttweaker:reinforced_concrete:0)
Block(-5,5,8,contenttweaker:reinforced_concrete:0)
Block(-5,5,9,contenttweaker:reinforced_concrete:0)
Block(-5,6,-6,contenttweaker:reinforced_concrete:0)
Block(-5,6,-5,rustic:deathstalk_mushroom:0)
Block(-5,6,-4,AIR:0)
Block(-5,6,-3,notreepunching:loose_rock/stone:0)
Block(-5,6,-2,AIR:0)
Block(-5,6,-1,AIR:0)
Block(-5,6,0,inspirations:path:0)
Block(-5,6,1,AIR:0)
Block(-5,6,2,contentcreator:iron_plate_stairs_reinforced:2)
Block(-5,6,3,quark:grate:0)
Block(-5,6,4,quark:grate:0)
Block(-5,6,5,contenttweaker:iron_plate_reinforced:0)
Block(-5,6,6,quark:grate:0)
Block(-5,6,7,quark:grate:0)
Block(-5,6,8,quark:grate:0)
Block(-5,6,9,contenttweaker:reinforced_concrete:0)
Block(-5,7,-6,contenttweaker:reinforced_concrete:0)
Block(-5,7,-5,AIR:0)
Block(-5,7,-4,AIR:0)
Block(-5,7,-3,AIR:0)
Block(-5,7,-2,AIR:0)
Block(-5,7,-1,AIR:0)
Block(-5,7,0,AIR:0)
Block(-5,7,1,AIR:0)
Block(-5,7,2,AIR:0)
Block(-5,7,3,AIR:0)
Block(-5,7,4,AIR:0)
Block(-5,7,5,rustic:deathstalk_mushroom:0)
Block(-5,7,6,AIR:0)
Block(-5,7,7,AIR:0)
Block(-5,7,8,AIR:0)
Block(-5,7,9,contenttweaker:reinforced_concrete:0)
Block(-5,8,-6,contenttweaker:reinforced_concrete:0)
Block(-5,8,-5,AIR:0)
Block(-5,8,-4,AIR:0)
Block(-5,8,-3,AIR:0)
Block(-5,8,-2,AIR:0)
Block(-5,8,-1,AIR:0)
Block(-5,8,0,AIR:0)
Block(-5,8,1,AIR:0)
Block(-5,8,2,AIR:0)
Block(-5,8,3,AIR:0)
Block(-5,8,4,AIR:0)
Block(-5,8,5,contentcreator:iron_plate_slab_reinforced:1)
Block(-5,8,6,AIR:0)
Block(-5,8,7,AIR:0)
Block(-5,8,8,AIR:0)
Block(-5,8,9,contenttweaker:reinforced_concrete:0)
Block(-5,9,-6,contenttweaker:reinforced_concrete:0)
Block(-5,9,-5,contenttweaker:reinforced_concrete:0)
Block(-5,9,-4,contenttweaker:reinforced_concrete:0)
Block(-5,9,-3,contenttweaker:reinforced_concrete:0)
Block(-5,9,-2,contenttweaker:reinforced_concrete:0)
Block(-5,9,-1,contenttweaker:reinforced_concrete:0)
Block(-5,9,0,contenttweaker:reinforced_concrete:0)
Block(-5,9,1,contenttweaker:reinforced_concrete:0)
Block(-5,9,2,contenttweaker:reinforced_concrete:0)
Block(-5,9,3,contenttweaker:reinforced_concrete:0)
Block(-5,9,4,contenttweaker:reinforced_concrete:0)
Block(-5,9,5,contenttweaker:reinforced_concrete:0)
Block(-5,9,6,contenttweaker:reinforced_concrete:0)
Block(-5,9,7,contenttweaker:reinforced_concrete:0)
Block(-5,9,8,contenttweaker:reinforced_concrete:0)
Block(-5,9,9,contenttweaker:reinforced_concrete:0)
Block(-5,10,-6,contenttweaker:reinforced_concrete:0)
RandomBlock(-5,10,-5,variedcommodities:crate:5,5,charm:crate_sealed:1,100)
Block(-5,10,-4,inspirations:path:0)
Block(-5,10,-3,AIR:0)
Block(-5,10,-2,inspirations:path:0)
Block(-5,10,-1,AIR:0)
Block(-5,10,0,inspirations:path:0)
Block(-5,10,1,AIR:0)
Block(-5,10,2,rustic:deathstalk_mushroom:3)
Block(-5,10,3,inspirations:path:0)
Block(-5,10,4,AIR:0)
Block(-5,10,5,cookingforblockheads:sink:3,f_bunker_apartements/134-cookingforblockheads_sink.nbt)
Block(-5,10,6,contenttweaker:iron_plate_reinforced:0)
Block(-5,10,7,simpledifficulty:purifiedwater:0)
Block(-5,10,8,simpledifficulty:purifiedwater:0)
Block(-5,10,9,contenttweaker:reinforced_concrete:0)
Block(-5,11,-6,contenttweaker:reinforced_concrete:0)
Block(-5,11,-5,inspirations:bookshelf:3,f_bunker_apartements/135-inspirations_bookshelf.nbt)
Block(-5,11,-4,AIR:0)
Block(-5,11,-3,AIR:0)
Block(-5,11,-2,AIR:0)
Block(-5,11,-1,AIR:0)
Block(-5,11,0,AIR:0)
Block(-5,11,1,AIR:0)
Block(-5,11,2,AIR:0)
Block(-5,11,3,AIR:0)
Block(-5,11,4,AIR:0)
Block(-5,11,5,AIR:0)
Block(-5,11,6,quark:framed_glass:0)
Block(-5,11,7,simpledifficulty:purifiedwater:0)
Block(-5,11,8,simpledifficulty:purifiedwater:0)
Block(-5,11,9,contenttweaker:reinforced_concrete:0)
Block(-5,12,-6,contenttweaker:reinforced_concrete:0)
Block(-5,12,-5,inspirations:bookshelf:3,f_bunker_apartements/136-inspirations_bookshelf.nbt)
Block(-5,12,-4,AIR:0)
Block(-5,12,-3,AIR:0)
Block(-5,12,-2,AIR:0)
Block(-5,12,-1,AIR:0)
Block(-5,12,0,AIR:0)
Block(-5,12,1,AIR:0)
Block(-5,12,2,AIR:0)
Block(-5,12,3,AIR:0)
Block(-5,12,4,AIR:0)
Block(-5,12,5,AIR:0)
Block(-5,12,6,contenttweaker:iron_plate_reinforced:0)
Block(-5,12,7,simpledifficulty:purifiedwater:0)
Block(-5,12,8,simpledifficulty:purifiedwater:0)
Block(-5,12,9,contenttweaker:reinforced_concrete:0)
Block(-5,13,-6,contenttweaker:reinforced_concrete:0)
Block(-5,13,-5,contenttweaker:reinforced_concrete:0)
Block(-5,13,-4,contenttweaker:reinforced_concrete:0)
Block(-5,13,-3,contenttweaker:reinforced_concrete:0)
Block(-5,13,-2,contenttweaker:reinforced_concrete:0)
Block(-5,13,-1,contenttweaker:reinforced_concrete:0)
Block(-5,13,0,contenttweaker:reinforced_concrete:0)
Block(-5,13,1,contenttweaker:reinforced_concrete:0)
Block(-5,13,2,contenttweaker:reinforced_concrete:0)
Block(-5,13,3,contenttweaker:reinforced_concrete:0)
Block(-5,13,4,contenttweaker:reinforced_concrete:0)
Block(-5,13,5,contenttweaker:reinforced_concrete:0)
Block(-5,13,6,contenttweaker:reinforced_concrete:0)
Block(-5,13,7,contenttweaker:reinforced_concrete:0)
Block(-5,13,8,contenttweaker:reinforced_concrete:0)
Block(-5,13,9,contenttweaker:reinforced_concrete:0)
Block(-5,14,-6,contenttweaker:reinforced_concrete:0)
Block(-5,14,-5,cookingforblockheads:counter_darkoak:2,../../../Chests/RLCraft/Containers/cooking_counter.nbt)
Block(-5,14,-4,AIR:0)
Block(-5,14,-3,CARPET:4)
Block(-5,14,-2,CARPET:15)
Block(-5,14,-1,CARPET:15)
Block(-5,14,0,CARPET:15)
Block(-5,14,1,CARPET:15)
Block(-5,14,2,CARPET:4)
Block(-5,14,3,notreepunching:loose_rock/stone:0)
Block(-5,14,4,AIR:0)
Block(-5,14,5,AIR:0)
Block(-5,14,6,variedcommodities:table:5,f_bunker_apartements/138-variedcommodities_table.nbt)
Block(-5,14,7,variedcommodities:table:5,f_bunker_apartements/139-variedcommodities_table.nbt)
Block(-5,14,8,variedcommodities:table:5,f_bunker_apartements/140-variedcommodities_table.nbt)
Block(-5,14,9,contenttweaker:reinforced_concrete:0)
Block(-5,15,-6,contenttweaker:reinforced_concrete:0)
Block(-5,15,-5,betternether:cincinnasite_pot:0)
Block(-5,15,-4,AIR:0)
Block(-5,15,-3,AIR:0)
Block(-5,15,-2,AIR:0)
Block(-5,15,-1,AIR:0)
Block(-5,15,0,AIR:0)
Block(-5,15,1,AIR:0)
Block(-5,15,2,AIR:0)
Block(-5,15,3,AIR:0)
Block(-5,15,4,AIR:0)
Block(-5,15,5,AIR:0)
Block(-5,15,6,AIR:0)
Block(-5,15,7,AIR:0)
Block(-5,15,8,variedcommodities:lamp,f_bunker_apartements/141-variedcommodities_lamp.nbt)
Block(-5,15,9,contenttweaker:reinforced_concrete:0)
Block(-5,16,-6,contenttweaker:reinforced_concrete:0)
Block(-5,16,-5,betternether:potted_plant_1:8)
Block(-5,16,-4,AIR:0)
Block(-5,16,-3,STEP:8)
Block(-5,16,-2,STEP:8)
Block(-5,16,-1,STEP:8)
Block(-5,16,0,STEP:8)
Block(-5,16,1,STEP:8)
Block(-5,16,2,STEP:8)
Block(-5,16,3,STEP:8)
Block(-5,16,4,STEP:8)
Block(-5,16,5,STEP:8)
Block(-5,16,6,STEP:8)
Block(-5,16,7,AIR:0)
Block(-5,16,8,variedcommodities:wall_banner,f_bunker_apartements/142-variedcommodities_wall_banner.nbt)
Block(-5,16,9,contenttweaker:reinforced_concrete:0)
Block(-5,17,-6,contenttweaker:reinforced_concrete:0)
Block(-5,17,-5,contenttweaker:reinforced_concrete:0)
Block(-5,17,-4,contenttweaker:reinforced_concrete:0)
Block(-5,17,-3,contenttweaker:reinforced_concrete:0)
Block(-5,17,-2,contenttweaker:reinforced_concrete:0)
Block(-5,17,-1,contenttweaker:reinforced_concrete:0)
Block(-5,17,0,contenttweaker:reinforced_concrete:0)
Block(-5,17,1,contenttweaker:reinforced_concrete:0)
Block(-5,17,2,contenttweaker:reinforced_concrete:0)
Block(-5,17,3,contenttweaker:reinforced_concrete:0)
Block(-5,17,4,contenttweaker:reinforced_concrete:0)
Block(-5,17,5,contenttweaker:reinforced_concrete:0)
Block(-5,17,6,contenttweaker:reinforced_concrete:0)
Block(-5,17,7,contenttweaker:reinforced_concrete:0)
Block(-5,17,8,contenttweaker:reinforced_concrete:0)
Block(-5,17,9,contenttweaker:reinforced_concrete:0)
Block(-5,18,-6,contenttweaker:reinforced_concrete:0)
Block(-5,18,-5,notreepunching:loose_rock/stone:0)
Block(-5,18,-4,AIR:0)
Block(-5,18,-3,inspirations:path:0)
Block(-5,18,-2,AIR:0)
Block(-5,18,-1,AIR:0)
Block(-5,18,0,AIR:0)
Block(-5,18,1,AIR:0)
Block(-5,18,2,AIR:0)
Block(-5,18,3,notreepunching:loose_rock/stone:0)
Block(-5,18,4,rustic:deathstalk_mushroom:0)
Block(-5,18,5,inspirations:path:0)
Block(-5,18,6,variedcommodities:table:5,f_bunker_apartements/143-variedcommodities_table.nbt)
Block(-5,18,7,variedcommodities:table:5,f_bunker_apartements/144-variedcommodities_table.nbt)
Block(-5,18,8,variedcommodities:table:5,f_bunker_apartements/145-variedcommodities_table.nbt)
Block(-5,18,9,contenttweaker:reinforced_concrete:0)
Block(-5,19,-6,contenttweaker:reinforced_concrete:0)
Block(-5,19,-5,AIR:0)
Block(-5,19,-4,AIR:0)
Block(-5,19,-3,AIR:0)
Block(-5,19,-2,AIR:0)
Block(-5,19,-1,AIR:0)
Block(-5,19,0,AIR:0)
Block(-5,19,1,AIR:0)
Block(-5,19,2,AIR:0)
Block(-5,19,3,AIR:0)
Block(-5,19,4,AIR:0)
Block(-5,19,5,AIR:0)
Block(-5,19,6,AIR:0)
Block(-5,19,7,variedcommodities:candle_unlit,f_bunker_apartements/146-variedcommodities_candle.nbt)
Block(-5,19,8,AIR:0)
Block(-5,19,9,contenttweaker:reinforced_concrete:0)
Block(-5,20,-6,contenttweaker:reinforced_concrete:0)
Block(-5,20,-5,AIR:0)
Block(-5,20,-4,STEP:8)
Block(-5,20,-3,STEP:8)
Block(-5,20,-2,STEP:8)
Block(-5,20,-1,STEP:8)
Block(-5,20,0,STEP:8)
Block(-5,20,1,STEP:8)
Block(-5,20,2,STEP:8)
Block(-5,20,3,STEP:8)
Block(-5,20,4,STEP:8)
Block(-5,20,5,STEP:8)
Block(-5,20,6,STEP:8)
Block(-5,20,7,AIR:0)
Block(-5,20,8,variedcommodities:wall_banner,f_bunker_apartements/147-variedcommodities_wall_banner.nbt)
Block(-5,20,9,contenttweaker:reinforced_concrete:0)
Block(-5,21,-6,contenttweaker:reinforced_concrete:0)
Block(-5,21,-5,contenttweaker:reinforced_concrete:0)
Block(-5,21,-4,contenttweaker:reinforced_concrete:0)
Block(-5,21,-3,contenttweaker:reinforced_concrete:0)
Block(-5,21,-2,contenttweaker:reinforced_concrete:0)
Block(-5,21,-1,contenttweaker:reinforced_concrete:0)
Block(-5,21,0,contenttweaker:reinforced_concrete:0)
Block(-5,21,1,contenttweaker:reinforced_concrete:0)
Block(-5,21,2,contenttweaker:reinforced_concrete:0)
Block(-5,21,3,contenttweaker:reinforced_concrete:0)
Block(-5,21,4,contenttweaker:reinforced_concrete:0)
Block(-5,21,5,contenttweaker:reinforced_concrete:0)
Block(-5,21,6,contenttweaker:reinforced_concrete:0)
Block(-5,21,7,contenttweaker:reinforced_concrete:0)
Block(-5,21,8,contenttweaker:reinforced_concrete:0)
Block(-5,21,9,contenttweaker:reinforced_concrete:0)
Block(-5,22,-6,contenttweaker:reinforced_concrete:0)
Block(-5,22,-5,AIR:0)
Block(-5,22,-4,inspirations:path:0)
Block(-5,22,-3,notreepunching:loose_rock/stone:0)
Block(-5,22,-2,AIR:0)
Block(-5,22,-1,AIR:0)
Block(-5,22,0,rustic:deathstalk_mushroom:0)
Block(-5,22,1,AIR:0)
Block(-5,22,2,AIR:0)
Block(-5,22,3,rustic:deathstalk_mushroom:0)
Block(-5,22,4,notreepunching:loose_rock/stone:0)
Block(-5,22,5,AIR:0)
Block(-5,22,6,variedcommodities:table:5,f_bunker_apartements/148-variedcommodities_table.nbt)
Block(-5,22,7,variedcommodities:table:5,f_bunker_apartements/149-variedcommodities_table.nbt)
Block(-5,22,8,variedcommodities:table:5,f_bunker_apartements/150-variedcommodities_table.nbt)
Block(-5,22,9,contenttweaker:reinforced_concrete:0)
Block(-5,23,-6,contenttweaker:reinforced_concrete:0)
Block(-5,23,-5,AIR:0)
Block(-5,23,-4,AIR:0)
Block(-5,23,-3,AIR:0)
Block(-5,23,-2,AIR:0)
Block(-5,23,-1,AIR:0)
Block(-5,23,0,AIR:0)
Block(-5,23,1,AIR:0)
Block(-5,23,2,AIR:0)
Block(-5,23,3,AIR:0)
Block(-5,23,4,AIR:0)
Block(-5,23,5,AIR:0)
Block(-5,23,6,variedcommodities:candle_unlit,f_bunker_apartements/151-variedcommodities_candle.nbt)
Block(-5,23,7,AIR:0)
Block(-5,23,8,cookingforblockheads:fruit_basket:5,f_bunker_apartements/152-cookingforblockheads_fruit_basket.nbt)
Block(-5,23,9,contenttweaker:reinforced_concrete:0)
Block(-5,24,-6,contenttweaker:reinforced_concrete:0)
Block(-5,24,-5,WEB:0)
Block(-5,24,-4,STEP:8)
Block(-5,24,-3,STEP:8)
Block(-5,24,-2,STEP:8)
Block(-5,24,-1,STEP:8)
Block(-5,24,0,STEP:8)
Block(-5,24,1,STEP:8)
Block(-5,24,2,STEP:8)
Block(-5,24,3,STEP:8)
Block(-5,24,4,STEP:8)
Block(-5,24,5,STEP:8)
Block(-5,24,6,STEP:8)
Block(-5,24,7,AIR:0)
Block(-5,24,8,variedcommodities:wall_banner,f_bunker_apartements/153-variedcommodities_wall_banner.nbt)
Block(-5,24,9,contenttweaker:reinforced_concrete:0)
Block(-5,25,-6,contenttweaker:reinforced_concrete:0)
Block(-5,25,-5,contenttweaker:reinforced_concrete:0)
Block(-5,25,-4,contenttweaker:reinforced_concrete:0)
Block(-5,25,-3,contenttweaker:reinforced_concrete:0)
Block(-5,25,-2,contenttweaker:reinforced_concrete:0)
Block(-5,25,-1,contenttweaker:reinforced_concrete:0)
Block(-5,25,0,contenttweaker:reinforced_concrete:0)
Block(-5,25,1,contenttweaker:reinforced_concrete:0)
Block(-5,25,2,contenttweaker:reinforced_concrete:0)
Block(-5,25,3,contenttweaker:reinforced_concrete:0)
Block(-5,25,4,contenttweaker:reinforced_concrete:0)
Block(-5,25,5,contenttweaker:reinforced_concrete:0)
Block(-5,25,6,contenttweaker:reinforced_concrete:0)
Block(-5,25,7,contenttweaker:reinforced_concrete:0)
Block(-5,25,8,contenttweaker:reinforced_concrete:0)
Block(-5,25,9,contenttweaker:reinforced_concrete:0)
Block(-5,26,-6,contenttweaker:reinforced_concrete:0)
Block(-5,26,-5,AIR:0)
Block(-5,26,-4,notreepunching:loose_rock/stone:0)
Block(-5,26,-3,AIR:0)
Block(-5,26,-2,AIR:0)
Block(-5,26,-1,rustic:deathstalk_mushroom:0)
Block(-5,26,0,inspirations:path:0)
Block(-5,26,1,AIR:0)
Block(-5,26,2,AIR:0)
Block(-5,26,3,notreepunching:loose_rock/stone:0)
Block(-5,26,4,inspirations:path:0)
Block(-5,26,5,AIR:0)
Block(-5,26,6,variedcommodities:table:5,f_bunker_apartements/154-variedcommodities_table.nbt)
Block(-5,26,7,variedcommodities:table:5,f_bunker_apartements/155-variedcommodities_table.nbt)
Block(-5,26,8,variedcommodities:table:5,f_bunker_apartements/156-variedcommodities_table.nbt)
Block(-5,26,9,contenttweaker:reinforced_concrete:0)
Block(-5,27,-6,contenttweaker:reinforced_concrete:0)
Block(-5,27,-5,AIR:0)
Block(-5,27,-4,AIR:0)
Block(-5,27,-3,AIR:0)
Block(-5,27,-2,AIR:0)
Block(-5,27,-1,AIR:0)
Block(-5,27,0,AIR:0)
Block(-5,27,1,AIR:0)
Block(-5,27,2,AIR:0)
Block(-5,27,3,AIR:0)
Block(-5,27,4,AIR:0)
Block(-5,27,5,AIR:0)
Block(-5,27,6,cookingforblockheads:fruit_basket,f_bunker_apartements/157-cookingforblockheads_fruit_basket.nbt)
Block(-5,27,7,AIR:0)
Block(-5,27,8,cookingforblockheads:fruit_basket:5,f_bunker_apartements/158-cookingforblockheads_fruit_basket.nbt)
Block(-5,27,9,contenttweaker:reinforced_concrete:0)
Block(-5,28,-6,contenttweaker:reinforced_concrete:0)
Block(-5,28,-5,WEB:0)
Block(-5,28,-4,STEP:8)
Block(-5,28,-3,STEP:8)
Block(-5,28,-2,STEP:8)
Block(-5,28,-1,STEP:8)
Block(-5,28,0,STEP:8)
Block(-5,28,1,STEP:8)
Block(-5,28,2,STEP:8)
Block(-5,28,3,STEP:8)
Block(-5,28,4,STEP:8)
Block(-5,28,5,STEP:8)
Block(-5,28,6,STEP:8)
Block(-5,28,7,AIR:0)
Block(-5,28,8,variedcommodities:wall_banner,f_bunker_apartements/159-variedcommodities_wall_banner.nbt)
Block(-5,28,9,contenttweaker:reinforced_concrete:0)
Block(-5,29,-6,contenttweaker:reinforced_concrete:0)
Block(-5,29,-5,contenttweaker:reinforced_concrete:0)
Block(-5,29,-4,contenttweaker:reinforced_concrete:0)
Block(-5,29,-3,contenttweaker:reinforced_concrete:0)
Block(-5,29,-2,contenttweaker:reinforced_concrete:0)
Block(-5,29,-1,contenttweaker:reinforced_concrete:0)
Block(-5,29,0,contenttweaker:reinforced_concrete:0)
Block(-5,29,1,contenttweaker:reinforced_concrete:0)
Block(-5,29,2,contenttweaker:reinforced_concrete:0)
Block(-5,29,3,contenttweaker:reinforced_concrete:0)
Block(-5,29,4,contenttweaker:reinforced_concrete:0)
Block(-5,29,5,contenttweaker:reinforced_concrete:0)
Block(-5,29,6,contenttweaker:reinforced_concrete:0)
Block(-5,29,7,contenttweaker:reinforced_concrete:0)
Block(-5,29,8,contenttweaker:reinforced_concrete:0)
Block(-5,29,9,contenttweaker:reinforced_concrete:0)
Block(-5,30,-6,contenttweaker:reinforced_concrete:0)
RandomBlock(-5,30,-5,variedcommodities:crate:5,5,charm:crate_sealed:5,100)
Block(-5,30,-4,AIR:0)
Block(-5,30,-3,AIR:0)
Block(-5,30,-2,notreepunching:loose_rock/stone:0)
Block(-5,30,-1,AIR:0)
Block(-5,30,0,inspirations:path:0)
Block(-5,30,1,notreepunching:loose_rock/stone:0)
Block(-5,30,2,contenttweaker:resource_crate:0)
Block(-5,30,3,contenttweaker:reinforced_concrete:0)
Block(-5,30,6,contenttweaker:reinforced_concrete:0)
Block(-5,30,7,contenttweaker:reinforced_concrete:0)
Block(-5,31,-6,contenttweaker:reinforced_concrete:0)
Block(-5,31,-5,variedcommodities:table:1,f_bunker_apartements/161-variedcommodities_table.nbt)
Block(-5,31,-4,AIR:0)
Block(-5,31,-3,AIR:0)
Block(-5,31,-2,AIR:0)
Block(-5,31,-1,AIR:0)
Block(-5,31,0,AIR:0)
Block(-5,31,1,AIR:0)
Block(-5,31,2,variedcommodities:shelf:5,f_bunker_apartements/162-variedcommodities_shelf.nbt)
Block(-5,31,3,contenttweaker:reinforced_concrete:0)
Block(-5,31,6,contenttweaker:reinforced_concrete:0)
Block(-5,31,7,contenttweaker:reinforced_concrete:0)
Block(-5,32,-6,contenttweaker:reinforced_concrete:0)
Block(-5,32,-5,WEB:0)
Block(-5,32,-4,AIR:0)
Block(-5,32,-3,AIR:0)
Block(-5,32,-2,AIR:0)
Block(-5,32,-1,AIR:0)
Block(-5,32,0,AIR:0)
Block(-5,32,1,AIR:0)
Block(-5,32,2,WEB:0)
Block(-5,32,3,contenttweaker:reinforced_concrete:0)
Block(-5,32,6,contenttweaker:reinforced_concrete:0)
Block(-5,32,7,contenttweaker:reinforced_concrete:0)
Block(-5,33,-6,contenttweaker:reinforced_concrete:0)
Block(-5,33,-5,contenttweaker:reinforced_concrete:0)
Block(-5,33,-4,contenttweaker:reinforced_concrete:0)
Block(-5,33,-3,contenttweaker:reinforced_concrete:0)
Block(-5,33,-2,contenttweaker:reinforced_concrete:0)
Block(-5,33,-1,contenttweaker:reinforced_concrete:0)
Block(-5,33,0,contenttweaker:reinforced_concrete:0)
Block(-5,33,1,contenttweaker:reinforced_concrete:0)
Block(-5,33,2,contenttweaker:reinforced_concrete:0)
Block(-5,33,3,contenttweaker:reinforced_concrete:0)
Block(-5,33,6,contenttweaker:reinforced_concrete:0)
Block(-5,33,7,contenttweaker:reinforced_concrete:0)
Block(-5,34,-5,contenttweaker:reinforced_concrete:0)
Block(-5,34,-4,contenttweaker:reinforced_concrete:0)
Block(-5,34,-1,contenttweaker:reinforced_concrete:0)
Block(-5,34,0,contenttweaker:reinforced_concrete:0)
Block(-5,34,6,contenttweaker:reinforced_concrete:0)
Block(-5,34,7,contenttweaker:reinforced_concrete:0)
Block(-5,35,-5,contenttweaker:reinforced_concrete:0)
Block(-5,35,-4,contenttweaker:reinforced_concrete:0)
Block(-5,35,-1,contenttweaker:reinforced_concrete:0)
Block(-5,35,0,contenttweaker:reinforced_concrete:0)
Block(-5,35,6,contenttweaker:reinforced_concrete:0)
Block(-5,35,7,contenttweaker:reinforced_concrete:0)
Block(-5,36,-5,contenttweaker:reinforced_concrete:0)
Block(-5,36,-4,contenttweaker:reinforced_concrete:0)
Block(-5,36,-1,contenttweaker:reinforced_concrete:0)
Block(-5,36,0,contenttweaker:reinforced_concrete:0)
Block(-5,36,6,contenttweaker:reinforced_concrete:0)
Block(-5,36,7,contenttweaker:reinforced_concrete:0)
Block(-5,37,-5,contenttweaker:reinforced_concrete:0)
Block(-5,37,-4,contenttweaker:reinforced_concrete:0)
Block(-5,37,-1,contenttweaker:reinforced_concrete:0)
Block(-5,37,0,contenttweaker:reinforced_concrete:0)
Block(-5,37,6,contenttweaker:reinforced_concrete:0)
Block(-5,37,7,contenttweaker:reinforced_concrete:0)
Block(-5,38,-5,contenttweaker:reinforced_concrete:0)
Block(-5,38,-4,contenttweaker:reinforced_concrete:0)
Block(-5,38,-1,contenttweaker:reinforced_concrete:0)
Block(-5,38,0,contenttweaker:reinforced_concrete:0)
Block(-5,38,6,contenttweaker:reinforced_concrete:0)
Block(-5,38,7,contenttweaker:reinforced_concrete:0)
Block(-5,39,-5,contenttweaker:reinforced_concrete:0)
Block(-5,39,-4,contenttweaker:reinforced_concrete:0)
Block(-5,39,-1,contenttweaker:reinforced_concrete:0)
Block(-5,39,0,contenttweaker:reinforced_concrete:0)
Block(-5,39,6,contenttweaker:reinforced_concrete:0)
Block(-5,39,7,contenttweaker:reinforced_concrete:0)
Block(-5,40,-5,contenttweaker:reinforced_concrete:0)
Block(-5,40,-4,contenttweaker:reinforced_concrete:0)
Block(-5,40,-1,contenttweaker:reinforced_concrete:0)
Block(-5,40,0,contenttweaker:reinforced_concrete:0)
Block(-5,40,6,contenttweaker:reinforced_concrete:0)
Block(-5,40,7,contenttweaker:reinforced_concrete:0)
Block(-5,41,-5,contenttweaker:reinforced_concrete:0)
Block(-5,41,-4,contenttweaker:reinforced_concrete:0)
Block(-5,41,-1,contenttweaker:reinforced_concrete:0)
Block(-5,41,0,contenttweaker:reinforced_concrete:0)
Block(-5,41,6,contenttweaker:reinforced_concrete:0)
Block(-5,41,7,contenttweaker:reinforced_concrete:0)
Block(-5,42,-5,contenttweaker:reinforced_concrete:0)
Block(-5,42,-4,contenttweaker:reinforced_concrete:0)
Block(-5,42,-1,contenttweaker:reinforced_concrete:0)
Block(-5,42,0,contenttweaker:reinforced_concrete:0)
Block(-5,42,6,contenttweaker:reinforced_concrete:0)
Block(-5,42,7,contenttweaker:reinforced_concrete:0)
Block(-5,43,-5,contentcreator:concrete_slab_reinforced:0)
Block(-5,43,-4,contentcreator:concrete_slab_reinforced:0)
Block(-5,43,-1,contentcreator:concrete_slab_reinforced:0)
Block(-5,43,0,contentcreator:concrete_slab_reinforced:0)
Block(-5,43,6,contentcreator:concrete_slab_reinforced:0)
Block(-5,43,7,contentcreator:concrete_slab_reinforced:0)
Block(-4,0,-6,contenttweaker:reinforced_concrete:0)
Block(-4,0,-5,contenttweaker:reinforced_concrete:0)
Block(-4,0,-4,contenttweaker:reinforced_concrete:0)
Block(-4,0,-3,contenttweaker:reinforced_concrete:0)
Block(-4,0,-2,contenttweaker:reinforced_concrete:0)
Block(-4,0,-1,contenttweaker:reinforced_concrete:0)
Block(-4,0,0,contenttweaker:reinforced_concrete:0)
Block(-4,0,1,contenttweaker:reinforced_concrete:0)
Block(-4,0,2,contenttweaker:reinforced_concrete:0)
Block(-4,0,3,contenttweaker:reinforced_concrete:0)
Block(-4,0,4,contenttweaker:reinforced_concrete:0)
Block(-4,0,5,contenttweaker:reinforced_concrete:0)
Block(-4,0,6,contenttweaker:reinforced_concrete:0)
Block(-4,0,7,contenttweaker:reinforced_concrete:0)
Block(-4,0,8,contenttweaker:reinforced_concrete:0)
Block(-4,0,9,contenttweaker:reinforced_concrete:0)
Block(-4,1,-6,contenttweaker:reinforced_concrete:0)
Block(-4,1,-5,contenttweaker:reinforced_concrete:0)
Block(-4,1,-4,contenttweaker:reinforced_concrete:0)
Block(-4,1,-3,contenttweaker:reinforced_concrete:0)
Block(-4,1,-2,contenttweaker:reinforced_concrete:0)
Block(-4,1,-1,STATIONARY_WATER:0)
Block(-4,1,0,STATIONARY_WATER:0)
Block(-4,1,1,STATIONARY_WATER:0)
Block(-4,1,2,STATIONARY_WATER:0)
Block(-4,1,3,STATIONARY_WATER:0)
Block(-4,1,4,STATIONARY_WATER:0)
Block(-4,1,5,STATIONARY_WATER:0)
Block(-4,1,6,STATIONARY_WATER:0)
Block(-4,1,7,STATIONARY_WATER:0)
Block(-4,1,8,STATIONARY_WATER:0)
Block(-4,1,9,contenttweaker:reinforced_concrete:0)
Block(-4,2,-6,contenttweaker:reinforced_concrete:0)
Block(-4,2,-5,contentcreator:iron_plate_slab_reinforced:1)
Block(-4,2,-4,AIR:0)
Block(-4,2,-3,rustic:deathstalk_mushroom:0)
Block(-4,2,-2,rustic:iron_lattice:0)
Block(-4,2,-1,AIR:0)
Block(-4,2,0,AIR:0)
Block(-4,2,1,AIR:0)
Block(-4,2,2,AIR:0)
Block(-4,2,3,AIR:0)
Block(-4,2,4,AIR:0)
Block(-4,2,5,AIR:0)
Block(-4,2,6,AIR:0)
Block(-4,2,7,AIR:0)
Block(-4,2,8,contentcreator:iron_plate_slab_reinforced:1)
Block(-4,2,9,contenttweaker:reinforced_concrete:0)
Block(-4,3,-6,contenttweaker:reinforced_concrete:0)
Block(-4,3,-5,cookingforblockheads:tool_rack:3,f_bunker_apartements/163-cookingforblockheads_tool_rack.nbt)
Block(-4,3,-4,AIR:0)
Block(-4,3,-3,AIR:0)
Block(-4,3,-2,rustic:iron_lattice:0)
Block(-4,3,-1,AIR:0)
Block(-4,3,0,AIR:0)
Block(-4,3,1,AIR:0)
Block(-4,3,2,AIR:0)
Block(-4,3,3,AIR:0)
Block(-4,3,4,AIR:0)
Block(-4,3,5,AIR:0)
Block(-4,3,6,AIR:0)
Block(-4,3,7,AIR:0)
Block(-4,3,8,AIR:0)
Block(-4,3,9,contenttweaker:reinforced_concrete:0)
Block(-4,4,-6,contenttweaker:reinforced_concrete:0)
Block(-4,4,-5,AIR:0)
Block(-4,4,-4,AIR:0)
Block(-4,4,-3,AIR:0)
Block(-4,4,-2,rustic:iron_lattice:0)
Block(-4,4,-1,AIR:0)
Block(-4,4,0,AIR:0)
Block(-4,4,1,AIR:0)
Block(-4,4,2,AIR:0)
Block(-4,4,3,AIR:0)
Block(-4,4,4,AIR:0)
Block(-4,4,5,AIR:0)
Block(-4,4,6,AIR:0)
Block(-4,4,7,AIR:0)
Block(-4,4,8,AIR:0)
Block(-4,4,9,contenttweaker:reinforced_concrete:0)
Block(-4,5,-6,contenttweaker:reinforced_concrete:0)
Block(-4,5,-5,contenttweaker:reinforced_concrete:0)
Block(-4,5,-4,contenttweaker:reinforced_concrete:0)
Block(-4,5,-3,contenttweaker:reinforced_concrete:0)
Block(-4,5,-2,contenttweaker:reinforced_concrete:0)
Block(-4,5,-1,contenttweaker:reinforced_concrete:0)
Block(-4,5,0,contenttweaker:reinforced_concrete:0)
Block(-4,5,1,contenttweaker:reinforced_concrete:0)
Block(-4,5,2,contenttweaker:reinforced_concrete:0)
Block(-4,5,3,contenttweaker:reinforced_concrete:0)
Block(-4,5,4,contenttweaker:reinforced_concrete:0)
Block(-4,5,5,contenttweaker:reinforced_concrete:0)
Block(-4,5,6,contenttweaker:reinforced_concrete:0)
Block(-4,5,7,contenttweaker:reinforced_concrete:0)
Block(-4,5,8,contenttweaker:reinforced_concrete:0)
Block(-4,5,9,contenttweaker:reinforced_concrete:0)
Block(-4,6,-6,contenttweaker:reinforced_concrete:0)
Block(-4,6,-5,AIR:0)
Block(-4,6,-4,AIR:0)
Block(-4,6,-3,inspirations:path:0)
Block(-4,6,-2,AIR:0)
Block(-4,6,-1,notreepunching:loose_rock/stone:0)
Block(-4,6,0,AIR:0)
Block(-4,6,1,AIR:0)
Block(-4,6,2,contenttweaker:reinforced_concrete:0)
Block(-4,6,3,contenttweaker:reinforced_concrete:0)
Block(-4,6,4,contenttweaker:reinforced_concrete:0)
Block(-4,6,5,contenttweaker:reinforced_concrete:0)
Block(-4,6,6,contenttweaker:reinforced_concrete:0)
Block(-4,6,7,contenttweaker:reinforced_concrete:0)
Block(-4,6,8,contenttweaker:reinforced_concrete:0)
Block(-4,6,9,contenttweaker:reinforced_concrete:0)
Block(-4,7,-6,contenttweaker:reinforced_concrete:0)
Block(-4,7,-5,AIR:0)
Block(-4,7,-4,AIR:0)
Block(-4,7,-3,AIR:0)
Block(-4,7,-2,AIR:0)
Block(-4,7,-1,AIR:0)
Block(-4,7,0,AIR:0)
Block(-4,7,1,AIR:0)
Block(-4,7,2,nuclearcraft:fission_block:1)
Block(-4,7,3,AIR:0)
Block(-4,7,4,nuclearcraft:fission_block:1)
Block(-4,7,5,nuclearcraft:fission_block:1)
Block(-4,7,6,nuclearcraft:fission_block:1)
Block(-4,7,7,AIR:0)
Block(-4,7,8,nuclearcraft:fission_block:1)
Block(-4,7,9,contenttweaker:reinforced_concrete:0)
Block(-4,8,-6,contenttweaker:reinforced_concrete:0)
Block(-4,8,-5,WEB:0)
Block(-4,8,-4,AIR:0)
Block(-4,8,-3,AIR:0)
Block(-4,8,-2,AIR:0)
Block(-4,8,-1,AIR:0)
Block(-4,8,0,AIR:0)
Block(-4,8,1,AIR:0)
Block(-4,8,2,nuclearcraft:fission_block:1)
Block(-4,8,3,AIR:0)
Block(-4,8,4,contentcreator:iron_plate_stairs_reinforced:0)
Block(-4,8,5,contenttweaker:iron_plate_reinforced:0)
Block(-4,8,6,contentcreator:iron_plate_stairs_reinforced:0)
Block(-4,8,7,AIR:0)
Block(-4,8,8,nuclearcraft:fission_block:1)
Block(-4,8,9,contenttweaker:reinforced_concrete:0)
Block(-4,9,-6,contenttweaker:reinforced_concrete:0)
Block(-4,9,-5,contenttweaker:reinforced_concrete:0)
Block(-4,9,-4,contenttweaker:reinforced_concrete:0)
Block(-4,9,-3,contenttweaker:reinforced_concrete:0)
Block(-4,9,-2,contenttweaker:reinforced_concrete:0)
Block(-4,9,-1,contenttweaker:reinforced_concrete:0)
Block(-4,9,0,contenttweaker:reinforced_concrete:0)
Block(-4,9,1,contenttweaker:reinforced_concrete:0)
Block(-4,9,2,contenttweaker:reinforced_concrete:0)
Block(-4,9,3,contenttweaker:reinforced_concrete:0)
Block(-4,9,4,contenttweaker:reinforced_concrete:0)
Block(-4,9,5,contenttweaker:reinforced_concrete:0)
Block(-4,9,6,contenttweaker:reinforced_concrete:0)
Block(-4,9,7,contenttweaker:reinforced_concrete:0)
Block(-4,9,8,contenttweaker:reinforced_concrete:0)
Block(-4,9,9,contenttweaker:reinforced_concrete:0)
Block(-4,10,-6,contenttweaker:reinforced_concrete:0)
Block(-4,10,-5,cookingforblockheads:cabinet_spruce:10,../../../Chests/RLCraft/Containers/cooking_cabinet.nbt)
Block(-4,10,-4,AIR:0)
Block(-4,10,-3,inspirations:path:0)
Block(-4,10,-2,AIR:0)
Block(-4,10,-1,AIR:0)
Block(-4,10,0,inspirations:path:0)
Block(-4,10,1,variedcommodities:table:5,f_bunker_apartements/165-variedcommodities_table.nbt)
Block(-4,10,2,notreepunching:loose_rock/stone:0)
RandomBlock(-4,10,3,variedcommodities:crate:5,5,charm:crate_sealed:1,100)
Block(-4,10,4,AIR:0)
Block(-4,10,5,cookingforblockheads:sink:3,f_bunker_apartements/167-cookingforblockheads_sink.nbt)
Block(-4,10,6,contenttweaker:iron_plate_reinforced:0)
Block(-4,10,7,simpledifficulty:purifiedwater:0)
Block(-4,10,8,simpledifficulty:purifiedwater:0)
Block(-4,10,9,contenttweaker:reinforced_concrete:0)
Block(-4,11,-6,contenttweaker:reinforced_concrete:0)
Block(-4,11,-5,variedcommodities:shelf:1,f_bunker_apartements/168-variedcommodities_shelf.nbt)
Block(-4,11,-4,AIR:0)
Block(-4,11,-3,AIR:0)
Block(-4,11,-2,AIR:0)
Block(-4,11,-1,AIR:0)
Block(-4,11,0,AIR:0)
Block(-4,11,1,CHEST:2,../../../Chests/RLCraft/Ruins/starter.nbt)
Block(-4,11,2,AIR:0)
Block(-4,11,3,inspirations:bookshelf:7,f_bunker_apartements/170-inspirations_bookshelf.nbt)
Block(-4,11,4,AIR:0)
Block(-4,11,5,AIR:0)
Block(-4,11,6,quark:framed_glass:0)
Block(-4,11,7,simpledifficulty:purifiedwater:0)
Block(-4,11,8,simpledifficulty:purifiedwater:0)
Block(-4,11,9,contenttweaker:reinforced_concrete:0)
Block(-4,12,-6,contenttweaker:reinforced_concrete:0)
Block(-4,12,-5,AIR:0)
Block(-4,12,-4,AIR:0)
Block(-4,12,-3,AIR:0)
Block(-4,12,-2,AIR:0)
Block(-4,12,-1,AIR:0)
Block(-4,12,0,AIR:0)
Block(-4,12,1,AIR:0)
Block(-4,12,2,AIR:0)
Block(-4,12,3,AIR:0)
Block(-4,12,4,AIR:0)
Block(-4,12,5,AIR:0)
Block(-4,12,6,contenttweaker:iron_plate_reinforced:0)
Block(-4,12,7,simpledifficulty:purifiedwater:0)
Block(-4,12,8,simpledifficulty:purifiedwater:0)
Block(-4,12,9,contenttweaker:reinforced_concrete:0)
Block(-4,13,-6,contenttweaker:reinforced_concrete:0)
Block(-4,13,-5,contenttweaker:reinforced_concrete:0)
Block(-4,13,-4,contenttweaker:reinforced_concrete:0)
Block(-4,13,-3,contenttweaker:reinforced_concrete:0)
Block(-4,13,-2,contenttweaker:reinforced_concrete:0)
Block(-4,13,-1,contenttweaker:reinforced_concrete:0)
Block(-4,13,0,contenttweaker:reinforced_concrete:0)
Block(-4,13,1,contenttweaker:reinforced_concrete:0)
Block(-4,13,2,contenttweaker:reinforced_concrete:0)
Block(-4,13,3,contenttweaker:reinforced_concrete:0)
Block(-4,13,4,contenttweaker:reinforced_concrete:0)
Block(-4,13,5,contenttweaker:reinforced_concrete:0)
Block(-4,13,6,contenttweaker:reinforced_concrete:0)
Block(-4,13,7,contenttweaker:reinforced_concrete:0)
Block(-4,13,8,contenttweaker:reinforced_concrete:0)
Block(-4,13,9,contenttweaker:reinforced_concrete:0)
Block(-4,14,-6,contenttweaker:reinforced_concrete:0)
Block(-4,14,-5,inspirations:bookshelf:0,f_bunker_apartements/171-inspirations_bookshelf.nbt)
Block(-4,14,-4,notreepunching:loose_rock/stone:0)
Block(-4,14,-3,CARPET:4)
Block(-4,14,-2,CARPET:15)
Block(-4,14,-1,CARPET:15)
Block(-4,14,0,CARPET:15)
Block(-4,14,1,CARPET:15)
Block(-4,14,2,CARPET:4)
Block(-4,14,3,inspirations:bookshelf:7,f_bunker_apartements/172-inspirations_bookshelf.nbt)
Block(-4,14,4,inspirations:bookshelf:7,f_bunker_apartements/173-inspirations_bookshelf.nbt)
Block(-4,14,5,notreepunching:loose_rock/stone:0)
Block(-4,14,6,variedcommodities:chair:5,f_bunker_apartements/174-variedcommodities_chair.nbt)
Block(-4,14,7,variedcommodities:chair:1,f_bunker_apartements/175-variedcommodities_chair.nbt)
Block(-4,14,8,variedcommodities:chair:1,f_bunker_apartements/176-variedcommodities_chair.nbt)
Block(-4,14,9,contenttweaker:reinforced_concrete:0)
Block(-4,15,-6,contenttweaker:reinforced_concrete:0)
Block(-4,15,-5,inspirations:bookshelf:0,f_bunker_apartements/177-inspirations_bookshelf.nbt)
Block(-4,15,-4,AIR:0)
Block(-4,15,-3,AIR:0)
Block(-4,15,-2,AIR:0)
Block(-4,15,-1,AIR:0)
Block(-4,15,0,AIR:0)
Block(-4,15,1,AIR:0)
Block(-4,15,2,AIR:0)
Block(-4,15,3,inspirations:bookshelf:7,f_bunker_apartements/178-inspirations_bookshelf.nbt)
Block(-4,15,4,inspirations:bookshelf:7,f_bunker_apartements/179-inspirations_bookshelf.nbt)
Block(-4,15,5,AIR:0)
Block(-4,15,6,AIR:0)
Block(-4,15,7,AIR:0)
Block(-4,15,8,AIR:0)
Block(-4,15,9,contenttweaker:reinforced_concrete:0)
Block(-4,16,-6,contenttweaker:reinforced_concrete:0)
Block(-4,16,-5,inspirations:bookshelf:0,f_bunker_apartements/180-inspirations_bookshelf.nbt)
Block(-4,16,-4,STEP:8)
Block(-4,16,-3,AIR:0)
Block(-4,16,-2,variedcommodities:wall_banner,f_bunker_apartements/181-variedcommodities_wall_banner.nbt)
Block(-4,16,-1,AIR:0)
Block(-4,16,0,AIR:0)
Block(-4,16,1,AIR:0)
Block(-4,16,2,AIR:0)
Block(-4,16,3,inspirations:bookshelf:7,f_bunker_apartements/182-inspirations_bookshelf.nbt)
Block(-4,16,4,inspirations:bookshelf:7,f_bunker_apartements/183-inspirations_bookshelf.nbt)
Block(-4,16,5,variedcommodities:wall_banner,f_bunker_apartements/184-variedcommodities_wall_banner.nbt)
Block(-4,16,6,STEP:8)
Block(-4,16,7,AIR:0)
Block(-4,16,8,WEB:0)
Block(-4,16,9,contenttweaker:reinforced_concrete:0)
Block(-4,17,-6,contenttweaker:reinforced_concrete:0)
Block(-4,17,-5,contenttweaker:reinforced_concrete:0)
Block(-4,17,-4,contenttweaker:reinforced_concrete:0)
Block(-4,17,-3,contenttweaker:reinforced_concrete:0)
Block(-4,17,-2,contenttweaker:reinforced_concrete:0)
Block(-4,17,-1,contenttweaker:reinforced_concrete:0)
Block(-4,17,0,contenttweaker:reinforced_concrete:0)
Block(-4,17,1,contenttweaker:reinforced_concrete:0)
Block(-4,17,2,contenttweaker:reinforced_concrete:0)
Block(-4,17,3,contenttweaker:reinforced_concrete:0)
Block(-4,17,4,contenttweaker:reinforced_concrete:0)
Block(-4,17,5,contenttweaker:reinforced_concrete:0)
Block(-4,17,6,contenttweaker:reinforced_concrete:0)
Block(-4,17,7,contenttweaker:reinforced_concrete:0)
Block(-4,17,8,contenttweaker:reinforced_concrete:0)
Block(-4,17,9,contenttweaker:reinforced_concrete:0)
Block(-4,18,-6,contenttweaker:reinforced_concrete:0)
Block(-4,18,-5,inspirations:bookshelf:3,f_bunker_apartements/185-inspirations_bookshelf.nbt)
Block(-4,18,-4,AIR:0)
Block(-4,18,-3,AIR:0)
Block(-4,18,-2,rustic:deathstalk_mushroom:3)
Block(-4,18,-1,AIR:0)
Block(-4,18,0,AIR:0)
Block(-4,18,1,inspirations:path:0)
Block(-4,18,2,variedcommodities:stool:1,f_bunker_apartements/186-variedcommodities_stool.nbt)
Block(-4,18,3,inspirations:bookshelf:7,f_bunker_apartements/187-inspirations_bookshelf.nbt)
Block(-4,18,4,inspirations:bookshelf:7,f_bunker_apartements/188-inspirations_bookshelf.nbt)
Block(-4,18,5,AIR:0)
Block(-4,18,6,variedcommodities:chair:5,f_bunker_apartements/189-variedcommodities_chair.nbt)
Block(-4,18,7,variedcommodities:chair:1,f_bunker_apartements/190-variedcommodities_chair.nbt)
Block(-4,18,8,variedcommodities:chair:1,f_bunker_apartements/191-variedcommodities_chair.nbt)
Block(-4,18,9,contenttweaker:reinforced_concrete:0)
Block(-4,19,-6,contenttweaker:reinforced_concrete:0)
Block(-4,19,-5,inspirations:bookshelf:3,f_bunker_apartements/192-inspirations_bookshelf.nbt)
Block(-4,19,-4,AIR:0)
Block(-4,19,-3,AIR:0)
Block(-4,19,-2,AIR:0)
Block(-4,19,-1,AIR:0)
Block(-4,19,0,AIR:0)
Block(-4,19,1,AIR:0)
Block(-4,19,2,AIR:0)
Block(-4,19,3,inspirations:bookshelf:7,f_bunker_apartements/193-inspirations_bookshelf.nbt)
Block(-4,19,4,inspirations:bookshelf:7,f_bunker_apartements/194-inspirations_bookshelf.nbt)
Block(-4,19,5,AIR:0)
Block(-4,19,6,AIR:0)
Block(-4,19,7,AIR:0)
Block(-4,19,8,AIR:0)
Block(-4,19,9,contenttweaker:reinforced_concrete:0)
Block(-4,20,-6,contenttweaker:reinforced_concrete:0)
Block(-4,20,-5,inspirations:bookshelf:3,f_bunker_apartements/195-inspirations_bookshelf.nbt)
Block(-4,20,-4,STEP:8)
Block(-4,20,-3,AIR:0)
Block(-4,20,-2,variedcommodities:wall_banner,f_bunker_apartements/196-variedcommodities_wall_banner.nbt)
Block(-4,20,-1,AIR:0)
Block(-4,20,0,AIR:0)
Block(-4,20,1,AIR:0)
Block(-4,20,2,AIR:0)
Block(-4,20,3,inspirations:bookshelf:7,f_bunker_apartements/197-inspirations_bookshelf.nbt)
Block(-4,20,4,inspirations:bookshelf:7,f_bunker_apartements/198-inspirations_bookshelf.nbt)
Block(-4,20,5,AIR:0)
Block(-4,20,6,STEP:8)
Block(-4,20,7,AIR:0)
Block(-4,20,8,WEB:0)
Block(-4,20,9,contenttweaker:reinforced_concrete:0)
Block(-4,21,-6,contenttweaker:reinforced_concrete:0)
Block(-4,21,-5,contenttweaker:reinforced_concrete:0)
Block(-4,21,-4,contenttweaker:reinforced_concrete:0)
Block(-4,21,-3,contenttweaker:reinforced_concrete:0)
Block(-4,21,-2,contenttweaker:reinforced_concrete:0)
Block(-4,21,-1,contenttweaker:reinforced_concrete:0)
Block(-4,21,0,contenttweaker:reinforced_concrete:0)
Block(-4,21,1,contenttweaker:reinforced_concrete:0)
Block(-4,21,2,contenttweaker:reinforced_concrete:0)
Block(-4,21,3,contenttweaker:reinforced_concrete:0)
Block(-4,21,4,contenttweaker:reinforced_concrete:0)
Block(-4,21,5,contenttweaker:reinforced_concrete:0)
Block(-4,21,6,contenttweaker:reinforced_concrete:0)
Block(-4,21,7,contenttweaker:reinforced_concrete:0)
Block(-4,21,8,contenttweaker:reinforced_concrete:0)
Block(-4,21,9,contenttweaker:reinforced_concrete:0)
Block(-4,22,-6,contenttweaker:reinforced_concrete:0)
Block(-4,22,-5,inspirations:bookshelf:3,f_bunker_apartements/199-inspirations_bookshelf.nbt)
Block(-4,22,-4,AIR:0)
Block(-4,22,-3,AIR:0)
Block(-4,22,-2,inspirations:path:0)
Block(-4,22,-1,AIR:0)
Block(-4,22,0,AIR:0)
Block(-4,22,1,notreepunching:loose_rock/stone:0)
Block(-4,22,2,variedcommodities:chair:5,f_bunker_apartements/200-variedcommodities_chair.nbt)
Block(-4,22,3,inspirations:bookshelf:7,f_bunker_apartements/201-inspirations_bookshelf.nbt)
Block(-4,22,4,inspirations:bookshelf:7,f_bunker_apartements/202-inspirations_bookshelf.nbt)
Block(-4,22,5,WEB:0)
Block(-4,22,6,variedcommodities:chair:5,f_bunker_apartements/203-variedcommodities_chair.nbt)
Block(-4,22,7,variedcommodities:chair:1,f_bunker_apartements/204-variedcommodities_chair.nbt)
Block(-4,22,8,variedcommodities:chair:1,f_bunker_apartements/205-variedcommodities_chair.nbt)
Block(-4,22,9,contenttweaker:reinforced_concrete:0)
Block(-4,23,-6,contenttweaker:reinforced_concrete:0)
Block(-4,23,-5,inspirations:bookshelf:3,f_bunker_apartements/206-inspirations_bookshelf.nbt)
Block(-4,23,-4,AIR:0)
