
#######################################################################
# +-----------------------------------------------------------------+ #
# |                            BO4 object                           | #
# +-----------------------------------------------------------------+ #
#######################################################################

Author: NLBlackEagle

Description: No description given

SettingsMode: WriteWithoutComments


#######################################################################
# +-----------------------------------------------------------------+ #
# |                          Main settings                          | #
# +-----------------------------------------------------------------+ #
#######################################################################

FixedRotation: 

Frequency: 0

SpawnHeight: highestBlock

UseCenterForHighestBlock: true

##############################
# Height Limits for the BO4. #
##############################

MinHeight: 0

MaxHeight: 255

InheritBO3: 

InheritBO3Rotation: NORTH

OverrideChildSettings: true

OverrideParentHeight: false

CanOverride: false

BranchFrequency: 0

BranchFrequencyGroup: 

MustBeBelowOther: false

MustBeInside: 

CannotBeInside: 

ReplacesBO3: 

MustBeInsideWorldBorders: false

CanSpawnOnWater: true

SpawnOnWaterOnly: false

SpawnUnderWater: false

SpawnAtWaterLevel: false

HeightOffset: 0

RemoveAir: false

ReplaceAbove: 

ReplaceBelow: 

ReplaceWithBiomeBlocks: true

ReplaceWithSurfaceBlock: GRASS

ReplaceWithGroundBlock: DIRT

ReplaceWithStoneBlock: STONE

SmoothRadius: 0

SmoothHeightOffset: 0

SmoothStartTop: false

SmoothStartWood: false

SmoothingSurfaceBlock: 

SmoothingGroundBlock: 

BO3Group: 

IsSpawnPoint: false

DoReplaceBlocks: true


#######################################################################
# +-----------------------------------------------------------------+ #
# |                              Blocks                             | #
# +-----------------------------------------------------------------+ #
#######################################################################

Block(-8,67,-7,biomesoplenty:dirt:8)
Block(-8,67,-6,biomesoplenty:dirt:8)
Block(-8,67,-5,biomesoplenty:dirt:8)
Block(-8,67,-4,biomesoplenty:dirt:8)
Block(-8,67,-3,biomesoplenty:dirt:8)
Block(-8,67,-2,biomesoplenty:dirt:8)
Block(-8,67,-1,biomesoplenty:dirt:8)
Block(-8,67,0,biomesoplenty:dirt:8)
Block(-8,67,1,biomesoplenty:dirt:8)
Block(-8,67,2,biomesoplenty:dirt:8)
Block(-8,67,3,biomesoplenty:dirt:8)
Block(-8,67,4,biomesoplenty:dirt:8)
Block(-8,67,5,biomesoplenty:dirt:8)
Block(-8,67,6,biomesoplenty:dirt:8)
Block(-8,67,7,biomesoplenty:dirt:8)
Block(-8,67,8,biomesoplenty:dirt:8)
Block(-8,68,-7,biomesoplenty:dirt:8)
Block(-8,68,-6,biomesoplenty:dirt:8)
Block(-8,68,-5,biomesoplenty:dirt:8)
Block(-8,68,-4,biomesoplenty:dirt:8)
Block(-8,68,-3,biomesoplenty:dirt:8)
Block(-8,68,-2,biomesoplenty:dirt:8)
Block(-8,68,-1,biomesoplenty:dirt:8)
Block(-8,68,0,biomesoplenty:dirt:8)
Block(-8,68,1,biomesoplenty:dirt:8)
Block(-8,68,2,biomesoplenty:dirt:8)
Block(-8,68,3,biomesoplenty:dirt:8)
Block(-8,68,4,biomesoplenty:dirt:8)
Block(-8,68,5,biomesoplenty:dirt:8)
Block(-8,68,6,biomesoplenty:dirt:8)
Block(-8,68,7,biomesoplenty:dirt:8)
Block(-8,68,8,biomesoplenty:dirt:8)
Block(-8,69,-7,biomesoplenty:dirt:8)
Block(-8,69,-6,biomesoplenty:dirt:8)
Block(-8,69,-5,biomesoplenty:dirt:8)
Block(-8,69,-4,biomesoplenty:dirt:8)
Block(-8,69,-3,biomesoplenty:dirt:8)
Block(-8,69,-2,biomesoplenty:dirt:8)
Block(-8,69,-1,biomesoplenty:dirt:8)
Block(-8,69,0,biomesoplenty:dirt:8)
Block(-8,69,1,biomesoplenty:dirt:8)
Block(-8,69,2,biomesoplenty:dirt:8)
Block(-8,69,3,biomesoplenty:dirt:8)
Block(-8,69,4,biomesoplenty:dirt:8)
Block(-8,69,5,biomesoplenty:dirt:8)
Block(-8,69,6,biomesoplenty:dirt:8)
Block(-8,69,7,biomesoplenty:dirt:8)
Block(-8,69,8,biomesoplenty:dirt:8)
Block(-8,70,-7,biomesoplenty:dirt:8)
Block(-8,70,-6,biomesoplenty:dirt:8)
Block(-8,70,-5,biomesoplenty:dirt:8)
Block(-8,70,-4,biomesoplenty:dirt:8)
Block(-8,70,-3,biomesoplenty:dirt:8)
Block(-8,70,-2,biomesoplenty:dirt:8)
Block(-8,70,-1,biomesoplenty:dirt:8)
Block(-8,70,0,biomesoplenty:dirt:8)
Block(-8,70,1,biomesoplenty:dirt:8)
Block(-8,70,2,biomesoplenty:dirt:8)
Block(-8,70,3,biomesoplenty:dirt:8)
Block(-8,70,4,biomesoplenty:dirt:8)
Block(-8,70,5,biomesoplenty:dirt:8)
Block(-8,70,6,biomesoplenty:dirt:8)
Block(-8,70,7,biomesoplenty:dirt:8)
Block(-8,70,8,biomesoplenty:dirt:8)
Block(-8,71,-7,biomesoplenty:dirt:8)
Block(-8,71,-6,biomesoplenty:dirt:8)
Block(-8,71,-5,biomesoplenty:dirt:8)
Block(-8,71,-4,biomesoplenty:dirt:8)
Block(-8,71,-3,biomesoplenty:dirt:8)
Block(-8,71,-2,biomesoplenty:dirt:8)
Block(-8,71,-1,biomesoplenty:dirt:8)
Block(-8,71,0,biomesoplenty:dirt:8)
Block(-8,71,1,biomesoplenty:dirt:8)
Block(-8,71,2,biomesoplenty:dirt:8)
Block(-8,71,3,biomesoplenty:dirt:8)
Block(-8,71,4,biomesoplenty:dirt:8)
Block(-8,71,5,biomesoplenty:dirt:8)
Block(-8,71,6,biomesoplenty:dirt:8)
Block(-8,71,7,biomesoplenty:dirt:8)
Block(-8,71,8,biomesoplenty:dirt:8)
Block(-8,72,-7,biomesoplenty:dirt:8)
Block(-8,72,-6,biomesoplenty:dirt:8)
Block(-8,72,-5,biomesoplenty:dirt:8)
Block(-8,72,-4,biomesoplenty:dirt:8)
Block(-8,72,-3,biomesoplenty:dirt:8)
Block(-8,72,-2,biomesoplenty:dirt:8)
Block(-8,72,-1,biomesoplenty:dirt:8)
Block(-8,72,0,biomesoplenty:dirt:8)
Block(-8,72,1,biomesoplenty:dirt:8)
Block(-8,72,2,biomesoplenty:dirt:8)
Block(-8,72,3,biomesoplenty:dirt:8)
Block(-8,72,4,biomesoplenty:dirt:8)
Block(-8,72,5,biomesoplenty:dirt:8)
Block(-8,72,6,biomesoplenty:dirt:8)
Block(-8,72,7,biomesoplenty:dirt:8)
Block(-8,72,8,biomesoplenty:dirt:8)
Block(-8,73,-7,biomesoplenty:dirt:8)
Block(-8,73,-6,biomesoplenty:dirt:8)
Block(-8,73,-5,biomesoplenty:dirt:8)
Block(-8,73,-4,biomesoplenty:dirt:8)
Block(-8,73,-3,biomesoplenty:dirt:8)
Block(-8,73,-2,biomesoplenty:dirt:8)
Block(-8,73,-1,biomesoplenty:dirt:8)
Block(-8,73,0,biomesoplenty:dirt:8)
Block(-8,73,1,biomesoplenty:dirt:8)
Block(-8,73,2,biomesoplenty:dirt:8)
Block(-8,73,3,biomesoplenty:dirt:8)
Block(-8,73,4,biomesoplenty:dirt:8)
Block(-8,73,5,biomesoplenty:dirt:8)
Block(-8,73,6,biomesoplenty:dirt:8)
Block(-8,73,7,biomesoplenty:dirt:8)
Block(-8,73,8,biomesoplenty:dirt:8)
Block(-8,74,-7,biomesoplenty:dirt:8)
Block(-8,74,-6,biomesoplenty:dirt:8)
Block(-8,74,-5,biomesoplenty:dirt:8)
Block(-8,74,-4,biomesoplenty:dirt:8)
Block(-8,74,-3,biomesoplenty:dirt:8)
Block(-8,74,-2,biomesoplenty:dirt:8)
Block(-8,74,-1,biomesoplenty:dirt:8)
Block(-8,74,0,biomesoplenty:dirt:8)
Block(-8,74,1,biomesoplenty:dirt:8)
Block(-8,74,2,biomesoplenty:dirt:8)
Block(-8,74,3,biomesoplenty:dirt:8)
Block(-8,74,4,biomesoplenty:dirt:8)
Block(-8,74,5,biomesoplenty:dirt:8)
Block(-8,74,6,biomesoplenty:dirt:8)
Block(-8,74,7,biomesoplenty:dirt:8)
Block(-8,74,8,biomesoplenty:dirt:8)
Block(-8,75,-7,biomesoplenty:dirt:8)
Block(-8,75,-6,biomesoplenty:dirt:8)
Block(-8,75,-5,biomesoplenty:dirt:8)
Block(-8,75,-4,biomesoplenty:dirt:8)
Block(-8,75,-3,biomesoplenty:dirt:8)
Block(-8,75,-2,biomesoplenty:dirt:8)
Block(-8,75,-1,biomesoplenty:dirt:8)
Block(-8,75,0,biomesoplenty:dirt:8)
Block(-8,75,1,biomesoplenty:dirt:8)
Block(-8,75,2,biomesoplenty:dirt:8)
Block(-8,75,3,biomesoplenty:dirt:8)
Block(-8,75,4,biomesoplenty:dirt:8)
Block(-8,75,5,biomesoplenty:dirt:8)
Block(-8,75,6,biomesoplenty:dirt:8)
Block(-8,75,7,biomesoplenty:dirt:8)
Block(-8,75,8,biomesoplenty:dirt:8)
Block(-8,76,-7,biomesoplenty:dirt:8)
Block(-8,76,-6,biomesoplenty:dirt:8)
Block(-8,76,-5,biomesoplenty:dirt:8)
Block(-8,76,-4,biomesoplenty:dirt:8)
Block(-8,76,-3,biomesoplenty:dirt:8)
Block(-8,76,-2,biomesoplenty:dirt:8)
Block(-8,76,-1,biomesoplenty:dirt:8)
Block(-8,76,0,biomesoplenty:dirt:8)
Block(-8,76,1,biomesoplenty:dirt:8)
Block(-8,76,2,biomesoplenty:dirt:8)
Block(-8,76,3,biomesoplenty:dirt:8)
Block(-8,76,4,biomesoplenty:dirt:8)
Block(-8,76,5,biomesoplenty:dirt:8)
Block(-8,76,6,biomesoplenty:dirt:8)
Block(-8,76,7,biomesoplenty:dirt:8)
Block(-8,76,8,biomesoplenty:dirt:8)
Block(-8,77,-7,biomesoplenty:dirt:8)
Block(-8,77,-6,biomesoplenty:dirt:8)
Block(-8,77,-5,biomesoplenty:dirt:8)
Block(-8,77,-4,biomesoplenty:dirt:8)
Block(-8,77,-3,biomesoplenty:dirt:8)
Block(-8,77,-2,biomesoplenty:dirt:8)
Block(-8,77,-1,biomesoplenty:dirt:8)
Block(-8,77,0,srparasites:parasitestain:2)
Block(-8,77,1,srparasites:parasitestain:2)
Block(-8,77,2,biomesoplenty:dirt:8)
Block(-8,77,3,biomesoplenty:dirt:8)
Block(-8,77,4,biomesoplenty:dirt:8)
Block(-8,77,5,biomesoplenty:dirt:8)
Block(-8,77,6,biomesoplenty:dirt:8)
Block(-8,77,7,biomesoplenty:dirt:8)
Block(-8,77,8,srparasites:parasitestain:2)
Block(-8,78,-7,srparasites:parasitestain:2)
Block(-8,78,-6,srparasites:parasitestain:2)
Block(-8,78,-5,srparasites:parasitestain:2)
Block(-8,78,-4,srparasites:parasitestain:2)
Block(-8,78,-3,biomesoplenty:dirt:8)
Block(-8,78,-2,biomesoplenty:dirt:8)
Block(-8,78,-1,biomesoplenty:dirt:8)
Block(-8,78,0,srparasites:parasitestain:2)
Block(-8,78,1,srparasites:parasitestain:2)
Block(-8,78,2,biomesoplenty:dirt:8)
Block(-8,78,3,biomesoplenty:dirt:8)
Block(-8,78,4,biomesoplenty:dirt:8)
Block(-8,78,5,biomesoplenty:dirt:8)
Block(-8,78,6,biomesoplenty:dirt:8)
Block(-8,78,7,biomesoplenty:dirt:8)
Block(-8,78,8,srparasites:parasitestain:2)
Block(-8,79,-7,srparasites:parasitestain:0)
Block(-8,79,-6,srparasites:parasitestain:0)
Block(-8,79,-5,srparasites:parasitestain:0)
Block(-8,79,-4,srparasites:parasitestain:0)
Block(-8,79,-3,srparasites:parasitestain:2)
Block(-8,79,-2,srparasites:parasitestain:2)
Block(-8,79,-1,srparasites:parasitestain:2)
Block(-8,79,0,srparasites:parasitestain:0)
Block(-8,79,1,srparasites:parasitestain:0)
Block(-8,79,2,srparasites:parasitestain:2)
Block(-8,79,3,srparasites:parasitestain:2)
Block(-8,79,4,srparasites:parasitestain:2)
Block(-8,79,5,srparasites:parasitestain:2)
Block(-8,79,6,srparasites:parasitestain:2)
Block(-8,79,7,srparasites:parasitestain:2)
Block(-8,79,8,srparasites:parasitestain:0)
Block(-8,80,-7,AIR:0)
Block(-8,80,-6,AIR:0)
Block(-8,80,-5,biomesoplenty:other_slab:0)
Block(-8,80,-4,srparasites:parasitestain:0)
Block(-8,80,-3,srparasites:parasitestain:0)
Block(-8,80,-2,srparasites:parasitestain:0)
Block(-8,80,-1,srparasites:parasitestain:0)
Block(-8,80,0,biomesoplenty:dirt:8)
Block(-8,80,1,biomesoplenty:dirt:8)
Block(-8,80,2,srparasites:parasitestain:0)
Block(-8,80,3,srparasites:parasitestain:0)
Block(-8,80,4,srparasites:parasitestain:0)
Block(-8,80,5,srparasites:parasitestain:0)
Block(-8,80,6,srparasites:parasitestain:0)
Block(-8,80,7,srparasites:parasitestain:0)
Block(-8,80,8,srparasites:parasitebush:0)
Block(-8,81,-7,AIR:0)
Block(-8,81,-6,AIR:0)
Block(-8,81,-5,AIR:0)
Block(-8,81,-4,srparasites:parasitebush:2)
Block(-8,81,-3,AIR:0)
Block(-8,81,-2,biomesoplenty:other_slab:0)
Block(-8,81,-1,AIR:0)
Block(-8,81,0,AIR:0)
Block(-8,81,1,AIR:0)
Block(-8,81,2,biomesoplenty:other_slab:0)
Block(-8,81,3,biomesoplenty:other_slab:0)
Block(-8,81,4,AIR:0)
Block(-8,81,5,AIR:0)
Block(-8,81,6,srparasites:parasitebush:2)
Block(-8,81,7,AIR:0)
Block(-8,81,8,AIR:0)
Block(-8,82,-7,AIR:0)
Block(-8,82,-6,AIR:0)
Block(-8,82,-5,AIR:0)
Block(-8,82,-4,AIR:0)
Block(-8,82,-3,AIR:0)
Block(-8,82,-2,AIR:0)
Block(-8,82,-1,AIR:0)
Block(-8,82,0,AIR:0)
Block(-8,82,1,AIR:0)
Block(-8,82,2,AIR:0)
Block(-8,82,3,AIR:0)
Block(-8,82,4,AIR:0)
Block(-8,82,5,AIR:0)
Block(-8,82,6,AIR:0)
Block(-8,82,7,AIR:0)
Block(-8,82,8,AIR:0)
Block(-8,83,-7,AIR:0)
Block(-8,83,-6,AIR:0)
Block(-8,83,-5,AIR:0)
Block(-8,83,-4,AIR:0)
Block(-8,83,-3,AIR:0)
Block(-8,83,-2,AIR:0)
Block(-8,83,-1,AIR:0)
Block(-8,83,0,AIR:0)
Block(-8,83,1,AIR:0)
Block(-8,83,2,AIR:0)
Block(-8,83,3,AIR:0)
Block(-8,83,4,AIR:0)
Block(-8,83,5,AIR:0)
Block(-8,83,6,AIR:0)
Block(-8,83,7,AIR:0)
Block(-8,83,8,AIR:0)
Block(-7,1,-7,srparasites:parasiterubbledense:1)
Block(-7,32,-7,srparasites:parasiterubbledense:1)
Block(-7,67,-7,biomesoplenty:dirt:8)
Block(-7,67,-6,biomesoplenty:dirt:8)
Block(-7,67,-5,biomesoplenty:dirt:8)
Block(-7,67,-4,biomesoplenty:dirt:8)
Block(-7,67,-3,biomesoplenty:dirt:8)
Block(-7,67,-2,biomesoplenty:dirt:8)
Block(-7,67,-1,biomesoplenty:dirt:8)
Block(-7,67,0,biomesoplenty:dirt:8)
Block(-7,67,1,biomesoplenty:dirt:8)
Block(-7,67,2,biomesoplenty:dirt:8)
Block(-7,67,3,biomesoplenty:dirt:8)
Block(-7,67,4,biomesoplenty:dirt:8)
Block(-7,67,5,biomesoplenty:dirt:8)
Block(-7,67,6,biomesoplenty:dirt:8)
Block(-7,67,7,biomesoplenty:dirt:8)
Block(-7,67,8,biomesoplenty:dirt:8)
Block(-7,68,-7,biomesoplenty:dirt:8)
Block(-7,68,-6,biomesoplenty:dirt:8)
Block(-7,68,-5,biomesoplenty:dirt:8)
Block(-7,68,-4,biomesoplenty:dirt:8)
Block(-7,68,-3,biomesoplenty:dirt:8)
Block(-7,68,-2,biomesoplenty:dirt:8)
Block(-7,68,-1,biomesoplenty:dirt:8)
Block(-7,68,0,biomesoplenty:dirt:8)
Block(-7,68,1,biomesoplenty:dirt:8)
Block(-7,68,2,biomesoplenty:dirt:8)
Block(-7,68,3,biomesoplenty:dirt:8)
Block(-7,68,4,biomesoplenty:dirt:8)
Block(-7,68,5,biomesoplenty:dirt:8)
Block(-7,68,6,biomesoplenty:dirt:8)
Block(-7,68,7,biomesoplenty:dirt:8)
Block(-7,68,8,biomesoplenty:dirt:8)
Block(-7,69,-7,biomesoplenty:dirt:8)
Block(-7,69,-6,biomesoplenty:dirt:8)
Block(-7,69,-5,biomesoplenty:dirt:8)
Block(-7,69,-4,biomesoplenty:dirt:8)
Block(-7,69,-3,biomesoplenty:dirt:8)
Block(-7,69,-2,biomesoplenty:dirt:8)
Block(-7,69,-1,biomesoplenty:dirt:8)
Block(-7,69,0,biomesoplenty:dirt:8)
Block(-7,69,1,biomesoplenty:dirt:8)
Block(-7,69,2,biomesoplenty:dirt:8)
Block(-7,69,3,biomesoplenty:dirt:8)
Block(-7,69,4,biomesoplenty:dirt:8)
Block(-7,69,5,biomesoplenty:dirt:8)
Block(-7,69,6,biomesoplenty:dirt:8)
Block(-7,69,7,biomesoplenty:dirt:8)
Block(-7,69,8,biomesoplenty:dirt:8)
Block(-7,70,-7,biomesoplenty:dirt:8)
Block(-7,70,-6,biomesoplenty:dirt:8)
Block(-7,70,-5,biomesoplenty:dirt:8)
Block(-7,70,-4,biomesoplenty:dirt:8)
Block(-7,70,-3,biomesoplenty:dirt:8)
Block(-7,70,-2,biomesoplenty:dirt:8)
Block(-7,70,-1,biomesoplenty:dirt:8)
Block(-7,70,0,biomesoplenty:dirt:8)
Block(-7,70,1,biomesoplenty:dirt:8)
Block(-7,70,2,biomesoplenty:dirt:8)
Block(-7,70,3,biomesoplenty:dirt:8)
Block(-7,70,4,biomesoplenty:dirt:8)
Block(-7,70,5,biomesoplenty:dirt:8)
Block(-7,70,6,biomesoplenty:dirt:8)
Block(-7,70,7,biomesoplenty:dirt:8)
Block(-7,70,8,biomesoplenty:dirt:8)
Block(-7,71,-7,biomesoplenty:dirt:8)
Block(-7,71,-6,biomesoplenty:dirt:8)
Block(-7,71,-5,biomesoplenty:dirt:8)
Block(-7,71,-4,biomesoplenty:dirt:8)
Block(-7,71,-3,biomesoplenty:dirt:8)
Block(-7,71,-2,biomesoplenty:dirt:8)
Block(-7,71,-1,biomesoplenty:dirt:8)
Block(-7,71,0,biomesoplenty:dirt:8)
Block(-7,71,1,biomesoplenty:dirt:8)
Block(-7,71,2,biomesoplenty:dirt:8)
Block(-7,71,3,biomesoplenty:dirt:8)
Block(-7,71,4,biomesoplenty:dirt:8)
Block(-7,71,5,biomesoplenty:dirt:8)
Block(-7,71,6,biomesoplenty:dirt:8)
Block(-7,71,7,biomesoplenty:dirt:8)
Block(-7,71,8,biomesoplenty:dirt:8)
Block(-7,72,-7,biomesoplenty:dirt:8)
Block(-7,72,-6,biomesoplenty:dirt:8)
Block(-7,72,-5,biomesoplenty:dirt:8)
Block(-7,72,-4,biomesoplenty:dirt:8)
Block(-7,72,-3,biomesoplenty:dirt:8)
Block(-7,72,-2,biomesoplenty:dirt:8)
Block(-7,72,-1,biomesoplenty:dirt:8)
Block(-7,72,0,biomesoplenty:dirt:8)
Block(-7,72,1,biomesoplenty:dirt:8)
Block(-7,72,2,biomesoplenty:dirt:8)
Block(-7,72,3,biomesoplenty:dirt:8)
Block(-7,72,4,biomesoplenty:dirt:8)
Block(-7,72,5,biomesoplenty:dirt:8)
Block(-7,72,6,biomesoplenty:dirt:8)
Block(-7,72,7,biomesoplenty:dirt:8)
Block(-7,72,8,biomesoplenty:dirt:8)
Block(-7,73,-7,biomesoplenty:dirt:8)
Block(-7,73,-6,biomesoplenty:dirt:8)
Block(-7,73,-5,biomesoplenty:dirt:8)
Block(-7,73,-4,biomesoplenty:dirt:8)
Block(-7,73,-3,biomesoplenty:dirt:8)
Block(-7,73,-2,biomesoplenty:dirt:8)
Block(-7,73,-1,biomesoplenty:dirt:8)
Block(-7,73,0,biomesoplenty:dirt:8)
Block(-7,73,1,biomesoplenty:dirt:8)
Block(-7,73,2,biomesoplenty:dirt:8)
Block(-7,73,3,biomesoplenty:dirt:8)
Block(-7,73,4,biomesoplenty:dirt:8)
Block(-7,73,5,biomesoplenty:dirt:8)
Block(-7,73,6,biomesoplenty:dirt:8)
Block(-7,73,7,biomesoplenty:dirt:8)
Block(-7,73,8,biomesoplenty:dirt:8)
Block(-7,74,-7,biomesoplenty:dirt:8)
Block(-7,74,-6,biomesoplenty:dirt:8)
Block(-7,74,-5,biomesoplenty:dirt:8)
Block(-7,74,-4,biomesoplenty:dirt:8)
Block(-7,74,-3,biomesoplenty:dirt:8)
Block(-7,74,-2,biomesoplenty:dirt:8)
Block(-7,74,-1,biomesoplenty:dirt:8)
Block(-7,74,0,biomesoplenty:dirt:8)
Block(-7,74,1,biomesoplenty:dirt:8)
Block(-7,74,2,biomesoplenty:dirt:8)
Block(-7,74,3,biomesoplenty:dirt:8)
Block(-7,74,4,biomesoplenty:dirt:8)
Block(-7,74,5,biomesoplenty:dirt:8)
Block(-7,74,6,biomesoplenty:dirt:8)
Block(-7,74,7,biomesoplenty:dirt:8)
Block(-7,74,8,biomesoplenty:dirt:8)
Block(-7,75,-7,biomesoplenty:dirt:8)
Block(-7,75,-6,biomesoplenty:dirt:8)
Block(-7,75,-5,biomesoplenty:dirt:8)
Block(-7,75,-4,biomesoplenty:dirt:8)
Block(-7,75,-3,biomesoplenty:dirt:8)
Block(-7,75,-2,biomesoplenty:dirt:8)
Block(-7,75,-1,biomesoplenty:dirt:8)
Block(-7,75,0,biomesoplenty:dirt:8)
Block(-7,75,1,biomesoplenty:dirt:8)
Block(-7,75,2,biomesoplenty:dirt:8)
Block(-7,75,3,biomesoplenty:dirt:8)
Block(-7,75,4,biomesoplenty:dirt:8)
Block(-7,75,5,biomesoplenty:dirt:8)
Block(-7,75,6,biomesoplenty:dirt:8)
Block(-7,75,7,biomesoplenty:dirt:8)
Block(-7,75,8,biomesoplenty:dirt:8)
Block(-7,76,-7,biomesoplenty:dirt:8)
Block(-7,76,-6,biomesoplenty:dirt:8)
Block(-7,76,-5,biomesoplenty:dirt:8)
Block(-7,76,-4,biomesoplenty:dirt:8)
Block(-7,76,-3,biomesoplenty:dirt:8)
Block(-7,76,-2,biomesoplenty:dirt:8)
Block(-7,76,-1,biomesoplenty:dirt:8)
Block(-7,76,0,biomesoplenty:dirt:8)
Block(-7,76,1,biomesoplenty:dirt:8)
Block(-7,76,2,biomesoplenty:dirt:8)
Block(-7,76,3,biomesoplenty:dirt:8)
Block(-7,76,4,biomesoplenty:dirt:8)
Block(-7,76,5,biomesoplenty:dirt:8)
Block(-7,76,6,biomesoplenty:dirt:8)
Block(-7,76,7,biomesoplenty:dirt:8)
Block(-7,76,8,biomesoplenty:dirt:8)
Block(-7,77,-7,srparasites:parasitestain:2)
Block(-7,77,-6,srparasites:parasitestain:2)
Block(-7,77,-5,srparasites:parasitestain:2)
Block(-7,77,-4,biomesoplenty:dirt:8)
Block(-7,77,-3,biomesoplenty:dirt:8)
Block(-7,77,-2,biomesoplenty:dirt:8)
Block(-7,77,-1,biomesoplenty:dirt:8)
Block(-7,77,0,biomesoplenty:dirt:8)
Block(-7,77,1,biomesoplenty:dirt:8)
Block(-7,77,2,biomesoplenty:dirt:8)
Block(-7,77,3,biomesoplenty:dirt:8)
Block(-7,77,4,biomesoplenty:dirt:8)
Block(-7,77,5,biomesoplenty:dirt:8)
Block(-7,77,6,biomesoplenty:dirt:8)
Block(-7,77,7,biomesoplenty:dirt:8)
Block(-7,77,8,srparasites:parasitestain:2)
Block(-7,78,-7,srparasites:parasitestain:0)
Block(-7,78,-6,srparasites:parasitestain:0)
Block(-7,78,-5,srparasites:parasitestain:0)
Block(-7,78,-4,srparasites:parasitestain:2)
Block(-7,78,-3,srparasites:parasitestain:2)
Block(-7,78,-2,biomesoplenty:dirt:8)
Block(-7,78,-1,biomesoplenty:dirt:8)
Block(-7,78,0,biomesoplenty:dirt:8)
Block(-7,78,1,biomesoplenty:dirt:8)
Block(-7,78,2,biomesoplenty:dirt:8)
Block(-7,78,3,biomesoplenty:dirt:8)
Block(-7,78,4,biomesoplenty:dirt:8)
Block(-7,78,5,biomesoplenty:dirt:8)
Block(-7,78,6,biomesoplenty:dirt:8)
Block(-7,78,7,srparasites:parasitestain:2)
Block(-7,78,8,srparasites:parasitestain:2)
Block(-7,79,-7,AIR:0)
Block(-7,79,-6,srparasites:parasiterubble_slabhalf:0)
Block(-7,79,-5,AIR:0)
Block(-7,79,-4,srparasites:parasitestain:0)
Block(-7,79,-3,srparasites:parasitestain:0)
Block(-7,79,-2,srparasites:parasitestain:2)
Block(-7,79,-1,srparasites:parasitestain:2)
Block(-7,79,0,srparasites:parasitestain:2)
Block(-7,79,1,srparasites:parasitestain:2)
Block(-7,79,2,srparasites:parasitestain:2)
Block(-7,79,3,srparasites:parasitestain:2)
Block(-7,79,4,srparasites:parasitestain:2)
Block(-7,79,5,srparasites:parasitestain:2)
Block(-7,79,6,srparasites:parasitestain:2)
Block(-7,79,7,srparasites:parasitestain:0)
Block(-7,79,8,srparasites:parasitestain:0)
Block(-7,80,-7,AIR:0)
Block(-7,80,-6,AIR:0)
Block(-7,80,-5,AIR:0)
Block(-7,80,-4,notreepunching:loose_rock/stone:0)
Block(-7,80,-3,biomesoplenty:double_other_slab:0)
Block(-7,80,-2,srparasites:parasitestain:0)
Block(-7,80,-1,srparasites:parasitestain:0)
Block(-7,80,0,srparasites:parasitestain:0)
Block(-7,80,1,srparasites:parasitestain:0)
Block(-7,80,2,srparasites:parasitestain:0)
Block(-7,80,3,srparasites:parasitestain:0)
Block(-7,80,4,srparasites:parasitestain:0)
Block(-7,80,5,srparasites:parasitestain:0)
Block(-7,80,6,srparasites:parasitestain:0)
Block(-7,80,7,AIR:0)
Block(-7,80,8,srparasites:parasiterubble_slabhalf:0)
Block(-7,81,-7,AIR:0)
Block(-7,81,-6,AIR:0)
Block(-7,81,-5,AIR:0)
Block(-7,81,-4,AIR:0)
Block(-7,81,-3,AIR:0)
Block(-7,81,-2,biomesoplenty:other_slab:0)
Block(-7,81,-1,AIR:0)
Block(-7,81,0,AIR:0)
Block(-7,81,1,biomesoplenty:other_slab:0)
Block(-7,81,2,srparasites:infestedbush:3)
Block(-7,81,3,AIR:0)
Block(-7,81,4,biomesoplenty:other_slab:0)
Block(-7,81,5,AIR:0)
Block(-7,81,6,AIR:0)
Block(-7,81,7,AIR:0)
Block(-7,81,8,AIR:0)
Block(-7,82,-7,AIR:0)
Block(-7,82,-6,AIR:0)
Block(-7,82,-5,AIR:0)
Block(-7,82,-4,AIR:0)
Block(-7,82,-3,AIR:0)
Block(-7,82,-2,AIR:0)
Block(-7,82,-1,AIR:0)
Block(-7,82,0,AIR:0)
Block(-7,82,1,AIR:0)
Block(-7,82,2,AIR:0)
Block(-7,82,3,AIR:0)
Block(-7,82,4,AIR:0)
Block(-7,82,5,AIR:0)
Block(-7,82,6,AIR:0)
Block(-7,82,7,AIR:0)
Block(-7,82,8,AIR:0)
Block(-7,83,-7,AIR:0)
Block(-7,83,-6,AIR:0)
Block(-7,83,-5,AIR:0)
Block(-7,83,-4,AIR:0)
Block(-7,83,-3,AIR:0)
Block(-7,83,-2,AIR:0)
Block(-7,83,-1,AIR:0)
Block(-7,83,0,AIR:0)
Block(-7,83,1,AIR:0)
Block(-7,83,2,AIR:0)
Block(-7,83,3,AIR:0)
Block(-7,83,4,AIR:0)
Block(-7,83,5,AIR:0)
Block(-7,83,6,AIR:0)
Block(-7,83,7,AIR:0)
Block(-7,83,8,AIR:0)
Block(-6,1,-7,srparasites:parasiterubbledense:1)
Block(-6,1,-6,srparasites:parasiterubbledense:1)
Block(-6,1,-5,srparasites:parasitestain:2)
Block(-6,2,-7,srparasites:parasiterubbledense:1)
Block(-6,2,-6,srparasites:parasiterubbledense:1)
Block(-6,17,-7,srparasites:parasiterubbledense:1)
Block(-6,18,-7,srparasites:parasiterubbledense:1)
Block(-6,18,-6,srparasites:parasiterubbledense:1)
Block(-6,19,-7,srparasites:parasiterubbledense:1)
Block(-6,20,-7,srparasites:parasiterubbledense:1)
Block(-6,30,-7,srparasites:parasiterubbledense:1)
Block(-6,31,-7,srparasites:parasiterubbledense:1)
Block(-6,32,-7,srparasites:parasiterubbledense:1)
Block(-6,32,-6,srparasites:parasiterubbledense:1)
Block(-6,33,-7,srparasites:parasiterubbledense:1)
Block(-6,34,-7,srparasites:parasiterubbledense:1)
Block(-6,67,-7,biomesoplenty:dirt:8)
Block(-6,67,-6,biomesoplenty:dirt:8)
Block(-6,67,-5,biomesoplenty:dirt:8)
Block(-6,67,-4,biomesoplenty:dirt:8)
Block(-6,67,-3,biomesoplenty:dirt:8)
Block(-6,67,-2,biomesoplenty:dirt:8)
Block(-6,67,-1,biomesoplenty:dirt:8)
Block(-6,67,0,biomesoplenty:dirt:8)
Block(-6,67,1,biomesoplenty:dirt:8)
Block(-6,67,2,biomesoplenty:dirt:8)
Block(-6,67,3,biomesoplenty:dirt:8)
Block(-6,67,4,biomesoplenty:dirt:8)
Block(-6,67,5,biomesoplenty:dirt:8)
Block(-6,67,6,biomesoplenty:dirt:8)
Block(-6,67,7,biomesoplenty:dirt:8)
Block(-6,67,8,biomesoplenty:dirt:8)
Block(-6,68,-7,biomesoplenty:dirt:8)
Block(-6,68,-6,biomesoplenty:dirt:8)
Block(-6,68,-5,biomesoplenty:dirt:8)
Block(-6,68,-4,biomesoplenty:dirt:8)
Block(-6,68,-3,biomesoplenty:dirt:8)
Block(-6,68,-2,biomesoplenty:dirt:8)
Block(-6,68,-1,biomesoplenty:dirt:8)
Block(-6,68,0,biomesoplenty:dirt:8)
Block(-6,68,1,biomesoplenty:dirt:8)
Block(-6,68,2,biomesoplenty:dirt:8)
Block(-6,68,3,biomesoplenty:dirt:8)
Block(-6,68,4,biomesoplenty:dirt:8)
Block(-6,68,5,biomesoplenty:dirt:8)
Block(-6,68,6,biomesoplenty:dirt:8)
Block(-6,68,7,biomesoplenty:dirt:8)
Block(-6,68,8,biomesoplenty:dirt:8)
Block(-6,69,-7,biomesoplenty:dirt:8)
Block(-6,69,-6,biomesoplenty:dirt:8)
Block(-6,69,-5,biomesoplenty:dirt:8)
Block(-6,69,-4,biomesoplenty:dirt:8)
Block(-6,69,-3,biomesoplenty:dirt:8)
Block(-6,69,-2,biomesoplenty:dirt:8)
Block(-6,69,-1,biomesoplenty:dirt:8)
Block(-6,69,0,biomesoplenty:dirt:8)
Block(-6,69,1,biomesoplenty:dirt:8)
Block(-6,69,2,biomesoplenty:dirt:8)
Block(-6,69,3,biomesoplenty:dirt:8)
Block(-6,69,4,biomesoplenty:dirt:8)
Block(-6,69,5,biomesoplenty:dirt:8)
Block(-6,69,6,biomesoplenty:dirt:8)
Block(-6,69,7,biomesoplenty:dirt:8)
Block(-6,69,8,biomesoplenty:dirt:8)
Block(-6,70,-7,biomesoplenty:dirt:8)
Block(-6,70,-6,biomesoplenty:dirt:8)
Block(-6,70,-5,biomesoplenty:dirt:8)
Block(-6,70,-4,biomesoplenty:dirt:8)
Block(-6,70,-3,biomesoplenty:dirt:8)
Block(-6,70,-2,biomesoplenty:dirt:8)
Block(-6,70,-1,biomesoplenty:dirt:8)
Block(-6,70,0,biomesoplenty:dirt:8)
Block(-6,70,1,biomesoplenty:dirt:8)
Block(-6,70,2,biomesoplenty:dirt:8)
Block(-6,70,3,biomesoplenty:dirt:8)
Block(-6,70,4,biomesoplenty:dirt:8)
Block(-6,70,5,biomesoplenty:dirt:8)
Block(-6,70,6,biomesoplenty:dirt:8)
Block(-6,70,7,biomesoplenty:dirt:8)
Block(-6,70,8,biomesoplenty:dirt:8)
Block(-6,71,-7,biomesoplenty:dirt:8)
Block(-6,71,-6,biomesoplenty:dirt:8)
Block(-6,71,-5,biomesoplenty:dirt:8)
Block(-6,71,-4,biomesoplenty:dirt:8)
Block(-6,71,-3,biomesoplenty:dirt:8)
Block(-6,71,-2,biomesoplenty:dirt:8)
Block(-6,71,-1,biomesoplenty:dirt:8)
Block(-6,71,0,biomesoplenty:dirt:8)
Block(-6,71,1,biomesoplenty:dirt:8)
Block(-6,71,2,biomesoplenty:dirt:8)
Block(-6,71,3,biomesoplenty:dirt:8)
Block(-6,71,4,biomesoplenty:dirt:8)
Block(-6,71,5,biomesoplenty:dirt:8)
Block(-6,71,6,biomesoplenty:dirt:8)
Block(-6,71,7,biomesoplenty:dirt:8)
Block(-6,71,8,biomesoplenty:dirt:8)
Block(-6,72,-7,biomesoplenty:dirt:8)
Block(-6,72,-6,biomesoplenty:dirt:8)
Block(-6,72,-5,biomesoplenty:dirt:8)
Block(-6,72,-4,biomesoplenty:dirt:8)
Block(-6,72,-3,biomesoplenty:dirt:8)
Block(-6,72,-2,biomesoplenty:dirt:8)
Block(-6,72,-1,biomesoplenty:dirt:8)
Block(-6,72,0,biomesoplenty:dirt:8)
Block(-6,72,1,biomesoplenty:dirt:8)
Block(-6,72,2,biomesoplenty:dirt:8)
Block(-6,72,3,biomesoplenty:dirt:8)
Block(-6,72,4,biomesoplenty:dirt:8)
Block(-6,72,5,biomesoplenty:dirt:8)
Block(-6,72,6,biomesoplenty:dirt:8)
Block(-6,72,7,biomesoplenty:dirt:8)
Block(-6,72,8,biomesoplenty:dirt:8)
Block(-6,73,-7,biomesoplenty:dirt:8)
Block(-6,73,-6,biomesoplenty:dirt:8)
Block(-6,73,-5,biomesoplenty:dirt:8)
Block(-6,73,-4,biomesoplenty:dirt:8)
Block(-6,73,-3,biomesoplenty:dirt:8)
Block(-6,73,-2,biomesoplenty:dirt:8)
Block(-6,73,-1,biomesoplenty:dirt:8)
Block(-6,73,0,biomesoplenty:dirt:8)
Block(-6,73,1,biomesoplenty:dirt:8)
Block(-6,73,2,biomesoplenty:dirt:8)
Block(-6,73,3,biomesoplenty:dirt:8)
Block(-6,73,4,biomesoplenty:dirt:8)
Block(-6,73,5,biomesoplenty:dirt:8)
Block(-6,73,6,biomesoplenty:dirt:8)
Block(-6,73,7,biomesoplenty:dirt:8)
Block(-6,73,8,biomesoplenty:dirt:8)
Block(-6,74,-7,biomesoplenty:dirt:8)
Block(-6,74,-6,biomesoplenty:dirt:8)
Block(-6,74,-5,biomesoplenty:dirt:8)
Block(-6,74,-4,biomesoplenty:dirt:8)
Block(-6,74,-3,biomesoplenty:dirt:8)
Block(-6,74,-2,biomesoplenty:dirt:8)
Block(-6,74,-1,biomesoplenty:dirt:8)
Block(-6,74,0,biomesoplenty:dirt:8)
Block(-6,74,1,biomesoplenty:dirt:8)
Block(-6,74,2,biomesoplenty:dirt:8)
Block(-6,74,3,biomesoplenty:dirt:8)
Block(-6,74,4,biomesoplenty:dirt:8)
Block(-6,74,5,biomesoplenty:dirt:8)
Block(-6,74,6,biomesoplenty:dirt:8)
Block(-6,74,7,biomesoplenty:dirt:8)
Block(-6,74,8,biomesoplenty:dirt:8)
Block(-6,75,-7,srparasites:parasitestain:2)
Block(-6,75,-6,biomesoplenty:dirt:8)
Block(-6,75,-5,biomesoplenty:dirt:8)
Block(-6,75,-4,biomesoplenty:dirt:8)
Block(-6,75,-3,biomesoplenty:dirt:8)
Block(-6,75,-2,biomesoplenty:dirt:8)
Block(-6,75,-1,biomesoplenty:dirt:8)
Block(-6,75,0,biomesoplenty:dirt:8)
Block(-6,75,1,biomesoplenty:dirt:8)
Block(-6,75,2,biomesoplenty:dirt:8)
Block(-6,75,3,biomesoplenty:dirt:8)
Block(-6,75,4,biomesoplenty:dirt:8)
Block(-6,75,5,biomesoplenty:dirt:8)
Block(-6,75,6,biomesoplenty:dirt:8)
Block(-6,75,7,biomesoplenty:dirt:8)
Block(-6,75,8,srparasites:parasitestain:2)
Block(-6,76,-7,srparasites:parasitestain:2)
Block(-6,76,-6,srparasites:parasitestain:2)
Block(-6,76,-5,biomesoplenty:dirt:8)
Block(-6,76,-4,biomesoplenty:dirt:8)
Block(-6,76,-3,biomesoplenty:dirt:8)
Block(-6,76,-2,biomesoplenty:dirt:8)
Block(-6,76,-1,biomesoplenty:dirt:8)
Block(-6,76,0,biomesoplenty:dirt:8)
Block(-6,76,1,biomesoplenty:dirt:8)
Block(-6,76,2,biomesoplenty:dirt:8)
Block(-6,76,3,biomesoplenty:dirt:8)
Block(-6,76,4,biomesoplenty:dirt:8)
Block(-6,76,5,biomesoplenty:dirt:8)
Block(-6,76,6,biomesoplenty:dirt:8)
Block(-6,76,7,biomesoplenty:dirt:8)
Block(-6,76,8,srparasites:parasitestain:2)
Block(-6,77,-7,srparasites:parasitestain:0)
Block(-6,77,-6,srparasites:parasitestain:0)
Block(-6,77,-5,srparasites:parasitestain:2)
Block(-6,77,-4,srparasites:parasitestain:2)
Block(-6,77,-3,biomesoplenty:dirt:8)
Block(-6,77,-2,biomesoplenty:dirt:8)
Block(-6,77,-1,biomesoplenty:dirt:8)
Block(-6,77,0,biomesoplenty:dirt:8)
Block(-6,77,1,biomesoplenty:dirt:8)
Block(-6,77,2,biomesoplenty:dirt:8)
Block(-6,77,3,biomesoplenty:dirt:8)
Block(-6,77,4,biomesoplenty:dirt:8)
Block(-6,77,5,biomesoplenty:dirt:8)
Block(-6,77,6,biomesoplenty:dirt:8)
Block(-6,77,7,srparasites:parasitestain:2)
Block(-6,77,8,srparasites:parasitestain:0)
Block(-6,78,-7,srparasites:parasiterubble_slabhalf:0)
Block(-6,78,-6,AIR:0)
Block(-6,78,-5,srparasites:parasitestain:0)
Block(-6,78,-4,srparasites:parasitestain:0)
Block(-6,78,-3,srparasites:parasitestain:2)
Block(-6,78,-2,srparasites:parasitestain:2)
Block(-6,78,-1,srparasites:parasitestain:2)
Block(-6,78,0,biomesoplenty:dirt:8)
Block(-6,78,1,biomesoplenty:dirt:8)
Block(-6,78,2,biomesoplenty:dirt:8)
Block(-6,78,3,biomesoplenty:dirt:8)
Block(-6,78,4,biomesoplenty:dirt:8)
Block(-6,78,5,biomesoplenty:dirt:8)
Block(-6,78,6,srparasites:parasitestain:2)
Block(-6,78,7,srparasites:parasitestain:2)
Block(-6,78,8,srparasites:parasitestain:0)
Block(-6,79,-7,AIR:0)
Block(-6,79,-6,AIR:0)
Block(-6,79,-5,srparasites:infestedbush:3)
Block(-6,79,-4,srparasites:gore:1)
Block(-6,79,-3,srparasites:parasitestain:0)
Block(-6,79,-2,srparasites:parasitestain:0)
Block(-6,79,-1,srparasites:parasitestain:0)
Block(-6,79,0,srparasites:parasitestain:2)
Block(-6,79,1,srparasites:parasitestain:2)
Block(-6,79,2,srparasites:parasitestain:2)
Block(-6,79,3,srparasites:parasitestain:2)
Block(-6,79,4,srparasites:parasitestain:2)
Block(-6,79,5,srparasites:parasitestain:2)
Block(-6,79,6,srparasites:parasitestain:0)
Block(-6,79,7,srparasites:parasitestain:0)
Block(-6,79,8,srparasites:parasiterubble_slabhalf:0)
Block(-6,80,-7,AIR:0)
Block(-6,80,-6,AIR:0)
Block(-6,80,-5,srparasites:infestedbush:3)
Block(-6,80,-4,AIR:0)
Block(-6,80,-3,biomesoplenty:other_slab:0)
Block(-6,80,-2,srparasites:parasiterubble_slabhalf:0)
Block(-6,80,-1,srparasites:parasitestain:0)
Block(-6,80,0,srparasites:parasitestain:0)
Block(-6,80,1,srparasites:parasitestain:0)
Block(-6,80,2,srparasites:parasitestain:0)
Block(-6,80,3,srparasites:parasitestain:0)
Block(-6,80,4,srparasites:parasitestain:0)
Block(-6,80,5,srparasites:parasitestain:0)
Block(-6,80,6,srparasites:parasitebush:0)
Block(-6,80,7,AIR:0)
Block(-6,80,8,AIR:0)
Block(-6,81,-7,AIR:0)
Block(-6,81,-6,AIR:0)
Block(-6,81,-5,srparasites:infestedbush:3)
Block(-6,81,-4,AIR:0)
Block(-6,81,-3,AIR:0)
Block(-6,81,-2,AIR:0)
Block(-6,81,-1,srparasites:parasitebush:2)
Block(-6,81,0,AIR:0)
Block(-6,81,1,biomesoplenty:other_slab:0)
Block(-6,81,2,srparasites:parasitebush:2)
Block(-6,81,3,AIR:0)
Block(-6,81,4,biomesoplenty:other_slab:0)
Block(-6,81,5,srparasites:parasitebush:2)
Block(-6,81,6,AIR:0)
Block(-6,81,7,AIR:0)
Block(-6,81,8,AIR:0)
Block(-6,82,-7,AIR:0)
Block(-6,82,-6,AIR:0)
Block(-6,82,-5,AIR:0)
Block(-6,82,-4,AIR:0)
Block(-6,82,-3,AIR:0)
Block(-6,82,-2,AIR:0)
Block(-6,82,-1,AIR:0)
Block(-6,82,0,AIR:0)
Block(-6,82,1,AIR:0)
Block(-6,82,2,AIR:0)
Block(-6,82,3,AIR:0)
Block(-6,82,4,AIR:0)
Block(-6,82,5,AIR:0)
Block(-6,82,6,AIR:0)
Block(-6,82,7,AIR:0)
Block(-6,82,8,AIR:0)
Block(-6,83,-7,AIR:0)
Block(-6,83,-6,AIR:0)
Block(-6,83,-5,AIR:0)
Block(-6,83,-4,AIR:0)
Block(-6,83,-3,AIR:0)
Block(-6,83,-2,AIR:0)
Block(-6,83,-1,AIR:0)
Block(-6,83,0,AIR:0)
Block(-6,83,1,AIR:0)
Block(-6,83,2,AIR:0)
Block(-6,83,3,AIR:0)
Block(-6,83,4,AIR:0)
Block(-6,83,5,AIR:0)
Block(-6,83,6,AIR:0)
Block(-6,83,7,AIR:0)
Block(-6,83,8,AIR:0)
Block(-5,1,-7,srparasites:parasiterubbledense:1)
Block(-5,1,-6,srparasites:parasiterubbledense:1)
Block(-5,1,-5,srparasites:parasitestain:2)
Block(-5,1,-4,srparasites:parasiterubbledense:1)
Block(-5,2,-7,srparasites:parasiterubbledense:1)
Block(-5,2,-6,srparasites:parasiterubbledense:1)
Block(-5,2,-5,srparasites:parasitestain:2)
Block(-5,2,-4,srparasites:parasitestain:3)
Block(-5,3,-7,srparasites:parasiterubbledense:1)
Block(-5,3,-4,srparasites:parasitestain:3)
Block(-5,4,-7,srparasites:parasiterubbledense:1)
Block(-5,4,-4,srparasites:parasitestain:3)
Block(-5,5,-7,srparasites:parasitestain:1)
Block(-5,5,-4,srparasites:parasitestain:3)
Block(-5,6,-7,srparasites:parasiterubble:1)
Block(-5,6,-4,srparasites:parasitestain:3)
Block(-5,7,-7,srparasites:parasitestain:2)
Block(-5,7,-4,srparasites:parasitestain:3)
Block(-5,8,-7,srparasites:parasiterubble:1)
Block(-5,8,-4,srparasites:parasitestain:3)
Block(-5,9,-7,AIR:0)
Block(-5,9,-4,srparasites:parasitestain:3)
Block(-5,10,-4,srparasites:parasitestain:3)
Block(-5,11,-7,srparasites:parasitestain:1)
Block(-5,11,-4,srparasites:parasitestain:3)
Block(-5,12,-7,srparasites:parasitestain:1)
Block(-5,12,-4,srparasites:parasitestain:3)
Block(-5,13,-7,srparasites:parasitestain:1)
Block(-5,13,-4,srparasites:parasitestain:3)
Block(-5,14,-7,srparasites:parasitestain:1)
Block(-5,14,-4,srparasites:parasitestain:3)
Block(-5,15,-7,AIR:0)
Block(-5,15,-4,srparasites:parasiterubbledense:1)
Block(-5,16,-7,srparasites:parasiterubbledense:1)
Block(-5,16,-5,srparasites:parasiterubbledense:1)
Block(-5,16,-4,srparasites:parasiterubbledense:1)
Block(-5,16,-3,srparasites:parasiterubbledense:1)
Block(-5,17,-7,srparasites:parasiterubbledense:1)
Block(-5,17,-6,srparasites:parasiterubbledense:1)
Block(-5,17,-5,srparasites:parasiterubbledense:1)
Block(-5,17,-4,srparasites:parasiterubbledense:1)
Block(-5,18,-7,srparasites:parasiterubbledense:1)
Block(-5,18,-6,srparasites:parasiterubbledense:1)
Block(-5,18,-5,srparasites:parasiterubbledense:1)
Block(-5,19,-7,srparasites:parasiterubbledense:1)
Block(-5,19,-6,srparasites:parasiterubbledense:1)
Block(-5,20,-7,srparasites:parasiterubbledense:1)
Block(-5,21,-7,srparasites:parasiterubbledense:1)
Block(-5,22,-7,srparasites:parasiterubbledense:1)
Block(-5,23,-7,AIR:0)
Block(-5,25,-7,srparasites:parasitestain:2)
Block(-5,26,-7,srparasites:parasitestain:2)
Block(-5,27,-7,srparasites:parasiterubbledense:1)
Block(-5,28,-7,srparasites:parasiterubbledense:1)
Block(-5,29,-7,srparasites:parasiterubbledense:1)
Block(-5,29,-5,srparasites:parasiterubbledense:1)
Block(-5,30,-7,srparasites:parasiterubbledense:1)
Block(-5,30,-6,srparasites:parasiterubbledense:1)
Block(-5,30,-5,srparasites:parasiterubbledense:1)
Block(-5,30,-4,srparasites:parasiterubbledense:1)
Block(-5,31,-7,srparasites:parasiterubbledense:1)
Block(-5,31,-6,srparasites:parasiterubbledense:1)
Block(-5,31,-5,srparasites:parasiterubbledense:1)
Block(-5,32,-7,srparasites:parasiterubbledense:1)
Block(-5,32,-6,srparasites:parasiterubbledense:1)
Block(-5,33,-7,srparasites:parasiterubbledense:1)
Block(-5,33,-6,srparasites:parasiterubbledense:1)
Block(-5,33,-5,srparasites:parasiterubbledense:1)
Block(-5,34,-7,srparasites:parasiterubbledense:1)
Block(-5,34,-6,srparasites:parasiterubbledense:1)
Block(-5,35,-7,srparasites:parasiterubbledense:1)
Block(-5,35,-5,srparasites:parasiterubbledense:1)
Block(-5,36,-7,srparasites:parasiterubbledense:1)
Block(-5,36,-6,srparasites:parasiterubbledense:1)
Block(-5,36,-5,srparasites:parasiterubbledense:1)
Block(-5,36,-4,srparasites:parasiterubbledense:1)
Block(-5,37,-7,srparasites:parasitestain:2)
Block(-5,37,-5,srparasites:parasiterubbledense:1)
Block(-5,38,-7,srparasites:parasitestain:2)
Block(-5,39,-7,srparasites:parasitestain:2)
Block(-5,40,-7,srparasites:parasitestain:2)
Block(-5,41,-7,srparasites:parasitestain:1)
Block(-5,42,-7,srparasites:parasitestain:1)
Block(-5,43,-7,srparasites:parasitestain:1)
Block(-5,44,-7,srparasites:parasitestain:2)
Block(-5,45,-7,srparasites:parasitestain:1)
Block(-5,46,-7,AIR:0)
Block(-5,47,-7,srparasites:parasitestain:1)
Block(-5,48,-7,srparasites:parasitestain:2)
Block(-5,49,-7,AIR:0)
Block(-5,50,-7,srparasites:parasitestain:1)
Block(-5,51,-7,srparasites:parasitestain:2)
Block(-5,52,-7,srparasites:parasitestain:2)
Block(-5,53,-7,srparasites:parasitestain:2)
Block(-5,54,-7,srparasites:parasitestain:2)
Block(-5,67,-7,biomesoplenty:dirt:8)
Block(-5,67,-6,biomesoplenty:dirt:8)
Block(-5,67,-5,biomesoplenty:dirt:8)
Block(-5,67,-4,biomesoplenty:dirt:8)
Block(-5,67,-3,biomesoplenty:dirt:8)
Block(-5,67,-2,biomesoplenty:dirt:8)
Block(-5,67,-1,biomesoplenty:dirt:8)
Block(-5,67,0,biomesoplenty:dirt:8)
Block(-5,67,1,biomesoplenty:dirt:8)
Block(-5,67,2,biomesoplenty:dirt:8)
Block(-5,67,3,biomesoplenty:dirt:8)
Block(-5,67,4,biomesoplenty:dirt:8)
Block(-5,67,5,biomesoplenty:dirt:8)
Block(-5,67,6,biomesoplenty:dirt:8)
Block(-5,67,7,biomesoplenty:dirt:8)
Block(-5,67,8,biomesoplenty:dirt:8)
Block(-5,68,-7,biomesoplenty:dirt:8)
Block(-5,68,-6,biomesoplenty:dirt:8)
Block(-5,68,-5,biomesoplenty:dirt:8)
Block(-5,68,-4,biomesoplenty:dirt:8)
Block(-5,68,-3,biomesoplenty:dirt:8)
Block(-5,68,-2,biomesoplenty:dirt:8)
Block(-5,68,-1,biomesoplenty:dirt:8)
Block(-5,68,0,biomesoplenty:dirt:8)
Block(-5,68,1,biomesoplenty:dirt:8)
Block(-5,68,2,biomesoplenty:dirt:8)
Block(-5,68,3,biomesoplenty:dirt:8)
Block(-5,68,4,biomesoplenty:dirt:8)
Block(-5,68,5,biomesoplenty:dirt:8)
Block(-5,68,6,biomesoplenty:dirt:8)
Block(-5,68,7,biomesoplenty:dirt:8)
Block(-5,68,8,biomesoplenty:dirt:8)
Block(-5,69,-7,biomesoplenty:dirt:8)
Block(-5,69,-6,biomesoplenty:dirt:8)
Block(-5,69,-5,biomesoplenty:dirt:8)
Block(-5,69,-4,biomesoplenty:dirt:8)
Block(-5,69,-3,biomesoplenty:dirt:8)
Block(-5,69,-2,biomesoplenty:dirt:8)
Block(-5,69,-1,biomesoplenty:dirt:8)
Block(-5,69,0,biomesoplenty:dirt:8)
Block(-5,69,1,biomesoplenty:dirt:8)
Block(-5,69,2,biomesoplenty:dirt:8)
Block(-5,69,3,biomesoplenty:dirt:8)
Block(-5,69,4,biomesoplenty:dirt:8)
Block(-5,69,5,biomesoplenty:dirt:8)
Block(-5,69,6,biomesoplenty:dirt:8)
Block(-5,69,7,biomesoplenty:dirt:8)
Block(-5,69,8,biomesoplenty:dirt:8)
Block(-5,70,-7,biomesoplenty:dirt:8)
Block(-5,70,-6,biomesoplenty:dirt:8)
Block(-5,70,-5,biomesoplenty:dirt:8)
Block(-5,70,-4,biomesoplenty:dirt:8)
Block(-5,70,-3,biomesoplenty:dirt:8)
Block(-5,70,-2,biomesoplenty:dirt:8)
Block(-5,70,-1,biomesoplenty:dirt:8)
Block(-5,70,0,biomesoplenty:dirt:8)
Block(-5,70,1,biomesoplenty:dirt:8)
Block(-5,70,2,biomesoplenty:dirt:8)
Block(-5,70,3,biomesoplenty:dirt:8)
Block(-5,70,4,biomesoplenty:dirt:8)
Block(-5,70,5,biomesoplenty:dirt:8)
Block(-5,70,6,biomesoplenty:dirt:8)
Block(-5,70,7,biomesoplenty:dirt:8)
Block(-5,70,8,biomesoplenty:dirt:8)
Block(-5,71,-7,biomesoplenty:dirt:8)
Block(-5,71,-6,biomesoplenty:dirt:8)
Block(-5,71,-5,biomesoplenty:dirt:8)
Block(-5,71,-4,biomesoplenty:dirt:8)
Block(-5,71,-3,biomesoplenty:dirt:8)
Block(-5,71,-2,biomesoplenty:dirt:8)
Block(-5,71,-1,biomesoplenty:dirt:8)
Block(-5,71,0,biomesoplenty:dirt:8)
Block(-5,71,1,biomesoplenty:dirt:8)
Block(-5,71,2,biomesoplenty:dirt:8)
Block(-5,71,3,biomesoplenty:dirt:8)
Block(-5,71,4,biomesoplenty:dirt:8)
Block(-5,71,5,biomesoplenty:dirt:8)
Block(-5,71,6,biomesoplenty:dirt:8)
Block(-5,71,7,biomesoplenty:dirt:8)
Block(-5,71,8,biomesoplenty:dirt:8)
Block(-5,72,-7,biomesoplenty:dirt:8)
Block(-5,72,-6,biomesoplenty:dirt:8)
Block(-5,72,-5,biomesoplenty:dirt:8)
Block(-5,72,-4,biomesoplenty:dirt:8)
Block(-5,72,-3,biomesoplenty:dirt:8)
Block(-5,72,-2,biomesoplenty:dirt:8)
Block(-5,72,-1,biomesoplenty:dirt:8)
Block(-5,72,0,biomesoplenty:dirt:8)
Block(-5,72,1,biomesoplenty:dirt:8)
Block(-5,72,2,biomesoplenty:dirt:8)
Block(-5,72,3,biomesoplenty:dirt:8)
Block(-5,72,4,biomesoplenty:dirt:8)
Block(-5,72,5,biomesoplenty:dirt:8)
Block(-5,72,6,biomesoplenty:dirt:8)
Block(-5,72,7,biomesoplenty:dirt:8)
Block(-5,72,8,biomesoplenty:dirt:8)
Block(-5,73,-7,biomesoplenty:dirt:8)
Block(-5,73,-6,biomesoplenty:dirt:8)
Block(-5,73,-5,biomesoplenty:dirt:8)
Block(-5,73,-4,biomesoplenty:dirt:8)
Block(-5,73,-3,biomesoplenty:dirt:8)
Block(-5,73,-2,biomesoplenty:dirt:8)
Block(-5,73,-1,biomesoplenty:dirt:8)
Block(-5,73,0,biomesoplenty:dirt:8)
Block(-5,73,1,biomesoplenty:dirt:8)
Block(-5,73,2,biomesoplenty:dirt:8)
Block(-5,73,3,biomesoplenty:dirt:8)
Block(-5,73,4,biomesoplenty:dirt:8)
Block(-5,73,5,biomesoplenty:dirt:8)
Block(-5,73,6,biomesoplenty:dirt:8)
Block(-5,73,7,biomesoplenty:dirt:8)
Block(-5,73,8,biomesoplenty:dirt:8)
Block(-5,74,-7,biomesoplenty:dirt:8)
Block(-5,74,-6,biomesoplenty:dirt:8)
Block(-5,74,-5,biomesoplenty:dirt:8)
Block(-5,74,-4,biomesoplenty:dirt:8)
Block(-5,74,-3,biomesoplenty:dirt:8)
Block(-5,74,-2,biomesoplenty:dirt:8)
Block(-5,74,-1,biomesoplenty:dirt:8)
Block(-5,74,0,biomesoplenty:dirt:8)
Block(-5,74,1,biomesoplenty:dirt:8)
Block(-5,74,2,biomesoplenty:dirt:8)
Block(-5,74,3,biomesoplenty:dirt:8)
Block(-5,74,4,biomesoplenty:dirt:8)
Block(-5,74,5,biomesoplenty:dirt:8)
Block(-5,74,6,biomesoplenty:dirt:8)
Block(-5,74,7,biomesoplenty:dirt:8)
Block(-5,74,8,biomesoplenty:dirt:8)
Block(-5,75,-7,srparasites:parasitestain:0)
Block(-5,75,-6,srparasites:parasitestain:2)
Block(-5,75,-5,biomesoplenty:dirt:8)
Block(-5,75,-4,biomesoplenty:dirt:8)
Block(-5,75,-3,biomesoplenty:dirt:8)
Block(-5,75,-2,biomesoplenty:dirt:8)
Block(-5,75,-1,biomesoplenty:dirt:8)
Block(-5,75,0,biomesoplenty:dirt:8)
Block(-5,75,1,biomesoplenty:dirt:8)
Block(-5,75,2,biomesoplenty:dirt:8)
Block(-5,75,3,biomesoplenty:dirt:8)
Block(-5,75,4,biomesoplenty:dirt:8)
Block(-5,75,5,biomesoplenty:dirt:8)
Block(-5,75,6,biomesoplenty:dirt:8)
Block(-5,75,7,biomesoplenty:dirt:8)
Block(-5,75,8,srparasites:parasitestain:2)
Block(-5,76,-7,srparasites:parasitestain:0)
Block(-5,76,-6,srparasites:parasitestain:2)
Block(-5,76,-5,srparasites:parasitestain:2)
Block(-5,76,-4,biomesoplenty:dirt:8)
Block(-5,76,-3,biomesoplenty:dirt:8)
Block(-5,76,-2,biomesoplenty:dirt:8)
Block(-5,76,-1,biomesoplenty:dirt:8)
Block(-5,76,0,biomesoplenty:dirt:8)
Block(-5,76,1,biomesoplenty:dirt:8)
Block(-5,76,2,biomesoplenty:dirt:8)
Block(-5,76,3,biomesoplenty:dirt:8)
Block(-5,76,4,biomesoplenty:dirt:8)
Block(-5,76,5,biomesoplenty:dirt:8)
Block(-5,76,6,biomesoplenty:dirt:8)
Block(-5,76,7,biomesoplenty:dirt:8)
Block(-5,76,8,srparasites:parasitestain:2)
Block(-5,77,-7,srparasites:parasiterubble_slabhalf:0)
Block(-5,77,-6,srparasites:parasitestain:0)
Block(-5,77,-5,srparasites:parasitestain:0)
Block(-5,77,-4,srparasites:parasitestain:2)
Block(-5,77,-3,srparasites:parasitestain:2)
Block(-5,77,-2,srparasites:parasitestain:2)
Block(-5,77,-1,biomesoplenty:dirt:8)
Block(-5,77,0,biomesoplenty:dirt:8)
Block(-5,77,1,biomesoplenty:dirt:8)
Block(-5,77,2,biomesoplenty:dirt:8)
Block(-5,77,3,biomesoplenty:dirt:8)
Block(-5,77,4,biomesoplenty:dirt:8)
Block(-5,77,5,biomesoplenty:dirt:8)
Block(-5,77,6,biomesoplenty:dirt:8)
Block(-5,77,7,srparasites:parasitestain:2)
Block(-5,77,8,srparasites:parasitestain:0)
Block(-5,78,-7,AIR:0)
Block(-5,78,-6,AIR:0)
Block(-5,78,-5,AIR:0)
Block(-5,78,-4,srparasites:parasitestain:0)
Block(-5,78,-3,srparasites:parasitestain:0)
Block(-5,78,-2,srparasites:parasitestain:0)
Block(-5,78,-1,srparasites:parasitestain:2)
Block(-5,78,0,srparasites:parasitestain:2)
Block(-5,78,1,srparasites:parasitestain:2)
Block(-5,78,2,srparasites:parasitestain:2)
Block(-5,78,3,srparasites:parasitestain:2)
Block(-5,78,4,biomesoplenty:dirt:8)
Block(-5,78,5,srparasites:parasitestain:2)
Block(-5,78,6,srparasites:parasitestain:2)
Block(-5,78,7,srparasites:parasitestain:0)
Block(-5,78,8,srparasites:parasitestain:0)
Block(-5,79,-7,AIR:0)
Block(-5,79,-6,AIR:0)
Block(-5,79,-5,AIR:0)
Block(-5,79,-4,AIR:0)
Block(-5,79,-3,srparasites:parasitebush:0)
Block(-5,79,-2,srparasites:parasiterubble_slabhalf:0)
Block(-5,79,-1,srparasites:parasitestain:0)
Block(-5,79,0,srparasites:parasitestain:0)
Block(-5,79,1,srparasites:parasitestain:0)
Block(-5,79,2,srparasites:parasitestain:0)
Block(-5,79,3,srparasites:parasitestain:2)
Block(-5,79,4,srparasites:parasitestain:2)
Block(-5,79,5,srparasites:parasitestain:0)
Block(-5,79,6,srparasites:parasitestain:0)
Block(-5,79,7,AIR:0)
Block(-5,79,8,AIR:0)
Block(-5,80,-7,AIR:0)
Block(-5,80,-6,AIR:0)
Block(-5,80,-5,AIR:0)
Block(-5,80,-4,AIR:0)
Block(-5,80,-3,srparasites:parasitebush:0)
Block(-5,80,-2,AIR:0)
Block(-5,80,-1,srparasites:infestedbush:3)
Block(-5,80,0,srparasites:parasitestain:0)
Block(-5,80,1,srparasites:parasitestain:0)
Block(-5,80,2,srparasites:parasitestain:0)
Block(-5,80,3,srparasites:parasitestain:0)
Block(-5,80,4,srparasites:parasitestain:0)
Block(-5,80,5,srparasites:parasiterubble_slabhalf:0)
Block(-5,80,6,AIR:0)
Block(-5,80,7,AIR:0)
Block(-5,80,8,AIR:0)
Block(-5,81,-7,AIR:0)
Block(-5,81,-6,AIR:0)
Block(-5,81,-5,AIR:0)
Block(-5,81,-4,AIR:0)
Block(-5,81,-3,srparasites:parasitebush:0)
Block(-5,81,-2,AIR:0)
Block(-5,81,-1,srparasites:infestedbush:3)
Block(-5,81,0,AIR:0)
Block(-5,81,1,biomesoplenty:other_slab:0)
Block(-5,81,2,biomesoplenty:other_slab:0)
Block(-5,81,3,AIR:0)
Block(-5,81,4,srparasites:gore:0)
Block(-5,81,5,AIR:0)
Block(-5,81,6,AIR:0)
Block(-5,81,7,AIR:0)
Block(-5,81,8,AIR:0)
Block(-5,82,-7,AIR:0)
Block(-5,82,-6,AIR:0)
Block(-5,82,-5,AIR:0)
Block(-5,82,-4,AIR:0)
Block(-5,82,-3,AIR:0)
Block(-5,82,-2,AIR:0)
Block(-5,82,-1,srparasites:infestedbush:3)
Block(-5,82,0,AIR:0)
Block(-5,82,1,AIR:0)
Block(-5,82,2,AIR:0)
Block(-5,82,3,AIR:0)
Block(-5,82,4,AIR:0)
Block(-5,82,5,AIR:0)
Block(-5,82,6,AIR:0)
Block(-5,82,7,AIR:0)
Block(-5,82,8,AIR:0)
Block(-5,83,-7,AIR:0)
Block(-5,83,-6,AIR:0)
Block(-5,83,-5,AIR:0)
Block(-5,83,-4,AIR:0)
Block(-5,83,-3,AIR:0)
Block(-5,83,-2,AIR:0)
Block(-5,83,-1,AIR:0)
Block(-5,83,0,AIR:0)
Block(-5,83,1,AIR:0)
Block(-5,83,2,AIR:0)
Block(-5,83,3,AIR:0)
Block(-5,83,4,AIR:0)
Block(-5,83,5,AIR:0)
Block(-5,83,6,AIR:0)
Block(-5,83,7,AIR:0)
Block(-5,83,8,AIR:0)
Block(-4,1,-7,srparasites:parasiterubbledense:1)
Block(-4,1,-6,srparasites:parasitestain:2)
Block(-4,1,-5,srparasites:parasiterubbledense:1)
Block(-4,1,-4,srparasites:parasiterubbledense:1)
Block(-4,1,-3,srparasites:parasiterubbledense:1)
Block(-4,1,-2,srparasites:parasiterubbledense:1)
Block(-4,1,0,srparasites:parasiterubbledense:1)
Block(-4,2,-7,srparasites:parasiterubbledense:1)
Block(-4,2,-6,srparasites:parasitestain:2)
Block(-4,2,-5,srparasites:parasiterubbledense:1)
Block(-4,3,-7,srparasites:parasiterubbledense:1)
Block(-4,3,-6,srparasites:parasitestain:2)
Block(-4,3,-5,srparasites:parasiterubbledense:1)
Block(-4,4,-7,srparasites:parasitestain:1)
Block(-4,4,-6,srparasites:parasitestain:1)
Block(-4,4,-5,srparasites:parasitestain:1)
Block(-4,5,-7,srparasites:parasiterubble:1)
Block(-4,5,-6,srparasites:parasiterubble:1)
Block(-4,5,-5,srparasites:parasitestain:1)
Block(-4,6,-7,srparasites:parasiterubble:1)
Block(-4,6,-6,srparasites:parasitestain:1)
Block(-4,6,-5,srparasites:parasiterubble:1)
Block(-4,7,-7,srparasites:parasitebush:0)
Block(-4,7,-6,srparasites:parasitestain:2)
Block(-4,7,-5,srparasites:parasitestain:2)
Block(-4,8,-7,srparasites:parasitestain:1)
Block(-4,8,-6,srparasites:parasitestain:2)
Block(-4,8,-5,srparasites:parasitestain:2)
Block(-4,9,-7,srparasites:parasitestain:1)
Block(-4,9,-6,srparasites:parasitestain:2)
Block(-4,9,-5,srparasites:parasitestain:2)
Block(-4,10,-7,srparasites:parasitestain:2)
Block(-4,10,-6,srparasites:parasitestain:2)
Block(-4,10,-5,srparasites:parasitestain:1)
Block(-4,11,-7,srparasites:parasitestain:2)
Block(-4,11,-6,AIR:0)
Block(-4,11,-5,srparasites:parasitestain:1)
Block(-4,12,-7,srparasites:parasitestain:2)
Block(-4,12,-6,srparasites:parasitestain:1)
Block(-4,12,-5,srparasites:parasitestain:1)
Block(-4,13,-7,srparasites:parasitestain:1)
Block(-4,13,-6,srparasites:parasitestain:2)
Block(-4,13,-5,srparasites:parasiterubbledense:1)
Block(-4,14,-7,srparasites:parasitestain:2)
Block(-4,14,-6,srparasites:parasiterubbledense:1)
Block(-4,14,-5,srparasites:parasiterubbledense:1)
Block(-4,15,-7,srparasites:parasitebush:0)
Block(-4,15,-6,srparasites:parasiterubbledense:1)
Block(-4,15,-5,srparasites:parasiterubbledense:1)
Block(-4,15,-4,srparasites:parasiterubbledense:1)
Block(-4,15,-3,srparasites:parasiterubbledense:1)
Block(-4,16,-7,srparasites:parasiterubbledense:1)
Block(-4,16,-6,srparasites:parasiterubbledense:1)
Block(-4,16,-5,srparasites:parasiterubbledense:1)
Block(-4,16,-4,srparasites:parasiterubbledense:1)
Block(-4,16,-3,srparasites:parasiterubbledense:1)
Block(-4,17,-7,srparasites:parasiterubbledense:1)
Block(-4,17,-6,srparasites:parasiterubbledense:1)
Block(-4,17,-5,srparasites:parasiterubbledense:1)
Block(-4,17,-4,srparasites:parasiterubbledense:1)
Block(-4,17,-3,srparasites:parasiterubbledense:1)
Block(-4,18,-7,srparasites:parasiterubbledense:1)
Block(-4,18,-6,srparasites:parasiterubbledense:1)
Block(-4,18,-5,srparasites:parasiterubbledense:1)
Block(-4,18,-4,srparasites:parasiterubbledense:1)
Block(-4,19,-7,srparasites:parasiterubbledense:1)
Block(-4,19,-6,srparasites:parasiterubbledense:1)
Block(-4,19,-5,srparasites:parasiterubbledense:1)
Block(-4,20,-7,srparasites:parasitestain:2)
Block(-4,20,-6,srparasites:parasitestain:2)
Block(-4,20,-5,srparasites:parasitestain:2)
Block(-4,21,-7,srparasites:parasitestain:2)
Block(-4,21,-6,srparasites:parasiterubble:1)
Block(-4,21,-5,srparasites:parasitestain:1)
Block(-4,22,-7,srparasites:parasiterubble:1)
Block(-4,22,-6,AIR:0)
Block(-4,22,-5,srparasites:parasitestain:1)
Block(-4,23,-7,srparasites:parasitebush:0)
Block(-4,23,-6,srparasites:parasitestain:1)
Block(-4,23,-5,AIR:0)
Block(-4,24,-7,srparasites:parasitestain:2)
Block(-4,24,-6,srparasites:parasitestain:1)
Block(-4,24,-5,srparasites:parasitestain:1)
Block(-4,25,-7,srparasites:parasitestain:2)
Block(-4,25,-6,srparasites:parasitestain:1)
Block(-4,25,-5,srparasites:parasiterubbledense:1)
Block(-4,26,-7,srparasites:parasitestain:2)
Block(-4,26,-6,srparasites:parasiterubbledense:1)
Block(-4,26,-5,srparasites:parasiterubbledense:1)
Block(-4,27,-7,srparasites:parasiterubbledense:1)
Block(-4,27,-6,srparasites:parasiterubbledense:1)
Block(-4,27,-5,srparasites:parasiterubbledense:1)
Block(-4,27,-4,srparasites:parasiterubbledense:1)
Block(-4,28,-7,srparasites:parasiterubbledense:1)
Block(-4,28,-6,srparasites:parasiterubbledense:1)
Block(-4,28,-5,srparasites:parasiterubbledense:1)
Block(-4,28,-4,srparasites:parasiterubbledense:1)
Block(-4,28,-3,srparasites:parasiterubbledense:1)
Block(-4,29,-7,srparasites:parasiterubbledense:1)
Block(-4,29,-6,srparasites:parasiterubbledense:1)
Block(-4,29,-5,srparasites:parasiterubbledense:1)
Block(-4,29,-4,srparasites:parasiterubbledense:1)
Block(-4,30,-7,srparasites:parasiterubbledense:1)
Block(-4,30,-6,srparasites:parasiterubbledense:1)
Block(-4,30,-5,srparasites:parasiterubbledense:1)
Block(-4,30,-4,srparasites:parasiterubbledense:1)
Block(-4,31,-7,srparasites:parasiterubbledense:1)
Block(-4,31,-6,srparasites:parasiterubbledense:1)
Block(-4,31,-5,srparasites:parasitestain:2)
Block(-4,31,-4,srparasites:parasitestain:2)
Block(-4,32,-7,srparasites:parasiterubbledense:1)
Block(-4,32,-6,srparasites:parasiterubbledense:1)
Block(-4,32,-5,srparasites:parasiterubbledense:1)
Block(-4,33,-7,srparasites:parasiterubbledense:1)
Block(-4,33,-6,srparasites:parasiterubbledense:1)
Block(-4,33,-5,srparasites:parasiterubbledense:1)
Block(-4,34,-7,srparasites:parasiterubbledense:1)
Block(-4,34,-6,srparasites:parasiterubbledense:1)
Block(-4,34,-5,srparasites:parasiterubbledense:1)
Block(-4,35,-7,srparasites:parasiterubbledense:1)
Block(-4,35,-6,srparasites:parasiterubbledense:1)
Block(-4,35,-5,srparasites:parasiterubbledense:1)
Block(-4,35,-4,srparasites:parasiterubbledense:1)
Block(-4,36,-7,srparasites:parasiterubbledense:1)
Block(-4,36,-6,srparasites:parasiterubbledense:1)
Block(-4,36,-5,srparasites:parasiterubbledense:1)
Block(-4,36,-4,srparasites:parasiterubbledense:1)
Block(-4,37,-7,srparasites:parasitestain:2)
Block(-4,37,-6,srparasites:parasiterubbledense:1)
Block(-4,37,-5,srparasites:parasiterubbledense:1)
Block(-4,37,-4,srparasites:parasiterubbledense:1)
Block(-4,37,-3,srparasites:parasiterubbledense:1)
Block(-4,38,-7,srparasites:parasitestain:2)
Block(-4,38,-6,srparasites:parasitestain:2)
Block(-4,38,-5,srparasites:parasiterubbledense:1)
Block(-4,38,-4,srparasites:parasiterubbledense:1)
Block(-4,39,-7,srparasites:parasitestain:2)
Block(-4,39,-6,srparasites:parasitestain:2)
Block(-4,39,-5,srparasites:parasitestain:2)
Block(-4,40,-7,srparasites:parasitestain:2)
Block(-4,40,-6,srparasites:parasitestain:2)
Block(-4,40,-5,srparasites:parasitestain:2)
Block(-4,41,-7,srparasites:parasitestain:2)
Block(-4,41,-6,srparasites:parasitestain:1)
Block(-4,41,-5,AIR:0)
Block(-4,42,-7,srparasites:parasitestain:1)
Block(-4,42,-6,srparasites:parasiterubble:1)
Block(-4,43,-7,srparasites:parasitestain:2)
Block(-4,43,-6,srparasites:parasiterubble:1)
Block(-4,43,-5,srparasites:parasitestain:1)
Block(-4,44,-7,srparasites:parasitestain:2)
Block(-4,44,-6,srparasites:parasitestain:2)
Block(-4,44,-5,srparasites:parasitestain:2)
Block(-4,45,-7,srparasites:parasitebush:0)
Block(-4,45,-6,srparasites:parasitestain:2)
Block(-4,45,-5,srparasites:parasitestain:2)
Block(-4,46,-7,srparasites:parasitestain:1)
Block(-4,46,-6,srparasites:parasitestain:1)
Block(-4,46,-5,AIR:0)
Block(-4,47,-7,srparasites:parasitestain:1)
Block(-4,47,-6,srparasites:parasitestain:1)
Block(-4,47,-5,srparasites:parasitestain:1)
Block(-4,48,-7,srparasites:parasiterubble:1)
Block(-4,48,-6,srparasites:parasitestain:1)
Block(-4,48,-5,srparasites:parasiterubble:1)
Block(-4,49,-7,srparasites:parasitebush:0)
Block(-4,49,-6,srparasites:parasitestain:1)
Block(-4,49,-5,srparasites:parasiterubble:1)
Block(-4,50,-7,srparasites:parasitebush:0)
Block(-4,50,-6,srparasites:parasitestain:2)
Block(-4,50,-5,srparasites:parasitestain:2)
Block(-4,51,-7,srparasites:parasitestain:2)
Block(-4,51,-6,srparasites:parasitestain:2)
Block(-4,51,-5,srparasites:parasitestain:2)
Block(-4,52,-7,srparasites:parasitestain:2)
Block(-4,52,-6,srparasites:parasitestain:2)
Block(-4,52,-5,srparasites:parasitestain:2)
Block(-4,53,-7,srparasites:parasitestain:2)
Block(-4,53,-6,srparasites:parasitestain:2)
Block(-4,53,-5,srparasites:parasitestain:2)
Block(-4,53,-4,srparasites:parasitestain:2)
Block(-4,54,-7,srparasites:parasitestain:2)
Block(-4,54,-6,srparasites:parasitestain:2)
Block(-4,54,-5,srparasites:parasitestain:2)
Block(-4,54,-4,srparasites:parasitestain:2)
Block(-4,55,-7,srparasites:parasitestain:2)
Block(-4,67,-7,biomesoplenty:dirt:8)
Block(-4,67,-6,biomesoplenty:dirt:8)
Block(-4,67,-5,biomesoplenty:dirt:8)
Block(-4,67,-4,biomesoplenty:dirt:8)
Block(-4,67,-3,biomesoplenty:dirt:8)
Block(-4,67,-2,biomesoplenty:dirt:8)
Block(-4,67,-1,biomesoplenty:dirt:8)
Block(-4,67,0,biomesoplenty:dirt:8)
Block(-4,67,1,biomesoplenty:dirt:8)
Block(-4,67,2,biomesoplenty:dirt:8)
Block(-4,67,3,biomesoplenty:dirt:8)
Block(-4,67,4,biomesoplenty:dirt:8)
Block(-4,67,5,biomesoplenty:dirt:8)
Block(-4,67,6,biomesoplenty:dirt:8)
Block(-4,67,7,biomesoplenty:dirt:8)
Block(-4,67,8,biomesoplenty:dirt:8)
Block(-4,68,-7,biomesoplenty:dirt:8)
Block(-4,68,-6,biomesoplenty:dirt:8)
Block(-4,68,-5,biomesoplenty:dirt:8)
Block(-4,68,-4,biomesoplenty:dirt:8)
Block(-4,68,-3,biomesoplenty:dirt:8)
Block(-4,68,-2,biomesoplenty:dirt:8)
Block(-4,68,-1,biomesoplenty:dirt:8)
Block(-4,68,0,biomesoplenty:dirt:8)
Block(-4,68,1,biomesoplenty:dirt:8)
Block(-4,68,2,biomesoplenty:dirt:8)
Block(-4,68,3,biomesoplenty:dirt:8)
Block(-4,68,4,biomesoplenty:dirt:8)
Block(-4,68,5,biomesoplenty:dirt:8)
Block(-4,68,6,biomesoplenty:dirt:8)
Block(-4,68,7,biomesoplenty:dirt:8)
Block(-4,68,8,biomesoplenty:dirt:8)
Block(-4,69,-7,biomesoplenty:dirt:8)
Block(-4,69,-6,biomesoplenty:dirt:8)
Block(-4,69,-5,biomesoplenty:dirt:8)
Block(-4,69,-4,biomesoplenty:dirt:8)
Block(-4,69,-3,biomesoplenty:dirt:8)
Block(-4,69,-2,biomesoplenty:dirt:8)
Block(-4,69,-1,biomesoplenty:dirt:8)
Block(-4,69,0,biomesoplenty:dirt:8)
Block(-4,69,1,biomesoplenty:dirt:8)
Block(-4,69,2,biomesoplenty:dirt:8)
Block(-4,69,3,biomesoplenty:dirt:8)
Block(-4,69,4,biomesoplenty:dirt:8)
Block(-4,69,5,biomesoplenty:dirt:8)
Block(-4,69,6,biomesoplenty:dirt:8)
Block(-4,69,7,biomesoplenty:dirt:8)
Block(-4,69,8,biomesoplenty:dirt:8)
Block(-4,70,-7,biomesoplenty:dirt:8)
Block(-4,70,-6,biomesoplenty:dirt:8)
Block(-4,70,-5,biomesoplenty:dirt:8)
Block(-4,70,-4,biomesoplenty:dirt:8)
Block(-4,70,-3,biomesoplenty:dirt:8)
Block(-4,70,-2,biomesoplenty:dirt:8)
Block(-4,70,-1,biomesoplenty:dirt:8)
Block(-4,70,0,biomesoplenty:dirt:8)
Block(-4,70,1,biomesoplenty:dirt:8)
Block(-4,70,2,biomesoplenty:dirt:8)
Block(-4,70,3,biomesoplenty:dirt:8)
Block(-4,70,4,biomesoplenty:dirt:8)
Block(-4,70,5,biomesoplenty:dirt:8)
Block(-4,70,6,biomesoplenty:dirt:8)
Block(-4,70,7,biomesoplenty:dirt:8)
Block(-4,70,8,biomesoplenty:dirt:8)
Block(-4,71,-7,biomesoplenty:dirt:8)
Block(-4,71,-6,biomesoplenty:dirt:8)
Block(-4,71,-5,biomesoplenty:dirt:8)
Block(-4,71,-4,biomesoplenty:dirt:8)
Block(-4,71,-3,biomesoplenty:dirt:8)
Block(-4,71,-2,biomesoplenty:dirt:8)
Block(-4,71,-1,biomesoplenty:dirt:8)
Block(-4,71,0,biomesoplenty:dirt:8)
Block(-4,71,1,biomesoplenty:dirt:8)
Block(-4,71,2,biomesoplenty:dirt:8)
Block(-4,71,3,biomesoplenty:dirt:8)
Block(-4,71,4,biomesoplenty:dirt:8)
Block(-4,71,5,biomesoplenty:dirt:8)
Block(-4,71,6,biomesoplenty:dirt:8)
Block(-4,71,7,biomesoplenty:dirt:8)
Block(-4,71,8,biomesoplenty:dirt:8)
Block(-4,72,-7,biomesoplenty:dirt:8)
Block(-4,72,-6,biomesoplenty:dirt:8)
Block(-4,72,-5,biomesoplenty:dirt:8)
Block(-4,72,-4,biomesoplenty:dirt:8)
Block(-4,72,-3,biomesoplenty:dirt:8)
Block(-4,72,-2,biomesoplenty:dirt:8)
Block(-4,72,-1,biomesoplenty:dirt:8)
Block(-4,72,0,biomesoplenty:dirt:8)
Block(-4,72,1,biomesoplenty:dirt:8)
Block(-4,72,2,biomesoplenty:dirt:8)
Block(-4,72,3,biomesoplenty:dirt:8)
Block(-4,72,4,biomesoplenty:dirt:8)
Block(-4,72,5,biomesoplenty:dirt:8)
Block(-4,72,6,biomesoplenty:dirt:8)
Block(-4,72,7,biomesoplenty:dirt:8)
Block(-4,72,8,biomesoplenty:dirt:8)
Block(-4,73,-7,biomesoplenty:dirt:8)
Block(-4,73,-6,biomesoplenty:dirt:8)
Block(-4,73,-5,biomesoplenty:dirt:8)
Block(-4,73,-4,biomesoplenty:dirt:8)
Block(-4,73,-3,biomesoplenty:dirt:8)
Block(-4,73,-2,biomesoplenty:dirt:8)
Block(-4,73,-1,biomesoplenty:dirt:8)
Block(-4,73,0,biomesoplenty:dirt:8)
Block(-4,73,1,biomesoplenty:dirt:8)
Block(-4,73,2,biomesoplenty:dirt:8)
Block(-4,73,3,biomesoplenty:dirt:8)
Block(-4,73,4,biomesoplenty:dirt:8)
Block(-4,73,5,biomesoplenty:dirt:8)
Block(-4,73,6,biomesoplenty:dirt:8)
Block(-4,73,7,biomesoplenty:dirt:8)
Block(-4,73,8,biomesoplenty:dirt:8)
Block(-4,74,-7,biomesoplenty:dirt:8)
Block(-4,74,-6,biomesoplenty:dirt:8)
Block(-4,74,-5,biomesoplenty:dirt:8)
Block(-4,74,-4,biomesoplenty:dirt:8)
Block(-4,74,-3,biomesoplenty:dirt:8)
Block(-4,74,-2,biomesoplenty:dirt:8)
Block(-4,74,-1,biomesoplenty:dirt:8)
Block(-4,74,0,biomesoplenty:dirt:8)
Block(-4,74,1,biomesoplenty:dirt:8)
Block(-4,74,2,biomesoplenty:dirt:8)
Block(-4,74,3,biomesoplenty:dirt:8)
Block(-4,74,4,biomesoplenty:dirt:8)
Block(-4,74,5,biomesoplenty:dirt:8)
Block(-4,74,6,biomesoplenty:dirt:8)
Block(-4,74,7,biomesoplenty:dirt:8)
Block(-4,74,8,biomesoplenty:dirt:8)
Block(-4,75,-7,srparasites:parasitestain:0)
Block(-4,75,-6,srparasites:parasitestain:0)
Block(-4,75,-5,srparasites:parasitestain:2)
Block(-4,75,-4,srparasites:parasitestain:2)
Block(-4,75,-3,biomesoplenty:dirt:8)
Block(-4,75,-2,biomesoplenty:dirt:8)
Block(-4,75,-1,biomesoplenty:dirt:8)
Block(-4,75,0,biomesoplenty:dirt:8)
Block(-4,75,1,biomesoplenty:dirt:8)
Block(-4,75,2,biomesoplenty:dirt:8)
Block(-4,75,3,biomesoplenty:dirt:8)
Block(-4,75,4,biomesoplenty:dirt:8)
Block(-4,75,5,biomesoplenty:dirt:8)
Block(-4,75,6,srparasites:parasitestain:2)
Block(-4,75,7,srparasites:parasitestain:2)
Block(-4,75,8,srparasites:parasitestain:0)
Block(-4,76,-7,srparasites:parasitestain:0)
Block(-4,76,-6,srparasites:parasitestain:0)
Block(-4,76,-5,srparasites:parasitestain:2)
Block(-4,76,-4,srparasites:parasitestain:2)
Block(-4,76,-3,srparasites:parasitestain:2)
Block(-4,76,-2,biomesoplenty:dirt:8)
Block(-4,76,-1,biomesoplenty:dirt:8)
Block(-4,76,0,biomesoplenty:dirt:8)
Block(-4,76,1,biomesoplenty:dirt:8)
Block(-4,76,2,biomesoplenty:dirt:8)
Block(-4,76,3,biomesoplenty:dirt:8)
Block(-4,76,4,biomesoplenty:dirt:8)
Block(-4,76,5,biomesoplenty:dirt:8)
Block(-4,76,6,srparasites:parasitestain:2)
Block(-4,76,7,srparasites:parasitestain:2)
Block(-4,76,8,srparasites:parasitestain:0)
Block(-4,77,-7,srparasites:parasitestain:0)
Block(-4,77,-6,srparasites:parasiterubble_slabhalf:0)
Block(-4,77,-5,srparasites:parasitestain:0)
Block(-4,77,-4,srparasites:parasitestain:0)
Block(-4,77,-3,srparasites:parasitestain:0)
Block(-4,77,-2,srparasites:parasitestain:2)
Block(-4,77,-1,srparasites:parasitestain:2)
Block(-4,77,0,srparasites:parasitestain:2)
Block(-4,77,1,srparasites:parasitestain:2)
Block(-4,77,2,srparasites:parasitestain:2)
Block(-4,77,3,srparasites:parasitestain:2)
Block(-4,77,4,biomesoplenty:dirt:8)
Block(-4,77,5,biomesoplenty:dirt:8)
Block(-4,77,6,srparasites:parasitestain:2)
Block(-4,77,7,srparasites:parasitestain:2)
Block(-4,77,8,srparasites:parasitestain:0)
Block(-4,78,-7,srparasites:infestedbush:3)
Block(-4,78,-6,AIR:0)
Block(-4,78,-5,AIR:0)
Block(-4,78,-4,AIR:0)
Block(-4,78,-3,srparasites:parasiterubble_slabhalf:0)
Block(-4,78,-2,srparasites:parasitestain:0)
Block(-4,78,-1,srparasites:parasitestain:0)
Block(-4,78,0,srparasites:parasitestain:0)
Block(-4,78,1,srparasites:parasitestain:0)
Block(-4,78,2,srparasites:parasitestain:0)
Block(-4,78,3,srparasites:parasitestain:0)
Block(-4,78,4,srparasites:parasitestain:2)
Block(-4,78,5,srparasites:parasitestain:2)
Block(-4,78,6,srparasites:parasitestain:0)
Block(-4,78,7,srparasites:parasitestain:0)
Block(-4,78,8,srparasites:infestedbush:3)
Block(-4,79,-7,srparasites:infestedbush:3)
Block(-4,79,-6,AIR:0)
Block(-4,79,-5,AIR:0)
Block(-4,79,-4,AIR:0)
Block(-4,79,-3,AIR:0)
Block(-4,79,-2,AIR:0)
Block(-4,79,-1,srparasites:parasiterubble_slabhalf:0)
Block(-4,79,0,AIR:0)
Block(-4,79,1,srparasites:parasitestain:0)
Block(-4,79,2,srparasites:parasitestain:0)
Block(-4,79,3,srparasites:parasitestain:0)
Block(-4,79,4,srparasites:parasitestain:0)
Block(-4,79,5,srparasites:parasitestain:0)
Block(-4,79,6,AIR:0)
Block(-4,79,7,srparasites:parasiterubble_slabhalf:0)
Block(-4,79,8,srparasites:infestedbush:3)
Block(-4,80,-7,srparasites:infestedbush:3)
Block(-4,80,-6,AIR:0)
Block(-4,80,-5,AIR:0)
Block(-4,80,-4,AIR:0)
Block(-4,80,-3,AIR:0)
Block(-4,80,-2,AIR:0)
Block(-4,80,-1,AIR:0)
Block(-4,80,0,AIR:0)
Block(-4,80,1,srparasites:parasitestain:0)
Block(-4,80,2,srparasites:parasitestain:0)
Block(-4,80,3,AIR:0)
Block(-4,80,4,AIR:0)
Block(-4,80,5,srparasites:infestedbush:3)
Block(-4,80,6,AIR:0)
Block(-4,80,7,AIR:0)
Block(-4,80,8,srparasites:infestedbush:3)
Block(-4,81,-7,srparasites:infestedbush:3)
Block(-4,81,-6,AIR:0)
Block(-4,81,-5,AIR:0)
Block(-4,81,-4,AIR:0)
Block(-4,81,-3,AIR:0)
Block(-4,81,-2,AIR:0)
Block(-4,81,-1,AIR:0)
Block(-4,81,0,AIR:0)
Block(-4,81,1,AIR:0)
Block(-4,81,2,biomesoplenty:other_slab:0)
Block(-4,81,3,AIR:0)
Block(-4,81,4,AIR:0)
Block(-4,81,5,srparasites:infestedbush:3)
Block(-4,81,6,AIR:0)
Block(-4,81,7,AIR:0)
Block(-4,81,8,srparasites:infestedbush:3)
Block(-4,82,-7,AIR:0)
Block(-4,82,-6,AIR:0)
Block(-4,82,-5,AIR:0)
Block(-4,82,-4,AIR:0)
Block(-4,82,-3,AIR:0)
Block(-4,82,-2,AIR:0)
Block(-4,82,-1,AIR:0)
Block(-4,82,0,AIR:0)
Block(-4,82,1,AIR:0)
Block(-4,82,2,AIR:0)
Block(-4,82,3,AIR:0)
Block(-4,82,4,AIR:0)
Block(-4,82,5,AIR:0)
Block(-4,82,6,AIR:0)
Block(-4,82,7,AIR:0)
Block(-4,82,8,AIR:0)
Block(-4,83,-7,AIR:0)
Block(-4,83,-6,AIR:0)
Block(-4,83,-5,AIR:0)
Block(-4,83,-4,AIR:0)
Block(-4,83,-3,AIR:0)
Block(-4,83,-2,AIR:0)
Block(-4,83,-1,AIR:0)
Block(-4,83,0,AIR:0)
Block(-4,83,1,AIR:0)
Block(-4,83,2,AIR:0)
Block(-4,83,3,AIR:0)
Block(-4,83,4,AIR:0)
Block(-4,83,5,AIR:0)
Block(-4,83,6,AIR:0)
Block(-4,83,7,AIR:0)
Block(-4,83,8,AIR:0)
Block(-3,1,-7,srparasites:parasitestain:2)
Block(-3,1,-6,srparasites:parasitestain:2)
Block(-3,1,-5,srparasites:parasiterubbledense:1)
Block(-3,1,-4,srparasites:parasiterubbledense:1)
Block(-3,1,-3,srparasites:parasiterubbledense:1)
Block(-3,1,-2,srparasites:parasiterubbledense:1)
Block(-3,1,-1,srparasites:parasiterubbledense:1)
Block(-3,1,0,srparasites:parasiterubbledense:1)
Block(-3,1,1,srparasites:parasitestain:2)
Block(-3,2,-7,srparasites:parasitestain:2)
Block(-3,2,-6,srparasites:parasitestain:2)
Block(-3,2,-5,srparasites:parasiterubbledense:1)
Block(-3,2,-4,srparasites:parasiterubbledense:1)
Block(-3,2,-3,srparasites:parasiterubbledense:1)
Block(-3,2,-2,srparasites:parasiterubbledense:1)
Block(-3,3,-7,srparasites:parasitestain:2)
Block(-3,3,-6,srparasites:parasitestain:2)
Block(-3,3,-5,srparasites:parasiterubbledense:1)
Block(-3,3,-4,srparasites:parasiterubbledense:1)
Block(-3,3,-3,srparasites:parasiterubbledense:1)
Block(-3,3,-1,srparasites:parasiterubbledense:1)
Block(-3,4,-7,srparasites:parasitestain:2)
Block(-3,4,-6,srparasites:parasitestain:2)
Block(-3,4,-5,srparasites:parasiterubble:1)
Block(-3,4,-4,srparasites:parasiterubbledense:1)
Block(-3,4,-2,srparasites:parasiterubbledense:1)
Block(-3,4,-1,srparasites:parasiterubbledense:1)
Block(-3,4,0,srparasites:parasiterubbledense:1)
Block(-3,5,-7,srparasites:parasitestain:2)
Block(-3,5,-6,srparasites:parasitestain:1)
Block(-3,5,-5,srparasites:parasiterubble:1)
Block(-3,5,-4,srparasites:parasitestain:1)
Block(-3,5,-1,srparasites:parasiterubbledense:1)
Block(-3,6,-7,srparasites:parasitestain:2)
Block(-3,6,-6,srparasites:parasitestain:2)
Block(-3,6,-5,srparasites:parasitebush:0)
Block(-3,6,-4,srparasites:parasitestain:2)
Block(-3,7,-7,srparasites:parasitestain:2)
Block(-3,7,-6,srparasites:parasitestain:2)
Block(-3,7,-5,srparasites:parasitestain:2)
Block(-3,7,-4,srparasites:parasitestain:1)
Block(-3,8,-7,srparasites:parasitestain:2)
Block(-3,8,-6,srparasites:parasitestain:2)
Block(-3,8,-5,srparasites:parasitestain:2)
Block(-3,8,-4,srparasites:parasitestain:2)
Block(-3,8,0,srparasites:parasiterubbledense:1)
Block(-3,9,-7,srparasites:parasitestain:2)
Block(-3,9,-6,srparasites:parasitestain:2)
Block(-3,9,-5,srparasites:parasitestain:2)
Block(-3,9,-4,srparasites:parasitestain:2)
Block(-3,9,-1,srparasites:parasiterubbledense:1)
Block(-3,9,0,srparasites:parasiterubbledense:1)
Block(-3,9,1,srparasites:parasiterubbledense:1)
Block(-3,10,-7,srparasites:parasitestain:2)
Block(-3,10,-6,srparasites:parasitestain:2)
Block(-3,10,-5,srparasites:parasitestain:2)
Block(-3,10,-4,srparasites:parasitestain:2)
Block(-3,10,-2,srparasites:parasiterubbledense:1)
Block(-3,10,-1,srparasites:parasiterubbledense:1)
Block(-3,10,0,srparasites:parasiterubbledense:1)
Block(-3,11,-7,srparasites:parasitestain:2)
Block(-3,11,-6,srparasites:parasitestain:1)
Block(-3,11,-5,srparasites:parasitestain:2)
Block(-3,11,-4,srparasites:parasiterubbledense:1)
Block(-3,11,-1,srparasites:parasiterubbledense:1)
Block(-3,12,-7,srparasites:parasitestain:2)
Block(-3,12,-6,srparasites:parasitestain:2)
Block(-3,12,-5,srparasites:parasiterubbledense:1)
Block(-3,12,-4,srparasites:parasiterubbledense:1)
Block(-3,13,-7,srparasites:parasitestain:2)
Block(-3,13,-6,srparasites:parasitestain:2)
Block(-3,13,-5,srparasites:parasiterubbledense:1)
Block(-3,13,-4,srparasites:parasiterubbledense:1)
Block(-3,13,-3,srparasites:parasiterubbledense:1)
Block(-3,14,-7,srparasites:parasitestain:2)
Block(-3,14,-6,srparasites:parasitestain:2)
Block(-3,14,-5,srparasites:parasiterubbledense:1)
Block(-3,14,-4,srparasites:parasiterubbledense:1)
Block(-3,14,-3,srparasites:parasiterubbledense:1)
Block(-3,14,-2,srparasites:parasiterubbledense:1)
Block(-3,15,-7,srparasites:parasitestain:2)
Block(-3,15,-6,srparasites:parasitestain:2)
Block(-3,15,-5,srparasites:parasiterubbledense:1)
Block(-3,15,-4,srparasites:parasiterubbledense:1)
Block(-3,15,-3,srparasites:parasiterubbledense:1)
Block(-3,16,-7,srparasites:parasitestain:2)
Block(-3,16,-6,srparasites:parasiterubbledense:1)
Block(-3,16,-5,srparasites:parasiterubbledense:1)
Block(-3,16,-4,srparasites:parasiterubbledense:1)
Block(-3,16,-3,srparasites:parasiterubbledense:1)
Block(-3,17,-7,srparasites:parasitestain:2)
Block(-3,17,-6,srparasites:parasiterubbledense:1)
Block(-3,17,-5,srparasites:parasiterubbledense:1)
Block(-3,17,-4,srparasites:parasiterubbledense:1)
Block(-3,18,-7,srparasites:parasitestain:2)
Block(-3,18,-6,srparasites:parasiterubbledense:1)
Block(-3,18,-5,srparasites:parasiterubbledense:1)
Block(-3,18,-4,srparasites:parasiterubbledense:1)
Block(-3,19,-7,srparasites:parasitestain:2)
Block(-3,19,-6,srparasites:parasitestain:2)
Block(-3,19,-5,srparasites:parasitebush:0)
Block(-3,19,-4,srparasites:parasiterubble:1)
Block(-3,20,-7,srparasites:parasitestain:2)
Block(-3,20,-6,srparasites:parasitestain:2)
Block(-3,20,-5,srparasites:parasitestain:1)
Block(-3,20,-4,AIR:0)
Block(-3,21,-7,srparasites:parasitestain:2)
Block(-3,21,-6,srparasites:parasitestain:2)
Block(-3,21,-5,srparasites:parasitestain:2)
Block(-3,21,-4,srparasites:parasiterubble:1)
Block(-3,22,-7,srparasites:parasitestain:2)
Block(-3,22,-6,srparasites:parasitestain:2)
Block(-3,22,-5,srparasites:parasitebush:0)
Block(-3,22,-4,srparasites:parasitestain:1)
Block(-3,23,-7,srparasites:parasitestain:2)
Block(-3,23,-6,srparasites:parasitestain:2)
Block(-3,23,-5,srparasites:parasiterubble:1)
Block(-3,23,-4,srparasites:parasitestain:1)
Block(-3,24,-7,srparasites:parasitestain:2)
Block(-3,24,-6,srparasites:parasitestain:2)
Block(-3,24,-5,srparasites:parasitebush:0)
Block(-3,24,-4,srparasites:parasiterubbledense:1)
Block(-3,25,-7,srparasites:parasitestain:2)
Block(-3,25,-6,srparasites:parasitestain:2)
Block(-3,25,-5,srparasites:parasiterubbledense:1)
Block(-3,25,-4,srparasites:parasiterubbledense:1)
Block(-3,25,-1,srparasites:parasiterubbledense:1)
Block(-3,26,-7,srparasites:parasitestain:2)
Block(-3,26,-6,srparasites:parasiterubbledense:1)
Block(-3,26,-5,srparasites:parasiterubbledense:1)
Block(-3,26,-4,srparasites:parasiterubbledense:1)
Block(-3,26,-3,srparasites:parasiterubbledense:1)
Block(-3,26,-2,srparasites:parasiterubbledense:1)
Block(-3,26,-1,srparasites:parasiterubbledense:1)
Block(-3,26,0,srparasites:parasiterubbledense:1)
Block(-3,27,-7,srparasites:parasiterubbledense:1)
Block(-3,27,-6,srparasites:parasiterubbledense:1)
Block(-3,27,-5,srparasites:parasiterubbledense:1)
Block(-3,27,-4,srparasites:parasiterubbledense:1)
Block(-3,27,-3,srparasites:parasiterubbledense:1)
Block(-3,27,-2,srparasites:parasiterubbledense:1)
Block(-3,27,-1,srparasites:parasiterubbledense:1)
Block(-3,28,-7,srparasites:parasiterubbledense:1)
Block(-3,28,-6,srparasites:parasiterubbledense:1)
Block(-3,28,-5,srparasites:parasiterubbledense:1)
Block(-3,28,-4,srparasites:parasiterubbledense:1)
Block(-3,28,-3,srparasites:parasiterubbledense:1)
Block(-3,29,-7,srparasites:parasiterubbledense:1)
Block(-3,29,-6,srparasites:parasiterubbledense:1)
Block(-3,29,-5,srparasites:parasiterubbledense:1)
Block(-3,29,-4,srparasites:parasiterubbledense:1)
Block(-3,29,-3,srparasites:parasiterubbledense:1)
Block(-3,30,-7,srparasites:parasitestain:2)
Block(-3,30,-6,srparasites:parasiterubbledense:1)
Block(-3,30,-5,srparasites:parasiterubbledense:1)
Block(-3,30,-4,srparasites:parasiterubbledense:1)
Block(-3,31,-7,srparasites:parasitestain:2)
Block(-3,31,-6,srparasites:parasitestain:2)
Block(-3,31,-5,srparasites:parasitestain:2)
Block(-3,31,-4,srparasites:parasitestain:2)
Block(-3,32,-7,srparasites:parasitestain:2)
Block(-3,32,-6,srparasites:parasitestain:2)
Block(-3,32,-5,srparasites:parasitestain:2)
Block(-3,32,-4,srparasites:parasitestain:2)
Block(-3,33,-7,srparasites:parasiterubbledense:1)
Block(-3,33,-6,srparasites:parasiterubbledense:1)
Block(-3,33,-5,srparasites:parasiterubbledense:1)
Block(-3,33,-4,srparasites:parasitestain:2)
Block(-3,34,-7,srparasites:parasiterubbledense:1)
Block(-3,34,-6,srparasites:parasiterubbledense:1)
Block(-3,34,-5,srparasites:parasiterubbledense:1)
Block(-3,34,-4,srparasites:parasiterubbledense:1)
Block(-3,35,-7,srparasites:parasiterubbledense:1)
Block(-3,35,-6,srparasites:parasiterubbledense:1)
Block(-3,35,-5,srparasites:parasiterubbledense:1)
Block(-3,35,-4,srparasites:parasiterubbledense:1)
Block(-3,35,0,srparasites:parasiterubbledense:1)
Block(-3,36,-7,srparasites:parasitestain:2)
Block(-3,36,-6,srparasites:parasitestain:2)
Block(-3,36,-5,srparasites:parasiterubbledense:1)
Block(-3,36,-4,srparasites:parasiterubbledense:1)
Block(-3,36,-3,srparasites:parasiterubbledense:1)
Block(-3,36,-1,srparasites:parasiterubbledense:1)
Block(-3,36,0,srparasites:parasiterubbledense:1)
Block(-3,36,1,srparasites:parasiterubbledense:1)
Block(-3,37,-7,srparasites:parasitestain:2)
Block(-3,37,-6,srparasites:parasitestain:2)
Block(-3,37,-5,srparasites:parasiterubbledense:1)
Block(-3,37,-4,srparasites:parasiterubbledense:1)
Block(-3,37,-3,srparasites:parasiterubbledense:1)
Block(-3,37,-2,srparasites:parasiterubbledense:1)
Block(-3,37,-1,srparasites:parasiterubbledense:1)
Block(-3,37,0,srparasites:parasiterubbledense:1)
Block(-3,38,-7,srparasites:parasitestain:2)
Block(-3,38,-6,srparasites:parasitestain:2)
Block(-3,38,-5,srparasites:parasitestain:2)
Block(-3,38,-4,srparasites:parasiterubbledense:1)
Block(-3,38,-3,srparasites:parasiterubbledense:1)
Block(-3,38,-1,srparasites:parasiterubbledense:1)
Block(-3,39,-7,srparasites:parasitestain:2)
Block(-3,39,-6,srparasites:parasitestain:2)
Block(-3,39,-5,srparasites:parasitestain:2)
Block(-3,39,-4,srparasites:parasitestain:2)
Block(-3,40,-7,srparasites:parasitestain:2)
Block(-3,40,-6,srparasites:parasitestain:2)
Block(-3,40,-5,srparasites:parasitestain:1)
Block(-3,40,-4,srparasites:parasitestain:1)
Block(-3,41,-7,srparasites:parasitestain:2)
Block(-3,41,-6,srparasites:parasitestain:2)
Block(-3,41,-5,srparasites:parasitestain:1)
Block(-3,41,-4,AIR:0)
Block(-3,42,-7,srparasites:parasitestain:2)
Block(-3,42,-6,srparasites:parasitebush:0)
Block(-3,43,-7,srparasites:parasitestain:2)
Block(-3,43,-6,srparasites:parasitestain:2)
Block(-3,43,-5,AIR:0)
Block(-3,43,-4,srparasites:parasitestain:2)
Block(-3,44,-7,srparasites:parasitestain:2)
Block(-3,44,-6,srparasites:parasitestain:2)
Block(-3,44,-5,srparasites:parasitestain:2)
Block(-3,44,-4,srparasites:parasitestain:2)
Block(-3,45,-7,srparasites:parasitestain:2)
Block(-3,45,-6,srparasites:parasitestain:1)
Block(-3,45,-5,srparasites:parasitestain:1)
Block(-3,45,-4,srparasites:parasitestain:1)
Block(-3,46,-7,srparasites:parasitestain:2)
Block(-3,46,-6,srparasites:parasiterubble:1)
Block(-3,46,-5,srparasites:parasitestain:1)
Block(-3,46,-4,AIR:0)
Block(-3,47,-7,srparasites:parasitestain:2)
Block(-3,47,-6,srparasites:parasitestain:1)
Block(-3,47,-5,srparasites:parasitebush:0)
Block(-3,47,-4,srparasites:parasitestain:1)
Block(-3,48,-7,srparasites:parasitestain:2)
Block(-3,48,-6,srparasites:parasitestain:1)
Block(-3,48,-5,srparasites:parasitestain:1)
Block(-3,48,-4,srparasites:parasitestain:1)
Block(-3,49,-7,srparasites:parasitestain:2)
Block(-3,49,-6,srparasites:parasitestain:2)
Block(-3,49,-5,srparasites:parasiterubble:1)
Block(-3,49,-4,AIR:0)
Block(-3,50,-7,srparasites:parasitestain:2)
Block(-3,50,-6,srparasites:parasitestain:2)
Block(-3,50,-5,srparasites:parasitestain:2)
Block(-3,50,-4,srparasites:parasitestain:2)
Block(-3,51,-7,srparasites:parasitestain:2)
Block(-3,51,-6,srparasites:parasitestain:2)
Block(-3,51,-5,srparasites:parasitestain:2)
Block(-3,51,-4,srparasites:parasiterubble:1)
Block(-3,52,-7,srparasites:parasitestain:2)
Block(-3,52,-6,srparasites:parasitestain:2)
Block(-3,52,-5,srparasites:parasitestain:2)
Block(-3,52,-4,srparasites:parasitestain:2)
Block(-3,53,-7,srparasites:parasitestain:2)
Block(-3,53,-6,srparasites:parasitestain:2)
Block(-3,53,-5,srparasites:parasitestain:2)
Block(-3,53,-4,srparasites:parasitestain:2)
Block(-3,53,-3,srparasites:parasitestain:2)
Block(-3,54,-7,srparasites:parasitestain:2)
Block(-3,54,-6,srparasites:parasitestain:2)
Block(-3,54,-5,srparasites:parasitestain:2)
Block(-3,54,-4,srparasites:parasitestain:2)
Block(-3,54,-3,srparasites:parasitestain:2)
Block(-3,55,-7,srparasites:parasitestain:2)
Block(-3,55,-6,srparasites:parasitestain:2)
Block(-3,55,-5,srparasites:parasitestain:2)
Block(-3,55,-4,srparasites:parasitestain:2)
Block(-3,58,-7,srparasites:parasitestain:2)
Block(-3,58,-6,srparasites:parasitestain:2)
Block(-3,59,-7,srparasites:parasitestain:2)
Block(-3,59,-6,srparasites:parasitestain:2)
Block(-3,60,-7,srparasites:parasitestain:2)
Block(-3,60,-6,srparasites:parasitestain:2)
Block(-3,61,-7,srparasites:parasitestain:2)
Block(-3,61,-6,srparasites:parasitestain:2)
Block(-3,67,-7,biomesoplenty:dirt:8)
Block(-3,67,-6,biomesoplenty:dirt:8)
Block(-3,67,-5,biomesoplenty:dirt:8)
Block(-3,67,-4,biomesoplenty:dirt:8)
Block(-3,67,-3,biomesoplenty:dirt:8)
Block(-3,67,-2,biomesoplenty:dirt:8)
Block(-3,67,-1,biomesoplenty:dirt:8)
Block(-3,67,0,biomesoplenty:dirt:8)
Block(-3,67,1,biomesoplenty:dirt:8)
Block(-3,67,2,biomesoplenty:dirt:8)
Block(-3,67,3,biomesoplenty:dirt:8)
Block(-3,67,4,biomesoplenty:dirt:8)
Block(-3,67,5,biomesoplenty:dirt:8)
Block(-3,67,6,biomesoplenty:dirt:8)
Block(-3,67,7,biomesoplenty:dirt:8)
Block(-3,67,8,biomesoplenty:dirt:8)
Block(-3,68,-7,biomesoplenty:dirt:8)
Block(-3,68,-6,biomesoplenty:dirt:8)
Block(-3,68,-5,biomesoplenty:dirt:8)
Block(-3,68,-4,biomesoplenty:dirt:8)
Block(-3,68,-3,biomesoplenty:dirt:8)
Block(-3,68,-2,biomesoplenty:dirt:8)
Block(-3,68,-1,biomesoplenty:dirt:8)
Block(-3,68,0,biomesoplenty:dirt:8)
Block(-3,68,1,biomesoplenty:dirt:8)
Block(-3,68,2,biomesoplenty:dirt:8)
Block(-3,68,3,biomesoplenty:dirt:8)
Block(-3,68,4,biomesoplenty:dirt:8)
Block(-3,68,5,biomesoplenty:dirt:8)
Block(-3,68,6,biomesoplenty:dirt:8)
Block(-3,68,7,biomesoplenty:dirt:8)
Block(-3,68,8,biomesoplenty:dirt:8)
Block(-3,69,-7,biomesoplenty:dirt:8)
Block(-3,69,-6,biomesoplenty:dirt:8)
Block(-3,69,-5,biomesoplenty:dirt:8)
Block(-3,69,-4,biomesoplenty:dirt:8)
Block(-3,69,-3,biomesoplenty:dirt:8)
Block(-3,69,-2,biomesoplenty:dirt:8)
Block(-3,69,-1,biomesoplenty:dirt:8)
Block(-3,69,0,biomesoplenty:dirt:8)
Block(-3,69,1,biomesoplenty:dirt:8)
Block(-3,69,2,biomesoplenty:dirt:8)
Block(-3,69,3,biomesoplenty:dirt:8)
Block(-3,69,4,biomesoplenty:dirt:8)
Block(-3,69,5,biomesoplenty:dirt:8)
Block(-3,69,6,biomesoplenty:dirt:8)
Block(-3,69,7,biomesoplenty:dirt:8)
Block(-3,69,8,biomesoplenty:dirt:8)
Block(-3,70,-7,biomesoplenty:dirt:8)
Block(-3,70,-6,biomesoplenty:dirt:8)
Block(-3,70,-5,biomesoplenty:dirt:8)
Block(-3,70,-4,biomesoplenty:dirt:8)
Block(-3,70,-3,biomesoplenty:dirt:8)
Block(-3,70,-2,biomesoplenty:dirt:8)
Block(-3,70,-1,biomesoplenty:dirt:8)
Block(-3,70,0,biomesoplenty:dirt:8)
Block(-3,70,1,biomesoplenty:dirt:8)
Block(-3,70,2,biomesoplenty:dirt:8)
Block(-3,70,3,biomesoplenty:dirt:8)
Block(-3,70,4,biomesoplenty:dirt:8)
Block(-3,70,5,biomesoplenty:dirt:8)
Block(-3,70,6,biomesoplenty:dirt:8)
Block(-3,70,7,biomesoplenty:dirt:8)
Block(-3,70,8,biomesoplenty:dirt:8)
Block(-3,71,-7,biomesoplenty:dirt:8)
Block(-3,71,-6,biomesoplenty:dirt:8)
Block(-3,71,-5,biomesoplenty:dirt:8)
Block(-3,71,-4,biomesoplenty:dirt:8)
Block(-3,71,-3,biomesoplenty:dirt:8)
Block(-3,71,-2,biomesoplenty:dirt:8)
Block(-3,71,-1,biomesoplenty:dirt:8)
Block(-3,71,0,biomesoplenty:dirt:8)
Block(-3,71,1,biomesoplenty:dirt:8)
Block(-3,71,2,biomesoplenty:dirt:8)
Block(-3,71,3,biomesoplenty:dirt:8)
Block(-3,71,4,biomesoplenty:dirt:8)
Block(-3,71,5,biomesoplenty:dirt:8)
Block(-3,71,6,biomesoplenty:dirt:8)
Block(-3,71,7,biomesoplenty:dirt:8)
Block(-3,71,8,biomesoplenty:dirt:8)
Block(-3,72,-7,biomesoplenty:dirt:8)
Block(-3,72,-6,biomesoplenty:dirt:8)
Block(-3,72,-5,biomesoplenty:dirt:8)
Block(-3,72,-4,biomesoplenty:dirt:8)
Block(-3,72,-3,biomesoplenty:dirt:8)
Block(-3,72,-2,biomesoplenty:dirt:8)
Block(-3,72,-1,biomesoplenty:dirt:8)
Block(-3,72,0,biomesoplenty:dirt:8)
Block(-3,72,1,biomesoplenty:dirt:8)
Block(-3,72,2,biomesoplenty:dirt:8)
Block(-3,72,3,biomesoplenty:dirt:8)
Block(-3,72,4,biomesoplenty:dirt:8)
Block(-3,72,5,biomesoplenty:dirt:8)
Block(-3,72,6,biomesoplenty:dirt:8)
Block(-3,72,7,biomesoplenty:dirt:8)
Block(-3,72,8,biomesoplenty:dirt:8)
Block(-3,73,-7,biomesoplenty:dirt:8)
Block(-3,73,-6,biomesoplenty:dirt:8)
Block(-3,73,-5,biomesoplenty:dirt:8)
Block(-3,73,-4,biomesoplenty:dirt:8)
Block(-3,73,-3,biomesoplenty:dirt:8)
Block(-3,73,-2,biomesoplenty:dirt:8)
Block(-3,73,-1,biomesoplenty:dirt:8)
Block(-3,73,0,biomesoplenty:dirt:8)
Block(-3,73,1,biomesoplenty:dirt:8)
Block(-3,73,2,biomesoplenty:dirt:8)
Block(-3,73,3,biomesoplenty:dirt:8)
Block(-3,73,4,biomesoplenty:dirt:8)
Block(-3,73,5,biomesoplenty:dirt:8)
Block(-3,73,6,biomesoplenty:dirt:8)
Block(-3,73,7,biomesoplenty:dirt:8)
Block(-3,73,8,biomesoplenty:dirt:8)
Block(-3,74,-7,biomesoplenty:dirt:8)
Block(-3,74,-6,biomesoplenty:dirt:8)
Block(-3,74,-5,biomesoplenty:dirt:8)
Block(-3,74,-4,biomesoplenty:dirt:8)
Block(-3,74,-3,biomesoplenty:dirt:8)
Block(-3,74,-2,biomesoplenty:dirt:8)
Block(-3,74,-1,biomesoplenty:dirt:8)
Block(-3,74,0,biomesoplenty:dirt:8)
Block(-3,74,1,biomesoplenty:dirt:8)
Block(-3,74,2,biomesoplenty:dirt:8)
Block(-3,74,3,biomesoplenty:dirt:8)
Block(-3,74,4,biomesoplenty:dirt:8)
Block(-3,74,5,biomesoplenty:dirt:8)
Block(-3,74,6,biomesoplenty:dirt:8)
Block(-3,74,7,biomesoplenty:dirt:8)
Block(-3,74,8,biomesoplenty:dirt:8)
Block(-3,75,-7,srparasites:parasiterubble_slabhalf:0)
Block(-3,75,-6,srparasites:parasitestain:2)
Block(-3,75,-5,srparasites:parasitestain:0)
Block(-3,75,-4,srparasites:parasitestain:0)
Block(-3,75,-3,srparasites:parasitestain:2)
Block(-3,75,-2,srparasites:parasitestain:2)
Block(-3,75,-1,srparasites:parasitestain:2)
Block(-3,75,0,biomesoplenty:dirt:8)
Block(-3,75,1,biomesoplenty:dirt:8)
Block(-3,75,2,biomesoplenty:dirt:8)
Block(-3,75,3,biomesoplenty:dirt:8)
Block(-3,75,4,srparasites:parasitestain:2)
Block(-3,75,5,srparasites:parasitestain:2)
Block(-3,75,6,srparasites:parasitestain:0)
Block(-3,75,7,srparasites:parasitestain:0)
Block(-3,75,8,srparasites:parasiterubble_slabhalf:0)
Block(-3,76,-7,biomesoplenty:blood:0)
Block(-3,76,-6,srparasites:parasitestain:2)
Block(-3,76,-5,srparasites:parasitestain:0)
Block(-3,76,-4,srparasites:parasitestain:0)
Block(-3,76,-3,srparasites:parasitestain:2)
Block(-3,76,-2,srparasites:parasitestain:2)
Block(-3,76,-1,srparasites:parasitestain:2)
Block(-3,76,0,srparasites:parasitestain:2)
Block(-3,76,1,biomesoplenty:dirt:8)
Block(-3,76,2,biomesoplenty:dirt:8)
Block(-3,76,3,biomesoplenty:dirt:8)
Block(-3,76,4,srparasites:parasitestain:2)
Block(-3,76,5,srparasites:parasitestain:2)
Block(-3,76,6,srparasites:parasitestain:0)
Block(-3,76,7,srparasites:parasitestain:0)
Block(-3,76,8,biomesoplenty:blood:0)
Block(-3,77,-7,AIR:0)
Block(-3,77,-6,srparasites:parasitebush:4)
Block(-3,77,-5,srparasites:parasitestain:0)
Block(-3,77,-4,srparasites:parasitestain:0)
Block(-3,77,-3,srparasites:parasitestain:0)
Block(-3,77,-2,srparasites:parasitestain:0)
Block(-3,77,-1,srparasites:parasitestain:0)
Block(-3,77,0,srparasites:parasitestain:0)
Block(-3,77,1,srparasites:parasitestain:2)
Block(-3,77,2,srparasites:parasitestain:2)
Block(-3,77,3,srparasites:parasitestain:2)
Block(-3,77,4,srparasites:parasitestain:2)
Block(-3,77,5,srparasites:parasitestain:2)
Block(-3,77,6,srparasites:parasitestain:0)
Block(-3,77,7,srparasites:parasitestain:0)
Block(-3,77,8,AIR:0)
Block(-3,78,-7,AIR:0)
Block(-3,78,-6,AIR:0)
Block(-3,78,-5,AIR:0)
Block(-3,78,-4,AIR:0)
Block(-3,78,-3,AIR:0)
Block(-3,78,-2,AIR:0)
Block(-3,78,-1,AIR:0)
Block(-3,78,0,srparasites:parasitebush:0)
Block(-3,78,1,srparasites:parasitestain:0)
Block(-3,78,2,srparasites:parasitestain:0)
Block(-3,78,3,srparasites:parasitestain:0)
Block(-3,78,4,srparasites:parasitestain:0)
Block(-3,78,5,srparasites:parasitestain:0)
Block(-3,78,6,AIR:0)
Block(-3,78,7,AIR:0)
Block(-3,78,8,AIR:0)
Block(-3,79,-7,AIR:0)
Block(-3,79,-6,AIR:0)
Block(-3,79,-5,AIR:0)
Block(-3,79,-4,AIR:0)
Block(-3,79,-3,AIR:0)
Block(-3,79,-2,AIR:0)
Block(-3,79,-1,AIR:0)
Block(-3,79,0,srparasites:parasitebush:0)
Block(-3,79,1,AIR:0)
Block(-3,79,2,AIR:0)
Block(-3,79,3,srparasites:gore:1)
Block(-3,79,4,srparasites:parasiterubble_slabhalf:0)
Block(-3,79,5,AIR:0)
Block(-3,79,6,AIR:0)
Block(-3,79,7,AIR:0)
Block(-3,79,8,AIR:0)
Block(-3,80,-7,AIR:0)
Block(-3,80,-6,AIR:0)
Block(-3,80,-5,AIR:0)
Block(-3,80,-4,AIR:0)
Block(-3,80,-3,AIR:0)
Block(-3,80,-2,AIR:0)
Block(-3,80,-1,AIR:0)
Block(-3,80,0,srparasites:parasitebush:0)
Block(-3,80,1,AIR:0)
Block(-3,80,2,AIR:0)
Block(-3,80,3,AIR:0)
Block(-3,80,4,AIR:0)
Block(-3,80,5,AIR:0)
Block(-3,80,6,AIR:0)
Block(-3,80,7,AIR:0)
Block(-3,80,8,AIR:0)
Block(-3,81,-7,AIR:0)
Block(-3,81,-6,AIR:0)
Block(-3,81,-5,AIR:0)
Block(-3,81,-4,AIR:0)
Block(-3,81,-3,AIR:0)
Block(-3,81,-2,AIR:0)
Block(-3,81,-1,AIR:0)
Block(-3,81,0,AIR:0)
Block(-3,81,1,AIR:0)
Block(-3,81,2,AIR:0)
Block(-3,81,3,AIR:0)
Block(-3,81,4,AIR:0)
Block(-3,81,5,AIR:0)
Block(-3,81,6,AIR:0)
Block(-3,81,7,AIR:0)
Block(-3,81,8,AIR:0)
Block(-3,82,-7,AIR:0)
Block(-3,82,-6,AIR:0)
Block(-3,82,-5,AIR:0)
Block(-3,82,-4,AIR:0)
Block(-3,82,-3,AIR:0)
Block(-3,82,-2,AIR:0)
Block(-3,82,-1,AIR:0)
Block(-3,82,0,AIR:0)
Block(-3,82,1,AIR:0)
Block(-3,82,2,AIR:0)
Block(-3,82,3,AIR:0)
Block(-3,82,4,AIR:0)
Block(-3,82,5,AIR:0)
Block(-3,82,6,AIR:0)
Block(-3,82,7,AIR:0)
Block(-3,82,8,AIR:0)
Block(-3,83,-7,AIR:0)
Block(-3,83,-6,AIR:0)
Block(-3,83,-5,AIR:0)
Block(-3,83,-4,AIR:0)
Block(-3,83,-3,AIR:0)
Block(-3,83,-2,AIR:0)
Block(-3,83,-1,AIR:0)
Block(-3,83,0,AIR:0)
Block(-3,83,1,AIR:0)
Block(-3,83,2,AIR:0)
Block(-3,83,3,AIR:0)
Block(-3,83,4,AIR:0)
Block(-3,83,5,AIR:0)
Block(-3,83,6,AIR:0)
Block(-3,83,7,AIR:0)
Block(-3,83,8,AIR:0)
Block(-2,0,-7,srparasites:parasitestain:2)
Block(-2,1,-7,srparasites:parasitestain:2)
Block(-2,1,-6,srparasites:parasitestain:2)
Block(-2,1,-5,srparasites:parasiterubbledense:1)
Block(-2,1,-4,srparasites:parasiterubbledense:1)
Block(-2,1,-3,srparasites:parasiterubbledense:1)
Block(-2,1,-2,srparasites:parasiterubbledense:1)
Block(-2,1,-1,srparasites:parasiterubbledense:1)
Block(-2,1,0,srparasites:parasiterubbledense:1)
Block(-2,1,1,srparasites:parasiterubbledense:1)
Block(-2,1,2,srparasites:parasiterubbledense:1)
Block(-2,1,3,srparasites:parasiterubbledense:1)
Block(-2,2,-7,srparasites:parasitestain:2)
Block(-2,2,-6,srparasites:parasitestain:2)
Block(-2,2,-5,srparasites:parasiterubbledense:1)
Block(-2,2,-4,srparasites:parasiterubbledense:1)
Block(-2,2,-3,srparasites:parasiterubbledense:1)
Block(-2,2,-2,srparasites:parasiterubbledense:1)
Block(-2,2,-1,srparasites:parasiterubbledense:1)
Block(-2,3,-7,srparasites:parasitestain:2)
Block(-2,3,-6,srparasites:parasitestain:2)
Block(-2,3,-5,srparasites:parasiterubbledense:1)
Block(-2,3,-4,srparasites:parasiterubbledense:1)
Block(-2,3,-3,srparasites:parasiterubbledense:1)
Block(-2,3,-2,srparasites:parasiterubbledense:1)
Block(-2,3,-1,srparasites:parasiterubbledense:1)
Block(-2,3,0,srparasites:parasiterubbledense:1)
Block(-2,4,-7,srparasites:parasitestain:2)
Block(-2,4,-6,srparasites:parasitestain:2)
Block(-2,4,-5,srparasites:parasitestain:2)
Block(-2,4,-4,srparasites:parasiterubbledense:1)
Block(-2,4,-3,srparasites:parasiterubbledense:1)
Block(-2,4,-2,srparasites:parasiterubbledense:1)
Block(-2,4,-1,srparasites:parasiterubbledense:1)
Block(-2,4,0,srparasites:parasiterubbledense:1)
Block(-2,5,-7,srparasites:parasitestain:2)
Block(-2,5,-6,srparasites:parasitestain:2)
Block(-2,5,-5,srparasites:parasitestain:2)
Block(-2,5,-4,srparasites:parasitestain:2)
Block(-2,5,-3,srparasites:parasiterubbledense:1)
Block(-2,5,-2,srparasites:parasiterubbledense:1)
Block(-2,5,-1,srparasites:parasiterubbledense:1)
Block(-2,5,0,srparasites:parasiterubbledense:1)
Block(-2,6,-7,srparasites:parasitestain:2)
Block(-2,6,-6,srparasites:parasitestain:2)
Block(-2,6,-5,srparasites:parasitestain:2)
Block(-2,6,-4,srparasites:parasitestain:1)
Block(-2,6,-3,srparasites:parasiterubbledense:1)
Block(-2,6,-1,srparasites:parasiterubbledense:1)
Block(-2,6,2,srparasites:parasiterubbledense:1)
Block(-2,7,-7,srparasites:parasitestain:2)
Block(-2,7,-6,srparasites:parasitestain:2)
Block(-2,7,-5,srparasites:parasitestain:2)
Block(-2,7,-4,srparasites:parasitestain:1)
Block(-2,7,-3,srparasites:parasiterubbledense:1)
Block(-2,7,-1,srparasites:parasiterubbledense:1)
Block(-2,7,1,srparasites:parasiterubbledense:1)
Block(-2,7,2,srparasites:parasiterubbledense:1)
Block(-2,7,3,srparasites:parasiterubbledense:1)
Block(-2,8,-7,srparasites:parasitestain:2)
Block(-2,8,-6,srparasites:parasitestain:2)
Block(-2,8,-5,srparasites:parasitestain:2)
Block(-2,8,-4,srparasites:parasitestain:1)
Block(-2,8,-3,srparasites:parasitestain:1)
Block(-2,8,-1,srparasites:parasiterubbledense:1)
Block(-2,8,0,srparasites:parasiterubbledense:1)
Block(-2,8,1,srparasites:parasiterubbledense:1)
Block(-2,8,2,srparasites:parasiterubbledense:1)
Block(-2,9,-7,srparasites:parasitestain:2)
Block(-2,9,-6,srparasites:parasitestain:2)
Block(-2,9,-5,srparasites:parasitestain:2)
Block(-2,9,-4,srparasites:parasitestain:2)
Block(-2,9,-3,srparasites:parasitestain:2)
Block(-2,9,-2,srparasites:parasiterubbledense:1)
Block(-2,9,-1,srparasites:parasiterubbledense:1)
Block(-2,9,0,srparasites:parasiterubbledense:1)
Block(-2,9,1,srparasites:parasiterubbledense:1)
Block(-2,10,-7,srparasites:parasitestain:2)
Block(-2,10,-6,srparasites:parasitestain:2)
Block(-2,10,-5,srparasites:parasitestain:2)
Block(-2,10,-4,srparasites:parasitestain:2)
Block(-2,10,-3,srparasites:parasiterubbledense:1)
Block(-2,10,-2,srparasites:parasiterubbledense:1)
Block(-2,10,-1,srparasites:parasiterubbledense:1)
Block(-2,10,0,srparasites:parasiterubbledense:1)
Block(-2,10,1,srparasites:parasiterubbledense:1)
Block(-2,11,-7,srparasites:parasitestain:2)
Block(-2,11,-6,srparasites:parasitestain:2)
Block(-2,11,-5,srparasites:parasitestain:2)
Block(-2,11,-4,srparasites:parasiterubbledense:1)
Block(-2,11,-3,srparasites:parasiterubbledense:1)
Block(-2,11,-2,srparasites:parasiterubbledense:1)
Block(-2,11,-1,srparasites:parasiterubbledense:1)
Block(-2,11,0,srparasites:parasiterubbledense:1)
Block(-2,12,-7,srparasites:parasitestain:2)
Block(-2,12,-6,srparasites:parasitestain:2)
Block(-2,12,-5,srparasites:parasiterubbledense:1)
Block(-2,12,-4,srparasites:parasiterubbledense:1)
Block(-2,12,-3,srparasites:parasiterubbledense:1)
Block(-2,12,-2,srparasites:parasiterubbledense:1)
Block(-2,12,-1,srparasites:parasiterubbledense:1)
Block(-2,13,-7,srparasites:parasitestain:2)
Block(-2,13,-6,srparasites:parasitestain:2)
Block(-2,13,-5,srparasites:parasiterubbledense:1)
Block(-2,13,-4,srparasites:parasiterubbledense:1)
Block(-2,13,-3,srparasites:parasiterubbledense:1)
Block(-2,13,-2,srparasites:parasiterubbledense:1)
Block(-2,13,-1,srparasites:parasiterubbledense:1)
Block(-2,14,-7,srparasites:parasitestain:2)
Block(-2,14,-6,srparasites:parasitestain:2)
Block(-2,14,-5,srparasites:parasiterubbledense:1)
Block(-2,14,-4,srparasites:parasiterubbledense:1)
Block(-2,14,-3,srparasites:parasiterubbledense:1)
Block(-2,14,-2,srparasites:parasiterubbledense:1)
Block(-2,14,-1,srparasites:parasiterubbledense:1)
Block(-2,15,-7,srparasites:parasitestain:2)
Block(-2,15,-6,srparasites:parasitestain:2)
Block(-2,15,-5,srparasites:parasitestain:2)
Block(-2,15,-4,srparasites:parasiterubbledense:1)
Block(-2,15,-3,srparasites:parasiterubbledense:1)
Block(-2,15,-2,srparasites:parasiterubbledense:1)
Block(-2,15,-1,srparasites:parasiterubble:1)
Block(-2,16,-7,srparasites:parasitestain:2)
Block(-2,16,-6,srparasites:parasitestain:2)
Block(-2,16,-5,srparasites:parasitestain:2)
Block(-2,16,-4,srparasites:parasitestain:1)
Block(-2,16,-3,srparasites:parasitebush:0)
Block(-2,16,-1,srparasites:parasitestain:2)
Block(-2,17,-7,srparasites:parasitestain:2)
Block(-2,17,-6,srparasites:parasitestain:2)
Block(-2,17,-5,srparasites:parasitestain:2)
Block(-2,17,-4,srparasites:parasitebush:0)
Block(-2,17,-3,AIR:0)
Block(-2,17,-1,srparasites:parasitestain:2)
Block(-2,18,-7,srparasites:parasitestain:2)
Block(-2,18,-6,srparasites:parasitestain:2)
Block(-2,18,-5,srparasites:parasitestain:2)
Block(-2,18,-4,srparasites:parasitestain:1)
Block(-2,18,-3,srparasites:parasitestain:1)
Block(-2,18,-1,AIR:0)
Block(-2,19,-7,srparasites:parasitestain:2)
Block(-2,19,-6,srparasites:parasitestain:2)
Block(-2,19,-5,srparasites:parasiterubble:1)
Block(-2,19,-4,srparasites:parasitestain:1)
Block(-2,19,-3,srparasites:parasitestain:2)
Block(-2,19,-1,srparasites:parasitestain:2)
Block(-2,20,-7,srparasites:parasitestain:2)
Block(-2,20,-6,srparasites:parasitestain:2)
Block(-2,20,-5,srparasites:parasitestain:2)
Block(-2,20,-4,srparasites:parasitestain:2)
Block(-2,20,-3,srparasites:parasitestain:2)
Block(-2,20,-1,srparasites:parasitestain:2)
Block(-2,21,-7,srparasites:parasitestain:2)
Block(-2,21,-6,srparasites:parasitestain:2)
Block(-2,21,-5,srparasites:parasiterubble:1)
Block(-2,21,-4,srparasites:parasitestain:2)
Block(-2,21,-3,srparasites:parasitestain:1)
Block(-2,21,-1,srparasites:parasitestain:2)
Block(-2,22,-7,srparasites:parasitestain:2)
Block(-2,22,-6,srparasites:parasitestain:2)
Block(-2,22,-5,srparasites:parasitebush:0)
Block(-2,22,-4,srparasites:parasiterubble:1)
Block(-2,22,-3,srparasites:parasitestain:1)
Block(-2,22,-1,srparasites:parasitestain:1)
Block(-2,23,-7,srparasites:parasitestain:2)
Block(-2,23,-6,srparasites:parasitestain:2)
Block(-2,23,-5,srparasites:parasitestain:2)
Block(-2,23,-4,srparasites:parasitestain:1)
Block(-2,23,-3,srparasites:parasitestain:1)
Block(-2,23,-1,srparasites:parasitestain:2)
Block(-2,24,-7,srparasites:parasitestain:2)
Block(-2,24,-6,srparasites:parasitestain:2)
Block(-2,24,-5,srparasites:parasitestain:2)
Block(-2,24,-4,srparasites:parasiterubbledense:1)
Block(-2,24,-3,srparasites:parasiterubbledense:1)
Block(-2,24,-1,srparasites:parasiterubbledense:1)
Block(-2,24,2,srparasites:parasiterubbledense:1)
Block(-2,25,-7,srparasites:parasitestain:2)
Block(-2,25,-6,srparasites:parasitestain:2)
Block(-2,25,-5,srparasites:parasiterubbledense:1)
Block(-2,25,-4,srparasites:parasiterubbledense:1)
Block(-2,25,-3,srparasites:parasiterubbledense:1)
Block(-2,25,-2,srparasites:parasiterubbledense:1)
Block(-2,25,-1,srparasites:parasiterubbledense:1)
Block(-2,25,0,srparasites:parasiterubbledense:1)
Block(-2,25,1,srparasites:parasiterubbledense:1)
Block(-2,25,2,srparasites:parasiterubbledense:1)
Block(-2,25,3,srparasites:parasiterubbledense:1)
Block(-2,26,-7,srparasites:parasitestain:2)
Block(-2,26,-6,srparasites:parasitestain:2)
Block(-2,26,-5,srparasites:parasiterubbledense:1)
Block(-2,26,-4,srparasites:parasiterubbledense:1)
Block(-2,26,-3,srparasites:parasiterubbledense:1)
Block(-2,26,-2,srparasites:parasiterubbledense:1)
Block(-2,26,-1,srparasites:parasiterubbledense:1)
Block(-2,26,0,srparasites:parasiterubbledense:1)
Block(-2,26,2,srparasites:parasiterubbledense:1)
Block(-2,27,-7,srparasites:parasitestain:2)
Block(-2,27,-6,srparasites:parasiterubbledense:1)
Block(-2,27,-5,srparasites:parasiterubbledense:1)
Block(-2,27,-4,srparasites:parasiterubbledense:1)
Block(-2,27,-3,srparasites:parasiterubbledense:1)
Block(-2,27,-2,srparasites:parasiterubbledense:1)
Block(-2,27,-1,srparasites:parasiterubbledense:1)
Block(-2,27,0,srparasites:parasiterubbledense:1)
Block(-2,28,-7,srparasites:parasitestain:2)
Block(-2,28,-6,srparasites:parasiterubbledense:1)
Block(-2,28,-5,srparasites:parasiterubbledense:1)
Block(-2,28,-4,srparasites:parasiterubbledense:1)
Block(-2,28,-3,srparasites:parasiterubbledense:1)
Block(-2,28,-2,srparasites:parasiterubbledense:1)
Block(-2,28,-1,srparasites:parasiterubbledense:1)
Block(-2,29,-7,srparasites:parasitestain:2)
Block(-2,29,-6,srparasites:parasiterubbledense:1)
Block(-2,29,-5,srparasites:parasiterubbledense:1)
Block(-2,29,-4,srparasites:parasiterubbledense:1)
Block(-2,29,-3,srparasites:parasitestain:2)
Block(-2,29,-1,srparasites:parasiterubbledense:1)
Block(-2,30,-7,srparasites:parasitestain:2)
Block(-2,30,-6,srparasites:parasitestain:2)
Block(-2,30,-5,srparasites:parasitestain:2)
Block(-2,30,-4,srparasites:parasitestain:2)
Block(-2,30,-3,srparasites:parasitestain:2)
Block(-2,30,-1,srparasites:parasitestain:1)
Block(-2,31,-7,srparasites:parasitestain:2)
Block(-2,31,-6,srparasites:parasitestain:2)
Block(-2,31,-5,srparasites:parasitestain:2)
Block(-2,31,-4,srparasites:parasitestain:2)
Block(-2,31,-3,srparasites:parasitestain:2)
Block(-2,31,-1,srparasites:parasitestain:1)
Block(-2,32,-7,srparasites:parasitestain:2)
Block(-2,32,-6,srparasites:parasitestain:2)
Block(-2,32,-5,srparasites:parasitestain:2)
Block(-2,32,-4,srparasites:parasitestain:2)
Block(-2,32,-3,srparasites:parasitestain:2)
Block(-2,32,-1,AIR:0)
Block(-2,33,-7,srparasites:parasitestain:2)
Block(-2,33,-6,srparasites:parasitestain:2)
Block(-2,33,-5,srparasites:parasitestain:2)
Block(-2,33,-4,srparasites:parasitestain:2)
Block(-2,33,-3,srparasites:parasitestain:2)
Block(-2,33,-1,srparasites:parasitestain:2)
Block(-2,34,-7,srparasites:parasiterubble:1)
Block(-2,34,-6,srparasites:parasitestain:2)
Block(-2,34,-5,srparasites:parasitestain:2)
Block(-2,34,-4,srparasites:parasiterubbledense:1)
Block(-2,34,-3,srparasites:parasiterubbledense:1)
Block(-2,34,-1,srparasites:parasitestain:2)
Block(-2,35,-7,srparasites:parasiterubble:1)
Block(-2,35,-6,srparasites:parasitestain:2)
Block(-2,35,-5,srparasites:parasiterubbledense:1)
Block(-2,35,-4,srparasites:parasiterubbledense:1)
Block(-2,35,-3,srparasites:parasiterubbledense:1)
Block(-2,35,-1,srparasites:parasiterubbledense:1)
Block(-2,35,0,srparasites:parasiterubbledense:1)
Block(-2,35,1,srparasites:parasiterubbledense:1)
Block(-2,36,-7,srparasites:parasiterubble:1)
Block(-2,36,-6,srparasites:parasitestain:2)
Block(-2,36,-5,srparasites:parasiterubbledense:1)
Block(-2,36,-4,srparasites:parasiterubbledense:1)
Block(-2,36,-3,srparasites:parasiterubbledense:1)
Block(-2,36,-2,srparasites:parasiterubbledense:1)
Block(-2,36,-1,srparasites:parasiterubbledense:1)
Block(-2,36,0,srparasites:parasiterubbledense:1)
Block(-2,36,1,srparasites:parasiterubbledense:1)
Block(-2,37,-7,quark:marble_speleothem:2)
Block(-2,37,-6,srparasites:parasitestain:2)
Block(-2,37,-5,srparasites:parasiterubbledense:1)
Block(-2,37,-4,srparasites:parasiterubbledense:1)
Block(-2,37,-3,srparasites:parasiterubbledense:1)
Block(-2,37,-2,srparasites:parasiterubbledense:1)
Block(-2,37,-1,srparasites:parasiterubbledense:1)
Block(-2,37,0,srparasites:parasiterubbledense:1)
Block(-2,37,1,srparasites:parasiterubbledense:1)
Block(-2,38,-7,quark:marble_speleothem:1)
Block(-2,38,-6,srparasites:parasitestain:2)
Block(-2,38,-5,srparasites:parasitestain:2)
Block(-2,38,-4,srparasites:parasiterubbledense:1)
Block(-2,38,-3,srparasites:parasiterubbledense:1)
Block(-2,38,-2,srparasites:parasiterubbledense:1)
Block(-2,38,-1,srparasites:parasiterubbledense:1)
Block(-2,38,0,srparasites:parasiterubbledense:1)
Block(-2,38,1,srparasites:parasiterubbledense:1)
Block(-2,39,-7,quark:marble_speleothem:0)
Block(-2,39,-6,AIR:0)
Block(-2,39,-5,srparasites:parasitestain:2)
Block(-2,39,-4,srparasites:parasitestain:2)
Block(-2,39,-3,srparasites:parasitestain:2)
Block(-2,39,-1,srparasites:parasiterubbledense:1)
Block(-2,39,0,srparasites:parasiterubbledense:1)
Block(-2,40,-7,AIR:0)
Block(-2,40,-6,AIR:0)
Block(-2,40,-5,srparasites:parasitestain:2)
Block(-2,40,-4,srparasites:parasitestain:1)
Block(-2,40,-3,srparasites:parasitestain:2)
Block(-2,40,-1,srparasites:parasiterubbledense:1)
Block(-2,41,-7,AIR:0)
Block(-2,41,-6,AIR:0)
Block(-2,41,-5,srparasites:parasitestain:2)
Block(-2,41,-4,srparasites:parasitestain:1)
Block(-2,41,-3,srparasites:parasitestain:1)
Block(-2,41,-1,AIR:0)
Block(-2,42,-7,AIR:0)
Block(-2,42,-6,AIR:0)
Block(-2,42,-5,srparasites:parasitestain:2)
Block(-2,42,-4,srparasites:parasitestain:1)
Block(-2,42,-3,srparasites:parasitestain:2)
Block(-2,42,-1,srparasites:parasitestain:2)
Block(-2,43,-7,AIR:0)
Block(-2,43,-6,srparasites:parasitestain:2)
Block(-2,43,-5,srparasites:parasitestain:2)
Block(-2,43,-4,srparasites:parasitestain:1)
Block(-2,43,-3,srparasites:parasiterubble:1)
Block(-2,43,-1,srparasites:parasitestain:2)
Block(-2,44,-7,AIR:0)
Block(-2,44,-6,srparasites:parasitestain:2)
Block(-2,44,-5,srparasites:parasitestain:2)
Block(-2,44,-4,srparasites:parasitestain:1)
Block(-2,44,-3,AIR:0)
Block(-2,44,-1,srparasites:parasiterubble:1)
Block(-2,45,-7,AIR:0)
Block(-2,45,-6,srparasites:parasitestain:2)
Block(-2,45,-5,srparasites:parasiterubble:1)
Block(-2,45,-4,srparasites:parasitestain:2)
Block(-2,45,-3,srparasites:parasitestain:1)
Block(-2,45,-1,srparasites:parasitestain:1)
Block(-2,46,-7,AIR:0)
Block(-2,46,-6,srparasites:parasiterubble:1)
Block(-2,46,-5,srparasites:parasitestain:1)
Block(-2,46,-4,srparasites:parasitestain:2)
Block(-2,46,-3,srparasites:parasitestain:2)
Block(-2,46,-1,srparasites:parasiterubble:1)
Block(-2,47,-7,srparasites:parasitestain:2)
Block(-2,47,-6,srparasites:parasitestain:2)
Block(-2,47,-5,srparasites:parasitestain:1)
Block(-2,47,-4,srparasites:parasiterubble:1)
Block(-2,47,-3,srparasites:parasitestain:2)
Block(-2,47,-1,srparasites:parasitestain:2)
