
#######################################################################
# +-----------------------------------------------------------------+ #
# |                            BO3 object                           | #
# +-----------------------------------------------------------------+ #
#######################################################################

Author: NLBlackEagle

Description: No description given

Version: 3

SettingsMode: WriteDisable


#######################################################################
# +-----------------------------------------------------------------+ #
# |                          Main settings                          | #
# +-----------------------------------------------------------------+ #
#######################################################################

Tree: true

Frequency: 0

Rarity: 100.0

RotateRandomly: true

SpawnHeight: highestSolidBlock

SpawnHeightOffset: 0

SpawnHeightVariance: 0

##############################
# Height Limits for the BO3. #
##############################

MinHeight: 0

MaxHeight: 60

######################
# Extrusion settings #
######################

ExtrudeMode: None

ExtrudeThroughBlocks: AIR

MaxBranchDepth: 10

ExcludedBiomes: All


#######################################################################
# +-----------------------------------------------------------------+ #
# |                      Source block settings                      | #
# +-----------------------------------------------------------------+ #
#######################################################################

SourceBlocks: AIR

MaxPercentageOutsideSourceBlock: 0

OutsideSourceBlock: placeAnyway

DoReplaceBlocks: true

IsOTGPlus: false


#######################################################################
# +-----------------------------------------------------------------+ #
# |                              Blocks                             | #
# +-----------------------------------------------------------------+ #
#######################################################################

Block(-5,29,1,srparasites:parasitestain:3)
Block(-4,0,0,srparasites:parasitestain:2)
Block(-4,0,1,srparasites:parasitestain:2)
Block(-4,0,2,srparasites:parasitestain:2)
Block(-4,1,0,srparasites:parasitestain:2)
Block(-4,1,1,srparasites:parasitestain:2)
Block(-4,1,2,srparasites:parasitestain:2)
Block(-4,2,1,srparasites:parasitestain:2)
Block(-4,3,1,srparasites:parasitestain:2)
Block(-4,27,1,srparasites:parasitestain:3)
Block(-4,28,1,srparasites:parasitestain:3)
Block(-3,0,0,srparasites:parasitestain:2)
Block(-3,0,1,srparasites:parasitestain:2)
Block(-3,0,2,srparasites:parasitestain:2)
Block(-3,1,0,srparasites:parasitestain:2)
Block(-3,1,1,srparasites:parasitestain:2)
Block(-3,1,2,srparasites:parasitestain:2)
Block(-3,2,0,srparasites:parasitestain:2)
Block(-3,2,1,srparasites:parasitetrunk:2)
Block(-3,2,2,srparasites:parasitestain:2)
Block(-3,3,0,srparasites:parasitestain:2)
Block(-3,3,1,srparasites:parasitetrunk:2)
Block(-3,3,2,srparasites:parasitestain:2)
Block(-3,4,1,srparasites:parasitetrunk:2)
Block(-3,5,1,srparasites:parasitetrunk:2)
Block(-3,6,1,srparasites:parasitetrunk:2)
Block(-3,23,1,srparasites:parasitestain:3)
Block(-3,24,1,srparasites:parasitestain:3)
Block(-3,25,-1,srparasites:parasitestain:3)
Block(-3,25,1,srparasites:parasitestain:3)
Block(-3,25,3,srparasites:parasitestain:3)
Block(-3,26,-1,srparasites:parasitestain:3)
Block(-3,26,1,srparasites:parasitestain:3)
Block(-3,26,3,srparasites:parasitestain:3)
Block(-3,27,-1,srparasites:parasitestain:3)
Block(-3,27,3,srparasites:parasitestain:3)
Block(-2,0,0,srparasites:parasitestain:2)
Block(-2,0,1,srparasites:parasitestain:2)
Block(-2,0,2,srparasites:parasitestain:2)
Block(-2,1,0,srparasites:parasitestain:2)
Block(-2,1,1,srparasites:parasitestain:2)
Block(-2,1,2,srparasites:parasitestain:2)
Block(-2,2,1,srparasites:parasitestain:2)
Block(-2,2,2,srparasites:parasitebush:4)
Block(-2,3,1,srparasites:parasitestain:2)
Block(-2,7,1,srparasites:parasitetrunk:2)
Block(-2,8,1,srparasites:parasitetrunk:2)
Block(-2,9,1,srparasites:parasitetrunk:2)
Block(-2,10,1,srparasites:parasitetrunk:2)
Block(-2,11,1,srparasites:parasitetrunk:2)
Block(-2,22,1,srparasites:parasitestain:3)
Block(-2,23,0,srparasites:parasitestain:3)
Block(-2,23,1,srparasites:parasitestain:3)
Block(-2,23,2,srparasites:parasitestain:3)
Block(-2,24,0,srparasites:parasitestain:3)
Block(-2,24,1,srparasites:parasitestain:3)
Block(-2,24,2,srparasites:parasitestain:3)
Block(-1,12,1,srparasites:parasitetrunk:2)
Block(-1,13,1,srparasites:parasitetrunk:2)
Block(-1,14,1,srparasites:parasitetrunk:2)
Block(-1,15,1,srparasites:parasitetrunk:2)
Block(-1,16,1,srparasites:parasitetrunk:2)
Block(-1,17,1,srparasites:parasitetrunk:2)
Block(-1,18,1,srparasites:parasitetrunk:2)
Block(-1,19,1,srparasites:parasitetrunk:2)
Block(-1,20,1,srparasites:parasitetrunk:2)
Block(-1,21,1,srparasites:parasitetrunk:2)
Block(-1,22,0,srparasites:parasitestain:3)
Block(-1,22,1,srparasites:parasitestain:3)
Block(-1,22,2,srparasites:parasitestain:3)
Block(-1,23,-1,srparasites:parasitestain:3)
Block(-1,23,0,srparasites:parasitestain:3)
Block(-1,23,1,srparasites:parasitestain:3)
Block(-1,23,2,srparasites:parasitestain:3)
Block(-1,23,3,srparasites:parasitestain:3)
Block(-1,24,-1,srparasites:parasitestain:3)
Block(-1,24,0,srparasites:parasitestain:3)
Block(-1,24,1,srparasites:parasitestain:3)
Block(-1,24,2,srparasites:parasitestain:3)
Block(-1,24,3,srparasites:parasitestain:3)
Block(-1,25,-1,srparasites:parasitestain:3)
Block(-1,25,1,srparasites:parasitestain:3)
Block(-1,25,3,srparasites:parasitestain:3)
Block(-1,26,-1,srparasites:parasitestain:3)
Block(-1,26,3,srparasites:parasitestain:3)
Block(-1,27,-2,srparasites:parasitestain:3)
Block(-1,27,4,srparasites:parasitestain:3)
Block(-1,28,-2,srparasites:parasitestain:3)
Block(-1,28,4,srparasites:parasitestain:3)
Block(-1,29,-3,srparasites:parasitestain:3)
Block(-1,29,5,srparasites:parasitestain:3)
Block(0,22,1,srparasites:parasitestain:3)
Block(0,23,0,srparasites:parasitestain:3)
Block(0,23,1,srparasites:parasitestain:3)
Block(0,23,2,srparasites:parasitestain:3)
Block(0,24,0,srparasites:parasitestain:3)
Block(0,24,1,srparasites:parasitestain:3)
Block(0,24,2,srparasites:parasitestain:3)
Block(1,23,1,srparasites:parasitestain:3)
Block(1,24,1,srparasites:parasitestain:3)
Block(1,25,-1,srparasites:parasitestain:3)
Block(1,25,1,srparasites:parasitestain:3)
Block(1,25,3,srparasites:parasitestain:3)
Block(1,26,-1,srparasites:parasitestain:3)
Block(1,26,1,srparasites:parasitestain:3)
Block(1,26,3,srparasites:parasitestain:3)
Block(1,27,-1,srparasites:parasitestain:3)
Block(1,27,3,srparasites:parasitestain:3)
Block(2,27,1,srparasites:parasitestain:3)
Block(2,28,1,srparasites:parasitestain:3)
Block(3,29,1,srparasites:parasitestain:3)

#######################################################################
# +-----------------------------------------------------------------+ #
# |                            BO3 checks                           | #
# +-----------------------------------------------------------------+ #
#######################################################################

BlockCheck(0,-1,0,Solid)

#######################################################################
# +-----------------------------------------------------------------+ #
# |                             Branches                            | #
# +-----------------------------------------------------------------+ #
#######################################################################


#######################################################################
# +-----------------------------------------------------------------+ #
# |                             Entities                            | #
# +-----------------------------------------------------------------+ #
#######################################################################


#######################################################################
# +-----------------------------------------------------------------+ #
# |                            Particles                            | #
# +-----------------------------------------------------------------+ #
#######################################################################


#######################################################################
# +-----------------------------------------------------------------+ #
# |                             Spawners                            | #
# +-----------------------------------------------------------------+ #
#######################################################################


#######################################################################
# +-----------------------------------------------------------------+ #
# |                             ModData                             | #
# +-----------------------------------------------------------------+ #
#######################################################################

