
#######################################################################
# +-----------------------------------------------------------------+ #
# |                            BO3 object                           | #
# +-----------------------------------------------------------------+ #
#######################################################################

Author: NLBlackEagle

Description: No description given

Version: 3

SettingsMode: WriteDisable


#######################################################################
# +-----------------------------------------------------------------+ #
# |                          Main settings                          | #
# +-----------------------------------------------------------------+ #
#######################################################################

Tree: true

Frequency: 0

Rarity: 100.0

RotateRandomly: true

SpawnHeight: highestSolidBlock

SpawnHeightOffset: 0

SpawnHeightVariance: 0

##############################
# Height Limits for the BO3. #
##############################

MinHeight: 0

MaxHeight: 60

######################
# Extrusion settings #
######################

ExtrudeMode: None

ExtrudeThroughBlocks: AIR

MaxBranchDepth: 10

ExcludedBiomes: All


#######################################################################
# +-----------------------------------------------------------------+ #
# |                      Source block settings                      | #
# +-----------------------------------------------------------------+ #
#######################################################################

SourceBlocks: AIR

MaxPercentageOutsideSourceBlock: 0

OutsideSourceBlock: placeAnyway

DoReplaceBlocks: true

IsOTGPlus: false


#######################################################################
# +-----------------------------------------------------------------+ #
# |                              Blocks                             | #
# +-----------------------------------------------------------------+ #
#######################################################################

Block(-4,0,-3,srparasites:parasitestain)
Block(-4,3,1,srparasites:parasiterubble_slabhalf)
Block(-3,3,1,srparasites:parasiterubble_bonestairs:4)
Block(-3,6,0,srparasites:parasiterubble_bonestairs:4)
Block(-3,8,-1,srparasites:parasiterubble_slabhalf)
Block(-3,10,-1,srparasites:parasiterubble_slabhalf)
Block(-3,13,-2,srparasites:parasiterubble_slabhalf)
Block(-3,15,-2,srparasites:parasiterubble_slabhalf)
Block(-2,0,1,srparasites:parasiterubble_bonestairs:0)
Block(-2,2,1,srparasites:parasiterubble_bonestairs:4)
Block(-2,3,1,srparasites:parasiterubble_bonestairs:1)
Block(-2,5,0,srparasites:parasiterubble_bonestairs:4)
Block(-2,6,0,srparasites:parasiterubble_bonestairs:1)
Block(-2,8,-1,srparasites:parasiterubble_bonestairs:4)
Block(-2,10,-1,srparasites:parasiterubble_bonestairs:4)
Block(-2,13,-2,srparasites:parasiterubble_bonestairs:4)
Block(-2,15,-2,srparasites:parasiterubble_bonestairs:4)
Block(-2,17,-2,srparasites:parasiterubble_bonestairs:4)
Block(-2,19,-2,srparasites:parasiterubble_bonestairs:4)
Block(-2,21,-2,srparasites:parasiterubble_bonestairs:4)
Block(-2,24,-3,srparasites:parasiterubble_bonestairs:4)
Block(-2,26,-3,srparasites:parasiterubble_bonestairs:4)
Block(-2,28,-3,srparasites:parasiterubble_bonestairs:4)
Block(-2,30,-3,srparasites:parasiterubble_bonestairs:4)
Block(-2,32,-3,srparasites:parasiterubble_bonestairs:4)
Block(-1,0,0,srparasites:parasiterubble)
Block(-1,0,1,srparasites:parasiterubble)
Block(-1,0,2,srparasites:parasiterubble_bonestairs)
Block(-1,1,0,srparasites:parasiterubble)
Block(-1,1,1,srparasites:parasiterubble)
Block(-1,2,0,srparasites:parasiterubble)
Block(-1,2,1,srparasites:parasiterubble)
Block(-1,3,0,srparasites:parasiterubble)
Block(-1,3,1,srparasites:parasiterubble)
Block(-1,4,0,srparasites:parasiterubble)
Block(-1,4,1,srparasites:parasiterubble_bonestairs)
Block(-1,5,0,srparasites:parasiterubble)
Block(-1,6,0,srparasites:parasiterubble)
Block(-1,7,-1,srparasites:parasiterubble_bonestairs:6)
Block(-1,7,0,srparasites:parasiterubble_bonestairs)
Block(-1,8,-1,srparasites:parasiterubble)
Block(-1,9,-1,srparasites:parasiterubble)
Block(-1,10,-1,srparasites:parasiterubble)
Block(-1,11,-1,srparasites:parasiterubble)
Block(-1,12,-2,srparasites:parasiterubble_bonestairs:6)
Block(-1,12,-1,srparasites:parasiterubble_bonestairs)
Block(-1,13,-2,srparasites:parasiterubble)
Block(-1,14,-2,srparasites:parasiterubble)
Block(-1,15,-2,srparasites:parasiterubble)
Block(-1,16,-2,srparasites:parasiterubble)
Block(-1,17,-2,srparasites:parasiterubble)
Block(-1,18,-2,srparasites:parasiterubble)
Block(-1,19,-2,srparasites:parasiterubble)
Block(-1,20,-2,srparasites:parasiterubble)
Block(-1,21,-2,srparasites:parasiterubble)
Block(-1,22,-2,srparasites:parasiterubble)
Block(-1,23,-3,srparasites:parasiterubble_bonestairs:6)
Block(-1,23,-2,srparasites:parasiterubble_bonestairs)
Block(-1,24,-3,srparasites:parasiterubble)
Block(-1,25,-3,srparasites:parasiterubble)
Block(-1,26,-3,srparasites:parasiterubble)
Block(-1,27,-3,srparasites:parasiterubble)
Block(-1,28,-3,srparasites:parasiterubble)
Block(-1,29,-3,srparasites:parasiterubble)
Block(-1,30,-3,srparasites:parasiterubble)
Block(-1,31,-3,srparasites:parasiterubble)
Block(-1,32,-3,srparasites:parasiterubble)
Block(-1,33,-3,srparasites:parasiterubble)
Block(-1,34,-3,srparasites:parasiterubble_bonestairs)
Block(0,0,0,srparasites:parasiterubble)
Block(0,0,1,srparasites:parasiterubble)
Block(0,0,2,srparasites:parasiterubble_bonestairs)
Block(0,1,0,srparasites:parasiterubble)
Block(0,1,1,srparasites:parasiterubble)
Block(0,2,0,srparasites:parasiterubble)
Block(0,2,1,srparasites:parasiterubble)
Block(0,3,0,srparasites:parasiterubble)
Block(0,3,1,srparasites:parasiterubble)
Block(0,4,0,srparasites:parasiterubble)
Block(0,4,1,srparasites:parasiterubble_bonestairs)
Block(0,5,0,srparasites:parasiterubble)
Block(0,6,0,srparasites:parasiterubble)
Block(0,7,-1,srparasites:parasiterubble_bonestairs:6)
Block(0,7,0,srparasites:parasiterubble_bonestairs)
Block(0,8,-1,srparasites:parasiterubble)
Block(0,9,-1,srparasites:parasiterubble)
Block(0,10,-1,srparasites:parasiterubble)
Block(0,11,-1,srparasites:parasiterubble)
Block(0,12,-2,srparasites:parasiterubble_bonestairs:6)
Block(0,12,-1,srparasites:parasiterubble_bonestairs)
Block(0,13,-2,srparasites:parasiterubble)
Block(0,14,-2,srparasites:parasiterubble)
Block(0,15,-2,srparasites:parasiterubble)
Block(0,16,-2,srparasites:parasiterubble)
Block(0,17,-2,srparasites:parasiterubble)
Block(0,18,-2,srparasites:parasiterubble)
Block(0,19,-2,srparasites:parasiterubble)
Block(0,20,-2,srparasites:parasiterubble)
Block(0,21,-2,srparasites:parasiterubble)
Block(0,22,-2,srparasites:parasiterubble)
Block(0,23,-3,srparasites:parasiterubble_bonestairs:6)
Block(0,23,-2,srparasites:parasiterubble_bonestairs)
Block(0,24,-3,srparasites:parasiterubble)
Block(0,25,-3,srparasites:parasiterubble)
Block(0,26,-3,srparasites:parasiterubble)
Block(0,27,-3,srparasites:parasiterubble)
Block(0,28,-3,srparasites:parasiterubble)
Block(0,29,-3,srparasites:parasiterubble)
Block(0,30,-3,srparasites:parasiterubble)
Block(0,31,-3,srparasites:parasiterubble)
Block(0,32,-3,srparasites:parasiterubble)
Block(0,33,-3,srparasites:parasiterubble)
Block(0,34,-3,srparasites:parasiterubble_bonestairs)
Block(1,0,1,srparasites:parasiterubble_bonestairs:1)
Block(1,2,1,srparasites:parasiterubble_bonestairs:5)
Block(1,3,1,srparasites:parasiterubble_bonestairs:0)
Block(1,5,0,srparasites:parasiterubble_bonestairs:5)
Block(1,6,0,srparasites:parasiterubble_bonestairs:0)
Block(1,8,-1,srparasites:parasiterubble_bonestairs:5)
Block(1,10,-1,srparasites:parasiterubble_bonestairs:5)
Block(1,13,-2,srparasites:parasiterubble_bonestairs:5)
Block(1,15,-2,srparasites:parasiterubble_bonestairs:5)
Block(1,17,-2,srparasites:parasiterubble_bonestairs:5)
Block(1,19,-2,srparasites:parasiterubble_bonestairs:5)
Block(1,21,-2,srparasites:parasiterubble_bonestairs:5)
Block(1,24,-3,srparasites:parasiterubble_bonestairs:5)
Block(1,26,-3,srparasites:parasiterubble_bonestairs:5)
Block(1,28,-3,srparasites:parasiterubble_bonestairs:5)
Block(1,30,-3,srparasites:parasiterubble_bonestairs:5)
Block(1,32,-3,srparasites:parasiterubble_bonestairs:5)
Block(2,3,1,srparasites:parasiterubble_bonestairs:5)
Block(2,6,0,srparasites:parasiterubble_bonestairs:5)
Block(2,8,-1,srparasites:parasiterubble_slabhalf)
Block(2,10,-1,srparasites:parasiterubble_slabhalf)
Block(2,13,-2,srparasites:parasiterubble_slabhalf)
Block(2,15,-2,srparasites:parasiterubble_slabhalf)
Block(3,3,1,srparasites:parasiterubble_slabhalf)

#######################################################################
# +-----------------------------------------------------------------+ #
# |                            BO3 checks                           | #
# +-----------------------------------------------------------------+ #
#######################################################################

BlockCheck(0,-1,0,Solid)

#######################################################################
# +-----------------------------------------------------------------+ #
# |                             Branches                            | #
# +-----------------------------------------------------------------+ #
#######################################################################


#######################################################################
# +-----------------------------------------------------------------+ #
# |                             Entities                            | #
# +-----------------------------------------------------------------+ #
#######################################################################


#######################################################################
# +-----------------------------------------------------------------+ #
# |                            Particles                            | #
# +-----------------------------------------------------------------+ #
#######################################################################


#######################################################################
# +-----------------------------------------------------------------+ #
# |                             Spawners                            | #
# +-----------------------------------------------------------------+ #
#######################################################################


#######################################################################
# +-----------------------------------------------------------------+ #
# |                             ModData                             | #
# +-----------------------------------------------------------------+ #
#######################################################################

