
#######################################################################
# +-----------------------------------------------------------------+ #
# |                            BO3 object                           | #
# +-----------------------------------------------------------------+ #
#######################################################################

Author: NLBlackEagle

Description: No description given

Version: 3

SettingsMode: WriteDisable


#######################################################################
# +-----------------------------------------------------------------+ #
# |                          Main settings                          | #
# +-----------------------------------------------------------------+ #
#######################################################################

Tree: true

Frequency: 0

Rarity: 100.0

RotateRandomly: true

SpawnHeight: highestSolidBlock

SpawnHeightOffset: 0

SpawnHeightVariance: 0

##############################
# Height Limits for the BO3. #
##############################

MinHeight: 0

MaxHeight: 60

######################
# Extrusion settings #
######################

ExtrudeMode: None

ExtrudeThroughBlocks: AIR

MaxBranchDepth: 10

ExcludedBiomes: All


#######################################################################
# +-----------------------------------------------------------------+ #
# |                      Source block settings                      | #
# +-----------------------------------------------------------------+ #
#######################################################################

SourceBlocks: AIR

MaxPercentageOutsideSourceBlock: 0

OutsideSourceBlock: placeAnyway

DoReplaceBlocks: true

IsOTGPlus: false


#######################################################################
# +-----------------------------------------------------------------+ #
# |                              Blocks                             | #
# +-----------------------------------------------------------------+ #
#######################################################################

Block(-3,0,0,srparasites:parasiterubble_bonestairs:0)
Block(-3,0,1,srparasites:parasiterubble_bonestairs:0)
Block(-2,0,-1,srparasites:parasiterubble_bonestairs:2)
Block(-2,0,0,srparasites:parasiterubble)
Block(-2,0,1,srparasites:parasiterubble)
Block(-2,0,2,srparasites:parasiterubble_bonestairs)
Block(-2,1,0,srparasites:parasiterubble)
Block(-2,1,1,srparasites:parasiterubble)
Block(-2,2,-1,srparasites:parasiterubble_bonestairs:6)
Block(-2,2,0,srparasites:parasiterubble)
Block(-2,2,1,srparasites:parasiterubble)
Block(-2,2,2,srparasites:parasiterubble_bonestairs:7)
Block(-2,3,-3,srparasites:parasiterubble_slabhalf)
Block(-2,3,-2,srparasites:parasiterubble_bonestairs:6)
Block(-2,3,-1,srparasites:parasiterubble_bonestairs)
Block(-2,3,0,srparasites:parasiterubble)
Block(-2,3,1,srparasites:parasiterubble)
Block(-2,3,2,srparasites:parasiterubble_bonestairs:2)
Block(-2,3,3,srparasites:parasiterubble_bonestairs:7)
Block(-2,3,4,srparasites:parasiterubble_slabhalf)
Block(-2,4,0,srparasites:parasiterubble_bonestairs:0)
Block(-2,4,1,srparasites:parasiterubble_bonestairs:0)
Block(-1,0,0,srparasites:parasiterubble)
Block(-1,0,1,srparasites:parasiterubble)
Block(-1,1,0,srparasites:parasiterubble)
Block(-1,1,1,srparasites:parasiterubble)
Block(-1,2,0,srparasites:parasiterubble)
Block(-1,2,1,srparasites:parasiterubble)
Block(-1,3,0,srparasites:parasiterubble)
Block(-1,3,1,srparasites:parasiterubble)
Block(-1,4,0,srparasites:parasiterubble)
Block(-1,4,1,srparasites:parasiterubble)
Block(-1,5,-1,srparasites:parasiterubble_bonestairs:6)
Block(-1,5,0,srparasites:parasiterubble)
Block(-1,5,1,srparasites:parasiterubble)
Block(-1,5,2,srparasites:parasiterubble_bonestairs:7)
Block(-1,6,-2,srparasites:parasiterubble_bonestairs:6)
Block(-1,6,-1,srparasites:parasiterubble_bonestairs)
Block(-1,6,0,srparasites:parasiterubble)
Block(-1,6,1,srparasites:parasiterubble)
Block(-1,6,2,srparasites:parasiterubble_bonestairs:2)
Block(-1,6,3,srparasites:parasiterubble_bonestairs:7)
Block(-1,7,0,srparasites:parasiterubble_bonestairs:0)
Block(-1,7,1,srparasites:parasiterubble_bonestairs:0)
Block(0,7,0,srparasites:parasiterubble_bonestairs:5)
Block(0,7,1,srparasites:parasiterubble_bonestairs:5)
Block(0,8,-2,srparasites:parasiterubble_slabhalf)
Block(0,8,-1,srparasites:parasiterubble_bonestairs:6)
Block(0,8,0,srparasites:parasiterubble)
Block(0,8,1,srparasites:parasiterubble)
Block(0,8,2,srparasites:parasiterubble_bonestairs:7)
Block(0,8,3,srparasites:parasiterubble_slabhalf)
Block(0,9,0,srparasites:parasiterubble)
Block(0,9,1,srparasites:parasiterubble)
Block(0,10,-2,srparasites:parasiterubble_slabhalf)
Block(0,10,-1,srparasites:parasiterubble_bonestairs:6)
Block(0,10,0,srparasites:parasiterubble)
Block(0,10,1,srparasites:parasiterubble)
Block(0,10,2,srparasites:parasiterubble_bonestairs:7)
Block(0,10,3,srparasites:parasiterubble_slabhalf)
Block(0,11,0,srparasites:parasiterubble)
Block(0,11,1,srparasites:parasiterubble)
Block(0,12,-2,srparasites:parasiterubble_slabhalf)
Block(0,12,-1,srparasites:parasiterubble_bonestairs:6)
Block(0,12,0,srparasites:parasiterubble)
Block(0,12,1,srparasites:parasiterubble)
Block(0,12,2,srparasites:parasiterubble_bonestairs:7)
Block(0,12,3,srparasites:parasiterubble_slabhalf)
Block(0,13,0,srparasites:parasiterubble)
Block(0,13,1,srparasites:parasiterubble)
Block(0,14,0,srparasites:parasiterubble_bonestairs:0)
Block(0,14,1,srparasites:parasiterubble_bonestairs:0)
Block(1,14,0,srparasites:parasiterubble_bonestairs:5)
Block(1,14,1,srparasites:parasiterubble_bonestairs:5)
Block(1,15,-2,srparasites:parasiterubble_slabhalf)
Block(1,15,-1,srparasites:parasiterubble_bonestairs:6)
Block(1,15,0,srparasites:parasiterubble)
Block(1,15,1,srparasites:parasiterubble)
Block(1,15,2,srparasites:parasiterubble_bonestairs:7)
Block(1,15,3,srparasites:parasiterubble_slabhalf)
Block(1,16,0,srparasites:parasiterubble)
Block(1,16,1,srparasites:parasiterubble)
Block(1,17,-2,srparasites:parasiterubble_slabhalf)
Block(1,17,-1,srparasites:parasiterubble_bonestairs:6)
Block(1,17,0,srparasites:parasiterubble)
Block(1,17,1,srparasites:parasiterubble)
Block(1,17,2,srparasites:parasiterubble_bonestairs:7)
Block(1,17,3,srparasites:parasiterubble_slabhalf)
Block(1,18,0,srparasites:parasiterubble)
Block(1,18,1,srparasites:parasiterubble)
Block(1,19,-1,srparasites:parasiterubble_bonestairs:6)
Block(1,19,0,srparasites:parasiterubble)
Block(1,19,1,srparasites:parasiterubble)
Block(1,19,2,srparasites:parasiterubble_bonestairs:7)
Block(1,20,0,srparasites:parasiterubble)
Block(1,20,1,srparasites:parasiterubble)
Block(1,21,-1,srparasites:parasiterubble_bonestairs:6)
Block(1,21,0,srparasites:parasiterubble)
Block(1,21,1,srparasites:parasiterubble)
Block(1,21,2,srparasites:parasiterubble_bonestairs:7)
Block(1,22,0,srparasites:parasiterubble)
Block(1,22,1,srparasites:parasiterubble)
Block(1,23,-1,srparasites:parasiterubble_bonestairs:6)
Block(1,23,0,srparasites:parasiterubble)
Block(1,23,1,srparasites:parasiterubble)
Block(1,23,2,srparasites:parasiterubble_bonestairs:7)
Block(1,24,0,srparasites:parasiterubble)
Block(1,24,1,srparasites:parasiterubble)
Block(1,25,0,srparasites:parasiterubble_bonestairs:0)
Block(1,25,1,srparasites:parasiterubble_bonestairs:0)
Block(2,25,0,srparasites:parasiterubble_bonestairs:5)
Block(2,25,1,srparasites:parasiterubble_bonestairs:5)
Block(2,26,-1,srparasites:parasiterubble_bonestairs:6)
Block(2,26,0,srparasites:parasiterubble)
Block(2,26,1,srparasites:parasiterubble)
Block(2,26,2,srparasites:parasiterubble_bonestairs:7)
Block(2,27,0,srparasites:parasiterubble)
Block(2,27,1,srparasites:parasiterubble)
Block(2,28,-1,srparasites:parasiterubble_bonestairs:6)
Block(2,28,0,srparasites:parasiterubble)
Block(2,28,1,srparasites:parasiterubble)
Block(2,28,2,srparasites:parasiterubble_bonestairs:7)
Block(2,29,0,srparasites:parasiterubble)
Block(2,29,1,srparasites:parasiterubble)
Block(2,30,-1,srparasites:parasiterubble_bonestairs:6)
Block(2,30,0,srparasites:parasiterubble)
Block(2,30,1,srparasites:parasiterubble)
Block(2,30,2,srparasites:parasiterubble_bonestairs:7)
Block(2,31,0,srparasites:parasiterubble)
Block(2,31,1,srparasites:parasiterubble)
Block(2,32,-1,srparasites:parasiterubble_bonestairs:6)
Block(2,32,0,srparasites:parasiterubble)
Block(2,32,1,srparasites:parasiterubble)
Block(2,32,2,srparasites:parasiterubble_bonestairs:7)
Block(2,33,0,srparasites:parasiterubble_bonestairs:0)
Block(2,33,1,srparasites:parasiterubble_bonestairs:0)

#######################################################################
# +-----------------------------------------------------------------+ #
# |                            BO3 checks                           | #
# +-----------------------------------------------------------------+ #
#######################################################################

BlockCheck(0,-1,0,Solid)

#######################################################################
# +-----------------------------------------------------------------+ #
# |                             Branches                            | #
# +-----------------------------------------------------------------+ #
#######################################################################


#######################################################################
# +-----------------------------------------------------------------+ #
# |                             Entities                            | #
# +-----------------------------------------------------------------+ #
#######################################################################


#######################################################################
# +-----------------------------------------------------------------+ #
# |                            Particles                            | #
# +-----------------------------------------------------------------+ #
#######################################################################


#######################################################################
# +-----------------------------------------------------------------+ #
# |                             Spawners                            | #
# +-----------------------------------------------------------------+ #
#######################################################################


#######################################################################
# +-----------------------------------------------------------------+ #
# |                             ModData                             | #
# +-----------------------------------------------------------------+ #
#######################################################################

