
#######################################################################
# +-----------------------------------------------------------------+ #
# |                            BO3 object                           | #
# +-----------------------------------------------------------------+ #
#######################################################################

Author: NLBlackHeavenNL

Description: No description given

Version: 3

SettingsMode: WriteWithoutComments


#######################################################################
# +-----------------------------------------------------------------+ #
# |                          Main settings                          | #
# +-----------------------------------------------------------------+ #
#######################################################################

Tree: true

Frequency: 1

Rarity: 100.0

RotateRandomly: false

SpawnHeight: highestSolidBlock

SpawnHeightOffset: -1

SpawnHeightVariance: 0

##############################
# Height Limits for the BO3. #
##############################

MinHeight: 0

MaxHeight: 255

######################
# Extrusion settings #
######################

ExtrudeMode: None

ExtrudeThroughBlocks: AIR

MaxBranchDepth: 10

ExcludedBiomes: All


#######################################################################
# +-----------------------------------------------------------------+ #
# |                      Source block settings                      | #
# +-----------------------------------------------------------------+ #
#######################################################################

SourceBlocks: AIR,GRASS,DIRT,biomesoplenty:dirt

MaxPercentageOutsideSourceBlock: 0

OutsideSourceBlock: placeAnyway

DoReplaceBlocks: true

IsOTGPlus: false


#######################################################################
# +-----------------------------------------------------------------+ #
# |                              Blocks                             | #
# +-----------------------------------------------------------------+ #
#######################################################################

Block(-4,32,-2,dynamictrees:leaves0:12)
Block(-4,32,-1,dynamictrees:leaves0:12)
Block(-4,32,0,dynamictrees:leaves0:12)
Block(-4,32,1,dynamictrees:leaves0:12)
Block(-4,32,2,dynamictrees:leaves0:12)
Block(-4,33,-1,dynamictrees:leaves0:12)
Block(-4,33,0,dynamictrees:leaves0:12)
Block(-4,33,1,dynamictrees:leaves0:12)
Block(-4,33,2,dynamictrees:leaves0:12)
Block(-4,33,3,dynamictrees:leaves0:12)
Block(-4,34,0,dynamictrees:leaves0:12)
Block(-4,34,1,dynamictrees:leaves0:12)
Block(-4,34,2,dynamictrees:leaves0:12)
Block(-4,35,1,dynamictrees:leaves0:12)
Block(-3,31,-2,dynamictrees:leaves0:12)
Block(-3,31,-1,dynamictrees:leaves0:12)
Block(-3,32,-3,dynamictrees:leaves0:12)
Block(-3,32,-2,dynamictrees:leaves0:13)
Block(-3,32,-1,dynamictrees:leaves0:14)
Block(-3,32,0,dynamictrees:leaves0:15)
Block(-3,32,2,dynamictrees:leaves0:12)
Block(-3,32,3,dynamictrees:leaves0:12)
Block(-3,32,4,dynamictrees:leaves0:12)
Block(-3,33,-2,dynamictrees:leaves0:12)
Block(-3,33,-1,dynamictrees:leaves0:13)
Block(-3,33,0,dynamictrees:leaves0:14)
Block(-3,33,1,dynamictrees:leaves0:15)
Block(-3,33,2,dynamictrees:leaves0:14)
Block(-3,33,3,dynamictrees:leaves0:13)
Block(-3,33,4,dynamictrees:leaves0:12)
Block(-3,34,-1,dynamictrees:leaves0:12)
Block(-3,34,0,dynamictrees:leaves0:13)
Block(-3,34,1,dynamictrees:leaves0:14)
Block(-3,34,2,dynamictrees:leaves0:13)
Block(-3,34,3,dynamictrees:leaves0:12)
Block(-3,35,0,dynamictrees:leaves0:12)
Block(-3,35,1,dynamictrees:leaves0:13)
Block(-3,35,2,dynamictrees:leaves0:12)
Block(-3,36,1,dynamictrees:leaves0:12)
Block(-2,0,-2,dynamictrees:jungleroot:0)
Block(-2,31,-2,dynamictrees:leaves0:12)
Block(-2,31,4,dynamictrees:leaves0:12)
Block(-2,32,-3,dynamictrees:leaves0:12)
Block(-2,32,-2,dynamictrees:leaves0:14)
Block(-2,32,-1,dynamictrees:leaves0:15)
Block(-2,32,0,dynamictrees:junglebranch:0)
Block(-2,32,1,dynamictrees:junglebranch:1)
Block(-2,32,3,dynamictrees:leaves0:15)
Block(-2,32,4,dynamictrees:leaves0:14)
Block(-2,32,5,dynamictrees:leaves0:12)
Block(-2,33,-3,dynamictrees:leaves0:12)
Block(-2,33,-2,dynamictrees:leaves0:13)
Block(-2,33,-1,dynamictrees:leaves0:14)
Block(-2,33,0,dynamictrees:leaves0:15)
Block(-2,33,1,dynamictrees:junglebranch:0)
Block(-2,33,2,dynamictrees:leaves0:15)
Block(-2,33,3,dynamictrees:leaves0:14)
Block(-2,33,4,dynamictrees:leaves0:13)
Block(-2,33,5,dynamictrees:leaves0:12)
Block(-2,34,-2,dynamictrees:leaves0:12)
Block(-2,34,-1,dynamictrees:leaves0:13)
Block(-2,34,0,dynamictrees:leaves0:14)
Block(-2,34,1,dynamictrees:leaves0:15)
Block(-2,34,2,dynamictrees:leaves0:14)
Block(-2,34,3,dynamictrees:leaves0:13)
Block(-2,34,4,dynamictrees:leaves0:12)
Block(-2,35,-1,dynamictrees:leaves0:12)
Block(-2,35,0,dynamictrees:leaves0:13)
Block(-2,35,1,dynamictrees:leaves0:14)
Block(-2,35,2,dynamictrees:leaves0:13)
Block(-2,35,3,dynamictrees:leaves0:12)
Block(-2,36,0,dynamictrees:leaves0:12)
Block(-2,36,1,dynamictrees:leaves0:12)
Block(-2,36,2,dynamictrees:leaves0:12)
Block(-1,0,-2,dynamictrees:jungleroot:1)
Block(-1,0,-1,dynamictrees:jungleroot:2)
Block(-1,0,0,GRASS:0)
Block(-1,0,1,GRASS:0)
Block(-1,0,2,GRASS:0)
Block(-1,1,0,dynamictrees:jungleroot:3)
Block(-1,1,1,dynamictrees:trunkshell:6)
Block(-1,1,2,dynamictrees:trunkshell:7)
Block(-1,2,0,dynamictrees:trunkshell:5)
Block(-1,2,1,dynamictrees:trunkshell:6)
Block(-1,2,2,dynamictrees:trunkshell:7)
Block(-1,3,0,dynamictrees:trunkshell:5)
Block(-1,3,1,dynamictrees:trunkshell:6)
Block(-1,3,2,dynamictrees:trunkshell:7)
Block(-1,4,0,dynamictrees:trunkshell:5)
Block(-1,4,1,dynamictrees:trunkshell:6)
Block(-1,4,2,dynamictrees:trunkshell:7)
Block(-1,5,0,dynamictrees:trunkshell:5)
Block(-1,5,1,dynamictrees:trunkshell:6)
Block(-1,5,2,dynamictrees:trunkshell:7)
Block(-1,6,0,dynamictrees:trunkshell:5)
Block(-1,6,1,dynamictrees:trunkshell:6)
Block(-1,6,2,dynamictrees:trunkshell:7)
Block(-1,7,0,dynamictrees:trunkshell:5)
Block(-1,7,1,dynamictrees:trunkshell:6)
Block(-1,7,2,dynamictrees:trunkshell:7)
Block(-1,8,0,dynamictrees:trunkshell:5)
Block(-1,8,1,dynamictrees:trunkshell:6)
Block(-1,8,2,dynamictrees:trunkshell:7)
Block(-1,9,0,dynamictrees:trunkshell:5)
Block(-1,9,1,dynamictrees:trunkshell:6)
Block(-1,9,2,dynamictrees:trunkshell:7)
Block(-1,10,0,dynamictrees:trunkshell:5)
Block(-1,10,1,dynamictrees:trunkshell:6)
Block(-1,10,2,dynamictrees:trunkshell:7)
Block(-1,11,0,dynamictrees:trunkshell:5)
Block(-1,11,1,dynamictrees:trunkshell:6)
Block(-1,11,2,dynamictrees:trunkshell:7)
Block(-1,12,0,dynamictrees:trunkshell:5)
Block(-1,12,1,dynamictrees:trunkshell:6)
Block(-1,12,2,dynamictrees:trunkshell:7)
Block(-1,13,0,dynamictrees:trunkshell:5)
Block(-1,13,1,dynamictrees:trunkshell:6)
Block(-1,13,2,dynamictrees:trunkshell:7)
Block(-1,14,0,dynamictrees:trunkshell:5)
Block(-1,14,1,dynamictrees:trunkshell:6)
Block(-1,14,2,dynamictrees:trunkshell:7)
Block(-1,15,0,dynamictrees:trunkshell:5)
Block(-1,15,1,dynamictrees:trunkshell:6)
Block(-1,15,2,dynamictrees:trunkshell:7)
Block(-1,32,-3,dynamictrees:leaves0:12)
Block(-1,32,-2,dynamictrees:leaves0:15)
Block(-1,32,-1,dynamictrees:junglebranch:0)
Block(-1,32,1,dynamictrees:junglebranch:1)
Block(-1,32,3,dynamictrees:junglebranch:0)
Block(-1,32,4,dynamictrees:leaves0:15)
Block(-1,32,5,dynamictrees:leaves0:12)
Block(-1,33,-3,dynamictrees:leaves0:12)
Block(-1,33,-2,dynamictrees:leaves0:14)
Block(-1,33,-1,dynamictrees:leaves0:15)
Block(-1,33,0,dynamictrees:leaves0:14)
Block(-1,33,1,dynamictrees:leaves0:15)
Block(-1,33,2,dynamictrees:leaves0:14)
Block(-1,33,3,dynamictrees:leaves0:15)
Block(-1,33,4,dynamictrees:leaves0:14)
Block(-1,33,5,dynamictrees:leaves0:12)
Block(-1,34,-3,dynamictrees:leaves0:12)
Block(-1,34,-2,dynamictrees:leaves0:13)
Block(-1,34,-1,dynamictrees:leaves0:14)
Block(-1,34,0,dynamictrees:leaves0:15)
Block(-1,34,1,dynamictrees:junglebranch:0)
Block(-1,34,2,dynamictrees:leaves0:15)
Block(-1,34,3,dynamictrees:leaves0:14)
Block(-1,34,4,dynamictrees:leaves0:13)
Block(-1,34,5,dynamictrees:leaves0:12)
Block(-1,35,-2,dynamictrees:leaves0:12)
Block(-1,35,-1,dynamictrees:leaves0:13)
Block(-1,35,0,dynamictrees:leaves0:14)
Block(-1,35,1,dynamictrees:leaves0:15)
Block(-1,35,2,dynamictrees:leaves0:14)
Block(-1,35,3,dynamictrees:leaves0:13)
Block(-1,35,4,dynamictrees:leaves0:12)
Block(-1,36,-1,dynamictrees:leaves0:12)
Block(-1,36,0,dynamictrees:leaves0:12)
Block(-1,36,1,dynamictrees:leaves0:12)
Block(-1,36,2,dynamictrees:leaves0:12)
Block(-1,36,3,dynamictrees:leaves0:12)
Block(0,0,0,GRASS:0)
Block(0,0,1,dynamictrees:rootydirtspecies:0,DT_Jungle_THuge_40/1-species_tile_entity.nbt)
Block(0,0,2,GRASS:0)
Block(0,0,4,dynamictrees:jungleroot:0)
Block(0,1,0,dynamictrees:jungleroot:4)
Block(0,1,1,dynamictrees:junglebranch:13)
Block(0,1,2,dynamictrees:jungleroot:4)
Block(0,2,0,dynamictrees:trunkshell:4)
Block(0,2,1,dynamictrees:junglebranch:12)
Block(0,2,2,dynamictrees:trunkshell:0)
Block(0,3,0,dynamictrees:trunkshell:4)
Block(0,3,1,dynamictrees:junglebranch:11)
Block(0,3,2,dynamictrees:trunkshell:0)
Block(0,4,0,dynamictrees:trunkshell:4)
Block(0,4,1,dynamictrees:junglebranch:10)
Block(0,4,2,dynamictrees:trunkshell:0)
Block(0,5,0,dynamictrees:trunkshell:4)
Block(0,5,1,dynamictrees:junglebranch:10)
Block(0,5,2,dynamictrees:trunkshell:0)
Block(0,6,0,dynamictrees:trunkshell:4)
Block(0,6,1,dynamictrees:junglebranch:10)
Block(0,6,2,dynamictrees:trunkshell:0)
Block(0,7,0,dynamictrees:trunkshell:4)
Block(0,7,1,dynamictrees:junglebranch:10)
Block(0,7,2,dynamictrees:trunkshell:0)
Block(0,8,0,dynamictrees:trunkshell:4)
Block(0,8,1,dynamictrees:junglebranch:9)
Block(0,8,2,dynamictrees:trunkshell:0)
Block(0,9,0,dynamictrees:trunkshell:4)
Block(0,9,1,dynamictrees:junglebranch:9)
Block(0,9,2,dynamictrees:trunkshell:0)
Block(0,10,0,dynamictrees:trunkshell:4)
Block(0,10,1,dynamictrees:junglebranch:9)
Block(0,10,2,dynamictrees:trunkshell:0)
Block(0,11,0,dynamictrees:trunkshell:4)
Block(0,11,1,dynamictrees:junglebranch:9)
Block(0,11,2,dynamictrees:trunkshell:0)
Block(0,12,0,dynamictrees:trunkshell:4)
Block(0,12,1,dynamictrees:junglebranch:8)
Block(0,12,2,dynamictrees:trunkshell:0)
Block(0,13,0,dynamictrees:trunkshell:4)
Block(0,13,1,dynamictrees:junglebranch:8)
Block(0,13,2,dynamictrees:trunkshell:0)
Block(0,14,0,dynamictrees:trunkshell:4)
Block(0,14,1,dynamictrees:junglebranch:8)
Block(0,14,2,dynamictrees:trunkshell:0)
Block(0,15,0,dynamictrees:trunkshell:4)
Block(0,15,1,dynamictrees:junglebranch:8)
Block(0,15,2,dynamictrees:trunkshell:0)
Block(0,16,1,dynamictrees:junglebranch:7)
Block(0,17,1,dynamictrees:junglebranch:7)
Block(0,18,1,dynamictrees:junglebranch:7)
Block(0,19,1,dynamictrees:junglebranch:7)
Block(0,20,1,dynamictrees:junglebranch:6)
Block(0,21,1,dynamictrees:junglebranch:6)
Block(0,22,1,dynamictrees:junglebranch:6)
Block(0,23,1,dynamictrees:junglebranch:6)
Block(0,24,1,dynamictrees:junglebranch:5)
Block(0,25,1,dynamictrees:junglebranch:5)
Block(0,26,1,dynamictrees:junglebranch:5)
Block(0,27,1,dynamictrees:junglebranch:5)
Block(0,28,1,dynamictrees:junglebranch:4)
Block(0,29,1,dynamictrees:junglebranch:4)
Block(0,30,1,dynamictrees:junglebranch:4)
Block(0,31,1,dynamictrees:junglebranch:4)
Block(0,32,-3,dynamictrees:leaves0:12)
Block(0,32,-2,dynamictrees:leaves0:14)
Block(0,32,-1,dynamictrees:junglebranch:1)
Block(0,32,0,dynamictrees:junglebranch:1)
Block(0,32,1,dynamictrees:junglebranch:3)
Block(0,32,2,dynamictrees:junglebranch:1)
Block(0,32,3,dynamictrees:junglebranch:1)
Block(0,32,4,dynamictrees:leaves0:14)
Block(0,32,5,dynamictrees:leaves0:12)
Block(0,33,-3,dynamictrees:leaves0:12)
Block(0,33,-2,dynamictrees:leaves0:15)
Block(0,33,-1,dynamictrees:junglebranch:0)
Block(0,33,0,dynamictrees:leaves0:15)
Block(0,33,1,dynamictrees:junglebranch:1)
Block(0,33,2,dynamictrees:leaves0:15)
Block(0,33,3,dynamictrees:junglebranch:0)
Block(0,33,4,dynamictrees:leaves0:15)
Block(0,33,5,dynamictrees:leaves0:12)
Block(0,34,-3,dynamictrees:leaves0:12)
Block(0,34,-2,dynamictrees:leaves0:14)
Block(0,34,-1,dynamictrees:leaves0:15)
Block(0,34,0,dynamictrees:junglebranch:0)
Block(0,34,1,dynamictrees:junglebranch:1)
Block(0,34,2,dynamictrees:junglebranch:0)
Block(0,34,3,dynamictrees:leaves0:15)
Block(0,34,4,dynamictrees:leaves0:14)
Block(0,34,5,dynamictrees:leaves0:12)
Block(0,35,-3,dynamictrees:leaves0:12)
Block(0,35,-2,dynamictrees:leaves0:13)
Block(0,35,-1,dynamictrees:leaves0:14)
Block(0,35,0,dynamictrees:leaves0:15)
Block(0,35,1,dynamictrees:leaves0:14)
Block(0,35,2,dynamictrees:leaves0:15)
Block(0,35,3,dynamictrees:leaves0:14)
Block(0,35,4,dynamictrees:leaves0:13)
Block(0,35,5,dynamictrees:leaves0:12)
Block(0,36,-2,dynamictrees:leaves0:12)
Block(0,36,-1,dynamictrees:leaves0:12)
Block(0,36,0,dynamictrees:leaves0:12)
Block(0,36,1,dynamictrees:leaves0:12)
Block(0,36,2,dynamictrees:leaves0:12)
Block(0,36,3,dynamictrees:leaves0:12)
Block(0,36,4,dynamictrees:leaves0:12)
Block(1,0,0,GRASS:0)
Block(1,0,1,GRASS:0)
Block(1,0,2,GRASS:0)
Block(1,0,3,dynamictrees:jungleroot:2)
Block(1,0,4,dynamictrees:jungleroot:1)
Block(1,1,0,dynamictrees:trunkshell:3)
Block(1,1,1,dynamictrees:trunkshell:2)
Block(1,1,2,dynamictrees:jungleroot:3)
Block(1,2,0,dynamictrees:trunkshell:3)
Block(1,2,1,dynamictrees:trunkshell:2)
Block(1,2,2,dynamictrees:trunkshell:1)
Block(1,3,0,dynamictrees:trunkshell:3)
Block(1,3,1,dynamictrees:trunkshell:2)
Block(1,3,2,dynamictrees:trunkshell:1)
Block(1,4,0,dynamictrees:trunkshell:3)
Block(1,4,1,dynamictrees:trunkshell:2)
Block(1,4,2,dynamictrees:trunkshell:1)
Block(1,5,0,dynamictrees:trunkshell:3)
Block(1,5,1,dynamictrees:trunkshell:2)
Block(1,5,2,dynamictrees:trunkshell:1)
Block(1,6,0,dynamictrees:trunkshell:3)
Block(1,6,1,dynamictrees:trunkshell:2)
Block(1,6,2,dynamictrees:trunkshell:1)
Block(1,7,0,dynamictrees:trunkshell:3)
Block(1,7,1,dynamictrees:trunkshell:2)
Block(1,7,2,dynamictrees:trunkshell:1)
Block(1,8,0,dynamictrees:trunkshell:3)
Block(1,8,1,dynamictrees:trunkshell:2)
Block(1,8,2,dynamictrees:trunkshell:1)
Block(1,9,0,dynamictrees:trunkshell:3)
Block(1,9,1,dynamictrees:trunkshell:2)
Block(1,9,2,dynamictrees:trunkshell:1)
Block(1,10,0,dynamictrees:trunkshell:3)
Block(1,10,1,dynamictrees:trunkshell:2)
Block(1,10,2,dynamictrees:trunkshell:1)
Block(1,11,0,dynamictrees:trunkshell:3)
Block(1,11,1,dynamictrees:trunkshell:2)
Block(1,11,2,dynamictrees:trunkshell:1)
Block(1,12,0,dynamictrees:trunkshell:3)
Block(1,12,1,dynamictrees:trunkshell:2)
Block(1,12,2,dynamictrees:trunkshell:1)
Block(1,13,0,dynamictrees:trunkshell:3)
Block(1,13,1,dynamictrees:trunkshell:2)
Block(1,13,2,dynamictrees:trunkshell:1)
Block(1,14,0,dynamictrees:trunkshell:3)
Block(1,14,1,dynamictrees:trunkshell:2)
Block(1,14,2,dynamictrees:trunkshell:1)
Block(1,15,0,dynamictrees:trunkshell:3)
Block(1,15,1,dynamictrees:trunkshell:2)
Block(1,15,2,dynamictrees:trunkshell:1)
Block(1,32,-3,dynamictrees:leaves0:12)
Block(1,32,-2,dynamictrees:leaves0:15)
Block(1,32,-1,dynamictrees:junglebranch:0)
Block(1,32,1,dynamictrees:junglebranch:1)
Block(1,32,3,dynamictrees:junglebranch:0)
Block(1,32,4,dynamictrees:leaves0:15)
Block(1,32,5,dynamictrees:leaves0:12)
Block(1,33,-3,dynamictrees:leaves0:12)
Block(1,33,-2,dynamictrees:leaves0:14)
Block(1,33,-1,dynamictrees:leaves0:15)
Block(1,33,0,dynamictrees:leaves0:14)
Block(1,33,1,dynamictrees:leaves0:15)
Block(1,33,2,dynamictrees:leaves0:14)
Block(1,33,3,dynamictrees:leaves0:15)
Block(1,33,4,dynamictrees:leaves0:14)
Block(1,33,5,dynamictrees:leaves0:12)
Block(1,34,-3,dynamictrees:leaves0:12)
Block(1,34,-2,dynamictrees:leaves0:13)
Block(1,34,-1,dynamictrees:leaves0:14)
Block(1,34,0,dynamictrees:leaves0:15)
Block(1,34,1,dynamictrees:junglebranch:0)
Block(1,34,2,dynamictrees:leaves0:15)
Block(1,34,3,dynamictrees:leaves0:14)
Block(1,34,4,dynamictrees:leaves0:13)
Block(1,34,5,dynamictrees:leaves0:12)
Block(1,35,-2,dynamictrees:leaves0:12)
Block(1,35,-1,dynamictrees:leaves0:13)
Block(1,35,0,dynamictrees:leaves0:14)
Block(1,35,1,dynamictrees:leaves0:15)
Block(1,35,2,dynamictrees:leaves0:14)
Block(1,35,3,dynamictrees:leaves0:13)
Block(1,35,4,dynamictrees:leaves0:12)
Block(1,36,-1,dynamictrees:leaves0:12)
Block(1,36,0,dynamictrees:leaves0:12)
Block(1,36,1,dynamictrees:leaves0:12)
Block(1,36,2,dynamictrees:leaves0:12)
Block(1,36,3,dynamictrees:leaves0:12)
Block(2,0,4,dynamictrees:jungleroot:0)
Block(2,31,-2,dynamictrees:leaves0:12)
Block(2,31,4,dynamictrees:leaves0:12)
Block(2,32,-3,dynamictrees:leaves0:12)
Block(2,32,-2,dynamictrees:leaves0:14)
Block(2,32,-1,dynamictrees:leaves0:15)
Block(2,32,0,dynamictrees:junglebranch:0)
Block(2,32,1,dynamictrees:junglebranch:1)
Block(2,32,3,dynamictrees:leaves0:15)
Block(2,32,4,dynamictrees:leaves0:14)
Block(2,32,5,dynamictrees:leaves0:12)
Block(2,33,-3,dynamictrees:leaves0:12)
Block(2,33,-2,dynamictrees:leaves0:13)
Block(2,33,-1,dynamictrees:leaves0:14)
Block(2,33,0,dynamictrees:leaves0:15)
Block(2,33,1,dynamictrees:junglebranch:0)
Block(2,33,2,dynamictrees:leaves0:15)
Block(2,33,3,dynamictrees:leaves0:14)
Block(2,33,4,dynamictrees:leaves0:13)
Block(2,33,5,dynamictrees:leaves0:12)
Block(2,34,-2,dynamictrees:leaves0:12)
Block(2,34,-1,dynamictrees:leaves0:13)
Block(2,34,0,dynamictrees:leaves0:14)
Block(2,34,1,dynamictrees:leaves0:15)
Block(2,34,2,dynamictrees:leaves0:14)
Block(2,34,3,dynamictrees:leaves0:13)
Block(2,34,4,dynamictrees:leaves0:12)
Block(2,35,-1,dynamictrees:leaves0:12)
Block(2,35,0,dynamictrees:leaves0:13)
Block(2,35,1,dynamictrees:leaves0:14)
Block(2,35,2,dynamictrees:leaves0:13)
Block(2,35,3,dynamictrees:leaves0:12)
Block(2,36,0,dynamictrees:leaves0:12)
Block(2,36,1,dynamictrees:leaves0:12)
Block(2,36,2,dynamictrees:leaves0:12)
Block(3,31,-2,dynamictrees:leaves0:12)
Block(3,31,-1,dynamictrees:leaves0:12)
Block(3,32,-3,dynamictrees:leaves0:12)
Block(3,32,-2,dynamictrees:leaves0:13)
Block(3,32,-1,dynamictrees:leaves0:14)
Block(3,32,0,dynamictrees:leaves0:15)
Block(3,32,2,dynamictrees:leaves0:12)
Block(3,32,3,dynamictrees:leaves0:12)
Block(3,32,4,dynamictrees:leaves0:12)
Block(3,33,-2,dynamictrees:leaves0:12)
Block(3,33,-1,dynamictrees:leaves0:13)
Block(3,33,0,dynamictrees:leaves0:14)
Block(3,33,1,dynamictrees:leaves0:15)
Block(3,33,2,dynamictrees:leaves0:14)
Block(3,33,3,dynamictrees:leaves0:13)
Block(3,33,4,dynamictrees:leaves0:12)
Block(3,34,-1,dynamictrees:leaves0:12)
Block(3,34,0,dynamictrees:leaves0:13)
Block(3,34,1,dynamictrees:leaves0:14)
Block(3,34,2,dynamictrees:leaves0:13)
Block(3,34,3,dynamictrees:leaves0:12)
Block(3,35,0,dynamictrees:leaves0:12)
Block(3,35,1,dynamictrees:leaves0:13)
Block(3,35,2,dynamictrees:leaves0:12)
Block(3,36,1,dynamictrees:leaves0:12)
Block(4,32,-2,dynamictrees:leaves0:12)
Block(4,32,-1,dynamictrees:leaves0:12)
Block(4,32,0,dynamictrees:leaves0:12)
Block(4,32,1,dynamictrees:leaves0:12)
Block(4,32,2,dynamictrees:leaves0:12)
Block(4,33,-1,dynamictrees:leaves0:12)
Block(4,33,0,dynamictrees:leaves0:12)
Block(4,33,1,dynamictrees:leaves0:12)
Block(4,33,2,dynamictrees:leaves0:12)
Block(4,33,3,dynamictrees:leaves0:12)
Block(4,34,0,dynamictrees:leaves0:12)
Block(4,34,1,dynamictrees:leaves0:12)
Block(4,34,2,dynamictrees:leaves0:12)
Block(4,35,1,dynamictrees:leaves0:12)

#######################################################################
# +-----------------------------------------------------------------+ #
# |                            BO3 checks                           | #
# +-----------------------------------------------------------------+ #
#######################################################################

BlockCheck(0,-1,1,GRASS,DIRT,biomesoplenty:grass,biomesoplenty:dirt)

#######################################################################
# +-----------------------------------------------------------------+ #
# |                             Branches                            | #
# +-----------------------------------------------------------------+ #
#######################################################################


#######################################################################
# +-----------------------------------------------------------------+ #
# |                             Entities                            | #
# +-----------------------------------------------------------------+ #
#######################################################################


#######################################################################
# +-----------------------------------------------------------------+ #
# |                            Particles                            | #
# +-----------------------------------------------------------------+ #
#######################################################################


#######################################################################
# +-----------------------------------------------------------------+ #
# |                             Spawners                            | #
# +-----------------------------------------------------------------+ #
#######################################################################


#######################################################################
# +-----------------------------------------------------------------+ #
# |                             ModData                             | #
# +-----------------------------------------------------------------+ #
#######################################################################

