
#######################################################################
# +-----------------------------------------------------------------+ #
# |                            BO4 object                           | #
# +-----------------------------------------------------------------+ #
#######################################################################

Author: NLBlackEagle

Description: No description given

SettingsMode: WriteWithoutComments


#######################################################################
# +-----------------------------------------------------------------+ #
# |                          Main settings                          | #
# +-----------------------------------------------------------------+ #
#######################################################################

FixedRotation: 

Frequency: 0

SpawnHeight: highestSolidBlock

UseCenterForHighestBlock: true

##############################
# Height Limits for the BO4. #
##############################

MinHeight: 0

MaxHeight: 255

InheritBO3: 

InheritBO3Rotation: NORTH

OverrideChildSettings: true

OverrideParentHeight: false

CanOverride: true

BranchFrequency: 0

BranchFrequencyGroup: 

MustBeBelowOther: false

MustBeInside: 

CannotBeInside: 

ReplacesBO3: 

MustBeInsideWorldBorders: false

CanSpawnOnWater: true

SpawnOnWaterOnly: true

SpawnUnderWater: false

SpawnAtWaterLevel: false

HeightOffset: 0

RemoveAir: false

ReplaceAbove: 

ReplaceBelow: 

ReplaceWithBiomeBlocks: false

ReplaceWithSurfaceBlock: GRASS

ReplaceWithGroundBlock: DIRT

ReplaceWithStoneBlock: STONE

SmoothRadius: 0

SmoothHeightOffset: 0

SmoothStartTop: false

SmoothStartWood: false

SmoothingSurfaceBlock: 

SmoothingGroundBlock: 

BO3Group: 

IsSpawnPoint: false

DoReplaceBlocks: true


#######################################################################
# +-----------------------------------------------------------------+ #
# |                              Blocks                             | #
# +-----------------------------------------------------------------+ #
#######################################################################

Block(-4,8,-3,WOOD_STEP:8)
Block(-4,8,-2,WOOD_STEP:8)
Block(-4,8,-1,WOOD_STEP:8)
Block(-4,8,0,WOOD_STEP:8)
Block(-4,8,1,WOOD_STEP:8)
Block(-4,8,2,WOOD_STEP:8)
Block(-4,8,3,WOOD_STEP:8)
Block(-4,9,-3,WOOD_STEP:8)
Block(-4,9,-2,WOOD_STEP:8)
Block(-4,9,-1,WOOD_STEP:8)
Block(-4,9,0,WOOD_STEP:8)
Block(-4,9,1,WOOD_STEP:8)
Block(-4,9,2,WOOD_STEP:8)
Block(-4,9,3,WOOD_STEP:8)
Block(-3,0,-2,LOG:1)
Block(-3,0,2,LOG:1)
Block(-3,1,-2,LOG:1)
Block(-3,1,2,LOG:1)
Block(-3,2,-2,LOG:1)
Block(-3,2,2,LOG:1)
Block(-3,3,-2,LOG:1)
Block(-3,3,2,LOG:1)
Block(-3,4,-2,LOG:1)
Block(-3,4,2,LOG:1)
Block(-3,5,-2,LOG:1)
Block(-3,5,2,LOG:1)
Block(-3,6,-2,LOG:1)
Block(-3,6,2,LOG:1)
Block(-3,7,-2,LOG:1)
Block(-3,7,2,LOG:1)
Block(-3,8,-3,WOOD_STEP:8)
Block(-3,8,-2,LOG:1)
Block(-3,8,-1,WOOD_STEP:8)
Block(-3,8,0,WOOD_STEP:8)
Block(-3,8,1,WOOD_STEP:8)
Block(-3,8,2,LOG:1)
Block(-3,8,3,WOOD_STEP:8)
Block(-3,9,-3,WOOD_STEP:8)
Block(-3,9,-2,WOOD_DOUBLE_STEP:0)
Block(-3,9,-1,WOOD_STEP:8)
Block(-3,9,0,WOOD_STEP:8)
Block(-3,9,1,WOOD_STEP:8)
Block(-3,9,2,WOOD_STEP:8)
Block(-3,9,3,WOOD_STEP:8)
Block(-3,10,-3,DARK_OAK_FENCE:0)
Block(-3,10,1,variedcommodities:stool:1)
Block(-3,10,3,DARK_OAK_FENCE:0)
Block(-3,11,-3,DARK_OAK_FENCE:0)
Block(-3,11,3,DARK_OAK_FENCE:0)
Block(-3,12,-3,DARK_OAK_FENCE:0)
Block(-3,12,-2,DARK_OAK_FENCE:0)
Block(-3,12,-1,DARK_OAK_FENCE:0)
Block(-3,12,0,DARK_OAK_FENCE:0)
Block(-3,12,1,DARK_OAK_FENCE:0)
Block(-3,12,2,DARK_OAK_FENCE:0)
Block(-3,12,3,DARK_OAK_FENCE:0)
Block(-3,13,-3,quark:spruce_trapdoor:0)
Block(-3,13,-2,quark:spruce_trapdoor:2)
Block(-3,13,-1,quark:spruce_trapdoor:2)
Block(-3,13,0,quark:spruce_trapdoor:2)
Block(-3,13,1,quark:spruce_trapdoor:2)
Block(-3,13,2,quark:spruce_trapdoor:2)
Block(-3,13,3,quark:spruce_trapdoor:1)
Block(-2,8,-3,WOOD_STEP:8)
Block(-2,8,3,WOOD_STEP:8)
Block(-2,9,-3,WOOD_STEP:8)
Block(-2,9,-2,WOOD_STEP:8)
Block(-2,9,-1,WOOD_STEP:8)
Block(-2,9,0,WOOD_STEP:8)
Block(-2,9,1,WOOD_STEP:8)
Block(-2,9,2,WOOD_STEP:8)
Block(-2,9,3,WOOD_STEP:8)
Block(-2,12,-3,DARK_OAK_FENCE:0)
Block(-2,12,3,DARK_OAK_FENCE:0)
Block(-2,13,-3,quark:spruce_trapdoor:0)
Block(-2,13,-2,STEP:0)
Block(-2,13,-1,STEP:0)
Block(-2,13,0,STEP:0)
Block(-2,13,1,STEP:0)
Block(-2,13,2,STEP:0)
Block(-2,13,3,quark:spruce_trapdoor:1)
Block(-1,7,-2,LADDER:4)
Block(-1,8,-3,WOOD_STEP:8)
Block(-1,8,-2,LADDER:4)
Block(-1,8,-1,WOOD_STEP:8)
Block(-1,8,0,WOOD_STEP:8)
Block(-1,8,1,WOOD_STEP:8)
Block(-1,8,2,WOOD_STEP:8)
Block(-1,8,3,WOOD_STEP:8)
Block(-1,9,-3,WOOD_STAIRS:4)
Block(-1,9,-2,LADDER:4)
Block(-1,9,-1,WOOD_STAIRS:4)
Block(-1,9,0,WOOD_STAIRS:4)
Block(-1,9,1,WOOD_STAIRS:4)
Block(-1,9,2,WOOD_STAIRS:4)
Block(-1,9,3,WOOD_STAIRS:7)
Block(-1,10,-3,DARK_OAK_FENCE:0)
Block(-1,10,-2,LADDER:4)
Block(-1,10,3,DARK_OAK_FENCE:0)
Block(-1,11,-3,DARK_OAK_FENCE:0)
Block(-1,11,3,DARK_OAK_FENCE:0)
Block(-1,12,-3,DARK_OAK_FENCE:0)
Block(-1,12,3,DARK_OAK_FENCE:0)
Block(-1,13,-3,quark:spruce_trapdoor:0)
Block(-1,13,-2,STEP:0)
Block(-1,13,-1,STEP:0)
Block(-1,13,0,STEP:0)
Block(-1,13,1,STEP:0)
Block(-1,13,2,STEP:0)
Block(-1,13,3,quark:spruce_trapdoor:1)
Block(0,0,-2,LOG:1)
Block(0,0,2,LOG:1)
Block(0,1,-2,LOG:1)
Block(0,1,2,LOG:1)
Block(0,2,-2,LOG:1)
Block(0,2,2,LOG:1)
Block(0,3,-2,LOG:1)
Block(0,3,2,LOG:1)
Block(0,4,-2,LOG:1)
Block(0,4,2,LOG:1)
Block(0,5,-2,LOG:1)
Block(0,5,2,LOG:1)
Block(0,6,-2,LOG:1)
Block(0,6,2,LOG:1)
Block(0,7,-2,LOG:1)
Block(0,7,2,LOG:1)
Block(0,8,-3,WOOD_STEP:8)
Block(0,8,-2,LOG:1)
Block(0,8,-1,WOOD_STEP:8)
Block(0,8,0,WOOD_STEP:8)
Block(0,8,1,WOOD_STEP:8)
Block(0,8,2,LOG:1)
Block(0,8,3,WOOD_STEP:8)
Block(0,9,-3,WOOD_STAIRS:6)
Block(0,9,-2,LOG:1)
Block(0,9,-1,WOOD:0)
Block(0,9,0,WOOD:0)
Block(0,9,1,WOOD:0)
Block(0,9,2,LOG:1)
Block(0,9,3,WOOD_STAIRS:7)
Block(0,10,-3,quark:bark_dark_oak_wall:0)
Block(0,10,-2,LOG:1)
Block(0,10,-1,quark:carved_wood:5)
Block(0,10,0,SPRUCE_DOOR:6)
Block(0,10,1,quark:carved_wood:0)
Block(0,10,2,LOG:1)
Block(0,10,3,quark:bark_dark_oak_wall:0)
Block(0,11,-3,quark:bark_dark_oak_wall:0)
Block(0,11,-2,LOG:1)
Block(0,11,-1,quark:carved_wood:0)
Block(0,11,0,SPRUCE_DOOR:9)
Block(0,11,1,quark:carved_wood:5)
Block(0,11,2,LOG:1)
Block(0,11,3,quark:bark_dark_oak_wall:0)
Block(0,12,-3,quark:bark_dark_oak_wall:0)
Block(0,12,-2,LOG:1)
Block(0,12,-1,quark:carved_wood:0)
Block(0,12,0,quark:carved_wood:0)
Block(0,12,1,quark:carved_wood:0)
Block(0,12,2,LOG:1)
Block(0,12,3,quark:bark_dark_oak_wall:0)
Block(0,13,-3,quark:spruce_trapdoor:0)
Block(0,13,-2,STEP:0)
Block(0,13,-1,STEP:0)
Block(0,13,0,STEP:0)
Block(0,13,1,STEP:0)
Block(0,13,2,STEP:0)
Block(0,13,3,quark:spruce_trapdoor:1)
Block(1,8,-3,WOOD_STEP:8)
Block(1,8,-2,WOOD_STEP:8)
Block(1,8,-1,WOOD_STEP:8)
Block(1,8,0,WOOD_STEP:8)
Block(1,8,1,WOOD_STEP:8)
Block(1,8,2,WOOD_STEP:8)
Block(1,8,3,WOOD_STEP:8)
Block(1,9,-3,WOOD_STAIRS:6)
Block(1,9,-2,WOOD:0)
RandomBlock(1,9,-1,CHEST:3,../../../../Chests/Loot/junk_loot.nbt,20,CHEST:3,../../../../Chests/Loot/fishing_loot.nbt,100)
Block(1,9,0,WOOD:0)
Block(1,9,1,WORKBENCH:0)
Block(1,9,2,WOOD:0)
Block(1,9,3,WOOD_STAIRS:7)
Block(1,10,-2,quark:carved_wood:5)
Block(1,10,1,variedcommodities:table:5)
Block(1,10,2,quark:carved_wood:0)
Block(1,11,-2,quark:carved_wood:5)
Block(1,11,1,realistictorches:torch_lit:5)
Block(1,11,2,quark:carved_wood:0)
Block(1,12,-3,DARK_OAK_FENCE:0)
Block(1,12,-2,quark:carved_wood:5)
Block(1,12,2,quark:carved_wood:0)
Block(1,12,3,DARK_OAK_FENCE:0)
Block(1,13,-3,quark:spruce_trapdoor:0)
Block(1,13,-2,STEP:0)
Block(1,13,-1,STEP:0)
Block(1,13,0,STEP:0)
Block(1,13,1,STEP:0)
Block(1,13,2,STEP:0)
Block(1,13,3,quark:spruce_trapdoor:1)
Block(2,8,-3,WOOD_STEP:8)
Block(2,8,-2,WOOD_STEP:8)
Block(2,8,-1,WOOD_STEP:8)
Block(2,8,1,WOOD_STEP:8)
Block(2,8,2,WOOD_STEP:8)
Block(2,8,3,WOOD_STEP:8)
Block(2,9,-3,WOOD_STAIRS:6)
Block(2,9,-2,WOOD:0)
Block(2,9,-1,WOOD:0)
Block(2,9,1,WOOD:0)
Block(2,9,2,WOOD:0)
Block(2,9,3,WOOD_STAIRS:7)
Block(2,10,-2,quark:carved_wood:5)
Block(2,10,-1,variedcommodities:stool:1)
Block(2,10,1,variedcommodities:stool:1)
Block(2,10,2,quark:carved_wood:0)
Block(2,11,-2,quark:carved_wood:5)
Block(2,11,2,quark:carved_wood:5)
Block(2,12,-3,DARK_OAK_FENCE:0)
Block(2,12,-2,quark:carved_wood:5)
Block(2,12,2,quark:carved_wood:5)
Block(2,12,3,DARK_OAK_FENCE:0)
Block(2,13,-3,quark:spruce_trapdoor:0)
Block(2,13,-2,STEP:0)
Block(2,13,-1,STEP:0)
Block(2,13,0,STEP:0)
Block(2,13,1,STEP:0)
Block(2,13,2,STEP:0)
Block(2,13,3,quark:spruce_trapdoor:1)
Block(3,0,-2,LOG:1)
Block(3,0,2,LOG:1)
Block(3,1,-2,LOG:1)
Block(3,1,2,LOG:1)
Block(3,2,-2,LOG:1)
Block(3,2,2,LOG:1)
Block(3,3,-2,LOG:1)
Block(3,3,2,LOG:1)
Block(3,4,-2,LOG:1)
Block(3,4,2,LOG:1)
Block(3,5,-2,LOG:1)
Block(3,5,2,LOG:1)
Block(3,6,-2,LOG:1)
Block(3,6,2,LOG:1)
Block(3,7,-2,LOG:1)
Block(3,7,2,LOG:1)
Block(3,8,-3,WOOD_STEP:8)
Block(3,8,-2,LOG:1)
Block(3,8,-1,WOOD_STEP:8)
Block(3,8,0,WOOD_STEP:8)
Block(3,8,1,WOOD_STEP:8)
Block(3,8,2,LOG:1)
Block(3,8,3,WOOD_STEP:8)
Block(3,9,-3,WOOD_STAIRS:6)
Block(3,9,-2,LOG:1)
Block(3,9,-1,WOOD:0)
Block(3,9,0,WOOD:0)
Block(3,9,1,WOOD:0)
Block(3,9,2,LOG:1)
Block(3,9,3,WOOD_STAIRS:7)
Block(3,10,-2,LOG:1)
Block(3,10,-1,quark:carved_wood:5)
Block(3,10,0,quark:carved_wood:5)
Block(3,10,1,quark:carved_wood:0)
Block(3,10,2,LOG:1)
Block(3,11,-2,LOG:1)
Block(3,11,-1,quark:carved_wood:0)
Block(3,11,0,quark:framed_glass_pane:0)
Block(3,11,1,quark:carved_wood:0)
Block(3,11,2,LOG:1)
Block(3,12,-3,DARK_OAK_FENCE:0)
Block(3,12,-2,LOG:1)
Block(3,12,-1,quark:carved_wood:0)
Block(3,12,0,quark:carved_wood:5)
Block(3,12,1,quark:carved_wood:0)
Block(3,12,2,LOG:1)
Block(3,12,3,DARK_OAK_FENCE:0)
Block(3,13,-3,quark:spruce_trapdoor:0)
Block(3,13,-2,STEP:0)
Block(3,13,-1,STEP:0)
Block(3,13,0,STEP:0)
Block(3,13,1,STEP:0)
Block(3,13,2,STEP:0)
Block(3,13,3,quark:spruce_trapdoor:1)
Block(4,8,-3,WOOD_STEP:8)
Block(4,8,-2,WOOD_STEP:8)
Block(4,8,-1,WOOD_STEP:8)
Block(4,8,0,WOOD_STEP:8)
Block(4,8,1,WOOD_STEP:8)
Block(4,8,2,WOOD_STEP:8)
Block(4,8,3,WOOD_STEP:8)
Block(4,9,-3,WOOD_STAIRS:5)
Block(4,9,-2,WOOD_STAIRS:5)
Block(4,9,-1,WOOD_STAIRS:5)
Block(4,9,0,WOOD_STAIRS:5)
Block(4,9,1,WOOD_STAIRS:5)
Block(4,9,2,WOOD_STAIRS:5)
Block(4,9,3,WOOD_STAIRS:5)
Block(4,10,-3,quark:bark_dark_oak_wall:0)
Block(4,10,3,quark:bark_dark_oak_wall:0)
Block(4,11,-3,quark:bark_dark_oak_wall:0)
Block(4,11,3,quark:bark_dark_oak_wall:0)
Block(4,12,-3,quark:bark_dark_oak_wall:0)
Block(4,12,-2,DARK_OAK_FENCE:0)
Block(4,12,-1,DARK_OAK_FENCE:0)
Block(4,12,0,DARK_OAK_FENCE:0)
Block(4,12,1,DARK_OAK_FENCE:0)
Block(4,12,2,DARK_OAK_FENCE:0)
Block(4,12,3,quark:bark_dark_oak_wall:0)
Block(4,13,-3,quark:spruce_trapdoor:0)
Block(4,13,-2,quark:spruce_trapdoor:3)
Block(4,13,-1,quark:spruce_trapdoor:3)
Block(4,13,0,quark:spruce_trapdoor:3)
Block(4,13,1,quark:spruce_trapdoor:3)
Block(4,13,2,quark:spruce_trapdoor:3)
Block(4,13,3,quark:spruce_trapdoor:3)

#######################################################################
# +-----------------------------------------------------------------+ #
# |                             Branches                            | #
# +-----------------------------------------------------------------+ #
#######################################################################


#######################################################################
# +-----------------------------------------------------------------+ #
# |                             Entities                            | #
# +-----------------------------------------------------------------+ #
#######################################################################


#######################################################################
# +-----------------------------------------------------------------+ #
# |                            Particles                            | #
# +-----------------------------------------------------------------+ #
#######################################################################


#######################################################################
# +-----------------------------------------------------------------+ #
# |                             Spawners                            | #
# +-----------------------------------------------------------------+ #
#######################################################################


#######################################################################
# +-----------------------------------------------------------------+ #
# |                             ModData                             | #
# +-----------------------------------------------------------------+ #
#######################################################################

