
#######################################################################
# +-----------------------------------------------------------------+ #
# |                            BO4 object                           | #
# +-----------------------------------------------------------------+ #
#######################################################################

Author: NLBlackEagle

Description: No description given

SettingsMode: WriteWithoutComments


#######################################################################
# +-----------------------------------------------------------------+ #
# |                          Main settings                          | #
# +-----------------------------------------------------------------+ #
#######################################################################

FixedRotation: NORTH

Frequency: 0

SpawnHeight: highestSolidBlock

UseCenterForHighestBlock: true

##############################
# Height Limits for the BO4. #
##############################

MinHeight: 0

MaxHeight: 255

InheritBO3: 

InheritBO3Rotation: NORTH

OverrideChildSettings: true

OverrideParentHeight: false

CanOverride: true

BranchFrequency: 0

BranchFrequencyGroup: 

MustBeBelowOther: false

MustBeInside: 

CannotBeInside: 

ReplacesBO3: 

MustBeInsideWorldBorders: false

CanSpawnOnWater: false

SpawnOnWaterOnly: false

SpawnUnderWater: false

SpawnAtWaterLevel: false

HeightOffset: 0

RemoveAir: false

ReplaceAbove: 

ReplaceBelow: 

ReplaceWithBiomeBlocks: false

ReplaceWithSurfaceBlock: GRASS

ReplaceWithGroundBlock: DIRT

ReplaceWithStoneBlock: STONE

SmoothRadius: 0

SmoothHeightOffset: 0

SmoothStartTop: false

SmoothStartWood: false

SmoothingSurfaceBlock: 

SmoothingGroundBlock: 

BO3Group: 

IsSpawnPoint: false

DoReplaceBlocks: true


#######################################################################
# +-----------------------------------------------------------------+ #
# |                              Blocks                             | #
# +-----------------------------------------------------------------+ #
#######################################################################

Block(-2,1,-1,quark:iron_plate_stairs:4)
Block(-2,1,0,quark:iron_plate_stairs:4)
Block(-2,1,1,quark:iron_plate_stairs:4)
Block(-2,2,-1,quark:iron_plate:1)
Block(-2,2,0,quark:iron_plate:0)
Block(-2,2,1,quark:iron_plate:1)
Block(-2,3,-1,quark:iron_plate:0)
Block(-2,3,0,quark:iron_plate:1)
Block(-2,3,1,quark:iron_plate:0)
Block(-2,4,-1,quark:iron_plate:1)
Block(-2,4,0,quark:iron_plate:0)
Block(-2,4,1,quark:iron_plate:0)
Block(-2,5,0,quark:iron_plate_stairs:0)
Block(-2,7,0,quark:iron_plate_stairs:4)
Block(-2,8,-2,quark:iron_plate_slab:8)
Block(-2,8,-1,quark:iron_plate_slab:8)
Block(-2,8,0,quark:iron_plate_slab_double:0)
Block(-2,8,1,quark:iron_plate_slab:8)
Block(-2,8,2,quark:iron_plate_slab:8)
Block(-2,9,-2,rustic:iron_lattice:0)
Block(-2,9,-1,rustic:iron_lattice:0)
Block(-2,9,0,rustic:iron_lattice:0)
Block(-2,9,1,rustic:iron_lattice:0)
Block(-2,9,2,rustic:iron_lattice:0)
Block(-1,0,-1,quark:iron_plate_stairs:4)
Block(-1,0,0,quark:iron_plate_stairs:4)
Block(-1,0,1,quark:iron_plate_stairs:7)
Block(-1,1,-2,quark:iron_plate_stairs:6)
Block(-1,1,-1,TNT:0)
Block(-1,1,0,TNT:0)
Block(-1,1,1,TNT:0)
Block(-1,1,2,quark:iron_plate_stairs:7)
Block(-1,2,-2,quark:iron_plate:1)
Block(-1,2,-1,TNT:0)
Block(-1,2,0,TNT:0)
Block(-1,2,1,TNT:0)
Block(-1,2,2,quark:iron_plate:1)
Block(-1,3,-2,quark:iron_plate:0)
Block(-1,3,-1,TNT:0)
Block(-1,3,0,OBSERVER:4)
Block(-1,3,1,TNT:0)
Block(-1,3,2,quark:iron_plate:1)
Block(-1,4,-2,quark:iron_plate:0)
Block(-1,4,-1,quark:iron_plate:1)
Block(-1,4,0,TNT:0)
Block(-1,4,1,quark:iron_plate:1)
Block(-1,4,2,quark:iron_plate:1)
Block(-1,5,-1,quark:iron_plate:1)
Block(-1,5,0,TNT:0)
Block(-1,5,1,quark:iron_plate:0)
Block(-1,6,-1,IRON_FENCE:0)
Block(-1,6,0,quark:iron_plate:0)
Block(-1,6,1,IRON_FENCE:0)
Block(-1,7,0,quark:iron_plate_stairs:1)
Block(-1,8,-2,quark:iron_plate_slab:8)
Block(-1,8,2,quark:iron_plate_slab:8)
Block(-1,9,-2,rustic:iron_lattice:0)
Block(-1,9,2,rustic:iron_lattice:0)
Block(0,0,-1,quark:iron_plate_stairs:6)
Block(0,0,0,OBSERVER:0)
Block(0,0,1,quark:iron_plate_stairs:7)
Block(0,1,-2,quark:iron_plate_stairs:6)
Block(0,1,-1,TNT:0)
Block(0,1,0,TNT:0)
Block(0,1,1,TNT:0)
Block(0,1,2,quark:iron_plate_stairs:7)
Block(0,2,-2,quark:iron_plate:1)
Block(0,2,-1,TNT:0)
Block(0,2,0,OBSERVER:0)
Block(0,2,1,TNT:0)
Block(0,2,2,quark:iron_plate:1)
Block(0,3,-2,quark:iron_plate:1)
Block(0,3,-1,OBSERVER:2)
Block(0,3,0,TNT:0)
Block(0,3,1,OBSERVER:3)
Block(0,3,2,quark:iron_plate:1)
Block(0,4,-2,quark:iron_plate:0)
Block(0,4,-1,TNT:0)
Block(0,4,0,OBSERVER:0)
Block(0,4,1,TNT:0)
Block(0,4,2,quark:iron_plate:1)
Block(0,5,-2,quark:iron_plate_stairs:2)
Block(0,5,-1,TNT:0)
Block(0,5,0,TNT:0)
Block(0,5,1,TNT:0)
Block(0,5,2,quark:iron_plate_stairs:3)
Block(0,6,-1,quark:iron_plate:0)
Block(0,6,0,TNT:0)
Block(0,6,1,quark:iron_plate:0)
Block(0,7,-2,quark:iron_plate_stairs:6)
Block(0,7,-1,quark:iron_plate_stairs:3)
Block(0,7,0,quark:iron_plate_slab:0)
Block(0,7,1,quark:iron_plate_stairs:2)
Block(0,7,2,quark:iron_plate_stairs:7)
Block(0,8,-2,quark:iron_plate_slab_double:0)
Block(0,8,2,quark:iron_plate_slab_double:0)
Block(0,9,-2,rustic:iron_lattice:0)
Block(0,9,2,rustic:iron_lattice:0)
Block(1,0,-1,quark:iron_plate_stairs:6)
Block(1,0,0,quark:iron_plate_stairs:5)
Block(1,0,1,quark:iron_plate_stairs:5)
Block(1,1,-2,quark:iron_plate_stairs:6)
Block(1,1,-1,TNT:0)
Block(1,1,0,TNT:0)
Block(1,1,1,TNT:0)
Block(1,1,2,quark:iron_plate_stairs:7)
Block(1,2,-2,quark:iron_plate:1)
Block(1,2,-1,TNT:0)
Block(1,2,0,TNT:0)
Block(1,2,1,TNT:0)
Block(1,2,2,quark:iron_plate:1)
Block(1,3,-2,quark:iron_plate:0)
Block(1,3,-1,TNT:0)
Block(1,3,0,OBSERVER:5)
Block(1,3,1,TNT:0)
Block(1,3,2,quark:iron_plate:0)
Block(1,4,-2,quark:iron_plate:1)
Block(1,4,-1,quark:iron_plate:1)
Block(1,4,0,TNT:0)
Block(1,4,1,quark:iron_plate:1)
Block(1,4,2,quark:iron_plate:1)
Block(1,5,-1,quark:iron_plate:0)
Block(1,5,0,TNT:0)
Block(1,5,1,quark:iron_plate:0)
Block(1,6,-1,IRON_FENCE:0)
Block(1,6,0,quark:iron_plate:0)
Block(1,6,1,IRON_FENCE:0)
Block(1,7,0,quark:iron_plate_stairs:0)
Block(1,8,-2,quark:iron_plate_slab:8)
Block(1,8,2,quark:iron_plate_slab:8)
Block(1,9,-2,rustic:iron_lattice:0)
Block(1,9,2,rustic:iron_lattice:0)
Block(2,1,-1,quark:iron_plate_stairs:5)
Block(2,1,0,quark:iron_plate_stairs:5)
Block(2,1,1,quark:iron_plate_stairs:5)
Block(2,2,-1,quark:iron_plate:1)
Block(2,2,0,quark:iron_plate:1)
Block(2,2,1,quark:iron_plate:1)
Block(2,3,-1,quark:iron_plate:0)
Block(2,3,0,quark:iron_plate:1)
Block(2,3,1,quark:iron_plate:1)
Block(2,4,-1,quark:iron_plate:1)
Block(2,4,0,quark:iron_plate:0)
Block(2,4,1,quark:iron_plate:0)
Block(2,5,0,quark:iron_plate_stairs:1)
Block(2,7,0,quark:iron_plate_stairs:5)
Block(2,8,-2,quark:iron_plate_slab:8)
Block(2,8,-1,quark:iron_plate_slab:8)
Block(2,8,0,quark:iron_plate_slab_double:0)
Block(2,8,1,quark:iron_plate_slab:8)
Block(2,8,2,quark:iron_plate_slab:8)
Block(2,9,-2,rustic:iron_lattice:0)
Block(2,9,-1,rustic:iron_lattice:0)
Block(2,9,0,rustic:iron_lattice:0)
Block(2,9,1,rustic:iron_lattice:0)
Block(2,9,2,rustic:iron_lattice:0)
RandomBlock(0,5,0,nuclearcraft:block_depleted_thorium:0,null,10,nuclearcraft:block_depleted_uranium:0,null,10,nuclearcraft:block_depleted_neptunium:0,null,10,nuclearcraft:block_depleted_neptunium:0,null,10,nuclearcraft:block_depleted_plutonium:0,null,10,nuclearcraft:ingot_block:3,null,10,nuclearcraft:ingot_block:4,null,10,nuclearcraft:block_depleted_thorium:0,null,30,nuclearcraft:block_depleted_uranium:0,null,30,nuclearcraft:block_depleted_neptunium:0,null,30,nuclearcraft:block_depleted_neptunium:0,null,30,nuclearcraft:block_depleted_plutonium:0,null,30,nuclearcraft:ingot_block:3,null,30,nuclearcraft:ingot_block:4,null,30,nuclearcraft:block_depleted_thorium:0,null,100)

#######################################################################
# +-----------------------------------------------------------------+ #
# |                             Branches                            | #
# +-----------------------------------------------------------------+ #
#######################################################################


#######################################################################
# +-----------------------------------------------------------------+ #
# |                             Entities                            | #
# +-----------------------------------------------------------------+ #
#######################################################################


#######################################################################
# +-----------------------------------------------------------------+ #
# |                            Particles                            | #
# +-----------------------------------------------------------------+ #
#######################################################################


#######################################################################
# +-----------------------------------------------------------------+ #
# |                             Spawners                            | #
# +-----------------------------------------------------------------+ #
#######################################################################


#######################################################################
# +-----------------------------------------------------------------+ #
# |                             ModData                             | #
# +-----------------------------------------------------------------+ #
#######################################################################

