
#######################################################################
# +-----------------------------------------------------------------+ #
# |                            BO4 object                           | #
# +-----------------------------------------------------------------+ #
#######################################################################

Author: NLBlackEagle

Description: No description given

SettingsMode: WriteWithoutComments


#######################################################################
# +-----------------------------------------------------------------+ #
# |                          Main settings                          | #
# +-----------------------------------------------------------------+ #
#######################################################################

FixedRotation: NORTH

Frequency: 0

SpawnHeight: highestSolidBlock

UseCenterForHighestBlock: true

##############################
# Height Limits for the BO4. #
##############################

MinHeight: 0

MaxHeight: 255

InheritBO3: 

InheritBO3Rotation: NORTH

OverrideChildSettings: true

OverrideParentHeight: false

CanOverride: true

BranchFrequency: 0

BranchFrequencyGroup: 

MustBeBelowOther: false

MustBeInside: 

CannotBeInside: 

ReplacesBO3: 

MustBeInsideWorldBorders: false

CanSpawnOnWater: false

SpawnOnWaterOnly: false

SpawnUnderWater: false

SpawnAtWaterLevel: false

HeightOffset: 0

RemoveAir: true

ReplaceAbove: 

ReplaceBelow: SANDSTONE

ReplaceWithBiomeBlocks: false

ReplaceWithSurfaceBlock: GRASS

ReplaceWithGroundBlock: DIRT

ReplaceWithStoneBlock: STONE

SmoothRadius: 0

SmoothHeightOffset: 0

SmoothStartTop: false

SmoothStartWood: false

SmoothingSurfaceBlock: 

SmoothingGroundBlock: 

BO3Group: 

IsSpawnPoint: false

DoReplaceBlocks: true


#######################################################################
# +-----------------------------------------------------------------+ #
# |                              Blocks                             | #
# +-----------------------------------------------------------------+ #
#######################################################################

Block(-4,0,-3,SANDSTONE:0)
Block(-4,0,-2,SANDSTONE:0)
Block(-4,0,-1,SANDSTONE:0)
Block(-4,0,0,SANDSTONE:0)
Block(-4,0,1,SANDSTONE:0)
Block(-4,0,2,SANDSTONE:0)
Block(-4,0,3,SANDSTONE:0)
Block(-4,0,4,SANDSTONE:0)
Block(-4,0,5,SANDSTONE:0)
Block(-4,1,-3,SANDSTONE:0)
Block(-4,1,-2,SANDSTONE:0)
Block(-4,1,-1,SANDSTONE:0)
Block(-4,1,0,SANDSTONE:0)
Block(-4,1,1,SANDSTONE:0)
Block(-4,1,2,SANDSTONE:0)
Block(-4,1,3,SANDSTONE:0)
Block(-4,1,4,SANDSTONE:0)
Block(-4,1,5,SANDSTONE:0)
Block(-4,2,-3,SANDSTONE:0)
Block(-4,2,-2,SANDSTONE:0)
Block(-4,2,-1,SANDSTONE:0)
Block(-4,2,0,SANDSTONE:0)
Block(-4,2,1,SANDSTONE:0)
Block(-4,2,2,SANDSTONE:0)
Block(-4,2,3,SANDSTONE:0)
Block(-4,2,4,SANDSTONE:0)
Block(-4,2,5,SANDSTONE:0)
Block(-4,3,-3,SANDSTONE:0)
Block(-4,3,-2,SANDSTONE:0)
Block(-4,3,-1,SANDSTONE:0)
Block(-4,3,0,SANDSTONE:0)
Block(-4,3,1,SANDSTONE:0)
Block(-4,3,2,SANDSTONE:0)
Block(-4,3,3,SANDSTONE:0)
Block(-4,3,4,SANDSTONE:0)
Block(-4,3,5,SANDSTONE:0)
Block(-4,4,-3,SANDSTONE:0)
Block(-4,4,-2,SANDSTONE:0)
Block(-4,4,-1,SANDSTONE:0)
Block(-4,4,0,SANDSTONE:0)
Block(-4,4,1,SANDSTONE:0)
Block(-4,4,2,SANDSTONE:0)
Block(-4,4,3,SANDSTONE:0)
Block(-4,4,4,SANDSTONE:0)
Block(-4,4,5,SANDSTONE:0)
Block(-3,0,-3,SANDSTONE:0)
Block(-3,0,-2,STONE:2)
Block(-3,0,-1,STEP:1)
Block(-3,0,0,STEP:1)
Block(-3,0,1,STONE:2)
Block(-3,0,2,SANDSTONE:0)
Block(-3,0,3,SANDSTONE:0)
Block(-3,0,4,SANDSTONE:0)
Block(-3,0,5,SANDSTONE:0)
Block(-3,1,-3,SANDSTONE:0)
Block(-3,1,-2,inspirations:carpeted_trapdoor_white:3)
Block(-3,1,1,inspirations:carpeted_trapdoor_white:0)
Block(-3,1,2,SANDSTONE:0)
Block(-3,1,3,SANDSTONE:0)
Block(-3,1,4,SANDSTONE:0)
Block(-3,1,5,STEP:1)
Block(-3,2,-3,SANDSTONE:0)
Block(-3,2,-2,STEP:9)
Block(-3,2,-1,STEP:9)
Block(-3,2,0,STEP:9)
Block(-3,2,1,STEP:9)
Block(-3,2,2,SANDSTONE:0)
Block(-3,2,3,STEP:1)
Block(-3,3,-3,SANDSTONE:0)
Block(-3,3,-2,SANDSTONE:0)
Block(-3,3,-1,SANDSTONE:0)
Block(-3,3,0,SANDSTONE:0)
Block(-3,3,1,STEP:1)
Block(-3,4,-3,SANDSTONE:0)
Block(-2,0,-3,SANDSTONE:0)
Block(-2,0,-2,STONE:2)
Block(-2,0,-1,STEP:1)
Block(-2,0,0,STEP:1)
Block(-2,0,1,STONE:2)
Block(-2,0,2,SANDSTONE:0)
Block(-2,0,3,SANDSTONE:0)
Block(-2,0,4,SANDSTONE:0)
Block(-2,0,5,SANDSTONE:0)
Block(-2,1,-3,SANDSTONE:0)
Block(-2,1,-2,inspirations:carpeted_trapdoor_red:1)
Block(-2,1,1,inspirations:carpeted_trapdoor_red:0)
Block(-2,1,2,SANDSTONE:0)
Block(-2,1,3,SANDSTONE:0)
Block(-2,1,4,SANDSTONE:0)
Block(-2,1,5,STEP:1)
Block(-2,2,-3,SANDSTONE:0)
Block(-2,2,2,SANDSTONE:0)
Block(-2,2,3,STEP:1)
Block(-2,3,-3,SANDSTONE:0)
Block(-2,3,-2,SANDSTONE:0)
Block(-2,3,-1,SANDSTONE:0)
Block(-2,3,0,SANDSTONE:0)
Block(-2,3,1,STEP:1)
Block(-2,4,-3,SANDSTONE:0)
Block(-1,0,-3,SANDSTONE:0)
Block(-1,0,-2,STONE:2)
Block(-1,0,-1,STEP:1)
Block(-1,0,0,STEP:1)
Block(-1,0,1,STONE:2)
Block(-1,0,2,SANDSTONE:0)
Block(-1,0,3,SANDSTONE:0)
Block(-1,0,4,SANDSTONE:0)
Block(-1,0,5,SANDSTONE:0)
Block(-1,1,-3,SANDSTONE:0)
Block(-1,1,-2,inspirations:carpeted_trapdoor_red:1)
Block(-1,1,1,inspirations:carpeted_trapdoor_red:0)
Block(-1,1,2,SANDSTONE:0)
Block(-1,1,3,SANDSTONE:0)
Block(-1,1,4,SANDSTONE:0)
Block(-1,1,5,SANDSTONE:0)
Block(-1,2,-3,SANDSTONE:0)
Block(-1,2,-2,STEP:9)
Block(-1,2,-1,STEP:9)
Block(-1,2,0,STEP:9)
Block(-1,2,1,STEP:9)
Block(-1,2,2,SANDSTONE:0)
Block(-1,2,3,SANDSTONE:0)
Block(-1,2,4,SANDSTONE:0)
Block(-1,2,5,SANDSTONE:0)
Block(-1,3,-3,SANDSTONE:0)
Block(-1,3,-2,SANDSTONE:0)
Block(-1,3,-1,SANDSTONE:0)
Block(-1,3,0,SANDSTONE:0)
Block(-1,3,1,SANDSTONE:0)
Block(-1,3,2,SANDSTONE:0)
Block(-1,3,3,SANDSTONE:0)
Block(-1,3,4,SANDSTONE:0)
Block(-1,3,5,SANDSTONE:0)
Block(-1,4,-3,SANDSTONE:0)
Block(-1,4,5,SANDSTONE:0)
Block(0,0,-3,SANDSTONE:0)
Block(0,0,-2,FURNACE:3)
Block(0,0,-1,STEP:1)
Block(0,0,0,STEP:1)
Block(0,0,1,FURNACE:2)
Block(0,0,2,SANDSTONE:0)
Block(0,0,3,STEP:1)
Block(0,0,4,SANDSTONE:0)
Block(0,0,5,SANDSTONE:0)
Block(0,1,-3,SANDSTONE:0)
Block(0,1,-2,realistictorches:torch_smoldering:5)
Block(0,1,2,BOOKSHELF:0)
Block(0,1,5,WOODEN_DOOR:1)
Block(0,2,-3,SANDSTONE:0)
Block(0,2,2,BOOKSHELF:0)
Block(0,2,5,WOODEN_DOOR:9)
Block(0,3,-3,SANDSTONE:0)
Block(0,3,-2,SANDSTONE:0)
Block(0,3,-1,SANDSTONE:0)
Block(0,3,0,SANDSTONE:0)
Block(0,3,1,SANDSTONE:0)
Block(0,3,2,SANDSTONE:0)
Block(0,3,3,SANDSTONE:0)
Block(0,3,4,SANDSTONE:0)
Block(0,3,5,SANDSTONE:0)
Block(0,4,-3,SANDSTONE:0)
Block(0,4,5,SANDSTONE:0)
Block(1,0,-3,SANDSTONE:0)
Block(1,0,-2,SANDSTONE:0)
Block(1,0,-1,SANDSTONE_STAIRS:0)
Block(1,0,0,SANDSTONE_STAIRS:0)
Block(1,0,1,SANDSTONE:0)
Block(1,0,2,SANDSTONE:0)
Block(1,0,3,STEP:1)
Block(1,0,4,SANDSTONE:0)
Block(1,0,5,SANDSTONE:0)
Block(1,1,-3,SANDSTONE:0)
Block(1,1,-2,SANDSTONE:0)
Block(1,1,1,SANDSTONE:0)
Block(1,1,2,SANDSTONE:0)
Block(1,1,4,SANDSTONE:0)
Block(1,1,5,SANDSTONE:0)
Block(1,2,-3,SANDSTONE:0)
Block(1,2,-2,SANDSTONE:0)
Block(1,2,-1,TRAP_DOOR:11)
Block(1,2,0,TRAP_DOOR:11)
Block(1,2,1,SANDSTONE:0)
Block(1,2,2,SANDSTONE:0)
Block(1,2,4,SANDSTONE:0)
Block(1,2,5,SANDSTONE:0)
Block(1,3,-3,SANDSTONE:0)
Block(1,3,-2,SANDSTONE:0)
Block(1,3,-1,SANDSTONE:0)
Block(1,3,0,SANDSTONE:0)
Block(1,3,1,SANDSTONE:0)
Block(1,3,2,SANDSTONE:0)
Block(1,3,3,SANDSTONE:0)
Block(1,3,4,SANDSTONE:0)
Block(1,3,5,SANDSTONE:0)
Block(1,4,-3,SANDSTONE:0)
Block(1,4,-2,SANDSTONE:0)
Block(1,4,-1,SANDSTONE:0)
Block(1,4,0,SANDSTONE:0)
Block(1,4,1,WOODEN_DOOR:0)
Block(1,4,2,SANDSTONE:0)
Block(1,4,3,SANDSTONE:0)
Block(1,4,4,SANDSTONE:0)
Block(1,4,5,SANDSTONE:0)
Block(1,5,-3,SANDSTONE:0)
Block(1,5,-2,SANDSTONE:0)
Block(1,5,-1,IRON_FENCE:0)
Block(1,5,0,SANDSTONE:0)
Block(1,5,1,WOODEN_DOOR:11)
Block(1,5,2,SANDSTONE:0)
Block(1,5,3,IRON_FENCE:0)
Block(1,5,4,SANDSTONE:0)
Block(1,5,5,SANDSTONE:0)
Block(1,6,-3,SANDSTONE:0)
Block(1,6,-2,SANDSTONE:0)
Block(1,6,-1,SANDSTONE:0)
Block(1,6,0,SANDSTONE:0)
Block(1,6,1,SANDSTONE:0)
Block(1,6,2,SANDSTONE:0)
Block(1,6,3,SANDSTONE:0)
Block(1,6,4,SANDSTONE:0)
Block(1,6,5,SANDSTONE:0)
Block(1,7,-3,STEP:1)
Block(1,7,-2,STEP:1)
Block(1,7,-1,STEP:1)
Block(1,7,0,STEP:1)
Block(1,7,1,STEP:1)
Block(1,7,2,STEP:1)
Block(1,7,3,STEP:1)
Block(1,7,4,STEP:1)
Block(1,7,5,STEP:1)
Block(2,0,-4,quark:sandy_bricks:0)
Block(2,0,-3,SANDSTONE:0)
Block(2,0,-2,SANDSTONE:0)
Block(2,0,-1,SANDSTONE:0)
Block(2,0,0,SANDSTONE:0)
Block(2,0,1,SANDSTONE:0)
Block(2,0,2,SANDSTONE_STAIRS:3)
Block(2,0,3,SANDSTONE_STAIRS:0)
Block(2,0,4,SANDSTONE_STAIRS:2)
Block(2,0,5,SANDSTONE:0)
Block(2,1,-4,quark:sandy_bricks:0)
Block(2,1,-3,quark:sandy_bricks:0)
Block(2,1,-2,quark:sandy_bricks:0)
Block(2,1,5,SANDSTONE:0)
Block(2,2,-4,quark:sandy_bricks:0)
Block(2,2,-3,quark:sandy_bricks:0)
Block(2,2,-2,quark:sandy_bricks:0)
Block(2,2,-1,WALL_BANNER:5)
Block(2,2,0,WALL_BANNER:5)
Block(2,2,5,SANDSTONE:0)
Block(2,3,-4,quark:sandy_bricks:0)
Block(2,3,-3,quark:sandy_bricks:0)
Block(2,3,-2,quark:sandy_bricks:0)
Block(2,3,-1,STEP:9)
Block(2,3,0,STEP:10)
Block(2,3,1,STEP:10)
Block(2,3,2,STEP:10)
Block(2,3,3,STEP:10)
Block(2,3,4,STEP:10)
Block(2,3,5,SANDSTONE:0)
Block(2,4,-4,quark:sandy_bricks:0)
Block(2,4,-3,quark:sandy_bricks:0)
Block(2,4,-2,quark:sandy_bricks_stairs:3)
Block(2,4,2,STEP:9)
Block(2,4,3,STEP:9)
Block(2,4,4,FURNACE:5)
Block(2,4,5,SANDSTONE:0)
Block(2,5,-4,quark:sandy_bricks:0)
Block(2,5,-3,quark:sandy_bricks:0)
Block(2,5,-2,quark:sandy_bricks_stairs:7)
Block(2,5,4,realistictorches:torch_smoldering:5)
Block(2,5,5,SANDSTONE:0)
Block(2,6,-4,quark:sandy_bricks:0)
Block(2,6,-3,quark:sandy_bricks:0)
Block(2,6,-2,quark:sandy_bricks:0)
Block(2,6,-1,STEP:9)
Block(2,6,0,STEP:10)
Block(2,6,1,STEP:10)
Block(2,6,2,STEP:10)
Block(2,6,3,STEP:10)
Block(2,6,4,STEP:10)
Block(2,6,5,SANDSTONE:0)
Block(2,7,-4,quark:sandy_bricks_stairs:2)
Block(2,7,-3,quark:sandy_bricks_stairs:0)
Block(2,7,-2,quark:sandy_bricks_stairs:3)
Block(2,7,-1,STEP:1)
Block(2,7,5,STEP:1)
Block(3,0,-4,quark:sandy_bricks:0)
Block(3,0,-3,SANDSTONE:0)
Block(3,0,-2,SANDSTONE:0)
Block(3,0,-1,SANDSTONE:0)
Block(3,0,0,SANDSTONE:0)
Block(3,0,1,SANDSTONE:0)
Block(3,0,2,SANDSTONE:0)
Block(3,0,3,SANDSTONE:0)
Block(3,0,4,SANDSTONE:0)
Block(3,0,5,SANDSTONE:0)
Block(3,1,-4,quark:sandy_bricks:0)
Block(3,1,-3,simpledifficulty:campfire:7)
Block(3,1,-2,quark:sandy_bricks_stairs:3)
Block(3,1,0,variedcommodities:chair:4)
Block(3,1,5,SANDSTONE:0)
Block(3,2,-4,quark:sandy_bricks_stairs:2)
Block(3,2,5,IRON_FENCE:0)
Block(3,3,-4,quark:sandy_bricks_stairs:6)
Block(3,3,-3,IRON_TRAPDOOR:11)
Block(3,3,-2,quark:sandy_bricks:0)
Block(3,3,-1,STEP:9)
Block(3,3,0,STEP:10)
Block(3,3,1,STEP:10)
Block(3,3,2,STEP:10)
Block(3,3,3,STEP:10)
Block(3,3,4,STEP:10)
Block(3,3,5,SANDSTONE:0)
Block(3,4,-4,quark:sandy_bricks:0)
Block(3,4,-3,simpledifficulty:campfire:13)
Block(3,4,1,TRAP_DOOR:6)
Block(3,4,2,TRAP_DOOR:6)
Block(3,4,3,TRAP_DOOR:6)
Block(3,4,4,TRAP_DOOR:6)
Block(3,4,5,SANDSTONE:0)
Block(3,5,-4,quark:sandy_bricks_stairs:2)
Block(3,5,-2,quark:sandy_bricks_stairs:7)
Block(3,5,5,SANDSTONE:0)
Block(3,6,-4,quark:sandy_bricks_stairs:6)
Block(3,6,-3,quark:sandy_bricks_wall:0)
Block(3,6,-2,quark:sandy_bricks:0)
Block(3,6,-1,STEP:9)
Block(3,6,0,STEP:10)
Block(3,6,1,STEP:10)
Block(3,6,2,STEP:10)
Block(3,6,3,STEP:10)
Block(3,6,4,STEP:10)
Block(3,6,5,SANDSTONE:0)
Block(3,7,-4,quark:sandy_bricks_stairs:2)
Block(3,7,-3,quark:sandy_bricks_wall:0)
Block(3,7,-2,quark:sandy_bricks_stairs:3)
Block(3,7,-1,STEP:1)
Block(3,7,5,STEP:1)
Block(3,8,-3,quark:sandy_bricks_wall:0)
Block(3,9,-3,quark:sandy_bricks_slab:0)
Block(4,0,-4,quark:sandy_bricks:0)
Block(4,0,-3,SANDSTONE:0)
Block(4,0,-2,SANDSTONE:0)
Block(4,0,-1,SANDSTONE:0)
Block(4,0,0,SANDSTONE:0)
Block(4,0,1,SANDSTONE:0)
Block(4,0,2,SANDSTONE:0)
Block(4,0,3,SANDSTONE:0)
Block(4,0,4,SANDSTONE:0)
Block(4,0,5,SANDSTONE:0)
Block(4,1,-4,quark:sandy_bricks:0)
Block(4,1,-3,quark:sandy_bricks:0)
Block(4,1,-2,quark:sandy_bricks:0)
Block(4,1,2,SANDSTONE_STAIRS:6)
Block(4,1,3,SANDSTONE_STAIRS:3)
Block(4,1,5,SANDSTONE:0)
Block(4,2,-4,quark:sandy_bricks:0)
Block(4,2,-3,quark:sandy_bricks:0)
Block(4,2,-2,quark:sandy_bricks:0)
Block(4,2,1,SANDSTONE_STAIRS:6)
Block(4,2,2,SANDSTONE_STAIRS:3)
Block(4,2,5,SANDSTONE:0)
Block(4,3,-4,quark:sandy_bricks:0)
Block(4,3,-3,quark:sandy_bricks:0)
Block(4,3,-2,quark:sandy_bricks:0)
Block(4,3,-1,STEP:9)
Block(4,3,0,STEP:10)
Block(4,3,1,SANDSTONE_STAIRS:3)
Block(4,3,5,SANDSTONE:0)
Block(4,4,-4,quark:sandy_bricks:0)
Block(4,4,-3,quark:sandy_bricks:0)
Block(4,4,-2,quark:sandy_bricks_stairs:3)
Block(4,4,5,SANDSTONE:0)
Block(4,5,-4,quark:sandy_bricks:0)
Block(4,5,-3,quark:sandy_bricks:0)
Block(4,5,-2,quark:sandy_bricks_stairs:7)
Block(4,5,5,SANDSTONE:0)
Block(4,6,-4,quark:sandy_bricks:0)
Block(4,6,-3,quark:sandy_bricks:0)
Block(4,6,-2,quark:sandy_bricks:0)
Block(4,6,-1,STEP:9)
Block(4,6,0,STEP:10)
Block(4,6,1,STEP:10)
Block(4,6,2,STEP:10)
Block(4,6,3,STEP:10)
Block(4,6,4,STEP:10)
Block(4,6,5,SANDSTONE:0)
Block(4,7,-4,quark:sandy_bricks_stairs:1)
Block(4,7,-3,quark:sandy_bricks_stairs:1)
Block(4,7,-2,quark:sandy_bricks_stairs:1)
Block(4,7,-1,STEP:1)
Block(4,7,5,STEP:1)
Block(5,0,-3,SANDSTONE:0)
Block(5,0,-2,SANDSTONE:0)
Block(5,0,-1,SANDSTONE:0)
Block(5,0,0,SANDSTONE:0)
Block(5,0,1,SANDSTONE:0)
Block(5,0,2,SANDSTONE:0)
Block(5,0,3,SANDSTONE:0)
Block(5,0,4,SANDSTONE:0)
Block(5,0,5,SANDSTONE:0)
Block(5,1,-3,SANDSTONE:0)
Block(5,1,-2,SANDSTONE:0)
Block(5,1,-1,SANDSTONE:0)
Block(5,1,0,SANDSTONE:0)
Block(5,1,1,SANDSTONE:0)
Block(5,1,2,SANDSTONE:0)
Block(5,1,3,SANDSTONE:0)
Block(5,1,4,SANDSTONE:0)
Block(5,1,5,SANDSTONE:0)
Block(5,2,-3,SANDSTONE:0)
Block(5,2,-2,SANDSTONE:0)
Block(5,2,-1,SANDSTONE:0)
Block(5,2,0,SANDSTONE:0)
Block(5,2,1,SANDSTONE:0)
Block(5,2,2,SANDSTONE:0)
Block(5,2,3,IRON_FENCE:0)
Block(5,2,4,SANDSTONE:0)
Block(5,2,5,SANDSTONE:0)
Block(5,3,-3,SANDSTONE:0)
Block(5,3,-2,SANDSTONE:0)
Block(5,3,-1,SANDSTONE:0)
Block(5,3,0,SANDSTONE:0)
Block(5,3,1,SANDSTONE:0)
Block(5,3,2,SANDSTONE:0)
Block(5,3,3,SANDSTONE:0)
Block(5,3,4,SANDSTONE:0)
Block(5,3,5,SANDSTONE:0)
Block(5,4,-3,SANDSTONE:0)
Block(5,4,-2,SANDSTONE:0)
Block(5,4,-1,SANDSTONE:0)
Block(5,4,0,SANDSTONE:0)
Block(5,4,1,SANDSTONE:0)
Block(5,4,2,SANDSTONE:0)
Block(5,4,3,SANDSTONE:0)
Block(5,4,4,SANDSTONE:0)
Block(5,4,5,SANDSTONE:0)
Block(5,5,-3,SANDSTONE:0)
Block(5,5,-2,SANDSTONE:0)
Block(5,5,-1,IRON_FENCE:0)
Block(5,5,0,SANDSTONE:0)
Block(5,5,1,SANDSTONE:0)
Block(5,5,2,SANDSTONE:0)
Block(5,5,3,IRON_FENCE:0)
Block(5,5,4,SANDSTONE:0)
Block(5,5,5,SANDSTONE:0)
Block(5,6,-3,SANDSTONE:0)
Block(5,6,-2,SANDSTONE:0)
Block(5,6,-1,SANDSTONE:0)
Block(5,6,0,SANDSTONE:0)
Block(5,6,1,SANDSTONE:0)
Block(5,6,2,SANDSTONE:0)
Block(5,6,3,SANDSTONE:0)
Block(5,6,4,SANDSTONE:0)
Block(5,6,5,SANDSTONE:0)
Block(5,7,-3,STEP:1)
Block(5,7,-2,STEP:1)
Block(5,7,-1,STEP:1)
Block(5,7,0,STEP:1)
Block(5,7,1,STEP:1)
Block(5,7,2,STEP:1)
Block(5,7,3,STEP:1)
Block(5,7,4,STEP:1)
Block(5,7,5,STEP:1)

#######################################################################
# +-----------------------------------------------------------------+ #
# |                             Branches                            | #
# +-----------------------------------------------------------------+ #
#######################################################################


#######################################################################
# +-----------------------------------------------------------------+ #
# |                             Entities                            | #
# +-----------------------------------------------------------------+ #
#######################################################################


#######################################################################
# +-----------------------------------------------------------------+ #
# |                            Particles                            | #
# +-----------------------------------------------------------------+ #
#######################################################################


#######################################################################
# +-----------------------------------------------------------------+ #
# |                             Spawners                            | #
# +-----------------------------------------------------------------+ #
#######################################################################


#######################################################################
# +-----------------------------------------------------------------+ #
# |                             ModData                             | #
# +-----------------------------------------------------------------+ #
#######################################################################

