
#######################################################################
# +-----------------------------------------------------------------+ #
# |                            BO4 object                           | #
# +-----------------------------------------------------------------+ #
#######################################################################

Author: NLBlackEagle

Description: No description given

SettingsMode: WriteWithoutComments


#######################################################################
# +-----------------------------------------------------------------+ #
# |                          Main settings                          | #
# +-----------------------------------------------------------------+ #
#######################################################################

FixedRotation: 

Frequency: 0

SpawnHeight: highestSolidBlock

UseCenterForHighestBlock: true

##############################
# Height Limits for the BO4. #
##############################

MinHeight: 0

MaxHeight: 255

InheritBO3: 

InheritBO3Rotation: NORTH

OverrideChildSettings: true

OverrideParentHeight: false

CanOverride: true

BranchFrequency: 0

BranchFrequencyGroup: 

MustBeBelowOther: false

MustBeInside: 

CannotBeInside: 

ReplacesBO3: 

MustBeInsideWorldBorders: false

CanSpawnOnWater: false

SpawnOnWaterOnly: false

SpawnUnderWater: false

SpawnAtWaterLevel: false

HeightOffset: 0

RemoveAir: true

ReplaceAbove: 

ReplaceBelow: SANDSTONE

ReplaceWithBiomeBlocks: false

ReplaceWithSurfaceBlock: GRASS

ReplaceWithGroundBlock: DIRT

ReplaceWithStoneBlock: STONE

SmoothRadius: 0

SmoothHeightOffset: 0

SmoothStartTop: false

SmoothStartWood: false

SmoothingSurfaceBlock: 

SmoothingGroundBlock: 

BO3Group: 

IsSpawnPoint: false

DoReplaceBlocks: true


#######################################################################
# +-----------------------------------------------------------------+ #
# |                              Blocks                             | #
# +-----------------------------------------------------------------+ #
#######################################################################

Block(-4,0,-4,SANDSTONE:0)
Block(-4,0,-3,SANDSTONE:0)
Block(-4,0,-2,SANDSTONE:0)
Block(-4,0,-1,SANDSTONE:0)
Block(-4,0,0,SANDSTONE:0)
Block(-4,0,1,SANDSTONE:0)
Block(-4,0,2,SANDSTONE:0)
Block(-4,0,3,SANDSTONE:0)
Block(-4,0,4,SANDSTONE:0)
Block(-4,1,-4,SANDSTONE:2)
Block(-4,1,-3,STEP:1)
Block(-4,1,-2,STEP:1)
Block(-4,1,-1,STEP:1)
Block(-4,1,0,STEP:1)
Block(-4,1,1,STEP:1)
Block(-4,1,2,STEP:1)
Block(-4,1,3,STEP:1)
Block(-4,1,4,SANDSTONE:2)
Block(-3,0,-4,SANDSTONE:0)
Block(-3,0,-3,SANDSTONE:0)
Block(-3,0,-2,SANDSTONE:0)
Block(-3,0,-1,SANDSTONE:0)
Block(-3,0,0,SANDSTONE:0)
Block(-3,0,1,SANDSTONE:0)
Block(-3,0,2,SANDSTONE:0)
Block(-3,0,3,SANDSTONE:0)
Block(-3,0,4,SANDSTONE:0)
Block(-3,1,-4,STEP:1)
Block(-3,1,-3,SANDSTONE:2)
Block(-3,1,-2,SANDSTONE:2)
Block(-3,1,-1,SANDSTONE:2)
Block(-3,1,0,SANDSTONE:2)
Block(-3,1,1,SANDSTONE:2)
Block(-3,1,2,SANDSTONE:2)
Block(-3,1,3,SANDSTONE:2)
Block(-3,1,4,STEP:1)
Block(-3,2,-3,quark:sandy_bricks_wall:0)
Block(-3,2,-1,biomesoplenty:redwood_fence:0)
Block(-3,2,0,biomesoplenty:redwood_fence:0)
Block(-3,2,1,biomesoplenty:redwood_fence:0)
Block(-3,2,2,biomesoplenty:redwood_fence:0)
Block(-3,2,3,quark:sandy_bricks_wall:0)
Block(-3,3,-3,quark:sandy_bricks_wall:0)
Block(-3,3,3,quark:sandy_bricks_wall:0)
Block(-3,4,-3,quark:sandy_bricks_wall:0)
Block(-3,4,3,quark:sandy_bricks_wall:0)
Block(-3,5,-3,quark:sandy_bricks_wall:0)
Block(-3,5,3,quark:sandy_bricks_wall:0)
Block(-3,6,-3,STEP:1)
Block(-3,6,-2,STEP:1)
Block(-3,6,-1,STEP:1)
Block(-3,6,0,STEP:1)
Block(-3,6,1,STEP:1)
Block(-3,6,2,STEP:1)
Block(-3,6,3,STEP:1)
Block(-2,0,-4,SANDSTONE:0)
Block(-2,0,-3,SANDSTONE:0)
Block(-2,0,-2,SANDSTONE:0)
Block(-2,0,-1,SANDSTONE:0)
Block(-2,0,0,SANDSTONE:0)
Block(-2,0,1,SANDSTONE:0)
Block(-2,0,2,SANDSTONE:0)
Block(-2,0,3,SANDSTONE:0)
Block(-2,0,4,SANDSTONE:0)
Block(-2,1,-4,STEP:1)
Block(-2,1,-3,SANDSTONE:2)
Block(-2,1,-2,STATIONARY_WATER:0)
Block(-2,1,-1,STATIONARY_WATER:0)
Block(-2,1,0,STATIONARY_WATER:0)
Block(-2,1,1,STATIONARY_WATER:0)
Block(-2,1,2,STATIONARY_WATER:0)
Block(-2,1,3,SANDSTONE:2)
Block(-2,1,4,STEP:1)
Block(-2,2,3,biomesoplenty:redwood_fence:0)
Block(-2,6,-3,STEP:1)
Block(-2,6,-2,SANDSTONE:0)
Block(-2,6,-1,SANDSTONE:0)
Block(-2,6,0,SANDSTONE:0)
Block(-2,6,1,SANDSTONE:0)
Block(-2,6,2,SANDSTONE:0)
Block(-2,6,3,STEP:1)
Block(-2,7,0,STEP:1)
Block(-1,0,-4,SANDSTONE:0)
Block(-1,0,-3,SANDSTONE:0)
Block(-1,0,-2,SANDSTONE:0)
Block(-1,0,-1,SANDSTONE:0)
Block(-1,0,0,SANDSTONE:0)
Block(-1,0,1,SANDSTONE:0)
Block(-1,0,2,SANDSTONE:0)
Block(-1,0,3,SANDSTONE:0)
Block(-1,0,4,SANDSTONE:0)
Block(-1,1,-4,STEP:1)
Block(-1,1,-3,quark:sandy_bricks:0)
Block(-1,1,-2,SANDSTONE:2)
Block(-1,1,-1,STATIONARY_WATER:0)
Block(-1,1,0,STATIONARY_WATER:0)
Block(-1,1,1,STATIONARY_WATER:0)
Block(-1,1,2,STATIONARY_WATER:0)
Block(-1,1,3,SANDSTONE:2)
Block(-1,1,4,STEP:1)
Block(-1,2,-2,quark:sandy_bricks_slab:0)
Block(-1,2,3,biomesoplenty:redwood_fence:0)
Block(-1,5,0,quark:sandy_bricks_wall:0)
Block(-1,6,-3,STEP:1)
Block(-1,6,-2,SANDSTONE:0)
Block(-1,6,0,realistictorches:torch_smoldering:5)
Block(-1,6,2,SANDSTONE:0)
Block(-1,6,3,STEP:1)
Block(-1,7,-1,inspirations:glass_trapdoor:0)
Block(-1,7,0,STEP:1)
Block(-1,7,1,inspirations:glass_trapdoor:1)
Block(0,0,-4,SANDSTONE:0)
Block(0,0,-3,SANDSTONE:0)
Block(0,0,-2,SANDSTONE:0)
Block(0,0,-1,SANDSTONE:0)
Block(0,0,0,SANDSTONE:0)
Block(0,0,1,SANDSTONE:0)
Block(0,0,2,SANDSTONE:0)
Block(0,0,3,SANDSTONE:0)
Block(0,0,4,SANDSTONE:0)
Block(0,1,-4,STEP:1)
Block(0,1,-2,FURNACE:2)
Block(0,1,-1,STATIONARY_WATER:0)
Block(0,1,0,STATIONARY_WATER:0)
Block(0,1,1,STATIONARY_WATER:0)
Block(0,1,2,STATIONARY_WATER:0)
Block(0,1,3,SANDSTONE:2)
Block(0,1,4,STEP:1)
Block(0,2,-2,quark:sandy_bricks_slab_double:0)
Block(0,2,3,biomesoplenty:redwood_fence:0)
Block(0,3,-2,quark:sandy_bricks_wall:0)
Block(0,4,-2,quark:sandy_bricks_wall:0)
Block(0,5,-2,quark:sandy_bricks_wall:0)
Block(0,5,0,quark:sandy_bricks_wall:0)
Block(0,6,-3,STEP:1)
Block(0,6,-2,DOUBLE_STEP:1)
Block(0,6,0,quark:sandy_bricks_wall:0)
Block(0,6,2,SANDSTONE:0)
Block(0,6,3,STEP:1)
Block(0,7,-2,quark:sandy_bricks_wall:0)
Block(0,7,-1,STEP:1)
Block(0,7,0,SANDSTONE:0)
Block(0,7,1,STEP:1)
Block(0,7,2,STEP:1)
Block(1,0,-4,SANDSTONE:0)
Block(1,0,-3,SANDSTONE:0)
Block(1,0,-2,SANDSTONE:0)
Block(1,0,-1,SANDSTONE:0)
Block(1,0,0,SANDSTONE:0)
Block(1,0,1,SANDSTONE:0)
Block(1,0,2,SANDSTONE:0)
Block(1,0,3,SANDSTONE:0)
Block(1,0,4,SANDSTONE:0)
Block(1,1,-4,STEP:1)
Block(1,1,-3,quark:sandy_bricks:0)
Block(1,1,-2,SANDSTONE:2)
Block(1,1,-1,STATIONARY_WATER:0)
Block(1,1,0,STATIONARY_WATER:0)
Block(1,1,1,STATIONARY_WATER:0)
Block(1,1,2,STATIONARY_WATER:0)
Block(1,1,3,SANDSTONE:2)
Block(1,1,4,STEP:1)
Block(1,2,-2,quark:sandy_bricks_slab:0)
Block(1,5,0,quark:sandy_bricks_wall:0)
Block(1,6,-3,STEP:1)
Block(1,6,-2,SANDSTONE:0)
Block(1,6,0,realistictorches:torch_smoldering:5)
Block(1,6,2,SANDSTONE:0)
Block(1,6,3,STEP:1)
Block(1,7,-1,inspirations:glass_trapdoor:0)
Block(1,7,0,STEP:1)
Block(1,7,1,inspirations:glass_trapdoor:1)
Block(2,0,-4,SANDSTONE:0)
Block(2,0,-3,SANDSTONE:0)
Block(2,0,-2,SANDSTONE:0)
Block(2,0,-1,SANDSTONE:0)
Block(2,0,0,SANDSTONE:0)
Block(2,0,1,SANDSTONE:0)
Block(2,0,2,SANDSTONE:0)
Block(2,0,3,SANDSTONE:0)
Block(2,0,4,SANDSTONE:0)
Block(2,1,-4,STEP:1)
Block(2,1,-3,SANDSTONE:2)
Block(2,1,-2,STATIONARY_WATER:0)
Block(2,1,-1,STATIONARY_WATER:0)
Block(2,1,0,STATIONARY_WATER:0)
Block(2,1,1,STATIONARY_WATER:0)
Block(2,1,2,STATIONARY_WATER:0)
Block(2,1,3,SANDSTONE:2)
Block(2,1,4,STEP:1)
Block(2,6,-3,STEP:1)
Block(2,6,-2,SANDSTONE:0)
Block(2,6,-1,SANDSTONE:0)
Block(2,6,0,SANDSTONE:0)
Block(2,6,1,SANDSTONE:0)
Block(2,6,2,SANDSTONE:0)
Block(2,6,3,STEP:1)
Block(2,7,0,STEP:1)
Block(3,0,-4,SANDSTONE:0)
Block(3,0,-3,SANDSTONE:0)
Block(3,0,-2,SANDSTONE:0)
Block(3,0,-1,SANDSTONE:0)
Block(3,0,0,SANDSTONE:0)
Block(3,0,1,SANDSTONE:0)
Block(3,0,2,SANDSTONE:0)
Block(3,0,3,SANDSTONE:0)
Block(3,0,4,SANDSTONE:0)
Block(3,1,-4,STEP:1)
Block(3,1,-3,SANDSTONE:2)
Block(3,1,-2,SANDSTONE:2)
Block(3,1,-1,SANDSTONE:2)
Block(3,1,0,SANDSTONE:2)
Block(3,1,1,SANDSTONE:2)
Block(3,1,2,SANDSTONE:2)
Block(3,1,3,SANDSTONE:2)
Block(3,1,4,STEP:1)
Block(3,2,-3,quark:sandy_bricks_wall:0)
Block(3,2,3,quark:sandy_bricks_wall:0)
Block(3,3,-3,quark:sandy_bricks_wall:0)
Block(3,3,3,quark:sandy_bricks_wall:0)
Block(3,4,-3,quark:sandy_bricks_wall:0)
Block(3,4,3,quark:sandy_bricks_wall:0)
Block(3,5,-3,quark:sandy_bricks_wall:0)
Block(3,5,3,quark:sandy_bricks_wall:0)
Block(3,6,-3,STEP:1)
Block(3,6,-2,STEP:1)
Block(3,6,-1,STEP:1)
Block(3,6,0,STEP:1)
Block(3,6,1,STEP:1)
Block(3,6,2,STEP:1)
Block(3,6,3,STEP:1)
Block(4,0,-4,SANDSTONE:0)
Block(4,0,-3,SANDSTONE:0)
Block(4,0,-2,SANDSTONE:0)
Block(4,0,-1,SANDSTONE:0)
Block(4,0,0,SANDSTONE:0)
Block(4,0,1,SANDSTONE:0)
Block(4,0,2,SANDSTONE:0)
Block(4,0,3,SANDSTONE:0)
Block(4,0,4,SANDSTONE:0)
Block(4,1,-4,SANDSTONE:2)
Block(4,1,-3,STEP:1)
Block(4,1,-2,STEP:1)
Block(4,1,-1,STEP:1)
Block(4,1,0,STEP:1)
Block(4,1,1,STEP:1)
Block(4,1,2,STEP:1)
Block(4,1,3,STEP:1)
Block(4,1,4,SANDSTONE:2)

#######################################################################
# +-----------------------------------------------------------------+ #
# |                             Branches                            | #
# +-----------------------------------------------------------------+ #
#######################################################################


#######################################################################
# +-----------------------------------------------------------------+ #
# |                             Entities                            | #
# +-----------------------------------------------------------------+ #
#######################################################################


#######################################################################
# +-----------------------------------------------------------------+ #
# |                            Particles                            | #
# +-----------------------------------------------------------------+ #
#######################################################################


#######################################################################
# +-----------------------------------------------------------------+ #
# |                             Spawners                            | #
# +-----------------------------------------------------------------+ #
#######################################################################


#######################################################################
# +-----------------------------------------------------------------+ #
# |                             ModData                             | #
# +-----------------------------------------------------------------+ #
#######################################################################

