
#######################################################################
# +-----------------------------------------------------------------+ #
# |                            BO4 object                           | #
# +-----------------------------------------------------------------+ #
#######################################################################

Author: NLBlackEagle

Description: No description given

SettingsMode: WriteWithoutComments


#######################################################################
# +-----------------------------------------------------------------+ #
# |                          Main settings                          | #
# +-----------------------------------------------------------------+ #
#######################################################################

FixedRotation: NORTH

Frequency: 0

SpawnHeight: highestSolidBlock

UseCenterForHighestBlock: true

##############################
# Height Limits for the BO4. #
##############################

MinHeight: 0

MaxHeight: 255

InheritBO3: 

InheritBO3Rotation: NORTH

OverrideChildSettings: true

OverrideParentHeight: false

CanOverride: true

BranchFrequency: 0

BranchFrequencyGroup: 

MustBeBelowOther: false

MustBeInside: 

CannotBeInside: 

ReplacesBO3: 

MustBeInsideWorldBorders: false

CanSpawnOnWater: false

SpawnOnWaterOnly: false

SpawnUnderWater: false

SpawnAtWaterLevel: false

HeightOffset: 0

RemoveAir: true

ReplaceAbove: 

ReplaceBelow: SANDSTONE

ReplaceWithBiomeBlocks: false

ReplaceWithSurfaceBlock: GRASS

ReplaceWithGroundBlock: DIRT

ReplaceWithStoneBlock: STONE

SmoothRadius: 0

SmoothHeightOffset: 0

SmoothStartTop: false

SmoothStartWood: false

SmoothingSurfaceBlock: 

SmoothingGroundBlock: 

BO3Group: 

IsSpawnPoint: false

DoReplaceBlocks: true


#######################################################################
# +-----------------------------------------------------------------+ #
# |                              Blocks                             | #
# +-----------------------------------------------------------------+ #
#######################################################################

Block(-5,0,0,SANDSTONE:0)
Block(-5,0,1,SANDSTONE:0)
Block(-5,0,2,SANDSTONE:0)
Block(-5,0,3,SANDSTONE:0)
Block(-5,0,4,SANDSTONE:0)
Block(-5,0,5,SANDSTONE:0)
Block(-5,0,6,SANDSTONE:0)
Block(-5,0,7,SANDSTONE:0)
Block(-5,1,0,quark:sandy_bricks_wall:0)
Block(-5,1,2,ACACIA_FENCE:0)
Block(-5,1,3,ACACIA_FENCE:0)
Block(-5,1,4,ACACIA_FENCE:0)
Block(-5,1,5,ACACIA_FENCE:0)
Block(-5,1,7,quark:sandy_bricks_wall:0)
Block(-5,2,0,quark:sandy_bricks_wall:0)
Block(-5,2,7,quark:sandy_bricks_wall:0)
Block(-5,3,0,SANDSTONE_STAIRS:2)
Block(-5,3,1,SANDSTONE_STAIRS:7)
Block(-5,3,6,SANDSTONE_STAIRS:6)
Block(-5,3,7,SANDSTONE_STAIRS:3)
Block(-5,4,1,SANDSTONE_STAIRS:2)
Block(-5,4,2,SANDSTONE_STAIRS:7)
Block(-5,4,5,SANDSTONE_STAIRS:6)
Block(-5,4,6,SANDSTONE_STAIRS:3)
Block(-5,5,2,SANDSTONE_STAIRS:2)
Block(-5,5,3,SANDSTONE_STAIRS:7)
Block(-5,5,4,SANDSTONE_STAIRS:6)
Block(-5,5,5,SANDSTONE_STAIRS:3)
Block(-5,6,3,STEP:1)
Block(-5,6,4,STEP:1)
Block(-4,0,0,SANDSTONE:0)
Block(-4,0,1,SANDSTONE:0)
Block(-4,0,2,SANDSTONE:0)
Block(-4,0,3,SANDSTONE:0)
Block(-4,0,4,SANDSTONE:0)
Block(-4,0,5,SANDSTONE:0)
Block(-4,0,6,SANDSTONE:0)
Block(-4,0,7,SANDSTONE:0)
Block(-4,1,0,ACACIA_FENCE:0)
Block(-4,1,1,SANDSTONE:0)
Block(-4,1,2,SANDSTONE:0)
Block(-4,1,3,SANDSTONE:0)
Block(-4,1,4,SANDSTONE:0)
Block(-4,1,5,SANDSTONE:0)
Block(-4,1,6,SANDSTONE:0)
Block(-4,2,1,SANDSTONE:0)
Block(-4,2,2,SANDSTONE:2)
Block(-4,2,3,STAINED_GLASS_PANE:0)
Block(-4,2,4,STAINED_GLASS_PANE:0)
Block(-4,2,5,SANDSTONE:2)
Block(-4,2,6,SANDSTONE:0)
Block(-4,3,0,SANDSTONE_STAIRS:2)
Block(-4,3,1,SANDSTONE:0)
Block(-4,3,2,SANDSTONE:0)
Block(-4,3,3,SANDSTONE:0)
Block(-4,3,4,SANDSTONE:0)
Block(-4,3,5,SANDSTONE:0)
Block(-4,3,6,SANDSTONE:0)
Block(-4,3,7,SANDSTONE_STAIRS:3)
Block(-4,4,1,SANDSTONE_STAIRS:2)
Block(-4,4,2,SANDSTONE:2)
Block(-4,4,3,SANDSTONE:2)
Block(-4,4,4,SANDSTONE:2)
Block(-4,4,5,SANDSTONE:2)
Block(-4,4,6,SANDSTONE_STAIRS:3)
Block(-4,5,2,SANDSTONE_STAIRS:2)
Block(-4,5,3,SANDSTONE:2)
Block(-4,5,4,SANDSTONE:2)
Block(-4,5,5,SANDSTONE_STAIRS:3)
Block(-4,6,3,STEP:1)
Block(-4,6,4,STEP:1)
Block(-3,0,0,SANDSTONE:0)
Block(-3,0,1,SANDSTONE:0)
Block(-3,0,2,SANDSTONE:0)
Block(-3,0,3,STEP:1)
Block(-3,0,4,STEP:1)
Block(-3,0,5,SANDSTONE_STAIRS:2)
Block(-3,0,6,SANDSTONE:0)
Block(-3,0,7,SANDSTONE:0)
Block(-3,1,0,ACACIA_FENCE:0)
Block(-3,1,1,SANDSTONE:0)
RandomBlock(-3,1,2,CHEST:3,20,CHEST:3,5,CHEST:3,30,CHEST:3,50,CHEST:3,100)
Block(-3,1,6,SANDSTONE:0)
Block(-3,1,7,SANDSTONE:2)
Block(-3,2,1,SANDSTONE:2)
Block(-3,2,6,SANDSTONE:2)
Block(-3,2,7,SANDSTONE:2)
Block(-3,3,0,SANDSTONE_STAIRS:2)
Block(-3,3,1,SANDSTONE:2)
Block(-3,3,2,SANDSTONE_STAIRS:7)
Block(-3,3,5,SANDSTONE_STAIRS:6)
Block(-3,3,6,SANDSTONE:2)
Block(-3,3,7,SANDSTONE_STAIRS:3)
Block(-3,4,1,SANDSTONE_STAIRS:2)
Block(-3,4,2,SANDSTONE:2)
Block(-3,4,3,SANDSTONE_STAIRS:7)
Block(-3,4,4,SANDSTONE_STAIRS:6)
Block(-3,4,5,SANDSTONE:2)
Block(-3,4,6,SANDSTONE_STAIRS:3)
Block(-3,5,2,SANDSTONE_STAIRS:2)
Block(-3,5,3,SANDSTONE:2)
Block(-3,5,4,SANDSTONE:2)
Block(-3,5,5,SANDSTONE_STAIRS:3)
Block(-3,6,3,STEP:1)
Block(-3,6,4,STEP:1)
Block(-2,0,-5,SANDSTONE:0)
Block(-2,0,-4,SANDSTONE:0)
Block(-2,0,-3,SANDSTONE:0)
Block(-2,0,-2,SANDSTONE:0)
Block(-2,0,-1,SANDSTONE:0)
Block(-2,0,0,SANDSTONE:0)
Block(-2,0,1,SANDSTONE:0)
Block(-2,0,2,SANDSTONE:0)
Block(-2,0,3,STEP:1)
Block(-2,0,4,STEP:1)
Block(-2,0,5,SANDSTONE_STAIRS:2)
Block(-2,0,6,SANDSTONE:0)
Block(-2,0,7,SANDSTONE:0)
Block(-2,1,-5,quark:sandy_bricks_wall:0)
Block(-2,1,-4,SANDSTONE:0)
Block(-2,1,-3,SANDSTONE:0)
Block(-2,1,-2,SANDSTONE:0)
Block(-2,1,-1,SANDSTONE:0)
Block(-2,1,0,SANDSTONE:0)
Block(-2,1,1,SANDSTONE:0)
RandomBlock(-2,1,2,CHEST:3,20,CHEST:3,5,CHEST:3,30,CHEST:3,50,CHEST:3,100)
Block(-2,1,6,WOODEN_DOOR:1)
Block(-2,2,-5,quark:sandy_bricks_wall:0)
Block(-2,2,-4,SANDSTONE:0)
Block(-2,2,-3,SANDSTONE:2)
Block(-2,2,-2,STAINED_GLASS_PANE:0)
Block(-2,2,-1,STAINED_GLASS_PANE:0)
Block(-2,2,0,SANDSTONE:2)
Block(-2,2,1,SANDSTONE:2)
Block(-2,2,6,WOODEN_DOOR:9)
Block(-2,3,-5,SANDSTONE_STAIRS:0)
Block(-2,3,-4,SANDSTONE_STAIRS:0)
Block(-2,3,-3,SANDSTONE_STAIRS:0)
Block(-2,3,-2,SANDSTONE_STAIRS:0)
Block(-2,3,-1,SANDSTONE_STAIRS:0)
Block(-2,3,0,SANDSTONE_STAIRS:2)
Block(-2,3,1,SANDSTONE:2)
Block(-2,3,2,SANDSTONE_STAIRS:7)
Block(-2,3,5,SANDSTONE_STAIRS:6)
Block(-2,3,6,SANDSTONE:2)
Block(-2,3,7,SANDSTONE_STAIRS:3)
Block(-2,4,1,SANDSTONE_STAIRS:2)
Block(-2,4,2,SANDSTONE:2)
Block(-2,4,3,SANDSTONE_STAIRS:7)
Block(-2,4,4,SANDSTONE_STAIRS:6)
Block(-2,4,5,SANDSTONE:2)
Block(-2,4,6,SANDSTONE_STAIRS:3)
Block(-2,5,2,SANDSTONE_STAIRS:2)
Block(-2,5,3,SANDSTONE:2)
Block(-2,5,4,SANDSTONE:2)
Block(-2,5,5,SANDSTONE_STAIRS:3)
Block(-2,6,3,STEP:1)
Block(-2,6,4,STEP:1)
Block(-1,0,-5,SANDSTONE:0)
Block(-1,0,-4,SANDSTONE:0)
Block(-1,0,-3,SANDSTONE:0)
Block(-1,0,-2,SANDSTONE:0)
Block(-1,0,-1,SANDSTONE:0)
Block(-1,0,0,SANDSTONE:0)
Block(-1,0,1,SANDSTONE:0)
Block(-1,0,2,SANDSTONE:0)
Block(-1,0,3,SANDSTONE_STAIRS:0)
Block(-1,0,4,SANDSTONE_STAIRS:0)
Block(-1,0,5,SANDSTONE:0)
Block(-1,0,6,SANDSTONE:0)
Block(-1,0,7,SANDSTONE:0)
Block(-1,1,-4,SANDSTONE:0)
Block(-1,1,-1,quark:sandy_bricks:0)
Block(-1,1,0,quark:sandy_bricks_slab:8)
Block(-1,1,1,quark:sandy_bricks_slab:8)
Block(-1,1,2,SANDSTONE:0)
Block(-1,1,5,SANDSTONE:0)
Block(-1,1,6,SANDSTONE:0)
Block(-1,1,7,SANDSTONE:2)
Block(-1,2,-4,SANDSTONE:0)
Block(-1,2,1,realistictorches:torch_smoldering:5)
Block(-1,2,2,SANDSTONE:0)
Block(-1,2,5,SANDSTONE:0)
Block(-1,2,6,SANDSTONE:2)
Block(-1,2,7,SANDSTONE:2)
Block(-1,3,-5,SANDSTONE_STAIRS:5)
Block(-1,3,-4,SANDSTONE:0)
Block(-1,3,-3,SANDSTONE_STAIRS:5)
Block(-1,3,-2,SANDSTONE_STAIRS:5)
Block(-1,3,-1,SANDSTONE_STAIRS:5)
Block(-1,3,0,SANDSTONE_STAIRS:5)
Block(-1,3,1,SANDSTONE_STAIRS:5)
Block(-1,3,2,SANDSTONE:0)
Block(-1,3,3,SANDSTONE_STAIRS:7)
Block(-1,3,4,SANDSTONE_STAIRS:6)
Block(-1,3,5,SANDSTONE:0)
Block(-1,3,6,SANDSTONE:2)
Block(-1,3,7,SANDSTONE_STAIRS:3)
Block(-1,4,-5,SANDSTONE_STAIRS:0)
Block(-1,4,-4,SANDSTONE_STAIRS:0)
Block(-1,4,-3,SANDSTONE_STAIRS:0)
Block(-1,4,-2,SANDSTONE_STAIRS:0)
Block(-1,4,-1,SANDSTONE_STAIRS:0)
Block(-1,4,0,SANDSTONE_STAIRS:0)
Block(-1,4,1,SANDSTONE_STAIRS:2)
Block(-1,4,2,SANDSTONE:2)
Block(-1,4,3,SANDSTONE:0)
Block(-1,4,4,SANDSTONE:0)
Block(-1,4,5,SANDSTONE:2)
Block(-1,4,6,SANDSTONE_STAIRS:3)
Block(-1,5,2,SANDSTONE_STAIRS:2)
Block(-1,5,3,SANDSTONE:2)
Block(-1,5,4,SANDSTONE:2)
Block(-1,5,5,SANDSTONE_STAIRS:3)
Block(-1,6,3,STEP:1)
Block(-1,6,4,STEP:1)
Block(0,0,-6,SANDSTONE:0)
Block(0,0,-5,SANDSTONE:0)
Block(0,0,-4,SANDSTONE:0)
Block(0,0,-3,SANDSTONE:0)
Block(0,0,-2,SANDSTONE:0)
Block(0,0,-1,SANDSTONE:0)
Block(0,0,0,SANDSTONE:0)
Block(0,0,1,SANDSTONE:0)
Block(0,0,2,SANDSTONE:0)
Block(0,0,3,SANDSTONE:0)
Block(0,0,4,SANDSTONE:0)
Block(0,0,5,SANDSTONE:0)
Block(0,0,6,SANDSTONE:0)
Block(0,0,7,SANDSTONE:0)
Block(0,1,-6,quark:sandy_bricks:0)
Block(0,1,-5,quark:sandy_bricks:0)
Block(0,1,-4,quark:sandy_bricks_wall:0)
Block(0,1,6,SANDSTONE:0)
Block(0,2,-6,quark:sandy_bricks:0)
Block(0,2,-5,quark:sandy_bricks:0)
Block(0,2,-4,quark:sandy_bricks_wall:0)
Block(0,2,6,SANDSTONE:2)
Block(0,3,-6,quark:sandy_bricks:0)
Block(0,3,-5,quark:sandy_bricks:0)
Block(0,3,-4,quark:sandy_bricks:0)
Block(0,3,3,WALL_BANNER:5)
Block(0,3,4,WALL_BANNER:5)
Block(0,3,5,SANDSTONE_STAIRS:6)
Block(0,3,6,SANDSTONE:2)
Block(0,3,7,SANDSTONE_STAIRS:3)
Block(0,4,-6,quark:sandy_bricks:0)
Block(0,4,-5,quark:sandy_bricks:0)
Block(0,4,-4,quark:sandy_bricks:0)
Block(0,4,-3,SANDSTONE_STAIRS:5)
Block(0,4,-2,SANDSTONE_STAIRS:5)
Block(0,4,-1,SANDSTONE_STAIRS:5)
Block(0,4,0,SANDSTONE_STAIRS:5)
Block(0,4,1,SANDSTONE_STAIRS:5)
Block(0,4,2,SANDSTONE_STAIRS:5)
Block(0,4,3,SANDSTONE_STAIRS:7)
Block(0,4,4,SANDSTONE_STAIRS:6)
Block(0,4,5,SANDSTONE:2)
Block(0,4,6,SANDSTONE_STAIRS:3)
Block(0,5,-6,quark:sandy_bricks:0)
Block(0,5,-5,quark:sandy_bricks:0)
Block(0,5,-4,quark:sandy_bricks:0)
Block(0,5,-3,SANDSTONE_STAIRS:0)
Block(0,5,-2,SANDSTONE_STAIRS:0)
Block(0,5,-1,SANDSTONE_STAIRS:0)
Block(0,5,0,SANDSTONE_STAIRS:0)
Block(0,5,1,SANDSTONE_STAIRS:0)
Block(0,5,2,SANDSTONE_STAIRS:2)
Block(0,5,3,SANDSTONE:2)
Block(0,5,4,SANDSTONE:2)
Block(0,5,5,SANDSTONE_STAIRS:3)
Block(0,6,-6,quark:sandy_bricks_wall:0)
Block(0,6,-4,quark:sandy_bricks_wall:0)
Block(0,6,3,STEP:1)
Block(0,6,4,STEP:1)
Block(0,7,-6,quark:sandy_bricks_slab:0)
Block(0,7,-5,quark:sandy_bricks_slab:0)
Block(0,7,-4,quark:sandy_bricks_slab:0)
Block(1,0,-6,SANDSTONE:0)
Block(1,0,-5,SANDSTONE:0)
Block(1,0,-4,SANDSTONE:0)
Block(1,0,-3,SANDSTONE:0)
Block(1,0,-2,SANDSTONE:0)
Block(1,0,-1,SANDSTONE:0)
Block(1,0,0,SANDSTONE:0)
Block(1,0,1,SANDSTONE:0)
Block(1,0,2,SANDSTONE:0)
Block(1,0,3,SANDSTONE:0)
Block(1,0,4,SANDSTONE:0)
Block(1,0,5,SANDSTONE_STAIRS:1)
Block(1,0,6,SANDSTONE:0)
Block(1,0,7,SANDSTONE:0)
Block(1,1,-6,quark:sandy_bricks:0)
Block(1,1,-5,quark:sandy_bricks:0)
Block(1,1,-4,quark:sandy_bricks:0)
Block(1,1,6,SANDSTONE:0)
Block(1,1,7,ACACIA_FENCE:0)
Block(1,2,-6,quark:sandy_bricks:0)
Block(1,2,-5,simpledifficulty:campfire:1)
Block(1,2,6,STAINED_GLASS_PANE:0)
Block(1,2,7,quark:acacia_trapdoor:14)
Block(1,3,-6,quark:sandy_bricks:0)
Block(1,3,-4,quark:sandy_bricks:0)
Block(1,3,5,SANDSTONE_STAIRS:6)
Block(1,3,6,SANDSTONE:2)
Block(1,3,7,SANDSTONE_STAIRS:3)
Block(1,4,-6,quark:sandy_bricks:0)
Block(1,4,-4,quark:sandy_bricks:0)
Block(1,4,4,SANDSTONE_STAIRS:6)
Block(1,4,5,SANDSTONE:2)
Block(1,4,6,SANDSTONE_STAIRS:3)
Block(1,5,-6,quark:sandy_bricks:0)
Block(1,5,-4,quark:sandy_bricks:0)
Block(1,5,-3,SANDSTONE:2)
Block(1,5,-2,SANDSTONE:2)
Block(1,5,-1,SANDSTONE:2)
Block(1,5,0,SANDSTONE:2)
Block(1,5,1,SANDSTONE:2)
Block(1,5,2,SANDSTONE:2)
Block(1,5,3,SANDSTONE:2)
Block(1,5,4,SANDSTONE:2)
Block(1,5,5,SANDSTONE_STAIRS:3)
Block(1,6,-3,STEP:1)
Block(1,6,-2,STEP:1)
Block(1,6,-1,STEP:1)
Block(1,6,0,STEP:1)
Block(1,6,1,STEP:1)
Block(1,6,2,STEP:1)
Block(1,6,3,STEP:1)
Block(1,6,4,STEP:1)
Block(1,7,-6,quark:sandy_bricks_slab:0)
Block(1,7,-5,quark:sandy_bricks_slab:0)
Block(1,7,-4,quark:sandy_bricks_slab:0)
Block(2,0,-6,SANDSTONE:0)
Block(2,0,-5,SANDSTONE:0)
Block(2,0,-4,SANDSTONE:0)
Block(2,0,-3,SANDSTONE:0)
Block(2,0,-2,SANDSTONE:0)
Block(2,0,-1,SANDSTONE:0)
Block(2,0,0,SANDSTONE:0)
Block(2,0,1,SANDSTONE:0)
Block(2,0,2,SANDSTONE:0)
Block(2,0,3,SANDSTONE:0)
Block(2,0,4,SANDSTONE:0)
Block(2,0,5,STEP:1)
Block(2,0,6,SANDSTONE:0)
Block(2,0,7,SANDSTONE:0)
Block(2,1,-6,quark:sandy_bricks:0)
Block(2,1,-5,quark:sandy_bricks:0)
Block(2,1,-4,quark:sandy_bricks_wall:0)
Block(2,1,6,SANDSTONE:0)
Block(2,1,7,ACACIA_FENCE:0)
Block(2,2,-6,quark:sandy_bricks:0)
Block(2,2,-5,quark:sandy_bricks:0)
Block(2,2,-4,quark:sandy_bricks_wall:0)
Block(2,2,6,SANDSTONE:2)
Block(2,3,-6,quark:sandy_bricks:0)
Block(2,3,-5,quark:sandy_bricks:0)
Block(2,3,-4,quark:sandy_bricks:0)
Block(2,3,5,SANDSTONE_STAIRS:6)
Block(2,3,6,SANDSTONE:2)
Block(2,3,7,SANDSTONE_STAIRS:3)
Block(2,4,-6,quark:sandy_bricks:0)
Block(2,4,-5,quark:sandy_bricks:0)
Block(2,4,-4,quark:sandy_bricks:0)
Block(2,4,-3,SANDSTONE_STAIRS:4)
Block(2,4,-2,SANDSTONE_STAIRS:4)
Block(2,4,-1,SANDSTONE_STAIRS:4)
Block(2,4,0,SANDSTONE_STAIRS:4)
Block(2,4,1,SANDSTONE_STAIRS:4)
Block(2,4,2,SANDSTONE_STAIRS:4)
Block(2,4,3,SANDSTONE_STAIRS:4)
Block(2,4,4,SANDSTONE_STAIRS:6)
Block(2,4,5,SANDSTONE:2)
Block(2,4,6,SANDSTONE_STAIRS:3)
Block(2,5,-6,quark:sandy_bricks:0)
Block(2,5,-5,quark:sandy_bricks:0)
Block(2,5,-4,quark:sandy_bricks:0)
Block(2,5,-3,SANDSTONE_STAIRS:1)
Block(2,5,-2,SANDSTONE_STAIRS:1)
Block(2,5,-1,SANDSTONE_STAIRS:1)
Block(2,5,0,SANDSTONE_STAIRS:1)
Block(2,5,1,SANDSTONE_STAIRS:1)
Block(2,5,2,SANDSTONE_STAIRS:2)
Block(2,5,3,SANDSTONE:2)
Block(2,5,4,SANDSTONE:2)
Block(2,5,5,SANDSTONE_STAIRS:3)
Block(2,6,-6,quark:sandy_bricks_wall:0)
Block(2,6,-4,quark:sandy_bricks_wall:0)
Block(2,6,3,STEP:1)
Block(2,6,4,STEP:1)
Block(2,7,-6,quark:sandy_bricks_slab:0)
Block(2,7,-5,quark:sandy_bricks_slab:0)
Block(2,7,-4,quark:sandy_bricks_slab:0)
Block(3,0,-5,SANDSTONE:0)
Block(3,0,-4,SANDSTONE:0)
Block(3,0,-3,SANDSTONE:0)
Block(3,0,-2,SANDSTONE:0)
Block(3,0,-1,SANDSTONE:0)
Block(3,0,0,SANDSTONE:0)
Block(3,0,1,SANDSTONE:0)
Block(3,0,2,SANDSTONE:0)
Block(3,0,3,SANDSTONE:0)
Block(3,0,4,SANDSTONE:0)
Block(3,0,5,FURNACE:4)
Block(3,0,6,SANDSTONE:0)
Block(3,0,7,SANDSTONE:0)
Block(3,1,-4,SANDSTONE:0)
Block(3,1,-3,quark:sandy_bricks_slab:8)
Block(3,1,-2,quark:sandy_bricks_slab:8)
Block(3,1,-1,quark:sandy_bricks_slab:8)
Block(3,1,0,FURNACE:4)
Block(3,1,1,quark:sandy_bricks_slab:8)
Block(3,1,2,quark:sandy_bricks:0)
Block(3,1,3,inspirations:carpeted_trapdoor_white:0)
Block(3,1,4,inspirations:carpeted_trapdoor_red:0)
Block(3,1,5,inspirations:carpeted_trapdoor_red:0)
Block(3,1,6,SANDSTONE:0)
Block(3,1,7,ACACIA_FENCE:0)
Block(3,2,-4,SANDSTONE:0)
Block(3,2,2,quark:sandy_bricks:0)
Block(3,2,6,SANDSTONE:2)
Block(3,3,-5,SANDSTONE_STAIRS:4)
Block(3,3,-4,SANDSTONE:0)
Block(3,3,-3,SANDSTONE_STAIRS:4)
Block(3,3,-2,SANDSTONE_STAIRS:4)
Block(3,3,-1,SANDSTONE_STAIRS:4)
Block(3,3,0,SANDSTONE_STAIRS:4)
Block(3,3,1,SANDSTONE_STAIRS:4)
Block(3,3,2,quark:sandy_bricks:0)
Block(3,3,3,SANDSTONE_STAIRS:4)
Block(3,3,4,SANDSTONE_STAIRS:4)
Block(3,3,5,SANDSTONE_STAIRS:4)
Block(3,3,6,SANDSTONE:2)
Block(3,3,7,SANDSTONE_STAIRS:3)
Block(3,4,-5,SANDSTONE_STAIRS:1)
Block(3,4,-4,SANDSTONE_STAIRS:1)
Block(3,4,-3,SANDSTONE_STAIRS:1)
Block(3,4,-2,SANDSTONE_STAIRS:1)
Block(3,4,-1,SANDSTONE_STAIRS:1)
Block(3,4,0,SANDSTONE_STAIRS:1)
Block(3,4,1,SANDSTONE_STAIRS:2)
Block(3,4,2,SANDSTONE:2)
Block(3,4,3,SANDSTONE:2)
Block(3,4,4,SANDSTONE:2)
Block(3,4,5,SANDSTONE:2)
Block(3,4,6,SANDSTONE_STAIRS:3)
Block(3,5,2,SANDSTONE_STAIRS:2)
Block(3,5,3,SANDSTONE:2)
Block(3,5,4,SANDSTONE:2)
Block(3,5,5,SANDSTONE_STAIRS:3)
Block(3,6,3,STEP:1)
Block(3,6,4,STEP:1)
Block(4,0,-5,SANDSTONE:0)
Block(4,0,-4,SANDSTONE:0)
Block(4,0,-3,SANDSTONE:0)
Block(4,0,-2,SANDSTONE:0)
Block(4,0,-1,SANDSTONE:0)
Block(4,0,0,SANDSTONE:0)
Block(4,0,1,SANDSTONE:0)
Block(4,0,2,SANDSTONE:0)
Block(4,0,3,SANDSTONE:0)
Block(4,0,4,SANDSTONE:0)
Block(4,0,5,SANDSTONE:0)
Block(4,0,6,SANDSTONE:0)
Block(4,0,7,SANDSTONE:0)
Block(4,1,-5,quark:sandy_bricks_wall:0)
Block(4,1,-4,SANDSTONE:0)
Block(4,1,-3,SANDSTONE:0)
Block(4,1,-2,SANDSTONE:0)
Block(4,1,-1,SANDSTONE:0)
Block(4,1,0,SANDSTONE:0)
Block(4,1,1,SANDSTONE:0)
Block(4,1,2,SANDSTONE:0)
Block(4,1,3,SANDSTONE:0)
Block(4,1,4,SANDSTONE:0)
Block(4,1,5,SANDSTONE:0)
Block(4,1,6,SANDSTONE:0)
Block(4,2,-5,quark:sandy_bricks_wall:0)
Block(4,2,-4,SANDSTONE:0)
Block(4,2,-3,SANDSTONE:2)
Block(4,2,-2,STAINED_GLASS_PANE:0)
Block(4,2,-1,STAINED_GLASS_PANE:0)
Block(4,2,0,SANDSTONE:2)
Block(4,2,1,SANDSTONE:2)
Block(4,2,2,SANDSTONE:2)
Block(4,2,3,STAINED_GLASS_PANE:0)
Block(4,2,4,STAINED_GLASS_PANE:0)
Block(4,2,5,SANDSTONE:2)
Block(4,2,6,SANDSTONE:0)
Block(4,3,-5,SANDSTONE_STAIRS:1)
Block(4,3,-4,SANDSTONE_STAIRS:1)
Block(4,3,-3,SANDSTONE_STAIRS:1)
Block(4,3,-2,SANDSTONE_STAIRS:1)
Block(4,3,-1,SANDSTONE_STAIRS:1)
Block(4,3,0,SANDSTONE_STAIRS:1)
Block(4,3,1,SANDSTONE:0)
Block(4,3,2,SANDSTONE:0)
Block(4,3,3,SANDSTONE:0)
Block(4,3,4,SANDSTONE:0)
Block(4,3,5,SANDSTONE:0)
Block(4,3,6,SANDSTONE:0)
Block(4,3,7,SANDSTONE_STAIRS:3)
Block(4,4,1,SANDSTONE_STAIRS:2)
Block(4,4,2,SANDSTONE:2)
Block(4,4,3,SANDSTONE:2)
Block(4,4,4,SANDSTONE:2)
Block(4,4,5,SANDSTONE:2)
Block(4,4,6,SANDSTONE_STAIRS:3)
Block(4,5,2,SANDSTONE_STAIRS:2)
Block(4,5,3,SANDSTONE:2)
Block(4,5,4,SANDSTONE:2)
Block(4,5,5,SANDSTONE_STAIRS:3)
Block(4,6,3,STEP:1)
Block(4,6,4,STEP:1)
Block(5,0,-3,SANDSTONE:0)
Block(5,0,0,SANDSTONE:0)
Block(5,0,1,SANDSTONE:0)
Block(5,0,2,SANDSTONE:0)
Block(5,0,3,SANDSTONE:0)
Block(5,0,4,SANDSTONE:0)
Block(5,0,5,SANDSTONE:0)
Block(5,0,6,SANDSTONE:0)
Block(5,0,7,SANDSTONE:0)
Block(5,1,-3,quark:sandy_bricks_wall:0)
Block(5,1,0,quark:sandy_bricks_wall:0)
Block(5,1,1,ACACIA_FENCE:0)
Block(5,1,2,ACACIA_FENCE:0)
Block(5,1,3,ACACIA_FENCE:0)
Block(5,1,6,ACACIA_FENCE:0)
Block(5,1,7,quark:sandy_bricks_wall:0)
Block(5,2,-3,quark:sandy_bricks_wall:0)
Block(5,2,-2,quark:acacia_trapdoor:9)
Block(5,2,-1,quark:acacia_trapdoor:9)
Block(5,2,0,quark:sandy_bricks_wall:0)
Block(5,2,3,quark:acacia_trapdoor:13)
Block(5,2,4,quark:acacia_trapdoor:9)
Block(5,2,7,quark:sandy_bricks_wall:0)
Block(5,3,-3,STEP:1)
Block(5,3,-2,STEP:1)
Block(5,3,-1,STEP:1)
Block(5,3,0,SANDSTONE_STAIRS:2)
Block(5,3,1,SANDSTONE_STAIRS:7)
Block(5,3,6,SANDSTONE_STAIRS:6)
Block(5,3,7,SANDSTONE_STAIRS:3)
Block(5,4,1,SANDSTONE_STAIRS:2)
Block(5,4,2,SANDSTONE_STAIRS:7)
Block(5,4,5,SANDSTONE_STAIRS:6)
Block(5,4,6,SANDSTONE_STAIRS:3)
Block(5,5,2,SANDSTONE_STAIRS:2)
Block(5,5,3,SANDSTONE_STAIRS:7)
Block(5,5,4,SANDSTONE_STAIRS:6)
Block(5,5,5,SANDSTONE_STAIRS:3)
Block(5,6,3,STEP:1)
Block(5,6,4,STEP:1)

#######################################################################
# +-----------------------------------------------------------------+ #
# |                             Branches                            | #
# +-----------------------------------------------------------------+ #
#######################################################################


#######################################################################
# +-----------------------------------------------------------------+ #
# |                             Entities                            | #
# +-----------------------------------------------------------------+ #
#######################################################################


#######################################################################
# +-----------------------------------------------------------------+ #
# |                            Particles                            | #
# +-----------------------------------------------------------------+ #
#######################################################################


#######################################################################
# +-----------------------------------------------------------------+ #
# |                             Spawners                            | #
# +-----------------------------------------------------------------+ #
#######################################################################


#######################################################################
# +-----------------------------------------------------------------+ #
# |                             ModData                             | #
# +-----------------------------------------------------------------+ #
#######################################################################

