
#######################################################################
# +-----------------------------------------------------------------+ #
# |                            BO4 object                           | #
# +-----------------------------------------------------------------+ #
#######################################################################

Author: NLBlackEagle

Description: No description given

SettingsMode: WriteWithoutComments


#######################################################################
# +-----------------------------------------------------------------+ #
# |                          Main settings                          | #
# +-----------------------------------------------------------------+ #
#######################################################################

FixedRotation: 

Frequency: 0

SpawnHeight: highestSolidBlock

UseCenterForHighestBlock: true

##############################
# Height Limits for the BO4. #
##############################

MinHeight: 0

MaxHeight: 255

InheritBO3: 

InheritBO3Rotation: NORTH

OverrideChildSettings: true

OverrideParentHeight: false

CanOverride: true

BranchFrequency: 0

BranchFrequencyGroup: 

MustBeBelowOther: false

MustBeInside: 

CannotBeInside: 

ReplacesBO3: 

MustBeInsideWorldBorders: false

CanSpawnOnWater: false

SpawnOnWaterOnly: false

SpawnUnderWater: false

SpawnAtWaterLevel: false

HeightOffset: 0

RemoveAir: false

ReplaceAbove: 

ReplaceBelow: SANDSTONE

ReplaceWithBiomeBlocks: false

ReplaceWithSurfaceBlock: GRASS

ReplaceWithGroundBlock: DIRT

ReplaceWithStoneBlock: STONE

SmoothRadius: 0

SmoothHeightOffset: 0

SmoothStartTop: false

SmoothStartWood: false

SmoothingSurfaceBlock: 

SmoothingGroundBlock: 

BO3Group: 

IsSpawnPoint: false

DoReplaceBlocks: true


#######################################################################
# +-----------------------------------------------------------------+ #
# |                              Blocks                             | #
# +-----------------------------------------------------------------+ #
#######################################################################

Block(-4,0,-3,SANDSTONE:0)
Block(-4,0,-2,SANDSTONE:0)
Block(-4,0,-1,SANDSTONE:0)
Block(-4,0,0,SANDSTONE:0)
Block(-4,0,1,SANDSTONE:0)
Block(-4,0,2,SANDSTONE:0)
Block(-4,0,3,SANDSTONE:0)
Block(-4,1,-3,SANDSTONE:0)
Block(-4,1,-2,SANDSTONE:0)
Block(-4,1,-1,SANDSTONE:0)
Block(-4,1,0,SANDSTONE:0)
Block(-4,1,1,SANDSTONE:0)
Block(-4,1,2,SANDSTONE:0)
Block(-4,1,3,SANDSTONE:0)
Block(-4,2,-3,SANDSTONE:0)
Block(-4,2,-2,SANDSTONE:0)
Block(-4,2,-1,SANDSTONE:0)
Block(-4,2,0,SANDSTONE:0)
Block(-4,2,1,SANDSTONE:0)
Block(-4,2,2,SANDSTONE:0)
Block(-4,2,3,SANDSTONE:0)
Block(-4,3,-3,SANDSTONE:0)
Block(-4,3,-2,SANDSTONE:0)
Block(-4,3,-1,SANDSTONE:0)
Block(-4,3,0,SANDSTONE:0)
Block(-4,3,1,SANDSTONE:0)
Block(-4,3,2,SANDSTONE:0)
Block(-4,3,3,SANDSTONE:0)
Block(-4,4,-3,SANDSTONE:0)
Block(-4,4,-2,SANDSTONE:0)
Block(-4,4,-1,SANDSTONE:0)
Block(-4,4,0,SANDSTONE:0)
Block(-4,4,1,SANDSTONE:0)
Block(-4,4,2,SANDSTONE:0)
Block(-4,4,3,SANDSTONE:0)
Block(-4,5,-3,quark:sandy_bricks_wall:0)
Block(-4,5,-2,STEP:1)
Block(-4,5,-1,DOUBLE_STEP:1)
Block(-4,5,0,rustic:iron_lattice:0)
Block(-4,5,1,DOUBLE_STEP:1)
Block(-4,5,2,STEP:1)
Block(-4,5,3,quark:sandy_bricks_wall:0)
Block(-4,6,-3,quark:sandy_bricks_wall:0)
Block(-4,6,-1,quark:sandy_bricks:0)
Block(-4,6,0,rustic:iron_lattice:0)
Block(-4,6,1,quark:sandy_bricks:0)
Block(-4,6,3,quark:sandy_bricks_wall:0)
Block(-4,7,-3,quark:sandy_bricks_wall:0)
Block(-4,7,-1,STEP:1)
Block(-4,7,0,STEP:1)
Block(-4,7,1,STEP:1)
Block(-4,7,3,quark:sandy_bricks_wall:0)
Block(-4,8,-3,STEP:1)
Block(-4,8,-2,STEP:1)
Block(-4,8,-1,STEP:1)
Block(-4,8,0,STEP:1)
Block(-4,8,1,STEP:1)
Block(-4,8,2,STEP:1)
Block(-4,8,3,STEP:1)
Block(-3,0,-3,SANDSTONE:0)
Block(-3,0,-2,SANDSTONE:0)
Block(-3,0,-1,SANDSTONE:0)
Block(-3,0,0,SANDSTONE:0)
Block(-3,0,1,SANDSTONE:0)
Block(-3,0,2,SANDSTONE:0)
Block(-3,0,3,SANDSTONE:0)
Block(-3,1,-3,SANDSTONE:0)
Block(-3,1,-2,lycanitesmobs:poison:0)
Block(-3,1,-1,lycanitesmobs:poison:0)
Block(-3,1,0,lycanitesmobs:poison:0)
Block(-3,1,1,lycanitesmobs:poison:0)
Block(-3,1,2,lycanitesmobs:poison:0)
Block(-3,1,3,SANDSTONE:0)
Block(-3,2,-3,SANDSTONE:0)
Block(-3,2,-2,AIR:0)
Block(-3,2,-1,AIR:0)
Block(-3,2,0,AIR:0)
Block(-3,2,1,AIR:0)
Block(-3,2,2,AIR:0)
Block(-3,2,3,SANDSTONE:0)
Block(-3,3,-3,SANDSTONE:0)
Block(-3,3,-2,AIR:0)
Block(-3,3,-1,AIR:0)
Block(-3,3,0,AIR:0)
Block(-3,3,1,AIR:0)
Block(-3,3,2,AIR:0)
Block(-3,3,3,SANDSTONE:0)
Block(-3,4,-3,SANDSTONE:0)
Block(-3,4,-2,SANDSTONE:0)
Block(-3,4,-1,SANDSTONE:0)
Block(-3,4,0,quark:world_stone_pavement:4)
Block(-3,4,1,SANDSTONE:0)
Block(-3,4,2,SANDSTONE:0)
Block(-3,4,3,SANDSTONE:0)
Block(-3,5,-3,SANDSTONE:0)
Block(-3,5,-2,SANDSTONE:0)
Block(-3,5,-1,SANDSTONE:0)
Block(-3,5,0,betternether:quartz_glass_framed_pane:0)
Block(-3,5,1,SANDSTONE:0)
Block(-3,5,2,SANDSTONE:0)
Block(-3,5,3,SANDSTONE:0)
Block(-3,6,-3,quark:sandy_bricks:0)
Block(-3,6,-2,quark:sandy_bricks:0)
Block(-3,6,-1,quark:sandy_bricks:0)
Block(-3,6,0,betternether:quartz_glass_framed_pane:0)
Block(-3,6,1,quark:sandy_bricks:0)
Block(-3,6,2,quark:sandy_bricks:0)
Block(-3,6,3,quark:sandy_bricks:0)
Block(-3,7,-3,SANDSTONE:0)
Block(-3,7,-2,SANDSTONE:0)
Block(-3,7,-1,SANDSTONE:0)
Block(-3,7,0,SANDSTONE:0)
Block(-3,7,1,SANDSTONE:0)
Block(-3,7,2,SANDSTONE:0)
Block(-3,7,3,SANDSTONE:0)
Block(-3,8,-3,SANDSTONE:0)
Block(-3,8,-2,DOUBLE_STEP:1)
Block(-3,8,-1,DOUBLE_STEP:1)
Block(-3,8,0,DOUBLE_STEP:1)
Block(-3,8,1,DOUBLE_STEP:1)
Block(-3,8,2,DOUBLE_STEP:1)
Block(-3,8,3,SANDSTONE:0)
Block(-2,0,-3,SANDSTONE:0)
Block(-2,0,-2,SANDSTONE:0)
Block(-2,0,-1,SANDSTONE:0)
Block(-2,0,0,SANDSTONE:0)
Block(-2,0,1,SANDSTONE:0)
Block(-2,0,2,SANDSTONE:0)
Block(-2,0,3,SANDSTONE:0)
Block(-2,1,-3,SANDSTONE:0)
Block(-2,1,-2,lycanitesmobs:poison:0)
Block(-2,1,-1,lycanitesmobs:poison:0)
Block(-2,1,0,lycanitesmobs:poison:0)
Block(-2,1,1,lycanitesmobs:poison:0)
Block(-2,1,2,lycanitesmobs:poison:0)
Block(-2,1,3,SANDSTONE:0)
Block(-2,2,-3,SANDSTONE:0)
Block(-2,2,-2,AIR:0)
Block(-2,2,-1,AIR:0)
Block(-2,2,0,TNT:0)
Block(-2,2,1,AIR:0)
Block(-2,2,2,AIR:0)
Block(-2,2,3,SANDSTONE:0)
Block(-2,3,-3,SANDSTONE:0)
Block(-2,3,-2,AIR:0)
Block(-2,3,-1,AIR:0)
Block(-2,3,0,OBSERVER:1)
Block(-2,3,1,AIR:0)
Block(-2,3,2,AIR:0)
Block(-2,3,3,SANDSTONE:0)
Block(-2,4,-3,SANDSTONE:0)
Block(-2,4,-2,SANDSTONE:0)
Block(-2,4,-1,quark:world_stone_pavement:4)
Block(-2,4,0,betternether:cincinnasite_brick_plate:0)
Block(-2,4,1,quark:world_stone_pavement:4)
Block(-2,4,2,SANDSTONE:0)
Block(-2,4,3,SANDSTONE:0)
Block(-2,5,-3,STEP:1)
Block(-2,5,-2,SANDSTONE:0)
Block(-2,5,-1,quark:stone_marble_slab:8)
Block(-2,5,0,AIR:0)
Block(-2,5,1,quark:stone_marble_slab:8)
Block(-2,5,2,SANDSTONE:0)
Block(-2,5,3,STEP:1)
Block(-2,6,-2,quark:sandy_bricks:0)
Block(-2,6,-1,AIR:0)
Block(-2,6,0,AIR:0)
Block(-2,6,1,contenttweaker:bone_pile:0)
Block(-2,6,2,quark:sandy_bricks:0)
Block(-2,7,-2,SANDSTONE:0)
Block(-2,7,-1,quark:stone_marble_slab:0)
Block(-2,7,0,AIR:0)
Block(-2,7,1,quark:stone_marble_slab:0)
Block(-2,7,2,SANDSTONE:0)
Block(-2,8,-3,SANDSTONE:0)
Block(-2,8,-2,DOUBLE_STEP:1)
Block(-2,8,-1,SANDSTONE:0)
Block(-2,8,0,quark:monster_box:0)
Block(-2,8,1,SANDSTONE:0)
Block(-2,8,2,DOUBLE_STEP:1)
Block(-2,8,3,SANDSTONE:0)
Block(-2,9,-3,STEP:1)
Block(-2,9,-2,STEP:1)
Block(-2,9,-1,STEP:1)
Block(-2,9,0,STEP:1)
Block(-2,9,1,STEP:1)
Block(-2,9,2,STEP:1)
Block(-2,9,3,STEP:1)
Block(-1,0,-3,SANDSTONE:0)
Block(-1,0,-2,SANDSTONE:0)
Block(-1,0,-1,SANDSTONE:0)
Block(-1,0,0,SANDSTONE:0)
Block(-1,0,1,SANDSTONE:0)
Block(-1,0,2,SANDSTONE:0)
Block(-1,0,3,SANDSTONE:0)
Block(-1,1,-3,SANDSTONE:0)
Block(-1,1,-2,lycanitesmobs:poison:0)
Block(-1,1,-1,lycanitesmobs:poison:0)
Block(-1,1,0,lycanitesmobs:poison:0)
Block(-1,1,1,lycanitesmobs:poison:0)
Block(-1,1,2,lycanitesmobs:poison:0)
Block(-1,1,3,SANDSTONE:0)
Block(-1,2,-3,SANDSTONE:0)
Block(-1,2,-2,AIR:0)
Block(-1,2,-1,AIR:0)
Block(-1,2,0,TNT:0)
Block(-1,2,1,AIR:0)
Block(-1,2,2,AIR:0)
Block(-1,2,3,SANDSTONE:0)
Block(-1,3,-3,SANDSTONE:0)
Block(-1,3,-2,AIR:0)
Block(-1,3,-1,AIR:0)
Block(-1,3,0,OBSERVER:1)
Block(-1,3,1,AIR:0)
Block(-1,3,2,AIR:0)
Block(-1,3,3,SANDSTONE:0)
Block(-1,4,-3,SANDSTONE:0)
Block(-1,4,-2,SANDSTONE:0)
Block(-1,4,-1,quark:world_stone_pavement:4)
Block(-1,4,0,betternether:cincinnasite_brick_plate:0)
Block(-1,4,1,quark:world_stone_pavement:4)
Block(-1,4,2,SANDSTONE:0)
Block(-1,4,3,SANDSTONE:0)
Block(-1,5,-3,SANDSTONE:0)
Block(-1,5,-2,SANDSTONE:0)
Block(-1,5,-1,quark:stone_marble_slab:8)
Block(-1,5,0,AIR:0)
Block(-1,5,1,quark:stone_marble_slab:8)
Block(-1,5,2,SANDSTONE:0)
Block(-1,5,3,SANDSTONE:0)
Block(-1,6,-3,quark:sandy_bricks:0)
Block(-1,6,-2,quark:sandy_bricks:0)
Block(-1,6,-1,contenttweaker:bone_pile:0)
Block(-1,6,0,AIR:0)
Block(-1,6,1,contenttweaker:bone_pile:0)
Block(-1,6,2,quark:sandy_bricks:0)
Block(-1,6,3,quark:sandy_bricks:0)
Block(-1,7,-3,SANDSTONE:0)
Block(-1,7,-2,SANDSTONE:0)
Block(-1,7,-1,quark:stone_marble_slab:0)
Block(-1,7,0,AIR:0)
Block(-1,7,1,quark:stone_marble_slab:0)
Block(-1,7,2,SANDSTONE:0)
Block(-1,7,3,SANDSTONE:0)
Block(-1,8,-3,SANDSTONE:0)
Block(-1,8,-2,SANDSTONE:0)
Block(-1,8,-1,SANDSTONE:0)
Block(-1,8,0,SANDSTONE:0)
Block(-1,8,1,SANDSTONE:0)
Block(-1,8,2,SANDSTONE:0)
Block(-1,8,3,SANDSTONE:0)
Block(-1,9,-3,SANDSTONE:0)
Block(-1,9,-2,DOUBLE_STEP:1)
Block(-1,9,-1,DOUBLE_STEP:1)
Block(-1,9,0,DOUBLE_STEP:1)
Block(-1,9,1,DOUBLE_STEP:1)
Block(-1,9,2,DOUBLE_STEP:1)
Block(-1,9,3,SANDSTONE:0)
Block(0,0,-3,SANDSTONE:0)
Block(0,0,-2,SANDSTONE:0)
Block(0,0,-1,SANDSTONE:0)
Block(0,0,0,SANDSTONE:0)
Block(0,0,1,SANDSTONE:0)
Block(0,0,2,SANDSTONE:0)
Block(0,0,3,SANDSTONE:0)
Block(0,1,-3,SANDSTONE:0)
Block(0,1,-2,lycanitesmobs:poison:0)
Block(0,1,-1,lycanitesmobs:poison:0)
Block(0,1,0,lycanitesmobs:poison:0)
Block(0,1,1,lycanitesmobs:poison:0)
Block(0,1,2,lycanitesmobs:poison:0)
Block(0,1,3,SANDSTONE:0)
Block(0,2,-3,SANDSTONE:0)
Block(0,2,-2,AIR:0)
Block(0,2,-1,AIR:0)
Block(0,2,0,TNT:0)
Block(0,2,1,AIR:0)
Block(0,2,2,AIR:0)
Block(0,2,3,SANDSTONE:0)
Block(0,3,-3,SANDSTONE:0)
Block(0,3,-2,AIR:0)
Block(0,3,-1,AIR:0)
Block(0,3,0,OBSERVER:1)
Block(0,3,1,AIR:0)
Block(0,3,2,AIR:0)
Block(0,3,3,SANDSTONE:0)
Block(0,4,-3,SANDSTONE:0)
Block(0,4,-2,SANDSTONE:0)
Block(0,4,-1,SANDSTONE:0)
Block(0,4,0,quark:monster_box:0)
Block(0,4,1,SANDSTONE:0)
Block(0,4,2,SANDSTONE:0)
Block(0,4,3,SANDSTONE:0)
Block(0,5,-3,STEP:1)
Block(0,5,-2,SANDSTONE:0)
Block(0,5,-1,betternether:cincinnasite_bricks_pillar:0)
Block(0,5,0,betternether:cincinnasite_pedestal:0)
Block(0,5,1,betternether:cincinnasite_bricks_pillar:0)
Block(0,5,2,SANDSTONE:0)
Block(0,5,3,STEP:1)
Block(0,6,-2,quark:sandy_bricks:0)
Block(0,6,-1,betternether:cincinnasite_bricks_pillar:0)
Block(0,6,0,betternether:cincinnasite_fire_bowl:1)
Block(0,6,1,betternether:cincinnasite_bricks_pillar:0)
Block(0,6,2,quark:sandy_bricks:0)
Block(0,7,-2,SANDSTONE:0)
Block(0,7,-1,betternether:cincinnasite_bricks_pillar:0)
Block(0,7,0,AIR:0)
Block(0,7,1,betternether:cincinnasite_bricks_pillar:0)
Block(0,7,2,SANDSTONE:0)
Block(0,8,-3,SANDSTONE:0)
Block(0,8,-2,SANDSTONE:0)
Block(0,8,-1,SANDSTONE:0)
Block(0,8,0,quark:stone_marble_slab:0)
Block(0,8,1,SANDSTONE:0)
Block(0,8,2,SANDSTONE:0)
Block(0,8,3,SANDSTONE:0)
Block(0,9,-3,SANDSTONE:0)
Block(0,9,-2,DOUBLE_STEP:1)
Block(0,9,-1,DOUBLE_STEP:1)
Block(0,9,0,DOUBLE_STEP:1)
Block(0,9,1,DOUBLE_STEP:1)
Block(0,9,2,DOUBLE_STEP:1)
Block(0,9,3,SANDSTONE:0)
Block(1,0,-3,SANDSTONE:0)
Block(1,0,-2,SANDSTONE:0)
Block(1,0,-1,SANDSTONE:0)
Block(1,0,0,SANDSTONE:0)
Block(1,0,1,SANDSTONE:0)
Block(1,0,2,SANDSTONE:0)
Block(1,0,3,SANDSTONE:0)
Block(1,1,-3,SANDSTONE:0)
Block(1,1,-2,lycanitesmobs:poison:0)
Block(1,1,-1,lycanitesmobs:poison:0)
Block(1,1,0,lycanitesmobs:poison:0)
Block(1,1,1,lycanitesmobs:poison:0)
Block(1,1,2,lycanitesmobs:poison:0)
Block(1,1,3,SANDSTONE:0)
Block(1,2,-3,SANDSTONE:0)
Block(1,2,-2,AIR:0)
Block(1,2,-1,AIR:0)
Block(1,2,0,TNT:0)
Block(1,2,1,AIR:0)
Block(1,2,2,AIR:0)
Block(1,2,3,SANDSTONE:0)
Block(1,3,-3,SANDSTONE:0)
Block(1,3,-2,AIR:0)
Block(1,3,-1,AIR:0)
Block(1,3,0,OBSERVER:1)
Block(1,3,1,AIR:0)
Block(1,3,2,AIR:0)
Block(1,3,3,SANDSTONE:0)
Block(1,4,-3,SANDSTONE:0)
Block(1,4,-2,SANDSTONE:0)
Block(1,4,-1,quark:world_stone_pavement:4)
Block(1,4,0,betternether:cincinnasite_brick_plate:0)
Block(1,4,1,quark:world_stone_pavement:4)
Block(1,4,2,SANDSTONE:0)
Block(1,4,3,SANDSTONE:0)
Block(1,5,-3,SANDSTONE:0)
Block(1,5,-2,SANDSTONE:0)
Block(1,5,-1,quark:stone_marble_slab:8)
Block(1,5,0,AIR:0)
Block(1,5,1,quark:stone_marble_slab:8)
Block(1,5,2,SANDSTONE:0)
Block(1,5,3,SANDSTONE:0)
Block(1,6,-3,quark:sandy_bricks:0)
Block(1,6,-2,quark:sandy_bricks:0)
Block(1,6,-1,contenttweaker:bone_pile:0)
Block(1,6,0,AIR:0)
Block(1,6,1,contenttweaker:bone_pile:0)
Block(1,6,2,quark:sandy_bricks:0)
Block(1,6,3,quark:sandy_bricks:0)
Block(1,7,-3,SANDSTONE:0)
Block(1,7,-2,SANDSTONE:0)
Block(1,7,-1,quark:stone_marble_slab:0)
Block(1,7,0,AIR:0)
Block(1,7,1,quark:stone_marble_slab:0)
Block(1,7,2,SANDSTONE:0)
Block(1,7,3,SANDSTONE:0)
Block(1,8,-3,SANDSTONE:0)
Block(1,8,-2,SANDSTONE:0)
Block(1,8,-1,SANDSTONE:0)
Block(1,8,0,SANDSTONE:0)
Block(1,8,1,SANDSTONE:0)
Block(1,8,2,SANDSTONE:0)
Block(1,8,3,SANDSTONE:0)
Block(1,9,-3,SANDSTONE:0)
Block(1,9,-2,DOUBLE_STEP:1)
Block(1,9,-1,DOUBLE_STEP:1)
Block(1,9,0,DOUBLE_STEP:1)
Block(1,9,1,DOUBLE_STEP:1)
Block(1,9,2,DOUBLE_STEP:1)
Block(1,9,3,SANDSTONE:0)
Block(2,0,-3,SANDSTONE:0)
Block(2,0,-2,SANDSTONE:0)
Block(2,0,-1,SANDSTONE:0)
Block(2,0,0,SANDSTONE:0)
Block(2,0,1,SANDSTONE:0)
Block(2,0,2,SANDSTONE:0)
Block(2,0,3,SANDSTONE:0)
Block(2,1,-3,SANDSTONE:0)
Block(2,1,-2,lycanitesmobs:poison:0)
Block(2,1,-1,lycanitesmobs:poison:0)
Block(2,1,0,lycanitesmobs:poison:0)
Block(2,1,1,lycanitesmobs:poison:0)
Block(2,1,2,lycanitesmobs:poison:0)
Block(2,1,3,SANDSTONE:0)
Block(2,2,-3,SANDSTONE:0)
Block(2,2,-2,AIR:0)
Block(2,2,-1,AIR:0)
Block(2,2,0,TNT:0)
Block(2,2,1,AIR:0)
Block(2,2,2,AIR:0)
Block(2,2,3,SANDSTONE:0)
Block(2,3,-3,SANDSTONE:0)
Block(2,3,-2,AIR:0)
Block(2,3,-1,AIR:0)
Block(2,3,0,OBSERVER:1)
Block(2,3,1,AIR:0)
Block(2,3,2,AIR:0)
Block(2,3,3,SANDSTONE:0)
Block(2,4,-3,SANDSTONE:0)
Block(2,4,-2,SANDSTONE:0)
Block(2,4,-1,quark:world_stone_pavement:4)
Block(2,4,0,betternether:cincinnasite_brick_plate:0)
Block(2,4,1,quark:world_stone_pavement:4)
Block(2,4,2,SANDSTONE:0)
Block(2,4,3,SANDSTONE:0)
Block(2,5,-3,STEP:1)
Block(2,5,-2,DOUBLE_STEP:1)
Block(2,5,-1,quark:stone_marble_slab:8)
Block(2,5,0,AIR:0)
Block(2,5,1,quark:stone_marble_slab:8)
Block(2,5,2,SANDSTONE:0)
Block(2,5,3,STEP:1)
Block(2,6,-2,quark:sandy_bricks:0)
Block(2,6,-1,contenttweaker:bone_pile:0)
Block(2,6,0,AIR:0)
Block(2,6,1,contenttweaker:bone_pile:0)
Block(2,6,2,quark:sandy_bricks:0)
Block(2,7,-2,SANDSTONE:0)
Block(2,7,-1,quark:stone_marble_slab:0)
Block(2,7,0,AIR:0)
Block(2,7,1,quark:stone_marble_slab:0)
Block(2,7,2,SANDSTONE:0)
Block(2,8,-3,SANDSTONE:0)
Block(2,8,-2,DOUBLE_STEP:1)
Block(2,8,-1,SANDSTONE:0)
Block(2,8,0,quark:monster_box:0)
Block(2,8,1,SANDSTONE:0)
Block(2,8,2,DOUBLE_STEP:1)
Block(2,8,3,SANDSTONE:0)
Block(2,9,-3,STEP:1)
Block(2,9,-2,STEP:1)
Block(2,9,-1,STEP:1)
Block(2,9,0,STEP:1)
Block(2,9,1,STEP:1)
Block(2,9,2,STEP:1)
Block(2,9,3,STEP:1)
Block(3,0,-3,SANDSTONE:0)
Block(3,0,-2,SANDSTONE:0)
Block(3,0,-1,SANDSTONE:0)
Block(3,0,0,SANDSTONE:0)
Block(3,0,1,SANDSTONE:0)
Block(3,0,2,SANDSTONE:0)
Block(3,0,3,SANDSTONE:0)
Block(3,1,-3,SANDSTONE:0)
Block(3,1,-2,lycanitesmobs:poison:0)
Block(3,1,-1,lycanitesmobs:poison:0)
Block(3,1,0,lycanitesmobs:poison:0)
Block(3,1,1,lycanitesmobs:poison:0)
Block(3,1,2,lycanitesmobs:poison:0)
Block(3,1,3,SANDSTONE:0)
Block(3,2,-3,SANDSTONE:0)
Block(3,2,-2,AIR:0)
Block(3,2,-1,AIR:0)
Block(3,2,0,AIR:0)
Block(3,2,1,AIR:0)
Block(3,2,2,AIR:0)
Block(3,2,3,SANDSTONE:0)
Block(3,3,-3,SANDSTONE:0)
Block(3,3,-2,AIR:0)
Block(3,3,-1,AIR:0)
Block(3,3,0,AIR:0)
Block(3,3,1,AIR:0)
Block(3,3,2,AIR:0)
Block(3,3,3,SANDSTONE:0)
Block(3,4,-3,SANDSTONE:0)
Block(3,4,-2,SANDSTONE:0)
Block(3,4,-1,SANDSTONE:0)
Block(3,4,0,quark:world_stone_pavement:4)
Block(3,4,1,SANDSTONE:0)
Block(3,4,2,SANDSTONE:0)
Block(3,4,3,SANDSTONE:0)
Block(3,5,-3,SANDSTONE:0)
Block(3,5,-2,SANDSTONE:0)
Block(3,5,-1,SANDSTONE:0)
Block(3,5,0,betternether:quartz_glass_framed_pane:0)
Block(3,5,1,SANDSTONE:0)
Block(3,5,2,SANDSTONE:0)
Block(3,5,3,SANDSTONE:0)
Block(3,6,-3,quark:sandy_bricks:0)
Block(3,6,-2,quark:sandy_bricks:0)
Block(3,6,-1,quark:sandy_bricks:0)
Block(3,6,0,betternether:quartz_glass_framed_pane:0)
Block(3,6,1,quark:sandy_bricks:0)
Block(3,6,2,quark:sandy_bricks:0)
Block(3,6,3,quark:sandy_bricks:0)
Block(3,7,-3,SANDSTONE:0)
Block(3,7,-2,SANDSTONE:0)
Block(3,7,-1,SANDSTONE:0)
Block(3,7,0,SANDSTONE:0)
Block(3,7,1,SANDSTONE:0)
Block(3,7,2,SANDSTONE:0)
Block(3,7,3,SANDSTONE:0)
Block(3,8,-3,SANDSTONE:0)
Block(3,8,-2,DOUBLE_STEP:1)
Block(3,8,-1,DOUBLE_STEP:1)
Block(3,8,0,DOUBLE_STEP:1)
Block(3,8,1,DOUBLE_STEP:1)
Block(3,8,2,DOUBLE_STEP:1)
Block(3,8,3,SANDSTONE:0)
Block(4,0,-3,SANDSTONE:0)
Block(4,0,-2,SANDSTONE:0)
Block(4,0,-1,SANDSTONE:0)
Block(4,0,0,SANDSTONE:0)
Block(4,0,1,SANDSTONE:0)
Block(4,0,2,SANDSTONE:0)
Block(4,0,3,SANDSTONE:0)
Block(4,1,-3,SANDSTONE:0)
Block(4,1,-2,SANDSTONE:0)
Block(4,1,-1,SANDSTONE:0)
Block(4,1,0,SANDSTONE:0)
Block(4,1,1,SANDSTONE:0)
Block(4,1,2,SANDSTONE:0)
Block(4,1,3,SANDSTONE:0)
Block(4,2,-3,SANDSTONE:0)
Block(4,2,-2,SANDSTONE:0)
Block(4,2,-1,SANDSTONE:0)
Block(4,2,0,SANDSTONE:0)
Block(4,2,1,SANDSTONE:0)
Block(4,2,2,SANDSTONE:0)
Block(4,2,3,SANDSTONE:0)
Block(4,3,-3,SANDSTONE:0)
Block(4,3,-2,SANDSTONE:0)
Block(4,3,-1,SANDSTONE:0)
Block(4,3,0,SANDSTONE:0)
Block(4,3,1,SANDSTONE:0)
Block(4,3,2,SANDSTONE:0)
Block(4,3,3,SANDSTONE:0)
Block(4,4,-3,SANDSTONE:0)
Block(4,4,-2,SANDSTONE:0)
Block(4,4,-1,SANDSTONE:0)
Block(4,4,0,SANDSTONE:0)
Block(4,4,1,SANDSTONE:0)
Block(4,4,2,SANDSTONE:0)
Block(4,4,3,SANDSTONE:0)
Block(4,5,-3,quark:sandy_bricks_wall:0)
Block(4,5,-2,STEP:1)
Block(4,5,-1,SANDSTONE:0)
Block(4,5,0,rustic:iron_lattice:0)
Block(4,5,1,SANDSTONE:0)
Block(4,5,2,STEP:1)
Block(4,5,3,quark:sandy_bricks_wall:0)
Block(4,6,-3,quark:sandy_bricks_wall:0)
Block(4,6,-1,quark:sandy_bricks:0)
Block(4,6,0,rustic:iron_lattice:0)
Block(4,6,1,quark:sandy_bricks:0)
Block(4,6,3,quark:sandy_bricks_wall:0)
Block(4,7,-3,quark:sandy_bricks_wall:0)
Block(4,7,-1,STEP:1)
Block(4,7,0,STEP:1)
Block(4,7,1,STEP:1)
Block(4,7,3,quark:sandy_bricks_wall:0)
Block(4,8,-3,STEP:1)
Block(4,8,-2,STEP:1)
Block(4,8,-1,STEP:1)
Block(4,8,0,STEP:1)
Block(4,8,1,STEP:1)
Block(4,8,2,STEP:1)
Block(4,8,3,STEP:1)

#######################################################################
# +-----------------------------------------------------------------+ #
# |                             Branches                            | #
# +-----------------------------------------------------------------+ #
#######################################################################


#######################################################################
# +-----------------------------------------------------------------+ #
# |                             Entities                            | #
# +-----------------------------------------------------------------+ #
#######################################################################


#######################################################################
# +-----------------------------------------------------------------+ #
# |                            Particles                            | #
# +-----------------------------------------------------------------+ #
#######################################################################


#######################################################################
# +-----------------------------------------------------------------+ #
# |                             Spawners                            | #
# +-----------------------------------------------------------------+ #
#######################################################################


#######################################################################
# +-----------------------------------------------------------------+ #
# |                             ModData                             | #
# +-----------------------------------------------------------------+ #
#######################################################################

