
#######################################################################
# +-----------------------------------------------------------------+ #
# |                            BO4 object                           | #
# +-----------------------------------------------------------------+ #
#######################################################################

Author: NLBlackEagle

Description: No description given

SettingsMode: WriteWithoutComments


#######################################################################
# +-----------------------------------------------------------------+ #
# |                          Main settings                          | #
# +-----------------------------------------------------------------+ #
#######################################################################

FixedRotation: 

Frequency: 0

SpawnHeight: highestSolidBlock

UseCenterForHighestBlock: true

##############################
# Height Limits for the BO4. #
##############################

MinHeight: 0

MaxHeight: 255

InheritBO3: 

InheritBO3Rotation: NORTH

OverrideChildSettings: true

OverrideParentHeight: false

CanOverride: true

BranchFrequency: 0

BranchFrequencyGroup: 

MustBeBelowOther: false

MustBeInside: 

CannotBeInside: 

ReplacesBO3: 

MustBeInsideWorldBorders: false

CanSpawnOnWater: false

SpawnOnWaterOnly: false

SpawnUnderWater: false

SpawnAtWaterLevel: false

HeightOffset: 0

RemoveAir: true

ReplaceAbove: 

ReplaceBelow: SANDSTONE

ReplaceWithBiomeBlocks: false

ReplaceWithSurfaceBlock: GRASS

ReplaceWithGroundBlock: DIRT

ReplaceWithStoneBlock: STONE

SmoothRadius: 0

SmoothHeightOffset: 0

SmoothStartTop: false

SmoothStartWood: false

SmoothingSurfaceBlock: 

SmoothingGroundBlock: 

BO3Group: 

IsSpawnPoint: false

DoReplaceBlocks: true


#######################################################################
# +-----------------------------------------------------------------+ #
# |                              Blocks                             | #
# +-----------------------------------------------------------------+ #
#######################################################################

Block(-4,0,-2,SANDSTONE:0)
Block(-4,0,-1,SANDSTONE:0)
Block(-4,0,0,SANDSTONE:0)
Block(-4,0,1,SANDSTONE:0)
Block(-4,0,2,SANDSTONE:0)
Block(-4,1,-2,quark:sandy_bricks_wall:0)
Block(-4,1,0,biomesoplenty:redwood_fence:0)
Block(-4,1,1,biomesoplenty:redwood_fence:0)
Block(-4,1,2,quark:sandy_bricks_wall:0)
Block(-4,2,-2,quark:sandy_bricks_wall:0)
Block(-4,2,-1,quark:acacia_trapdoor:14)
Block(-4,2,0,quark:acacia_trapdoor:14)
Block(-4,2,1,quark:acacia_trapdoor:10)
Block(-4,2,2,quark:sandy_bricks_wall:0)
Block(-4,3,-2,STEP:1)
Block(-4,3,-1,STEP:1)
Block(-4,3,0,STEP:1)
Block(-4,3,1,STEP:1)
Block(-4,3,2,STEP:1)
Block(-3,0,-2,SANDSTONE:0)
Block(-3,0,-1,SANDSTONE:0)
Block(-3,0,0,SANDSTONE:0)
Block(-3,0,1,SANDSTONE:0)
Block(-3,0,2,SANDSTONE:0)
Block(-3,1,-2,SANDSTONE:0)
Block(-3,1,-1,SANDSTONE:0)
Block(-3,1,0,SANDSTONE:0)
Block(-3,1,1,SANDSTONE:0)
Block(-3,1,2,SANDSTONE:0)
Block(-3,2,-2,SANDSTONE:0)
Block(-3,2,-1,inspirations:glass_trapdoor:7)
Block(-3,2,0,inspirations:glass_trapdoor:7)
Block(-3,2,1,inspirations:glass_trapdoor:7)
Block(-3,2,2,SANDSTONE:0)
Block(-3,3,-2,SANDSTONE:0)
Block(-3,3,-1,SANDSTONE:0)
Block(-3,3,0,SANDSTONE:0)
Block(-3,3,1,SANDSTONE:0)
Block(-3,3,2,SANDSTONE:0)
Block(-3,3,3,STEP:1)
Block(-2,0,-4,SANDSTONE:0)
Block(-2,0,-3,SANDSTONE:0)
Block(-2,0,-2,SANDSTONE:0)
Block(-2,0,-1,SANDSTONE:0)
Block(-2,0,0,SANDSTONE:0)
Block(-2,0,1,SANDSTONE:0)
Block(-2,0,2,SANDSTONE:0)
Block(-2,0,3,SANDSTONE:0)
Block(-2,0,4,SANDSTONE:0)
Block(-2,1,-4,quark:sandy_bricks_wall:0)
Block(-2,1,-3,SANDSTONE:0)
Block(-2,1,-2,STEP:9)
Block(-2,1,0,CARPET:0)
Block(-2,1,2,STEP:9)
Block(-2,1,3,SANDSTONE:0)
Block(-2,1,4,quark:sandy_bricks_wall:0)
Block(-2,2,-4,quark:sandy_bricks_wall:0)
Block(-2,2,-3,SANDSTONE:0)
Block(-2,2,-2,realistictorches:torch_smoldering:5)
Block(-2,2,2,realistictorches:torch_smoldering:5)
Block(-2,2,3,SANDSTONE:0)
Block(-2,2,4,quark:sandy_bricks_wall:0)
Block(-2,3,-4,STEP:1)
Block(-2,3,-3,SANDSTONE:0)
Block(-2,3,3,SANDSTONE:0)
Block(-2,3,4,STEP:1)
Block(-2,4,-2,STEP:1)
Block(-2,4,-1,SANDSTONE:0)
Block(-2,4,0,SANDSTONE:0)
Block(-2,4,1,SANDSTONE:0)
Block(-2,4,2,STEP:1)
Block(-1,0,-4,SANDSTONE:0)
Block(-1,0,-3,SANDSTONE:0)
Block(-1,0,-2,SANDSTONE:0)
Block(-1,0,-1,SANDSTONE:0)
Block(-1,0,0,SANDSTONE:0)
Block(-1,0,1,SANDSTONE:0)
Block(-1,0,2,SANDSTONE:0)
Block(-1,0,3,SANDSTONE:0)
Block(-1,0,4,SANDSTONE:0)
Block(-1,1,-4,biomesoplenty:redwood_fence:0)
Block(-1,1,-3,SANDSTONE:0)
Block(-1,1,-2,FURNACE:3)
Block(-1,1,-1,CARPET:0)
Block(-1,1,0,CARPET:0)
Block(-1,1,1,CARPET:0)
Block(-1,1,2,STEP:9)
Block(-1,1,3,SANDSTONE:0)
Block(-1,1,4,biomesoplenty:redwood_fence:0)
Block(-1,2,-4,quark:acacia_trapdoor:8)
Block(-1,2,-3,inspirations:glass_trapdoor:5)
Block(-1,2,3,inspirations:glass_trapdoor:4)
Block(-1,2,4,quark:acacia_trapdoor:9)
Block(-1,3,-4,STEP:1)
Block(-1,3,-3,SANDSTONE:0)
Block(-1,3,3,SANDSTONE:0)
Block(-1,3,4,STEP:1)
Block(-1,4,-2,SANDSTONE:0)
Block(-1,4,-1,STEP:9)
Block(-1,4,0,inspirations:glass_trapdoor:11)
Block(-1,4,1,STEP:9)
Block(-1,4,2,SANDSTONE:0)
Block(0,0,-4,SANDSTONE:0)
Block(0,0,-3,SANDSTONE:0)
Block(0,0,-2,SANDSTONE:0)
Block(0,0,-1,SANDSTONE:0)
Block(0,0,0,SANDSTONE:0)
Block(0,0,1,SANDSTONE:0)
Block(0,0,2,SANDSTONE:0)
Block(0,0,3,SANDSTONE:0)
Block(0,0,4,SANDSTONE:0)
Block(0,1,-4,biomesoplenty:redwood_fence:0)
Block(0,1,-3,SANDSTONE:0)
Block(0,1,-1,CARPET:0)
Block(0,1,0,CARPET:0)
Block(0,1,1,CARPET:0)
Block(0,1,2,STEP:9)
Block(0,1,3,SANDSTONE:0)
Block(0,1,4,biomesoplenty:redwood_fence:0)
Block(0,2,-4,quark:acacia_trapdoor:8)
Block(0,2,-3,inspirations:glass_trapdoor:5)
Block(0,2,3,inspirations:glass_trapdoor:4)
Block(0,2,4,quark:acacia_trapdoor:9)
Block(0,3,-4,STEP:1)
Block(0,3,-3,SANDSTONE:0)
Block(0,3,3,SANDSTONE:0)
Block(0,3,4,STEP:1)
Block(0,4,-2,SANDSTONE:0)
Block(0,4,-1,inspirations:glass_trapdoor:11)
Block(0,4,0,inspirations:glass_trapdoor:10)
Block(0,4,1,inspirations:glass_trapdoor:10)
Block(0,4,2,SANDSTONE:0)
Block(1,0,-4,SANDSTONE:0)
Block(1,0,-3,SANDSTONE:0)
Block(1,0,-2,SANDSTONE:0)
Block(1,0,-1,SANDSTONE:0)
Block(1,0,0,SANDSTONE:0)
Block(1,0,1,SANDSTONE:0)
Block(1,0,2,SANDSTONE:0)
Block(1,0,3,SANDSTONE:0)
Block(1,0,4,SANDSTONE:0)
Block(1,1,-3,SANDSTONE:0)
RandomBlock(1,1,-2,CHEST:3,20,CHEST:3,5,CHEST:3,30,CHEST:3,50,CHEST:3,100)
Block(1,1,-1,CARPET:0)
Block(1,1,1,CARPET:0)
Block(1,1,2,STEP:9)
Block(1,1,3,SANDSTONE:0)
Block(1,1,4,biomesoplenty:redwood_fence:0)
Block(1,2,-4,quark:acacia_trapdoor:8)
Block(1,2,-3,inspirations:glass_trapdoor:5)
Block(1,2,3,inspirations:glass_trapdoor:4)
Block(1,2,4,quark:acacia_trapdoor:13)
Block(1,3,-4,STEP:1)
Block(1,3,-3,SANDSTONE:0)
Block(1,3,3,SANDSTONE:0)
Block(1,3,4,STEP:1)
Block(1,4,-2,SANDSTONE:0)
Block(1,4,-1,STEP:9)
Block(1,4,0,inspirations:glass_trapdoor:9)
Block(1,4,1,STEP:9)
Block(1,4,2,SANDSTONE:0)
Block(2,0,-4,SANDSTONE:0)
Block(2,0,-3,SANDSTONE:0)
Block(2,0,-2,SANDSTONE:0)
Block(2,0,-1,SANDSTONE:0)
Block(2,0,0,SANDSTONE:0)
Block(2,0,1,SANDSTONE:0)
Block(2,0,2,SANDSTONE:0)
Block(2,0,3,SANDSTONE:0)
Block(2,0,4,SANDSTONE:0)
Block(2,1,-4,quark:sandy_bricks_wall:0)
Block(2,1,-3,SANDSTONE:0)
RandomBlock(2,1,-2,CHEST:3,20,CHEST:3,5,CHEST:3,30,CHEST:3,50,CHEST:3,100)
Block(2,1,2,WOOD:0)
Block(2,1,3,SANDSTONE:0)
Block(2,1,4,quark:sandy_bricks_wall:0)
Block(2,2,-4,quark:sandy_bricks_wall:0)
Block(2,2,-3,SANDSTONE:0)
Block(2,2,2,BOOKSHELF:0)
Block(2,2,3,SANDSTONE:0)
Block(2,2,4,quark:sandy_bricks_wall:0)
Block(2,3,-4,STEP:1)
Block(2,3,-3,SANDSTONE:0)
Block(2,3,3,SANDSTONE:0)
Block(2,3,4,STEP:1)
Block(2,4,-2,STEP:1)
Block(2,4,-1,SANDSTONE:0)
Block(2,4,0,SANDSTONE:0)
Block(2,4,1,SANDSTONE:0)
Block(2,4,2,STEP:1)
Block(3,0,-2,SANDSTONE:0)
Block(3,0,-1,SANDSTONE:0)
Block(3,0,0,SANDSTONE:0)
Block(3,0,1,SANDSTONE:0)
Block(3,0,2,SANDSTONE:0)
Block(3,1,-2,SANDSTONE:0)
Block(3,1,-1,SANDSTONE:2)
Block(3,1,0,WOODEN_DOOR:0)
Block(3,1,1,SANDSTONE:2)
Block(3,1,2,SANDSTONE:0)
Block(3,2,-2,SANDSTONE:0)
Block(3,2,-1,SANDSTONE:2)
Block(3,2,0,WOODEN_DOOR:9)
Block(3,2,1,SANDSTONE:2)
Block(3,2,2,SANDSTONE:0)
Block(3,3,-3,STEP:1)
Block(3,3,-2,SANDSTONE:0)
Block(3,3,-1,SANDSTONE:2)
Block(3,3,0,SANDSTONE:2)
Block(3,3,1,SANDSTONE:2)
Block(3,3,2,SANDSTONE:0)
Block(3,3,3,STEP:1)
Block(4,0,-2,SANDSTONE:0)
Block(4,0,-1,SANDSTONE:0)
Block(4,0,0,SANDSTONE:0)
Block(4,0,1,SANDSTONE:0)
Block(4,0,2,SANDSTONE:0)
Block(4,1,-2,quark:sandy_bricks_wall:0)
Block(4,1,1,biomesoplenty:redwood_fence:0)
Block(4,1,2,quark:sandy_bricks_wall:0)
Block(4,2,-2,quark:sandy_bricks_wall:0)
Block(4,2,2,quark:sandy_bricks_wall:0)
Block(4,3,-2,STEP:1)
Block(4,3,-1,STEP:1)
Block(4,3,0,STEP:1)
Block(4,3,1,STEP:1)
Block(4,3,2,STEP:1)

#######################################################################
# +-----------------------------------------------------------------+ #
# |                             Branches                            | #
# +-----------------------------------------------------------------+ #
#######################################################################


#######################################################################
# +-----------------------------------------------------------------+ #
# |                             Entities                            | #
# +-----------------------------------------------------------------+ #
#######################################################################


#######################################################################
# +-----------------------------------------------------------------+ #
# |                            Particles                            | #
# +-----------------------------------------------------------------+ #
#######################################################################


#######################################################################
# +-----------------------------------------------------------------+ #
# |                             Spawners                            | #
# +-----------------------------------------------------------------+ #
#######################################################################


#######################################################################
# +-----------------------------------------------------------------+ #
# |                             ModData                             | #
# +-----------------------------------------------------------------+ #
#######################################################################

