
#######################################################################
# +-----------------------------------------------------------------+ #
# |                            BO4 object                           | #
# +-----------------------------------------------------------------+ #
#######################################################################

Author: NLBlackEagle

Description: No description given

SettingsMode: WriteWithoutComments


#######################################################################
# +-----------------------------------------------------------------+ #
# |                          Main settings                          | #
# +-----------------------------------------------------------------+ #
#######################################################################

FixedRotation: 

Frequency: 0

SpawnHeight: highestSolidBlock

UseCenterForHighestBlock: true

##############################
# Height Limits for the BO4. #
##############################

MinHeight: 0

MaxHeight: 255

InheritBO3: 

InheritBO3Rotation: NORTH

OverrideChildSettings: true

OverrideParentHeight: false

CanOverride: true

BranchFrequency: 0

BranchFrequencyGroup: 

MustBeBelowOther: false

MustBeInside: 

CannotBeInside: 

ReplacesBO3: 

MustBeInsideWorldBorders: false

CanSpawnOnWater: false

SpawnOnWaterOnly: false

SpawnUnderWater: false

SpawnAtWaterLevel: false

HeightOffset: 0

RemoveAir: true

ReplaceAbove: 

ReplaceBelow: SANDSTONE

ReplaceWithBiomeBlocks: false

ReplaceWithSurfaceBlock: GRASS

ReplaceWithGroundBlock: DIRT

ReplaceWithStoneBlock: STONE

SmoothRadius: 0

SmoothHeightOffset: 0

SmoothStartTop: false

SmoothStartWood: false

SmoothingSurfaceBlock: 

SmoothingGroundBlock: 

BO3Group: 

IsSpawnPoint: false

DoReplaceBlocks: true


#######################################################################
# +-----------------------------------------------------------------+ #
# |                              Blocks                             | #
# +-----------------------------------------------------------------+ #
#######################################################################

Block(-4,0,-3,SANDSTONE:0)
Block(-4,0,-2,SANDSTONE:0)
Block(-4,0,-1,SANDSTONE:0)
Block(-4,0,0,SANDSTONE:0)
Block(-4,0,1,SANDSTONE:0)
Block(-4,0,2,SANDSTONE:0)
Block(-4,0,3,SANDSTONE:0)
Block(-4,1,-3,quark:sandy_bricks_wall:0)
Block(-4,1,-2,STEP:1)
Block(-4,1,-1,DOUBLE_STEP:1)
Block(-4,1,1,DOUBLE_STEP:1)
Block(-4,1,2,STEP:1)
Block(-4,1,3,quark:sandy_bricks_wall:0)
Block(-4,2,-1,quark:sandy_bricks:0)
Block(-4,2,0,rustic:iron_lattice:0)
Block(-4,2,1,quark:sandy_bricks:0)
Block(-4,2,3,quark:sandy_bricks_wall:0)
Block(-4,3,0,STEP:1)
Block(-4,3,1,STEP:1)
Block(-4,3,3,quark:sandy_bricks_wall:0)
Block(-4,4,0,STEP:1)
Block(-4,4,1,STEP:1)
Block(-4,4,2,STEP:1)
Block(-4,4,3,STEP:1)
Block(-3,0,-3,SANDSTONE:0)
Block(-3,0,-2,SANDSTONE:0)
Block(-3,0,-1,SANDSTONE:0)
Block(-3,0,1,SANDSTONE:0)
Block(-3,0,2,SANDSTONE:0)
Block(-3,0,3,SANDSTONE:0)
Block(-3,1,-3,SANDSTONE:0)
Block(-3,1,-2,SANDSTONE:0)
Block(-3,1,-1,SANDSTONE:0)
Block(-3,1,1,SANDSTONE:0)
Block(-3,1,2,SANDSTONE:0)
Block(-3,1,3,SANDSTONE:0)
Block(-3,2,1,quark:sandy_bricks:0)
Block(-3,2,2,quark:sandy_bricks:0)
Block(-3,2,3,quark:sandy_bricks:0)
Block(-3,3,1,SANDSTONE:0)
Block(-3,3,2,SANDSTONE:0)
Block(-3,3,3,SANDSTONE:0)
Block(-3,4,0,DOUBLE_STEP:1)
Block(-3,4,1,DOUBLE_STEP:1)
Block(-3,4,2,DOUBLE_STEP:1)
Block(-3,4,3,SANDSTONE:0)
Block(-2,0,-3,SANDSTONE:0)
Block(-2,0,-2,SANDSTONE:0)
Block(-2,0,-1,quark:world_stone_pavement:4)
Block(-2,0,1,quark:world_stone_pavement:4)
Block(-2,0,2,SANDSTONE:0)
Block(-2,0,3,SANDSTONE:0)
Block(-2,1,-3,STEP:1)
Block(-2,1,-2,SANDSTONE:0)
Block(-2,1,1,quark:stone_marble_slab:8)
Block(-2,1,2,SANDSTONE:0)
Block(-2,1,3,STEP:1)
Block(-2,2,-2,quark:sandy_bricks:0)
Block(-2,2,1,contenttweaker:bone_pile:0)
Block(-2,2,2,quark:sandy_bricks:0)
Block(-2,3,1,quark:stone_marble_slab:0)
Block(-2,3,2,SANDSTONE:0)
Block(-2,4,-3,SANDSTONE:0)
Block(-2,4,1,SANDSTONE:0)
Block(-2,4,2,DOUBLE_STEP:1)
Block(-2,4,3,SANDSTONE:0)
Block(-2,5,-3,STEP:1)
Block(-2,5,-2,STEP:1)
Block(-2,5,-1,STEP:1)
Block(-2,5,0,STEP:1)
Block(-2,5,1,STEP:1)
Block(-2,5,2,STEP:1)
Block(-2,5,3,STEP:1)
Block(-1,0,-3,SANDSTONE:0)
Block(-1,0,-2,SANDSTONE:0)
Block(-1,0,1,quark:world_stone_pavement:4)
Block(-1,0,2,SANDSTONE:0)
Block(-1,0,3,SANDSTONE:0)
Block(-1,1,-3,SANDSTONE:0)
Block(-1,1,-2,SANDSTONE:0)
Block(-1,1,1,quark:stone_marble_slab:8)
Block(-1,1,2,SANDSTONE:0)
Block(-1,1,3,SANDSTONE:0)
Block(-1,2,-3,quark:sandy_bricks:0)
Block(-1,2,-2,quark:sandy_bricks:0)
Block(-1,2,1,contenttweaker:bone_pile:0)
Block(-1,2,2,quark:sandy_bricks:0)
Block(-1,2,3,quark:sandy_bricks:0)
Block(-1,3,-3,SANDSTONE:0)
Block(-1,3,-2,SANDSTONE:0)
Block(-1,3,1,quark:stone_marble_slab:0)
Block(-1,3,2,SANDSTONE:0)
Block(-1,3,3,SANDSTONE:0)
Block(-1,4,-3,SANDSTONE:0)
Block(-1,4,1,SANDSTONE:0)
Block(-1,4,2,SANDSTONE:0)
Block(-1,4,3,SANDSTONE:0)
Block(-1,5,-3,SANDSTONE:0)
Block(-1,5,-2,DOUBLE_STEP:1)
Block(-1,5,-1,STEP:1)
Block(-1,5,0,STEP:1)
Block(-1,5,1,DOUBLE_STEP:1)
Block(-1,5,2,DOUBLE_STEP:1)
Block(-1,5,3,SANDSTONE:0)
Block(0,0,-3,SANDSTONE:0)
Block(0,0,-2,SANDSTONE:0)
Block(0,0,-1,SANDSTONE:0)
Block(0,0,1,SANDSTONE:0)
Block(0,0,2,SANDSTONE:0)
Block(0,0,3,SANDSTONE:0)
Block(0,1,-3,STEP:1)
Block(0,1,-2,SANDSTONE:0)
Block(0,1,2,SANDSTONE:0)
Block(0,1,3,STEP:1)
Block(0,2,-2,quark:sandy_bricks:0)
Block(0,2,2,quark:sandy_bricks:0)
Block(0,3,-2,SANDSTONE:0)
Block(0,3,2,SANDSTONE:0)
Block(0,4,-3,SANDSTONE:0)
Block(0,4,1,SANDSTONE:0)
Block(0,4,2,SANDSTONE:0)
Block(0,4,3,SANDSTONE:0)
Block(0,5,-3,STEP:1)
Block(0,5,-2,DOUBLE_STEP:1)
Block(0,5,-1,DOUBLE_STEP:1)
Block(0,5,0,DOUBLE_STEP:1)
Block(0,5,1,DOUBLE_STEP:1)
Block(0,5,2,DOUBLE_STEP:1)
Block(0,5,3,SANDSTONE:0)
Block(1,0,-3,SANDSTONE:0)
Block(1,0,-2,SANDSTONE:0)
Block(1,0,-1,quark:world_stone_pavement:4)
Block(1,0,1,quark:world_stone_pavement:4)
Block(1,0,2,SANDSTONE:0)
Block(1,0,3,SANDSTONE:0)
Block(1,1,-3,SANDSTONE:0)
Block(1,1,-2,SANDSTONE:0)
Block(1,1,-1,quark:stone_marble_slab:8)
Block(1,1,1,quark:stone_marble_slab:8)
Block(1,1,2,SANDSTONE:0)
Block(1,1,3,SANDSTONE:0)
Block(1,2,-3,quark:sandy_bricks:0)
Block(1,2,-2,quark:sandy_bricks:0)
Block(1,2,-1,contenttweaker:bone_pile:0)
Block(1,2,1,contenttweaker:bone_pile:0)
Block(1,2,2,quark:sandy_bricks:0)
Block(1,3,-3,SANDSTONE:0)
Block(1,3,-2,SANDSTONE:0)
Block(1,3,1,quark:stone_marble_slab:0)
Block(1,3,2,SANDSTONE:0)
Block(1,4,-3,SANDSTONE:0)
Block(1,4,-2,SANDSTONE:0)
Block(1,4,-1,SANDSTONE:0)
Block(1,4,1,SANDSTONE:0)
Block(1,4,2,SANDSTONE:0)
Block(1,4,3,SANDSTONE:0)
Block(1,5,-3,STEP:1)
Block(1,5,-2,DOUBLE_STEP:1)
Block(1,5,-1,DOUBLE_STEP:1)
Block(1,5,0,DOUBLE_STEP:1)
Block(1,5,1,DOUBLE_STEP:1)
Block(1,5,2,DOUBLE_STEP:1)
Block(1,5,3,SANDSTONE:0)
Block(2,0,-3,SANDSTONE:0)
Block(2,0,-2,SANDSTONE:0)
Block(2,0,-1,quark:world_stone_pavement:4)
Block(2,0,1,quark:world_stone_pavement:4)
Block(2,0,2,SANDSTONE:0)
Block(2,0,3,SANDSTONE:0)
Block(2,1,-3,STEP:1)
Block(2,1,-2,DOUBLE_STEP:1)
Block(2,1,-1,quark:stone_marble_slab:8)
Block(2,1,1,quark:stone_marble_slab:8)
Block(2,1,2,SANDSTONE:0)
Block(2,1,3,STEP:1)
Block(2,2,-2,quark:sandy_bricks:0)
Block(2,2,-1,contenttweaker:bone_pile:0)
Block(2,2,2,quark:sandy_bricks:0)
Block(2,3,-3,TORCH:4)
Block(2,3,-2,SANDSTONE:0)
Block(2,3,-1,quark:stone_marble_slab:0)
Block(2,3,1,quark:stone_marble_slab:0)
Block(2,3,2,SANDSTONE:0)
Block(2,4,-3,SANDSTONE:0)
Block(2,4,-2,DOUBLE_STEP:1)
Block(2,4,-1,SANDSTONE:0)
Block(2,4,0,SANDSTONE:0)
Block(2,4,1,SANDSTONE:0)
Block(2,4,2,DOUBLE_STEP:1)
Block(2,4,3,SANDSTONE:0)
Block(2,5,-3,STEP:1)
Block(2,5,-2,STEP:1)
Block(2,5,-1,STEP:1)
Block(2,5,0,STEP:1)
Block(2,5,2,STEP:1)
Block(2,5,3,STEP:1)
Block(3,0,-3,SANDSTONE:0)
Block(3,0,-2,SANDSTONE:0)
Block(3,0,-1,SANDSTONE:0)
Block(3,0,0,SANDSTONE:0)
Block(3,0,1,SANDSTONE:0)
Block(3,0,2,SANDSTONE:0)
Block(3,0,3,SANDSTONE:0)
Block(3,1,-3,SANDSTONE:0)
Block(3,1,-2,SANDSTONE:0)
Block(3,1,-1,SANDSTONE:0)
Block(3,1,1,SANDSTONE:0)
Block(3,1,2,SANDSTONE:0)
Block(3,1,3,SANDSTONE:0)
Block(3,2,-3,quark:sandy_bricks:0)
Block(3,2,-2,quark:sandy_bricks:0)
Block(3,2,-1,quark:sandy_bricks:0)
Block(3,2,1,quark:sandy_bricks:0)
Block(3,2,2,quark:sandy_bricks:0)
Block(3,2,3,quark:sandy_bricks:0)
Block(3,3,-3,SANDSTONE:0)
Block(3,3,-2,SANDSTONE:0)
Block(3,3,-1,SANDSTONE:0)
Block(3,3,0,SANDSTONE:0)
Block(3,3,1,SANDSTONE:0)
Block(3,3,2,SANDSTONE:0)
Block(3,4,-3,SANDSTONE:0)
Block(3,4,-2,DOUBLE_STEP:1)
Block(3,4,-1,STEP:1)
Block(3,4,0,SANDSTONE:0)
Block(3,4,1,DOUBLE_STEP:1)
Block(3,4,2,DOUBLE_STEP:1)
Block(3,4,3,SANDSTONE:0)
Block(4,0,-3,SANDSTONE:0)
Block(4,0,-2,SANDSTONE:0)
Block(4,0,-1,SANDSTONE:0)
Block(4,0,0,SANDSTONE:0)
Block(4,0,1,SANDSTONE:0)
Block(4,0,2,SANDSTONE:0)
Block(4,0,3,SANDSTONE:0)
Block(4,1,-3,quark:sandy_bricks_wall:0)
Block(4,1,-2,STEP:1)
Block(4,1,-1,SANDSTONE:0)
Block(4,1,1,SANDSTONE:0)
Block(4,1,2,STEP:1)
Block(4,1,3,quark:sandy_bricks_wall:0)
Block(4,2,-1,quark:sandy_bricks:0)
Block(4,2,1,quark:sandy_bricks:0)
Block(4,2,3,quark:sandy_bricks_wall:0)
Block(4,3,-1,STEP:1)
Block(4,3,0,STEP:1)
Block(4,3,1,STEP:1)
Block(4,3,3,quark:sandy_bricks_wall:0)
Block(4,4,0,STEP:1)
Block(4,4,1,STEP:1)
Block(4,4,2,STEP:1)
Block(4,4,3,STEP:1)

#######################################################################
# +-----------------------------------------------------------------+ #
# |                             Branches                            | #
# +-----------------------------------------------------------------+ #
#######################################################################


#######################################################################
# +-----------------------------------------------------------------+ #
# |                             Entities                            | #
# +-----------------------------------------------------------------+ #
#######################################################################


#######################################################################
# +-----------------------------------------------------------------+ #
# |                            Particles                            | #
# +-----------------------------------------------------------------+ #
#######################################################################


#######################################################################
# +-----------------------------------------------------------------+ #
# |                             Spawners                            | #
# +-----------------------------------------------------------------+ #
#######################################################################


#######################################################################
# +-----------------------------------------------------------------+ #
# |                             ModData                             | #
# +-----------------------------------------------------------------+ #
#######################################################################

