
#######################################################################
# +-----------------------------------------------------------------+ #
# |                            BO4 object                           | #
# +-----------------------------------------------------------------+ #
#######################################################################

Author: NLBlackEagle

Description: No description given

SettingsMode: WriteWithoutComments


#######################################################################
# +-----------------------------------------------------------------+ #
# |                          Main settings                          | #
# +-----------------------------------------------------------------+ #
#######################################################################

FixedRotation: 

Frequency: 0

SpawnHeight: highestSolidBlock

UseCenterForHighestBlock: true

##############################
# Height Limits for the BO4. #
##############################

MinHeight: 0

MaxHeight: 255

InheritBO3: 

InheritBO3Rotation: NORTH

OverrideChildSettings: true

OverrideParentHeight: false

CanOverride: true

BranchFrequency: 0

BranchFrequencyGroup: 

MustBeBelowOther: false

MustBeInside: 

CannotBeInside: 

ReplacesBO3: 

MustBeInsideWorldBorders: false

CanSpawnOnWater: false

SpawnOnWaterOnly: false

SpawnUnderWater: false

SpawnAtWaterLevel: false

HeightOffset: 0

RemoveAir: true

ReplaceAbove: 

ReplaceBelow: SANDSTONE

ReplaceWithBiomeBlocks: false

ReplaceWithSurfaceBlock: GRASS

ReplaceWithGroundBlock: DIRT

ReplaceWithStoneBlock: STONE

SmoothRadius: 0

SmoothHeightOffset: 0

SmoothStartTop: false

SmoothStartWood: false

SmoothingSurfaceBlock: 

SmoothingGroundBlock: 

BO3Group: 

IsSpawnPoint: false

DoReplaceBlocks: true


#######################################################################
# +-----------------------------------------------------------------+ #
# |                              Blocks                             | #
# +-----------------------------------------------------------------+ #
#######################################################################

Block(-5,0,-4,SANDSTONE:0)
Block(-5,0,-3,SANDSTONE:0)
Block(-5,0,-2,SANDSTONE:0)
Block(-5,0,-1,SANDSTONE:0)
Block(-5,0,0,SANDSTONE:0)
Block(-5,0,1,SANDSTONE:0)
Block(-5,0,2,SANDSTONE:0)
Block(-5,0,3,SANDSTONE:0)
Block(-5,0,4,SANDSTONE:0)
Block(-5,1,-4,DOUBLE_STEP:1)
Block(-5,1,-3,STEP:1)
Block(-5,1,-2,STEP:1)
Block(-5,1,-1,STEP:1)
Block(-5,1,0,DOUBLE_STEP:1)
Block(-5,1,1,STEP:1)
Block(-5,1,2,STEP:1)
Block(-5,1,3,STEP:1)
Block(-5,1,4,DOUBLE_STEP:1)
Block(-5,2,-4,quark:sandy_bricks_wall:0)
Block(-5,2,0,quark:sandy_bricks_wall:0)
Block(-5,2,4,quark:sandy_bricks_wall:0)
Block(-5,3,-4,quark:sandy_bricks_wall:0)
Block(-5,3,0,quark:sandy_bricks_wall:0)
Block(-5,3,4,quark:sandy_bricks_wall:0)
Block(-5,4,-4,quark:sandy_bricks_wall:0)
Block(-5,4,0,quark:sandy_bricks_wall:0)
Block(-5,4,4,quark:sandy_bricks_wall:0)
Block(-5,5,-4,STEP:1)
Block(-5,5,-3,STEP:1)
Block(-5,5,-2,STEP:1)
Block(-5,5,-1,STEP:1)
Block(-5,5,0,STEP:1)
Block(-5,5,1,STEP:1)
Block(-5,5,2,STEP:1)
Block(-5,5,3,STEP:1)
Block(-5,5,4,STEP:1)
Block(-4,0,-4,SANDSTONE:0)
Block(-4,0,-3,SANDSTONE:0)
Block(-4,0,-2,SANDSTONE:0)
Block(-4,0,-1,SANDSTONE:0)
Block(-4,0,0,SANDSTONE:0)
Block(-4,0,1,SANDSTONE:0)
Block(-4,0,2,SANDSTONE:0)
Block(-4,0,3,SANDSTONE:0)
Block(-4,0,4,SANDSTONE:0)
Block(-4,1,-4,STEP:1)
Block(-4,1,-3,SANDSTONE:0)
Block(-4,1,-2,STEP:1)
Block(-4,1,-1,STEP:1)
Block(-4,1,0,SANDSTONE:0)
Block(-4,1,1,STEP:1)
Block(-4,1,2,STEP:1)
Block(-4,1,3,SANDSTONE:0)
Block(-4,1,4,STEP:1)
Block(-4,2,-3,SANDSTONE:0)
Block(-4,2,0,SANDSTONE:0)
Block(-4,2,3,SANDSTONE:0)
Block(-4,3,-3,SANDSTONE:0)
Block(-4,3,0,SANDSTONE:0)
Block(-4,3,3,SANDSTONE:0)
Block(-4,4,-3,SANDSTONE:0)
Block(-4,4,0,SANDSTONE:0)
Block(-4,4,3,SANDSTONE:0)
Block(-4,5,-4,STEP:1)
Block(-4,5,-3,SANDSTONE:0)
Block(-4,5,-2,SANDSTONE:0)
Block(-4,5,-1,SANDSTONE:0)
Block(-4,5,0,SANDSTONE:0)
Block(-4,5,1,SANDSTONE:0)
Block(-4,5,2,SANDSTONE:0)
Block(-4,5,3,SANDSTONE:0)
Block(-4,5,4,STEP:1)
Block(-3,0,-4,SANDSTONE:0)
Block(-3,0,-3,SANDSTONE:0)
Block(-3,0,-2,SANDSTONE:0)
Block(-3,0,-1,SANDSTONE:0)
Block(-3,0,0,SANDSTONE:0)
Block(-3,0,1,SANDSTONE:0)
Block(-3,0,2,SANDSTONE:0)
Block(-3,0,3,SANDSTONE:0)
Block(-3,0,4,SANDSTONE:0)
Block(-3,1,-4,STEP:1)
Block(-3,1,-3,STEP:1)
Block(-3,1,-2,STEP:1)
Block(-3,1,-1,STEP:1)
Block(-3,1,0,STEP:1)
Block(-3,1,1,STEP:1)
Block(-3,1,2,STEP:1)
Block(-3,1,3,STEP:1)
Block(-3,1,4,STEP:1)
Block(-3,5,-4,STEP:1)
Block(-3,5,-3,SANDSTONE:0)
Block(-3,5,-2,SANDSTONE:0)
Block(-3,5,-1,SANDSTONE:0)
Block(-3,5,0,SANDSTONE:0)
Block(-3,5,1,SANDSTONE:0)
Block(-3,5,2,SANDSTONE:0)
Block(-3,5,3,SANDSTONE:0)
Block(-3,5,4,STEP:1)
Block(-3,6,-2,STEP:1)
Block(-3,6,-1,STEP:1)
Block(-3,6,0,STEP:1)
Block(-3,6,1,STEP:1)
Block(-3,6,2,STEP:1)
Block(-2,0,-4,SANDSTONE:0)
Block(-2,0,-3,SANDSTONE:0)
Block(-2,0,-2,SANDSTONE:0)
Block(-2,0,-1,SANDSTONE:0)
Block(-2,0,0,SANDSTONE:0)
Block(-2,0,1,SANDSTONE:0)
Block(-2,0,2,SANDSTONE:0)
Block(-2,0,3,SANDSTONE:0)
Block(-2,0,4,SANDSTONE:0)
Block(-2,1,-4,STEP:1)
Block(-2,1,-3,STEP:1)
Block(-2,1,-2,STEP:1)
Block(-2,1,-1,quark:sandy_bricks:0)
Block(-2,1,0,quark:sandy_bricks:0)
Block(-2,1,1,quark:sandy_bricks:0)
Block(-2,1,2,STEP:1)
Block(-2,1,3,STEP:1)
Block(-2,1,4,STEP:1)
Block(-2,5,-4,STEP:1)
Block(-2,5,-3,SANDSTONE:0)
Block(-2,5,-2,SANDSTONE:0)
Block(-2,5,-1,SANDSTONE:0)
Block(-2,5,0,SANDSTONE:0)
Block(-2,5,1,SANDSTONE:0)
Block(-2,5,2,SANDSTONE:0)
Block(-2,5,3,SANDSTONE:0)
Block(-2,5,4,STEP:1)
Block(-2,6,-2,STEP:1)
Block(-2,6,-1,DOUBLE_STEP:1)
Block(-2,6,0,DOUBLE_STEP:1)
Block(-2,6,1,DOUBLE_STEP:1)
Block(-2,6,2,STEP:1)
Block(-1,0,-4,SANDSTONE:0)
Block(-1,0,-3,SANDSTONE:0)
Block(-1,0,-2,SANDSTONE:0)
Block(-1,0,-1,SANDSTONE:0)
Block(-1,0,0,SANDSTONE:0)
Block(-1,0,1,SANDSTONE:0)
Block(-1,0,2,SANDSTONE:0)
Block(-1,0,3,SANDSTONE:0)
Block(-1,0,4,SANDSTONE:0)
Block(-1,1,-4,DOUBLE_STEP:1)
Block(-1,1,-3,SANDSTONE:0)
Block(-1,1,-2,STEP:1)
Block(-1,1,-1,quark:sandy_bricks:0)
Block(-1,1,0,quark:sandy_bricks:0)
Block(-1,1,1,quark:sandy_bricks:0)
Block(-1,1,2,STEP:1)
Block(-1,1,3,SANDSTONE:0)
Block(-1,1,4,DOUBLE_STEP:1)
Block(-1,2,-4,quark:sandy_bricks_wall:0)
Block(-1,2,-3,SANDSTONE:0)
Block(-1,2,0,quark:sandy_bricks:0)
Block(-1,2,3,SANDSTONE:0)
Block(-1,2,4,quark:sandy_bricks_wall:0)
Block(-1,3,-4,quark:sandy_bricks_wall:0)
Block(-1,3,-3,SANDSTONE:0)
Block(-1,3,0,quark:sandy_bricks_slab:0)
Block(-1,3,3,SANDSTONE:0)
Block(-1,3,4,quark:sandy_bricks_wall:0)
Block(-1,4,-4,quark:sandy_bricks_wall:0)
Block(-1,4,-3,SANDSTONE:0)
Block(-1,4,-2,STEP:9)
Block(-1,4,-1,STEP:9)
Block(-1,4,0,STEP:9)
Block(-1,4,1,STEP:9)
Block(-1,4,2,STEP:9)
Block(-1,4,3,SANDSTONE:0)
Block(-1,4,4,quark:sandy_bricks_wall:0)
Block(-1,5,-4,STEP:1)
Block(-1,5,-3,SANDSTONE:0)
Block(-1,5,-2,SANDSTONE:0)
Block(-1,5,-1,SANDSTONE:0)
Block(-1,5,0,SANDSTONE:0)
Block(-1,5,1,SANDSTONE:0)
Block(-1,5,2,SANDSTONE:0)
Block(-1,5,3,SANDSTONE:0)
Block(-1,5,4,STEP:1)
Block(-1,6,-2,STEP:1)
Block(-1,6,-1,DOUBLE_STEP:1)
Block(-1,6,0,DOUBLE_STEP:1)
Block(-1,6,1,DOUBLE_STEP:1)
Block(-1,6,2,STEP:1)
Block(-1,7,0,STEP:1)
Block(0,0,-4,SANDSTONE:0)
Block(0,0,-3,SANDSTONE:0)
Block(0,0,-2,SANDSTONE:0)
Block(0,0,-1,SANDSTONE:0)
Block(0,0,0,SANDSTONE:0)
Block(0,0,1,SANDSTONE:0)
Block(0,0,2,SANDSTONE:0)
Block(0,0,3,SANDSTONE:0)
Block(0,0,4,SANDSTONE:0)
Block(0,1,-4,STEP:1)
Block(0,1,-3,STEP:1)
Block(0,1,-2,STEP:1)
Block(0,1,-1,quark:sandy_bricks:0)
Block(0,1,0,iceandfire:chared_gravel:0)
Block(0,1,1,quark:sandy_bricks:0)
Block(0,1,2,STEP:1)
Block(0,1,3,STEP:1)
Block(0,1,4,STEP:1)
Block(0,2,0,simpledifficulty:campfire:7)
Block(0,3,0,quark:sandy_bricks_slab:0)
Block(0,5,-4,STEP:1)
Block(0,5,-3,SANDSTONE:0)
Block(0,5,-2,SANDSTONE:0)
Block(0,5,-1,SANDSTONE:0)
Block(0,5,0,SANDSTONE:0)
Block(0,5,1,SANDSTONE:0)
Block(0,5,2,SANDSTONE:0)
Block(0,5,3,SANDSTONE:0)
Block(0,5,4,STEP:1)
Block(0,6,-2,STEP:1)
Block(0,6,-1,DOUBLE_STEP:1)
Block(0,6,0,DOUBLE_STEP:1)
Block(0,6,1,DOUBLE_STEP:1)
Block(0,6,2,STEP:1)
Block(0,7,0,STEP:1)
Block(1,0,-4,SANDSTONE:0)
Block(1,0,-3,SANDSTONE:0)
Block(1,0,-2,SANDSTONE:0)
Block(1,0,-1,SANDSTONE:0)
Block(1,0,0,SANDSTONE:0)
Block(1,0,1,SANDSTONE:0)
Block(1,0,2,SANDSTONE:0)
Block(1,0,3,SANDSTONE:0)
Block(1,0,4,SANDSTONE:0)
Block(1,1,-4,STEP:1)
Block(1,1,-3,STEP:1)
Block(1,1,-2,STEP:1)
Block(1,1,-1,quark:sandy_bricks:0)
Block(1,1,0,iceandfire:chared_gravel:0)
Block(1,1,1,quark:sandy_bricks:0)
Block(1,1,2,STEP:1)
Block(1,1,3,STEP:1)
Block(1,1,4,STEP:1)
Block(1,2,0,simpledifficulty:campfire:3)
Block(1,3,0,quark:sandy_bricks_slab:0)
Block(1,5,-4,STEP:1)
Block(1,5,-3,SANDSTONE:0)
Block(1,5,-2,SANDSTONE:0)
Block(1,5,-1,SANDSTONE:0)
Block(1,5,0,SANDSTONE:0)
Block(1,5,1,SANDSTONE:0)
Block(1,5,2,SANDSTONE:0)
Block(1,5,3,SANDSTONE:0)
Block(1,5,4,STEP:1)
Block(1,6,-2,STEP:1)
Block(1,6,-1,DOUBLE_STEP:1)
Block(1,6,0,DOUBLE_STEP:1)
Block(1,6,1,DOUBLE_STEP:1)
Block(1,6,2,STEP:1)
Block(1,7,0,STEP:1)
Block(2,0,-4,SANDSTONE:0)
Block(2,0,-3,SANDSTONE:0)
Block(2,0,-2,SANDSTONE:0)
Block(2,0,-1,SANDSTONE:0)
Block(2,0,0,SANDSTONE:0)
Block(2,0,1,SANDSTONE:0)
Block(2,0,2,SANDSTONE:0)
Block(2,0,3,SANDSTONE:0)
Block(2,0,4,SANDSTONE:0)
Block(2,1,-4,DOUBLE_STEP:1)
Block(2,1,-3,SANDSTONE:0)
Block(2,1,-2,STEP:1)
Block(2,1,-1,quark:sandy_bricks:0)
Block(2,1,0,quark:sandy_bricks:0)
Block(2,1,1,quark:sandy_bricks:0)
Block(2,1,2,STEP:1)
Block(2,1,3,SANDSTONE:0)
Block(2,1,4,DOUBLE_STEP:1)
Block(2,2,-4,quark:sandy_bricks_wall:0)
Block(2,2,-3,SANDSTONE:0)
Block(2,2,0,quark:sandy_bricks:0)
Block(2,2,3,SANDSTONE:0)
Block(2,2,4,quark:sandy_bricks_wall:0)
Block(2,3,-4,quark:sandy_bricks_wall:0)
Block(2,3,-3,SANDSTONE:0)
Block(2,3,0,quark:sandy_bricks_slab:0)
Block(2,3,3,SANDSTONE:0)
Block(2,3,4,quark:sandy_bricks_wall:0)
Block(2,4,-4,quark:sandy_bricks_wall:0)
Block(2,4,-3,SANDSTONE:0)
Block(2,4,-2,STEP:9)
Block(2,4,-1,STEP:9)
Block(2,4,0,STEP:9)
Block(2,4,1,STEP:9)
Block(2,4,2,STEP:9)
Block(2,4,3,SANDSTONE:0)
Block(2,4,4,quark:sandy_bricks_wall:0)
Block(2,5,-4,STEP:1)
Block(2,5,-3,SANDSTONE:0)
Block(2,5,-2,SANDSTONE:0)
Block(2,5,-1,SANDSTONE:0)
Block(2,5,0,SANDSTONE:0)
Block(2,5,1,SANDSTONE:0)
Block(2,5,2,SANDSTONE:0)
Block(2,5,3,SANDSTONE:0)
Block(2,5,4,STEP:1)
Block(2,6,-2,STEP:1)
Block(2,6,-1,DOUBLE_STEP:1)
Block(2,6,0,DOUBLE_STEP:1)
Block(2,6,1,DOUBLE_STEP:1)
Block(2,6,2,STEP:1)
Block(2,7,0,STEP:1)
Block(3,0,-4,SANDSTONE:0)
Block(3,0,-3,SANDSTONE:0)
Block(3,0,-2,SANDSTONE:0)
Block(3,0,-1,SANDSTONE:0)
Block(3,0,0,SANDSTONE:0)
Block(3,0,1,SANDSTONE:0)
Block(3,0,2,SANDSTONE:0)
Block(3,0,3,SANDSTONE:0)
Block(3,0,4,SANDSTONE:0)
Block(3,1,-4,STEP:1)
Block(3,1,-3,STEP:1)
Block(3,1,-2,STEP:1)
Block(3,1,-1,quark:sandy_bricks:0)
Block(3,1,0,quark:sandy_bricks:0)
Block(3,1,1,quark:sandy_bricks:0)
Block(3,1,2,STEP:1)
Block(3,1,3,STEP:1)
Block(3,1,4,STEP:1)
Block(3,5,-4,STEP:1)
Block(3,5,-3,SANDSTONE:0)
Block(3,5,-2,SANDSTONE:0)
Block(3,5,-1,SANDSTONE:0)
Block(3,5,0,SANDSTONE:0)
Block(3,5,1,SANDSTONE:0)
Block(3,5,2,SANDSTONE:0)
Block(3,5,3,SANDSTONE:0)
Block(3,5,4,STEP:1)
Block(3,6,-2,STEP:1)
Block(3,6,-1,DOUBLE_STEP:1)
Block(3,6,0,DOUBLE_STEP:1)
Block(3,6,1,DOUBLE_STEP:1)
Block(3,6,2,STEP:1)
Block(4,0,-4,SANDSTONE:0)
Block(4,0,-3,SANDSTONE:0)
Block(4,0,-2,SANDSTONE:0)
Block(4,0,-1,SANDSTONE:0)
Block(4,0,0,SANDSTONE:0)
Block(4,0,1,SANDSTONE:0)
Block(4,0,2,SANDSTONE:0)
Block(4,0,3,SANDSTONE:0)
Block(4,0,4,SANDSTONE:0)
Block(4,1,-4,STEP:1)
Block(4,1,-3,STEP:1)
Block(4,1,-2,STEP:1)
Block(4,1,-1,STEP:1)
Block(4,1,0,STEP:1)
Block(4,1,1,STEP:1)
Block(4,1,2,STEP:1)
Block(4,1,3,STEP:1)
Block(4,1,4,STEP:1)
Block(4,5,-4,STEP:1)
Block(4,5,-3,SANDSTONE:0)
Block(4,5,-2,SANDSTONE:0)
Block(4,5,-1,SANDSTONE:0)
Block(4,5,0,SANDSTONE:0)
Block(4,5,1,SANDSTONE:0)
Block(4,5,2,SANDSTONE:0)
Block(4,5,3,SANDSTONE:0)
Block(4,5,4,STEP:1)
Block(4,6,-2,STEP:1)
Block(4,6,-1,STEP:1)
Block(4,6,0,STEP:1)
Block(4,6,1,STEP:1)
Block(4,6,2,STEP:1)
Block(5,0,-4,SANDSTONE:0)
Block(5,0,-3,SANDSTONE:0)
Block(5,0,-2,SANDSTONE:0)
Block(5,0,-1,SANDSTONE:0)
Block(5,0,0,SANDSTONE:0)
Block(5,0,1,SANDSTONE:0)
Block(5,0,2,SANDSTONE:0)
Block(5,0,3,SANDSTONE:0)
Block(5,0,4,SANDSTONE:0)
Block(5,1,-4,STEP:1)
Block(5,1,-3,SANDSTONE:0)
Block(5,1,-2,STEP:1)
Block(5,1,-1,STEP:1)
Block(5,1,0,SANDSTONE:0)
Block(5,1,1,STEP:1)
Block(5,1,2,STEP:1)
Block(5,1,3,SANDSTONE:0)
Block(5,1,4,STEP:1)
Block(5,2,-3,SANDSTONE:0)
Block(5,2,0,SANDSTONE:0)
Block(5,2,3,SANDSTONE:0)
Block(5,3,-3,SANDSTONE:0)
Block(5,3,0,SANDSTONE:0)
Block(5,3,3,SANDSTONE:0)
Block(5,4,-3,SANDSTONE:0)
Block(5,4,0,SANDSTONE:0)
Block(5,4,3,SANDSTONE:0)
Block(5,5,-4,STEP:1)
Block(5,5,-3,SANDSTONE:0)
Block(5,5,-2,SANDSTONE:0)
Block(5,5,-1,SANDSTONE:0)
Block(5,5,0,SANDSTONE:0)
Block(5,5,1,SANDSTONE:0)
Block(5,5,2,SANDSTONE:0)
Block(5,5,3,SANDSTONE:0)
Block(5,5,4,STEP:1)
Block(6,0,-4,SANDSTONE:0)
Block(6,0,-3,SANDSTONE:0)
Block(6,0,-2,SANDSTONE:0)
Block(6,0,-1,SANDSTONE:0)
Block(6,0,0,SANDSTONE:0)
Block(6,0,1,SANDSTONE:0)
Block(6,0,2,SANDSTONE:0)
Block(6,0,3,SANDSTONE:0)
Block(6,0,4,SANDSTONE:0)
Block(6,1,-4,DOUBLE_STEP:1)
Block(6,1,-3,STEP:1)
Block(6,1,-2,STEP:1)
Block(6,1,-1,STEP:1)
Block(6,1,0,DOUBLE_STEP:1)
Block(6,1,1,STEP:1)
Block(6,1,2,STEP:1)
Block(6,1,3,STEP:1)
Block(6,1,4,DOUBLE_STEP:1)
Block(6,2,-4,quark:sandy_bricks_wall:0)
Block(6,2,0,quark:sandy_bricks_wall:0)
Block(6,2,4,quark:sandy_bricks_wall:0)
Block(6,3,-4,quark:sandy_bricks_wall:0)
Block(6,3,0,quark:sandy_bricks_wall:0)
Block(6,3,4,quark:sandy_bricks_wall:0)
Block(6,4,-4,quark:sandy_bricks_wall:0)
Block(6,4,0,quark:sandy_bricks_wall:0)
Block(6,4,4,quark:sandy_bricks_wall:0)
Block(6,5,-4,STEP:1)
Block(6,5,-3,STEP:1)
Block(6,5,-2,STEP:1)
Block(6,5,-1,STEP:1)
Block(6,5,0,STEP:1)
Block(6,5,1,STEP:1)
Block(6,5,2,STEP:1)
Block(6,5,3,STEP:1)
Block(6,5,4,STEP:1)

#######################################################################
# +-----------------------------------------------------------------+ #
# |                             Branches                            | #
# +-----------------------------------------------------------------+ #
#######################################################################


#######################################################################
# +-----------------------------------------------------------------+ #
# |                             Entities                            | #
# +-----------------------------------------------------------------+ #
#######################################################################


#######################################################################
# +-----------------------------------------------------------------+ #
# |                            Particles                            | #
# +-----------------------------------------------------------------+ #
#######################################################################


#######################################################################
# +-----------------------------------------------------------------+ #
# |                             Spawners                            | #
# +-----------------------------------------------------------------+ #
#######################################################################


#######################################################################
# +-----------------------------------------------------------------+ #
# |                             ModData                             | #
# +-----------------------------------------------------------------+ #
#######################################################################

