
#######################################################################
# +-----------------------------------------------------------------+ #
# |                            BO4 object                           | #
# +-----------------------------------------------------------------+ #
#######################################################################

Author: NLBlackEagle

Description: No description given

SettingsMode: WriteWithoutComments


#######################################################################
# +-----------------------------------------------------------------+ #
# |                          Main settings                          | #
# +-----------------------------------------------------------------+ #
#######################################################################

FixedRotation: 

Frequency: 0

SpawnHeight: highestSolidBlock

UseCenterForHighestBlock: true

##############################
# Height Limits for the BO4. #
##############################

MinHeight: 0

MaxHeight: 255

InheritBO3: 

InheritBO3Rotation: NORTH

OverrideChildSettings: true

OverrideParentHeight: false

CanOverride: true

BranchFrequency: 0

BranchFrequencyGroup: 

MustBeBelowOther: false

MustBeInside: 

CannotBeInside: 

ReplacesBO3: 

MustBeInsideWorldBorders: false

CanSpawnOnWater: false

SpawnOnWaterOnly: false

SpawnUnderWater: false

SpawnAtWaterLevel: false

HeightOffset: 0

RemoveAir: true

ReplaceAbove: 

ReplaceBelow: SANDSTONE

ReplaceWithBiomeBlocks: false

ReplaceWithSurfaceBlock: GRASS

ReplaceWithGroundBlock: DIRT

ReplaceWithStoneBlock: STONE

SmoothRadius: 0

SmoothHeightOffset: 0

SmoothStartTop: false

SmoothStartWood: false

SmoothingSurfaceBlock: 

SmoothingGroundBlock: 

BO3Group: 

IsSpawnPoint: false

DoReplaceBlocks: true


#######################################################################
# +-----------------------------------------------------------------+ #
# |                              Blocks                             | #
# +-----------------------------------------------------------------+ #
#######################################################################

Block(-5,0,-4,SANDSTONE:0)
Block(-5,0,-3,SANDSTONE:0)
Block(-5,0,-2,SANDSTONE:0)
Block(-5,0,-1,SANDSTONE:0)
Block(-5,0,0,SANDSTONE:0)
Block(-5,0,1,SANDSTONE:0)
Block(-5,0,2,SANDSTONE:0)
Block(-5,0,3,SANDSTONE:0)
Block(-5,0,4,SANDSTONE:0)
Block(-5,1,-4,biomesoplenty:redwood_fence:0)
Block(-5,1,-3,biomesoplenty:redwood_fence:0)
Block(-5,1,-2,biomesoplenty:redwood_fence:0)
Block(-5,1,-1,biomesoplenty:redwood_fence:0)
Block(-5,1,2,biomesoplenty:redwood_fence:0)
Block(-5,1,3,biomesoplenty:redwood_fence:0)
Block(-5,1,4,biomesoplenty:redwood_fence:0)
Block(-4,0,-4,SANDSTONE:0)
Block(-4,0,-3,SANDSTONE:0)
Block(-4,0,-2,SANDSTONE:0)
Block(-4,0,-1,SANDSTONE:0)
Block(-4,0,0,SANDSTONE:0)
Block(-4,0,1,SANDSTONE:0)
Block(-4,0,2,SANDSTONE:0)
Block(-4,0,3,SANDSTONE:0)
Block(-4,0,4,SANDSTONE:0)
Block(-4,1,-4,quark:sandy_bricks_wall:0)
Block(-4,1,-3,biomesoplenty:redwood_fence:0)
Block(-4,1,-2,STEP:1)
Block(-4,1,-1,STEP:1)
Block(-4,1,0,STEP:1)
Block(-4,1,1,STEP:1)
Block(-4,1,2,STEP:1)
Block(-4,1,3,STEP:1)
Block(-4,1,4,quark:sandy_bricks_wall:0)
Block(-4,2,-4,quark:sandy_bricks_wall:0)
Block(-4,2,4,quark:sandy_bricks_wall:0)
Block(-4,3,-4,STEP:1)
Block(-4,3,-3,STEP:1)
Block(-4,3,-2,STEP:1)
Block(-4,3,-1,STEP:1)
Block(-4,3,1,STEP:1)
Block(-4,3,2,STEP:1)
Block(-4,3,4,quark:sandy_bricks_wall:0)
Block(-4,4,-2,STEP:1)
Block(-4,4,-1,STEP:1)
Block(-4,4,0,STEP:1)
Block(-4,4,1,STEP:1)
Block(-4,4,2,STEP:1)
Block(-4,4,3,STEP:1)
Block(-4,4,4,STEP:1)
Block(-3,0,-5,SANDSTONE:0)
Block(-3,0,-4,SANDSTONE:0)
Block(-3,0,-3,SANDSTONE:0)
Block(-3,0,-2,SANDSTONE:0)
Block(-3,0,-1,SANDSTONE:0)
Block(-3,0,0,SANDSTONE:0)
Block(-3,0,1,SANDSTONE:0)
Block(-3,0,2,SANDSTONE:0)
Block(-3,0,3,SANDSTONE:0)
Block(-3,0,4,SANDSTONE:0)
Block(-3,0,5,SANDSTONE:0)
Block(-3,0,6,SANDSTONE:0)
Block(-3,1,-5,quark:sandy_bricks_wall:0)
Block(-3,1,-4,SANDSTONE:1)
Block(-3,1,-3,SANDSTONE:0)
Block(-3,1,-2,SANDSTONE:0)
Block(-3,1,-1,SANDSTONE:0)
Block(-3,1,0,SANDSTONE:0)
Block(-3,1,1,SANDSTONE:0)
Block(-3,1,2,SANDSTONE:0)
Block(-3,1,3,SANDSTONE:0)
Block(-3,1,4,SANDSTONE:2)
Block(-3,1,5,quark:sandy_bricks_wall:0)
Block(-3,1,6,biomesoplenty:redwood_fence:0)
Block(-3,2,-5,quark:sandy_bricks_wall:0)
Block(-3,2,-4,SANDSTONE:1)
Block(-3,2,-3,SANDSTONE:0)
Block(-3,2,-2,inspirations:glass_trapdoor:15)
Block(-3,2,-1,inspirations:glass_trapdoor:15)
Block(-3,2,0,SANDSTONE:0)
Block(-3,2,1,inspirations:glass_trapdoor:15)
Block(-3,2,2,inspirations:glass_trapdoor:15)
Block(-3,2,3,SANDSTONE:0)
Block(-3,2,4,SANDSTONE:2)
Block(-3,2,5,quark:sandy_bricks_wall:0)
Block(-3,3,-5,STEP:1)
Block(-3,3,-4,SANDSTONE:0)
Block(-3,3,-3,DOUBLE_STEP:1)
Block(-3,3,-2,SANDSTONE:0)
Block(-3,3,-1,SANDSTONE:0)
Block(-3,3,0,SANDSTONE:0)
Block(-3,3,1,SANDSTONE:0)
Block(-3,3,2,SANDSTONE:0)
Block(-3,3,3,SANDSTONE:0)
Block(-3,3,4,SANDSTONE:2)
Block(-3,3,5,quark:sandy_bricks_wall:0)
Block(-3,4,-3,STEP:1)
Block(-3,4,-2,DOUBLE_STEP:1)
Block(-3,4,-1,SANDSTONE:0)
Block(-3,4,0,SANDSTONE:0)
Block(-3,4,1,SANDSTONE:0)
Block(-3,4,2,SANDSTONE:0)
Block(-3,4,3,SANDSTONE:0)
Block(-3,4,4,DOUBLE_STEP:1)
Block(-3,4,5,STEP:1)
Block(-2,0,-5,SANDSTONE:0)
Block(-2,0,-4,SANDSTONE:0)
Block(-2,0,-3,SANDSTONE:0)
Block(-2,0,-2,SANDSTONE:0)
Block(-2,0,-1,SANDSTONE:0)
Block(-2,0,0,SANDSTONE:0)
Block(-2,0,1,SANDSTONE:0)
Block(-2,0,2,SANDSTONE:0)
Block(-2,0,3,SANDSTONE:0)
Block(-2,0,4,SANDSTONE:0)
Block(-2,0,5,SANDSTONE:0)
Block(-2,0,6,SANDSTONE:0)
Block(-2,1,-4,WOODEN_DOOR:3)
Block(-2,1,4,SANDSTONE:0)
Block(-2,1,5,STEP:1)
Block(-2,1,6,biomesoplenty:redwood_fence:0)
Block(-2,2,-4,WOODEN_DOOR:9)
Block(-2,2,4,inspirations:glass_trapdoor:12)
Block(-2,3,-5,STEP:1)
Block(-2,3,-4,SANDSTONE:0)
Block(-2,3,-3,SANDSTONE:0)
Block(-2,3,-2,SANDSTONE:0)
Block(-2,3,4,SANDSTONE:0)
Block(-2,3,5,STEP:1)
Block(-2,4,-3,STEP:1)
Block(-2,4,-2,SANDSTONE:0)
Block(-2,4,-1,quark:sandy_bricks_wall:0)
Block(-2,4,3,quark:sandy_bricks_wall:0)
Block(-2,4,4,SANDSTONE:0)
Block(-2,4,5,STEP:1)
Block(-2,5,-1,STEP:1)
Block(-2,5,0,inspirations:glass_trapdoor:3)
Block(-2,5,1,inspirations:glass_trapdoor:3)
Block(-2,5,2,inspirations:glass_trapdoor:3)
Block(-2,5,3,STEP:1)
Block(-1,0,-5,SANDSTONE:0)
Block(-1,0,-4,SANDSTONE:0)
Block(-1,0,-3,SANDSTONE:0)
Block(-1,0,-2,SANDSTONE:0)
Block(-1,0,-1,SANDSTONE:0)
Block(-1,0,0,WOOL:7)
Block(-1,0,1,WOOL:7)
Block(-1,0,2,WOOL:7)
Block(-1,0,3,SANDSTONE:0)
Block(-1,0,4,SANDSTONE:0)
Block(-1,0,5,SANDSTONE:0)
Block(-1,0,6,SANDSTONE:0)
Block(-1,1,-5,quark:sandy_bricks_wall:0)
Block(-1,1,-4,SANDSTONE:1)
Block(-1,1,-3,SANDSTONE:0)
Block(-1,1,4,SANDSTONE:0)
Block(-1,1,5,STEP:1)
Block(-1,2,-5,quark:sandy_bricks_wall:0)
Block(-1,2,-4,SANDSTONE:1)
Block(-1,2,-3,SANDSTONE:0)
Block(-1,2,4,inspirations:glass_trapdoor:12)
Block(-1,3,-5,STEP:1)
Block(-1,3,-4,SANDSTONE:0)
Block(-1,3,-3,SANDSTONE:0)
Block(-1,3,-2,SANDSTONE:0)
Block(-1,3,4,SANDSTONE:0)
Block(-1,3,5,STEP:1)
Block(-1,4,-3,STEP:1)
Block(-1,4,-2,DOUBLE_STEP:1)
Block(-1,4,-1,quark:sandy_bricks_wall:0)
Block(-1,4,3,quark:sandy_bricks_wall:0)
Block(-1,4,4,SANDSTONE:0)
Block(-1,4,5,STEP:1)
Block(-1,5,-1,STEP:1)
Block(-1,5,0,inspirations:glass_trapdoor:2)
Block(-1,5,1,inspirations:glass_trapdoor:2)
Block(-1,5,2,inspirations:glass_trapdoor:0)
Block(-1,5,3,STEP:1)
Block(0,0,-4,SANDSTONE:0)
Block(0,0,-3,SANDSTONE:0)
Block(0,0,-2,SANDSTONE:0)
Block(0,0,-1,SANDSTONE:0)
Block(0,0,0,WOOL:7)
Block(0,0,1,SANDSTONE:0)
Block(0,0,2,WOOL:7)
Block(0,0,3,SANDSTONE:0)
Block(0,0,4,SANDSTONE:0)
Block(0,0,5,SANDSTONE:0)
Block(0,0,6,SANDSTONE:0)
Block(0,1,-4,biomesoplenty:redwood_fence:0)
Block(0,1,-3,STEP:1)
Block(0,1,-2,SANDSTONE:0)
Block(0,1,3,quark:sandy_bricks_wall:0)
Block(0,1,4,SANDSTONE:0)
Block(0,1,5,STEP:1)
Block(0,2,-2,SANDSTONE:0)
Block(0,2,3,realistictorches:torch_smoldering:5)
Block(0,2,4,SANDSTONE:0)
Block(0,3,-4,STEP:1)
Block(0,3,-3,SANDSTONE:0)
Block(0,3,-2,SANDSTONE:0)
Block(0,3,4,SANDSTONE:0)
Block(0,4,-3,STEP:1)
Block(0,4,-2,DOUBLE_STEP:1)
Block(0,4,-1,quark:sandy_bricks_wall:0)
Block(0,4,0,quark:sandy_bricks_wall:0)
Block(0,4,1,quark:sandy_bricks_wall:0)
Block(0,4,2,quark:sandy_bricks_wall:0)
Block(0,4,3,quark:sandy_bricks_wall:0)
Block(0,4,4,SANDSTONE:0)
Block(0,4,5,STEP:1)
Block(0,5,-1,STEP:1)
Block(0,5,0,STEP:1)
Block(0,5,1,STEP:1)
Block(0,5,2,STEP:1)
Block(0,5,3,STEP:1)
Block(1,0,-4,SANDSTONE:0)
Block(1,0,-3,SANDSTONE:0)
Block(1,0,-2,SANDSTONE:0)
Block(1,0,-1,SANDSTONE:0)
Block(1,0,0,WOOL:7)
Block(1,0,1,WOOL:7)
Block(1,0,2,WOOL:7)
Block(1,0,3,SANDSTONE:0)
Block(1,0,4,SANDSTONE:0)
Block(1,0,5,SANDSTONE:0)
Block(1,0,6,SANDSTONE:0)
Block(1,1,-3,STEP:1)
Block(1,1,-2,SANDSTONE:0)
Block(1,1,4,SANDSTONE:0)
Block(1,1,5,STEP:1)
Block(1,1,6,biomesoplenty:redwood_fence:0)
Block(1,2,-2,inspirations:glass_trapdoor:13)
Block(1,2,4,inspirations:glass_trapdoor:12)
Block(1,3,-3,DOUBLE_STEP:1)
Block(1,3,-2,SANDSTONE:0)
Block(1,3,4,SANDSTONE:0)
Block(1,3,5,STEP:1)
Block(1,4,-3,STEP:1)
Block(1,4,-2,DOUBLE_STEP:1)
Block(1,4,-1,quark:sandy_bricks_wall:0)
Block(1,4,3,quark:sandy_bricks_wall:0)
Block(1,4,4,SANDSTONE:0)
Block(1,4,5,STEP:1)
Block(1,5,-1,STEP:1)
Block(1,5,0,inspirations:glass_trapdoor:3)
Block(1,5,1,inspirations:glass_trapdoor:3)
Block(1,5,2,inspirations:glass_trapdoor:3)
Block(1,5,3,STEP:1)
Block(2,0,-4,SANDSTONE:0)
Block(2,0,-3,SANDSTONE:0)
Block(2,0,-2,SANDSTONE:0)
Block(2,0,-1,SANDSTONE:0)
Block(2,0,0,SANDSTONE:0)
Block(2,0,1,SANDSTONE:0)
Block(2,0,2,SANDSTONE:0)
Block(2,0,3,SANDSTONE:0)
Block(2,0,4,SANDSTONE:0)
Block(2,0,5,SANDSTONE:0)
Block(2,0,6,SANDSTONE:0)
Block(2,1,-4,biomesoplenty:redwood_fence:0)
Block(2,1,-3,STEP:1)
Block(2,1,-2,SANDSTONE:0)
Block(2,1,4,SANDSTONE:0)
Block(2,1,5,STEP:1)
Block(2,1,6,biomesoplenty:redwood_fence:0)
Block(2,2,-2,inspirations:glass_trapdoor:13)
Block(2,2,4,inspirations:glass_trapdoor:12)
Block(2,3,-3,DOUBLE_STEP:1)
Block(2,3,-2,SANDSTONE:0)
Block(2,3,4,SANDSTONE:0)
Block(2,3,5,STEP:1)
Block(2,4,-3,STEP:1)
Block(2,4,-2,DOUBLE_STEP:1)
Block(2,4,-1,quark:sandy_bricks_wall:0)
Block(2,4,3,quark:sandy_bricks_wall:0)
Block(2,4,4,SANDSTONE:0)
Block(2,4,5,STEP:1)
Block(2,5,-1,STEP:1)
Block(2,5,0,inspirations:glass_trapdoor:2)
Block(2,5,1,inspirations:glass_trapdoor:2)
Block(2,5,2,inspirations:glass_trapdoor:2)
Block(2,5,3,STEP:1)
Block(3,0,-4,SANDSTONE:0)
Block(3,0,-3,SANDSTONE:0)
Block(3,0,-2,SANDSTONE:0)
Block(3,0,-1,SANDSTONE:0)
Block(3,0,0,SANDSTONE:0)
Block(3,0,1,SANDSTONE:0)
Block(3,0,2,SANDSTONE:0)
Block(3,0,3,SANDSTONE:0)
Block(3,0,4,SANDSTONE:0)
Block(3,0,5,SANDSTONE:0)
Block(3,0,6,SANDSTONE:0)
Block(3,1,-4,biomesoplenty:redwood_fence:0)
Block(3,1,-3,STEP:1)
Block(3,1,-2,SANDSTONE:0)
Block(3,1,0,SANDSTONE:0)
Block(3,1,1,SANDSTONE:0)
Block(3,1,2,SANDSTONE:0)
Block(3,1,3,SANDSTONE:0)
Block(3,1,4,SANDSTONE:2)
Block(3,1,5,quark:sandy_bricks_wall:0)
Block(3,1,6,biomesoplenty:redwood_fence:0)
Block(3,2,-2,inspirations:glass_trapdoor:13)
Block(3,2,0,SANDSTONE:0)
Block(3,2,1,inspirations:glass_trapdoor:14)
Block(3,2,2,inspirations:glass_trapdoor:14)
Block(3,2,3,inspirations:glass_trapdoor:14)
Block(3,2,4,SANDSTONE:2)
Block(3,2,5,quark:sandy_bricks_wall:0)
Block(3,3,-3,DOUBLE_STEP:1)
Block(3,3,-2,SANDSTONE:0)
Block(3,3,0,SANDSTONE:0)
Block(3,3,1,SANDSTONE:0)
Block(3,3,2,SANDSTONE:0)
Block(3,3,3,SANDSTONE:0)
Block(3,3,4,SANDSTONE:2)
Block(3,3,5,quark:sandy_bricks_wall:0)
Block(3,4,-3,STEP:1)
Block(3,4,-2,DOUBLE_STEP:1)
Block(3,4,-1,SANDSTONE:0)
Block(3,4,0,SANDSTONE:0)
Block(3,4,1,SANDSTONE:0)
Block(3,4,2,SANDSTONE:0)
Block(3,4,3,SANDSTONE:0)
Block(3,4,4,SANDSTONE:0)
Block(3,4,5,STEP:1)
Block(4,0,-4,SANDSTONE:0)
Block(4,0,-3,SANDSTONE:0)
Block(4,0,-2,SANDSTONE:0)
Block(4,0,-1,SANDSTONE:0)
Block(4,0,0,SANDSTONE:0)
Block(4,0,1,SANDSTONE:0)
Block(4,0,2,SANDSTONE:0)
Block(4,0,3,SANDSTONE:0)
Block(4,0,4,SANDSTONE:0)
Block(4,1,-4,biomesoplenty:redwood_fence:0)
Block(4,1,-3,STEP:1)
Block(4,1,-2,SANDSTONE:0)
Block(4,1,0,SANDSTONE:0)
Block(4,1,1,STEP:1)
Block(4,1,2,STEP:1)
Block(4,1,3,STEP:1)
Block(4,1,4,quark:sandy_bricks_wall:0)
Block(4,2,-2,SANDSTONE:0)
Block(4,2,0,SANDSTONE:0)
Block(4,2,4,quark:sandy_bricks_wall:0)
Block(4,3,-3,DOUBLE_STEP:1)
Block(4,3,-2,SANDSTONE:0)
Block(4,3,-1,SANDSTONE:0)
Block(4,3,0,SANDSTONE:0)
Block(4,3,1,STEP:1)
Block(4,3,2,STEP:1)
Block(4,3,3,STEP:1)
Block(4,3,4,quark:sandy_bricks_wall:0)
Block(4,4,-2,STEP:1)
Block(4,4,-1,STEP:1)
Block(4,4,0,STEP:1)
Block(4,4,1,STEP:1)
Block(4,4,2,STEP:1)
Block(4,4,3,STEP:1)
Block(4,4,4,STEP:1)
Block(5,0,-4,SANDSTONE:0)
Block(5,0,-3,SANDSTONE:0)
Block(5,0,-2,SANDSTONE:0)
Block(5,0,-1,SANDSTONE:0)
Block(5,0,0,SANDSTONE:0)
Block(5,1,-3,quark:sandy_bricks_wall:0)
Block(5,1,-2,SANDSTONE:1)
Block(5,1,-1,WOODEN_DOOR:0)
Block(5,1,0,SANDSTONE:1)
Block(5,2,-3,quark:sandy_bricks_wall:0)
Block(5,2,-2,SANDSTONE:1)
Block(5,2,-1,WOODEN_DOOR:9)
Block(5,2,0,SANDSTONE:1)
Block(5,3,-3,STEP:1)
Block(5,3,-2,SANDSTONE:0)
Block(5,3,-1,SANDSTONE:0)
Block(5,3,0,SANDSTONE:0)
Block(5,3,1,STEP:1)
Block(6,0,-4,SANDSTONE:0)
Block(6,0,-3,SANDSTONE:0)
Block(6,0,-2,SANDSTONE:0)
Block(6,0,-1,SANDSTONE:0)
Block(6,0,0,SANDSTONE:0)
Block(6,1,-4,biomesoplenty:redwood_fence:0)
Block(6,1,-3,biomesoplenty:redwood_fence:0)
Block(6,1,-2,quark:sandy_bricks_wall:0)
Block(6,1,0,quark:sandy_bricks_wall:0)
Block(6,2,-2,quark:sandy_bricks_wall:0)
Block(6,2,0,quark:sandy_bricks_wall:0)
Block(6,3,-2,STEP:1)
Block(6,3,-1,STEP:1)
Block(6,3,0,STEP:1)

#######################################################################
# +-----------------------------------------------------------------+ #
# |                             Branches                            | #
# +-----------------------------------------------------------------+ #
#######################################################################


#######################################################################
# +-----------------------------------------------------------------+ #
# |                             Entities                            | #
# +-----------------------------------------------------------------+ #
#######################################################################


#######################################################################
# +-----------------------------------------------------------------+ #
# |                            Particles                            | #
# +-----------------------------------------------------------------+ #
#######################################################################


#######################################################################
# +-----------------------------------------------------------------+ #
# |                             Spawners                            | #
# +-----------------------------------------------------------------+ #
#######################################################################


#######################################################################
# +-----------------------------------------------------------------+ #
# |                             ModData                             | #
# +-----------------------------------------------------------------+ #
#######################################################################

