
#######################################################################
# +-----------------------------------------------------------------+ #
# |                            BO4 object                           | #
# +-----------------------------------------------------------------+ #
#######################################################################

Author: NLBlackEagle

Description: No description given

SettingsMode: WriteWithoutComments


#######################################################################
# +-----------------------------------------------------------------+ #
# |                          Main settings                          | #
# +-----------------------------------------------------------------+ #
#######################################################################

FixedRotation: 

Frequency: 0

SpawnHeight: highestBlock

UseCenterForHighestBlock: true

##############################
# Height Limits for the BO4. #
##############################

MinHeight: 0

MaxHeight: 255

InheritBO3: 

InheritBO3Rotation: NORTH

OverrideChildSettings: true

OverrideParentHeight: false

CanOverride: false

BranchFrequency: 0

BranchFrequencyGroup: 

MustBeBelowOther: false

MustBeInside: 

CannotBeInside: 

ReplacesBO3: 

MustBeInsideWorldBorders: false

CanSpawnOnWater: true

SpawnOnWaterOnly: false

SpawnUnderWater: false

SpawnAtWaterLevel: false

HeightOffset: 0

RemoveAir: false

ReplaceAbove: 

ReplaceBelow: 

ReplaceWithBiomeBlocks: true

ReplaceWithSurfaceBlock: STONE, SAND, BIOMESOPLENTY:DRIED_SAND

ReplaceWithGroundBlock: STONE, SAND, BIOMESOPLENTY:DRIED_SAND

ReplaceWithStoneBlock: STONE, SAND, BIOMESOPLENTY:DRIED_SAND

SmoothRadius: 0

SmoothHeightOffset: 0

SmoothStartTop: false

SmoothStartWood: false

SmoothingSurfaceBlock: 

SmoothingGroundBlock: 

BO3Group: 

IsSpawnPoint: false

DoReplaceBlocks: false


#######################################################################
# +-----------------------------------------------------------------+ #
# |                              Blocks                             | #
# +-----------------------------------------------------------------+ #
#######################################################################

Block(-8,0,-7,SANDSTONE:0)
Block(-8,0,-6,SANDSTONE:0)
Block(-8,0,-5,SANDSTONE:0)
Block(-8,0,-4,SANDSTONE:0)
Block(-8,0,-3,SANDSTONE:0)
Block(-8,0,-2,SANDSTONE:0)
Block(-8,0,-1,SANDSTONE:0)
Block(-8,0,0,SANDSTONE:0)
Block(-8,0,1,SANDSTONE:0)
Block(-8,0,2,SANDSTONE:0)
Block(-8,0,3,SANDSTONE:0)
Block(-8,0,4,SANDSTONE:0)
Block(-8,0,5,SANDSTONE:0)
Block(-8,0,6,SANDSTONE:0)
Block(-8,0,7,SANDSTONE:0)
Block(-8,0,8,SANDSTONE:0)
Block(-8,1,-7,SANDSTONE:0)
Block(-8,1,-6,SANDSTONE:0)
Block(-8,1,-5,SANDSTONE:0)
Block(-8,1,-4,SANDSTONE:0)
Block(-8,1,-3,SANDSTONE:0)
Block(-8,1,-2,SANDSTONE:0)
Block(-8,1,-1,SANDSTONE:0)
Block(-8,1,0,SANDSTONE:0)
Block(-8,1,1,SANDSTONE:0)
Block(-8,1,2,SANDSTONE:0)
Block(-8,1,3,SANDSTONE:0)
Block(-8,1,4,SANDSTONE:0)
Block(-8,1,5,SANDSTONE:0)
Block(-8,1,6,SANDSTONE:0)
Block(-8,1,7,SANDSTONE:0)
Block(-8,1,8,SANDSTONE:0)
Block(-8,2,-7,SANDSTONE:0)
Block(-8,2,-6,SANDSTONE:0)
Block(-8,2,-5,SANDSTONE:0)
Block(-8,2,-4,SANDSTONE:0)
Block(-8,2,-3,SANDSTONE:0)
Block(-8,2,-2,SANDSTONE:0)
Block(-8,2,-1,SANDSTONE:0)
Block(-8,2,0,SANDSTONE:0)
Block(-8,2,1,SANDSTONE:0)
Block(-8,2,2,SANDSTONE:0)
Block(-8,2,3,SANDSTONE:0)
Block(-8,2,4,SANDSTONE:0)
Block(-8,2,5,SANDSTONE:0)
Block(-8,2,6,SANDSTONE:0)
Block(-8,2,7,SANDSTONE:0)
Block(-8,2,8,SANDSTONE:0)
Block(-8,3,-7,SANDSTONE:0)
Block(-8,3,-6,SANDSTONE:0)
Block(-8,3,-5,SANDSTONE:0)
Block(-8,3,-4,SANDSTONE:0)
Block(-8,3,-3,SANDSTONE:0)
Block(-8,3,-2,SANDSTONE:0)
Block(-8,3,-1,SANDSTONE:0)
Block(-8,3,0,SANDSTONE:0)
Block(-8,3,1,SANDSTONE:0)
Block(-8,3,2,SANDSTONE:0)
Block(-8,3,3,SANDSTONE:0)
Block(-8,3,4,SANDSTONE:0)
Block(-8,3,5,SANDSTONE:0)
Block(-8,3,6,SANDSTONE:0)
Block(-8,3,7,SANDSTONE:0)
Block(-8,3,8,SANDSTONE:0)
Block(-8,4,-7,SANDSTONE:0)
Block(-8,4,-6,SANDSTONE:0)
Block(-8,4,-5,SANDSTONE:0)
Block(-8,4,-4,SANDSTONE:0)
Block(-8,4,-3,SANDSTONE:0)
Block(-8,4,-2,SANDSTONE:0)
Block(-8,4,-1,SANDSTONE:0)
Block(-8,4,0,SANDSTONE:0)
Block(-8,4,1,SANDSTONE:0)
Block(-8,4,2,SANDSTONE:0)
Block(-8,4,3,SANDSTONE:0)
Block(-8,4,4,SANDSTONE:0)
Block(-8,4,5,SANDSTONE:0)
Block(-8,4,6,SANDSTONE:0)
Block(-8,4,7,SANDSTONE:0)
Block(-8,4,8,SANDSTONE:0)
Block(-8,5,-7,SANDSTONE:0)
Block(-8,5,-6,SANDSTONE:0)
Block(-8,5,-5,SANDSTONE:0)
Block(-8,5,-4,SANDSTONE:0)
Block(-8,5,-3,SANDSTONE:0)
Block(-8,5,-2,SANDSTONE:0)
Block(-8,5,-1,SANDSTONE:0)
Block(-8,5,0,SANDSTONE:0)
Block(-8,5,1,SANDSTONE:0)
Block(-8,5,2,SANDSTONE:0)
Block(-8,5,3,SANDSTONE:0)
Block(-8,5,4,SANDSTONE:0)
Block(-8,5,5,SANDSTONE:0)
Block(-8,5,6,SANDSTONE:0)
Block(-8,5,7,SANDSTONE:0)
Block(-8,5,8,SANDSTONE:0)
Block(-8,6,-7,SANDSTONE:0)
Block(-8,6,-6,SANDSTONE:0)
Block(-8,6,-5,SANDSTONE:0)
Block(-8,6,-4,SANDSTONE:0)
Block(-8,6,-3,SANDSTONE:0)
Block(-8,6,-2,SANDSTONE:0)
Block(-8,6,-1,SANDSTONE:0)
Block(-8,6,0,SANDSTONE:0)
Block(-8,6,1,SANDSTONE:0)
Block(-8,6,2,SANDSTONE:0)
Block(-8,6,3,SANDSTONE:0)
Block(-8,6,4,SANDSTONE:0)
Block(-8,6,5,SANDSTONE:0)
Block(-8,6,6,SANDSTONE:0)
Block(-8,6,7,SANDSTONE:0)
Block(-8,6,8,SANDSTONE:0)
Block(-8,7,-7,SANDSTONE:0)
Block(-8,7,-6,SANDSTONE:0)
Block(-8,7,-5,SANDSTONE:0)
Block(-8,7,-4,SANDSTONE:0)
Block(-8,7,-3,SANDSTONE:0)
Block(-8,7,-2,SANDSTONE:0)
Block(-8,7,-1,SANDSTONE:0)
Block(-8,7,0,SANDSTONE:0)
Block(-8,7,1,SANDSTONE:0)
Block(-8,7,2,SANDSTONE:0)
Block(-8,7,3,SANDSTONE:0)
Block(-8,7,4,SANDSTONE:0)
Block(-8,7,5,SANDSTONE:0)
Block(-8,7,6,SANDSTONE:0)
Block(-8,7,7,SANDSTONE:0)
Block(-8,7,8,SANDSTONE:0)
Block(-8,8,-7,SANDSTONE:0)
Block(-8,8,-6,SANDSTONE:0)
Block(-8,8,-5,SANDSTONE:0)
Block(-8,8,-4,SANDSTONE:0)
Block(-8,8,-3,SANDSTONE:0)
Block(-8,8,-2,SANDSTONE:0)
Block(-8,8,-1,SANDSTONE:0)
Block(-8,8,0,SANDSTONE:0)
Block(-8,8,1,SANDSTONE:0)
Block(-8,8,2,SANDSTONE:0)
Block(-8,8,3,SANDSTONE:0)
Block(-8,8,4,SANDSTONE:0)
Block(-8,8,5,SANDSTONE:0)
Block(-8,8,6,SANDSTONE:0)
Block(-8,8,7,SANDSTONE:0)
Block(-8,8,8,SANDSTONE:0)
Block(-8,9,-7,SANDSTONE:0)
Block(-8,9,-6,SANDSTONE:0)
Block(-8,9,-5,SANDSTONE:0)
Block(-8,9,-4,SANDSTONE:0)
Block(-8,9,-3,SANDSTONE:0)
Block(-8,9,-2,SANDSTONE:0)
Block(-8,9,-1,SANDSTONE:0)
Block(-8,9,0,SANDSTONE:0)
Block(-8,9,1,SANDSTONE:0)
Block(-8,9,2,SANDSTONE:0)
Block(-8,9,3,SANDSTONE:0)
Block(-8,9,4,SANDSTONE:0)
Block(-8,9,5,SANDSTONE:0)
Block(-8,9,6,SANDSTONE:0)
Block(-8,9,7,SANDSTONE:0)
Block(-8,9,8,SANDSTONE:0)
Block(-8,10,-7,SANDSTONE:0)
Block(-8,10,-6,SANDSTONE:0)
Block(-8,10,-5,SANDSTONE:0)
Block(-8,10,-4,SANDSTONE:0)
Block(-8,10,-3,SANDSTONE:0)
Block(-8,10,-2,SANDSTONE:0)
Block(-8,10,-1,SANDSTONE:0)
Block(-8,10,0,SANDSTONE:0)
Block(-8,10,1,SANDSTONE:0)
Block(-8,10,2,SANDSTONE:0)
Block(-8,10,3,SANDSTONE:0)
Block(-8,10,4,SANDSTONE:0)
Block(-8,10,5,SANDSTONE:0)
Block(-8,10,6,SANDSTONE:0)
Block(-8,10,7,SANDSTONE:0)
Block(-8,10,8,SANDSTONE:0)
Block(-8,11,-7,SANDSTONE:0)
Block(-8,11,-6,SANDSTONE:0)
Block(-8,11,-5,SANDSTONE:0)
Block(-8,11,-4,SANDSTONE:0)
Block(-8,11,-3,SANDSTONE:0)
Block(-8,11,-2,SANDSTONE:0)
Block(-8,11,-1,SANDSTONE:0)
Block(-8,11,0,SANDSTONE:0)
Block(-8,11,1,SANDSTONE:0)
Block(-8,11,2,SANDSTONE:0)
Block(-8,11,3,SANDSTONE:0)
Block(-8,11,4,SANDSTONE:0)
Block(-8,11,5,SANDSTONE:0)
Block(-8,11,6,SANDSTONE:0)
Block(-8,11,7,SANDSTONE:0)
Block(-8,11,8,SANDSTONE:0)
Block(-8,12,-7,SANDSTONE:0)
Block(-8,12,-6,SANDSTONE:0)
Block(-8,12,-5,SANDSTONE:0)
Block(-8,12,-4,SANDSTONE:0)
Block(-8,12,-3,SANDSTONE:0)
Block(-8,12,-2,SANDSTONE:0)
Block(-8,12,-1,SANDSTONE:0)
Block(-8,12,0,SANDSTONE:0)
Block(-8,12,1,SANDSTONE:0)
Block(-8,12,2,SANDSTONE:0)
Block(-8,12,3,SANDSTONE:0)
Block(-8,12,4,SANDSTONE:0)
Block(-8,12,5,SANDSTONE:0)
Block(-8,12,6,SANDSTONE:0)
Block(-8,12,7,SANDSTONE:0)
Block(-8,12,8,SANDSTONE:0)
Block(-8,13,-7,SANDSTONE:0)
Block(-8,13,-6,SANDSTONE:0)
Block(-8,13,-5,SANDSTONE:0)
Block(-8,13,-4,SANDSTONE:0)
Block(-8,13,-3,SANDSTONE:0)
Block(-8,13,-2,SANDSTONE:0)
Block(-8,13,-1,SANDSTONE:0)
Block(-8,13,0,SANDSTONE:0)
Block(-8,13,1,SANDSTONE:0)
Block(-8,13,2,SANDSTONE:0)
Block(-8,13,3,SANDSTONE:0)
Block(-8,13,4,SANDSTONE:0)
Block(-8,13,5,SANDSTONE:0)
Block(-8,13,6,SANDSTONE:0)
Block(-8,13,7,SANDSTONE:0)
Block(-8,13,8,SANDSTONE:0)
Block(-8,14,-7,SANDSTONE:0)
Block(-8,14,-6,SANDSTONE:0)
Block(-8,14,-5,SANDSTONE:0)
Block(-8,14,-4,SANDSTONE:0)
Block(-8,14,-3,SANDSTONE:0)
Block(-8,14,-2,SANDSTONE:0)
Block(-8,14,-1,SANDSTONE:0)
Block(-8,14,0,SANDSTONE:0)
Block(-8,14,1,SANDSTONE:0)
Block(-8,14,2,SANDSTONE:0)
Block(-8,14,3,SANDSTONE:0)
Block(-8,14,4,SANDSTONE:0)
Block(-8,14,5,SANDSTONE:0)
Block(-8,14,6,SANDSTONE:0)
Block(-8,14,7,SANDSTONE:0)
Block(-8,14,8,SANDSTONE:0)
Block(-8,15,-7,SANDSTONE:0)
Block(-8,15,-6,SANDSTONE:0)
Block(-8,15,-5,SANDSTONE:0)
Block(-8,15,-4,SANDSTONE:0)
Block(-8,15,-3,SANDSTONE:0)
Block(-8,15,-2,SANDSTONE:0)
Block(-8,15,-1,SANDSTONE:0)
Block(-8,15,0,SANDSTONE:0)
Block(-8,15,1,SANDSTONE:0)
Block(-8,15,2,SANDSTONE:0)
Block(-8,15,3,SANDSTONE:0)
Block(-8,15,4,SANDSTONE:0)
Block(-8,15,5,SANDSTONE:0)
Block(-8,15,6,SANDSTONE:0)
Block(-8,15,7,SANDSTONE:0)
Block(-8,15,8,SANDSTONE:0)
Block(-8,16,-7,SANDSTONE:0)
Block(-8,16,-6,SANDSTONE:0)
Block(-8,16,-5,SANDSTONE:0)
Block(-8,16,-4,SANDSTONE:0)
Block(-8,16,-3,SANDSTONE:0)
Block(-8,16,-2,SANDSTONE:0)
Block(-8,16,-1,SANDSTONE:0)
Block(-8,16,0,SANDSTONE:0)
Block(-8,16,1,SANDSTONE:0)
Block(-8,16,2,SANDSTONE:0)
Block(-8,16,3,SANDSTONE:0)
Block(-8,16,4,SANDSTONE:0)
Block(-8,16,5,SANDSTONE:0)
Block(-8,16,6,SANDSTONE:0)
Block(-8,16,7,SANDSTONE:0)
Block(-8,16,8,SANDSTONE:0)
Block(-8,17,-7,SANDSTONE:0)
Block(-8,17,-6,SANDSTONE:0)
Block(-8,17,-5,SANDSTONE:0)
Block(-8,17,-4,SANDSTONE:0)
Block(-8,17,-3,SANDSTONE:0)
Block(-8,17,-2,SANDSTONE:0)
Block(-8,17,-1,SANDSTONE:0)
Block(-8,17,0,SANDSTONE:0)
Block(-8,17,1,SANDSTONE:0)
Block(-8,17,2,SANDSTONE:0)
Block(-8,17,3,SANDSTONE:0)
Block(-8,17,4,SANDSTONE:0)
Block(-8,17,5,SANDSTONE:0)
Block(-8,17,6,SANDSTONE:0)
Block(-8,17,7,SANDSTONE:0)
Block(-8,17,8,SANDSTONE:0)
Block(-8,18,-7,SANDSTONE:0)
Block(-8,18,-6,SANDSTONE:0)
Block(-8,18,-5,SANDSTONE:0)
Block(-8,18,-4,SANDSTONE:0)
Block(-8,18,-3,SANDSTONE:0)
Block(-8,18,-2,SANDSTONE:0)
Block(-8,18,-1,SANDSTONE:0)
Block(-8,18,0,SANDSTONE:0)
Block(-8,18,1,SANDSTONE:0)
Block(-8,18,2,SANDSTONE:0)
Block(-8,18,3,SANDSTONE:0)
Block(-8,18,4,SANDSTONE:0)
Block(-8,18,5,SANDSTONE:0)
Block(-8,18,6,SANDSTONE:0)
Block(-8,18,7,SANDSTONE:0)
Block(-8,18,8,SANDSTONE:0)
Block(-8,19,-7,SANDSTONE:0)
Block(-8,19,-6,SANDSTONE:0)
Block(-8,19,-5,SANDSTONE:0)
Block(-8,19,-4,SANDSTONE:0)
Block(-8,19,-3,SANDSTONE:0)
Block(-8,19,-2,SANDSTONE:0)
Block(-8,19,-1,SANDSTONE:0)
Block(-8,19,0,SANDSTONE:0)
Block(-8,19,1,SANDSTONE:0)
Block(-8,19,2,SANDSTONE:0)
Block(-8,19,3,SANDSTONE:0)
Block(-8,19,4,SANDSTONE:0)
Block(-8,19,5,SANDSTONE:0)
Block(-8,19,6,SANDSTONE:0)
Block(-8,19,7,SANDSTONE:0)
Block(-8,19,8,SANDSTONE:0)
Block(-8,20,-7,SANDSTONE:0)
Block(-8,20,-6,SANDSTONE:0)
Block(-8,20,-5,SANDSTONE:0)
Block(-8,20,-4,SANDSTONE:0)
Block(-8,20,-3,SANDSTONE:0)
Block(-8,20,-2,SANDSTONE:0)
Block(-8,20,-1,SANDSTONE:0)
Block(-8,20,0,SANDSTONE:0)
Block(-8,20,1,SANDSTONE:0)
Block(-8,20,2,SANDSTONE:0)
Block(-8,20,3,SANDSTONE:0)
Block(-8,20,4,SANDSTONE:0)
Block(-8,20,5,SANDSTONE:0)
Block(-8,20,6,SANDSTONE:0)
Block(-8,20,7,SANDSTONE:0)
Block(-8,20,8,SANDSTONE:0)
Block(-8,21,-7,SANDSTONE:0)
Block(-8,21,-6,SANDSTONE:0)
Block(-8,21,-5,SANDSTONE:0)
Block(-8,21,-4,SANDSTONE:0)
Block(-8,21,-3,SANDSTONE:0)
Block(-8,21,-2,SANDSTONE:0)
Block(-8,21,-1,SANDSTONE:0)
Block(-8,21,0,SANDSTONE:0)
Block(-8,21,1,SANDSTONE:0)
Block(-8,21,2,SANDSTONE:0)
Block(-8,21,3,SANDSTONE:0)
Block(-8,21,4,SANDSTONE:0)
Block(-8,21,5,SANDSTONE:0)
Block(-8,21,6,SANDSTONE:0)
Block(-8,21,7,SANDSTONE:0)
Block(-8,21,8,SANDSTONE:0)
Block(-8,22,-7,SANDSTONE:0)
Block(-8,22,-6,SANDSTONE:0)
Block(-8,22,-5,SANDSTONE:0)
Block(-8,22,-4,SANDSTONE:0)
Block(-8,22,-3,SANDSTONE:0)
Block(-8,22,-2,SANDSTONE:0)
Block(-8,22,-1,SANDSTONE:0)
Block(-8,22,0,SANDSTONE:0)
Block(-8,22,1,SANDSTONE:0)
Block(-8,22,2,SANDSTONE:0)
Block(-8,22,3,SANDSTONE:0)
Block(-8,22,4,SANDSTONE:0)
Block(-8,22,5,SANDSTONE:0)
Block(-8,22,6,SANDSTONE:0)
Block(-8,22,7,SANDSTONE:0)
Block(-8,22,8,SANDSTONE:0)
Block(-8,23,-7,SANDSTONE:0)
Block(-8,23,-6,SANDSTONE:0)
Block(-8,23,-5,SANDSTONE:0)
Block(-8,23,-4,SANDSTONE:0)
Block(-8,23,-3,SANDSTONE:0)
Block(-8,23,-2,SANDSTONE:0)
Block(-8,23,-1,SANDSTONE:0)
Block(-8,23,0,SANDSTONE:0)
Block(-8,23,1,SANDSTONE:0)
Block(-8,23,2,SANDSTONE:0)
Block(-8,23,3,SANDSTONE:0)
Block(-8,23,4,SANDSTONE:0)
Block(-8,23,5,SANDSTONE:0)
Block(-8,23,6,SANDSTONE:0)
Block(-8,23,7,SANDSTONE:0)
Block(-8,23,8,SANDSTONE:0)
Block(-8,24,-7,SANDSTONE:0)
Block(-8,24,-6,SANDSTONE:0)
Block(-8,24,-5,SANDSTONE:0)
Block(-8,24,-4,SANDSTONE:0)
Block(-8,24,-3,SANDSTONE:0)
Block(-8,24,-2,SANDSTONE:0)
Block(-8,24,-1,SANDSTONE:0)
Block(-8,24,0,SANDSTONE:0)
Block(-8,24,1,SANDSTONE:0)
Block(-8,24,2,SANDSTONE:0)
Block(-8,24,3,SANDSTONE:0)
Block(-8,24,4,SANDSTONE:0)
Block(-8,24,5,SANDSTONE:0)
Block(-8,24,6,SANDSTONE:0)
Block(-8,24,7,SANDSTONE:0)
Block(-8,24,8,SANDSTONE:0)
Block(-8,25,-7,SANDSTONE:0)
Block(-8,25,-6,SANDSTONE:0)
Block(-8,25,-5,SANDSTONE:0)
Block(-8,25,-4,SANDSTONE:0)
Block(-8,25,-3,SANDSTONE:0)
Block(-8,25,-2,SANDSTONE:0)
Block(-8,25,-1,SANDSTONE:0)
Block(-8,25,0,SANDSTONE:0)
Block(-8,25,1,SANDSTONE:0)
Block(-8,25,2,SANDSTONE:0)
Block(-8,25,3,SANDSTONE:0)
Block(-8,25,4,SANDSTONE:0)
Block(-8,25,5,SANDSTONE:0)
Block(-8,25,6,SANDSTONE:0)
Block(-8,25,7,SANDSTONE:0)
Block(-8,25,8,SANDSTONE:0)
Block(-8,26,-7,SANDSTONE:0)
Block(-8,26,-6,SANDSTONE:0)
Block(-8,26,-5,SANDSTONE:0)
Block(-8,26,-4,SANDSTONE:0)
Block(-8,26,-3,SANDSTONE:0)
Block(-8,26,-2,SANDSTONE:0)
Block(-8,26,-1,SANDSTONE:0)
Block(-8,26,0,SANDSTONE:0)
Block(-8,26,1,SANDSTONE:0)
Block(-8,26,2,SANDSTONE:0)
Block(-8,26,3,SANDSTONE:0)
Block(-8,26,4,SANDSTONE:0)
Block(-8,26,5,SANDSTONE:0)
Block(-8,26,6,SANDSTONE:0)
Block(-8,26,7,SANDSTONE:0)
Block(-8,26,8,SANDSTONE:0)
Block(-8,27,-7,SANDSTONE:0)
Block(-8,27,-6,SANDSTONE:0)
Block(-8,27,-5,SANDSTONE:0)
Block(-8,27,-4,SANDSTONE:0)
Block(-8,27,-3,SANDSTONE:0)
Block(-8,27,-2,SANDSTONE:0)
Block(-8,27,-1,SANDSTONE:0)
Block(-8,27,0,SANDSTONE:0)
Block(-8,27,1,SANDSTONE:0)
Block(-8,27,2,SANDSTONE:0)
Block(-8,27,3,SANDSTONE:0)
Block(-8,27,4,SANDSTONE:0)
Block(-8,27,5,SANDSTONE:0)
Block(-8,27,6,SANDSTONE:0)
Block(-8,27,7,SANDSTONE:0)
Block(-8,27,8,SANDSTONE:0)
Block(-8,28,-7,SANDSTONE:0)
Block(-8,28,-6,SANDSTONE:0)
Block(-8,28,-5,SANDSTONE:0)
Block(-8,28,-4,SANDSTONE:0)
Block(-8,28,-3,SANDSTONE:0)
Block(-8,28,-2,SANDSTONE:0)
Block(-8,28,-1,SANDSTONE:0)
Block(-8,28,0,SANDSTONE:0)
Block(-8,28,1,SANDSTONE:0)
Block(-8,28,2,SANDSTONE:0)
Block(-8,28,3,SANDSTONE:0)
Block(-8,28,4,SANDSTONE:0)
Block(-8,28,5,SANDSTONE:0)
Block(-8,28,6,SANDSTONE:0)
Block(-8,28,7,SANDSTONE:0)
Block(-8,28,8,SANDSTONE:0)
Block(-8,29,-7,SANDSTONE:0)
Block(-8,29,-6,SANDSTONE:0)
Block(-8,29,-5,SANDSTONE:0)
Block(-8,29,-4,SANDSTONE:0)
Block(-8,29,-3,SANDSTONE:0)
Block(-8,29,-2,SANDSTONE:0)
Block(-8,29,-1,SANDSTONE:0)
Block(-8,29,0,SANDSTONE:0)
Block(-8,29,1,SANDSTONE:0)
Block(-8,29,2,SANDSTONE:0)
Block(-8,29,3,SANDSTONE:0)
Block(-8,29,4,SANDSTONE:0)
Block(-8,29,5,SANDSTONE:0)
Block(-8,29,6,SANDSTONE:0)
Block(-8,29,7,SANDSTONE:0)
Block(-8,29,8,SANDSTONE:0)
Block(-8,30,-7,SANDSTONE:0)
Block(-8,30,-6,SANDSTONE:0)
Block(-8,30,-5,SANDSTONE:0)
Block(-8,30,-4,SANDSTONE:0)
Block(-8,30,-3,SANDSTONE:0)
Block(-8,30,-2,SANDSTONE:0)
Block(-8,30,-1,SANDSTONE:0)
Block(-8,30,0,SANDSTONE:0)
Block(-8,30,1,SANDSTONE:0)
Block(-8,30,2,SANDSTONE:0)
Block(-8,30,3,SANDSTONE:0)
Block(-8,30,4,SANDSTONE:0)
Block(-8,30,5,SANDSTONE:0)
Block(-8,30,6,SANDSTONE:0)
Block(-8,30,7,SANDSTONE:0)
Block(-8,30,8,SANDSTONE:0)
Block(-8,31,-7,SANDSTONE:0)
Block(-8,31,-6,SANDSTONE:0)
Block(-8,31,-5,SANDSTONE:0)
Block(-8,31,-4,SANDSTONE:0)
Block(-8,31,-3,SANDSTONE:0)
Block(-8,31,-2,SANDSTONE:0)
Block(-8,31,-1,SANDSTONE:0)
Block(-8,31,0,SANDSTONE:0)
Block(-8,31,1,SANDSTONE:0)
Block(-8,31,2,SANDSTONE:0)
Block(-8,31,3,SANDSTONE:0)
Block(-8,31,4,SANDSTONE:0)
Block(-8,31,5,SANDSTONE:0)
Block(-8,31,6,SANDSTONE:0)
Block(-8,31,7,SANDSTONE:0)
Block(-8,31,8,SANDSTONE:0)
Block(-8,32,-7,SANDSTONE:0)
Block(-8,32,-6,SANDSTONE:0)
Block(-8,32,-5,SANDSTONE:0)
Block(-8,32,-4,SANDSTONE:0)
Block(-8,32,-3,SANDSTONE:0)
Block(-8,32,-2,SANDSTONE:0)
RandomBlock(-8,32,-1,SAND:0,50,SANDSTONE:0,100)
Block(-8,32,0,SANDSTONE:0)
Block(-8,32,1,SANDSTONE:0)
Block(-8,32,2,SANDSTONE:0)
Block(-8,32,3,SANDSTONE:0)
RandomBlock(-8,32,4,SAND:0,50,SANDSTONE:0,100)
Block(-8,32,5,SANDSTONE:0)
Block(-8,32,6,SANDSTONE:0)
Block(-8,32,7,SANDSTONE:0)
Block(-8,32,8,SANDSTONE:0)
Block(-8,33,-7,SANDSTONE:0)
Block(-8,33,-6,SANDSTONE:0)
Block(-8,33,-5,SANDSTONE:0)
Block(-8,33,-4,SANDSTONE:0)
RandomBlock(-8,33,-3,SAND:0,50,SANDSTONE:0,100)
RandomBlock(-8,33,-2,SAND:0,50,SANDSTONE:0,100)
RandomBlock(-8,33,-1,SAND:0,50,SANDSTONE:0,100)
RandomBlock(-8,33,0,SAND:0,50,SANDSTONE:0,100)
RandomBlock(-8,33,1,SAND:0,50,SANDSTONE:0,100)
RandomBlock(-8,33,2,SAND:0,50,SANDSTONE:0,100)
RandomBlock(-8,33,3,SAND:0,50,SANDSTONE:0,100)
RandomBlock(-8,33,4,SAND:0,50,SANDSTONE:0,100)
Block(-8,33,5,SANDSTONE:0)
Block(-8,33,6,SANDSTONE:0)
Block(-8,33,7,SANDSTONE:0)
Block(-8,33,8,SANDSTONE:0)
Block(-8,34,-7,SANDSTONE:0)
Block(-8,34,-6,SANDSTONE:0)
RandomBlock(-8,34,-5,SAND:0,50,SANDSTONE:0,100)
RandomBlock(-8,34,-4,SAND:0,50,SANDSTONE:0,100)
RandomBlock(-8,34,-3,SAND:0,50,SANDSTONE:0,100)
RandomBlock(-8,34,-2,SAND:0,50,SANDSTONE:0,100)
RandomBlock(-8,34,-1,SAND:0,50,SANDSTONE:0,100)
RandomBlock(-8,34,0,SAND:0,50,SANDSTONE:0,100)
RandomBlock(-8,34,1,SAND:0,50,SANDSTONE:0,100)
RandomBlock(-8,34,2,SAND:0,50,SANDSTONE:0,100)
RandomBlock(-8,34,3,SAND:0,50,SANDSTONE:0,100)
RandomBlock(-8,34,4,SAND:0,50,SANDSTONE:0,100)
Block(-8,34,5,SANDSTONE:0)
Block(-8,34,6,SANDSTONE:0)
Block(-8,34,7,SANDSTONE:0)
Block(-8,34,8,SANDSTONE:0)
RandomBlock(-8,35,-7,SAND:0,50,SANDSTONE:0,100)
RandomBlock(-8,35,-6,SAND:0,50,SANDSTONE:0,100)
RandomBlock(-8,35,-5,SAND:0,50,SANDSTONE:0,100)
RandomBlock(-8,35,-4,SAND:0,50,SANDSTONE:0,100)
RandomBlock(-8,35,-3,SAND:0,50,SANDSTONE:0,100)
RandomBlock(-8,35,-2,SAND:0,50,SANDSTONE:0,100)
RandomBlock(-8,35,-1,SAND:0,50,SANDSTONE:0,100)
RandomBlock(-8,35,0,SAND:0,50,SANDSTONE:0,100)
RandomBlock(-8,35,1,SAND:0,50,SANDSTONE:0,100)
RandomBlock(-8,35,2,SAND:0,50,SANDSTONE:0,100)
RandomBlock(-8,35,3,SAND:0,50,SANDSTONE:0,100)
RandomBlock(-8,35,4,SAND:0,50,SANDSTONE:0,100)
Block(-8,35,5,SANDSTONE:0)
Block(-8,35,6,SANDSTONE:0)
Block(-8,35,7,SANDSTONE:0)
Block(-8,35,8,SANDSTONE:0)
RandomBlock(-8,36,-7,SAND:0,50,SANDSTONE:0,100)
RandomBlock(-8,36,-6,SAND:0,50,SANDSTONE:0,100)
RandomBlock(-8,36,-5,SAND:0,50,SANDSTONE:0,100)
RandomBlock(-8,36,-4,SAND:0,50,SANDSTONE:0,100)
RandomBlock(-8,36,-3,SAND:0,50,SANDSTONE:0,100)
RandomBlock(-8,36,-2,SAND:0,50,SANDSTONE:0,100)
RandomBlock(-8,36,0,SAND:0,50,SANDSTONE:0,100)
RandomBlock(-8,36,1,SAND:0,50,SANDSTONE:0,100)
RandomBlock(-8,36,2,SAND:0,50,SANDSTONE:0,100)
RandomBlock(-8,36,3,SAND:0,50,SANDSTONE:0,100)
Block(-8,36,5,SANDSTONE:0)
Block(-8,36,6,SANDSTONE:0)
Block(-8,36,7,SANDSTONE:0)
Block(-8,36,8,SANDSTONE:0)
RandomBlock(-8,37,-7,SAND:0,50,SANDSTONE:0,100)
RandomBlock(-8,37,-6,SAND:0,50,SANDSTONE:0,100)
RandomBlock(-8,37,-5,SAND:0,50,SANDSTONE:0,100)
RandomBlock(-8,37,-4,SAND:0,50,SANDSTONE:0,100)
Block(-8,37,5,SANDSTONE:0)
Block(-8,37,6,SANDSTONE:0)
Block(-8,37,7,SANDSTONE:0)
Block(-8,37,8,SANDSTONE:0)
RandomBlock(-8,38,-7,SAND:0,50,SANDSTONE:0,100)
RandomBlock(-8,38,-6,SAND:0,50,SANDSTONE:0,100)
Block(-8,38,4,SANDSTONE:0)
Block(-8,38,5,SANDSTONE:0)
Block(-8,38,6,SANDSTONE:0)
Block(-8,38,7,SANDSTONE:0)
Block(-8,38,8,SANDSTONE:0)
RandomBlock(-8,39,-7,SAND:0,50,SANDSTONE:0,100)
Block(-8,39,5,SANDSTONE:0)
Block(-8,39,6,SANDSTONE:0)
Block(-8,39,7,SANDSTONE:0)
Block(-8,39,8,SANDSTONE:0)
Block(-8,40,6,SANDSTONE:0)
Block(-7,0,-7,SANDSTONE:0)
Block(-7,0,-6,SANDSTONE:0)
Block(-7,0,-5,SANDSTONE:0)
Block(-7,0,-4,SANDSTONE:0)
Block(-7,0,-3,SANDSTONE:0)
Block(-7,0,-2,SANDSTONE:0)
Block(-7,0,-1,SANDSTONE:0)
Block(-7,0,0,SANDSTONE:0)
Block(-7,0,1,SANDSTONE:0)
Block(-7,0,2,SANDSTONE:0)
Block(-7,0,3,SANDSTONE:0)
Block(-7,0,4,SANDSTONE:0)
Block(-7,0,5,SANDSTONE:0)
Block(-7,0,6,SANDSTONE:0)
Block(-7,0,7,SANDSTONE:0)
Block(-7,0,8,SANDSTONE:0)
Block(-7,1,-7,SANDSTONE:0)
Block(-7,1,-6,SANDSTONE:0)
Block(-7,1,-5,SANDSTONE:0)
Block(-7,1,-4,SANDSTONE:0)
Block(-7,1,-3,SANDSTONE:0)
Block(-7,1,-2,SANDSTONE:0)
Block(-7,1,-1,SANDSTONE:0)
Block(-7,1,0,SANDSTONE:0)
Block(-7,1,1,SANDSTONE:0)
Block(-7,1,2,SANDSTONE:0)
Block(-7,1,3,SANDSTONE:0)
Block(-7,1,4,SANDSTONE:0)
Block(-7,1,5,SANDSTONE:0)
Block(-7,1,6,SANDSTONE:0)
Block(-7,1,7,SANDSTONE:0)
Block(-7,1,8,SANDSTONE:0)
Block(-7,2,-7,SANDSTONE:0)
Block(-7,2,-6,SANDSTONE:0)
Block(-7,2,-5,SANDSTONE:0)
Block(-7,2,-4,SANDSTONE:0)
Block(-7,2,-3,SANDSTONE:0)
Block(-7,2,-2,SANDSTONE:0)
Block(-7,2,-1,SANDSTONE:0)
Block(-7,2,0,SANDSTONE:0)
Block(-7,2,1,SANDSTONE:0)
Block(-7,2,2,SANDSTONE:0)
Block(-7,2,3,SANDSTONE:0)
Block(-7,2,4,SANDSTONE:0)
Block(-7,2,5,SANDSTONE:0)
Block(-7,2,6,SANDSTONE:0)
Block(-7,2,7,SANDSTONE:0)
Block(-7,2,8,SANDSTONE:0)
Block(-7,3,-7,SANDSTONE:0)
Block(-7,3,-6,SANDSTONE:0)
Block(-7,3,-5,SANDSTONE:0)
Block(-7,3,-4,SANDSTONE:0)
Block(-7,3,-3,SANDSTONE:0)
Block(-7,3,-2,SANDSTONE:0)
Block(-7,3,-1,SANDSTONE:0)
Block(-7,3,0,SANDSTONE:0)
Block(-7,3,1,SANDSTONE:0)
Block(-7,3,2,SANDSTONE:0)
Block(-7,3,3,SANDSTONE:0)
Block(-7,3,4,SANDSTONE:0)
Block(-7,3,5,SANDSTONE:0)
Block(-7,3,6,SANDSTONE:0)
Block(-7,3,7,SANDSTONE:0)
Block(-7,3,8,SANDSTONE:0)
Block(-7,4,-7,SANDSTONE:0)
Block(-7,4,-6,SANDSTONE:0)
Block(-7,4,-5,SANDSTONE:0)
Block(-7,4,-4,SANDSTONE:0)
Block(-7,4,-3,SANDSTONE:0)
Block(-7,4,-2,SANDSTONE:0)
Block(-7,4,-1,SANDSTONE:0)
Block(-7,4,0,SANDSTONE:0)
Block(-7,4,1,SANDSTONE:0)
Block(-7,4,2,SANDSTONE:0)
Block(-7,4,3,SANDSTONE:0)
Block(-7,4,4,SANDSTONE:0)
Block(-7,4,5,SANDSTONE:0)
Block(-7,4,6,SANDSTONE:0)
Block(-7,4,7,SANDSTONE:0)
Block(-7,4,8,SANDSTONE:0)
Block(-7,5,-7,SANDSTONE:0)
Block(-7,5,-6,SANDSTONE:0)
Block(-7,5,-5,SANDSTONE:0)
Block(-7,5,-4,SANDSTONE:0)
Block(-7,5,-3,SANDSTONE:0)
Block(-7,5,-2,SANDSTONE:0)
Block(-7,5,-1,SANDSTONE:0)
Block(-7,5,0,SANDSTONE:0)
Block(-7,5,1,SANDSTONE:0)
Block(-7,5,2,SANDSTONE:0)
Block(-7,5,3,SANDSTONE:0)
Block(-7,5,4,SANDSTONE:0)
Block(-7,5,5,SANDSTONE:0)
Block(-7,5,6,SANDSTONE:0)
Block(-7,5,7,SANDSTONE:0)
Block(-7,5,8,SANDSTONE:0)
Block(-7,6,-7,SANDSTONE:0)
Block(-7,6,-6,SANDSTONE:0)
Block(-7,6,-5,SANDSTONE:0)
Block(-7,6,-4,SANDSTONE:0)
Block(-7,6,-3,SANDSTONE:0)
Block(-7,6,-2,SANDSTONE:0)
Block(-7,6,-1,SANDSTONE:0)
Block(-7,6,0,SANDSTONE:0)
Block(-7,6,1,SANDSTONE:0)
Block(-7,6,2,SANDSTONE:0)
Block(-7,6,3,SANDSTONE:0)
Block(-7,6,4,SANDSTONE:0)
Block(-7,6,5,SANDSTONE:0)
Block(-7,6,6,SANDSTONE:0)
Block(-7,6,7,SANDSTONE:0)
Block(-7,6,8,SANDSTONE:0)
Block(-7,7,-7,SANDSTONE:0)
Block(-7,7,-6,SANDSTONE:0)
Block(-7,7,-5,SANDSTONE:0)
Block(-7,7,-4,SANDSTONE:0)
Block(-7,7,-3,SANDSTONE:0)
Block(-7,7,-2,SANDSTONE:0)
Block(-7,7,-1,SANDSTONE:0)
Block(-7,7,0,SANDSTONE:0)
Block(-7,7,1,SANDSTONE:0)
Block(-7,7,2,SANDSTONE:0)
Block(-7,7,3,SANDSTONE:0)
Block(-7,7,4,SANDSTONE:0)
Block(-7,7,5,SANDSTONE:0)
Block(-7,7,6,SANDSTONE:0)
Block(-7,7,7,SANDSTONE:0)
Block(-7,7,8,SANDSTONE:0)
Block(-7,8,-7,SANDSTONE:0)
Block(-7,8,-6,SANDSTONE:0)
Block(-7,8,-5,SANDSTONE:0)
Block(-7,8,-4,SANDSTONE:0)
Block(-7,8,-3,SANDSTONE:0)
Block(-7,8,-2,SANDSTONE:0)
Block(-7,8,-1,SANDSTONE:0)
Block(-7,8,0,SANDSTONE:0)
Block(-7,8,1,SANDSTONE:0)
Block(-7,8,2,SANDSTONE:0)
Block(-7,8,3,SANDSTONE:0)
Block(-7,8,4,SANDSTONE:0)
Block(-7,8,5,SANDSTONE:0)
Block(-7,8,6,SANDSTONE:0)
Block(-7,8,7,SANDSTONE:0)
Block(-7,8,8,SANDSTONE:0)
Block(-7,9,-7,SANDSTONE:0)
Block(-7,9,-6,SANDSTONE:0)
Block(-7,9,-5,SANDSTONE:0)
Block(-7,9,-4,SANDSTONE:0)
Block(-7,9,-3,SANDSTONE:0)
Block(-7,9,-2,SANDSTONE:0)
Block(-7,9,-1,SANDSTONE:0)
Block(-7,9,0,SANDSTONE:0)
Block(-7,9,1,SANDSTONE:0)
Block(-7,9,2,SANDSTONE:0)
Block(-7,9,3,SANDSTONE:0)
Block(-7,9,4,SANDSTONE:0)
Block(-7,9,5,SANDSTONE:0)
Block(-7,9,6,SANDSTONE:0)
Block(-7,9,7,SANDSTONE:0)
Block(-7,9,8,SANDSTONE:0)
Block(-7,10,-7,SANDSTONE:0)
Block(-7,10,-6,SANDSTONE:0)
Block(-7,10,-5,SANDSTONE:0)
Block(-7,10,-4,SANDSTONE:0)
Block(-7,10,-3,SANDSTONE:0)
Block(-7,10,-2,SANDSTONE:0)
Block(-7,10,-1,SANDSTONE:0)
Block(-7,10,0,SANDSTONE:0)
Block(-7,10,1,SANDSTONE:0)
Block(-7,10,2,SANDSTONE:0)
Block(-7,10,3,SANDSTONE:0)
Block(-7,10,4,SANDSTONE:0)
Block(-7,10,5,SANDSTONE:0)
Block(-7,10,6,SANDSTONE:0)
Block(-7,10,7,SANDSTONE:0)
Block(-7,10,8,SANDSTONE:0)
Block(-7,11,-7,SANDSTONE:0)
Block(-7,11,-6,SANDSTONE:0)
Block(-7,11,-5,SANDSTONE:0)
Block(-7,11,-4,SANDSTONE:0)
Block(-7,11,-3,SANDSTONE:0)
Block(-7,11,-2,SANDSTONE:0)
Block(-7,11,-1,SANDSTONE:0)
Block(-7,11,0,SANDSTONE:0)
Block(-7,11,1,SANDSTONE:0)
Block(-7,11,2,SANDSTONE:0)
Block(-7,11,3,SANDSTONE:0)
Block(-7,11,4,SANDSTONE:0)
Block(-7,11,5,SANDSTONE:0)
Block(-7,11,6,SANDSTONE:0)
Block(-7,11,7,SANDSTONE:0)
Block(-7,11,8,SANDSTONE:0)
Block(-7,12,-7,SANDSTONE:0)
Block(-7,12,-6,SANDSTONE:0)
Block(-7,12,-5,SANDSTONE:0)
Block(-7,12,-4,SANDSTONE:0)
Block(-7,12,-3,SANDSTONE:0)
Block(-7,12,-2,SANDSTONE:0)
Block(-7,12,-1,SANDSTONE:0)
Block(-7,12,0,SANDSTONE:0)
Block(-7,12,1,SANDSTONE:0)
Block(-7,12,2,SANDSTONE:0)
Block(-7,12,3,SANDSTONE:0)
Block(-7,12,4,SANDSTONE:0)
Block(-7,12,5,SANDSTONE:0)
Block(-7,12,6,SANDSTONE:0)
Block(-7,12,7,SANDSTONE:0)
Block(-7,12,8,SANDSTONE:0)
Block(-7,13,-7,SANDSTONE:0)
Block(-7,13,-6,SANDSTONE:0)
Block(-7,13,-5,SANDSTONE:0)
Block(-7,13,-4,SANDSTONE:0)
Block(-7,13,-3,SANDSTONE:0)
Block(-7,13,-2,SANDSTONE:0)
Block(-7,13,-1,SANDSTONE:0)
Block(-7,13,0,SANDSTONE:0)
Block(-7,13,1,SANDSTONE:0)
Block(-7,13,2,SANDSTONE:0)
Block(-7,13,3,SANDSTONE:0)
Block(-7,13,4,SANDSTONE:0)
Block(-7,13,5,SANDSTONE:0)
Block(-7,13,6,SANDSTONE:0)
Block(-7,13,7,SANDSTONE:0)
Block(-7,13,8,SANDSTONE:0)
Block(-7,14,-7,SANDSTONE:0)
Block(-7,14,-6,SANDSTONE:0)
Block(-7,14,-5,SANDSTONE:0)
Block(-7,14,-4,SANDSTONE:0)
Block(-7,14,-3,SANDSTONE:0)
Block(-7,14,-2,SANDSTONE:0)
Block(-7,14,-1,SANDSTONE:0)
Block(-7,14,0,SANDSTONE:0)
Block(-7,14,1,SANDSTONE:0)
Block(-7,14,2,SANDSTONE:0)
Block(-7,14,3,SANDSTONE:0)
Block(-7,14,4,SANDSTONE:0)
Block(-7,14,5,SANDSTONE:0)
Block(-7,14,6,SANDSTONE:0)
Block(-7,14,7,SANDSTONE:0)
Block(-7,14,8,SANDSTONE:0)
Block(-7,15,-7,SANDSTONE:0)
Block(-7,15,-6,SANDSTONE:0)
Block(-7,15,-5,SANDSTONE:0)
Block(-7,15,-4,SANDSTONE:0)
Block(-7,15,-3,SANDSTONE:0)
Block(-7,15,-2,SANDSTONE:0)
Block(-7,15,-1,SANDSTONE:0)
Block(-7,15,0,SANDSTONE:0)
Block(-7,15,1,SANDSTONE:0)
Block(-7,15,2,SANDSTONE:0)
Block(-7,15,3,SANDSTONE:0)
Block(-7,15,4,SANDSTONE:0)
Block(-7,15,5,SANDSTONE:0)
Block(-7,15,6,SANDSTONE:0)
Block(-7,15,7,SANDSTONE:0)
Block(-7,15,8,SANDSTONE:0)
Block(-7,16,-7,SANDSTONE:0)
Block(-7,16,-6,SANDSTONE:0)
Block(-7,16,-5,SANDSTONE:0)
Block(-7,16,-4,SANDSTONE:0)
Block(-7,16,-3,SANDSTONE:0)
Block(-7,16,-2,SANDSTONE:0)
Block(-7,16,-1,SANDSTONE:0)
Block(-7,16,0,SANDSTONE:0)
Block(-7,16,1,SANDSTONE:0)
Block(-7,16,2,SANDSTONE:0)
Block(-7,16,3,SANDSTONE:0)
Block(-7,16,4,SANDSTONE:0)
Block(-7,16,5,SANDSTONE:0)
Block(-7,16,6,SANDSTONE:0)
Block(-7,16,7,SANDSTONE:0)
Block(-7,16,8,SANDSTONE:0)
Block(-7,17,-7,SANDSTONE:0)
Block(-7,17,-6,SANDSTONE:0)
Block(-7,17,-5,SANDSTONE:0)
Block(-7,17,-4,SANDSTONE:0)
Block(-7,17,-3,SANDSTONE:0)
Block(-7,17,-2,SANDSTONE:0)
Block(-7,17,-1,SANDSTONE:0)
Block(-7,17,0,SANDSTONE:0)
Block(-7,17,1,SANDSTONE:0)
Block(-7,17,2,SANDSTONE:0)
Block(-7,17,3,SANDSTONE:0)
Block(-7,17,4,SANDSTONE:0)
Block(-7,17,5,SANDSTONE:0)
Block(-7,17,6,SANDSTONE:0)
Block(-7,17,7,SANDSTONE:0)
Block(-7,17,8,SANDSTONE:0)
Block(-7,18,-7,SANDSTONE:0)
Block(-7,18,-6,SANDSTONE:0)
Block(-7,18,-5,SANDSTONE:0)
Block(-7,18,-4,SANDSTONE:0)
Block(-7,18,-3,SANDSTONE:0)
Block(-7,18,-2,SANDSTONE:0)
Block(-7,18,-1,SANDSTONE:0)
Block(-7,18,0,SANDSTONE:0)
Block(-7,18,1,SANDSTONE:0)
Block(-7,18,2,SANDSTONE:0)
Block(-7,18,3,SANDSTONE:0)
Block(-7,18,4,SANDSTONE:0)
Block(-7,18,5,SANDSTONE:0)
Block(-7,18,6,SANDSTONE:0)
Block(-7,18,7,SANDSTONE:0)
Block(-7,18,8,SANDSTONE:0)
Block(-7,19,-7,SANDSTONE:0)
Block(-7,19,-6,SANDSTONE:0)
Block(-7,19,-5,SANDSTONE:0)
Block(-7,19,-4,SANDSTONE:0)
Block(-7,19,-3,SANDSTONE:0)
Block(-7,19,-2,SANDSTONE:0)
Block(-7,19,-1,SANDSTONE:0)
Block(-7,19,0,SANDSTONE:0)
Block(-7,19,1,SANDSTONE:0)
Block(-7,19,2,SANDSTONE:0)
Block(-7,19,3,SANDSTONE:0)
Block(-7,19,4,SANDSTONE:0)
Block(-7,19,5,SANDSTONE:0)
Block(-7,19,6,SANDSTONE:0)
Block(-7,19,7,SANDSTONE:0)
Block(-7,19,8,SANDSTONE:0)
Block(-7,20,-7,SANDSTONE:0)
Block(-7,20,-6,SANDSTONE:0)
Block(-7,20,-5,SANDSTONE:0)
Block(-7,20,-4,SANDSTONE:0)
Block(-7,20,-3,SANDSTONE:0)
Block(-7,20,-2,SANDSTONE:0)
Block(-7,20,-1,SANDSTONE:0)
Block(-7,20,0,SANDSTONE:0)
Block(-7,20,1,SANDSTONE:0)
Block(-7,20,2,SANDSTONE:0)
Block(-7,20,3,SANDSTONE:0)
Block(-7,20,4,SANDSTONE:0)
Block(-7,20,5,SANDSTONE:0)
Block(-7,20,6,SANDSTONE:0)
Block(-7,20,7,SANDSTONE:0)
Block(-7,20,8,SANDSTONE:0)
Block(-7,21,-7,SANDSTONE:0)
Block(-7,21,-6,SANDSTONE:0)
Block(-7,21,-5,SANDSTONE:0)
Block(-7,21,-4,SANDSTONE:0)
Block(-7,21,-3,SANDSTONE:0)
Block(-7,21,-2,SANDSTONE:0)
Block(-7,21,-1,SANDSTONE:0)
Block(-7,21,0,SANDSTONE:0)
Block(-7,21,1,SANDSTONE:0)
Block(-7,21,2,SANDSTONE:0)
Block(-7,21,3,SANDSTONE:0)
Block(-7,21,4,SANDSTONE:0)
Block(-7,21,5,SANDSTONE:0)
Block(-7,21,6,SANDSTONE:0)
Block(-7,21,7,SANDSTONE:0)
Block(-7,21,8,SANDSTONE:0)
Block(-7,22,-7,SANDSTONE:0)
Block(-7,22,-6,SANDSTONE:0)
Block(-7,22,-5,SANDSTONE:0)
Block(-7,22,-4,SANDSTONE:0)
Block(-7,22,-3,SANDSTONE:0)
Block(-7,22,-2,SANDSTONE:0)
Block(-7,22,-1,SANDSTONE:0)
Block(-7,22,0,SANDSTONE:0)
Block(-7,22,1,SANDSTONE:0)
Block(-7,22,2,SANDSTONE:0)
Block(-7,22,3,SANDSTONE:0)
Block(-7,22,4,SANDSTONE:0)
Block(-7,22,5,SANDSTONE:0)
Block(-7,22,6,SANDSTONE:0)
Block(-7,22,7,SANDSTONE:0)
Block(-7,22,8,SANDSTONE:0)
Block(-7,23,-7,SANDSTONE:0)
Block(-7,23,-6,SANDSTONE:0)
Block(-7,23,-5,SANDSTONE:0)
Block(-7,23,-4,SANDSTONE:0)
Block(-7,23,-3,SANDSTONE:0)
Block(-7,23,-2,SANDSTONE:0)
Block(-7,23,-1,SANDSTONE:0)
Block(-7,23,0,SANDSTONE:0)
Block(-7,23,1,SANDSTONE:0)
Block(-7,23,2,SANDSTONE:0)
Block(-7,23,3,SANDSTONE:0)
Block(-7,23,4,SANDSTONE:0)
Block(-7,23,5,SANDSTONE:0)
Block(-7,23,6,SANDSTONE:0)
Block(-7,23,7,SANDSTONE:0)
Block(-7,23,8,SANDSTONE:0)
Block(-7,24,-7,SANDSTONE:0)
Block(-7,24,-6,SANDSTONE:0)
Block(-7,24,-5,SANDSTONE:0)
Block(-7,24,-4,SANDSTONE:0)
Block(-7,24,-3,SANDSTONE:0)
Block(-7,24,-2,SANDSTONE:0)
Block(-7,24,-1,SANDSTONE:0)
Block(-7,24,0,SANDSTONE:0)
Block(-7,24,1,SANDSTONE:0)
Block(-7,24,2,SANDSTONE:0)
Block(-7,24,3,SANDSTONE:0)
Block(-7,24,4,SANDSTONE:0)
Block(-7,24,5,SANDSTONE:0)
Block(-7,24,6,SANDSTONE:0)
Block(-7,24,7,SANDSTONE:0)
Block(-7,24,8,SANDSTONE:0)
Block(-7,25,-7,SANDSTONE:0)
Block(-7,25,-6,SANDSTONE:0)
Block(-7,25,-5,SANDSTONE:0)
Block(-7,25,-4,SANDSTONE:0)
Block(-7,25,-3,SANDSTONE:0)
Block(-7,25,-2,SANDSTONE:0)
Block(-7,25,-1,SANDSTONE:0)
Block(-7,25,0,SANDSTONE:0)
Block(-7,25,1,SANDSTONE:0)
Block(-7,25,2,SANDSTONE:0)
Block(-7,25,3,SANDSTONE:0)
Block(-7,25,4,SANDSTONE:0)
Block(-7,25,5,SANDSTONE:0)
Block(-7,25,6,SANDSTONE:0)
Block(-7,25,7,SANDSTONE:0)
Block(-7,25,8,SANDSTONE:0)
Block(-7,26,-7,SANDSTONE:0)
Block(-7,26,-6,SANDSTONE:0)
Block(-7,26,-5,SANDSTONE:0)
Block(-7,26,-4,SANDSTONE:0)
Block(-7,26,-3,SANDSTONE:0)
Block(-7,26,-2,SANDSTONE:0)
Block(-7,26,-1,SANDSTONE:0)
Block(-7,26,0,SANDSTONE:0)
Block(-7,26,1,SANDSTONE:0)
Block(-7,26,2,SANDSTONE:0)
Block(-7,26,3,SANDSTONE:0)
Block(-7,26,4,SANDSTONE:0)
Block(-7,26,5,SANDSTONE:0)
Block(-7,26,6,SANDSTONE:0)
Block(-7,26,7,SANDSTONE:0)
Block(-7,26,8,SANDSTONE:0)
Block(-7,27,-7,SANDSTONE:0)
Block(-7,27,-6,SANDSTONE:0)
Block(-7,27,-5,SANDSTONE:0)
Block(-7,27,-4,SANDSTONE:0)
Block(-7,27,-3,SANDSTONE:0)
Block(-7,27,-2,SANDSTONE:0)
Block(-7,27,-1,SANDSTONE:0)
Block(-7,27,0,SANDSTONE:0)
Block(-7,27,1,SANDSTONE:0)
Block(-7,27,2,SANDSTONE:0)
Block(-7,27,3,SANDSTONE:0)
Block(-7,27,4,SANDSTONE:0)
Block(-7,27,5,SANDSTONE:0)
Block(-7,27,6,SANDSTONE:0)
Block(-7,27,7,SANDSTONE:0)
Block(-7,27,8,SANDSTONE:0)
Block(-7,28,-7,SANDSTONE:0)
Block(-7,28,-6,SANDSTONE:0)
Block(-7,28,-5,SANDSTONE:0)
Block(-7,28,-4,SANDSTONE:0)
Block(-7,28,-3,SANDSTONE:0)
Block(-7,28,-2,SANDSTONE:0)
Block(-7,28,-1,SANDSTONE:0)
Block(-7,28,0,SANDSTONE:0)
Block(-7,28,1,SANDSTONE:0)
Block(-7,28,2,SANDSTONE:0)
Block(-7,28,3,SANDSTONE:0)
Block(-7,28,4,SANDSTONE:0)
Block(-7,28,5,SANDSTONE:0)
Block(-7,28,6,SANDSTONE:0)
Block(-7,28,7,SANDSTONE:0)
Block(-7,28,8,SANDSTONE:0)
Block(-7,29,-7,SANDSTONE:0)
Block(-7,29,-6,SANDSTONE:0)
Block(-7,29,-5,SANDSTONE:0)
Block(-7,29,-4,SANDSTONE:0)
Block(-7,29,-3,SANDSTONE:0)
Block(-7,29,-2,SANDSTONE:0)
Block(-7,29,-1,SANDSTONE:0)
Block(-7,29,0,SANDSTONE:0)
Block(-7,29,1,SANDSTONE:0)
Block(-7,29,2,SANDSTONE:0)
Block(-7,29,3,SANDSTONE:0)
Block(-7,29,4,SANDSTONE:0)
Block(-7,29,5,SANDSTONE:0)
Block(-7,29,6,SANDSTONE:0)
Block(-7,29,7,SANDSTONE:0)
Block(-7,29,8,SANDSTONE:0)
Block(-7,30,-7,SANDSTONE:0)
Block(-7,30,-6,SANDSTONE:0)
Block(-7,30,-5,SANDSTONE:0)
Block(-7,30,-4,SANDSTONE:0)
Block(-7,30,-3,SANDSTONE:0)
Block(-7,30,-2,SANDSTONE:0)
Block(-7,30,-1,SANDSTONE:0)
Block(-7,30,0,SANDSTONE:0)
Block(-7,30,1,SANDSTONE:0)
Block(-7,30,2,SANDSTONE:0)
Block(-7,30,3,SANDSTONE:0)
Block(-7,30,4,SANDSTONE:0)
Block(-7,30,5,SANDSTONE:0)
Block(-7,30,6,SANDSTONE:0)
Block(-7,30,7,SANDSTONE:0)
Block(-7,30,8,SANDSTONE:0)
Block(-7,31,-7,SANDSTONE:0)
Block(-7,31,-6,SANDSTONE:0)
Block(-7,31,-5,SANDSTONE:0)
Block(-7,31,-4,SANDSTONE:0)
Block(-7,31,-3,SANDSTONE:0)
Block(-7,31,-2,SANDSTONE:0)
Block(-7,31,-1,SANDSTONE:0)
Block(-7,31,0,SANDSTONE:0)
Block(-7,31,1,SANDSTONE:0)
Block(-7,31,2,SANDSTONE:0)
Block(-7,31,3,SANDSTONE:0)
Block(-7,31,4,SANDSTONE:0)
Block(-7,31,5,SANDSTONE:0)
Block(-7,31,6,SANDSTONE:0)
Block(-7,31,7,SANDSTONE:0)
Block(-7,31,8,SANDSTONE:0)
Block(-7,32,-7,SANDSTONE:0)
Block(-7,32,-6,SANDSTONE:0)
Block(-7,32,-5,SANDSTONE:0)
Block(-7,32,-4,SANDSTONE:0)
Block(-7,32,-3,SANDSTONE:0)
Block(-7,32,-2,SANDSTONE:0)
Block(-7,32,-1,SANDSTONE:0)
Block(-7,32,0,SANDSTONE:0)
Block(-7,32,1,SANDSTONE:0)
Block(-7,32,2,SANDSTONE:0)
Block(-7,32,3,SANDSTONE:0)
Block(-7,32,4,SANDSTONE:0)
Block(-7,32,5,SANDSTONE:0)
Block(-7,32,6,SANDSTONE:0)
Block(-7,32,7,SANDSTONE:0)
Block(-7,32,8,SANDSTONE:0)
Block(-7,33,-7,SANDSTONE:0)
Block(-7,33,-6,SANDSTONE:0)
Block(-7,33,-5,SANDSTONE:0)
Block(-7,33,-4,SANDSTONE:0)
RandomBlock(-7,33,-3,SAND:0,50,SANDSTONE:0,100)
RandomBlock(-7,33,-2,SAND:0,50,SANDSTONE:0,100)
RandomBlock(-7,33,-1,SAND:0,50,SANDSTONE:0,100)
RandomBlock(-7,33,0,SAND:0,50,SANDSTONE:0,100)
Block(-7,33,1,SANDSTONE:0)
RandomBlock(-7,33,2,SAND:0,50,SANDSTONE:0,100)
RandomBlock(-7,33,3,SAND:0,50,SANDSTONE:0,100)
Block(-7,33,4,SANDSTONE:0)
Block(-7,33,5,SANDSTONE:0)
Block(-7,33,6,SANDSTONE:0)
Block(-7,33,7,SANDSTONE:0)
Block(-7,33,8,SANDSTONE:0)
Block(-7,34,-7,SANDSTONE:0)
Block(-7,34,-6,SANDSTONE:0)
Block(-7,34,-5,SANDSTONE:0)
Block(-7,34,-4,SANDSTONE:0)
RandomBlock(-7,34,-3,SAND:0,50,SANDSTONE:0,100)
RandomBlock(-7,34,-2,SAND:0,50,SANDSTONE:0,100)
RandomBlock(-7,34,-1,SAND:0,50,SANDSTONE:0,100)
RandomBlock(-7,34,0,SAND:0,50,SANDSTONE:0,100)
RandomBlock(-7,34,1,SAND:0,50,SANDSTONE:0,100)
RandomBlock(-7,34,2,SAND:0,50,SANDSTONE:0,100)
RandomBlock(-7,34,3,SAND:0,50,SANDSTONE:0,100)
Block(-7,34,4,SANDSTONE:0)
Block(-7,34,5,SANDSTONE:0)
Block(-7,34,6,SANDSTONE:0)
Block(-7,34,7,SANDSTONE:0)
Block(-7,34,8,SANDSTONE:0)
Block(-7,35,-7,SANDSTONE:0)
Block(-7,35,-6,SANDSTONE:0)
Block(-7,35,-5,SANDSTONE:0)
Block(-7,35,-4,SANDSTONE:0)
RandomBlock(-7,35,-3,SAND:0,50,SANDSTONE:0,100)
RandomBlock(-7,35,-2,SAND:0,50,SANDSTONE:0,100)
RandomBlock(-7,35,-1,SAND:0,50,SANDSTONE:0,100)
RandomBlock(-7,35,0,SAND:0,50,SANDSTONE:0,100)
RandomBlock(-7,35,1,SAND:0,50,SANDSTONE:0,100)
RandomBlock(-7,35,2,SAND:0,50,SANDSTONE:0,100)
RandomBlock(-7,35,3,SAND:0,50,SANDSTONE:0,100)
Block(-7,35,4,SANDSTONE:0)
Block(-7,35,5,SANDSTONE:0)
Block(-7,35,6,SANDSTONE:0)
Block(-7,35,7,SANDSTONE:0)
Block(-7,35,8,SANDSTONE:0)
Block(-7,36,-7,SANDSTONE:0)
Block(-7,36,-6,SANDSTONE:0)
Block(-7,36,-5,SANDSTONE:0)
RandomBlock(-7,36,-4,SAND:0,50,SANDSTONE:0,100)
RandomBlock(-7,36,-3,SAND:0,50,SANDSTONE:0,100)
RandomBlock(-7,36,-2,SAND:0,50,SANDSTONE:0,100)
RandomBlock(-7,36,-1,SAND:0,50,SANDSTONE:0,100)
RandomBlock(-7,36,0,SAND:0,50,SANDSTONE:0,100)
RandomBlock(-7,36,1,SAND:0,50,SANDSTONE:0,100)
RandomBlock(-7,36,2,SAND:0,50,SANDSTONE:0,100)
RandomBlock(-7,36,3,SAND:0,50,SANDSTONE:0,100)
Block(-7,36,4,SANDSTONE:0)
Block(-7,36,5,SANDSTONE:0)
Block(-7,36,6,SANDSTONE:0)
Block(-7,36,7,SANDSTONE:0)
Block(-7,36,8,SANDSTONE:0)
Block(-7,37,-7,SANDSTONE:0)
Block(-7,37,-6,SANDSTONE:0)
Block(-7,37,-5,SANDSTONE:0)
RandomBlock(-7,37,-4,SAND:0,50,SANDSTONE:0,100)
RandomBlock(-7,37,1,SAND:0,50,SANDSTONE:0,100)
Block(-7,37,4,SANDSTONE:0)
Block(-7,37,5,SANDSTONE:0)
Block(-7,37,6,SANDSTONE:0)
Block(-7,37,7,SANDSTONE:0)
Block(-7,37,8,SANDSTONE:0)
RandomBlock(-7,38,-7,SAND:0,50,SANDSTONE:0,100)
RandomBlock(-7,38,-6,SAND:0,50,SANDSTONE:0,100)
RandomBlock(-7,38,-5,SAND:0,50,SANDSTONE:0,100)
RandomBlock(-7,38,-4,SAND:0,50,SANDSTONE:0,100)
Block(-7,38,4,SANDSTONE:0)
Block(-7,38,5,SANDSTONE:0)
Block(-7,38,6,SANDSTONE:0)
Block(-7,38,7,SANDSTONE:0)
Block(-7,38,8,SANDSTONE:0)
RandomBlock(-7,39,-7,SAND:0,50,SANDSTONE:0,100)
RandomBlock(-7,39,-6,SAND:0,50,SANDSTONE:0,100)
RandomBlock(-7,39,-5,SAND:0,50,SANDSTONE:0,100)
Block(-7,39,4,SANDSTONE:0)
Block(-7,39,5,SANDSTONE:0)
Block(-7,39,6,SANDSTONE:0)
Block(-7,39,7,SANDSTONE:0)
Block(-7,39,8,SANDSTONE:0)
RandomBlock(-7,40,-7,SAND:0,50,SANDSTONE:0,100)
RandomBlock(-7,40,-6,SAND:0,50,SANDSTONE:0,100)
RandomBlock(-7,40,-5,SAND:0,50,SANDSTONE:0,100)
Block(-7,40,5,SANDSTONE:0)
Block(-7,40,6,SANDSTONE:0)
Block(-7,40,7,SANDSTONE:0)
Block(-7,40,8,SANDSTONE:0)
RandomBlock(-7,41,-7,SAND:0,50,SANDSTONE:0,100)
RandomBlock(-7,41,-6,SAND:0,50,SANDSTONE:0,100)
RandomBlock(-7,41,-5,SAND:0,50,SANDSTONE:0,100)
Block(-7,41,6,SANDSTONE:0)
Block(-6,0,-7,SANDSTONE:0)
Block(-6,0,-6,SANDSTONE:0)
Block(-6,0,-5,SANDSTONE:0)
Block(-6,0,-4,SANDSTONE:0)
Block(-6,0,-3,SANDSTONE:0)
Block(-6,0,-2,SANDSTONE:0)
Block(-6,0,-1,SANDSTONE:0)
Block(-6,0,0,SANDSTONE:0)
Block(-6,0,1,SANDSTONE:0)
Block(-6,0,2,SANDSTONE:0)
Block(-6,0,3,SANDSTONE:0)
Block(-6,0,4,SANDSTONE:0)
Block(-6,0,5,SANDSTONE:0)
Block(-6,0,6,SANDSTONE:0)
Block(-6,0,7,SANDSTONE:0)
Block(-6,0,8,SANDSTONE:0)
Block(-6,1,-7,SANDSTONE:0)
Block(-6,1,-6,SANDSTONE:0)
Block(-6,1,-5,SANDSTONE:0)
Block(-6,1,-4,SANDSTONE:0)
Block(-6,1,-3,SANDSTONE:0)
Block(-6,1,-2,SANDSTONE:0)
Block(-6,1,-1,SANDSTONE:0)
Block(-6,1,0,SANDSTONE:0)
Block(-6,1,1,SANDSTONE:0)
Block(-6,1,2,SANDSTONE:0)
Block(-6,1,3,SANDSTONE:0)
Block(-6,1,4,SANDSTONE:0)
Block(-6,1,5,SANDSTONE:0)
Block(-6,1,6,SANDSTONE:0)
Block(-6,1,7,SANDSTONE:0)
Block(-6,1,8,SANDSTONE:0)
Block(-6,2,-7,SANDSTONE:0)
Block(-6,2,-6,SANDSTONE:0)
Block(-6,2,-5,SANDSTONE:0)
Block(-6,2,-4,SANDSTONE:0)
Block(-6,2,-3,SANDSTONE:0)
Block(-6,2,-2,SANDSTONE:0)
Block(-6,2,-1,SANDSTONE:0)
Block(-6,2,0,SANDSTONE:0)
Block(-6,2,1,SANDSTONE:0)
Block(-6,2,2,SANDSTONE:0)
Block(-6,2,3,SANDSTONE:0)
Block(-6,2,4,SANDSTONE:0)
Block(-6,2,5,SANDSTONE:0)
Block(-6,2,6,SANDSTONE:0)
Block(-6,2,7,SANDSTONE:0)
Block(-6,2,8,SANDSTONE:0)
Block(-6,3,-7,SANDSTONE:0)
Block(-6,3,-6,SANDSTONE:0)
Block(-6,3,-5,SANDSTONE:0)
Block(-6,3,-4,SANDSTONE:0)
Block(-6,3,-3,SANDSTONE:0)
Block(-6,3,-2,SANDSTONE:0)
Block(-6,3,-1,SANDSTONE:0)
Block(-6,3,0,SANDSTONE:0)
Block(-6,3,1,SANDSTONE:0)
Block(-6,3,2,SANDSTONE:0)
Block(-6,3,3,SANDSTONE:0)
Block(-6,3,4,SANDSTONE:0)
Block(-6,3,5,SANDSTONE:0)
Block(-6,3,6,SANDSTONE:0)
Block(-6,3,7,SANDSTONE:0)
Block(-6,3,8,SANDSTONE:0)
Block(-6,4,-7,SANDSTONE:0)
Block(-6,4,-6,SANDSTONE:0)
Block(-6,4,-5,SANDSTONE:0)
Block(-6,4,-4,SANDSTONE:0)
Block(-6,4,-3,SANDSTONE:0)
Block(-6,4,-2,SANDSTONE:0)
Block(-6,4,-1,SANDSTONE:0)
Block(-6,4,0,SANDSTONE:0)
Block(-6,4,1,SANDSTONE:0)
Block(-6,4,2,SANDSTONE:0)
Block(-6,4,3,SANDSTONE:0)
Block(-6,4,4,SANDSTONE:0)
Block(-6,4,5,SANDSTONE:0)
Block(-6,4,6,SANDSTONE:0)
Block(-6,4,7,SANDSTONE:0)
Block(-6,4,8,SANDSTONE:0)
Block(-6,5,-7,SANDSTONE:0)
Block(-6,5,-6,SANDSTONE:0)
Block(-6,5,-5,SANDSTONE:0)
Block(-6,5,-4,SANDSTONE:0)
Block(-6,5,-3,SANDSTONE:0)
Block(-6,5,-2,SANDSTONE:0)
Block(-6,5,-1,SANDSTONE:0)
Block(-6,5,0,SANDSTONE:0)
Block(-6,5,1,SANDSTONE:0)
Block(-6,5,2,SANDSTONE:0)
Block(-6,5,3,SANDSTONE:0)
Block(-6,5,4,SANDSTONE:0)
Block(-6,5,5,SANDSTONE:0)
Block(-6,5,6,SANDSTONE:0)
Block(-6,5,7,SANDSTONE:0)
Block(-6,5,8,SANDSTONE:0)
Block(-6,6,-7,SANDSTONE:0)
Block(-6,6,-6,SANDSTONE:0)
Block(-6,6,-5,SANDSTONE:0)
Block(-6,6,-4,SANDSTONE:0)
Block(-6,6,-3,SANDSTONE:0)
Block(-6,6,-2,SANDSTONE:0)
Block(-6,6,-1,SANDSTONE:0)
Block(-6,6,0,SANDSTONE:0)
Block(-6,6,1,SANDSTONE:0)
Block(-6,6,2,SANDSTONE:0)
Block(-6,6,3,SANDSTONE:0)
Block(-6,6,4,SANDSTONE:0)
Block(-6,6,5,SANDSTONE:0)
Block(-6,6,6,SANDSTONE:0)
Block(-6,6,7,SANDSTONE:0)
Block(-6,6,8,SANDSTONE:0)
Block(-6,7,-7,SANDSTONE:0)
Block(-6,7,-6,SANDSTONE:0)
Block(-6,7,-5,SANDSTONE:0)
Block(-6,7,-4,SANDSTONE:0)
Block(-6,7,-3,SANDSTONE:0)
Block(-6,7,-2,SANDSTONE:0)
Block(-6,7,-1,SANDSTONE:0)
Block(-6,7,0,SANDSTONE:0)
Block(-6,7,1,SANDSTONE:0)
Block(-6,7,2,SANDSTONE:0)
Block(-6,7,3,SANDSTONE:0)
Block(-6,7,4,SANDSTONE:0)
Block(-6,7,5,SANDSTONE:0)
Block(-6,7,6,SANDSTONE:0)
Block(-6,7,7,SANDSTONE:0)
Block(-6,7,8,SANDSTONE:0)
Block(-6,8,-7,SANDSTONE:0)
Block(-6,8,-6,SANDSTONE:0)
Block(-6,8,-5,SANDSTONE:0)
Block(-6,8,-4,SANDSTONE:0)
Block(-6,8,-3,SANDSTONE:0)
Block(-6,8,-2,SANDSTONE:0)
Block(-6,8,-1,SANDSTONE:0)
Block(-6,8,0,SANDSTONE:0)
Block(-6,8,1,SANDSTONE:0)
Block(-6,8,2,SANDSTONE:0)
Block(-6,8,3,SANDSTONE:0)
Block(-6,8,4,SANDSTONE:0)
Block(-6,8,5,SANDSTONE:0)
Block(-6,8,6,SANDSTONE:0)
Block(-6,8,7,SANDSTONE:0)
Block(-6,8,8,SANDSTONE:0)
Block(-6,9,-7,SANDSTONE:0)
Block(-6,9,-6,SANDSTONE:0)
Block(-6,9,-5,SANDSTONE:0)
Block(-6,9,-4,SANDSTONE:0)
Block(-6,9,-3,SANDSTONE:0)
Block(-6,9,-2,SANDSTONE:0)
Block(-6,9,-1,SANDSTONE:0)
Block(-6,9,0,SANDSTONE:0)
Block(-6,9,1,SANDSTONE:0)
Block(-6,9,2,SANDSTONE:0)
Block(-6,9,3,SANDSTONE:0)
Block(-6,9,4,SANDSTONE:0)
Block(-6,9,5,SANDSTONE:0)
Block(-6,9,6,SANDSTONE:0)
Block(-6,9,7,SANDSTONE:0)
Block(-6,9,8,SANDSTONE:0)
Block(-6,10,-7,SANDSTONE:0)
Block(-6,10,-6,SANDSTONE:0)
Block(-6,10,-5,SANDSTONE:0)
Block(-6,10,-4,SANDSTONE:0)
Block(-6,10,-3,SANDSTONE:0)
Block(-6,10,-2,SANDSTONE:0)
Block(-6,10,-1,SANDSTONE:0)
Block(-6,10,0,SANDSTONE:0)
Block(-6,10,1,SANDSTONE:0)
Block(-6,10,2,SANDSTONE:0)
Block(-6,10,3,SANDSTONE:0)
Block(-6,10,4,SANDSTONE:0)
Block(-6,10,5,SANDSTONE:0)
Block(-6,10,6,SANDSTONE:0)
Block(-6,10,7,SANDSTONE:0)
Block(-6,10,8,SANDSTONE:0)
Block(-6,11,-7,SANDSTONE:0)
Block(-6,11,-6,SANDSTONE:0)
Block(-6,11,-5,SANDSTONE:0)
Block(-6,11,-4,SANDSTONE:0)
Block(-6,11,-3,SANDSTONE:0)
Block(-6,11,-2,SANDSTONE:0)
Block(-6,11,-1,SANDSTONE:0)
Block(-6,11,0,SANDSTONE:0)
Block(-6,11,1,SANDSTONE:0)
Block(-6,11,2,SANDSTONE:0)
Block(-6,11,3,SANDSTONE:0)
Block(-6,11,4,SANDSTONE:0)
Block(-6,11,5,SANDSTONE:0)
Block(-6,11,6,SANDSTONE:0)
Block(-6,11,7,SANDSTONE:0)
Block(-6,11,8,SANDSTONE:0)
Block(-6,12,-7,SANDSTONE:0)
Block(-6,12,-6,SANDSTONE:0)
Block(-6,12,-5,SANDSTONE:0)
Block(-6,12,-4,SANDSTONE:0)
Block(-6,12,-3,SANDSTONE:0)
Block(-6,12,-2,SANDSTONE:0)
Block(-6,12,-1,SANDSTONE:0)
Block(-6,12,0,SANDSTONE:0)
Block(-6,12,1,SANDSTONE:0)
Block(-6,12,2,SANDSTONE:0)
Block(-6,12,3,SANDSTONE:0)
Block(-6,12,4,SANDSTONE:0)
Block(-6,12,5,SANDSTONE:0)
Block(-6,12,6,SANDSTONE:0)
Block(-6,12,7,SANDSTONE:0)
Block(-6,12,8,SANDSTONE:0)
Block(-6,13,-7,SANDSTONE:0)
Block(-6,13,-6,SANDSTONE:0)
Block(-6,13,-5,SANDSTONE:0)
Block(-6,13,-4,SANDSTONE:0)
Block(-6,13,-3,SANDSTONE:0)
Block(-6,13,-2,SANDSTONE:0)
Block(-6,13,-1,SANDSTONE:0)
Block(-6,13,0,SANDSTONE:0)
Block(-6,13,1,SANDSTONE:0)
Block(-6,13,2,SANDSTONE:0)
Block(-6,13,3,SANDSTONE:0)
Block(-6,13,4,SANDSTONE:0)
Block(-6,13,5,SANDSTONE:0)
Block(-6,13,6,SANDSTONE:0)
Block(-6,13,7,SANDSTONE:0)
Block(-6,13,8,SANDSTONE:0)
Block(-6,14,-7,SANDSTONE:0)
Block(-6,14,-6,SANDSTONE:0)
Block(-6,14,-5,SANDSTONE:0)
Block(-6,14,-4,SANDSTONE:0)
Block(-6,14,-3,SANDSTONE:0)
Block(-6,14,-2,SANDSTONE:0)
Block(-6,14,-1,SANDSTONE:0)
Block(-6,14,0,SANDSTONE:0)
Block(-6,14,1,SANDSTONE:0)
Block(-6,14,2,SANDSTONE:0)
Block(-6,14,3,SANDSTONE:0)
Block(-6,14,4,SANDSTONE:0)
Block(-6,14,5,SANDSTONE:0)
Block(-6,14,6,SANDSTONE:0)
Block(-6,14,7,SANDSTONE:0)
Block(-6,14,8,SANDSTONE:0)
Block(-6,15,-7,SANDSTONE:0)
Block(-6,15,-6,SANDSTONE:0)
Block(-6,15,-5,SANDSTONE:0)
Block(-6,15,-4,SANDSTONE:0)
Block(-6,15,-3,SANDSTONE:0)
Block(-6,15,-2,SANDSTONE:0)
Block(-6,15,-1,SANDSTONE:0)
Block(-6,15,0,SANDSTONE:0)
Block(-6,15,1,SANDSTONE:0)
Block(-6,15,2,SANDSTONE:0)
Block(-6,15,3,SANDSTONE:0)
Block(-6,15,4,SANDSTONE:0)
Block(-6,15,5,SANDSTONE:0)
Block(-6,15,6,SANDSTONE:0)
Block(-6,15,7,SANDSTONE:0)
Block(-6,15,8,SANDSTONE:0)
Block(-6,16,-7,SANDSTONE:0)
Block(-6,16,-6,SANDSTONE:0)
Block(-6,16,-5,SANDSTONE:0)
Block(-6,16,-4,SANDSTONE:0)
Block(-6,16,-3,SANDSTONE:0)
Block(-6,16,-2,SANDSTONE:0)
Block(-6,16,-1,SANDSTONE:0)
Block(-6,16,0,SANDSTONE:0)
Block(-6,16,1,SANDSTONE:0)
Block(-6,16,2,SANDSTONE:0)
Block(-6,16,3,SANDSTONE:0)
Block(-6,16,4,SANDSTONE:0)
Block(-6,16,5,SANDSTONE:0)
Block(-6,16,6,SANDSTONE:0)
Block(-6,16,7,SANDSTONE:0)
Block(-6,16,8,SANDSTONE:0)
Block(-6,17,-7,SANDSTONE:0)
Block(-6,17,-6,SANDSTONE:0)
Block(-6,17,-5,SANDSTONE:0)
Block(-6,17,-4,SANDSTONE:0)
Block(-6,17,-3,SANDSTONE:0)
Block(-6,17,-2,SANDSTONE:0)
Block(-6,17,-1,SANDSTONE:0)
Block(-6,17,0,SANDSTONE:0)
Block(-6,17,1,SANDSTONE:0)
Block(-6,17,2,SANDSTONE:0)
Block(-6,17,3,SANDSTONE:0)
Block(-6,17,4,SANDSTONE:0)
Block(-6,17,5,SANDSTONE:0)
Block(-6,17,6,SANDSTONE:0)
Block(-6,17,7,SANDSTONE:0)
Block(-6,17,8,SANDSTONE:0)
Block(-6,18,-7,SANDSTONE:0)
Block(-6,18,-6,SANDSTONE:0)
Block(-6,18,-5,SANDSTONE:0)
Block(-6,18,-4,SANDSTONE:0)
Block(-6,18,-3,SANDSTONE:0)
Block(-6,18,-2,SANDSTONE:0)
Block(-6,18,-1,SANDSTONE:0)
Block(-6,18,0,SANDSTONE:0)
Block(-6,18,1,SANDSTONE:0)
Block(-6,18,2,SANDSTONE:0)
Block(-6,18,3,SANDSTONE:0)
Block(-6,18,4,SANDSTONE:0)
Block(-6,18,5,SANDSTONE:0)
Block(-6,18,6,SANDSTONE:0)
Block(-6,18,7,SANDSTONE:0)
Block(-6,18,8,SANDSTONE:0)
Block(-6,19,-7,SANDSTONE:0)
Block(-6,19,-6,SANDSTONE:0)
Block(-6,19,-5,SANDSTONE:0)
Block(-6,19,-4,SANDSTONE:0)
Block(-6,19,-3,SANDSTONE:0)
Block(-6,19,-2,SANDSTONE:0)
Block(-6,19,-1,SANDSTONE:0)
Block(-6,19,0,SANDSTONE:0)
Block(-6,19,1,SANDSTONE:0)
Block(-6,19,2,SANDSTONE:0)
Block(-6,19,3,SANDSTONE:0)
Block(-6,19,4,SANDSTONE:0)
Block(-6,19,5,SANDSTONE:0)
Block(-6,19,6,SANDSTONE:0)
Block(-6,19,7,SANDSTONE:0)
Block(-6,19,8,SANDSTONE:0)
Block(-6,20,-7,SANDSTONE:0)
Block(-6,20,-6,SANDSTONE:0)
Block(-6,20,-5,SANDSTONE:0)
Block(-6,20,-4,SANDSTONE:0)
Block(-6,20,-3,SANDSTONE:0)
Block(-6,20,-2,SANDSTONE:0)
Block(-6,20,-1,SANDSTONE:0)
Block(-6,20,0,SANDSTONE:0)
Block(-6,20,1,SANDSTONE:0)
Block(-6,20,2,SANDSTONE:0)
Block(-6,20,3,SANDSTONE:0)
Block(-6,20,4,SANDSTONE:0)
Block(-6,20,5,SANDSTONE:0)
Block(-6,20,6,SANDSTONE:0)
Block(-6,20,7,SANDSTONE:0)
Block(-6,20,8,SANDSTONE:0)
Block(-6,21,-7,SANDSTONE:0)
Block(-6,21,-6,SANDSTONE:0)
Block(-6,21,-5,SANDSTONE:0)
Block(-6,21,-4,SANDSTONE:0)
Block(-6,21,-3,SANDSTONE:0)
Block(-6,21,-2,SANDSTONE:0)
Block(-6,21,-1,SANDSTONE:0)
Block(-6,21,0,SANDSTONE:0)
Block(-6,21,1,SANDSTONE:0)
Block(-6,21,2,SANDSTONE:0)
Block(-6,21,3,SANDSTONE:0)
Block(-6,21,4,SANDSTONE:0)
Block(-6,21,5,SANDSTONE:0)
Block(-6,21,6,SANDSTONE:0)
Block(-6,21,7,SANDSTONE:0)
Block(-6,21,8,SANDSTONE:0)
Block(-6,22,-7,SANDSTONE:0)
Block(-6,22,-6,SANDSTONE:0)
Block(-6,22,-5,SANDSTONE:0)
Block(-6,22,-4,SANDSTONE:0)
Block(-6,22,-3,SANDSTONE:0)
Block(-6,22,-2,SANDSTONE:0)
Block(-6,22,-1,SANDSTONE:0)
Block(-6,22,0,SANDSTONE:0)
Block(-6,22,1,SANDSTONE:0)
Block(-6,22,2,SANDSTONE:0)
Block(-6,22,3,SANDSTONE:0)
Block(-6,22,4,SANDSTONE:0)
Block(-6,22,5,SANDSTONE:0)
Block(-6,22,6,SANDSTONE:0)
Block(-6,22,7,SANDSTONE:0)
Block(-6,22,8,SANDSTONE:0)
Block(-6,23,-7,SANDSTONE:0)
Block(-6,23,-6,SANDSTONE:0)
Block(-6,23,-5,SANDSTONE:0)
Block(-6,23,-4,SANDSTONE:0)
Block(-6,23,-3,SANDSTONE:0)
Block(-6,23,-2,SANDSTONE:0)
Block(-6,23,-1,SANDSTONE:0)
Block(-6,23,0,SANDSTONE:0)
Block(-6,23,1,SANDSTONE:0)
Block(-6,23,2,SANDSTONE:0)
Block(-6,23,3,SANDSTONE:0)
Block(-6,23,4,SANDSTONE:0)
Block(-6,23,5,SANDSTONE:0)
Block(-6,23,6,SANDSTONE:0)
Block(-6,23,7,SANDSTONE:0)
Block(-6,23,8,SANDSTONE:0)
Block(-6,24,-7,SANDSTONE:0)
Block(-6,24,-6,SANDSTONE:0)
Block(-6,24,-5,SANDSTONE:0)
Block(-6,24,-4,SANDSTONE:0)
Block(-6,24,-3,SANDSTONE:0)
Block(-6,24,-2,SANDSTONE:0)
Block(-6,24,-1,SANDSTONE:0)
Block(-6,24,0,SANDSTONE:0)
Block(-6,24,1,SANDSTONE:0)
Block(-6,24,2,SANDSTONE:0)
Block(-6,24,3,SANDSTONE:0)
Block(-6,24,4,SANDSTONE:0)
Block(-6,24,5,SANDSTONE:0)
Block(-6,24,6,SANDSTONE:0)
Block(-6,24,7,SANDSTONE:0)
Block(-6,24,8,SANDSTONE:0)
Block(-6,25,-7,SANDSTONE:0)
Block(-6,25,-6,SANDSTONE:0)
Block(-6,25,-5,SANDSTONE:0)
Block(-6,25,-4,SANDSTONE:0)
Block(-6,25,-3,SANDSTONE:0)
Block(-6,25,-2,SANDSTONE:0)
Block(-6,25,-1,SANDSTONE:0)
Block(-6,25,0,SANDSTONE:0)
Block(-6,25,1,SANDSTONE:0)
Block(-6,25,2,SANDSTONE:0)
Block(-6,25,3,SANDSTONE:0)
Block(-6,25,4,SANDSTONE:0)
Block(-6,25,5,SANDSTONE:0)
Block(-6,25,6,SANDSTONE:0)
Block(-6,25,7,SANDSTONE:0)
Block(-6,25,8,SANDSTONE:0)
Block(-6,26,-7,SANDSTONE:0)
Block(-6,26,-6,SANDSTONE:0)
Block(-6,26,-5,SANDSTONE:0)
Block(-6,26,-4,SANDSTONE:0)
Block(-6,26,-3,SANDSTONE:0)
Block(-6,26,-2,SANDSTONE:0)
Block(-6,26,-1,SANDSTONE:0)
Block(-6,26,0,SANDSTONE:0)
Block(-6,26,1,SANDSTONE:0)
Block(-6,26,2,SANDSTONE:0)
Block(-6,26,3,SANDSTONE:0)
Block(-6,26,4,SANDSTONE:0)
Block(-6,26,5,SANDSTONE:0)
Block(-6,26,6,SANDSTONE:0)
Block(-6,26,7,SANDSTONE:0)
Block(-6,26,8,SANDSTONE:0)
Block(-6,27,-7,SANDSTONE:0)
Block(-6,27,-6,SANDSTONE:0)
Block(-6,27,-5,SANDSTONE:0)
Block(-6,27,-4,SANDSTONE:0)
Block(-6,27,-3,SANDSTONE:0)
Block(-6,27,-2,SANDSTONE:0)
Block(-6,27,-1,SANDSTONE:0)
Block(-6,27,0,SANDSTONE:0)
Block(-6,27,1,SANDSTONE:0)
Block(-6,27,2,SANDSTONE:0)
Block(-6,27,3,SANDSTONE:0)
Block(-6,27,4,SANDSTONE:0)
Block(-6,27,5,SANDSTONE:0)
Block(-6,27,6,SANDSTONE:0)
Block(-6,27,7,SANDSTONE:0)
Block(-6,27,8,SANDSTONE:0)
Block(-6,28,-7,SANDSTONE:0)
Block(-6,28,-6,SANDSTONE:0)
Block(-6,28,-5,SANDSTONE:0)
Block(-6,28,-4,SANDSTONE:0)
Block(-6,28,-3,SANDSTONE:0)
Block(-6,28,-2,SANDSTONE:0)
Block(-6,28,-1,SANDSTONE:0)
Block(-6,28,0,SANDSTONE:0)
Block(-6,28,1,SANDSTONE:0)
Block(-6,28,2,SANDSTONE:0)
Block(-6,28,3,SANDSTONE:0)
Block(-6,28,4,SANDSTONE:0)
Block(-6,28,5,SANDSTONE:0)
Block(-6,28,6,SANDSTONE:0)
Block(-6,28,7,SANDSTONE:0)
Block(-6,28,8,SANDSTONE:0)
Block(-6,29,-7,SANDSTONE:0)
Block(-6,29,-6,SANDSTONE:0)
Block(-6,29,-5,SANDSTONE:0)
Block(-6,29,-4,SANDSTONE:0)
Block(-6,29,-3,SANDSTONE:0)
Block(-6,29,-2,SANDSTONE:0)
Block(-6,29,-1,SANDSTONE:0)
Block(-6,29,0,SANDSTONE:0)
Block(-6,29,1,SANDSTONE:0)
Block(-6,29,2,SANDSTONE:0)
Block(-6,29,3,SANDSTONE:0)
Block(-6,29,4,SANDSTONE:0)
Block(-6,29,5,SANDSTONE:0)
Block(-6,29,6,SANDSTONE:0)
Block(-6,29,7,SANDSTONE:0)
Block(-6,29,8,SANDSTONE:0)
Block(-6,30,-7,SANDSTONE:0)
Block(-6,30,-6,SANDSTONE:0)
Block(-6,30,-5,SANDSTONE:0)
Block(-6,30,-4,SANDSTONE:0)
Block(-6,30,-3,SANDSTONE:0)
Block(-6,30,-2,SANDSTONE:0)
Block(-6,30,-1,SANDSTONE:0)
Block(-6,30,0,SANDSTONE:0)
Block(-6,30,1,SANDSTONE:0)
Block(-6,30,2,SANDSTONE:0)
Block(-6,30,3,SANDSTONE:0)
Block(-6,30,4,SANDSTONE:0)
Block(-6,30,5,SANDSTONE:0)
Block(-6,30,6,SANDSTONE:0)
Block(-6,30,7,SANDSTONE:0)
Block(-6,30,8,SANDSTONE:0)
Block(-6,31,-7,SANDSTONE:0)
Block(-6,31,-6,SANDSTONE:0)
Block(-6,31,-5,SANDSTONE:0)
Block(-6,31,-4,SANDSTONE:0)
Block(-6,31,-3,SANDSTONE:0)
Block(-6,31,-2,SANDSTONE:0)
Block(-6,31,-1,SANDSTONE:0)
Block(-6,31,0,SANDSTONE:0)
Block(-6,31,1,SANDSTONE:0)
Block(-6,31,2,SANDSTONE:0)
Block(-6,31,3,SANDSTONE:0)
Block(-6,31,4,SANDSTONE:0)
Block(-6,31,5,SANDSTONE:0)
Block(-6,31,6,SANDSTONE:0)
Block(-6,31,7,SANDSTONE:0)
Block(-6,31,8,SANDSTONE:0)
Block(-6,32,-7,SANDSTONE:0)
Block(-6,32,-6,SANDSTONE:0)
Block(-6,32,-5,SANDSTONE:0)
Block(-6,32,-4,SANDSTONE:0)
Block(-6,32,-3,SANDSTONE:0)
Block(-6,32,-2,SANDSTONE:0)
Block(-6,32,-1,SANDSTONE:0)
Block(-6,32,0,SANDSTONE:0)
Block(-6,32,1,SANDSTONE:0)
Block(-6,32,2,SANDSTONE:0)
Block(-6,32,3,SANDSTONE:0)
Block(-6,32,4,SANDSTONE:0)
Block(-6,32,5,SANDSTONE:0)
Block(-6,32,6,SANDSTONE:0)
Block(-6,32,7,SANDSTONE:0)
Block(-6,32,8,SANDSTONE:0)
Block(-6,33,-7,SANDSTONE:0)
Block(-6,33,-6,SANDSTONE:0)
Block(-6,33,-5,SANDSTONE:0)
Block(-6,33,-4,SANDSTONE:0)
Block(-6,33,-3,SANDSTONE:0)
Block(-6,33,-2,SANDSTONE:0)
Block(-6,33,-1,SANDSTONE:0)
Block(-6,33,0,SANDSTONE:0)
Block(-6,33,1,SANDSTONE:0)
Block(-6,33,2,SANDSTONE:0)
Block(-6,33,3,SANDSTONE:0)
Block(-6,33,4,SANDSTONE:0)
Block(-6,33,5,SANDSTONE:0)
Block(-6,33,6,SANDSTONE:0)
Block(-6,33,7,SANDSTONE:0)
Block(-6,33,8,SANDSTONE:0)
Block(-6,34,-7,SANDSTONE:0)
Block(-6,34,-6,SANDSTONE:0)
Block(-6,34,-5,SANDSTONE:0)
Block(-6,34,-4,SANDSTONE:0)
Block(-6,34,-3,SANDSTONE:0)
Block(-6,34,-2,SANDSTONE:0)
Block(-6,34,-1,SANDSTONE:0)
Block(-6,34,0,SANDSTONE:0)
Block(-6,34,1,SANDSTONE:0)
Block(-6,34,2,SANDSTONE:0)
Block(-6,34,3,SANDSTONE:0)
Block(-6,34,4,SANDSTONE:0)
Block(-6,34,5,SANDSTONE:0)
Block(-6,34,6,SANDSTONE:0)
Block(-6,34,7,SANDSTONE:0)
Block(-6,34,8,SANDSTONE:0)
Block(-6,35,-7,SANDSTONE:0)
Block(-6,35,-6,SANDSTONE:0)
Block(-6,35,-5,SANDSTONE:0)
Block(-6,35,-4,SANDSTONE:0)
Block(-6,35,-3,SANDSTONE:0)
RandomBlock(-6,35,-2,SAND:0,50,SANDSTONE:0,100)
RandomBlock(-6,35,-1,SAND:0,50,SANDSTONE:0,100)
RandomBlock(-6,35,0,SAND:0,50,SANDSTONE:0,100)
Block(-6,35,1,SANDSTONE:0)
Block(-6,35,2,SANDSTONE:0)
Block(-6,35,3,SANDSTONE:0)
Block(-6,35,4,SANDSTONE:0)
Block(-6,35,5,SANDSTONE:0)
Block(-6,35,6,SANDSTONE:0)
Block(-6,35,7,SANDSTONE:0)
Block(-6,35,8,SANDSTONE:0)
Block(-6,36,-7,SANDSTONE:0)
Block(-6,36,-6,SANDSTONE:0)
Block(-6,36,-5,SANDSTONE:0)
RandomBlock(-6,36,-4,SAND:0,50,SANDSTONE:0,100)
RandomBlock(-6,36,-3,SAND:0,50,SANDSTONE:0,100)
RandomBlock(-6,36,-2,SAND:0,50,SANDSTONE:0,100)
RandomBlock(-6,36,-1,SAND:0,50,SANDSTONE:0,100)
RandomBlock(-6,36,0,SAND:0,50,SANDSTONE:0,100)
RandomBlock(-6,36,1,SAND:0,50,SANDSTONE:0,100)
Block(-6,36,2,SANDSTONE:0)
Block(-6,36,3,SANDSTONE:0)
Block(-6,36,4,SANDSTONE:0)
Block(-6,36,5,SANDSTONE:0)
Block(-6,36,6,SANDSTONE:0)
Block(-6,36,7,SANDSTONE:0)
Block(-6,36,8,SANDSTONE:0)
Block(-6,37,-7,SANDSTONE:0)
Block(-6,37,-6,SANDSTONE:0)
RandomBlock(-6,37,-5,SAND:0,50,SANDSTONE:0,100)
RandomBlock(-6,37,-4,SAND:0,50,SANDSTONE:0,100)
RandomBlock(-6,37,-3,SAND:0,50,SANDSTONE:0,100)
RandomBlock(-6,37,-2,SAND:0,50,SANDSTONE:0,100)
RandomBlock(-6,37,-1,SAND:0,50,SANDSTONE:0,100)
RandomBlock(-6,37,0,SAND:0,50,SANDSTONE:0,100)
RandomBlock(-6,37,1,SAND:0,50,SANDSTONE:0,100)
Block(-6,37,2,SANDSTONE:0)
Block(-6,37,3,SANDSTONE:0)
Block(-6,37,4,SANDSTONE:0)
Block(-6,37,5,SANDSTONE:0)
Block(-6,37,6,SANDSTONE:0)
Block(-6,37,7,SANDSTONE:0)
Block(-6,37,8,SANDSTONE:0)
RandomBlock(-6,38,-7,SAND:0,50,SANDSTONE:0,100)
RandomBlock(-6,38,-6,SAND:0,50,SANDSTONE:0,100)
RandomBlock(-6,38,-5,SAND:0,50,SANDSTONE:0,100)
RandomBlock(-6,38,-4,SAND:0,50,SANDSTONE:0,100)
RandomBlock(-6,38,-3,SAND:0,50,SANDSTONE:0,100)
RandomBlock(-6,38,-2,SAND:0,50,SANDSTONE:0,100)
RandomBlock(-6,38,-1,SAND:0,50,SANDSTONE:0,100)
RandomBlock(-6,38,0,SAND:0,50,SANDSTONE:0,100)
RandomBlock(-6,38,1,SAND:0,50,SANDSTONE:0,100)
Block(-6,38,2,SANDSTONE:0)
Block(-6,38,3,SANDSTONE:0)
Block(-6,38,4,SANDSTONE:0)
Block(-6,38,5,SANDSTONE:0)
Block(-6,38,6,SANDSTONE:0)
Block(-6,38,7,SANDSTONE:0)
Block(-6,38,8,SANDSTONE:0)
RandomBlock(-6,39,-7,SAND:0,50,SANDSTONE:0,100)
RandomBlock(-6,39,-6,SAND:0,50,SANDSTONE:0,100)
RandomBlock(-6,39,-5,SAND:0,50,SANDSTONE:0,100)
RandomBlock(-6,39,-4,SAND:0,50,SANDSTONE:0,100)
RandomBlock(-6,39,-3,SAND:0,50,SANDSTONE:0,100)
RandomBlock(-6,39,1,SAND:0,50,SANDSTONE:0,100)
Block(-6,39,2,SANDSTONE:0)
Block(-6,39,3,SANDSTONE:0)
Block(-6,39,4,SANDSTONE:0)
Block(-6,39,5,SANDSTONE:0)
Block(-6,39,6,SANDSTONE:0)
Block(-6,39,7,SANDSTONE:0)
Block(-6,39,8,SANDSTONE:0)
RandomBlock(-6,40,-7,SAND:0,50,SANDSTONE:0,100)
RandomBlock(-6,40,-6,SAND:0,50,SANDSTONE:0,100)
RandomBlock(-6,40,-5,SAND:0,50,SANDSTONE:0,100)
Block(-6,40,3,SANDSTONE:0)
Block(-6,40,4,SANDSTONE:0)
Block(-6,40,5,SANDSTONE:0)
Block(-6,40,6,SANDSTONE:0)
Block(-6,40,7,SANDSTONE:0)
Block(-6,40,8,SANDSTONE:0)
RandomBlock(-6,41,-7,SAND:0,50,SANDSTONE:0,100)
RandomBlock(-6,41,-6,SAND:0,50,SANDSTONE:0,100)
Block(-6,41,3,SANDSTONE:0)
Block(-6,41,4,SANDSTONE:0)
Block(-6,41,5,SANDSTONE:0)
Block(-6,41,6,SANDSTONE:0)
Block(-6,41,7,SANDSTONE:0)
Block(-6,41,8,SANDSTONE:0)
Block(-6,42,4,SANDSTONE:0)
Block(-6,42,5,SANDSTONE:0)
Block(-6,42,6,SANDSTONE:0)
Block(-6,42,7,SANDSTONE:0)
Block(-6,42,8,SANDSTONE:0)
Block(-6,43,6,SANDSTONE:0)
Block(-5,0,-7,SANDSTONE:0)
Block(-5,0,-6,SANDSTONE:0)
Block(-5,0,-5,SANDSTONE:0)
Block(-5,0,-4,SANDSTONE:0)
Block(-5,0,-3,SANDSTONE:0)
Block(-5,0,-2,SANDSTONE:0)
Block(-5,0,-1,SANDSTONE:0)
Block(-5,0,0,SANDSTONE:0)
Block(-5,0,1,SANDSTONE:0)
Block(-5,0,2,SANDSTONE:0)
Block(-5,0,3,SANDSTONE:0)
Block(-5,0,4,SANDSTONE:0)
Block(-5,0,5,SANDSTONE:0)
Block(-5,0,6,SANDSTONE:0)
Block(-5,0,7,SANDSTONE:0)
Block(-5,0,8,SANDSTONE:0)
Block(-5,1,-7,SANDSTONE:0)
Block(-5,1,-6,SANDSTONE:0)
Block(-5,1,-5,SANDSTONE:0)
Block(-5,1,-4,SANDSTONE:0)
Block(-5,1,-3,SANDSTONE:0)
Block(-5,1,-2,SANDSTONE:0)
Block(-5,1,-1,SANDSTONE:0)
Block(-5,1,0,SANDSTONE:0)
Block(-5,1,1,SANDSTONE:0)
Block(-5,1,2,SANDSTONE:0)
Block(-5,1,3,SANDSTONE:0)
Block(-5,1,4,SANDSTONE:0)
Block(-5,1,5,SANDSTONE:0)
Block(-5,1,6,SANDSTONE:0)
Block(-5,1,7,SANDSTONE:0)
Block(-5,1,8,SANDSTONE:0)
Block(-5,2,-7,SANDSTONE:0)
Block(-5,2,-6,SANDSTONE:0)
Block(-5,2,-5,SANDSTONE:0)
Block(-5,2,-4,SANDSTONE:0)
Block(-5,2,-3,SANDSTONE:0)
Block(-5,2,-2,SANDSTONE:0)
Block(-5,2,-1,SANDSTONE:0)
Block(-5,2,0,SANDSTONE:0)
Block(-5,2,1,SANDSTONE:0)
Block(-5,2,2,SANDSTONE:0)
Block(-5,2,3,SANDSTONE:0)
Block(-5,2,4,SANDSTONE:0)
Block(-5,2,5,SANDSTONE:0)
Block(-5,2,6,SANDSTONE:0)
Block(-5,2,7,SANDSTONE:0)
Block(-5,2,8,SANDSTONE:0)
Block(-5,3,-7,SANDSTONE:0)
Block(-5,3,-6,SANDSTONE:0)
Block(-5,3,-5,SANDSTONE:0)
Block(-5,3,-4,SANDSTONE:0)
Block(-5,3,-3,SANDSTONE:0)
Block(-5,3,-2,SANDSTONE:0)
Block(-5,3,-1,SANDSTONE:0)
Block(-5,3,0,SANDSTONE:0)
Block(-5,3,1,SANDSTONE:0)
Block(-5,3,2,SANDSTONE:0)
Block(-5,3,3,SANDSTONE:0)
Block(-5,3,4,SANDSTONE:0)
Block(-5,3,5,SANDSTONE:0)
Block(-5,3,6,SANDSTONE:0)
Block(-5,3,7,SANDSTONE:0)
Block(-5,3,8,SANDSTONE:0)
Block(-5,4,-7,SANDSTONE:0)
Block(-5,4,-6,SANDSTONE:0)
Block(-5,4,-5,SANDSTONE:0)
Block(-5,4,-4,SANDSTONE:0)
Block(-5,4,-3,SANDSTONE:0)
Block(-5,4,-2,SANDSTONE:0)
Block(-5,4,-1,SANDSTONE:0)
Block(-5,4,0,SANDSTONE:0)
Block(-5,4,1,SANDSTONE:0)
Block(-5,4,2,SANDSTONE:0)
Block(-5,4,3,SANDSTONE:0)
Block(-5,4,4,SANDSTONE:0)
Block(-5,4,5,SANDSTONE:0)
Block(-5,4,6,SANDSTONE:0)
Block(-5,4,7,SANDSTONE:0)
Block(-5,4,8,SANDSTONE:0)
Block(-5,5,-7,SANDSTONE:0)
Block(-5,5,-6,SANDSTONE:0)
Block(-5,5,-5,SANDSTONE:0)
Block(-5,5,-4,SANDSTONE:0)
Block(-5,5,-3,SANDSTONE:0)
Block(-5,5,-2,SANDSTONE:0)
Block(-5,5,-1,SANDSTONE:0)
Block(-5,5,0,SANDSTONE:0)
Block(-5,5,1,SANDSTONE:0)
Block(-5,5,2,SANDSTONE:0)
Block(-5,5,3,SANDSTONE:0)
Block(-5,5,4,SANDSTONE:0)
Block(-5,5,5,SANDSTONE:0)
Block(-5,5,6,SANDSTONE:0)
Block(-5,5,7,SANDSTONE:0)
Block(-5,5,8,SANDSTONE:0)
Block(-5,6,-7,SANDSTONE:0)
Block(-5,6,-6,SANDSTONE:0)
Block(-5,6,-5,SANDSTONE:0)
Block(-5,6,-4,SANDSTONE:0)
Block(-5,6,-3,SANDSTONE:0)
Block(-5,6,-2,SANDSTONE:0)
Block(-5,6,-1,SANDSTONE:0)
Block(-5,6,0,SANDSTONE:0)
Block(-5,6,1,SANDSTONE:0)
Block(-5,6,2,SANDSTONE:0)
Block(-5,6,3,SANDSTONE:0)
Block(-5,6,4,SANDSTONE:0)
Block(-5,6,5,SANDSTONE:0)
Block(-5,6,6,SANDSTONE:0)
Block(-5,6,7,SANDSTONE:0)
Block(-5,6,8,SANDSTONE:0)
Block(-5,7,-7,SANDSTONE:0)
Block(-5,7,-6,SANDSTONE:0)
Block(-5,7,-5,SANDSTONE:0)
Block(-5,7,-4,SANDSTONE:0)
Block(-5,7,-3,SANDSTONE:0)
Block(-5,7,-2,SANDSTONE:0)
Block(-5,7,-1,SANDSTONE:0)
Block(-5,7,0,SANDSTONE:0)
Block(-5,7,1,SANDSTONE:0)
Block(-5,7,2,SANDSTONE:0)
Block(-5,7,3,SANDSTONE:0)
Block(-5,7,4,SANDSTONE:0)
Block(-5,7,5,SANDSTONE:0)
Block(-5,7,6,SANDSTONE:0)
Block(-5,7,7,SANDSTONE:0)
Block(-5,7,8,SANDSTONE:0)
Block(-5,8,-7,SANDSTONE:0)
Block(-5,8,-6,SANDSTONE:0)
Block(-5,8,-5,SANDSTONE:0)
Block(-5,8,-4,SANDSTONE:0)
Block(-5,8,-3,SANDSTONE:0)
Block(-5,8,-2,SANDSTONE:0)
Block(-5,8,-1,SANDSTONE:0)
Block(-5,8,0,SANDSTONE:0)
Block(-5,8,1,SANDSTONE:0)
Block(-5,8,2,SANDSTONE:0)
Block(-5,8,3,SANDSTONE:0)
Block(-5,8,4,SANDSTONE:0)
Block(-5,8,5,SANDSTONE:0)
Block(-5,8,6,SANDSTONE:0)
Block(-5,8,7,SANDSTONE:0)
Block(-5,8,8,SANDSTONE:0)
Block(-5,9,-7,SANDSTONE:0)
Block(-5,9,-6,SANDSTONE:0)
Block(-5,9,-5,SANDSTONE:0)
Block(-5,9,-4,SANDSTONE:0)
Block(-5,9,-3,SANDSTONE:0)
Block(-5,9,-2,SANDSTONE:0)
Block(-5,9,-1,SANDSTONE:0)
Block(-5,9,0,SANDSTONE:0)
Block(-5,9,1,SANDSTONE:0)
Block(-5,9,2,SANDSTONE:0)
Block(-5,9,3,SANDSTONE:0)
Block(-5,9,4,SANDSTONE:0)
Block(-5,9,5,SANDSTONE:0)
Block(-5,9,6,SANDSTONE:0)
Block(-5,9,7,SANDSTONE:0)
Block(-5,9,8,SANDSTONE:0)
Block(-5,10,-7,SANDSTONE:0)
Block(-5,10,-6,SANDSTONE:0)
Block(-5,10,-5,SANDSTONE:0)
Block(-5,10,-4,SANDSTONE:0)
Block(-5,10,-3,SANDSTONE:0)
Block(-5,10,-2,SANDSTONE:0)
Block(-5,10,-1,SANDSTONE:0)
Block(-5,10,0,SANDSTONE:0)
Block(-5,10,1,SANDSTONE:0)
Block(-5,10,2,SANDSTONE:0)
Block(-5,10,3,SANDSTONE:0)
Block(-5,10,4,SANDSTONE:0)
Block(-5,10,5,SANDSTONE:0)
Block(-5,10,6,SANDSTONE:0)
Block(-5,10,7,SANDSTONE:0)
Block(-5,10,8,SANDSTONE:0)
Block(-5,11,-7,SANDSTONE:0)
Block(-5,11,-6,SANDSTONE:0)
Block(-5,11,-5,SANDSTONE:0)
Block(-5,11,-4,SANDSTONE:0)
Block(-5,11,-3,SANDSTONE:0)
Block(-5,11,-2,SANDSTONE:0)
Block(-5,11,-1,SANDSTONE:0)
Block(-5,11,0,SANDSTONE:0)
Block(-5,11,1,SANDSTONE:0)
Block(-5,11,2,SANDSTONE:0)
Block(-5,11,3,SANDSTONE:0)
Block(-5,11,4,SANDSTONE:0)
Block(-5,11,5,SANDSTONE:0)
Block(-5,11,6,SANDSTONE:0)
Block(-5,11,7,SANDSTONE:0)
Block(-5,11,8,SANDSTONE:0)
Block(-5,12,-7,SANDSTONE:0)
Block(-5,12,-6,SANDSTONE:0)
Block(-5,12,-5,SANDSTONE:0)
Block(-5,12,-4,SANDSTONE:0)
Block(-5,12,-3,SANDSTONE:0)
Block(-5,12,-2,SANDSTONE:0)
Block(-5,12,-1,SANDSTONE:0)
Block(-5,12,0,SANDSTONE:0)
Block(-5,12,1,SANDSTONE:0)
Block(-5,12,2,SANDSTONE:0)
Block(-5,12,3,SANDSTONE:0)
Block(-5,12,4,SANDSTONE:0)
Block(-5,12,5,SANDSTONE:0)
Block(-5,12,6,SANDSTONE:0)
Block(-5,12,7,SANDSTONE:0)
Block(-5,12,8,SANDSTONE:0)
Block(-5,13,-7,SANDSTONE:0)
Block(-5,13,-6,SANDSTONE:0)
Block(-5,13,-5,SANDSTONE:0)
Block(-5,13,-4,SANDSTONE:0)
Block(-5,13,-3,SANDSTONE:0)
Block(-5,13,-2,SANDSTONE:0)
Block(-5,13,-1,SANDSTONE:0)
Block(-5,13,0,SANDSTONE:0)
Block(-5,13,1,SANDSTONE:0)
Block(-5,13,2,SANDSTONE:0)
Block(-5,13,3,SANDSTONE:0)
Block(-5,13,4,SANDSTONE:0)
Block(-5,13,5,SANDSTONE:0)
Block(-5,13,6,SANDSTONE:0)
Block(-5,13,7,SANDSTONE:0)
Block(-5,13,8,SANDSTONE:0)
Block(-5,14,-7,SANDSTONE:0)
Block(-5,14,-6,SANDSTONE:0)
Block(-5,14,-5,SANDSTONE:0)
Block(-5,14,-4,SANDSTONE:0)
Block(-5,14,-3,SANDSTONE:0)
Block(-5,14,-2,SANDSTONE:0)
Block(-5,14,-1,SANDSTONE:0)
Block(-5,14,0,SANDSTONE:0)
Block(-5,14,1,SANDSTONE:0)
Block(-5,14,2,SANDSTONE:0)
Block(-5,14,3,SANDSTONE:0)
Block(-5,14,4,SANDSTONE:0)
Block(-5,14,5,SANDSTONE:0)
Block(-5,14,6,SANDSTONE:0)
Block(-5,14,7,SANDSTONE:0)
Block(-5,14,8,SANDSTONE:0)
Block(-5,15,-7,SANDSTONE:0)
Block(-5,15,-6,SANDSTONE:0)
Block(-5,15,-5,SANDSTONE:0)
Block(-5,15,-4,SANDSTONE:0)
Block(-5,15,-3,SANDSTONE:0)
Block(-5,15,-2,SANDSTONE:0)
Block(-5,15,-1,SANDSTONE:0)
Block(-5,15,0,SANDSTONE:0)
Block(-5,15,1,SANDSTONE:0)
Block(-5,15,2,SANDSTONE:0)
Block(-5,15,3,SANDSTONE:0)
Block(-5,15,4,SANDSTONE:0)
Block(-5,15,5,SANDSTONE:0)
Block(-5,15,6,SANDSTONE:0)
Block(-5,15,7,SANDSTONE:0)
Block(-5,15,8,SANDSTONE:0)
Block(-5,16,-7,SANDSTONE:0)
Block(-5,16,-6,SANDSTONE:0)
Block(-5,16,-5,SANDSTONE:0)
Block(-5,16,-4,SANDSTONE:0)
Block(-5,16,-3,SANDSTONE:0)
Block(-5,16,-2,SANDSTONE:0)
Block(-5,16,-1,SANDSTONE:0)
Block(-5,16,0,SANDSTONE:0)
Block(-5,16,1,SANDSTONE:0)
Block(-5,16,2,SANDSTONE:0)
Block(-5,16,3,SANDSTONE:0)
Block(-5,16,4,SANDSTONE:0)
Block(-5,16,5,SANDSTONE:0)
Block(-5,16,6,SANDSTONE:0)
Block(-5,16,7,SANDSTONE:0)
Block(-5,16,8,SANDSTONE:0)
Block(-5,17,-7,SANDSTONE:0)
Block(-5,17,-6,SANDSTONE:0)
Block(-5,17,-5,SANDSTONE:0)
Block(-5,17,-4,SANDSTONE:0)
Block(-5,17,-3,SANDSTONE:0)
Block(-5,17,-2,SANDSTONE:0)
Block(-5,17,-1,SANDSTONE:0)
Block(-5,17,0,SANDSTONE:0)
Block(-5,17,1,SANDSTONE:0)
Block(-5,17,2,SANDSTONE:0)
Block(-5,17,3,SANDSTONE:0)
Block(-5,17,4,SANDSTONE:0)
Block(-5,17,5,SANDSTONE:0)
Block(-5,17,6,SANDSTONE:0)
Block(-5,17,7,SANDSTONE:0)
Block(-5,17,8,SANDSTONE:0)
Block(-5,18,-7,SANDSTONE:0)
Block(-5,18,-6,SANDSTONE:0)
Block(-5,18,-5,SANDSTONE:0)
Block(-5,18,-4,SANDSTONE:0)
Block(-5,18,-3,SANDSTONE:0)
Block(-5,18,-2,SANDSTONE:0)
Block(-5,18,-1,SANDSTONE:0)
Block(-5,18,0,SANDSTONE:0)
Block(-5,18,1,SANDSTONE:0)
Block(-5,18,2,SANDSTONE:0)
Block(-5,18,3,SANDSTONE:0)
Block(-5,18,4,SANDSTONE:0)
Block(-5,18,5,SANDSTONE:0)
Block(-5,18,6,SANDSTONE:0)
Block(-5,18,7,SANDSTONE:0)
Block(-5,18,8,SANDSTONE:0)
Block(-5,19,-7,SANDSTONE:0)
Block(-5,19,-6,SANDSTONE:0)
Block(-5,19,-5,SANDSTONE:0)
Block(-5,19,-4,SANDSTONE:0)
Block(-5,19,-3,SANDSTONE:0)
Block(-5,19,-2,SANDSTONE:0)
Block(-5,19,-1,SANDSTONE:0)
Block(-5,19,0,SANDSTONE:0)
Block(-5,19,1,SANDSTONE:0)
Block(-5,19,2,SANDSTONE:0)
Block(-5,19,3,SANDSTONE:0)
Block(-5,19,4,SANDSTONE:0)
Block(-5,19,5,SANDSTONE:0)
Block(-5,19,6,SANDSTONE:0)
Block(-5,19,7,SANDSTONE:0)
Block(-5,19,8,SANDSTONE:0)
Block(-5,20,-7,SANDSTONE:0)
Block(-5,20,-6,SANDSTONE:0)
Block(-5,20,-5,SANDSTONE:0)
Block(-5,20,-4,SANDSTONE:0)
Block(-5,20,-3,SANDSTONE:0)
Block(-5,20,-2,SANDSTONE:0)
Block(-5,20,-1,SANDSTONE:0)
Block(-5,20,0,SANDSTONE:0)
Block(-5,20,1,SANDSTONE:0)
Block(-5,20,2,SANDSTONE:0)
Block(-5,20,3,SANDSTONE:0)
Block(-5,20,4,SANDSTONE:0)
Block(-5,20,5,SANDSTONE:0)
Block(-5,20,6,SANDSTONE:0)
Block(-5,20,7,SANDSTONE:0)
Block(-5,20,8,SANDSTONE:0)
Block(-5,21,-7,SANDSTONE:0)
Block(-5,21,-6,SANDSTONE:0)
Block(-5,21,-5,SANDSTONE:0)
Block(-5,21,-4,SANDSTONE:0)
Block(-5,21,-3,SANDSTONE:0)
Block(-5,21,-2,SANDSTONE:0)
Block(-5,21,-1,SANDSTONE:0)
Block(-5,21,0,SANDSTONE:0)
Block(-5,21,1,SANDSTONE:0)
Block(-5,21,2,SANDSTONE:0)
Block(-5,21,3,SANDSTONE:0)
Block(-5,21,4,SANDSTONE:0)
Block(-5,21,5,SANDSTONE:0)
Block(-5,21,6,SANDSTONE:0)
Block(-5,21,7,SANDSTONE:0)
Block(-5,21,8,SANDSTONE:0)
Block(-5,22,-7,SANDSTONE:0)
Block(-5,22,-6,SANDSTONE:0)
Block(-5,22,-5,SANDSTONE:0)
Block(-5,22,-4,SANDSTONE:0)
Block(-5,22,-3,SANDSTONE:0)
Block(-5,22,-2,SANDSTONE:0)
Block(-5,22,-1,SANDSTONE:0)
Block(-5,22,0,SANDSTONE:0)
Block(-5,22,1,SANDSTONE:0)
Block(-5,22,2,SANDSTONE:0)
Block(-5,22,3,SANDSTONE:0)
Block(-5,22,4,SANDSTONE:0)
Block(-5,22,5,SANDSTONE:0)
Block(-5,22,6,SANDSTONE:0)
Block(-5,22,7,SANDSTONE:0)
Block(-5,22,8,SANDSTONE:0)
Block(-5,23,-7,SANDSTONE:0)
Block(-5,23,-6,SANDSTONE:0)
Block(-5,23,-5,SANDSTONE:0)
Block(-5,23,-4,SANDSTONE:0)
Block(-5,23,-3,SANDSTONE:0)
Block(-5,23,-2,SANDSTONE:0)
Block(-5,23,-1,SANDSTONE:0)
Block(-5,23,0,SANDSTONE:0)
Block(-5,23,1,SANDSTONE:0)
Block(-5,23,2,SANDSTONE:0)
Block(-5,23,3,SANDSTONE:0)
Block(-5,23,4,SANDSTONE:0)
Block(-5,23,5,SANDSTONE:0)
Block(-5,23,6,SANDSTONE:0)
Block(-5,23,7,SANDSTONE:0)
Block(-5,23,8,SANDSTONE:0)
Block(-5,24,-7,SANDSTONE:0)
Block(-5,24,-6,SANDSTONE:0)
Block(-5,24,-5,SANDSTONE:0)
Block(-5,24,-4,SANDSTONE:0)
Block(-5,24,-3,SANDSTONE:0)
Block(-5,24,-2,SANDSTONE:0)
Block(-5,24,-1,SANDSTONE:0)
Block(-5,24,0,SANDSTONE:0)
Block(-5,24,1,SANDSTONE:0)
Block(-5,24,2,SANDSTONE:0)
Block(-5,24,3,SANDSTONE:0)
Block(-5,24,4,SANDSTONE:0)
Block(-5,24,5,SANDSTONE:0)
Block(-5,24,6,SANDSTONE:0)
Block(-5,24,7,SANDSTONE:0)
Block(-5,24,8,SANDSTONE:0)
Block(-5,25,-7,SANDSTONE:0)
Block(-5,25,-6,SANDSTONE:0)
Block(-5,25,-5,SANDSTONE:0)
Block(-5,25,-4,SANDSTONE:0)
Block(-5,25,-3,SANDSTONE:0)
Block(-5,25,-2,SANDSTONE:0)
Block(-5,25,-1,SANDSTONE:0)
Block(-5,25,0,SANDSTONE:0)
Block(-5,25,1,SANDSTONE:0)
Block(-5,25,2,SANDSTONE:0)
Block(-5,25,3,SANDSTONE:0)
Block(-5,25,4,SANDSTONE:0)
Block(-5,25,5,SANDSTONE:0)
Block(-5,25,6,SANDSTONE:0)
Block(-5,25,7,SANDSTONE:0)
Block(-5,25,8,SANDSTONE:0)
Block(-5,26,-7,SANDSTONE:0)
Block(-5,26,-6,SANDSTONE:0)
Block(-5,26,-5,SANDSTONE:0)
Block(-5,26,-4,SANDSTONE:0)
Block(-5,26,-3,SANDSTONE:0)
Block(-5,26,-2,SANDSTONE:0)
Block(-5,26,-1,SANDSTONE:0)
Block(-5,26,0,SANDSTONE:0)
Block(-5,26,1,SANDSTONE:0)
Block(-5,26,2,SANDSTONE:0)
Block(-5,26,3,SANDSTONE:0)
Block(-5,26,4,SANDSTONE:0)
Block(-5,26,5,SANDSTONE:0)
Block(-5,26,6,SANDSTONE:0)
Block(-5,26,7,SANDSTONE:0)
Block(-5,26,8,SANDSTONE:0)
Block(-5,27,-7,SANDSTONE:0)
Block(-5,27,-6,SANDSTONE:0)
Block(-5,27,-5,SANDSTONE:0)
Block(-5,27,-4,SANDSTONE:0)
Block(-5,27,-3,SANDSTONE:0)
Block(-5,27,-2,SANDSTONE:0)
Block(-5,27,-1,SANDSTONE:0)
Block(-5,27,0,SANDSTONE:0)
Block(-5,27,1,SANDSTONE:0)
Block(-5,27,2,SANDSTONE:0)
Block(-5,27,3,SANDSTONE:0)
Block(-5,27,4,SANDSTONE:0)
Block(-5,27,5,SANDSTONE:0)
Block(-5,27,6,SANDSTONE:0)
Block(-5,27,7,SANDSTONE:0)
Block(-5,27,8,SANDSTONE:0)
Block(-5,28,-7,SANDSTONE:0)
Block(-5,28,-6,SANDSTONE:0)
Block(-5,28,-5,SANDSTONE:0)
Block(-5,28,-4,SANDSTONE:0)
Block(-5,28,-3,SANDSTONE:0)
Block(-5,28,-2,SANDSTONE:0)
Block(-5,28,-1,SANDSTONE:0)
Block(-5,28,0,SANDSTONE:0)
Block(-5,28,1,SANDSTONE:0)
Block(-5,28,2,SANDSTONE:0)
Block(-5,28,3,SANDSTONE:0)
Block(-5,28,4,SANDSTONE:0)
Block(-5,28,5,SANDSTONE:0)
Block(-5,28,6,SANDSTONE:0)
Block(-5,28,7,SANDSTONE:0)
Block(-5,28,8,SANDSTONE:0)
Block(-5,29,-7,SANDSTONE:0)
Block(-5,29,-6,SANDSTONE:0)
Block(-5,29,-5,SANDSTONE:0)
Block(-5,29,-4,SANDSTONE:0)
Block(-5,29,-3,SANDSTONE:0)
Block(-5,29,-2,SANDSTONE:0)
Block(-5,29,-1,SANDSTONE:0)
Block(-5,29,0,SANDSTONE:0)
Block(-5,29,1,SANDSTONE:0)
Block(-5,29,2,SANDSTONE:0)
Block(-5,29,3,SANDSTONE:0)
Block(-5,29,4,SANDSTONE:0)
Block(-5,29,5,SANDSTONE:0)
Block(-5,29,6,SANDSTONE:0)
Block(-5,29,7,SANDSTONE:0)
Block(-5,29,8,SANDSTONE:0)
Block(-5,30,-7,SANDSTONE:0)
Block(-5,30,-6,SANDSTONE:0)
Block(-5,30,-5,SANDSTONE:0)
Block(-5,30,-4,SANDSTONE:0)
Block(-5,30,-3,SANDSTONE:0)
Block(-5,30,-2,SANDSTONE:0)
Block(-5,30,-1,SANDSTONE:0)
Block(-5,30,0,SANDSTONE:0)
Block(-5,30,1,SANDSTONE:0)
Block(-5,30,2,SANDSTONE:0)
Block(-5,30,3,SANDSTONE:0)
Block(-5,30,4,SANDSTONE:0)
Block(-5,30,5,SANDSTONE:0)
Block(-5,30,6,SANDSTONE:0)
Block(-5,30,7,SANDSTONE:0)
Block(-5,30,8,SANDSTONE:0)
Block(-5,31,-7,SANDSTONE:0)
Block(-5,31,-6,SANDSTONE:0)
Block(-5,31,-5,SANDSTONE:0)
Block(-5,31,-4,SANDSTONE:0)
Block(-5,31,-3,SANDSTONE:0)
Block(-5,31,-2,SANDSTONE:0)
Block(-5,31,-1,SANDSTONE:0)
Block(-5,31,0,SANDSTONE:0)
Block(-5,31,1,SANDSTONE:0)
Block(-5,31,2,SANDSTONE:0)
Block(-5,31,3,SANDSTONE:0)
Block(-5,31,4,SANDSTONE:0)
Block(-5,31,5,SANDSTONE:0)
Block(-5,31,6,SANDSTONE:0)
Block(-5,31,7,SANDSTONE:0)
Block(-5,31,8,SANDSTONE:0)
Block(-5,32,-7,SANDSTONE:0)
Block(-5,32,-6,SANDSTONE:0)
Block(-5,32,-5,SANDSTONE:0)
Block(-5,32,-4,SANDSTONE:0)
Block(-5,32,-3,SANDSTONE:0)
Block(-5,32,-2,SANDSTONE:0)
Block(-5,32,-1,SANDSTONE:0)
Block(-5,32,0,SANDSTONE:0)
Block(-5,32,1,SANDSTONE:0)
Block(-5,32,2,SANDSTONE:0)
Block(-5,32,3,SANDSTONE:0)
Block(-5,32,4,SANDSTONE:0)
Block(-5,32,5,SANDSTONE:0)
Block(-5,32,6,SANDSTONE:0)
Block(-5,32,7,SANDSTONE:0)
Block(-5,32,8,SANDSTONE:0)
Block(-5,33,-7,SANDSTONE:0)
Block(-5,33,-6,SANDSTONE:0)
Block(-5,33,-5,SANDSTONE:0)
Block(-5,33,-4,SANDSTONE:0)
Block(-5,33,-3,SANDSTONE:0)
Block(-5,33,-2,SANDSTONE:0)
Block(-5,33,-1,SANDSTONE:0)
Block(-5,33,0,SANDSTONE:0)
Block(-5,33,1,SANDSTONE:0)
Block(-5,33,2,SANDSTONE:0)
Block(-5,33,3,SANDSTONE:0)
Block(-5,33,4,SANDSTONE:0)
Block(-5,33,5,SANDSTONE:0)
Block(-5,33,6,SANDSTONE:0)
Block(-5,33,7,SANDSTONE:0)
Block(-5,33,8,SANDSTONE:0)
Block(-5,34,-7,SANDSTONE:0)
Block(-5,34,-6,SANDSTONE:0)
Block(-5,34,-5,SANDSTONE:0)
Block(-5,34,-4,SANDSTONE:0)
Block(-5,34,-3,SANDSTONE:0)
Block(-5,34,-2,SANDSTONE:0)
Block(-5,34,-1,SANDSTONE:0)
Block(-5,34,0,SANDSTONE:0)
Block(-5,34,1,SANDSTONE:0)
Block(-5,34,2,SANDSTONE:0)
Block(-5,34,3,SANDSTONE:0)
Block(-5,34,4,SANDSTONE:0)
Block(-5,34,5,SANDSTONE:0)
Block(-5,34,6,SANDSTONE:0)
Block(-5,34,7,SANDSTONE:0)
Block(-5,34,8,SANDSTONE:0)
Block(-5,35,-7,SANDSTONE:0)
Block(-5,35,-6,SANDSTONE:0)
Block(-5,35,-5,SANDSTONE:0)
Block(-5,35,-4,SANDSTONE:0)
Block(-5,35,-3,SANDSTONE:0)
RandomBlock(-5,35,-2,SAND:0,50,SANDSTONE:0,100)
Block(-5,35,-1,SANDSTONE:0)
Block(-5,35,0,SANDSTONE:0)
Block(-5,35,1,SANDSTONE:0)
Block(-5,35,2,SANDSTONE:0)
Block(-5,35,3,SANDSTONE:0)
Block(-5,35,4,SANDSTONE:0)
Block(-5,35,5,SANDSTONE:0)
Block(-5,35,6,SANDSTONE:0)
Block(-5,35,7,SANDSTONE:0)
Block(-5,35,8,SANDSTONE:0)
Block(-5,36,-7,SANDSTONE:0)
Block(-5,36,-6,SANDSTONE:0)
Block(-5,36,-5,SANDSTONE:0)
Block(-5,36,-4,SANDSTONE:0)
RandomBlock(-5,36,-3,SAND:0,50,SANDSTONE:0,100)
RandomBlock(-5,36,-2,SAND:0,50,SANDSTONE:0,100)
RandomBlock(-5,36,-1,SAND:0,50,SANDSTONE:0,100)
RandomBlock(-5,36,0,SAND:0,50,SANDSTONE:0,100)
Block(-5,36,1,SANDSTONE:0)
Block(-5,36,2,SANDSTONE:0)
Block(-5,36,3,SANDSTONE:0)
Block(-5,36,4,SANDSTONE:0)
Block(-5,36,5,SANDSTONE:0)
Block(-5,36,6,SANDSTONE:0)
Block(-5,36,7,SANDSTONE:0)
Block(-5,36,8,SANDSTONE:0)
Block(-5,37,-7,SANDSTONE:0)
Block(-5,37,-6,SANDSTONE:0)
Block(-5,37,-5,SANDSTONE:0)
RandomBlock(-5,37,-4,SAND:0,50,SANDSTONE:0,100)
RandomBlock(-5,37,-3,SAND:0,50,SANDSTONE:0,100)
RandomBlock(-5,37,-2,SAND:0,50,SANDSTONE:0,100)
RandomBlock(-5,37,-1,SAND:0,50,SANDSTONE:0,100)
RandomBlock(-5,37,0,SAND:0,50,SANDSTONE:0,100)
Block(-5,37,1,SANDSTONE:0)
Block(-5,37,2,SANDSTONE:0)
Block(-5,37,3,SANDSTONE:0)
Block(-5,37,4,SANDSTONE:0)
Block(-5,37,5,SANDSTONE:0)
Block(-5,37,6,SANDSTONE:0)
Block(-5,37,7,SANDSTONE:0)
Block(-5,37,8,SANDSTONE:0)
Block(-5,38,-7,SANDSTONE:0)
RandomBlock(-5,38,-6,SAND:0,50,SANDSTONE:0,100)
RandomBlock(-5,38,-5,SAND:0,50,SANDSTONE:0,100)
RandomBlock(-5,38,-4,SAND:0,50,SANDSTONE:0,100)
RandomBlock(-5,38,-3,SAND:0,50,SANDSTONE:0,100)
RandomBlock(-5,38,-2,SAND:0,50,SANDSTONE:0,100)
RandomBlock(-5,38,-1,SAND:0,50,SANDSTONE:0,100)
RandomBlock(-5,38,0,SAND:0,50,SANDSTONE:0,100)
Block(-5,38,1,SANDSTONE:0)
Block(-5,38,2,SANDSTONE:0)
Block(-5,38,3,SANDSTONE:0)
Block(-5,38,4,SANDSTONE:0)
Block(-5,38,5,SANDSTONE:0)
Block(-5,38,6,SANDSTONE:0)
Block(-5,38,7,SANDSTONE:0)
Block(-5,38,8,SANDSTONE:0)
RandomBlock(-5,39,-7,SAND:0,50,SANDSTONE:0,100)
RandomBlock(-5,39,-6,SAND:0,50,SANDSTONE:0,100)
RandomBlock(-5,39,-5,SAND:0,50,SANDSTONE:0,100)
RandomBlock(-5,39,-4,SAND:0,50,SANDSTONE:0,100)
RandomBlock(-5,39,-3,SAND:0,50,SANDSTONE:0,100)
RandomBlock(-5,39,-1,SAND:0,50,SANDSTONE:0,100)
RandomBlock(-5,39,0,SAND:0,50,SANDSTONE:0,100)
Block(-5,39,1,SANDSTONE:0)
Block(-5,39,2,SANDSTONE:0)
Block(-5,39,3,SANDSTONE:0)
Block(-5,39,4,SANDSTONE:0)
Block(-5,39,5,SANDSTONE:0)
Block(-5,39,6,SANDSTONE:0)
Block(-5,39,7,SANDSTONE:0)
Block(-5,39,8,SANDSTONE:0)
RandomBlock(-5,40,-7,SAND:0,50,SANDSTONE:0,100)
RandomBlock(-5,40,-6,SAND:0,50,SANDSTONE:0,100)
RandomBlock(-5,40,-5,SAND:0,50,SANDSTONE:0,100)
RandomBlock(-5,40,-4,SAND:0,50,SANDSTONE:0,100)
Block(-5,40,2,SANDSTONE:0)
Block(-5,40,3,SANDSTONE:0)
Block(-5,40,4,SANDSTONE:0)
Block(-5,40,5,SANDSTONE:0)
Block(-5,40,6,SANDSTONE:0)
Block(-5,40,7,SANDSTONE:0)
Block(-5,40,8,SANDSTONE:0)
RandomBlock(-5,41,-7,SAND:0,50,SANDSTONE:0,100)
RandomBlock(-5,41,-6,SAND:0,50,SANDSTONE:0,100)
RandomBlock(-5,41,-5,SAND:0,50,SANDSTONE:0,100)
Block(-5,41,2,SANDSTONE:0)
Block(-5,41,3,SANDSTONE:0)
Block(-5,41,4,SANDSTONE:0)
Block(-5,41,5,SANDSTONE:0)
Block(-5,41,6,SANDSTONE:0)
Block(-5,41,7,SANDSTONE:0)
Block(-5,41,8,SANDSTONE:0)
RandomBlock(-5,42,-7,SAND:0,50,SANDSTONE:0,100)
Block(-5,42,3,SANDSTONE:0)
Block(-5,42,4,SANDSTONE:0)
Block(-5,42,5,SANDSTONE:0)
Block(-5,42,6,SANDSTONE:0)
Block(-5,42,7,SANDSTONE:0)
Block(-5,42,8,SANDSTONE:0)
Block(-5,43,3,SANDSTONE:0)
Block(-5,43,5,SANDSTONE:0)
Block(-5,43,6,SANDSTONE:0)
Block(-5,43,7,SANDSTONE:0)
Block(-5,43,8,SANDSTONE:0)
Block(-4,0,-7,SANDSTONE:0)
Block(-4,0,-6,SANDSTONE:0)
Block(-4,0,-5,SANDSTONE:0)
Block(-4,0,-4,SANDSTONE:0)
Block(-4,0,-3,SANDSTONE:0)
Block(-4,0,-2,SANDSTONE:0)
Block(-4,0,-1,SANDSTONE:0)
Block(-4,0,0,SANDSTONE:0)
Block(-4,0,1,SANDSTONE:0)
Block(-4,0,2,SANDSTONE:0)
Block(-4,0,3,SANDSTONE:0)
Block(-4,0,4,SANDSTONE:0)
Block(-4,0,5,SANDSTONE:0)
Block(-4,0,6,SANDSTONE:0)
Block(-4,0,7,SANDSTONE:0)
Block(-4,0,8,SANDSTONE:0)
Block(-4,1,-7,SANDSTONE:0)
Block(-4,1,-6,SANDSTONE:0)
Block(-4,1,-5,SANDSTONE:0)
Block(-4,1,-4,SANDSTONE:0)
Block(-4,1,-3,SANDSTONE:0)
Block(-4,1,-2,SANDSTONE:0)
Block(-4,1,-1,SANDSTONE:0)
Block(-4,1,0,SANDSTONE:0)
Block(-4,1,1,SANDSTONE:0)
Block(-4,1,2,SANDSTONE:0)
Block(-4,1,3,SANDSTONE:0)
Block(-4,1,4,SANDSTONE:0)
Block(-4,1,5,SANDSTONE:0)
Block(-4,1,6,SANDSTONE:0)
Block(-4,1,7,SANDSTONE:0)
Block(-4,1,8,SANDSTONE:0)
Block(-4,2,-7,SANDSTONE:0)
Block(-4,2,-6,SANDSTONE:0)
Block(-4,2,-5,SANDSTONE:0)
Block(-4,2,-4,SANDSTONE:0)
Block(-4,2,-3,SANDSTONE:0)
Block(-4,2,-2,SANDSTONE:0)
Block(-4,2,-1,SANDSTONE:0)
Block(-4,2,0,SANDSTONE:0)
Block(-4,2,1,SANDSTONE:0)
Block(-4,2,2,SANDSTONE:0)
Block(-4,2,3,SANDSTONE:0)
Block(-4,2,4,SANDSTONE:0)
Block(-4,2,5,SANDSTONE:0)
Block(-4,2,6,SANDSTONE:0)
Block(-4,2,7,SANDSTONE:0)
Block(-4,2,8,SANDSTONE:0)
Block(-4,3,-7,SANDSTONE:0)
Block(-4,3,-6,SANDSTONE:0)
Block(-4,3,-5,SANDSTONE:0)
Block(-4,3,-4,SANDSTONE:0)
Block(-4,3,-3,SANDSTONE:0)
Block(-4,3,-2,SANDSTONE:0)
Block(-4,3,-1,SANDSTONE:0)
Block(-4,3,0,SANDSTONE:0)
Block(-4,3,1,SANDSTONE:0)
Block(-4,3,2,SANDSTONE:0)
Block(-4,3,3,SANDSTONE:0)
Block(-4,3,4,SANDSTONE:0)
Block(-4,3,5,SANDSTONE:0)
Block(-4,3,6,SANDSTONE:0)
Block(-4,3,7,SANDSTONE:0)
Block(-4,3,8,SANDSTONE:0)
Block(-4,4,-7,SANDSTONE:0)
Block(-4,4,-6,SANDSTONE:0)
Block(-4,4,-5,SANDSTONE:0)
Block(-4,4,-4,SANDSTONE:0)
Block(-4,4,-3,SANDSTONE:0)
Block(-4,4,-2,SANDSTONE:0)
Block(-4,4,-1,SANDSTONE:0)
Block(-4,4,0,SANDSTONE:0)
Block(-4,4,1,SANDSTONE:0)
Block(-4,4,2,SANDSTONE:0)
Block(-4,4,3,SANDSTONE:0)
Block(-4,4,4,SANDSTONE:0)
Block(-4,4,5,SANDSTONE:0)
Block(-4,4,6,SANDSTONE:0)
Block(-4,4,7,SANDSTONE:0)
Block(-4,4,8,SANDSTONE:0)
Block(-4,5,-7,SANDSTONE:0)
Block(-4,5,-6,SANDSTONE:0)
Block(-4,5,-5,SANDSTONE:0)
Block(-4,5,-4,SANDSTONE:0)
Block(-4,5,-3,SANDSTONE:0)
Block(-4,5,-2,SANDSTONE:0)
Block(-4,5,-1,SANDSTONE:0)
Block(-4,5,0,SANDSTONE:0)
Block(-4,5,1,SANDSTONE:0)
Block(-4,5,2,SANDSTONE:0)
Block(-4,5,3,SANDSTONE:0)
Block(-4,5,4,SANDSTONE:0)
Block(-4,5,5,SANDSTONE:0)
Block(-4,5,6,SANDSTONE:0)
Block(-4,5,7,SANDSTONE:0)
Block(-4,5,8,SANDSTONE:0)
Block(-4,6,-7,SANDSTONE:0)
Block(-4,6,-6,SANDSTONE:0)
Block(-4,6,-5,SANDSTONE:0)
Block(-4,6,-4,SANDSTONE:0)
Block(-4,6,-3,SANDSTONE:0)
Block(-4,6,-2,SANDSTONE:0)
Block(-4,6,-1,SANDSTONE:0)
Block(-4,6,0,SANDSTONE:0)
Block(-4,6,1,SANDSTONE:0)
Block(-4,6,2,SANDSTONE:0)
Block(-4,6,3,SANDSTONE:0)
Block(-4,6,4,SANDSTONE:0)
Block(-4,6,5,SANDSTONE:0)
Block(-4,6,6,SANDSTONE:0)
Block(-4,6,7,SANDSTONE:0)
Block(-4,6,8,SANDSTONE:0)
Block(-4,7,-7,SANDSTONE:0)
Block(-4,7,-6,SANDSTONE:0)
Block(-4,7,-5,SANDSTONE:0)
Block(-4,7,-4,SANDSTONE:0)
Block(-4,7,-3,SANDSTONE:0)
Block(-4,7,-2,SANDSTONE:0)
Block(-4,7,-1,SANDSTONE:0)
Block(-4,7,0,SANDSTONE:0)
Block(-4,7,1,SANDSTONE:0)
Block(-4,7,2,SANDSTONE:0)
Block(-4,7,3,SANDSTONE:0)
Block(-4,7,4,SANDSTONE:0)
Block(-4,7,5,SANDSTONE:0)
Block(-4,7,6,SANDSTONE:0)
Block(-4,7,7,SANDSTONE:0)
Block(-4,7,8,SANDSTONE:0)
Block(-4,8,-7,SANDSTONE:0)
Block(-4,8,-6,SANDSTONE:0)
Block(-4,8,-5,SANDSTONE:0)
Block(-4,8,-4,SANDSTONE:0)
Block(-4,8,-3,SANDSTONE:0)
Block(-4,8,-2,SANDSTONE:0)
Block(-4,8,-1,SANDSTONE:0)
Block(-4,8,0,SANDSTONE:0)
Block(-4,8,1,SANDSTONE:0)
Block(-4,8,2,SANDSTONE:0)
Block(-4,8,3,SANDSTONE:0)
Block(-4,8,4,SANDSTONE:0)
Block(-4,8,5,SANDSTONE:0)
Block(-4,8,6,SANDSTONE:0)
Block(-4,8,7,SANDSTONE:0)
Block(-4,8,8,SANDSTONE:0)
Block(-4,9,-7,SANDSTONE:0)
Block(-4,9,-6,SANDSTONE:0)
Block(-4,9,-5,SANDSTONE:0)
Block(-4,9,-4,SANDSTONE:0)
Block(-4,9,-3,SANDSTONE:0)
Block(-4,9,-2,SANDSTONE:0)
Block(-4,9,-1,SANDSTONE:0)
Block(-4,9,0,SANDSTONE:0)
Block(-4,9,1,SANDSTONE:0)
Block(-4,9,2,SANDSTONE:0)
Block(-4,9,3,SANDSTONE:0)
Block(-4,9,4,SANDSTONE:0)
Block(-4,9,5,SANDSTONE:0)
Block(-4,9,6,SANDSTONE:0)
Block(-4,9,7,SANDSTONE:0)
Block(-4,9,8,SANDSTONE:0)
Block(-4,10,-7,SANDSTONE:0)
Block(-4,10,-6,SANDSTONE:0)
Block(-4,10,-5,SANDSTONE:0)
Block(-4,10,-4,SANDSTONE:0)
Block(-4,10,-3,SANDSTONE:0)
Block(-4,10,-2,SANDSTONE:0)
Block(-4,10,-1,SANDSTONE:0)
Block(-4,10,0,SANDSTONE:0)
Block(-4,10,1,SANDSTONE:0)
Block(-4,10,2,SANDSTONE:0)
Block(-4,10,3,SANDSTONE:0)
Block(-4,10,4,SANDSTONE:0)
Block(-4,10,5,SANDSTONE:0)
Block(-4,10,6,SANDSTONE:0)
Block(-4,10,7,SANDSTONE:0)
Block(-4,10,8,SANDSTONE:0)
Block(-4,11,-7,SANDSTONE:0)
Block(-4,11,-6,SANDSTONE:0)
Block(-4,11,-5,SANDSTONE:0)
Block(-4,11,-4,SANDSTONE:0)
Block(-4,11,-3,SANDSTONE:0)
Block(-4,11,-2,SANDSTONE:0)
Block(-4,11,-1,SANDSTONE:0)
Block(-4,11,0,SANDSTONE:0)
Block(-4,11,1,SANDSTONE:0)
Block(-4,11,2,SANDSTONE:0)
Block(-4,11,3,SANDSTONE:0)
Block(-4,11,4,SANDSTONE:0)
Block(-4,11,5,SANDSTONE:0)
Block(-4,11,6,SANDSTONE:0)
Block(-4,11,7,SANDSTONE:0)
Block(-4,11,8,SANDSTONE:0)
Block(-4,12,-7,SANDSTONE:0)
Block(-4,12,-6,SANDSTONE:0)
Block(-4,12,-5,SANDSTONE:0)
Block(-4,12,-4,SANDSTONE:0)
Block(-4,12,-3,SANDSTONE:0)
Block(-4,12,-2,SANDSTONE:0)
Block(-4,12,-1,SANDSTONE:0)
Block(-4,12,0,SANDSTONE:0)
Block(-4,12,1,SANDSTONE:0)
Block(-4,12,2,SANDSTONE:0)
Block(-4,12,3,SANDSTONE:0)
Block(-4,12,4,SANDSTONE:0)
Block(-4,12,5,SANDSTONE:0)
Block(-4,12,6,SANDSTONE:0)
Block(-4,12,7,SANDSTONE:0)
Block(-4,12,8,SANDSTONE:0)
Block(-4,13,-7,SANDSTONE:0)
Block(-4,13,-6,SANDSTONE:0)
Block(-4,13,-5,SANDSTONE:0)
Block(-4,13,-4,SANDSTONE:0)
Block(-4,13,-3,SANDSTONE:0)
Block(-4,13,-2,SANDSTONE:0)
Block(-4,13,-1,SANDSTONE:0)
Block(-4,13,0,SANDSTONE:0)
Block(-4,13,1,SANDSTONE:0)
Block(-4,13,2,SANDSTONE:0)
Block(-4,13,3,SANDSTONE:0)
Block(-4,13,4,SANDSTONE:0)
Block(-4,13,5,SANDSTONE:0)
Block(-4,13,6,SANDSTONE:0)
Block(-4,13,7,SANDSTONE:0)
Block(-4,13,8,SANDSTONE:0)
Block(-4,14,-7,SANDSTONE:0)
Block(-4,14,-6,SANDSTONE:0)
Block(-4,14,-5,SANDSTONE:0)
Block(-4,14,-4,SANDSTONE:0)
Block(-4,14,-3,SANDSTONE:0)
Block(-4,14,-2,SANDSTONE:0)
Block(-4,14,-1,SANDSTONE:0)
Block(-4,14,0,SANDSTONE:0)
Block(-4,14,1,SANDSTONE:0)
Block(-4,14,2,SANDSTONE:0)
Block(-4,14,3,SANDSTONE:0)
Block(-4,14,4,SANDSTONE:0)
Block(-4,14,5,SANDSTONE:0)
Block(-4,14,6,SANDSTONE:0)
Block(-4,14,7,SANDSTONE:0)
Block(-4,14,8,SANDSTONE:0)
Block(-4,15,-7,SANDSTONE:0)
Block(-4,15,-6,SANDSTONE:0)
Block(-4,15,-5,SANDSTONE:0)
Block(-4,15,-4,SANDSTONE:0)
Block(-4,15,-3,SANDSTONE:0)
Block(-4,15,-2,SANDSTONE:0)
Block(-4,15,-1,SANDSTONE:0)
Block(-4,15,0,SANDSTONE:0)
Block(-4,15,1,SANDSTONE:0)
Block(-4,15,2,SANDSTONE:0)
Block(-4,15,3,SANDSTONE:0)
Block(-4,15,4,SANDSTONE:0)
Block(-4,15,5,SANDSTONE:0)
Block(-4,15,6,SANDSTONE:0)
Block(-4,15,7,SANDSTONE:0)
Block(-4,15,8,SANDSTONE:0)
Block(-4,16,-7,SANDSTONE:0)
Block(-4,16,-6,SANDSTONE:0)
Block(-4,16,-5,SANDSTONE:0)
Block(-4,16,-4,SANDSTONE:0)
Block(-4,16,-3,SANDSTONE:0)
Block(-4,16,-2,SANDSTONE:0)
Block(-4,16,-1,SANDSTONE:0)
Block(-4,16,0,SANDSTONE:0)
Block(-4,16,1,SANDSTONE:0)
Block(-4,16,2,SANDSTONE:0)
Block(-4,16,3,SANDSTONE:0)
Block(-4,16,4,SANDSTONE:0)
Block(-4,16,5,SANDSTONE:0)
Block(-4,16,6,SANDSTONE:0)
Block(-4,16,7,SANDSTONE:0)
Block(-4,16,8,SANDSTONE:0)
Block(-4,17,-7,SANDSTONE:0)
Block(-4,17,-6,SANDSTONE:0)
Block(-4,17,-5,SANDSTONE:0)
Block(-4,17,-4,SANDSTONE:0)
Block(-4,17,-3,SANDSTONE:0)
Block(-4,17,-2,SANDSTONE:0)
Block(-4,17,-1,SANDSTONE:0)
Block(-4,17,0,SANDSTONE:0)
Block(-4,17,1,SANDSTONE:0)
Block(-4,17,2,SANDSTONE:0)
Block(-4,17,3,SANDSTONE:0)
Block(-4,17,4,SANDSTONE:0)
Block(-4,17,5,SANDSTONE:0)
Block(-4,17,6,SANDSTONE:0)
Block(-4,17,7,SANDSTONE:0)
Block(-4,17,8,SANDSTONE:0)
Block(-4,18,-7,SANDSTONE:0)
Block(-4,18,-6,SANDSTONE:0)
Block(-4,18,-5,SANDSTONE:0)
Block(-4,18,-4,SANDSTONE:0)
Block(-4,18,-3,SANDSTONE:0)
Block(-4,18,-2,SANDSTONE:0)
Block(-4,18,-1,SANDSTONE:0)
Block(-4,18,0,SANDSTONE:0)
Block(-4,18,1,SANDSTONE:0)
Block(-4,18,2,SANDSTONE:0)
Block(-4,18,3,SANDSTONE:0)
Block(-4,18,4,SANDSTONE:0)
Block(-4,18,5,SANDSTONE:0)
Block(-4,18,6,SANDSTONE:0)
Block(-4,18,7,SANDSTONE:0)
Block(-4,18,8,SANDSTONE:0)
Block(-4,19,-7,SANDSTONE:0)
Block(-4,19,-6,SANDSTONE:0)
Block(-4,19,-5,SANDSTONE:0)
Block(-4,19,-4,SANDSTONE:0)
Block(-4,19,-3,SANDSTONE:0)
Block(-4,19,-2,SANDSTONE:0)
Block(-4,19,-1,SANDSTONE:0)
Block(-4,19,0,SANDSTONE:0)
Block(-4,19,1,SANDSTONE:0)
Block(-4,19,2,SANDSTONE:0)
Block(-4,19,3,SANDSTONE:0)
Block(-4,19,4,SANDSTONE:0)
Block(-4,19,5,SANDSTONE:0)
Block(-4,19,6,SANDSTONE:0)
Block(-4,19,7,SANDSTONE:0)
Block(-4,19,8,SANDSTONE:0)
Block(-4,20,-7,SANDSTONE:0)
Block(-4,20,-6,SANDSTONE:0)
Block(-4,20,-5,SANDSTONE:0)
Block(-4,20,-4,SANDSTONE:0)
Block(-4,20,-3,SANDSTONE:0)
Block(-4,20,-2,SANDSTONE:0)
Block(-4,20,-1,SANDSTONE:0)
Block(-4,20,0,SANDSTONE:0)
Block(-4,20,1,SANDSTONE:0)
Block(-4,20,2,SANDSTONE:0)
Block(-4,20,3,SANDSTONE:0)
Block(-4,20,4,SANDSTONE:0)
Block(-4,20,5,SANDSTONE:0)
Block(-4,20,6,SANDSTONE:0)
Block(-4,20,7,SANDSTONE:0)
Block(-4,20,8,SANDSTONE:0)
Block(-4,21,-7,SANDSTONE:0)
Block(-4,21,-6,SANDSTONE:0)
Block(-4,21,-5,SANDSTONE:0)
Block(-4,21,-4,SANDSTONE:0)
Block(-4,21,-3,SANDSTONE:0)
Block(-4,21,-2,SANDSTONE:0)
Block(-4,21,-1,SANDSTONE:0)
Block(-4,21,0,SANDSTONE:0)
Block(-4,21,1,SANDSTONE:0)
Block(-4,21,2,SANDSTONE:0)
Block(-4,21,3,SANDSTONE:0)
Block(-4,21,4,SANDSTONE:0)
Block(-4,21,5,SANDSTONE:0)
Block(-4,21,6,SANDSTONE:0)
Block(-4,21,7,SANDSTONE:0)
Block(-4,21,8,SANDSTONE:0)
Block(-4,22,-7,SANDSTONE:0)
Block(-4,22,-6,SANDSTONE:0)
Block(-4,22,-5,SANDSTONE:0)
Block(-4,22,-4,SANDSTONE:0)
Block(-4,22,-3,SANDSTONE:0)
Block(-4,22,-2,SANDSTONE:0)
Block(-4,22,-1,SANDSTONE:0)
Block(-4,22,0,SANDSTONE:0)
Block(-4,22,1,SANDSTONE:0)
Block(-4,22,2,SANDSTONE:0)
Block(-4,22,3,SANDSTONE:0)
Block(-4,22,4,SANDSTONE:0)
Block(-4,22,5,SANDSTONE:0)
Block(-4,22,6,SANDSTONE:0)
Block(-4,22,7,SANDSTONE:0)
Block(-4,22,8,SANDSTONE:0)
Block(-4,23,-7,SANDSTONE:0)
Block(-4,23,-6,SANDSTONE:0)
Block(-4,23,-5,SANDSTONE:0)
Block(-4,23,-4,SANDSTONE:0)
Block(-4,23,-3,SANDSTONE:0)
Block(-4,23,-2,SANDSTONE:0)
Block(-4,23,-1,SANDSTONE:0)
Block(-4,23,0,SANDSTONE:0)
Block(-4,23,1,SANDSTONE:0)
Block(-4,23,2,SANDSTONE:0)
Block(-4,23,3,SANDSTONE:0)
Block(-4,23,4,SANDSTONE:0)
Block(-4,23,5,SANDSTONE:0)
Block(-4,23,6,SANDSTONE:0)
Block(-4,23,7,SANDSTONE:0)
Block(-4,23,8,SANDSTONE:0)
Block(-4,24,-7,SANDSTONE:0)
Block(-4,24,-6,SANDSTONE:0)
Block(-4,24,-5,SANDSTONE:0)
Block(-4,24,-4,SANDSTONE:0)
Block(-4,24,-3,SANDSTONE:0)
Block(-4,24,-2,SANDSTONE:0)
Block(-4,24,-1,SANDSTONE:0)
Block(-4,24,0,SANDSTONE:0)
Block(-4,24,1,SANDSTONE:0)
Block(-4,24,2,SANDSTONE:0)
Block(-4,24,3,SANDSTONE:0)
Block(-4,24,4,SANDSTONE:0)
Block(-4,24,5,SANDSTONE:0)
Block(-4,24,6,SANDSTONE:0)
Block(-4,24,7,SANDSTONE:0)
Block(-4,24,8,SANDSTONE:0)
Block(-4,25,-7,SANDSTONE:0)
Block(-4,25,-6,SANDSTONE:0)
Block(-4,25,-5,SANDSTONE:0)
Block(-4,25,-4,SANDSTONE:0)
Block(-4,25,-3,SANDSTONE:0)
Block(-4,25,-2,SANDSTONE:0)
Block(-4,25,-1,SANDSTONE:0)
Block(-4,25,0,SANDSTONE:0)
Block(-4,25,1,SANDSTONE:0)
Block(-4,25,2,SANDSTONE:0)
Block(-4,25,3,SANDSTONE:0)
Block(-4,25,4,SANDSTONE:0)
Block(-4,25,5,SANDSTONE:0)
Block(-4,25,6,SANDSTONE:0)
Block(-4,25,7,SANDSTONE:0)
Block(-4,25,8,SANDSTONE:0)
Block(-4,26,-7,SANDSTONE:0)
Block(-4,26,-6,SANDSTONE:0)
Block(-4,26,-5,SANDSTONE:0)
Block(-4,26,-4,SANDSTONE:0)
Block(-4,26,-3,SANDSTONE:0)
Block(-4,26,-2,SANDSTONE:0)
Block(-4,26,-1,SANDSTONE:0)
Block(-4,26,0,SANDSTONE:0)
Block(-4,26,1,SANDSTONE:0)
Block(-4,26,2,SANDSTONE:0)
Block(-4,26,3,SANDSTONE:0)
Block(-4,26,4,SANDSTONE:0)
Block(-4,26,5,SANDSTONE:0)
Block(-4,26,6,SANDSTONE:0)
Block(-4,26,7,SANDSTONE:0)
Block(-4,26,8,SANDSTONE:0)
Block(-4,27,-7,SANDSTONE:0)
Block(-4,27,-6,SANDSTONE:0)
Block(-4,27,-5,SANDSTONE:0)
Block(-4,27,-4,SANDSTONE:0)
Block(-4,27,-3,SANDSTONE:0)
Block(-4,27,-2,SANDSTONE:0)
Block(-4,27,-1,SANDSTONE:0)
Block(-4,27,0,SANDSTONE:0)
Block(-4,27,1,SANDSTONE:0)
Block(-4,27,2,SANDSTONE:0)
Block(-4,27,3,SANDSTONE:0)
Block(-4,27,4,SANDSTONE:0)
Block(-4,27,5,SANDSTONE:0)
Block(-4,27,6,SANDSTONE:0)
Block(-4,27,7,SANDSTONE:0)
Block(-4,27,8,SANDSTONE:0)
Block(-4,28,-7,SANDSTONE:0)
Block(-4,28,-6,SANDSTONE:0)
Block(-4,28,-5,SANDSTONE:0)
Block(-4,28,-4,SANDSTONE:0)
Block(-4,28,-3,SANDSTONE:0)
Block(-4,28,-2,SANDSTONE:0)
Block(-4,28,-1,SANDSTONE:0)
Block(-4,28,0,SANDSTONE:0)
Block(-4,28,1,SANDSTONE:0)
Block(-4,28,2,SANDSTONE:0)
Block(-4,28,3,SANDSTONE:0)
Block(-4,28,4,SANDSTONE:0)
Block(-4,28,5,SANDSTONE:0)
Block(-4,28,6,SANDSTONE:0)
Block(-4,28,7,SANDSTONE:0)
Block(-4,28,8,SANDSTONE:0)
Block(-4,29,-7,SANDSTONE:0)
Block(-4,29,-6,SANDSTONE:0)
Block(-4,29,-5,SANDSTONE:0)
Block(-4,29,-4,SANDSTONE:0)
Block(-4,29,-3,SANDSTONE:0)
Block(-4,29,-2,SANDSTONE:0)
Block(-4,29,-1,SANDSTONE:0)
Block(-4,29,0,SANDSTONE:0)
Block(-4,29,1,SANDSTONE:0)
Block(-4,29,2,SANDSTONE:0)
Block(-4,29,3,SANDSTONE:0)
Block(-4,29,4,SANDSTONE:0)
Block(-4,29,5,SANDSTONE:0)
Block(-4,29,6,SANDSTONE:0)
Block(-4,29,7,SANDSTONE:0)
Block(-4,29,8,SANDSTONE:0)
Block(-4,30,-7,SANDSTONE:0)
Block(-4,30,-6,SANDSTONE:0)
Block(-4,30,-5,SANDSTONE:0)
Block(-4,30,-4,SANDSTONE:0)
Block(-4,30,-3,SANDSTONE:0)
Block(-4,30,-2,SANDSTONE:0)
Block(-4,30,-1,SANDSTONE:0)
Block(-4,30,0,SANDSTONE:0)
Block(-4,30,1,SANDSTONE:0)
Block(-4,30,2,SANDSTONE:0)
Block(-4,30,3,SANDSTONE:0)
Block(-4,30,4,SANDSTONE:0)
Block(-4,30,5,SANDSTONE:0)
Block(-4,30,6,SANDSTONE:0)
Block(-4,30,7,SANDSTONE:0)
Block(-4,30,8,SANDSTONE:0)
Block(-4,31,-7,SANDSTONE:0)
Block(-4,31,-6,SANDSTONE:0)
Block(-4,31,-5,SANDSTONE:0)
Block(-4,31,-4,SANDSTONE:0)
Block(-4,31,-3,SANDSTONE:0)
Block(-4,31,-2,SANDSTONE:0)
Block(-4,31,-1,SANDSTONE:0)
Block(-4,31,0,SANDSTONE:0)
Block(-4,31,1,SANDSTONE:0)
Block(-4,31,2,SANDSTONE:0)
Block(-4,31,3,SANDSTONE:0)
Block(-4,31,4,SANDSTONE:0)
Block(-4,31,5,SANDSTONE:0)
Block(-4,31,6,SANDSTONE:0)
Block(-4,31,7,SANDSTONE:0)
Block(-4,31,8,SANDSTONE:0)
Block(-4,32,-7,SANDSTONE:0)
Block(-4,32,-6,SANDSTONE:0)
Block(-4,32,-5,SANDSTONE:0)
Block(-4,32,-4,SANDSTONE:0)
Block(-4,32,-3,SANDSTONE:0)
Block(-4,32,-2,SANDSTONE:0)
Block(-4,32,-1,SANDSTONE:0)
Block(-4,32,0,SANDSTONE:0)
Block(-4,32,1,SANDSTONE:0)
Block(-4,32,2,SANDSTONE:0)
Block(-4,32,3,SANDSTONE:0)
Block(-4,32,4,SANDSTONE:0)
Block(-4,32,5,SANDSTONE:0)
Block(-4,32,6,SANDSTONE:0)
Block(-4,32,7,SANDSTONE:0)
Block(-4,32,8,SANDSTONE:0)
Block(-4,33,-7,SANDSTONE:0)
Block(-4,33,-6,SANDSTONE:0)
Block(-4,33,-5,SANDSTONE:0)
Block(-4,33,-4,SANDSTONE:0)
Block(-4,33,-3,SANDSTONE:0)
Block(-4,33,-2,SANDSTONE:0)
Block(-4,33,-1,SANDSTONE:0)
Block(-4,33,0,SANDSTONE:0)
Block(-4,33,1,SANDSTONE:0)
Block(-4,33,2,SANDSTONE:0)
Block(-4,33,3,SANDSTONE:0)
Block(-4,33,4,SANDSTONE:0)
Block(-4,33,5,SANDSTONE:0)
Block(-4,33,6,SANDSTONE:0)
Block(-4,33,7,SANDSTONE:0)
Block(-4,33,8,SANDSTONE:0)
Block(-4,34,-7,SANDSTONE:0)
Block(-4,34,-6,SANDSTONE:0)
Block(-4,34,-5,SANDSTONE:0)
Block(-4,34,-4,SANDSTONE:0)
Block(-4,34,-3,SANDSTONE:0)
Block(-4,34,-2,SANDSTONE:0)
Block(-4,34,-1,SANDSTONE:0)
Block(-4,34,0,SANDSTONE:0)
Block(-4,34,1,SANDSTONE:0)
Block(-4,34,2,SANDSTONE:0)
Block(-4,34,3,SANDSTONE:0)
Block(-4,34,4,SANDSTONE:0)
Block(-4,34,5,SANDSTONE:0)
Block(-4,34,6,SANDSTONE:0)
Block(-4,34,7,SANDSTONE:0)
Block(-4,34,8,SANDSTONE:0)
Block(-4,35,-7,SANDSTONE:0)
Block(-4,35,-6,SANDSTONE:0)
Block(-4,35,-5,SANDSTONE:0)
Block(-4,35,-4,SANDSTONE:0)
Block(-4,35,-3,SANDSTONE:0)
Block(-4,35,-2,SANDSTONE:0)
Block(-4,35,-1,SANDSTONE:0)
Block(-4,35,0,SANDSTONE:0)
Block(-4,35,1,SANDSTONE:0)
Block(-4,35,2,SANDSTONE:0)
Block(-4,35,3,SANDSTONE:0)
Block(-4,35,4,SANDSTONE:0)
Block(-4,35,5,SANDSTONE:0)
Block(-4,35,6,SANDSTONE:0)
Block(-4,35,7,SANDSTONE:0)
Block(-4,35,8,SANDSTONE:0)
Block(-4,36,-7,SANDSTONE:0)
Block(-4,36,-6,SANDSTONE:0)
Block(-4,36,-5,SANDSTONE:0)
Block(-4,36,-4,SANDSTONE:0)
Block(-4,36,-3,SANDSTONE:0)
RandomBlock(-4,36,-2,SAND:0,50,SANDSTONE:0,100)
RandomBlock(-4,36,-1,SAND:0,50,SANDSTONE:0,100)
Block(-4,36,0,SANDSTONE:0)
Block(-4,36,1,SANDSTONE:0)
Block(-4,36,2,SANDSTONE:0)
Block(-4,36,3,SANDSTONE:0)
Block(-4,36,4,SANDSTONE:0)
Block(-4,36,5,SANDSTONE:0)
Block(-4,36,6,SANDSTONE:0)
Block(-4,36,7,SANDSTONE:0)
Block(-4,36,8,SANDSTONE:0)
Block(-4,37,-7,SANDSTONE:0)
Block(-4,37,-6,SANDSTONE:0)
Block(-4,37,-5,SANDSTONE:0)
RandomBlock(-4,37,-4,SAND:0,50,SANDSTONE:0,100)
RandomBlock(-4,37,-3,SAND:0,50,SANDSTONE:0,100)
RandomBlock(-4,37,-2,SAND:0,50,SANDSTONE:0,100)
RandomBlock(-4,37,-1,SAND:0,50,SANDSTONE:0,100)
Block(-4,37,0,SANDSTONE:0)
Block(-4,37,1,SANDSTONE:0)
Block(-4,37,2,SANDSTONE:0)
Block(-4,37,3,SANDSTONE:0)
Block(-4,37,4,SANDSTONE:0)
Block(-4,37,5,SANDSTONE:0)
Block(-4,37,6,SANDSTONE:0)
Block(-4,37,7,SANDSTONE:0)
Block(-4,37,8,SANDSTONE:0)
Block(-4,38,-7,SANDSTONE:0)
Block(-4,38,-6,SANDSTONE:0)
RandomBlock(-4,38,-5,SAND:0,50,SANDSTONE:0,100)
RandomBlock(-4,38,-4,SAND:0,50,SANDSTONE:0,100)
RandomBlock(-4,38,-3,SAND:0,50,SANDSTONE:0,100)
RandomBlock(-4,38,-2,SAND:0,50,SANDSTONE:0,100)
RandomBlock(-4,38,-1,SAND:0,50,SANDSTONE:0,100)
RandomBlock(-4,38,0,SAND:0,50,SANDSTONE:0,100)
Block(-4,38,1,SANDSTONE:0)
Block(-4,38,2,SANDSTONE:0)
Block(-4,38,3,SANDSTONE:0)
Block(-4,38,4,SANDSTONE:0)
Block(-4,38,5,SANDSTONE:0)
Block(-4,38,6,SANDSTONE:0)
Block(-4,38,7,SANDSTONE:0)
Block(-4,38,8,SANDSTONE:0)
Block(-4,39,-7,SANDSTONE:0)
RandomBlock(-4,39,-6,SAND:0,50,SANDSTONE:0,100)
RandomBlock(-4,39,-5,SAND:0,50,SANDSTONE:0,100)
RandomBlock(-4,39,-4,SAND:0,50,SANDSTONE:0,100)
RandomBlock(-4,39,-3,SAND:0,50,SANDSTONE:0,100)
RandomBlock(-4,39,-2,SAND:0,50,SANDSTONE:0,100)
RandomBlock(-4,39,-1,SAND:0,50,SANDSTONE:0,100)
RandomBlock(-4,39,0,SAND:0,50,SANDSTONE:0,100)
Block(-4,39,1,SANDSTONE:0)
Block(-4,39,2,SANDSTONE:0)
Block(-4,39,3,SANDSTONE:0)
Block(-4,39,4,SANDSTONE:0)
Block(-4,39,5,SANDSTONE:0)
Block(-4,39,6,SANDSTONE:0)
Block(-4,39,7,SANDSTONE:0)
Block(-4,39,8,SANDSTONE:0)
RandomBlock(-4,40,-7,SAND:0,50,SANDSTONE:0,100)
RandomBlock(-4,40,-6,SAND:0,50,SANDSTONE:0,100)
RandomBlock(-4,40,-5,SAND:0,50,SANDSTONE:0,100)
RandomBlock(-4,40,-4,SAND:0,50,SANDSTONE:0,100)
RandomBlock(-4,40,-3,SAND:0,50,SANDSTONE:0,100)
RandomBlock(-4,40,0,SAND:0,50,SANDSTONE:0,100)
Block(-4,40,1,SANDSTONE:0)
Block(-4,40,2,SANDSTONE:0)
Block(-4,40,3,SANDSTONE:0)
Block(-4,40,4,SANDSTONE:0)
Block(-4,40,5,SANDSTONE:0)
Block(-4,40,6,SANDSTONE:0)
Block(-4,40,7,SANDSTONE:0)
Block(-4,40,8,SANDSTONE:0)
RandomBlock(-4,41,-7,SAND:0,50,SANDSTONE:0,100)
RandomBlock(-4,41,-6,SAND:0,50,SANDSTONE:0,100)
RandomBlock(-4,41,-5,SAND:0,50,SANDSTONE:0,100)
RandomBlock(-4,41,0,SAND:0,50,SANDSTONE:0,100)
Block(-4,41,1,SANDSTONE:0)
Block(-4,41,2,SANDSTONE:0)
Block(-4,41,3,SANDSTONE:0)
Block(-4,41,4,SANDSTONE:0)
Block(-4,41,5,SANDSTONE:0)
Block(-4,41,6,SANDSTONE:0)
Block(-4,41,7,SANDSTONE:0)
Block(-4,41,8,SANDSTONE:0)
RandomBlock(-4,42,-7,SAND:0,50,SANDSTONE:0,100)
RandomBlock(-4,42,-6,SAND:0,50,SANDSTONE:0,100)
Block(-4,42,2,SANDSTONE:0)
Block(-4,42,3,SANDSTONE:0)
Block(-4,42,4,SANDSTONE:0)
Block(-4,42,5,SANDSTONE:0)
Block(-4,42,6,SANDSTONE:0)
Block(-4,42,7,SANDSTONE:0)
Block(-4,42,8,SANDSTONE:0)
RandomBlock(-4,43,-7,SAND:0,50,SANDSTONE:0,100)
Block(-4,43,3,SANDSTONE:0)
Block(-4,43,4,SANDSTONE:0)
Block(-4,43,5,SANDSTONE:0)
Block(-4,43,6,SANDSTONE:0)
Block(-4,43,7,SANDSTONE:0)
Block(-4,43,8,SANDSTONE:0)
Block(-4,44,5,SANDSTONE:0)
Block(-4,44,6,SANDSTONE:0)
Block(-4,44,7,SANDSTONE:0)
Block(-4,44,8,SANDSTONE:0)
Block(-3,0,-7,SANDSTONE:0)
Block(-3,0,-6,SANDSTONE:0)
Block(-3,0,-5,SANDSTONE:0)
Block(-3,0,-4,SANDSTONE:0)
Block(-3,0,-3,SANDSTONE:0)
Block(-3,0,-2,SANDSTONE:0)
Block(-3,0,-1,SANDSTONE:0)
Block(-3,0,0,SANDSTONE:0)
Block(-3,0,1,SANDSTONE:0)
Block(-3,0,2,SANDSTONE:0)
Block(-3,0,3,SANDSTONE:0)
Block(-3,0,4,SANDSTONE:0)
Block(-3,0,5,SANDSTONE:0)
Block(-3,0,6,SANDSTONE:0)
Block(-3,0,7,SANDSTONE:0)
Block(-3,0,8,SANDSTONE:0)
Block(-3,1,-7,SANDSTONE:0)
Block(-3,1,-6,SANDSTONE:0)
Block(-3,1,-5,SANDSTONE:0)
Block(-3,1,-4,SANDSTONE:0)
Block(-3,1,-3,SANDSTONE:0)
Block(-3,1,-2,SANDSTONE:0)
Block(-3,1,-1,SANDSTONE:0)
Block(-3,1,0,SANDSTONE:0)
Block(-3,1,1,SANDSTONE:0)
Block(-3,1,2,SANDSTONE:0)
Block(-3,1,3,SANDSTONE:0)
Block(-3,1,4,SANDSTONE:0)
Block(-3,1,5,SANDSTONE:0)
Block(-3,1,6,SANDSTONE:0)
Block(-3,1,7,SANDSTONE:0)
Block(-3,1,8,SANDSTONE:0)
Block(-3,2,-7,SANDSTONE:0)
Block(-3,2,-6,SANDSTONE:0)
Block(-3,2,-5,SANDSTONE:0)
Block(-3,2,-4,SANDSTONE:0)
Block(-3,2,-3,SANDSTONE:0)
Block(-3,2,-2,SANDSTONE:0)
Block(-3,2,-1,SANDSTONE:0)
Block(-3,2,0,SANDSTONE:0)
Block(-3,2,1,SANDSTONE:0)
Block(-3,2,2,SANDSTONE:0)
Block(-3,2,3,SANDSTONE:0)
Block(-3,2,4,SANDSTONE:0)
Block(-3,2,5,SANDSTONE:0)
Block(-3,2,6,SANDSTONE:0)
Block(-3,2,7,SANDSTONE:0)
Block(-3,2,8,SANDSTONE:0)
Block(-3,3,-7,SANDSTONE:0)
Block(-3,3,-6,SANDSTONE:0)
Block(-3,3,-5,SANDSTONE:0)
Block(-3,3,-4,SANDSTONE:0)
Block(-3,3,-3,SANDSTONE:0)
Block(-3,3,-2,SANDSTONE:0)
Block(-3,3,-1,SANDSTONE:0)
Block(-3,3,0,SANDSTONE:0)
Block(-3,3,1,SANDSTONE:0)
Block(-3,3,2,SANDSTONE:0)
Block(-3,3,3,SANDSTONE:0)
Block(-3,3,4,SANDSTONE:0)
Block(-3,3,5,SANDSTONE:0)
Block(-3,3,6,SANDSTONE:0)
Block(-3,3,7,SANDSTONE:0)
Block(-3,3,8,SANDSTONE:0)
Block(-3,4,-7,SANDSTONE:0)
Block(-3,4,-6,SANDSTONE:0)
Block(-3,4,-5,SANDSTONE:0)
Block(-3,4,-4,SANDSTONE:0)
Block(-3,4,-3,SANDSTONE:0)
Block(-3,4,-2,SANDSTONE:0)
Block(-3,4,-1,SANDSTONE:0)
Block(-3,4,0,SANDSTONE:0)
Block(-3,4,1,SANDSTONE:0)
Block(-3,4,2,SANDSTONE:0)
Block(-3,4,3,SANDSTONE:0)
Block(-3,4,4,SANDSTONE:0)
Block(-3,4,5,SANDSTONE:0)
Block(-3,4,6,SANDSTONE:0)
Block(-3,4,7,SANDSTONE:0)
Block(-3,4,8,SANDSTONE:0)
Block(-3,5,-7,SANDSTONE:0)
Block(-3,5,-6,SANDSTONE:0)
Block(-3,5,-5,SANDSTONE:0)
Block(-3,5,-4,SANDSTONE:0)
Block(-3,5,-3,SANDSTONE:0)
Block(-3,5,-2,SANDSTONE:0)
Block(-3,5,-1,SANDSTONE:0)
Block(-3,5,0,SANDSTONE:0)
Block(-3,5,1,SANDSTONE:0)
Block(-3,5,2,SANDSTONE:0)
Block(-3,5,3,SANDSTONE:0)
Block(-3,5,4,SANDSTONE:0)
Block(-3,5,5,SANDSTONE:0)
Block(-3,5,6,SANDSTONE:0)
Block(-3,5,7,SANDSTONE:0)
Block(-3,5,8,SANDSTONE:0)
Block(-3,6,-7,SANDSTONE:0)
Block(-3,6,-6,SANDSTONE:0)
Block(-3,6,-5,SANDSTONE:0)
Block(-3,6,-4,SANDSTONE:0)
Block(-3,6,-3,SANDSTONE:0)
Block(-3,6,-2,SANDSTONE:0)
Block(-3,6,-1,SANDSTONE:0)
Block(-3,6,0,SANDSTONE:0)
Block(-3,6,1,SANDSTONE:0)
Block(-3,6,2,SANDSTONE:0)
Block(-3,6,3,SANDSTONE:0)
Block(-3,6,4,SANDSTONE:0)
Block(-3,6,5,SANDSTONE:0)
Block(-3,6,6,SANDSTONE:0)
Block(-3,6,7,SANDSTONE:0)
Block(-3,6,8,SANDSTONE:0)
Block(-3,7,-7,SANDSTONE:0)
Block(-3,7,-6,SANDSTONE:0)
Block(-3,7,-5,SANDSTONE:0)
Block(-3,7,-4,SANDSTONE:0)
Block(-3,7,-3,SANDSTONE:0)
Block(-3,7,-2,SANDSTONE:0)
Block(-3,7,-1,SANDSTONE:0)
Block(-3,7,0,SANDSTONE:0)
Block(-3,7,1,SANDSTONE:0)
Block(-3,7,2,SANDSTONE:0)
Block(-3,7,3,SANDSTONE:0)
Block(-3,7,4,SANDSTONE:0)
Block(-3,7,5,SANDSTONE:0)
Block(-3,7,6,SANDSTONE:0)
Block(-3,7,7,SANDSTONE:0)
Block(-3,7,8,SANDSTONE:0)
Block(-3,8,-7,SANDSTONE:0)
Block(-3,8,-6,SANDSTONE:0)
Block(-3,8,-5,SANDSTONE:0)
Block(-3,8,-4,SANDSTONE:0)
Block(-3,8,-3,SANDSTONE:0)
Block(-3,8,-2,SANDSTONE:0)
Block(-3,8,-1,SANDSTONE:0)
Block(-3,8,0,SANDSTONE:0)
Block(-3,8,1,SANDSTONE:0)
Block(-3,8,2,SANDSTONE:0)
Block(-3,8,3,SANDSTONE:0)
Block(-3,8,4,SANDSTONE:0)
Block(-3,8,5,SANDSTONE:0)
Block(-3,8,6,SANDSTONE:0)
Block(-3,8,7,SANDSTONE:0)
Block(-3,8,8,SANDSTONE:0)
Block(-3,9,-7,SANDSTONE:0)
Block(-3,9,-6,SANDSTONE:0)
Block(-3,9,-5,SANDSTONE:0)
Block(-3,9,-4,SANDSTONE:0)
Block(-3,9,-3,SANDSTONE:0)
Block(-3,9,-2,SANDSTONE:0)
Block(-3,9,-1,SANDSTONE:0)
Block(-3,9,0,SANDSTONE:0)
Block(-3,9,1,SANDSTONE:0)
Block(-3,9,2,SANDSTONE:0)
Block(-3,9,3,SANDSTONE:0)
Block(-3,9,4,SANDSTONE:0)
Block(-3,9,5,SANDSTONE:0)
Block(-3,9,6,SANDSTONE:0)
Block(-3,9,7,SANDSTONE:0)
Block(-3,9,8,SANDSTONE:0)
Block(-3,10,-7,SANDSTONE:0)
Block(-3,10,-6,SANDSTONE:0)
Block(-3,10,-5,SANDSTONE:0)
Block(-3,10,-4,SANDSTONE:0)
Block(-3,10,-3,SANDSTONE:0)
Block(-3,10,-2,SANDSTONE:0)
Block(-3,10,-1,SANDSTONE:0)
Block(-3,10,0,SANDSTONE:0)
Block(-3,10,1,SANDSTONE:0)
Block(-3,10,2,SANDSTONE:0)
Block(-3,10,3,SANDSTONE:0)
Block(-3,10,4,SANDSTONE:0)
Block(-3,10,5,SANDSTONE:0)
Block(-3,10,6,SANDSTONE:0)
Block(-3,10,7,SANDSTONE:0)
Block(-3,10,8,SANDSTONE:0)
Block(-3,11,-7,SANDSTONE:0)
Block(-3,11,-6,SANDSTONE:0)
Block(-3,11,-5,SANDSTONE:0)
Block(-3,11,-4,SANDSTONE:0)
Block(-3,11,-3,SANDSTONE:0)
Block(-3,11,-2,SANDSTONE:0)
Block(-3,11,-1,SANDSTONE:0)
Block(-3,11,0,SANDSTONE:0)
Block(-3,11,1,SANDSTONE:0)
Block(-3,11,2,SANDSTONE:0)
Block(-3,11,3,SANDSTONE:0)
Block(-3,11,4,SANDSTONE:0)
Block(-3,11,5,SANDSTONE:0)
Block(-3,11,6,SANDSTONE:0)
Block(-3,11,7,SANDSTONE:0)
Block(-3,11,8,SANDSTONE:0)
Block(-3,12,-7,SANDSTONE:0)
Block(-3,12,-6,SANDSTONE:0)
Block(-3,12,-5,SANDSTONE:0)
Block(-3,12,-4,SANDSTONE:0)
Block(-3,12,-3,SANDSTONE:0)
Block(-3,12,-2,SANDSTONE:0)
Block(-3,12,-1,SANDSTONE:0)
