
#######################################################################
# +-----------------------------------------------------------------+ #
# |                            BO4 object                           | #
# +-----------------------------------------------------------------+ #
#######################################################################

Author: NLBlackEagle

Description: No description given

SettingsMode: WriteWithoutComments


#######################################################################
# +-----------------------------------------------------------------+ #
# |                          Main settings                          | #
# +-----------------------------------------------------------------+ #
#######################################################################

FixedRotation: 

Frequency: 0

SpawnHeight: highestBlock

UseCenterForHighestBlock: true

##############################
# Height Limits for the BO4. #
##############################

MinHeight: 0

MaxHeight: 255

InheritBO3: 

InheritBO3Rotation: NORTH

OverrideChildSettings: true

OverrideParentHeight: false

CanOverride: false

BranchFrequency: 0

BranchFrequencyGroup: 

MustBeBelowOther: false

MustBeInside: 

CannotBeInside: 

ReplacesBO3: 

MustBeInsideWorldBorders: false

CanSpawnOnWater: true

SpawnOnWaterOnly: false

SpawnUnderWater: false

SpawnAtWaterLevel: false

HeightOffset: 0

RemoveAir: false

ReplaceAbove: 

ReplaceBelow: 

ReplaceWithBiomeBlocks: true

ReplaceWithSurfaceBlock: STONE, SAND, BIOMESOPLENTY:DRIED_SAND

ReplaceWithGroundBlock: STONE, SAND, BIOMESOPLENTY:DRIED_SAND

ReplaceWithStoneBlock: STONE, SAND, BIOMESOPLENTY:DRIED_SAND

SmoothRadius: 0

SmoothHeightOffset: 0

SmoothStartTop: false

SmoothStartWood: false

SmoothingSurfaceBlock: 

SmoothingGroundBlock: 

BO3Group: 

IsSpawnPoint: false

DoReplaceBlocks: false


#######################################################################
# +-----------------------------------------------------------------+ #
# |                              Blocks                             | #
# +-----------------------------------------------------------------+ #
#######################################################################

Block(-8,0,-7,SANDSTONE:0)
Block(-8,0,-6,SANDSTONE:0)
Block(-8,0,-5,SANDSTONE:0)
Block(-8,0,-4,SANDSTONE:0)
Block(-8,0,-3,SANDSTONE:0)
Block(-8,0,-2,SANDSTONE:0)
Block(-8,0,-1,SANDSTONE:0)
Block(-8,0,0,SANDSTONE:0)
Block(-8,0,1,SANDSTONE:0)
Block(-8,0,2,SANDSTONE:0)
Block(-8,0,3,SANDSTONE:0)
Block(-8,0,4,SANDSTONE:0)
Block(-8,0,5,SANDSTONE:0)
Block(-8,0,6,SANDSTONE:0)
Block(-8,0,7,SANDSTONE:0)
Block(-8,0,8,SANDSTONE:0)
Block(-8,1,-7,SANDSTONE:0)
Block(-8,1,-6,SANDSTONE:0)
Block(-8,1,-5,SANDSTONE:0)
Block(-8,1,-4,SANDSTONE:0)
Block(-8,1,-3,SANDSTONE:0)
Block(-8,1,-2,SANDSTONE:0)
Block(-8,1,-1,SANDSTONE:0)
Block(-8,1,0,SANDSTONE:0)
Block(-8,1,1,SANDSTONE:0)
Block(-8,1,2,SANDSTONE:0)
Block(-8,1,3,SANDSTONE:0)
Block(-8,1,4,SANDSTONE:0)
Block(-8,1,5,SANDSTONE:0)
Block(-8,1,6,SANDSTONE:0)
Block(-8,1,7,SANDSTONE:0)
Block(-8,1,8,SANDSTONE:0)
Block(-8,2,-7,SANDSTONE:0)
Block(-8,2,-6,SANDSTONE:0)
Block(-8,2,-5,SANDSTONE:0)
Block(-8,2,-4,SANDSTONE:0)
Block(-8,2,-3,SANDSTONE:0)
Block(-8,2,-2,SANDSTONE:0)
Block(-8,2,-1,SANDSTONE:0)
Block(-8,2,0,SANDSTONE:0)
Block(-8,2,1,SANDSTONE:0)
Block(-8,2,2,SANDSTONE:0)
Block(-8,2,3,SANDSTONE:0)
Block(-8,2,4,SANDSTONE:0)
Block(-8,2,5,SANDSTONE:0)
Block(-8,2,6,SANDSTONE:0)
Block(-8,2,7,SANDSTONE:0)
Block(-8,2,8,SANDSTONE:0)
Block(-8,3,-7,SANDSTONE:0)
Block(-8,3,-6,SANDSTONE:0)
Block(-8,3,-5,SANDSTONE:0)
Block(-8,3,-4,SANDSTONE:0)
Block(-8,3,-3,SANDSTONE:0)
Block(-8,3,-2,SANDSTONE:0)
Block(-8,3,-1,SANDSTONE:0)
Block(-8,3,0,SANDSTONE:0)
Block(-8,3,1,SANDSTONE:0)
Block(-8,3,2,SANDSTONE:0)
Block(-8,3,3,SANDSTONE:0)
Block(-8,3,4,SANDSTONE:0)
Block(-8,3,5,SANDSTONE:0)
Block(-8,3,6,SANDSTONE:0)
Block(-8,3,7,SANDSTONE:0)
Block(-8,3,8,SANDSTONE:0)
Block(-8,4,-7,SANDSTONE:0)
Block(-8,4,-6,SANDSTONE:0)
Block(-8,4,-5,SANDSTONE:0)
Block(-8,4,-4,SANDSTONE:0)
Block(-8,4,-3,SANDSTONE:0)
Block(-8,4,-2,SANDSTONE:0)
Block(-8,4,-1,SANDSTONE:0)
Block(-8,4,0,SANDSTONE:0)
Block(-8,4,1,SANDSTONE:0)
Block(-8,4,2,SANDSTONE:0)
Block(-8,4,3,SANDSTONE:0)
Block(-8,4,4,SANDSTONE:0)
Block(-8,4,5,SANDSTONE:0)
Block(-8,4,6,SANDSTONE:0)
Block(-8,4,7,SANDSTONE:0)
Block(-8,4,8,SANDSTONE:0)
Block(-8,5,-7,SANDSTONE:0)
Block(-8,5,-6,SANDSTONE:0)
Block(-8,5,-5,SANDSTONE:0)
Block(-8,5,-4,SANDSTONE:0)
Block(-8,5,-3,SANDSTONE:0)
Block(-8,5,-2,SANDSTONE:0)
Block(-8,5,-1,SANDSTONE:0)
Block(-8,5,0,SANDSTONE:0)
Block(-8,5,1,SANDSTONE:0)
Block(-8,5,2,SANDSTONE:0)
Block(-8,5,3,SANDSTONE:0)
Block(-8,5,4,SANDSTONE:0)
Block(-8,5,5,SANDSTONE:0)
Block(-8,5,6,SANDSTONE:0)
Block(-8,5,7,SANDSTONE:0)
Block(-8,5,8,SANDSTONE:0)
Block(-8,6,-7,SANDSTONE:0)
Block(-8,6,-6,SANDSTONE:0)
Block(-8,6,-5,SANDSTONE:0)
Block(-8,6,-4,SANDSTONE:0)
Block(-8,6,-3,SANDSTONE:0)
Block(-8,6,-2,SANDSTONE:0)
Block(-8,6,-1,SANDSTONE:0)
Block(-8,6,0,SANDSTONE:0)
Block(-8,6,1,SANDSTONE:0)
Block(-8,6,2,SANDSTONE:0)
Block(-8,6,3,SANDSTONE:0)
Block(-8,6,4,SANDSTONE:0)
Block(-8,6,5,SANDSTONE:0)
Block(-8,6,6,SANDSTONE:0)
Block(-8,6,7,SANDSTONE:0)
Block(-8,6,8,SANDSTONE:0)
Block(-8,7,-7,SANDSTONE:0)
Block(-8,7,-6,SANDSTONE:0)
Block(-8,7,-5,SANDSTONE:0)
Block(-8,7,-4,SANDSTONE:0)
Block(-8,7,-3,SANDSTONE:0)
Block(-8,7,-2,SANDSTONE:0)
Block(-8,7,-1,SANDSTONE:0)
Block(-8,7,0,SANDSTONE:0)
Block(-8,7,1,SANDSTONE:0)
Block(-8,7,2,SANDSTONE:0)
Block(-8,7,3,SANDSTONE:0)
Block(-8,7,4,SANDSTONE:0)
Block(-8,7,5,SANDSTONE:0)
Block(-8,7,6,SANDSTONE:0)
Block(-8,7,7,SANDSTONE:0)
Block(-8,7,8,SANDSTONE:0)
Block(-8,8,-7,SANDSTONE:0)
Block(-8,8,-6,SANDSTONE:0)
Block(-8,8,-5,SANDSTONE:0)
Block(-8,8,-4,SANDSTONE:0)
Block(-8,8,-3,SANDSTONE:0)
Block(-8,8,-2,SANDSTONE:0)
Block(-8,8,-1,SANDSTONE:0)
Block(-8,8,0,SANDSTONE:0)
Block(-8,8,1,SANDSTONE:0)
Block(-8,8,2,SANDSTONE:0)
Block(-8,8,3,SANDSTONE:0)
Block(-8,8,4,SANDSTONE:0)
Block(-8,8,5,SANDSTONE:0)
Block(-8,8,6,SANDSTONE:0)
Block(-8,8,7,SANDSTONE:0)
Block(-8,8,8,SANDSTONE:0)
Block(-8,9,-7,SANDSTONE:0)
Block(-8,9,-6,SANDSTONE:0)
Block(-8,9,-5,SANDSTONE:0)
Block(-8,9,-4,SANDSTONE:0)
Block(-8,9,-3,SANDSTONE:0)
Block(-8,9,-2,SANDSTONE:0)
Block(-8,9,-1,SANDSTONE:0)
Block(-8,9,0,SANDSTONE:0)
Block(-8,9,1,SANDSTONE:0)
Block(-8,9,2,SANDSTONE:0)
Block(-8,9,3,SANDSTONE:0)
Block(-8,9,4,SANDSTONE:0)
Block(-8,9,5,SANDSTONE:0)
Block(-8,9,6,SANDSTONE:0)
Block(-8,9,7,SANDSTONE:0)
Block(-8,9,8,SANDSTONE:0)
Block(-8,10,-7,SANDSTONE:0)
Block(-8,10,-6,SANDSTONE:0)
Block(-8,10,-5,SANDSTONE:0)
Block(-8,10,-4,SANDSTONE:0)
Block(-8,10,-3,SANDSTONE:0)
Block(-8,10,-2,SANDSTONE:0)
Block(-8,10,-1,SANDSTONE:0)
Block(-8,10,0,SANDSTONE:0)
Block(-8,10,1,SANDSTONE:0)
Block(-8,10,2,SANDSTONE:0)
Block(-8,10,3,SANDSTONE:0)
Block(-8,10,4,SANDSTONE:0)
Block(-8,10,5,SANDSTONE:0)
Block(-8,10,6,SANDSTONE:0)
Block(-8,10,7,SANDSTONE:0)
Block(-8,10,8,SANDSTONE:0)
RandomBlock(-8,11,-7,SAND:0,50,SANDSTONE:0,100)
Block(-8,11,-6,SANDSTONE:0)
Block(-8,11,-5,SANDSTONE:0)
Block(-8,11,-4,SANDSTONE:0)
Block(-8,11,-3,SANDSTONE:0)
Block(-8,11,-2,SANDSTONE:0)
Block(-8,11,-1,SANDSTONE:0)
Block(-8,11,0,SANDSTONE:0)
Block(-8,11,1,SANDSTONE:0)
Block(-8,11,2,SANDSTONE:0)
Block(-8,11,3,SANDSTONE:0)
Block(-8,11,4,SANDSTONE:0)
Block(-8,11,5,SANDSTONE:0)
Block(-8,11,6,SANDSTONE:0)
Block(-8,11,7,SANDSTONE:0)
Block(-8,11,8,SANDSTONE:0)
RandomBlock(-8,12,-7,SAND:0,50,SANDSTONE:0,100)
RandomBlock(-8,12,-6,SAND:0,50,SANDSTONE:0,100)
Block(-8,12,-5,SANDSTONE:0)
Block(-8,12,-4,SANDSTONE:0)
Block(-8,12,-3,SANDSTONE:0)
Block(-8,12,-2,SANDSTONE:0)
RandomBlock(-8,12,-1,SAND:0,50,SANDSTONE:0,100)
RandomBlock(-8,12,0,SAND:0,50,SANDSTONE:0,100)
RandomBlock(-8,12,1,SAND:0,50,SANDSTONE:0,100)
RandomBlock(-8,12,2,SAND:0,50,SANDSTONE:0,100)
Block(-8,12,3,SANDSTONE:0)
Block(-8,12,4,SANDSTONE:0)
Block(-8,12,5,SANDSTONE:0)
Block(-8,12,6,SANDSTONE:0)
Block(-8,12,7,SANDSTONE:0)
Block(-8,12,8,SANDSTONE:0)
RandomBlock(-8,13,-7,SAND:0,50,SANDSTONE:0,100)
RandomBlock(-8,13,-6,SAND:0,50,SANDSTONE:0,100)
RandomBlock(-8,13,-5,SAND:0,50,SANDSTONE:0,100)
Block(-8,13,-4,SANDSTONE:0)
RandomBlock(-8,13,-3,SAND:0,50,SANDSTONE:0,100)
RandomBlock(-8,13,-2,SAND:0,50,SANDSTONE:0,100)
RandomBlock(-8,13,-1,SAND:0,50,SANDSTONE:0,100)
RandomBlock(-8,13,0,SAND:0,50,SANDSTONE:0,100)
RandomBlock(-8,13,1,SAND:0,50,SANDSTONE:0,100)
RandomBlock(-8,13,2,SAND:0,50,SANDSTONE:0,100)
RandomBlock(-8,13,3,SAND:0,50,SANDSTONE:0,100)
Block(-8,13,4,SANDSTONE:0)
Block(-8,13,5,SANDSTONE:0)
Block(-8,13,6,SANDSTONE:0)
Block(-8,13,7,SANDSTONE:0)
Block(-8,13,8,SANDSTONE:0)
RandomBlock(-8,14,-7,SAND:0,50,SANDSTONE:0,100)
RandomBlock(-8,14,-6,SAND:0,50,SANDSTONE:0,100)
RandomBlock(-8,14,-5,SAND:0,50,SANDSTONE:0,100)
RandomBlock(-8,14,-4,SAND:0,50,SANDSTONE:0,100)
RandomBlock(-8,14,-3,SAND:0,50,SANDSTONE:0,100)
RandomBlock(-8,14,-2,SAND:0,50,SANDSTONE:0,100)
RandomBlock(-8,14,-1,SAND:0,50,SANDSTONE:0,100)
RandomBlock(-8,14,0,SAND:0,50,SANDSTONE:0,100)
RandomBlock(-8,14,1,SAND:0,50,SANDSTONE:0,100)
RandomBlock(-8,14,2,SAND:0,50,SANDSTONE:0,100)
RandomBlock(-8,14,3,SAND:0,50,SANDSTONE:0,100)
RandomBlock(-8,14,4,SAND:0,50,SANDSTONE:0,100)
RandomBlock(-8,14,5,SAND:0,50,SANDSTONE:0,100)
RandomBlock(-8,14,6,SAND:0,50,SANDSTONE:0,100)
Block(-8,14,7,SANDSTONE:0)
Block(-8,14,8,SANDSTONE:0)
RandomBlock(-8,15,-6,SAND:0,50,SANDSTONE:0,100)
RandomBlock(-8,15,-5,SAND:0,50,SANDSTONE:0,100)
RandomBlock(-8,15,-4,SAND:0,50,SANDSTONE:0,100)
RandomBlock(-8,15,-3,SAND:0,50,SANDSTONE:0,100)
RandomBlock(-8,15,-2,SAND:0,50,SANDSTONE:0,100)
RandomBlock(-8,15,-1,SAND:0,50,SANDSTONE:0,100)
RandomBlock(-8,15,0,SAND:0,50,SANDSTONE:0,100)
RandomBlock(-8,15,1,SAND:0,50,SANDSTONE:0,100)
RandomBlock(-8,15,2,SAND:0,50,SANDSTONE:0,100)
RandomBlock(-8,15,3,SAND:0,50,SANDSTONE:0,100)
RandomBlock(-8,15,4,SAND:0,50,SANDSTONE:0,100)
RandomBlock(-8,15,5,SAND:0,50,SANDSTONE:0,100)
RandomBlock(-8,15,6,SAND:0,50,SANDSTONE:0,100)
RandomBlock(-8,15,7,SAND:0,50,SANDSTONE:0,100)
Block(-8,15,8,SANDSTONE:0)
RandomBlock(-8,16,-6,SAND:0,50,SANDSTONE:0,100)
RandomBlock(-8,16,-5,SAND:0,50,SANDSTONE:0,100)
RandomBlock(-8,16,-4,SAND:0,50,SANDSTONE:0,100)
RandomBlock(-8,16,-3,SAND:0,50,SANDSTONE:0,100)
RandomBlock(-8,16,-2,SAND:0,50,SANDSTONE:0,100)
RandomBlock(-8,16,-1,SAND:0,50,SANDSTONE:0,100)
RandomBlock(-8,16,0,SAND:0,50,SANDSTONE:0,100)
RandomBlock(-8,16,1,SAND:0,50,SANDSTONE:0,100)
RandomBlock(-8,16,2,SAND:0,50,SANDSTONE:0,100)
RandomBlock(-8,16,3,SAND:0,50,SANDSTONE:0,100)
RandomBlock(-8,16,4,SAND:0,50,SANDSTONE:0,100)
RandomBlock(-8,16,5,SAND:0,50,SANDSTONE:0,100)
RandomBlock(-8,16,6,SAND:0,50,SANDSTONE:0,100)
RandomBlock(-8,16,7,SAND:0,50,SANDSTONE:0,100)
Block(-8,16,8,SANDSTONE:0)
RandomBlock(-8,17,-5,SAND:0,50,SANDSTONE:0,100)
RandomBlock(-8,17,-4,SAND:0,50,SANDSTONE:0,100)
RandomBlock(-8,17,-3,SAND:0,50,SANDSTONE:0,100)
RandomBlock(-8,17,-2,SAND:0,50,SANDSTONE:0,100)
RandomBlock(-8,17,-1,SAND:0,50,SANDSTONE:0,100)
RandomBlock(-8,17,0,SAND:0,50,SANDSTONE:0,100)
RandomBlock(-8,17,1,SAND:0,50,SANDSTONE:0,100)
RandomBlock(-8,17,2,SAND:0,50,SANDSTONE:0,100)
RandomBlock(-8,17,3,SAND:0,50,SANDSTONE:0,100)
RandomBlock(-8,17,4,SAND:0,50,SANDSTONE:0,100)
RandomBlock(-8,17,5,SAND:0,50,SANDSTONE:0,100)
RandomBlock(-8,17,6,SAND:0,50,SANDSTONE:0,100)
RandomBlock(-8,17,7,SAND:0,50,SANDSTONE:0,100)
RandomBlock(-8,17,8,SAND:0,50,SANDSTONE:0,100)
RandomBlock(-8,18,-3,SAND:0,50,SANDSTONE:0,100)
RandomBlock(-8,18,-2,SAND:0,50,SANDSTONE:0,100)
RandomBlock(-8,18,-1,SAND:0,50,SANDSTONE:0,100)
RandomBlock(-8,18,0,SAND:0,50,SANDSTONE:0,100)
RandomBlock(-8,18,1,SAND:0,50,SANDSTONE:0,100)
RandomBlock(-8,18,2,SAND:0,50,SANDSTONE:0,100)
RandomBlock(-8,18,3,SAND:0,50,SANDSTONE:0,100)
RandomBlock(-8,18,4,SAND:0,50,SANDSTONE:0,100)
RandomBlock(-8,18,5,SAND:0,50,SANDSTONE:0,100)
RandomBlock(-8,18,6,SAND:0,50,SANDSTONE:0,100)
RandomBlock(-8,18,7,SAND:0,50,SANDSTONE:0,100)
RandomBlock(-8,18,8,SAND:0,50,SANDSTONE:0,100)
RandomBlock(-8,19,-3,SAND:0,50,SANDSTONE:0,100)
RandomBlock(-8,19,-2,SAND:0,50,SANDSTONE:0,100)
RandomBlock(-8,19,-1,SAND:0,50,SANDSTONE:0,100)
RandomBlock(-8,19,0,SAND:0,50,SANDSTONE:0,100)
RandomBlock(-8,19,1,SAND:0,50,SANDSTONE:0,100)
RandomBlock(-8,19,2,SAND:0,50,SANDSTONE:0,100)
RandomBlock(-8,19,3,SAND:0,50,SANDSTONE:0,100)
RandomBlock(-8,19,4,SAND:0,50,SANDSTONE:0,100)
RandomBlock(-8,19,5,SAND:0,50,SANDSTONE:0,100)
RandomBlock(-8,19,6,SAND:0,50,SANDSTONE:0,100)
RandomBlock(-8,19,7,SAND:0,50,SANDSTONE:0,100)
RandomBlock(-8,19,8,SAND:0,50,SANDSTONE:0,100)
RandomBlock(-8,20,0,SAND:0,50,SANDSTONE:0,100)
RandomBlock(-8,20,1,SAND:0,50,SANDSTONE:0,100)
RandomBlock(-8,20,2,SAND:0,50,SANDSTONE:0,100)
RandomBlock(-8,20,3,SAND:0,50,SANDSTONE:0,100)
RandomBlock(-8,20,4,SAND:0,50,SANDSTONE:0,100)
RandomBlock(-8,20,5,SAND:0,50,SANDSTONE:0,100)
RandomBlock(-8,20,6,SAND:0,50,SANDSTONE:0,100)
RandomBlock(-8,20,7,SAND:0,50,SANDSTONE:0,100)
RandomBlock(-8,20,8,SAND:0,50,SANDSTONE:0,100)
RandomBlock(-8,21,0,SAND:0,50,SANDSTONE:0,100)
RandomBlock(-8,21,1,SAND:0,50,SANDSTONE:0,100)
RandomBlock(-8,21,2,SAND:0,50,SANDSTONE:0,100)
RandomBlock(-8,21,3,SAND:0,50,SANDSTONE:0,100)
RandomBlock(-8,21,4,SAND:0,50,SANDSTONE:0,100)
RandomBlock(-8,21,5,SAND:0,50,SANDSTONE:0,100)
RandomBlock(-8,21,6,SAND:0,50,SANDSTONE:0,100)
RandomBlock(-8,21,7,SAND:0,50,SANDSTONE:0,100)
RandomBlock(-8,21,8,SAND:0,50,SANDSTONE:0,100)
RandomBlock(-8,22,3,SAND:0,50,SANDSTONE:0,100)
RandomBlock(-8,22,4,SAND:0,50,SANDSTONE:0,100)
RandomBlock(-8,22,5,SAND:0,50,SANDSTONE:0,100)
RandomBlock(-8,22,6,SAND:0,50,SANDSTONE:0,100)
RandomBlock(-8,22,7,SAND:0,50,SANDSTONE:0,100)
RandomBlock(-8,22,8,SAND:0,50,SANDSTONE:0,100)
RandomBlock(-8,23,4,SAND:0,50,SANDSTONE:0,100)
RandomBlock(-8,23,5,SAND:0,50,SANDSTONE:0,100)
RandomBlock(-8,23,6,SAND:0,50,SANDSTONE:0,100)
RandomBlock(-8,23,7,SAND:0,50,SANDSTONE:0,100)
RandomBlock(-8,23,8,SAND:0,50,SANDSTONE:0,100)
RandomBlock(-8,24,4,SAND:0,50,SANDSTONE:0,100)
RandomBlock(-8,24,5,SAND:0,50,SANDSTONE:0,100)
RandomBlock(-8,24,6,SAND:0,50,SANDSTONE:0,100)
Block(-7,0,-7,SANDSTONE:0)
Block(-7,0,-6,SANDSTONE:0)
Block(-7,0,-5,SANDSTONE:0)
Block(-7,0,-4,SANDSTONE:0)
Block(-7,0,-3,SANDSTONE:0)
Block(-7,0,-2,SANDSTONE:0)
Block(-7,0,-1,SANDSTONE:0)
Block(-7,0,0,SANDSTONE:0)
Block(-7,0,1,SANDSTONE:0)
Block(-7,0,2,SANDSTONE:0)
Block(-7,0,3,SANDSTONE:0)
Block(-7,0,4,SANDSTONE:0)
Block(-7,0,5,SANDSTONE:0)
Block(-7,0,6,SANDSTONE:0)
Block(-7,0,7,SANDSTONE:0)
Block(-7,0,8,SANDSTONE:0)
Block(-7,1,-7,SANDSTONE:0)
Block(-7,1,-6,SANDSTONE:0)
Block(-7,1,-5,SANDSTONE:0)
Block(-7,1,-4,SANDSTONE:0)
Block(-7,1,-3,SANDSTONE:0)
Block(-7,1,-2,SANDSTONE:0)
Block(-7,1,-1,SANDSTONE:0)
Block(-7,1,0,SANDSTONE:0)
Block(-7,1,1,SANDSTONE:0)
Block(-7,1,2,SANDSTONE:0)
Block(-7,1,3,SANDSTONE:0)
Block(-7,1,4,SANDSTONE:0)
Block(-7,1,5,SANDSTONE:0)
Block(-7,1,6,SANDSTONE:0)
Block(-7,1,7,SANDSTONE:0)
Block(-7,1,8,SANDSTONE:0)
Block(-7,2,-7,SANDSTONE:0)
Block(-7,2,-6,SANDSTONE:0)
Block(-7,2,-5,SANDSTONE:0)
Block(-7,2,-4,SANDSTONE:0)
Block(-7,2,-3,SANDSTONE:0)
Block(-7,2,-2,SANDSTONE:0)
Block(-7,2,-1,SANDSTONE:0)
Block(-7,2,0,SANDSTONE:0)
Block(-7,2,1,SANDSTONE:0)
Block(-7,2,2,SANDSTONE:0)
Block(-7,2,3,SANDSTONE:0)
Block(-7,2,4,SANDSTONE:0)
Block(-7,2,5,SANDSTONE:0)
Block(-7,2,6,SANDSTONE:0)
Block(-7,2,7,SANDSTONE:0)
Block(-7,2,8,SANDSTONE:0)
Block(-7,3,-7,SANDSTONE:0)
Block(-7,3,-6,SANDSTONE:0)
Block(-7,3,-5,SANDSTONE:0)
Block(-7,3,-4,SANDSTONE:0)
Block(-7,3,-3,SANDSTONE:0)
Block(-7,3,-2,SANDSTONE:0)
Block(-7,3,-1,SANDSTONE:0)
Block(-7,3,0,SANDSTONE:0)
Block(-7,3,1,SANDSTONE:0)
Block(-7,3,2,SANDSTONE:0)
Block(-7,3,3,SANDSTONE:0)
Block(-7,3,4,SANDSTONE:0)
Block(-7,3,5,SANDSTONE:0)
Block(-7,3,6,SANDSTONE:0)
Block(-7,3,7,SANDSTONE:0)
Block(-7,3,8,SANDSTONE:0)
Block(-7,4,-7,SANDSTONE:0)
Block(-7,4,-6,SANDSTONE:0)
Block(-7,4,-5,SANDSTONE:0)
Block(-7,4,-4,SANDSTONE:0)
Block(-7,4,-3,SANDSTONE:0)
Block(-7,4,-2,SANDSTONE:0)
Block(-7,4,-1,SANDSTONE:0)
Block(-7,4,0,SANDSTONE:0)
Block(-7,4,1,SANDSTONE:0)
Block(-7,4,2,SANDSTONE:0)
Block(-7,4,3,SANDSTONE:0)
Block(-7,4,4,SANDSTONE:0)
Block(-7,4,5,SANDSTONE:0)
Block(-7,4,6,SANDSTONE:0)
Block(-7,4,7,SANDSTONE:0)
Block(-7,4,8,SANDSTONE:0)
Block(-7,5,-7,SANDSTONE:0)
Block(-7,5,-6,SANDSTONE:0)
Block(-7,5,-5,SANDSTONE:0)
Block(-7,5,-4,SANDSTONE:0)
Block(-7,5,-3,SANDSTONE:0)
Block(-7,5,-2,SANDSTONE:0)
Block(-7,5,-1,SANDSTONE:0)
Block(-7,5,0,SANDSTONE:0)
Block(-7,5,1,SANDSTONE:0)
Block(-7,5,2,SANDSTONE:0)
Block(-7,5,3,SANDSTONE:0)
Block(-7,5,4,SANDSTONE:0)
Block(-7,5,5,SANDSTONE:0)
Block(-7,5,6,SANDSTONE:0)
Block(-7,5,7,SANDSTONE:0)
Block(-7,5,8,SANDSTONE:0)
Block(-7,6,-7,SANDSTONE:0)
Block(-7,6,-6,SANDSTONE:0)
Block(-7,6,-5,SANDSTONE:0)
Block(-7,6,-4,SANDSTONE:0)
Block(-7,6,-3,SANDSTONE:0)
Block(-7,6,-2,SANDSTONE:0)
Block(-7,6,-1,SANDSTONE:0)
Block(-7,6,0,SANDSTONE:0)
Block(-7,6,1,SANDSTONE:0)
Block(-7,6,2,SANDSTONE:0)
Block(-7,6,3,SANDSTONE:0)
Block(-7,6,4,SANDSTONE:0)
Block(-7,6,5,SANDSTONE:0)
Block(-7,6,6,SANDSTONE:0)
Block(-7,6,7,SANDSTONE:0)
Block(-7,6,8,SANDSTONE:0)
Block(-7,7,-7,SANDSTONE:0)
Block(-7,7,-6,SANDSTONE:0)
Block(-7,7,-5,SANDSTONE:0)
Block(-7,7,-4,SANDSTONE:0)
Block(-7,7,-3,SANDSTONE:0)
Block(-7,7,-2,SANDSTONE:0)
Block(-7,7,-1,SANDSTONE:0)
Block(-7,7,0,SANDSTONE:0)
Block(-7,7,1,SANDSTONE:0)
Block(-7,7,2,SANDSTONE:0)
Block(-7,7,3,SANDSTONE:0)
Block(-7,7,4,SANDSTONE:0)
Block(-7,7,5,SANDSTONE:0)
Block(-7,7,6,SANDSTONE:0)
Block(-7,7,7,SANDSTONE:0)
Block(-7,7,8,SANDSTONE:0)
Block(-7,8,-7,SANDSTONE:0)
Block(-7,8,-6,SANDSTONE:0)
Block(-7,8,-5,SANDSTONE:0)
Block(-7,8,-4,SANDSTONE:0)
Block(-7,8,-3,SANDSTONE:0)
Block(-7,8,-2,SANDSTONE:0)
Block(-7,8,-1,SANDSTONE:0)
Block(-7,8,0,SANDSTONE:0)
Block(-7,8,1,SANDSTONE:0)
Block(-7,8,2,SANDSTONE:0)
Block(-7,8,3,SANDSTONE:0)
Block(-7,8,4,SANDSTONE:0)
Block(-7,8,5,SANDSTONE:0)
Block(-7,8,6,SANDSTONE:0)
Block(-7,8,7,SANDSTONE:0)
Block(-7,8,8,SANDSTONE:0)
Block(-7,9,-7,SANDSTONE:0)
Block(-7,9,-6,SANDSTONE:0)
Block(-7,9,-5,SANDSTONE:0)
Block(-7,9,-4,SANDSTONE:0)
Block(-7,9,-3,SANDSTONE:0)
Block(-7,9,-2,SANDSTONE:0)
Block(-7,9,-1,SANDSTONE:0)
Block(-7,9,0,SANDSTONE:0)
Block(-7,9,1,SANDSTONE:0)
Block(-7,9,2,SANDSTONE:0)
Block(-7,9,3,SANDSTONE:0)
Block(-7,9,4,SANDSTONE:0)
Block(-7,9,5,SANDSTONE:0)
Block(-7,9,6,SANDSTONE:0)
Block(-7,9,7,SANDSTONE:0)
Block(-7,9,8,SANDSTONE:0)
Block(-7,10,-7,SANDSTONE:0)
Block(-7,10,-6,SANDSTONE:0)
Block(-7,10,-5,SANDSTONE:0)
Block(-7,10,-4,SANDSTONE:0)
Block(-7,10,-3,SANDSTONE:0)
Block(-7,10,-2,SANDSTONE:0)
Block(-7,10,-1,SANDSTONE:0)
Block(-7,10,0,SANDSTONE:0)
Block(-7,10,1,SANDSTONE:0)
Block(-7,10,2,SANDSTONE:0)
Block(-7,10,3,SANDSTONE:0)
Block(-7,10,4,SANDSTONE:0)
Block(-7,10,5,SANDSTONE:0)
Block(-7,10,6,SANDSTONE:0)
Block(-7,10,7,SANDSTONE:0)
Block(-7,10,8,SANDSTONE:0)
Block(-7,11,-7,SANDSTONE:0)
Block(-7,11,-6,SANDSTONE:0)
Block(-7,11,-5,SANDSTONE:0)
Block(-7,11,-4,SANDSTONE:0)
Block(-7,11,-3,SANDSTONE:0)
Block(-7,11,-2,SANDSTONE:0)
Block(-7,11,-1,SANDSTONE:0)
Block(-7,11,0,SANDSTONE:0)
Block(-7,11,1,SANDSTONE:0)
Block(-7,11,2,SANDSTONE:0)
Block(-7,11,3,SANDSTONE:0)
Block(-7,11,4,SANDSTONE:0)
Block(-7,11,5,SANDSTONE:0)
Block(-7,11,6,SANDSTONE:0)
Block(-7,11,7,SANDSTONE:0)
Block(-7,11,8,SANDSTONE:0)
RandomBlock(-7,12,-7,SAND:0,50,SANDSTONE:0,100)
Block(-7,12,-6,SANDSTONE:0)
Block(-7,12,-5,SANDSTONE:0)
Block(-7,12,-4,SANDSTONE:0)
Block(-7,12,-3,SANDSTONE:0)
Block(-7,12,-2,SANDSTONE:0)
RandomBlock(-7,12,-1,SAND:0,50,SANDSTONE:0,100)
RandomBlock(-7,12,0,SAND:0,50,SANDSTONE:0,100)
Block(-7,12,1,SANDSTONE:0)
Block(-7,12,2,SANDSTONE:0)
Block(-7,12,3,SANDSTONE:0)
Block(-7,12,4,SANDSTONE:0)
Block(-7,12,5,SANDSTONE:0)
Block(-7,12,6,SANDSTONE:0)
Block(-7,12,7,SANDSTONE:0)
Block(-7,12,8,SANDSTONE:0)
RandomBlock(-7,13,-7,SAND:0,50,SANDSTONE:0,100)
RandomBlock(-7,13,-6,SAND:0,50,SANDSTONE:0,100)
Block(-7,13,-5,SANDSTONE:0)
Block(-7,13,-4,SANDSTONE:0)
Block(-7,13,-3,SANDSTONE:0)
RandomBlock(-7,13,-2,SAND:0,50,SANDSTONE:0,100)
RandomBlock(-7,13,-1,SAND:0,50,SANDSTONE:0,100)
RandomBlock(-7,13,0,SAND:0,50,SANDSTONE:0,100)
RandomBlock(-7,13,1,SAND:0,50,SANDSTONE:0,100)
RandomBlock(-7,13,2,SAND:0,50,SANDSTONE:0,100)
Block(-7,13,3,SANDSTONE:0)
Block(-7,13,4,SANDSTONE:0)
Block(-7,13,5,SANDSTONE:0)
Block(-7,13,6,SANDSTONE:0)
Block(-7,13,7,SANDSTONE:0)
Block(-7,13,8,SANDSTONE:0)
RandomBlock(-7,14,-7,SAND:0,50,SANDSTONE:0,100)
RandomBlock(-7,14,-6,SAND:0,50,SANDSTONE:0,100)
RandomBlock(-7,14,-5,SAND:0,50,SANDSTONE:0,100)
RandomBlock(-7,14,-4,SAND:0,50,SANDSTONE:0,100)
RandomBlock(-7,14,-3,SAND:0,50,SANDSTONE:0,100)
RandomBlock(-7,14,-2,SAND:0,50,SANDSTONE:0,100)
RandomBlock(-7,14,-1,SAND:0,50,SANDSTONE:0,100)
RandomBlock(-7,14,0,SAND:0,50,SANDSTONE:0,100)
RandomBlock(-7,14,1,SAND:0,50,SANDSTONE:0,100)
RandomBlock(-7,14,2,SAND:0,50,SANDSTONE:0,100)
Block(-7,14,3,SANDSTONE:0)
Block(-7,14,4,SANDSTONE:0)
Block(-7,14,5,SANDSTONE:0)
Block(-7,14,6,SANDSTONE:0)
Block(-7,14,7,SANDSTONE:0)
Block(-7,14,8,SANDSTONE:0)
RandomBlock(-7,15,-7,SAND:0,50,SANDSTONE:0,100)
RandomBlock(-7,15,-6,SAND:0,50,SANDSTONE:0,100)
RandomBlock(-7,15,-5,SAND:0,50,SANDSTONE:0,100)
RandomBlock(-7,15,-4,SAND:0,50,SANDSTONE:0,100)
RandomBlock(-7,15,-3,SAND:0,50,SANDSTONE:0,100)
RandomBlock(-7,15,-2,SAND:0,50,SANDSTONE:0,100)
RandomBlock(-7,15,-1,SAND:0,50,SANDSTONE:0,100)
RandomBlock(-7,15,0,SAND:0,50,SANDSTONE:0,100)
RandomBlock(-7,15,1,SAND:0,50,SANDSTONE:0,100)
RandomBlock(-7,15,2,SAND:0,50,SANDSTONE:0,100)
RandomBlock(-7,15,3,SAND:0,50,SANDSTONE:0,100)
RandomBlock(-7,15,4,SAND:0,50,SANDSTONE:0,100)
RandomBlock(-7,15,5,SAND:0,50,SANDSTONE:0,100)
Block(-7,15,6,SANDSTONE:0)
Block(-7,15,7,SANDSTONE:0)
Block(-7,15,8,SANDSTONE:0)
RandomBlock(-7,16,-6,SAND:0,50,SANDSTONE:0,100)
RandomBlock(-7,16,-5,SAND:0,50,SANDSTONE:0,100)
RandomBlock(-7,16,-4,SAND:0,50,SANDSTONE:0,100)
RandomBlock(-7,16,-3,SAND:0,50,SANDSTONE:0,100)
RandomBlock(-7,16,-2,SAND:0,50,SANDSTONE:0,100)
RandomBlock(-7,16,-1,SAND:0,50,SANDSTONE:0,100)
RandomBlock(-7,16,0,SAND:0,50,SANDSTONE:0,100)
RandomBlock(-7,16,1,SAND:0,50,SANDSTONE:0,100)
RandomBlock(-7,16,2,SAND:0,50,SANDSTONE:0,100)
RandomBlock(-7,16,3,SAND:0,50,SANDSTONE:0,100)
RandomBlock(-7,16,4,SAND:0,50,SANDSTONE:0,100)
RandomBlock(-7,16,5,SAND:0,50,SANDSTONE:0,100)
RandomBlock(-7,16,6,SAND:0,50,SANDSTONE:0,100)
Block(-7,16,7,SANDSTONE:0)
Block(-7,16,8,SANDSTONE:0)
RandomBlock(-7,17,-5,SAND:0,50,SANDSTONE:0,100)
RandomBlock(-7,17,-4,SAND:0,50,SANDSTONE:0,100)
RandomBlock(-7,17,-3,SAND:0,50,SANDSTONE:0,100)
RandomBlock(-7,17,-2,SAND:0,50,SANDSTONE:0,100)
RandomBlock(-7,17,-1,SAND:0,50,SANDSTONE:0,100)
RandomBlock(-7,17,0,SAND:0,50,SANDSTONE:0,100)
RandomBlock(-7,17,1,SAND:0,50,SANDSTONE:0,100)
RandomBlock(-7,17,2,SAND:0,50,SANDSTONE:0,100)
RandomBlock(-7,17,3,SAND:0,50,SANDSTONE:0,100)
RandomBlock(-7,17,4,SAND:0,50,SANDSTONE:0,100)
RandomBlock(-7,17,5,SAND:0,50,SANDSTONE:0,100)
RandomBlock(-7,17,6,SAND:0,50,SANDSTONE:0,100)
RandomBlock(-7,17,7,SAND:0,50,SANDSTONE:0,100)
Block(-7,17,8,SANDSTONE:0)
RandomBlock(-7,18,-3,SAND:0,50,SANDSTONE:0,100)
RandomBlock(-7,18,-2,SAND:0,50,SANDSTONE:0,100)
RandomBlock(-7,18,-1,SAND:0,50,SANDSTONE:0,100)
RandomBlock(-7,18,0,SAND:0,50,SANDSTONE:0,100)
RandomBlock(-7,18,1,SAND:0,50,SANDSTONE:0,100)
RandomBlock(-7,18,2,SAND:0,50,SANDSTONE:0,100)
RandomBlock(-7,18,3,SAND:0,50,SANDSTONE:0,100)
RandomBlock(-7,18,4,SAND:0,50,SANDSTONE:0,100)
RandomBlock(-7,18,5,SAND:0,50,SANDSTONE:0,100)
RandomBlock(-7,18,6,SAND:0,50,SANDSTONE:0,100)
RandomBlock(-7,18,7,SAND:0,50,SANDSTONE:0,100)
RandomBlock(-7,18,8,SAND:0,50,SANDSTONE:0,100)
RandomBlock(-7,19,-3,SAND:0,50,SANDSTONE:0,100)
RandomBlock(-7,19,-2,SAND:0,50,SANDSTONE:0,100)
RandomBlock(-7,19,-1,SAND:0,50,SANDSTONE:0,100)
RandomBlock(-7,19,0,SAND:0,50,SANDSTONE:0,100)
RandomBlock(-7,19,1,SAND:0,50,SANDSTONE:0,100)
RandomBlock(-7,19,2,SAND:0,50,SANDSTONE:0,100)
RandomBlock(-7,19,3,SAND:0,50,SANDSTONE:0,100)
RandomBlock(-7,19,4,SAND:0,50,SANDSTONE:0,100)
RandomBlock(-7,19,5,SAND:0,50,SANDSTONE:0,100)
RandomBlock(-7,19,6,SAND:0,50,SANDSTONE:0,100)
RandomBlock(-7,19,7,SAND:0,50,SANDSTONE:0,100)
RandomBlock(-7,19,8,SAND:0,50,SANDSTONE:0,100)
RandomBlock(-7,20,-1,SAND:0,50,SANDSTONE:0,100)
RandomBlock(-7,20,0,SAND:0,50,SANDSTONE:0,100)
RandomBlock(-7,20,1,SAND:0,50,SANDSTONE:0,100)
RandomBlock(-7,20,2,SAND:0,50,SANDSTONE:0,100)
RandomBlock(-7,20,3,SAND:0,50,SANDSTONE:0,100)
RandomBlock(-7,20,4,SAND:0,50,SANDSTONE:0,100)
RandomBlock(-7,20,5,SAND:0,50,SANDSTONE:0,100)
RandomBlock(-7,20,6,SAND:0,50,SANDSTONE:0,100)
RandomBlock(-7,20,7,SAND:0,50,SANDSTONE:0,100)
RandomBlock(-7,20,8,SAND:0,50,SANDSTONE:0,100)
RandomBlock(-7,21,-1,SAND:0,50,SANDSTONE:0,100)
RandomBlock(-7,21,0,SAND:0,50,SANDSTONE:0,100)
RandomBlock(-7,21,1,SAND:0,50,SANDSTONE:0,100)
RandomBlock(-7,21,2,SAND:0,50,SANDSTONE:0,100)
RandomBlock(-7,21,3,SAND:0,50,SANDSTONE:0,100)
RandomBlock(-7,21,4,SAND:0,50,SANDSTONE:0,100)
RandomBlock(-7,21,5,SAND:0,50,SANDSTONE:0,100)
RandomBlock(-7,21,6,SAND:0,50,SANDSTONE:0,100)
RandomBlock(-7,21,7,SAND:0,50,SANDSTONE:0,100)
RandomBlock(-7,21,8,SAND:0,50,SANDSTONE:0,100)
RandomBlock(-7,22,2,SAND:0,50,SANDSTONE:0,100)
RandomBlock(-7,22,3,SAND:0,50,SANDSTONE:0,100)
RandomBlock(-7,22,4,SAND:0,50,SANDSTONE:0,100)
RandomBlock(-7,22,5,SAND:0,50,SANDSTONE:0,100)
RandomBlock(-7,22,6,SAND:0,50,SANDSTONE:0,100)
RandomBlock(-7,22,7,SAND:0,50,SANDSTONE:0,100)
RandomBlock(-7,22,8,SAND:0,50,SANDSTONE:0,100)
RandomBlock(-7,23,3,SAND:0,50,SANDSTONE:0,100)
RandomBlock(-7,23,4,SAND:0,50,SANDSTONE:0,100)
RandomBlock(-7,23,5,SAND:0,50,SANDSTONE:0,100)
RandomBlock(-7,23,6,SAND:0,50,SANDSTONE:0,100)
RandomBlock(-7,23,7,SAND:0,50,SANDSTONE:0,100)
RandomBlock(-7,23,8,SAND:0,50,SANDSTONE:0,100)
RandomBlock(-7,24,3,SAND:0,50,SANDSTONE:0,100)
RandomBlock(-7,24,4,SAND:0,50,SANDSTONE:0,100)
RandomBlock(-7,24,5,SAND:0,50,SANDSTONE:0,100)
RandomBlock(-7,24,6,SAND:0,50,SANDSTONE:0,100)
RandomBlock(-7,24,7,SAND:0,50,SANDSTONE:0,100)
RandomBlock(-7,24,8,SAND:0,50,SANDSTONE:0,100)
RandomBlock(-7,25,6,SAND:0,50,SANDSTONE:0,100)
RandomBlock(-7,25,7,SAND:0,50,SANDSTONE:0,100)
RandomBlock(-7,25,8,SAND:0,50,SANDSTONE:0,100)
Block(-6,0,-7,SANDSTONE:0)
Block(-6,0,-6,SANDSTONE:0)
Block(-6,0,-5,SANDSTONE:0)
Block(-6,0,-4,SANDSTONE:0)
Block(-6,0,-3,SANDSTONE:0)
Block(-6,0,-2,SANDSTONE:0)
Block(-6,0,-1,SANDSTONE:0)
Block(-6,0,0,SANDSTONE:0)
Block(-6,0,1,SANDSTONE:0)
Block(-6,0,2,SANDSTONE:0)
Block(-6,0,3,SANDSTONE:0)
Block(-6,0,4,SANDSTONE:0)
Block(-6,0,5,SANDSTONE:0)
Block(-6,0,6,SANDSTONE:0)
Block(-6,0,7,SANDSTONE:0)
Block(-6,0,8,SANDSTONE:0)
Block(-6,1,-7,SANDSTONE:0)
Block(-6,1,-6,SANDSTONE:0)
Block(-6,1,-5,SANDSTONE:0)
Block(-6,1,-4,SANDSTONE:0)
Block(-6,1,-3,SANDSTONE:0)
Block(-6,1,-2,SANDSTONE:0)
Block(-6,1,-1,SANDSTONE:0)
Block(-6,1,0,SANDSTONE:0)
Block(-6,1,1,SANDSTONE:0)
Block(-6,1,2,SANDSTONE:0)
Block(-6,1,3,SANDSTONE:0)
Block(-6,1,4,SANDSTONE:0)
Block(-6,1,5,SANDSTONE:0)
Block(-6,1,6,SANDSTONE:0)
Block(-6,1,7,SANDSTONE:0)
Block(-6,1,8,SANDSTONE:0)
Block(-6,2,-7,SANDSTONE:0)
Block(-6,2,-6,SANDSTONE:0)
Block(-6,2,-5,SANDSTONE:0)
Block(-6,2,-4,SANDSTONE:0)
Block(-6,2,-3,SANDSTONE:0)
Block(-6,2,-2,SANDSTONE:0)
Block(-6,2,-1,SANDSTONE:0)
Block(-6,2,0,SANDSTONE:0)
Block(-6,2,1,SANDSTONE:0)
Block(-6,2,2,SANDSTONE:0)
Block(-6,2,3,SANDSTONE:0)
Block(-6,2,4,SANDSTONE:0)
Block(-6,2,5,SANDSTONE:0)
Block(-6,2,6,SANDSTONE:0)
Block(-6,2,7,SANDSTONE:0)
Block(-6,2,8,SANDSTONE:0)
Block(-6,3,-7,SANDSTONE:0)
Block(-6,3,-6,SANDSTONE:0)
Block(-6,3,-5,SANDSTONE:0)
Block(-6,3,-4,SANDSTONE:0)
Block(-6,3,-3,SANDSTONE:0)
Block(-6,3,-2,SANDSTONE:0)
Block(-6,3,-1,SANDSTONE:0)
Block(-6,3,0,SANDSTONE:0)
Block(-6,3,1,SANDSTONE:0)
Block(-6,3,2,SANDSTONE:0)
Block(-6,3,3,SANDSTONE:0)
Block(-6,3,4,SANDSTONE:0)
Block(-6,3,5,SANDSTONE:0)
Block(-6,3,6,SANDSTONE:0)
Block(-6,3,7,SANDSTONE:0)
Block(-6,3,8,SANDSTONE:0)
Block(-6,4,-7,SANDSTONE:0)
Block(-6,4,-6,SANDSTONE:0)
Block(-6,4,-5,SANDSTONE:0)
Block(-6,4,-4,SANDSTONE:0)
Block(-6,4,-3,SANDSTONE:0)
Block(-6,4,-2,SANDSTONE:0)
Block(-6,4,-1,SANDSTONE:0)
Block(-6,4,0,SANDSTONE:0)
Block(-6,4,1,SANDSTONE:0)
Block(-6,4,2,SANDSTONE:0)
Block(-6,4,3,SANDSTONE:0)
Block(-6,4,4,SANDSTONE:0)
Block(-6,4,5,SANDSTONE:0)
Block(-6,4,6,SANDSTONE:0)
Block(-6,4,7,SANDSTONE:0)
Block(-6,4,8,SANDSTONE:0)
Block(-6,5,-7,SANDSTONE:0)
Block(-6,5,-6,SANDSTONE:0)
Block(-6,5,-5,SANDSTONE:0)
Block(-6,5,-4,SANDSTONE:0)
Block(-6,5,-3,SANDSTONE:0)
Block(-6,5,-2,SANDSTONE:0)
Block(-6,5,-1,SANDSTONE:0)
Block(-6,5,0,SANDSTONE:0)
Block(-6,5,1,SANDSTONE:0)
Block(-6,5,2,SANDSTONE:0)
Block(-6,5,3,SANDSTONE:0)
Block(-6,5,4,SANDSTONE:0)
Block(-6,5,5,SANDSTONE:0)
Block(-6,5,6,SANDSTONE:0)
Block(-6,5,7,SANDSTONE:0)
Block(-6,5,8,SANDSTONE:0)
Block(-6,6,-7,SANDSTONE:0)
Block(-6,6,-6,SANDSTONE:0)
Block(-6,6,-5,SANDSTONE:0)
Block(-6,6,-4,SANDSTONE:0)
Block(-6,6,-3,SANDSTONE:0)
Block(-6,6,-2,SANDSTONE:0)
Block(-6,6,-1,SANDSTONE:0)
Block(-6,6,0,SANDSTONE:0)
Block(-6,6,1,SANDSTONE:0)
Block(-6,6,2,SANDSTONE:0)
Block(-6,6,3,SANDSTONE:0)
Block(-6,6,4,SANDSTONE:0)
Block(-6,6,5,SANDSTONE:0)
Block(-6,6,6,SANDSTONE:0)
Block(-6,6,7,SANDSTONE:0)
Block(-6,6,8,SANDSTONE:0)
Block(-6,7,-7,SANDSTONE:0)
Block(-6,7,-6,SANDSTONE:0)
Block(-6,7,-5,SANDSTONE:0)
Block(-6,7,-4,SANDSTONE:0)
Block(-6,7,-3,SANDSTONE:0)
Block(-6,7,-2,SANDSTONE:0)
Block(-6,7,-1,SANDSTONE:0)
Block(-6,7,0,SANDSTONE:0)
Block(-6,7,1,SANDSTONE:0)
Block(-6,7,2,SANDSTONE:0)
Block(-6,7,3,SANDSTONE:0)
Block(-6,7,4,SANDSTONE:0)
Block(-6,7,5,SANDSTONE:0)
Block(-6,7,6,SANDSTONE:0)
Block(-6,7,7,SANDSTONE:0)
Block(-6,7,8,SANDSTONE:0)
Block(-6,8,-7,SANDSTONE:0)
Block(-6,8,-6,SANDSTONE:0)
Block(-6,8,-5,SANDSTONE:0)
Block(-6,8,-4,SANDSTONE:0)
Block(-6,8,-3,SANDSTONE:0)
Block(-6,8,-2,SANDSTONE:0)
Block(-6,8,-1,SANDSTONE:0)
Block(-6,8,0,SANDSTONE:0)
Block(-6,8,1,SANDSTONE:0)
Block(-6,8,2,SANDSTONE:0)
Block(-6,8,3,SANDSTONE:0)
Block(-6,8,4,SANDSTONE:0)
Block(-6,8,5,SANDSTONE:0)
Block(-6,8,6,SANDSTONE:0)
Block(-6,8,7,SANDSTONE:0)
Block(-6,8,8,SANDSTONE:0)
Block(-6,9,-7,SANDSTONE:0)
Block(-6,9,-6,SANDSTONE:0)
Block(-6,9,-5,SANDSTONE:0)
Block(-6,9,-4,SANDSTONE:0)
Block(-6,9,-3,SANDSTONE:0)
Block(-6,9,-2,SANDSTONE:0)
Block(-6,9,-1,SANDSTONE:0)
Block(-6,9,0,SANDSTONE:0)
Block(-6,9,1,SANDSTONE:0)
Block(-6,9,2,SANDSTONE:0)
Block(-6,9,3,SANDSTONE:0)
Block(-6,9,4,SANDSTONE:0)
Block(-6,9,5,SANDSTONE:0)
Block(-6,9,6,SANDSTONE:0)
Block(-6,9,7,SANDSTONE:0)
Block(-6,9,8,SANDSTONE:0)
Block(-6,10,-7,SANDSTONE:0)
Block(-6,10,-6,SANDSTONE:0)
Block(-6,10,-5,SANDSTONE:0)
Block(-6,10,-4,SANDSTONE:0)
Block(-6,10,-3,SANDSTONE:0)
Block(-6,10,-2,SANDSTONE:0)
Block(-6,10,-1,SANDSTONE:0)
Block(-6,10,0,SANDSTONE:0)
Block(-6,10,1,SANDSTONE:0)
Block(-6,10,2,SANDSTONE:0)
Block(-6,10,3,SANDSTONE:0)
Block(-6,10,4,SANDSTONE:0)
Block(-6,10,5,SANDSTONE:0)
Block(-6,10,6,SANDSTONE:0)
Block(-6,10,7,SANDSTONE:0)
Block(-6,10,8,SANDSTONE:0)
Block(-6,11,-7,SANDSTONE:0)
Block(-6,11,-6,SANDSTONE:0)
Block(-6,11,-5,SANDSTONE:0)
Block(-6,11,-4,SANDSTONE:0)
Block(-6,11,-3,SANDSTONE:0)
Block(-6,11,-2,SANDSTONE:0)
Block(-6,11,-1,SANDSTONE:0)
Block(-6,11,0,SANDSTONE:0)
Block(-6,11,1,SANDSTONE:0)
Block(-6,11,2,SANDSTONE:0)
Block(-6,11,3,SANDSTONE:0)
Block(-6,11,4,SANDSTONE:0)
Block(-6,11,5,SANDSTONE:0)
Block(-6,11,6,SANDSTONE:0)
Block(-6,11,7,SANDSTONE:0)
Block(-6,11,8,SANDSTONE:0)
RandomBlock(-6,12,-7,SAND:0,50,SANDSTONE:0,100)
Block(-6,12,-6,SANDSTONE:0)
Block(-6,12,-5,SANDSTONE:0)
Block(-6,12,-4,SANDSTONE:0)
Block(-6,12,-3,SANDSTONE:0)
Block(-6,12,-2,SANDSTONE:0)
Block(-6,12,-1,SANDSTONE:0)
Block(-6,12,0,SANDSTONE:0)
Block(-6,12,1,SANDSTONE:0)
Block(-6,12,2,SANDSTONE:0)
Block(-6,12,3,SANDSTONE:0)
Block(-6,12,4,SANDSTONE:0)
Block(-6,12,5,SANDSTONE:0)
Block(-6,12,6,SANDSTONE:0)
Block(-6,12,7,SANDSTONE:0)
Block(-6,12,8,SANDSTONE:0)
RandomBlock(-6,13,-7,SAND:0,50,SANDSTONE:0,100)
RandomBlock(-6,13,-6,SAND:0,50,SANDSTONE:0,100)
Block(-6,13,-5,SANDSTONE:0)
Block(-6,13,-4,SANDSTONE:0)
Block(-6,13,-3,SANDSTONE:0)
Block(-6,13,-2,SANDSTONE:0)
Block(-6,13,-1,SANDSTONE:0)
RandomBlock(-6,13,0,SAND:0,50,SANDSTONE:0,100)
Block(-6,13,1,SANDSTONE:0)
Block(-6,13,2,SANDSTONE:0)
Block(-6,13,3,SANDSTONE:0)
Block(-6,13,4,SANDSTONE:0)
Block(-6,13,5,SANDSTONE:0)
Block(-6,13,6,SANDSTONE:0)
Block(-6,13,7,SANDSTONE:0)
Block(-6,13,8,SANDSTONE:0)
RandomBlock(-6,14,-7,SAND:0,50,SANDSTONE:0,100)
RandomBlock(-6,14,-6,SAND:0,50,SANDSTONE:0,100)
RandomBlock(-6,14,-5,SAND:0,50,SANDSTONE:0,100)
Block(-6,14,-4,SANDSTONE:0)
RandomBlock(-6,14,-3,SAND:0,50,SANDSTONE:0,100)
RandomBlock(-6,14,-2,SAND:0,50,SANDSTONE:0,100)
RandomBlock(-6,14,-1,SAND:0,50,SANDSTONE:0,100)
RandomBlock(-6,14,0,SAND:0,50,SANDSTONE:0,100)
RandomBlock(-6,14,1,SAND:0,50,SANDSTONE:0,100)
Block(-6,14,2,SANDSTONE:0)
Block(-6,14,3,SANDSTONE:0)
Block(-6,14,4,SANDSTONE:0)
Block(-6,14,5,SANDSTONE:0)
Block(-6,14,6,SANDSTONE:0)
Block(-6,14,7,SANDSTONE:0)
Block(-6,14,8,SANDSTONE:0)
RandomBlock(-6,15,-6,SAND:0,50,SANDSTONE:0,100)
RandomBlock(-6,15,-5,SAND:0,50,SANDSTONE:0,100)
RandomBlock(-6,15,-4,SAND:0,50,SANDSTONE:0,100)
RandomBlock(-6,15,-3,SAND:0,50,SANDSTONE:0,100)
RandomBlock(-6,15,-2,SAND:0,50,SANDSTONE:0,100)
RandomBlock(-6,15,-1,SAND:0,50,SANDSTONE:0,100)
RandomBlock(-6,15,0,SAND:0,50,SANDSTONE:0,100)
RandomBlock(-6,15,1,SAND:0,50,SANDSTONE:0,100)
RandomBlock(-6,15,2,SAND:0,50,SANDSTONE:0,100)
RandomBlock(-6,15,3,SAND:0,50,SANDSTONE:0,100)
Block(-6,15,4,SANDSTONE:0)
Block(-6,15,5,SANDSTONE:0)
Block(-6,15,6,SANDSTONE:0)
Block(-6,15,7,SANDSTONE:0)
Block(-6,15,8,SANDSTONE:0)
RandomBlock(-6,16,-6,SAND:0,50,SANDSTONE:0,100)
RandomBlock(-6,16,-5,SAND:0,50,SANDSTONE:0,100)
RandomBlock(-6,16,-4,SAND:0,50,SANDSTONE:0,100)
RandomBlock(-6,16,-3,SAND:0,50,SANDSTONE:0,100)
RandomBlock(-6,16,-2,SAND:0,50,SANDSTONE:0,100)
RandomBlock(-6,16,-1,SAND:0,50,SANDSTONE:0,100)
RandomBlock(-6,16,0,SAND:0,50,SANDSTONE:0,100)
RandomBlock(-6,16,1,SAND:0,50,SANDSTONE:0,100)
RandomBlock(-6,16,2,SAND:0,50,SANDSTONE:0,100)
RandomBlock(-6,16,3,SAND:0,50,SANDSTONE:0,100)
RandomBlock(-6,16,4,SAND:0,50,SANDSTONE:0,100)
RandomBlock(-6,16,5,SAND:0,50,SANDSTONE:0,100)
Block(-6,16,6,SANDSTONE:0)
Block(-6,16,7,SANDSTONE:0)
Block(-6,16,8,SANDSTONE:0)
RandomBlock(-6,17,-5,SAND:0,50,SANDSTONE:0,100)
RandomBlock(-6,17,-4,SAND:0,50,SANDSTONE:0,100)
RandomBlock(-6,17,-3,SAND:0,50,SANDSTONE:0,100)
RandomBlock(-6,17,-2,SAND:0,50,SANDSTONE:0,100)
RandomBlock(-6,17,-1,SAND:0,50,SANDSTONE:0,100)
RandomBlock(-6,17,0,SAND:0,50,SANDSTONE:0,100)
RandomBlock(-6,17,1,SAND:0,50,SANDSTONE:0,100)
RandomBlock(-6,17,2,SAND:0,50,SANDSTONE:0,100)
RandomBlock(-6,17,3,SAND:0,50,SANDSTONE:0,100)
RandomBlock(-6,17,4,SAND:0,50,SANDSTONE:0,100)
RandomBlock(-6,17,5,SAND:0,50,SANDSTONE:0,100)
RandomBlock(-6,17,6,SAND:0,50,SANDSTONE:0,100)
RandomBlock(-6,17,7,SAND:0,50,SANDSTONE:0,100)
Block(-6,17,8,SANDSTONE:0)
RandomBlock(-6,18,-3,SAND:0,50,SANDSTONE:0,100)
RandomBlock(-6,18,-2,SAND:0,50,SANDSTONE:0,100)
RandomBlock(-6,18,-1,SAND:0,50,SANDSTONE:0,100)
RandomBlock(-6,18,0,SAND:0,50,SANDSTONE:0,100)
RandomBlock(-6,18,1,SAND:0,50,SANDSTONE:0,100)
RandomBlock(-6,18,2,SAND:0,50,SANDSTONE:0,100)
RandomBlock(-6,18,3,SAND:0,50,SANDSTONE:0,100)
RandomBlock(-6,18,4,SAND:0,50,SANDSTONE:0,100)
RandomBlock(-6,18,5,SAND:0,50,SANDSTONE:0,100)
RandomBlock(-6,18,6,SAND:0,50,SANDSTONE:0,100)
RandomBlock(-6,18,7,SAND:0,50,SANDSTONE:0,100)
Block(-6,18,8,SANDSTONE:0)
RandomBlock(-6,19,-3,SAND:0,50,SANDSTONE:0,100)
RandomBlock(-6,19,-2,SAND:0,50,SANDSTONE:0,100)
RandomBlock(-6,19,-1,SAND:0,50,SANDSTONE:0,100)
RandomBlock(-6,19,0,SAND:0,50,SANDSTONE:0,100)
RandomBlock(-6,19,1,SAND:0,50,SANDSTONE:0,100)
RandomBlock(-6,19,2,SAND:0,50,SANDSTONE:0,100)
RandomBlock(-6,19,3,SAND:0,50,SANDSTONE:0,100)
RandomBlock(-6,19,4,SAND:0,50,SANDSTONE:0,100)
RandomBlock(-6,19,5,SAND:0,50,SANDSTONE:0,100)
RandomBlock(-6,19,6,SAND:0,50,SANDSTONE:0,100)
Block(-6,19,7,SANDSTONE:0)
RandomBlock(-6,19,8,SAND:0,50,SANDSTONE:0,100)
RandomBlock(-6,20,-1,SAND:0,50,SANDSTONE:0,100)
RandomBlock(-6,20,0,SAND:0,50,SANDSTONE:0,100)
RandomBlock(-6,20,1,SAND:0,50,SANDSTONE:0,100)
RandomBlock(-6,20,2,SAND:0,50,SANDSTONE:0,100)
RandomBlock(-6,20,3,SAND:0,50,SANDSTONE:0,100)
RandomBlock(-6,20,4,SAND:0,50,SANDSTONE:0,100)
RandomBlock(-6,20,5,SAND:0,50,SANDSTONE:0,100)
RandomBlock(-6,20,6,SAND:0,50,SANDSTONE:0,100)
RandomBlock(-6,20,7,SAND:0,50,SANDSTONE:0,100)
RandomBlock(-6,20,8,SAND:0,50,SANDSTONE:0,100)
RandomBlock(-6,21,-1,SAND:0,50,SANDSTONE:0,100)
RandomBlock(-6,21,0,SAND:0,50,SANDSTONE:0,100)
RandomBlock(-6,21,1,SAND:0,50,SANDSTONE:0,100)
RandomBlock(-6,21,2,SAND:0,50,SANDSTONE:0,100)
RandomBlock(-6,21,3,SAND:0,50,SANDSTONE:0,100)
RandomBlock(-6,21,4,SAND:0,50,SANDSTONE:0,100)
RandomBlock(-6,21,5,SAND:0,50,SANDSTONE:0,100)
RandomBlock(-6,21,6,SAND:0,50,SANDSTONE:0,100)
RandomBlock(-6,21,7,SAND:0,50,SANDSTONE:0,100)
RandomBlock(-6,21,8,SAND:0,50,SANDSTONE:0,100)
RandomBlock(-6,22,1,SAND:0,50,SANDSTONE:0,100)
RandomBlock(-6,22,2,SAND:0,50,SANDSTONE:0,100)
RandomBlock(-6,22,3,SAND:0,50,SANDSTONE:0,100)
RandomBlock(-6,22,4,SAND:0,50,SANDSTONE:0,100)
RandomBlock(-6,22,5,SAND:0,50,SANDSTONE:0,100)
RandomBlock(-6,22,6,SAND:0,50,SANDSTONE:0,100)
RandomBlock(-6,22,7,SAND:0,50,SANDSTONE:0,100)
RandomBlock(-6,22,8,SAND:0,50,SANDSTONE:0,100)
RandomBlock(-6,23,2,SAND:0,50,SANDSTONE:0,100)
RandomBlock(-6,23,3,SAND:0,50,SANDSTONE:0,100)
RandomBlock(-6,23,4,SAND:0,50,SANDSTONE:0,100)
RandomBlock(-6,23,5,SAND:0,50,SANDSTONE:0,100)
RandomBlock(-6,23,6,SAND:0,50,SANDSTONE:0,100)
RandomBlock(-6,23,7,SAND:0,50,SANDSTONE:0,100)
RandomBlock(-6,23,8,SAND:0,50,SANDSTONE:0,100)
RandomBlock(-6,24,2,SAND:0,50,SANDSTONE:0,100)
RandomBlock(-6,24,3,SAND:0,50,SANDSTONE:0,100)
RandomBlock(-6,24,4,SAND:0,50,SANDSTONE:0,100)
RandomBlock(-6,24,5,SAND:0,50,SANDSTONE:0,100)
RandomBlock(-6,24,6,SAND:0,50,SANDSTONE:0,100)
RandomBlock(-6,24,7,SAND:0,50,SANDSTONE:0,100)
RandomBlock(-6,24,8,SAND:0,50,SANDSTONE:0,100)
RandomBlock(-6,25,5,SAND:0,50,SANDSTONE:0,100)
RandomBlock(-6,25,6,SAND:0,50,SANDSTONE:0,100)
RandomBlock(-6,25,7,SAND:0,50,SANDSTONE:0,100)
RandomBlock(-6,25,8,SAND:0,50,SANDSTONE:0,100)
RandomBlock(-6,26,6,SAND:0,50,SANDSTONE:0,100)
RandomBlock(-6,26,7,SAND:0,50,SANDSTONE:0,100)
RandomBlock(-6,26,8,SAND:0,50,SANDSTONE:0,100)
RandomBlock(-6,27,7,SAND:0,50,SANDSTONE:0,100)
RandomBlock(-6,27,8,SAND:0,50,SANDSTONE:0,100)
RandomBlock(-6,28,8,SAND:0,50,SANDSTONE:0,100)
Block(-5,0,-7,SANDSTONE:0)
Block(-5,0,-6,SANDSTONE:0)
Block(-5,0,-5,SANDSTONE:0)
Block(-5,0,-4,SANDSTONE:0)
Block(-5,0,-3,SANDSTONE:0)
Block(-5,0,-2,SANDSTONE:0)
Block(-5,0,-1,SANDSTONE:0)
Block(-5,0,0,SANDSTONE:0)
Block(-5,0,1,SANDSTONE:0)
Block(-5,0,2,SANDSTONE:0)
Block(-5,0,3,SANDSTONE:0)
Block(-5,0,4,SANDSTONE:0)
Block(-5,0,5,SANDSTONE:0)
Block(-5,0,6,SANDSTONE:0)
Block(-5,0,7,SANDSTONE:0)
Block(-5,0,8,SANDSTONE:0)
Block(-5,1,-7,SANDSTONE:0)
Block(-5,1,-6,SANDSTONE:0)
Block(-5,1,-5,SANDSTONE:0)
Block(-5,1,-4,SANDSTONE:0)
Block(-5,1,-3,SANDSTONE:0)
Block(-5,1,-2,SANDSTONE:0)
Block(-5,1,-1,SANDSTONE:0)
Block(-5,1,0,SANDSTONE:0)
Block(-5,1,1,SANDSTONE:0)
Block(-5,1,2,SANDSTONE:0)
Block(-5,1,3,SANDSTONE:0)
Block(-5,1,4,SANDSTONE:0)
Block(-5,1,5,SANDSTONE:0)
Block(-5,1,6,SANDSTONE:0)
Block(-5,1,7,SANDSTONE:0)
Block(-5,1,8,SANDSTONE:0)
Block(-5,2,-7,SANDSTONE:0)
Block(-5,2,-6,SANDSTONE:0)
Block(-5,2,-5,SANDSTONE:0)
Block(-5,2,-4,SANDSTONE:0)
Block(-5,2,-3,SANDSTONE:0)
Block(-5,2,-2,SANDSTONE:0)
Block(-5,2,-1,SANDSTONE:0)
Block(-5,2,0,SANDSTONE:0)
Block(-5,2,1,SANDSTONE:0)
Block(-5,2,2,SANDSTONE:0)
Block(-5,2,3,SANDSTONE:0)
Block(-5,2,4,SANDSTONE:0)
Block(-5,2,5,SANDSTONE:0)
Block(-5,2,6,SANDSTONE:0)
Block(-5,2,7,SANDSTONE:0)
Block(-5,2,8,SANDSTONE:0)
Block(-5,3,-7,SANDSTONE:0)
Block(-5,3,-6,SANDSTONE:0)
Block(-5,3,-5,SANDSTONE:0)
Block(-5,3,-4,SANDSTONE:0)
Block(-5,3,-3,SANDSTONE:0)
Block(-5,3,-2,SANDSTONE:0)
Block(-5,3,-1,SANDSTONE:0)
Block(-5,3,0,SANDSTONE:0)
Block(-5,3,1,SANDSTONE:0)
Block(-5,3,2,SANDSTONE:0)
Block(-5,3,3,SANDSTONE:0)
Block(-5,3,4,SANDSTONE:0)
Block(-5,3,5,SANDSTONE:0)
Block(-5,3,6,SANDSTONE:0)
Block(-5,3,7,SANDSTONE:0)
Block(-5,3,8,SANDSTONE:0)
Block(-5,4,-7,SANDSTONE:0)
Block(-5,4,-6,SANDSTONE:0)
Block(-5,4,-5,SANDSTONE:0)
Block(-5,4,-4,SANDSTONE:0)
Block(-5,4,-3,SANDSTONE:0)
Block(-5,4,-2,SANDSTONE:0)
Block(-5,4,-1,SANDSTONE:0)
Block(-5,4,0,SANDSTONE:0)
Block(-5,4,1,SANDSTONE:0)
Block(-5,4,2,SANDSTONE:0)
Block(-5,4,3,SANDSTONE:0)
Block(-5,4,4,SANDSTONE:0)
Block(-5,4,5,SANDSTONE:0)
Block(-5,4,6,SANDSTONE:0)
Block(-5,4,7,SANDSTONE:0)
Block(-5,4,8,SANDSTONE:0)
Block(-5,5,-7,SANDSTONE:0)
Block(-5,5,-6,SANDSTONE:0)
Block(-5,5,-5,SANDSTONE:0)
Block(-5,5,-4,SANDSTONE:0)
Block(-5,5,-3,SANDSTONE:0)
Block(-5,5,-2,SANDSTONE:0)
Block(-5,5,-1,SANDSTONE:0)
Block(-5,5,0,SANDSTONE:0)
Block(-5,5,1,SANDSTONE:0)
Block(-5,5,2,SANDSTONE:0)
Block(-5,5,3,SANDSTONE:0)
Block(-5,5,4,SANDSTONE:0)
Block(-5,5,5,SANDSTONE:0)
Block(-5,5,6,SANDSTONE:0)
Block(-5,5,7,SANDSTONE:0)
Block(-5,5,8,SANDSTONE:0)
Block(-5,6,-7,SANDSTONE:0)
Block(-5,6,-6,SANDSTONE:0)
Block(-5,6,-5,SANDSTONE:0)
Block(-5,6,-4,SANDSTONE:0)
Block(-5,6,-3,SANDSTONE:0)
Block(-5,6,-2,SANDSTONE:0)
Block(-5,6,-1,SANDSTONE:0)
Block(-5,6,0,SANDSTONE:0)
Block(-5,6,1,SANDSTONE:0)
Block(-5,6,2,SANDSTONE:0)
Block(-5,6,3,SANDSTONE:0)
Block(-5,6,4,SANDSTONE:0)
Block(-5,6,5,SANDSTONE:0)
Block(-5,6,6,SANDSTONE:0)
Block(-5,6,7,SANDSTONE:0)
Block(-5,6,8,SANDSTONE:0)
Block(-5,7,-7,SANDSTONE:0)
Block(-5,7,-6,SANDSTONE:0)
Block(-5,7,-5,SANDSTONE:0)
Block(-5,7,-4,SANDSTONE:0)
Block(-5,7,-3,SANDSTONE:0)
Block(-5,7,-2,SANDSTONE:0)
Block(-5,7,-1,SANDSTONE:0)
Block(-5,7,0,SANDSTONE:0)
Block(-5,7,1,SANDSTONE:0)
Block(-5,7,2,SANDSTONE:0)
Block(-5,7,3,SANDSTONE:0)
Block(-5,7,4,SANDSTONE:0)
Block(-5,7,5,SANDSTONE:0)
Block(-5,7,6,SANDSTONE:0)
Block(-5,7,7,SANDSTONE:0)
Block(-5,7,8,SANDSTONE:0)
Block(-5,8,-7,SANDSTONE:0)
Block(-5,8,-6,SANDSTONE:0)
Block(-5,8,-5,SANDSTONE:0)
Block(-5,8,-4,SANDSTONE:0)
Block(-5,8,-3,SANDSTONE:0)
Block(-5,8,-2,SANDSTONE:0)
Block(-5,8,-1,SANDSTONE:0)
Block(-5,8,0,SANDSTONE:0)
Block(-5,8,1,SANDSTONE:0)
Block(-5,8,2,SANDSTONE:0)
Block(-5,8,3,SANDSTONE:0)
Block(-5,8,4,SANDSTONE:0)
Block(-5,8,5,SANDSTONE:0)
Block(-5,8,6,SANDSTONE:0)
Block(-5,8,7,SANDSTONE:0)
Block(-5,8,8,SANDSTONE:0)
Block(-5,9,-7,SANDSTONE:0)
Block(-5,9,-6,SANDSTONE:0)
Block(-5,9,-5,SANDSTONE:0)
Block(-5,9,-4,SANDSTONE:0)
Block(-5,9,-3,SANDSTONE:0)
Block(-5,9,-2,SANDSTONE:0)
Block(-5,9,-1,SANDSTONE:0)
Block(-5,9,0,SANDSTONE:0)
Block(-5,9,1,SANDSTONE:0)
Block(-5,9,2,SANDSTONE:0)
Block(-5,9,3,SANDSTONE:0)
Block(-5,9,4,SANDSTONE:0)
Block(-5,9,5,SANDSTONE:0)
Block(-5,9,6,SANDSTONE:0)
Block(-5,9,7,SANDSTONE:0)
Block(-5,9,8,SANDSTONE:0)
Block(-5,10,-7,SANDSTONE:0)
Block(-5,10,-6,SANDSTONE:0)
Block(-5,10,-5,SANDSTONE:0)
Block(-5,10,-4,SANDSTONE:0)
Block(-5,10,-3,SANDSTONE:0)
Block(-5,10,-2,SANDSTONE:0)
Block(-5,10,-1,SANDSTONE:0)
Block(-5,10,0,SANDSTONE:0)
Block(-5,10,1,SANDSTONE:0)
Block(-5,10,2,SANDSTONE:0)
Block(-5,10,3,SANDSTONE:0)
Block(-5,10,4,SANDSTONE:0)
Block(-5,10,5,SANDSTONE:0)
Block(-5,10,6,SANDSTONE:0)
Block(-5,10,7,SANDSTONE:0)
Block(-5,10,8,SANDSTONE:0)
Block(-5,11,-7,SANDSTONE:0)
Block(-5,11,-6,SANDSTONE:0)
Block(-5,11,-5,SANDSTONE:0)
Block(-5,11,-4,SANDSTONE:0)
Block(-5,11,-3,SANDSTONE:0)
Block(-5,11,-2,SANDSTONE:0)
Block(-5,11,-1,SANDSTONE:0)
Block(-5,11,0,SANDSTONE:0)
Block(-5,11,1,SANDSTONE:0)
Block(-5,11,2,SANDSTONE:0)
Block(-5,11,3,SANDSTONE:0)
Block(-5,11,4,SANDSTONE:0)
Block(-5,11,5,SANDSTONE:0)
Block(-5,11,6,SANDSTONE:0)
Block(-5,11,7,SANDSTONE:0)
Block(-5,11,8,SANDSTONE:0)
RandomBlock(-5,12,-7,SAND:0,50,SANDSTONE:0,100)
Block(-5,12,-6,SANDSTONE:0)
Block(-5,12,-5,SANDSTONE:0)
Block(-5,12,-4,SANDSTONE:0)
Block(-5,12,-3,SANDSTONE:0)
Block(-5,12,-2,SANDSTONE:0)
Block(-5,12,-1,SANDSTONE:0)
Block(-5,12,0,SANDSTONE:0)
Block(-5,12,1,SANDSTONE:0)
Block(-5,12,2,SANDSTONE:0)
Block(-5,12,3,SANDSTONE:0)
Block(-5,12,4,SANDSTONE:0)
Block(-5,12,5,SANDSTONE:0)
Block(-5,12,6,SANDSTONE:0)
Block(-5,12,7,SANDSTONE:0)
Block(-5,12,8,SANDSTONE:0)
RandomBlock(-5,13,-7,SAND:0,50,SANDSTONE:0,100)
RandomBlock(-5,13,-6,SAND:0,50,SANDSTONE:0,100)
Block(-5,13,-5,SANDSTONE:0)
Block(-5,13,-4,SANDSTONE:0)
Block(-5,13,-3,SANDSTONE:0)
Block(-5,13,-2,SANDSTONE:0)
Block(-5,13,-1,SANDSTONE:0)
Block(-5,13,0,SANDSTONE:0)
Block(-5,13,1,SANDSTONE:0)
Block(-5,13,2,SANDSTONE:0)
Block(-5,13,3,SANDSTONE:0)
Block(-5,13,4,SANDSTONE:0)
Block(-5,13,5,SANDSTONE:0)
Block(-5,13,6,SANDSTONE:0)
Block(-5,13,7,SANDSTONE:0)
Block(-5,13,8,SANDSTONE:0)
RandomBlock(-5,14,-7,SAND:0,50,SANDSTONE:0,100)
RandomBlock(-5,14,-6,SAND:0,50,SANDSTONE:0,100)
RandomBlock(-5,14,-5,SAND:0,50,SANDSTONE:0,100)
RandomBlock(-5,14,-4,SAND:0,50,SANDSTONE:0,100)
RandomBlock(-5,14,-3,SAND:0,50,SANDSTONE:0,100)
RandomBlock(-5,14,-2,SAND:0,50,SANDSTONE:0,100)
Block(-5,14,-1,SANDSTONE:0)
Block(-5,14,0,SANDSTONE:0)
Block(-5,14,1,SANDSTONE:0)
Block(-5,14,2,SANDSTONE:0)
Block(-5,14,3,SANDSTONE:0)
Block(-5,14,4,SANDSTONE:0)
Block(-5,14,5,SANDSTONE:0)
Block(-5,14,6,SANDSTONE:0)
Block(-5,14,7,SANDSTONE:0)
Block(-5,14,8,SANDSTONE:0)
RandomBlock(-5,15,-6,SAND:0,50,SANDSTONE:0,100)
RandomBlock(-5,15,-5,SAND:0,50,SANDSTONE:0,100)
RandomBlock(-5,15,-4,SAND:0,50,SANDSTONE:0,100)
RandomBlock(-5,15,-3,SAND:0,50,SANDSTONE:0,100)
RandomBlock(-5,15,-2,SAND:0,50,SANDSTONE:0,100)
RandomBlock(-5,15,-1,SAND:0,50,SANDSTONE:0,100)
RandomBlock(-5,15,0,SAND:0,50,SANDSTONE:0,100)
Block(-5,15,1,SANDSTONE:0)
Block(-5,15,2,SANDSTONE:0)
Block(-5,15,3,SANDSTONE:0)
Block(-5,15,4,SANDSTONE:0)
Block(-5,15,5,SANDSTONE:0)
Block(-5,15,6,SANDSTONE:0)
Block(-5,15,7,SANDSTONE:0)
Block(-5,15,8,SANDSTONE:0)
RandomBlock(-5,16,-5,SAND:0,50,SANDSTONE:0,100)
RandomBlock(-5,16,-4,SAND:0,50,SANDSTONE:0,100)
RandomBlock(-5,16,-3,SAND:0,50,SANDSTONE:0,100)
RandomBlock(-5,16,-2,SAND:0,50,SANDSTONE:0,100)
RandomBlock(-5,16,-1,SAND:0,50,SANDSTONE:0,100)
RandomBlock(-5,16,0,SAND:0,50,SANDSTONE:0,100)
RandomBlock(-5,16,1,SAND:0,50,SANDSTONE:0,100)
RandomBlock(-5,16,2,SAND:0,50,SANDSTONE:0,100)
Block(-5,16,3,SANDSTONE:0)
Block(-5,16,4,SANDSTONE:0)
Block(-5,16,5,SANDSTONE:0)
Block(-5,16,6,SANDSTONE:0)
Block(-5,16,7,SANDSTONE:0)
Block(-5,16,8,SANDSTONE:0)
RandomBlock(-5,17,-5,SAND:0,50,SANDSTONE:0,100)
RandomBlock(-5,17,-4,SAND:0,50,SANDSTONE:0,100)
RandomBlock(-5,17,-3,SAND:0,50,SANDSTONE:0,100)
RandomBlock(-5,17,-2,SAND:0,50,SANDSTONE:0,100)
RandomBlock(-5,17,-1,SAND:0,50,SANDSTONE:0,100)
RandomBlock(-5,17,0,SAND:0,50,SANDSTONE:0,100)
RandomBlock(-5,17,1,SAND:0,50,SANDSTONE:0,100)
RandomBlock(-5,17,2,SAND:0,50,SANDSTONE:0,100)
RandomBlock(-5,17,3,SAND:0,50,SANDSTONE:0,100)
Block(-5,17,4,SANDSTONE:0)
Block(-5,17,5,SANDSTONE:0)
Block(-5,17,6,SANDSTONE:0)
Block(-5,17,7,SANDSTONE:0)
Block(-5,17,8,SANDSTONE:0)
RandomBlock(-5,18,-4,SAND:0,50,SANDSTONE:0,100)
RandomBlock(-5,18,-3,SAND:0,50,SANDSTONE:0,100)
RandomBlock(-5,18,-2,SAND:0,50,SANDSTONE:0,100)
RandomBlock(-5,18,-1,SAND:0,50,SANDSTONE:0,100)
RandomBlock(-5,18,0,SAND:0,50,SANDSTONE:0,100)
RandomBlock(-5,18,1,SAND:0,50,SANDSTONE:0,100)
RandomBlock(-5,18,2,SAND:0,50,SANDSTONE:0,100)
RandomBlock(-5,18,3,SAND:0,50,SANDSTONE:0,100)
Block(-5,18,4,SANDSTONE:0)
RandomBlock(-5,18,5,SAND:0,50,SANDSTONE:0,100)
Block(-5,18,6,SANDSTONE:0)
Block(-5,18,7,SANDSTONE:0)
Block(-5,18,8,SANDSTONE:0)
RandomBlock(-5,19,-3,SAND:0,50,SANDSTONE:0,100)
RandomBlock(-5,19,-2,SAND:0,50,SANDSTONE:0,100)
RandomBlock(-5,19,-1,SAND:0,50,SANDSTONE:0,100)
RandomBlock(-5,19,0,SAND:0,50,SANDSTONE:0,100)
RandomBlock(-5,19,1,SAND:0,50,SANDSTONE:0,100)
RandomBlock(-5,19,2,SAND:0,50,SANDSTONE:0,100)
RandomBlock(-5,19,3,SAND:0,50,SANDSTONE:0,100)
RandomBlock(-5,19,4,SAND:0,50,SANDSTONE:0,100)
RandomBlock(-5,19,5,SAND:0,50,SANDSTONE:0,100)
RandomBlock(-5,19,6,SAND:0,50,SANDSTONE:0,100)
Block(-5,19,7,SANDSTONE:0)
Block(-5,19,8,SANDSTONE:0)
RandomBlock(-5,20,-3,SAND:0,50,SANDSTONE:0,100)
RandomBlock(-5,20,-2,SAND:0,50,SANDSTONE:0,100)
RandomBlock(-5,20,-1,SAND:0,50,SANDSTONE:0,100)
RandomBlock(-5,20,0,SAND:0,50,SANDSTONE:0,100)
RandomBlock(-5,20,1,SAND:0,50,SANDSTONE:0,100)
RandomBlock(-5,20,2,SAND:0,50,SANDSTONE:0,100)
RandomBlock(-5,20,3,SAND:0,50,SANDSTONE:0,100)
RandomBlock(-5,20,4,SAND:0,50,SANDSTONE:0,100)
RandomBlock(-5,20,5,SAND:0,50,SANDSTONE:0,100)
RandomBlock(-5,20,6,SAND:0,50,SANDSTONE:0,100)
RandomBlock(-5,20,7,SAND:0,50,SANDSTONE:0,100)
Block(-5,20,8,SANDSTONE:0)
RandomBlock(-5,21,-1,SAND:0,50,SANDSTONE:0,100)
RandomBlock(-5,21,0,SAND:0,50,SANDSTONE:0,100)
RandomBlock(-5,21,1,SAND:0,50,SANDSTONE:0,100)
RandomBlock(-5,21,2,SAND:0,50,SANDSTONE:0,100)
RandomBlock(-5,21,3,SAND:0,50,SANDSTONE:0,100)
RandomBlock(-5,21,4,SAND:0,50,SANDSTONE:0,100)
RandomBlock(-5,21,5,SAND:0,50,SANDSTONE:0,100)
RandomBlock(-5,21,6,SAND:0,50,SANDSTONE:0,100)
RandomBlock(-5,21,7,SAND:0,50,SANDSTONE:0,100)
RandomBlock(-5,21,8,SAND:0,50,SANDSTONE:0,100)
RandomBlock(-5,22,1,SAND:0,50,SANDSTONE:0,100)
RandomBlock(-5,22,2,SAND:0,50,SANDSTONE:0,100)
RandomBlock(-5,22,3,SAND:0,50,SANDSTONE:0,100)
RandomBlock(-5,22,4,SAND:0,50,SANDSTONE:0,100)
RandomBlock(-5,22,5,SAND:0,50,SANDSTONE:0,100)
RandomBlock(-5,22,6,SAND:0,50,SANDSTONE:0,100)
RandomBlock(-5,22,7,SAND:0,50,SANDSTONE:0,100)
RandomBlock(-5,22,8,SAND:0,50,SANDSTONE:0,100)
RandomBlock(-5,23,2,SAND:0,50,SANDSTONE:0,100)
RandomBlock(-5,23,3,SAND:0,50,SANDSTONE:0,100)
RandomBlock(-5,23,4,SAND:0,50,SANDSTONE:0,100)
RandomBlock(-5,23,5,SAND:0,50,SANDSTONE:0,100)
RandomBlock(-5,23,6,SAND:0,50,SANDSTONE:0,100)
RandomBlock(-5,23,7,SAND:0,50,SANDSTONE:0,100)
RandomBlock(-5,23,8,SAND:0,50,SANDSTONE:0,100)
RandomBlock(-5,24,2,SAND:0,50,SANDSTONE:0,100)
RandomBlock(-5,24,3,SAND:0,50,SANDSTONE:0,100)
RandomBlock(-5,24,4,SAND:0,50,SANDSTONE:0,100)
RandomBlock(-5,24,5,SAND:0,50,SANDSTONE:0,100)
RandomBlock(-5,24,6,SAND:0,50,SANDSTONE:0,100)
RandomBlock(-5,24,7,SAND:0,50,SANDSTONE:0,100)
RandomBlock(-5,24,8,SAND:0,50,SANDSTONE:0,100)
RandomBlock(-5,25,4,SAND:0,50,SANDSTONE:0,100)
RandomBlock(-5,25,5,SAND:0,50,SANDSTONE:0,100)
RandomBlock(-5,25,6,SAND:0,50,SANDSTONE:0,100)
RandomBlock(-5,25,7,SAND:0,50,SANDSTONE:0,100)
RandomBlock(-5,25,8,SAND:0,50,SANDSTONE:0,100)
RandomBlock(-5,26,5,SAND:0,50,SANDSTONE:0,100)
RandomBlock(-5,26,6,SAND:0,50,SANDSTONE:0,100)
RandomBlock(-5,26,7,SAND:0,50,SANDSTONE:0,100)
RandomBlock(-5,26,8,SAND:0,50,SANDSTONE:0,100)
RandomBlock(-5,27,6,SAND:0,50,SANDSTONE:0,100)
RandomBlock(-5,27,7,SAND:0,50,SANDSTONE:0,100)
RandomBlock(-5,27,8,SAND:0,50,SANDSTONE:0,100)
RandomBlock(-5,28,7,SAND:0,50,SANDSTONE:0,100)
RandomBlock(-5,28,8,SAND:0,50,SANDSTONE:0,100)
Block(-4,0,-7,SANDSTONE:0)
Block(-4,0,-6,SANDSTONE:0)
Block(-4,0,-5,SANDSTONE:0)
Block(-4,0,-4,SANDSTONE:0)
Block(-4,0,-3,SANDSTONE:0)
Block(-4,0,-2,SANDSTONE:0)
Block(-4,0,-1,SANDSTONE:0)
Block(-4,0,0,SANDSTONE:0)
Block(-4,0,1,SANDSTONE:0)
Block(-4,0,2,SANDSTONE:0)
Block(-4,0,3,SANDSTONE:0)
Block(-4,0,4,SANDSTONE:0)
Block(-4,0,5,SANDSTONE:0)
Block(-4,0,6,SANDSTONE:0)
Block(-4,0,7,SANDSTONE:0)
Block(-4,0,8,SANDSTONE:0)
Block(-4,1,-7,SANDSTONE:0)
Block(-4,1,-6,SANDSTONE:0)
Block(-4,1,-5,SANDSTONE:0)
Block(-4,1,-4,SANDSTONE:0)
Block(-4,1,-3,SANDSTONE:0)
Block(-4,1,-2,SANDSTONE:0)
Block(-4,1,-1,SANDSTONE:0)
Block(-4,1,0,SANDSTONE:0)
Block(-4,1,1,SANDSTONE:0)
Block(-4,1,2,SANDSTONE:0)
Block(-4,1,3,SANDSTONE:0)
Block(-4,1,4,SANDSTONE:0)
Block(-4,1,5,SANDSTONE:0)
Block(-4,1,6,SANDSTONE:0)
Block(-4,1,7,SANDSTONE:0)
Block(-4,1,8,SANDSTONE:0)
Block(-4,2,-7,SANDSTONE:0)
Block(-4,2,-6,SANDSTONE:0)
Block(-4,2,-5,SANDSTONE:0)
Block(-4,2,-4,SANDSTONE:0)
Block(-4,2,-3,SANDSTONE:0)
Block(-4,2,-2,SANDSTONE:0)
Block(-4,2,-1,SANDSTONE:0)
Block(-4,2,0,SANDSTONE:0)
Block(-4,2,1,SANDSTONE:0)
Block(-4,2,2,SANDSTONE:0)
Block(-4,2,3,SANDSTONE:0)
Block(-4,2,4,SANDSTONE:0)
Block(-4,2,5,SANDSTONE:0)
Block(-4,2,6,SANDSTONE:0)
Block(-4,2,7,SANDSTONE:0)
Block(-4,2,8,SANDSTONE:0)
Block(-4,3,-7,SANDSTONE:0)
Block(-4,3,-6,SANDSTONE:0)
Block(-4,3,-5,SANDSTONE:0)
Block(-4,3,-4,SANDSTONE:0)
Block(-4,3,-3,SANDSTONE:0)
Block(-4,3,-2,SANDSTONE:0)
Block(-4,3,-1,SANDSTONE:0)
Block(-4,3,0,SANDSTONE:0)
Block(-4,3,1,SANDSTONE:0)
Block(-4,3,2,SANDSTONE:0)
Block(-4,3,3,SANDSTONE:0)
Block(-4,3,4,SANDSTONE:0)
Block(-4,3,5,SANDSTONE:0)
Block(-4,3,6,SANDSTONE:0)
Block(-4,3,7,SANDSTONE:0)
Block(-4,3,8,SANDSTONE:0)
Block(-4,4,-7,SANDSTONE:0)
Block(-4,4,-6,SANDSTONE:0)
Block(-4,4,-5,SANDSTONE:0)
Block(-4,4,-4,SANDSTONE:0)
Block(-4,4,-3,SANDSTONE:0)
Block(-4,4,-2,SANDSTONE:0)
Block(-4,4,-1,SANDSTONE:0)
Block(-4,4,0,SANDSTONE:0)
Block(-4,4,1,SANDSTONE:0)
Block(-4,4,2,SANDSTONE:0)
Block(-4,4,3,SANDSTONE:0)
Block(-4,4,4,SANDSTONE:0)
Block(-4,4,5,SANDSTONE:0)
Block(-4,4,6,SANDSTONE:0)
Block(-4,4,7,SANDSTONE:0)
Block(-4,4,8,SANDSTONE:0)
Block(-4,5,-7,SANDSTONE:0)
Block(-4,5,-6,SANDSTONE:0)
Block(-4,5,-5,SANDSTONE:0)
Block(-4,5,-4,SANDSTONE:0)
Block(-4,5,-3,SANDSTONE:0)
Block(-4,5,-2,SANDSTONE:0)
Block(-4,5,-1,SANDSTONE:0)
Block(-4,5,0,SANDSTONE:0)
Block(-4,5,1,SANDSTONE:0)
Block(-4,5,2,SANDSTONE:0)
Block(-4,5,3,SANDSTONE:0)
Block(-4,5,4,SANDSTONE:0)
Block(-4,5,5,SANDSTONE:0)
Block(-4,5,6,SANDSTONE:0)
Block(-4,5,7,SANDSTONE:0)
Block(-4,5,8,SANDSTONE:0)
Block(-4,6,-7,SANDSTONE:0)
Block(-4,6,-6,SANDSTONE:0)
Block(-4,6,-5,SANDSTONE:0)
Block(-4,6,-4,SANDSTONE:0)
Block(-4,6,-3,SANDSTONE:0)
Block(-4,6,-2,SANDSTONE:0)
Block(-4,6,-1,SANDSTONE:0)
Block(-4,6,0,SANDSTONE:0)
Block(-4,6,1,SANDSTONE:0)
Block(-4,6,2,SANDSTONE:0)
Block(-4,6,3,SANDSTONE:0)
Block(-4,6,4,SANDSTONE:0)
Block(-4,6,5,SANDSTONE:0)
Block(-4,6,6,SANDSTONE:0)
Block(-4,6,7,SANDSTONE:0)
Block(-4,6,8,SANDSTONE:0)
Block(-4,7,-7,SANDSTONE:0)
Block(-4,7,-6,SANDSTONE:0)
Block(-4,7,-5,SANDSTONE:0)
Block(-4,7,-4,SANDSTONE:0)
Block(-4,7,-3,SANDSTONE:0)
Block(-4,7,-2,SANDSTONE:0)
Block(-4,7,-1,SANDSTONE:0)
Block(-4,7,0,SANDSTONE:0)
Block(-4,7,1,SANDSTONE:0)
Block(-4,7,2,SANDSTONE:0)
Block(-4,7,3,SANDSTONE:0)
Block(-4,7,4,SANDSTONE:0)
Block(-4,7,5,SANDSTONE:0)
Block(-4,7,6,SANDSTONE:0)
Block(-4,7,7,SANDSTONE:0)
Block(-4,7,8,SANDSTONE:0)
Block(-4,8,-7,SANDSTONE:0)
Block(-4,8,-6,SANDSTONE:0)
Block(-4,8,-5,SANDSTONE:0)
Block(-4,8,-4,SANDSTONE:0)
Block(-4,8,-3,SANDSTONE:0)
Block(-4,8,-2,SANDSTONE:0)
Block(-4,8,-1,SANDSTONE:0)
Block(-4,8,0,SANDSTONE:0)
Block(-4,8,1,SANDSTONE:0)
Block(-4,8,2,SANDSTONE:0)
Block(-4,8,3,SANDSTONE:0)
Block(-4,8,4,SANDSTONE:0)
Block(-4,8,5,SANDSTONE:0)
Block(-4,8,6,SANDSTONE:0)
Block(-4,8,7,SANDSTONE:0)
Block(-4,8,8,SANDSTONE:0)
Block(-4,9,-7,SANDSTONE:0)
Block(-4,9,-6,SANDSTONE:0)
Block(-4,9,-5,SANDSTONE:0)
Block(-4,9,-4,SANDSTONE:0)
Block(-4,9,-3,SANDSTONE:0)
Block(-4,9,-2,SANDSTONE:0)
Block(-4,9,-1,SANDSTONE:0)
Block(-4,9,0,SANDSTONE:0)
Block(-4,9,1,SANDSTONE:0)
Block(-4,9,2,SANDSTONE:0)
Block(-4,9,3,SANDSTONE:0)
Block(-4,9,4,SANDSTONE:0)
Block(-4,9,5,SANDSTONE:0)
Block(-4,9,6,SANDSTONE:0)
Block(-4,9,7,SANDSTONE:0)
Block(-4,9,8,SANDSTONE:0)
Block(-4,10,-7,SANDSTONE:0)
Block(-4,10,-6,SANDSTONE:0)
Block(-4,10,-5,SANDSTONE:0)
Block(-4,10,-4,SANDSTONE:0)
Block(-4,10,-3,SANDSTONE:0)
Block(-4,10,-2,SANDSTONE:0)
Block(-4,10,-1,SANDSTONE:0)
Block(-4,10,0,SANDSTONE:0)
Block(-4,10,1,SANDSTONE:0)
Block(-4,10,2,SANDSTONE:0)
Block(-4,10,3,SANDSTONE:0)
Block(-4,10,4,SANDSTONE:0)
Block(-4,10,5,SANDSTONE:0)
Block(-4,10,6,SANDSTONE:0)
Block(-4,10,7,SANDSTONE:0)
Block(-4,10,8,SANDSTONE:0)
Block(-4,11,-7,SANDSTONE:0)
Block(-4,11,-6,SANDSTONE:0)
Block(-4,11,-5,SANDSTONE:0)
Block(-4,11,-4,SANDSTONE:0)
Block(-4,11,-3,SANDSTONE:0)
Block(-4,11,-2,SANDSTONE:0)
Block(-4,11,-1,SANDSTONE:0)
Block(-4,11,0,SANDSTONE:0)
Block(-4,11,1,SANDSTONE:0)
Block(-4,11,2,SANDSTONE:0)
Block(-4,11,3,SANDSTONE:0)
Block(-4,11,4,SANDSTONE:0)
Block(-4,11,5,SANDSTONE:0)
Block(-4,11,6,SANDSTONE:0)
Block(-4,11,7,SANDSTONE:0)
Block(-4,11,8,SANDSTONE:0)
RandomBlock(-4,12,-7,SAND:0,50,SANDSTONE:0,100)
RandomBlock(-4,12,-6,SAND:0,50,SANDSTONE:0,100)
Block(-4,12,-5,SANDSTONE:0)
Block(-4,12,-4,SANDSTONE:0)
Block(-4,12,-3,SANDSTONE:0)
Block(-4,12,-2,SANDSTONE:0)
Block(-4,12,-1,SANDSTONE:0)
Block(-4,12,0,SANDSTONE:0)
Block(-4,12,1,SANDSTONE:0)
Block(-4,12,2,SANDSTONE:0)
Block(-4,12,3,SANDSTONE:0)
Block(-4,12,4,SANDSTONE:0)
Block(-4,12,5,SANDSTONE:0)
Block(-4,12,6,SANDSTONE:0)
Block(-4,12,7,SANDSTONE:0)
Block(-4,12,8,SANDSTONE:0)
RandomBlock(-4,13,-7,SAND:0,50,SANDSTONE:0,100)
RandomBlock(-4,13,-6,SAND:0,50,SANDSTONE:0,100)
RandomBlock(-4,13,-5,SAND:0,50,SANDSTONE:0,100)
Block(-4,13,-4,SANDSTONE:0)
Block(-4,13,-3,SANDSTONE:0)
Block(-4,13,-2,SANDSTONE:0)
Block(-4,13,-1,SANDSTONE:0)
Block(-4,13,0,SANDSTONE:0)
Block(-4,13,1,SANDSTONE:0)
Block(-4,13,2,SANDSTONE:0)
Block(-4,13,3,SANDSTONE:0)
Block(-4,13,4,SANDSTONE:0)
Block(-4,13,5,SANDSTONE:0)
Block(-4,13,6,SANDSTONE:0)
Block(-4,13,7,SANDSTONE:0)
Block(-4,13,8,SANDSTONE:0)
RandomBlock(-4,14,-7,SAND:0,50,SANDSTONE:0,100)
RandomBlock(-4,14,-6,SAND:0,50,SANDSTONE:0,100)
RandomBlock(-4,14,-5,SAND:0,50,SANDSTONE:0,100)
RandomBlock(-4,14,-4,SAND:0,50,SANDSTONE:0,100)
RandomBlock(-4,14,-3,SAND:0,50,SANDSTONE:0,100)
Block(-4,14,-2,SANDSTONE:0)
Block(-4,14,-1,SANDSTONE:0)
Block(-4,14,0,SANDSTONE:0)
Block(-4,14,1,SANDSTONE:0)
Block(-4,14,2,SANDSTONE:0)
Block(-4,14,3,SANDSTONE:0)
Block(-4,14,4,SANDSTONE:0)
Block(-4,14,5,SANDSTONE:0)
Block(-4,14,6,SANDSTONE:0)
Block(-4,14,7,SANDSTONE:0)
Block(-4,14,8,SANDSTONE:0)
RandomBlock(-4,15,-6,SAND:0,50,SANDSTONE:0,100)
RandomBlock(-4,15,-5,SAND:0,50,SANDSTONE:0,100)
RandomBlock(-4,15,-4,SAND:0,50,SANDSTONE:0,100)
RandomBlock(-4,15,-3,SAND:0,50,SANDSTONE:0,100)
RandomBlock(-4,15,-2,SAND:0,50,SANDSTONE:0,100)
RandomBlock(-4,15,-1,SAND:0,50,SANDSTONE:0,100)
Block(-4,15,0,SANDSTONE:0)
Block(-4,15,1,SANDSTONE:0)
Block(-4,15,2,SANDSTONE:0)
Block(-4,15,3,SANDSTONE:0)
Block(-4,15,4,SANDSTONE:0)
Block(-4,15,5,SANDSTONE:0)
Block(-4,15,6,SANDSTONE:0)
Block(-4,15,7,SANDSTONE:0)
Block(-4,15,8,SANDSTONE:0)
RandomBlock(-4,16,-4,SAND:0,50,SANDSTONE:0,100)
RandomBlock(-4,16,-3,SAND:0,50,SANDSTONE:0,100)
RandomBlock(-4,16,-2,SAND:0,50,SANDSTONE:0,100)
RandomBlock(-4,16,-1,SAND:0,50,SANDSTONE:0,100)
RandomBlock(-4,16,0,SAND:0,50,SANDSTONE:0,100)
RandomBlock(-4,16,1,SAND:0,50,SANDSTONE:0,100)
Block(-4,16,2,SANDSTONE:0)
Block(-4,16,3,SANDSTONE:0)
Block(-4,16,4,SANDSTONE:0)
Block(-4,16,5,SANDSTONE:0)
Block(-4,16,6,SANDSTONE:0)
Block(-4,16,7,SANDSTONE:0)
Block(-4,16,8,SANDSTONE:0)
RandomBlock(-4,17,-4,SAND:0,50,SANDSTONE:0,100)
RandomBlock(-4,17,-3,SAND:0,50,SANDSTONE:0,100)
RandomBlock(-4,17,-2,SAND:0,50,SANDSTONE:0,100)
RandomBlock(-4,17,-1,SAND:0,50,SANDSTONE:0,100)
RandomBlock(-4,17,0,SAND:0,50,SANDSTONE:0,100)
RandomBlock(-4,17,1,SAND:0,50,SANDSTONE:0,100)
RandomBlock(-4,17,2,SAND:0,50,SANDSTONE:0,100)
Block(-4,17,3,SANDSTONE:0)
Block(-4,17,4,SANDSTONE:0)
Block(-4,17,5,SANDSTONE:0)
Block(-4,17,6,SANDSTONE:0)
Block(-4,17,7,SANDSTONE:0)
Block(-4,17,8,SANDSTONE:0)
RandomBlock(-4,18,-3,SAND:0,50,SANDSTONE:0,100)
RandomBlock(-4,18,-2,SAND:0,50,SANDSTONE:0,100)
RandomBlock(-4,18,-1,SAND:0,50,SANDSTONE:0,100)
RandomBlock(-4,18,0,SAND:0,50,SANDSTONE:0,100)
RandomBlock(-4,18,1,SAND:0,50,SANDSTONE:0,100)
RandomBlock(-4,18,2,SAND:0,50,SANDSTONE:0,100)
Block(-4,18,3,SANDSTONE:0)
Block(-4,18,4,SANDSTONE:0)
Block(-4,18,5,SANDSTONE:0)
Block(-4,18,6,SANDSTONE:0)
Block(-4,18,7,SANDSTONE:0)
Block(-4,18,8,SANDSTONE:0)
RandomBlock(-4,19,-3,SAND:0,50,SANDSTONE:0,100)
RandomBlock(-4,19,-2,SAND:0,50,SANDSTONE:0,100)
RandomBlock(-4,19,-1,SAND:0,50,SANDSTONE:0,100)
RandomBlock(-4,19,0,SAND:0,50,SANDSTONE:0,100)
RandomBlock(-4,19,1,SAND:0,50,SANDSTONE:0,100)
RandomBlock(-4,19,2,SAND:0,50,SANDSTONE:0,100)
RandomBlock(-4,19,3,SAND:0,50,SANDSTONE:0,100)
RandomBlock(-4,19,4,SAND:0,50,SANDSTONE:0,100)
RandomBlock(-4,19,5,SAND:0,50,SANDSTONE:0,100)
Block(-4,19,6,SANDSTONE:0)
Block(-4,19,7,SANDSTONE:0)
Block(-4,19,8,SANDSTONE:0)
RandomBlock(-4,20,-3,SAND:0,50,SANDSTONE:0,100)
RandomBlock(-4,20,-2,SAND:0,50,SANDSTONE:0,100)
RandomBlock(-4,20,-1,SAND:0,50,SANDSTONE:0,100)
RandomBlock(-4,20,0,SAND:0,50,SANDSTONE:0,100)
RandomBlock(-4,20,1,SAND:0,50,SANDSTONE:0,100)
RandomBlock(-4,20,2,SAND:0,50,SANDSTONE:0,100)
RandomBlock(-4,20,3,SAND:0,50,SANDSTONE:0,100)
RandomBlock(-4,20,4,SAND:0,50,SANDSTONE:0,100)
RandomBlock(-4,20,5,SAND:0,50,SANDSTONE:0,100)
RandomBlock(-4,20,6,SAND:0,50,SANDSTONE:0,100)
Block(-4,20,7,SANDSTONE:0)
Block(-4,20,8,SANDSTONE:0)
RandomBlock(-4,21,-1,SAND:0,50,SANDSTONE:0,100)
RandomBlock(-4,21,0,SAND:0,50,SANDSTONE:0,100)
RandomBlock(-4,21,1,SAND:0,50,SANDSTONE:0,100)
RandomBlock(-4,21,2,SAND:0,50,SANDSTONE:0,100)
RandomBlock(-4,21,3,SAND:0,50,SANDSTONE:0,100)
RandomBlock(-4,21,4,SAND:0,50,SANDSTONE:0,100)
RandomBlock(-4,21,5,SAND:0,50,SANDSTONE:0,100)
RandomBlock(-4,21,6,SAND:0,50,SANDSTONE:0,100)
RandomBlock(-4,21,7,SAND:0,50,SANDSTONE:0,100)
Block(-4,21,8,SANDSTONE:0)
RandomBlock(-4,22,1,SAND:0,50,SANDSTONE:0,100)
RandomBlock(-4,22,2,SAND:0,50,SANDSTONE:0,100)
RandomBlock(-4,22,3,SAND:0,50,SANDSTONE:0,100)
RandomBlock(-4,22,4,SAND:0,50,SANDSTONE:0,100)
RandomBlock(-4,22,5,SAND:0,50,SANDSTONE:0,100)
RandomBlock(-4,22,6,SAND:0,50,SANDSTONE:0,100)
RandomBlock(-4,22,7,SAND:0,50,SANDSTONE:0,100)
RandomBlock(-4,22,8,SAND:0,50,SANDSTONE:0,100)
RandomBlock(-4,23,1,SAND:0,50,SANDSTONE:0,100)
RandomBlock(-4,23,2,SAND:0,50,SANDSTONE:0,100)
RandomBlock(-4,23,3,SAND:0,50,SANDSTONE:0,100)
RandomBlock(-4,23,4,SAND:0,50,SANDSTONE:0,100)
RandomBlock(-4,23,5,SAND:0,50,SANDSTONE:0,100)
RandomBlock(-4,23,6,SAND:0,50,SANDSTONE:0,100)
RandomBlock(-4,23,7,SAND:0,50,SANDSTONE:0,100)
RandomBlock(-4,23,8,SAND:0,50,SANDSTONE:0,100)
RandomBlock(-4,24,2,SAND:0,50,SANDSTONE:0,100)
RandomBlock(-4,24,3,SAND:0,50,SANDSTONE:0,100)
RandomBlock(-4,24,4,SAND:0,50,SANDSTONE:0,100)
RandomBlock(-4,24,5,SAND:0,50,SANDSTONE:0,100)
RandomBlock(-4,24,6,SAND:0,50,SANDSTONE:0,100)
RandomBlock(-4,24,7,SAND:0,50,SANDSTONE:0,100)
RandomBlock(-4,24,8,SAND:0,50,SANDSTONE:0,100)
RandomBlock(-4,25,3,SAND:0,50,SANDSTONE:0,100)
RandomBlock(-4,25,4,SAND:0,50,SANDSTONE:0,100)
RandomBlock(-4,25,5,SAND:0,50,SANDSTONE:0,100)
RandomBlock(-4,25,6,SAND:0,50,SANDSTONE:0,100)
RandomBlock(-4,25,7,SAND:0,50,SANDSTONE:0,100)
RandomBlock(-4,25,8,SAND:0,50,SANDSTONE:0,100)
RandomBlock(-4,26,4,SAND:0,50,SANDSTONE:0,100)
RandomBlock(-4,26,5,SAND:0,50,SANDSTONE:0,100)
RandomBlock(-4,26,6,SAND:0,50,SANDSTONE:0,100)
RandomBlock(-4,26,7,SAND:0,50,SANDSTONE:0,100)
RandomBlock(-4,26,8,SAND:0,50,SANDSTONE:0,100)
RandomBlock(-4,27,5,SAND:0,50,SANDSTONE:0,100)
RandomBlock(-4,27,6,SAND:0,50,SANDSTONE:0,100)
RandomBlock(-4,27,7,SAND:0,50,SANDSTONE:0,100)
RandomBlock(-4,27,8,SAND:0,50,SANDSTONE:0,100)
RandomBlock(-4,28,6,SAND:0,50,SANDSTONE:0,100)
RandomBlock(-4,28,7,SAND:0,50,SANDSTONE:0,100)
RandomBlock(-4,28,8,SAND:0,50,SANDSTONE:0,100)
RandomBlock(-4,29,8,SAND:0,50,SANDSTONE:0,100)
Block(-3,0,-7,SANDSTONE:0)
Block(-3,0,-6,SANDSTONE:0)
Block(-3,0,-5,SANDSTONE:0)
Block(-3,0,-4,SANDSTONE:0)
Block(-3,0,-3,SANDSTONE:0)
Block(-3,0,-2,SANDSTONE:0)
Block(-3,0,-1,SANDSTONE:0)
Block(-3,0,0,SANDSTONE:0)
Block(-3,0,1,SANDSTONE:0)
Block(-3,0,2,SANDSTONE:0)
Block(-3,0,3,SANDSTONE:0)
Block(-3,0,4,SANDSTONE:0)
Block(-3,0,5,SANDSTONE:0)
Block(-3,0,6,SANDSTONE:0)
Block(-3,0,7,SANDSTONE:0)
Block(-3,0,8,SANDSTONE:0)
Block(-3,1,-7,SANDSTONE:0)
Block(-3,1,-6,SANDSTONE:0)
Block(-3,1,-5,SANDSTONE:0)
Block(-3,1,-4,SANDSTONE:0)
Block(-3,1,-3,SANDSTONE:0)
Block(-3,1,-2,SANDSTONE:0)
Block(-3,1,-1,SANDSTONE:0)
Block(-3,1,0,SANDSTONE:0)
Block(-3,1,1,SANDSTONE:0)
Block(-3,1,2,SANDSTONE:0)
Block(-3,1,3,SANDSTONE:0)
Block(-3,1,4,SANDSTONE:0)
Block(-3,1,5,SANDSTONE:0)
Block(-3,1,6,SANDSTONE:0)
Block(-3,1,7,SANDSTONE:0)
Block(-3,1,8,SANDSTONE:0)
Block(-3,2,-7,SANDSTONE:0)
Block(-3,2,-6,SANDSTONE:0)
Block(-3,2,-5,SANDSTONE:0)
Block(-3,2,-4,SANDSTONE:0)
Block(-3,2,-3,SANDSTONE:0)
Block(-3,2,-2,SANDSTONE:0)
Block(-3,2,-1,SANDSTONE:0)
Block(-3,2,0,SANDSTONE:0)
Block(-3,2,1,SANDSTONE:0)
Block(-3,2,2,SANDSTONE:0)
Block(-3,2,3,SANDSTONE:0)
Block(-3,2,4,SANDSTONE:0)
Block(-3,2,5,SANDSTONE:0)
Block(-3,2,6,SANDSTONE:0)
Block(-3,2,7,SANDSTONE:0)
Block(-3,2,8,SANDSTONE:0)
Block(-3,3,-7,SANDSTONE:0)
Block(-3,3,-6,SANDSTONE:0)
Block(-3,3,-5,SANDSTONE:0)
Block(-3,3,-4,SANDSTONE:0)
Block(-3,3,-3,SANDSTONE:0)
Block(-3,3,-2,SANDSTONE:0)
Block(-3,3,-1,SANDSTONE:0)
Block(-3,3,0,SANDSTONE:0)
Block(-3,3,1,SANDSTONE:0)
Block(-3,3,2,SANDSTONE:0)
Block(-3,3,3,SANDSTONE:0)
Block(-3,3,4,SANDSTONE:0)
Block(-3,3,5,SANDSTONE:0)
Block(-3,3,6,SANDSTONE:0)
Block(-3,3,7,SANDSTONE:0)
Block(-3,3,8,SANDSTONE:0)
Block(-3,4,-7,SANDSTONE:0)
Block(-3,4,-6,SANDSTONE:0)
Block(-3,4,-5,SANDSTONE:0)
Block(-3,4,-4,SANDSTONE:0)
Block(-3,4,-3,SANDSTONE:0)
Block(-3,4,-2,SANDSTONE:0)
Block(-3,4,-1,SANDSTONE:0)
Block(-3,4,0,SANDSTONE:0)
Block(-3,4,1,SANDSTONE:0)
Block(-3,4,2,SANDSTONE:0)
Block(-3,4,3,SANDSTONE:0)
Block(-3,4,4,SANDSTONE:0)
Block(-3,4,5,SANDSTONE:0)
Block(-3,4,6,SANDSTONE:0)
Block(-3,4,7,SANDSTONE:0)
Block(-3,4,8,SANDSTONE:0)
Block(-3,5,-7,SANDSTONE:0)
Block(-3,5,-6,SANDSTONE:0)
Block(-3,5,-5,SANDSTONE:0)
Block(-3,5,-4,SANDSTONE:0)
Block(-3,5,-3,SANDSTONE:0)
Block(-3,5,-2,SANDSTONE:0)
Block(-3,5,-1,SANDSTONE:0)
Block(-3,5,0,SANDSTONE:0)
Block(-3,5,1,SANDSTONE:0)
Block(-3,5,2,SANDSTONE:0)
Block(-3,5,3,SANDSTONE:0)
Block(-3,5,4,SANDSTONE:0)
Block(-3,5,5,SANDSTONE:0)
Block(-3,5,6,SANDSTONE:0)
Block(-3,5,7,SANDSTONE:0)
Block(-3,5,8,SANDSTONE:0)
Block(-3,6,-7,SANDSTONE:0)
Block(-3,6,-6,SANDSTONE:0)
Block(-3,6,-5,SANDSTONE:0)
Block(-3,6,-4,SANDSTONE:0)
Block(-3,6,-3,SANDSTONE:0)
Block(-3,6,-2,SANDSTONE:0)
Block(-3,6,-1,SANDSTONE:0)
Block(-3,6,0,SANDSTONE:0)
Block(-3,6,1,SANDSTONE:0)
Block(-3,6,2,SANDSTONE:0)
Block(-3,6,3,SANDSTONE:0)
Block(-3,6,4,SANDSTONE:0)
Block(-3,6,5,SANDSTONE:0)
Block(-3,6,6,SANDSTONE:0)
Block(-3,6,7,SANDSTONE:0)
Block(-3,6,8,SANDSTONE:0)
Block(-3,7,-7,SANDSTONE:0)
Block(-3,7,-6,SANDSTONE:0)
Block(-3,7,-5,SANDSTONE:0)
Block(-3,7,-4,SANDSTONE:0)
Block(-3,7,-3,SANDSTONE:0)
Block(-3,7,-2,SANDSTONE:0)
Block(-3,7,-1,SANDSTONE:0)
Block(-3,7,0,SANDSTONE:0)
Block(-3,7,1,SANDSTONE:0)
Block(-3,7,2,SANDSTONE:0)
Block(-3,7,3,SANDSTONE:0)
Block(-3,7,4,SANDSTONE:0)
Block(-3,7,5,SANDSTONE:0)
Block(-3,7,6,SANDSTONE:0)
Block(-3,7,7,SANDSTONE:0)
Block(-3,7,8,SANDSTONE:0)
Block(-3,8,-7,SANDSTONE:0)
Block(-3,8,-6,SANDSTONE:0)
Block(-3,8,-5,SANDSTONE:0)
Block(-3,8,-4,SANDSTONE:0)
Block(-3,8,-3,SANDSTONE:0)
Block(-3,8,-2,SANDSTONE:0)
Block(-3,8,-1,SANDSTONE:0)
Block(-3,8,0,SANDSTONE:0)
Block(-3,8,1,SANDSTONE:0)
Block(-3,8,2,SANDSTONE:0)
Block(-3,8,3,SANDSTONE:0)
Block(-3,8,4,SANDSTONE:0)
Block(-3,8,5,SANDSTONE:0)
Block(-3,8,6,SANDSTONE:0)
Block(-3,8,7,SANDSTONE:0)
Block(-3,8,8,SANDSTONE:0)
Block(-3,9,-7,SANDSTONE:0)
Block(-3,9,-6,SANDSTONE:0)
Block(-3,9,-5,SANDSTONE:0)
Block(-3,9,-4,SANDSTONE:0)
Block(-3,9,-3,SANDSTONE:0)
Block(-3,9,-2,SANDSTONE:0)
Block(-3,9,-1,SANDSTONE:0)
Block(-3,9,0,SANDSTONE:0)
Block(-3,9,1,SANDSTONE:0)
Block(-3,9,2,SANDSTONE:0)
Block(-3,9,3,SANDSTONE:0)
Block(-3,9,4,SANDSTONE:0)
Block(-3,9,5,SANDSTONE:0)
Block(-3,9,6,SANDSTONE:0)
Block(-3,9,7,SANDSTONE:0)
Block(-3,9,8,SANDSTONE:0)
Block(-3,10,-7,SANDSTONE:0)
Block(-3,10,-6,SANDSTONE:0)
Block(-3,10,-5,SANDSTONE:0)
Block(-3,10,-4,SANDSTONE:0)
Block(-3,10,-3,SANDSTONE:0)
Block(-3,10,-2,SANDSTONE:0)
Block(-3,10,-1,SANDSTONE:0)
Block(-3,10,0,SANDSTONE:0)
Block(-3,10,1,SANDSTONE:0)
Block(-3,10,2,SANDSTONE:0)
Block(-3,10,3,SANDSTONE:0)
Block(-3,10,4,SANDSTONE:0)
Block(-3,10,5,SANDSTONE:0)
Block(-3,10,6,SANDSTONE:0)
Block(-3,10,7,SANDSTONE:0)
Block(-3,10,8,SANDSTONE:0)
RandomBlock(-3,11,-7,SAND:0,50,SANDSTONE:0,100)
Block(-3,11,-6,SANDSTONE:0)
Block(-3,11,-5,SANDSTONE:0)
Block(-3,11,-4,SANDSTONE:0)
Block(-3,11,-3,SANDSTONE:0)
Block(-3,11,-2,SANDSTONE:0)
Block(-3,11,-1,SANDSTONE:0)
Block(-3,11,0,SANDSTONE:0)
Block(-3,11,1,SANDSTONE:0)
Block(-3,11,2,SANDSTONE:0)
Block(-3,11,3,SANDSTONE:0)
Block(-3,11,4,SANDSTONE:0)
Block(-3,11,5,SANDSTONE:0)
Block(-3,11,6,SANDSTONE:0)
Block(-3,11,7,SANDSTONE:0)
Block(-3,11,8,SANDSTONE:0)
RandomBlock(-3,12,-7,SAND:0,50,SANDSTONE:0,100)
RandomBlock(-3,12,-6,SAND:0,50,SANDSTONE:0,100)
Block(-3,12,-5,SANDSTONE:0)
Block(-3,12,-4,SANDSTONE:0)
Block(-3,12,-3,SANDSTONE:0)
Block(-3,12,-2,SANDSTONE:0)
Block(-3,12,-1,SANDSTONE:0)
Block(-3,12,0,SANDSTONE:0)
Block(-3,12,1,SANDSTONE:0)
Block(-3,12,2,SANDSTONE:0)
Block(-3,12,3,SANDSTONE:0)
Block(-3,12,4,SANDSTONE:0)
Block(-3,12,5,SANDSTONE:0)
Block(-3,12,6,SANDSTONE:0)
Block(-3,12,7,SANDSTONE:0)
Block(-3,12,8,SANDSTONE:0)
RandomBlock(-3,13,-7,SAND:0,50,SANDSTONE:0,100)
RandomBlock(-3,13,-6,SAND:0,50,SANDSTONE:0,100)
RandomBlock(-3,13,-5,SAND:0,50,SANDSTONE:0,100)
Block(-3,13,-4,SANDSTONE:0)
Block(-3,13,-3,SANDSTONE:0)
Block(-3,13,-2,SANDSTONE:0)
Block(-3,13,-1,SANDSTONE:0)
Block(-3,13,0,SANDSTONE:0)
Block(-3,13,1,SANDSTONE:0)
Block(-3,13,2,SANDSTONE:0)
Block(-3,13,3,SANDSTONE:0)
Block(-3,13,4,SANDSTONE:0)
Block(-3,13,5,SANDSTONE:0)
Block(-3,13,6,SANDSTONE:0)
Block(-3,13,7,SANDSTONE:0)
Block(-3,13,8,SANDSTONE:0)
RandomBlock(-3,14,-7,SAND:0,50,SANDSTONE:0,100)
RandomBlock(-3,14,-6,SAND:0,50,SANDSTONE:0,100)
RandomBlock(-3,14,-5,SAND:0,50,SANDSTONE:0,100)
RandomBlock(-3,14,-4,SAND:0,50,SANDSTONE:0,100)
RandomBlock(-3,14,-3,SAND:0,50,SANDSTONE:0,100)
Block(-3,14,-2,SANDSTONE:0)
Block(-3,14,-1,SANDSTONE:0)
Block(-3,14,0,SANDSTONE:0)
Block(-3,14,1,SANDSTONE:0)
Block(-3,14,2,SANDSTONE:0)
Block(-3,14,3,SANDSTONE:0)
Block(-3,14,4,SANDSTONE:0)
Block(-3,14,5,SANDSTONE:0)
Block(-3,14,6,SANDSTONE:0)
Block(-3,14,7,SANDSTONE:0)
Block(-3,14,8,SANDSTONE:0)
RandomBlock(-3,15,-6,SAND:0,50,SANDSTONE:0,100)
RandomBlock(-3,15,-5,SAND:0,50,SANDSTONE:0,100)
RandomBlock(-3,15,-4,SAND:0,50,SANDSTONE:0,100)
RandomBlock(-3,15,-3,SAND:0,50,SANDSTONE:0,100)
RandomBlock(-3,15,-2,SAND:0,50,SANDSTONE:0,100)
RandomBlock(-3,15,-1,SAND:0,50,SANDSTONE:0,100)
Block(-3,15,0,SANDSTONE:0)
Block(-3,15,1,SANDSTONE:0)
Block(-3,15,2,SANDSTONE:0)
Block(-3,15,3,SANDSTONE:0)
Block(-3,15,4,SANDSTONE:0)
Block(-3,15,5,SANDSTONE:0)
Block(-3,15,6,SANDSTONE:0)
Block(-3,15,7,SANDSTONE:0)
Block(-3,15,8,SANDSTONE:0)
RandomBlock(-3,16,-5,SAND:0,50,SANDSTONE:0,100)
RandomBlock(-3,16,-4,SAND:0,50,SANDSTONE:0,100)
RandomBlock(-3,16,-3,SAND:0,50,SANDSTONE:0,100)
RandomBlock(-3,16,-2,SAND:0,50,SANDSTONE:0,100)
RandomBlock(-3,16,-1,SAND:0,50,SANDSTONE:0,100)
Block(-3,16,0,SANDSTONE:0)
Block(-3,16,1,SANDSTONE:0)
Block(-3,16,2,SANDSTONE:0)
Block(-3,16,3,SANDSTONE:0)
Block(-3,16,4,SANDSTONE:0)
Block(-3,16,5,SANDSTONE:0)
Block(-3,16,6,SANDSTONE:0)
Block(-3,16,7,SANDSTONE:0)
Block(-3,16,8,SANDSTONE:0)
RandomBlock(-3,17,-4,SAND:0,50,SANDSTONE:0,100)
RandomBlock(-3,17,-3,SAND:0,50,SANDSTONE:0,100)
RandomBlock(-3,17,-2,SAND:0,50,SANDSTONE:0,100)
RandomBlock(-3,17,-1,SAND:0,50,SANDSTONE:0,100)
RandomBlock(-3,17,0,SAND:0,50,SANDSTONE:0,100)
RandomBlock(-3,17,1,SAND:0,50,SANDSTONE:0,100)
Block(-3,17,2,SANDSTONE:0)
Block(-3,17,3,SANDSTONE:0)
Block(-3,17,4,SANDSTONE:0)
Block(-3,17,5,SANDSTONE:0)
Block(-3,17,6,SANDSTONE:0)
Block(-3,17,7,SANDSTONE:0)
Block(-3,17,8,SANDSTONE:0)
RandomBlock(-3,18,-3,SAND:0,50,SANDSTONE:0,100)
RandomBlock(-3,18,-2,SAND:0,50,SANDSTONE:0,100)
RandomBlock(-3,18,-1,SAND:0,50,SANDSTONE:0,100)
RandomBlock(-3,18,0,SAND:0,50,SANDSTONE:0,100)
RandomBlock(-3,18,1,SAND:0,50,SANDSTONE:0,100)
Block(-3,18,2,SANDSTONE:0)
Block(-3,18,3,SANDSTONE:0)
Block(-3,18,4,SANDSTONE:0)
Block(-3,18,5,SANDSTONE:0)
Block(-3,18,6,SANDSTONE:0)
Block(-3,18,7,SANDSTONE:0)
Block(-3,18,8,SANDSTONE:0)
RandomBlock(-3,19,-3,SAND:0,50,SANDSTONE:0,100)
RandomBlock(-3,19,-2,SAND:0,50,SANDSTONE:0,100)
RandomBlock(-3,19,-1,SAND:0,50,SANDSTONE:0,100)
RandomBlock(-3,19,0,SAND:0,50,SANDSTONE:0,100)
RandomBlock(-3,19,1,SAND:0,50,SANDSTONE:0,100)
RandomBlock(-3,19,2,SAND:0,50,SANDSTONE:0,100)
RandomBlock(-3,19,3,SAND:0,50,SANDSTONE:0,100)
Block(-3,19,4,SANDSTONE:0)
Block(-3,19,5,SANDSTONE:0)
Block(-3,19,6,SANDSTONE:0)
Block(-3,19,7,SANDSTONE:0)
Block(-3,19,8,SANDSTONE:0)
RandomBlock(-3,20,-2,SAND:0,50,SANDSTONE:0,100)
RandomBlock(-3,20,-1,SAND:0,50,SANDSTONE:0,100)
RandomBlock(-3,20,0,SAND:0,50,SANDSTONE:0,100)
RandomBlock(-3,20,1,SAND:0,50,SANDSTONE:0,100)
RandomBlock(-3,20,2,SAND:0,50,SANDSTONE:0,100)
RandomBlock(-3,20,3,SAND:0,50,SANDSTONE:0,100)
RandomBlock(-3,20,4,SAND:0,50,SANDSTONE:0,100)
RandomBlock(-3,20,5,SAND:0,50,SANDSTONE:0,100)
Block(-3,20,6,SANDSTONE:0)
Block(-3,20,7,SANDSTONE:0)
Block(-3,20,8,SANDSTONE:0)
RandomBlock(-3,21,0,SAND:0,50,SANDSTONE:0,100)
RandomBlock(-3,21,1,SAND:0,50,SANDSTONE:0,100)
RandomBlock(-3,21,2,SAND:0,50,SANDSTONE:0,100)
RandomBlock(-3,21,3,SAND:0,50,SANDSTONE:0,100)
RandomBlock(-3,21,4,SAND:0,50,SANDSTONE:0,100)
RandomBlock(-3,21,5,SAND:0,50,SANDSTONE:0,100)
RandomBlock(-3,21,6,SAND:0,50,SANDSTONE:0,100)
Block(-3,21,7,SANDSTONE:0)
Block(-3,21,8,SANDSTONE:0)
RandomBlock(-3,22,0,SAND:0,50,SANDSTONE:0,100)
RandomBlock(-3,22,1,SAND:0,50,SANDSTONE:0,100)
RandomBlock(-3,22,2,SAND:0,50,SANDSTONE:0,100)
RandomBlock(-3,22,3,SAND:0,50,SANDSTONE:0,100)
RandomBlock(-3,22,4,SAND:0,50,SANDSTONE:0,100)
RandomBlock(-3,22,5,SAND:0,50,SANDSTONE:0,100)
RandomBlock(-3,22,6,SAND:0,50,SANDSTONE:0,100)
RandomBlock(-3,22,7,SAND:0,50,SANDSTONE:0,100)
RandomBlock(-3,22,8,SAND:0,50,SANDSTONE:0,100)
RandomBlock(-3,23,0,SAND:0,50,SANDSTONE:0,100)
RandomBlock(-3,23,1,SAND:0,50,SANDSTONE:0,100)
RandomBlock(-3,23,2,SAND:0,50,SANDSTONE:0,100)
RandomBlock(-3,23,3,SAND:0,50,SANDSTONE:0,100)
RandomBlock(-3,23,4,SAND:0,50,SANDSTONE:0,100)
RandomBlock(-3,23,5,SAND:0,50,SANDSTONE:0,100)
RandomBlock(-3,23,6,SAND:0,50,SANDSTONE:0,100)
RandomBlock(-3,23,7,SAND:0,50,SANDSTONE:0,100)
RandomBlock(-3,23,8,SAND:0,50,SANDSTONE:0,100)
RandomBlock(-3,24,1,SAND:0,50,SANDSTONE:0,100)
RandomBlock(-3,24,2,SAND:0,50,SANDSTONE:0,100)
RandomBlock(-3,24,3,SAND:0,50,SANDSTONE:0,100)
RandomBlock(-3,24,4,SAND:0,50,SANDSTONE:0,100)
RandomBlock(-3,24,5,SAND:0,50,SANDSTONE:0,100)
RandomBlock(-3,24,6,SAND:0,50,SANDSTONE:0,100)
RandomBlock(-3,24,7,SAND:0,50,SANDSTONE:0,100)
RandomBlock(-3,24,8,SAND:0,50,SANDSTONE:0,100)
RandomBlock(-3,25,2,SAND:0,50,SANDSTONE:0,100)
RandomBlock(-3,25,3,SAND:0,50,SANDSTONE:0,100)
RandomBlock(-3,25,4,SAND:0,50,SANDSTONE:0,100)
RandomBlock(-3,25,5,SAND:0,50,SANDSTONE:0,100)
RandomBlock(-3,25,6,SAND:0,50,SANDSTONE:0,100)
RandomBlock(-3,25,7,SAND:0,50,SANDSTONE:0,100)
RandomBlock(-3,25,8,SAND:0,50,SANDSTONE:0,100)
RandomBlock(-3,26,3,SAND:0,50,SANDSTONE:0,100)
RandomBlock(-3,26,4,SAND:0,50,SANDSTONE:0,100)
RandomBlock(-3,26,5,SAND:0,50,SANDSTONE:0,100)
RandomBlock(-3,26,6,SAND:0,50,SANDSTONE:0,100)
RandomBlock(-3,26,7,SAND:0,50,SANDSTONE:0,100)
RandomBlock(-3,26,8,SAND:0,50,SANDSTONE:0,100)
RandomBlock(-3,27,4,SAND:0,50,SANDSTONE:0,100)
RandomBlock(-3,27,5,SAND:0,50,SANDSTONE:0,100)
RandomBlock(-3,27,6,SAND:0,50,SANDSTONE:0,100)
RandomBlock(-3,27,7,SAND:0,50,SANDSTONE:0,100)
RandomBlock(-3,27,8,SAND:0,50,SANDSTONE:0,100)
RandomBlock(-3,28,5,SAND:0,50,SANDSTONE:0,100)
RandomBlock(-3,28,6,SAND:0,50,SANDSTONE:0,100)
RandomBlock(-3,28,7,SAND:0,50,SANDSTONE:0,100)
RandomBlock(-3,28,8,SAND:0,50,SANDSTONE:0,100)
RandomBlock(-3,29,7,SAND:0,50,SANDSTONE:0,100)
RandomBlock(-3,29,8,SAND:0,50,SANDSTONE:0,100)
Block(-2,0,-7,SANDSTONE:0)
Block(-2,0,-6,SANDSTONE:0)
Block(-2,0,-5,SANDSTONE:0)
Block(-2,0,-4,SANDSTONE:0)
Block(-2,0,-3,SANDSTONE:0)
Block(-2,0,-2,SANDSTONE:0)
Block(-2,0,-1,SANDSTONE:0)
Block(-2,0,0,SANDSTONE:0)
Block(-2,0,1,SANDSTONE:0)
Block(-2,0,2,SANDSTONE:0)
Block(-2,0,3,SANDSTONE:0)
Block(-2,0,4,SANDSTONE:0)
Block(-2,0,5,SANDSTONE:0)
Block(-2,0,6,SANDSTONE:0)
Block(-2,0,7,SANDSTONE:0)
Block(-2,0,8,SANDSTONE:0)
Block(-2,1,-7,SANDSTONE:0)
Block(-2,1,-6,SANDSTONE:0)
Block(-2,1,-5,SANDSTONE:0)
Block(-2,1,-4,SANDSTONE:0)
Block(-2,1,-3,SANDSTONE:0)
Block(-2,1,-2,SANDSTONE:0)
Block(-2,1,-1,SANDSTONE:0)
Block(-2,1,0,SANDSTONE:0)
Block(-2,1,1,SANDSTONE:0)
Block(-2,1,2,SANDSTONE:0)
Block(-2,1,3,SANDSTONE:0)
Block(-2,1,4,SANDSTONE:0)
Block(-2,1,5,SANDSTONE:0)
Block(-2,1,6,SANDSTONE:0)
Block(-2,1,7,SANDSTONE:0)
Block(-2,1,8,SANDSTONE:0)
Block(-2,2,-7,SANDSTONE:0)
Block(-2,2,-6,SANDSTONE:0)
Block(-2,2,-5,SANDSTONE:0)
Block(-2,2,-4,SANDSTONE:0)
Block(-2,2,-3,SANDSTONE:0)
Block(-2,2,-2,SANDSTONE:0)
Block(-2,2,-1,SANDSTONE:0)
Block(-2,2,0,SANDSTONE:0)
Block(-2,2,1,SANDSTONE:0)
Block(-2,2,2,SANDSTONE:0)
Block(-2,2,3,SANDSTONE:0)
Block(-2,2,4,SANDSTONE:0)
Block(-2,2,5,SANDSTONE:0)
Block(-2,2,6,SANDSTONE:0)
Block(-2,2,7,SANDSTONE:0)
Block(-2,2,8,SANDSTONE:0)
Block(-2,3,-7,SANDSTONE:0)
Block(-2,3,-6,SANDSTONE:0)
Block(-2,3,-5,SANDSTONE:0)
Block(-2,3,-4,SANDSTONE:0)
Block(-2,3,-3,SANDSTONE:0)
Block(-2,3,-2,SANDSTONE:0)
Block(-2,3,-1,SANDSTONE:0)
Block(-2,3,0,SANDSTONE:0)
Block(-2,3,1,SANDSTONE:0)
Block(-2,3,2,SANDSTONE:0)
Block(-2,3,3,SANDSTONE:0)
Block(-2,3,4,SANDSTONE:0)
Block(-2,3,5,SANDSTONE:0)
Block(-2,3,6,SANDSTONE:0)
Block(-2,3,7,SANDSTONE:0)
Block(-2,3,8,SANDSTONE:0)
Block(-2,4,-7,SANDSTONE:0)
Block(-2,4,-6,SANDSTONE:0)
Block(-2,4,-5,SANDSTONE:0)
Block(-2,4,-4,SANDSTONE:0)
Block(-2,4,-3,SANDSTONE:0)
Block(-2,4,-2,SANDSTONE:0)
Block(-2,4,-1,SANDSTONE:0)
Block(-2,4,0,SANDSTONE:0)
Block(-2,4,1,SANDSTONE:0)
Block(-2,4,2,SANDSTONE:0)
Block(-2,4,3,SANDSTONE:0)
Block(-2,4,4,SANDSTONE:0)
Block(-2,4,5,SANDSTONE:0)
Block(-2,4,6,SANDSTONE:0)
Block(-2,4,7,SANDSTONE:0)
Block(-2,4,8,SANDSTONE:0)
Block(-2,5,-7,SANDSTONE:0)
Block(-2,5,-6,SANDSTONE:0)
Block(-2,5,-5,SANDSTONE:0)
Block(-2,5,-4,SANDSTONE:0)
Block(-2,5,-3,SANDSTONE:0)
Block(-2,5,-2,SANDSTONE:0)
Block(-2,5,-1,SANDSTONE:0)
Block(-2,5,0,SANDSTONE:0)
Block(-2,5,1,SANDSTONE:0)
Block(-2,5,2,SANDSTONE:0)
Block(-2,5,3,SANDSTONE:0)
Block(-2,5,4,SANDSTONE:0)
Block(-2,5,5,SANDSTONE:0)
Block(-2,5,6,SANDSTONE:0)
Block(-2,5,7,SANDSTONE:0)
Block(-2,5,8,SANDSTONE:0)
Block(-2,6,-7,SANDSTONE:0)
Block(-2,6,-6,SANDSTONE:0)
Block(-2,6,-5,SANDSTONE:0)
Block(-2,6,-4,SANDSTONE:0)
Block(-2,6,-3,SANDSTONE:0)
Block(-2,6,-2,SANDSTONE:0)
Block(-2,6,-1,SANDSTONE:0)
Block(-2,6,0,SANDSTONE:0)
Block(-2,6,1,SANDSTONE:0)
Block(-2,6,2,SANDSTONE:0)
Block(-2,6,3,SANDSTONE:0)
Block(-2,6,4,SANDSTONE:0)
Block(-2,6,5,SANDSTONE:0)
Block(-2,6,6,SANDSTONE:0)
Block(-2,6,7,SANDSTONE:0)
Block(-2,6,8,SANDSTONE:0)
Block(-2,7,-7,SANDSTONE:0)
Block(-2,7,-6,SANDSTONE:0)
Block(-2,7,-5,SANDSTONE:0)
Block(-2,7,-4,SANDSTONE:0)
Block(-2,7,-3,SANDSTONE:0)
Block(-2,7,-2,SANDSTONE:0)
Block(-2,7,-1,SANDSTONE:0)
Block(-2,7,0,SANDSTONE:0)
Block(-2,7,1,SANDSTONE:0)
Block(-2,7,2,SANDSTONE:0)
Block(-2,7,3,SANDSTONE:0)
Block(-2,7,4,SANDSTONE:0)
Block(-2,7,5,SANDSTONE:0)
Block(-2,7,6,SANDSTONE:0)
Block(-2,7,7,SANDSTONE:0)
Block(-2,7,8,SANDSTONE:0)
Block(-2,8,-7,SANDSTONE:0)
Block(-2,8,-6,SANDSTONE:0)
Block(-2,8,-5,SANDSTONE:0)
Block(-2,8,-4,SANDSTONE:0)
Block(-2,8,-3,SANDSTONE:0)
Block(-2,8,-2,SANDSTONE:0)
Block(-2,8,-1,SANDSTONE:0)
Block(-2,8,0,SANDSTONE:0)
Block(-2,8,1,SANDSTONE:0)
Block(-2,8,2,SANDSTONE:0)
Block(-2,8,3,SANDSTONE:0)
Block(-2,8,4,SANDSTONE:0)
Block(-2,8,5,SANDSTONE:0)
Block(-2,8,6,SANDSTONE:0)
Block(-2,8,7,SANDSTONE:0)
Block(-2,8,8,SANDSTONE:0)
Block(-2,9,-7,SANDSTONE:0)
Block(-2,9,-6,SANDSTONE:0)
Block(-2,9,-5,SANDSTONE:0)
Block(-2,9,-4,SANDSTONE:0)
Block(-2,9,-3,SANDSTONE:0)
Block(-2,9,-2,SANDSTONE:0)
Block(-2,9,-1,SANDSTONE:0)
Block(-2,9,0,SANDSTONE:0)
Block(-2,9,1,SANDSTONE:0)
Block(-2,9,2,SANDSTONE:0)
Block(-2,9,3,SANDSTONE:0)
Block(-2,9,4,SANDSTONE:0)
Block(-2,9,5,SANDSTONE:0)
Block(-2,9,6,SANDSTONE:0)
Block(-2,9,7,SANDSTONE:0)
Block(-2,9,8,SANDSTONE:0)
Block(-2,10,-7,SANDSTONE:0)
Block(-2,10,-6,SANDSTONE:0)
Block(-2,10,-5,SANDSTONE:0)
Block(-2,10,-4,SANDSTONE:0)
Block(-2,10,-3,SANDSTONE:0)
Block(-2,10,-2,SANDSTONE:0)
Block(-2,10,-1,SANDSTONE:0)
Block(-2,10,0,SANDSTONE:0)
Block(-2,10,1,SANDSTONE:0)
Block(-2,10,2,SANDSTONE:0)
Block(-2,10,3,SANDSTONE:0)
Block(-2,10,4,SANDSTONE:0)
Block(-2,10,5,SANDSTONE:0)
Block(-2,10,6,SANDSTONE:0)
Block(-2,10,7,SANDSTONE:0)
Block(-2,10,8,SANDSTONE:0)
RandomBlock(-2,11,-7,SAND:0,50,SANDSTONE:0,100)
Block(-2,11,-6,SANDSTONE:0)
Block(-2,11,-5,SANDSTONE:0)
Block(-2,11,-4,SANDSTONE:0)
Block(-2,11,-3,SANDSTONE:0)
Block(-2,11,-2,SANDSTONE:0)
Block(-2,11,-1,SANDSTONE:0)
Block(-2,11,0,SANDSTONE:0)
Block(-2,11,1,SANDSTONE:0)
Block(-2,11,2,SANDSTONE:0)
Block(-2,11,3,SANDSTONE:0)
Block(-2,11,4,SANDSTONE:0)
Block(-2,11,5,SANDSTONE:0)
Block(-2,11,6,SANDSTONE:0)
Block(-2,11,7,SANDSTONE:0)
Block(-2,11,8,SANDSTONE:0)
RandomBlock(-2,12,-7,SAND:0,50,SANDSTONE:0,100)
RandomBlock(-2,12,-6,SAND:0,50,SANDSTONE:0,100)
Block(-2,12,-5,SANDSTONE:0)
Block(-2,12,-4,SANDSTONE:0)
Block(-2,12,-3,SANDSTONE:0)
Block(-2,12,-2,SANDSTONE:0)
Block(-2,12,-1,SANDSTONE:0)
Block(-2,12,0,SANDSTONE:0)
Block(-2,12,1,SANDSTONE:0)
Block(-2,12,2,SANDSTONE:0)
Block(-2,12,3,SANDSTONE:0)
Block(-2,12,4,SANDSTONE:0)
Block(-2,12,5,SANDSTONE:0)
Block(-2,12,6,SANDSTONE:0)
Block(-2,12,7,SANDSTONE:0)
Block(-2,12,8,SANDSTONE:0)
RandomBlock(-2,13,-7,SAND:0,50,SANDSTONE:0,100)
RandomBlock(-2,13,-6,SAND:0,50,SANDSTONE:0,100)
RandomBlock(-2,13,-5,SAND:0,50,SANDSTONE:0,100)
Block(-2,13,-4,SANDSTONE:0)
Block(-2,13,-3,SANDSTONE:0)
Block(-2,13,-2,SANDSTONE:0)
Block(-2,13,-1,SANDSTONE:0)
Block(-2,13,0,SANDSTONE:0)
Block(-2,13,1,SANDSTONE:0)
Block(-2,13,2,SANDSTONE:0)
Block(-2,13,3,SANDSTONE:0)
Block(-2,13,4,SANDSTONE:0)
Block(-2,13,5,SANDSTONE:0)
Block(-2,13,6,SANDSTONE:0)
Block(-2,13,7,SANDSTONE:0)
Block(-2,13,8,SANDSTONE:0)
RandomBlock(-2,14,-7,SAND:0,50,SANDSTONE:0,100)
RandomBlock(-2,14,-6,SAND:0,50,SANDSTONE:0,100)
RandomBlock(-2,14,-5,SAND:0,50,SANDSTONE:0,100)
RandomBlock(-2,14,-4,SAND:0,50,SANDSTONE:0,100)
RandomBlock(-2,14,-3,SAND:0,50,SANDSTONE:0,100)
Block(-2,14,-2,SANDSTONE:0)
Block(-2,14,-1,SANDSTONE:0)
Block(-2,14,0,SANDSTONE:0)
Block(-2,14,1,SANDSTONE:0)
Block(-2,14,2,SANDSTONE:0)
Block(-2,14,3,SANDSTONE:0)
Block(-2,14,4,SANDSTONE:0)
Block(-2,14,5,SANDSTONE:0)
Block(-2,14,6,SANDSTONE:0)
Block(-2,14,7,SANDSTONE:0)
Block(-2,14,8,SANDSTONE:0)
RandomBlock(-2,15,-6,SAND:0,50,SANDSTONE:0,100)
RandomBlock(-2,15,-5,SAND:0,50,SANDSTONE:0,100)
RandomBlock(-2,15,-4,SAND:0,50,SANDSTONE:0,100)
RandomBlock(-2,15,-3,SAND:0,50,SANDSTONE:0,100)
RandomBlock(-2,15,-2,SAND:0,50,SANDSTONE:0,100)
Block(-2,15,-1,SANDSTONE:0)
Block(-2,15,0,SANDSTONE:0)
Block(-2,15,1,SANDSTONE:0)
Block(-2,15,2,SANDSTONE:0)
Block(-2,15,3,SANDSTONE:0)
Block(-2,15,4,SANDSTONE:0)
Block(-2,15,5,SANDSTONE:0)
Block(-2,15,6,SANDSTONE:0)
Block(-2,15,7,SANDSTONE:0)
Block(-2,15,8,SANDSTONE:0)
RandomBlock(-2,16,-5,SAND:0,50,SANDSTONE:0,100)
RandomBlock(-2,16,-4,SAND:0,50,SANDSTONE:0,100)
RandomBlock(-2,16,-3,SAND:0,50,SANDSTONE:0,100)
RandomBlock(-2,16,-2,SAND:0,50,SANDSTONE:0,100)
Block(-2,16,-1,SANDSTONE:0)
Block(-2,16,0,SANDSTONE:0)
Block(-2,16,1,SANDSTONE:0)
Block(-2,16,2,SANDSTONE:0)
Block(-2,16,3,SANDSTONE:0)
Block(-2,16,4,SANDSTONE:0)
Block(-2,16,5,SANDSTONE:0)
Block(-2,16,6,SANDSTONE:0)
Block(-2,16,7,SANDSTONE:0)
Block(-2,16,8,SANDSTONE:0)
RandomBlock(-2,17,-4,SAND:0,50,SANDSTONE:0,100)
RandomBlock(-2,17,-3,SAND:0,50,SANDSTONE:0,100)
RandomBlock(-2,17,-2,SAND:0,50,SANDSTONE:0,100)
RandomBlock(-2,17,-1,SAND:0,50,SANDSTONE:0,100)
RandomBlock(-2,17,0,SAND:0,50,SANDSTONE:0,100)
Block(-2,17,1,SANDSTONE:0)
Block(-2,17,2,SANDSTONE:0)
Block(-2,17,3,SANDSTONE:0)
Block(-2,17,4,SANDSTONE:0)
Block(-2,17,5,SANDSTONE:0)
Block(-2,17,6,SANDSTONE:0)
Block(-2,17,7,SANDSTONE:0)
Block(-2,17,8,SANDSTONE:0)
RandomBlock(-2,18,-2,SAND:0,50,SANDSTONE:0,100)
RandomBlock(-2,18,-1,SAND:0,50,SANDSTONE:0,100)
RandomBlock(-2,18,0,SAND:0,50,SANDSTONE:0,100)
Block(-2,18,1,SANDSTONE:0)
Block(-2,18,2,SANDSTONE:0)
Block(-2,18,3,SANDSTONE:0)
Block(-2,18,4,SANDSTONE:0)
Block(-2,18,5,SANDSTONE:0)
Block(-2,18,6,SANDSTONE:0)
Block(-2,18,7,SANDSTONE:0)
Block(-2,18,8,SANDSTONE:0)
RandomBlock(-2,19,-2,SAND:0,50,SANDSTONE:0,100)
RandomBlock(-2,19,-1,SAND:0,50,SANDSTONE:0,100)
RandomBlock(-2,19,0,SAND:0,50,SANDSTONE:0,100)
RandomBlock(-2,19,1,SAND:0,50,SANDSTONE:0,100)
RandomBlock(-2,19,2,SAND:0,50,SANDSTONE:0,100)
Block(-2,19,3,SANDSTONE:0)
Block(-2,19,4,SANDSTONE:0)
Block(-2,19,5,SANDSTONE:0)
Block(-2,19,6,SANDSTONE:0)
Block(-2,19,7,SANDSTONE:0)
Block(-2,19,8,SANDSTONE:0)
RandomBlock(-2,20,-1,SAND:0,50,SANDSTONE:0,100)
RandomBlock(-2,20,0,SAND:0,50,SANDSTONE:0,100)
RandomBlock(-2,20,1,SAND:0,50,SANDSTONE:0,100)
RandomBlock(-2,20,2,SAND:0,50,SANDSTONE:0,100)
RandomBlock(-2,20,3,SAND:0,50,SANDSTONE:0,100)
Block(-2,20,4,SANDSTONE:0)
Block(-2,20,5,SANDSTONE:0)
Block(-2,20,6,SANDSTONE:0)
Block(-2,20,7,SANDSTONE:0)
Block(-2,20,8,SANDSTONE:0)
RandomBlock(-2,21,0,SAND:0,50,SANDSTONE:0,100)
RandomBlock(-2,21,1,SAND:0,50,SANDSTONE:0,100)
RandomBlock(-2,21,2,SAND:0,50,SANDSTONE:0,100)
RandomBlock(-2,21,3,SAND:0,50,SANDSTONE:0,100)
RandomBlock(-2,21,4,SAND:0,50,SANDSTONE:0,100)
RandomBlock(-2,21,5,SAND:0,50,SANDSTONE:0,100)
Block(-2,21,6,SANDSTONE:0)
Block(-2,21,7,SANDSTONE:0)
Block(-2,21,8,SANDSTONE:0)
RandomBlock(-2,22,0,SAND:0,50,SANDSTONE:0,100)
RandomBlock(-2,22,1,SAND:0,50,SANDSTONE:0,100)
RandomBlock(-2,22,2,SAND:0,50,SANDSTONE:0,100)
RandomBlock(-2,22,3,SAND:0,50,SANDSTONE:0,100)
RandomBlock(-2,22,4,SAND:0,50,SANDSTONE:0,100)
RandomBlock(-2,22,5,SAND:0,50,SANDSTONE:0,100)
RandomBlock(-2,22,6,SAND:0,50,SANDSTONE:0,100)
RandomBlock(-2,22,7,SAND:0,50,SANDSTONE:0,100)
Block(-2,22,8,SANDSTONE:0)
RandomBlock(-2,23,0,SAND:0,50,SANDSTONE:0,100)
RandomBlock(-2,23,1,SAND:0,50,SANDSTONE:0,100)
RandomBlock(-2,23,2,SAND:0,50,SANDSTONE:0,100)
RandomBlock(-2,23,3,SAND:0,50,SANDSTONE:0,100)
RandomBlock(-2,23,4,SAND:0,50,SANDSTONE:0,100)
RandomBlock(-2,23,5,SAND:0,50,SANDSTONE:0,100)
RandomBlock(-2,23,6,SAND:0,50,SANDSTONE:0,100)
RandomBlock(-2,23,7,SAND:0,50,SANDSTONE:0,100)
RandomBlock(-2,23,8,SAND:0,50,SANDSTONE:0,100)
RandomBlock(-2,24,2,SAND:0,50,SANDSTONE:0,100)
RandomBlock(-2,24,3,SAND:0,50,SANDSTONE:0,100)
RandomBlock(-2,24,4,SAND:0,50,SANDSTONE:0,100)
RandomBlock(-2,24,5,SAND:0,50,SANDSTONE:0,100)
RandomBlock(-2,24,6,SAND:0,50,SANDSTONE:0,100)
RandomBlock(-2,24,7,SAND:0,50,SANDSTONE:0,100)
RandomBlock(-2,24,8,SAND:0,50,SANDSTONE:0,100)
RandomBlock(-2,25,2,SAND:0,50,SANDSTONE:0,100)
RandomBlock(-2,25,3,SAND:0,50,SANDSTONE:0,100)
RandomBlock(-2,25,4,SAND:0,50,SANDSTONE:0,100)
RandomBlock(-2,25,5,SAND:0,50,SANDSTONE:0,100)
RandomBlock(-2,25,6,SAND:0,50,SANDSTONE:0,100)
RandomBlock(-2,25,7,SAND:0,50,SANDSTONE:0,100)
RandomBlock(-2,25,8,SAND:0,50,SANDSTONE:0,100)
RandomBlock(-2,26,3,SAND:0,50,SANDSTONE:0,100)
RandomBlock(-2,26,4,SAND:0,50,SANDSTONE:0,100)
RandomBlock(-2,26,5,SAND:0,50,SANDSTONE:0,100)
RandomBlock(-2,26,6,SAND:0,50,SANDSTONE:0,100)
RandomBlock(-2,26,7,SAND:0,50,SANDSTONE:0,100)
RandomBlock(-2,26,8,SAND:0,50,SANDSTONE:0,100)
RandomBlock(-2,27,4,SAND:0,50,SANDSTONE:0,100)
RandomBlock(-2,27,5,SAND:0,50,SANDSTONE:0,100)
RandomBlock(-2,27,6,SAND:0,50,SANDSTONE:0,100)
RandomBlock(-2,27,7,SAND:0,50,SANDSTONE:0,100)
RandomBlock(-2,27,8,SAND:0,50,SANDSTONE:0,100)
RandomBlock(-2,28,5,SAND:0,50,SANDSTONE:0,100)
RandomBlock(-2,28,6,SAND:0,50,SANDSTONE:0,100)
RandomBlock(-2,28,7,SAND:0,50,SANDSTONE:0,100)
RandomBlock(-2,28,8,SAND:0,50,SANDSTONE:0,100)
RandomBlock(-2,29,6,SAND:0,50,SANDSTONE:0,100)
RandomBlock(-2,29,7,SAND:0,50,SANDSTONE:0,100)
RandomBlock(-2,29,8,SAND:0,50,SANDSTONE:0,100)
Block(-1,0,-7,SANDSTONE:0)
Block(-1,0,-6,SANDSTONE:0)
Block(-1,0,-5,SANDSTONE:0)
Block(-1,0,-4,SANDSTONE:0)
Block(-1,0,-3,SANDSTONE:0)
Block(-1,0,-2,SANDSTONE:0)
Block(-1,0,-1,SANDSTONE:0)
Block(-1,0,0,SANDSTONE:0)
Block(-1,0,1,SANDSTONE:0)
Block(-1,0,2,SANDSTONE:0)
Block(-1,0,3,SANDSTONE:0)
Block(-1,0,4,SANDSTONE:0)
Block(-1,0,5,SANDSTONE:0)
Block(-1,0,6,SANDSTONE:0)
Block(-1,0,7,SANDSTONE:0)
Block(-1,0,8,SANDSTONE:0)
Block(-1,1,-7,SANDSTONE:0)
Block(-1,1,-6,SANDSTONE:0)
Block(-1,1,-5,SANDSTONE:0)
Block(-1,1,-4,SANDSTONE:0)
Block(-1,1,-3,SANDSTONE:0)
Block(-1,1,-2,SANDSTONE:0)
Block(-1,1,-1,SANDSTONE:0)
Block(-1,1,0,SANDSTONE:0)
Block(-1,1,1,SANDSTONE:0)
Block(-1,1,2,SANDSTONE:0)
Block(-1,1,3,SANDSTONE:0)
Block(-1,1,4,SANDSTONE:0)
Block(-1,1,5,SANDSTONE:0)
Block(-1,1,6,SANDSTONE:0)
Block(-1,1,7,SANDSTONE:0)
Block(-1,1,8,SANDSTONE:0)
Block(-1,2,-7,SANDSTONE:0)
Block(-1,2,-6,SANDSTONE:0)
Block(-1,2,-5,SANDSTONE:0)
Block(-1,2,-4,SANDSTONE:0)
Block(-1,2,-3,SANDSTONE:0)
Block(-1,2,-2,SANDSTONE:0)
Block(-1,2,-1,SANDSTONE:0)
Block(-1,2,0,SANDSTONE:0)
Block(-1,2,1,SANDSTONE:0)
Block(-1,2,2,SANDSTONE:0)
Block(-1,2,3,SANDSTONE:0)
Block(-1,2,4,SANDSTONE:0)
Block(-1,2,5,SANDSTONE:0)
Block(-1,2,6,SANDSTONE:0)
Block(-1,2,7,SANDSTONE:0)
Block(-1,2,8,SANDSTONE:0)
Block(-1,3,-7,SANDSTONE:0)
Block(-1,3,-6,SANDSTONE:0)
Block(-1,3,-5,SANDSTONE:0)
Block(-1,3,-4,SANDSTONE:0)
Block(-1,3,-3,SANDSTONE:0)
Block(-1,3,-2,SANDSTONE:0)
Block(-1,3,-1,SANDSTONE:0)
Block(-1,3,0,SANDSTONE:0)
Block(-1,3,1,SANDSTONE:0)
Block(-1,3,2,SANDSTONE:0)
Block(-1,3,3,SANDSTONE:0)
Block(-1,3,4,SANDSTONE:0)
Block(-1,3,5,SANDSTONE:0)
Block(-1,3,6,SANDSTONE:0)
Block(-1,3,7,SANDSTONE:0)
Block(-1,3,8,SANDSTONE:0)
Block(-1,4,-7,SANDSTONE:0)
Block(-1,4,-6,SANDSTONE:0)
Block(-1,4,-5,SANDSTONE:0)
Block(-1,4,-4,SANDSTONE:0)
Block(-1,4,-3,SANDSTONE:0)
Block(-1,4,-2,SANDSTONE:0)
Block(-1,4,-1,SANDSTONE:0)
Block(-1,4,0,SANDSTONE:0)
Block(-1,4,1,SANDSTONE:0)
Block(-1,4,2,SANDSTONE:0)
Block(-1,4,3,SANDSTONE:0)
Block(-1,4,4,SANDSTONE:0)
Block(-1,4,5,SANDSTONE:0)
Block(-1,4,6,SANDSTONE:0)
Block(-1,4,7,SANDSTONE:0)
Block(-1,4,8,SANDSTONE:0)
Block(-1,5,-7,SANDSTONE:0)
Block(-1,5,-6,SANDSTONE:0)
Block(-1,5,-5,SANDSTONE:0)
Block(-1,5,-4,SANDSTONE:0)
Block(-1,5,-3,SANDSTONE:0)
Block(-1,5,-2,SANDSTONE:0)
Block(-1,5,-1,SANDSTONE:0)
Block(-1,5,0,SANDSTONE:0)
Block(-1,5,1,SANDSTONE:0)
Block(-1,5,2,SANDSTONE:0)
Block(-1,5,3,SANDSTONE:0)
Block(-1,5,4,SANDSTONE:0)
Block(-1,5,5,SANDSTONE:0)
Block(-1,5,6,SANDSTONE:0)
Block(-1,5,7,SANDSTONE:0)
Block(-1,5,8,SANDSTONE:0)
Block(-1,6,-7,SANDSTONE:0)
Block(-1,6,-6,SANDSTONE:0)
Block(-1,6,-5,SANDSTONE:0)
Block(-1,6,-4,SANDSTONE:0)
Block(-1,6,-3,SANDSTONE:0)
Block(-1,6,-2,SANDSTONE:0)
Block(-1,6,-1,SANDSTONE:0)
Block(-1,6,0,SANDSTONE:0)
Block(-1,6,1,SANDSTONE:0)
Block(-1,6,2,SANDSTONE:0)
Block(-1,6,3,SANDSTONE:0)
Block(-1,6,4,SANDSTONE:0)
Block(-1,6,5,SANDSTONE:0)
Block(-1,6,6,SANDSTONE:0)
Block(-1,6,7,SANDSTONE:0)
Block(-1,6,8,SANDSTONE:0)
Block(-1,7,-7,SANDSTONE:0)
Block(-1,7,-6,SANDSTONE:0)
Block(-1,7,-5,SANDSTONE:0)
Block(-1,7,-4,SANDSTONE:0)
Block(-1,7,-3,SANDSTONE:0)
Block(-1,7,-2,SANDSTONE:0)
Block(-1,7,-1,SANDSTONE:0)
Block(-1,7,0,SANDSTONE:0)
Block(-1,7,1,SANDSTONE:0)
Block(-1,7,2,SANDSTONE:0)
Block(-1,7,3,SANDSTONE:0)
Block(-1,7,4,SANDSTONE:0)
Block(-1,7,5,SANDSTONE:0)
Block(-1,7,6,SANDSTONE:0)
Block(-1,7,7,SANDSTONE:0)
Block(-1,7,8,SANDSTONE:0)
Block(-1,8,-7,SANDSTONE:0)
Block(-1,8,-6,SANDSTONE:0)
Block(-1,8,-5,SANDSTONE:0)
Block(-1,8,-4,SANDSTONE:0)
Block(-1,8,-3,SANDSTONE:0)
Block(-1,8,-2,SANDSTONE:0)
Block(-1,8,-1,SANDSTONE:0)
Block(-1,8,0,SANDSTONE:0)
Block(-1,8,1,SANDSTONE:0)
Block(-1,8,2,SANDSTONE:0)
Block(-1,8,3,SANDSTONE:0)
Block(-1,8,4,SANDSTONE:0)
Block(-1,8,5,SANDSTONE:0)
Block(-1,8,6,SANDSTONE:0)
Block(-1,8,7,SANDSTONE:0)
Block(-1,8,8,SANDSTONE:0)
Block(-1,9,-7,SANDSTONE:0)
Block(-1,9,-6,SANDSTONE:0)
Block(-1,9,-5,SANDSTONE:0)
Block(-1,9,-4,SANDSTONE:0)
Block(-1,9,-3,SANDSTONE:0)
Block(-1,9,-2,SANDSTONE:0)
Block(-1,9,-1,SANDSTONE:0)
Block(-1,9,0,SANDSTONE:0)
Block(-1,9,1,SANDSTONE:0)
Block(-1,9,2,SANDSTONE:0)
Block(-1,9,3,SANDSTONE:0)
Block(-1,9,4,SANDSTONE:0)
Block(-1,9,5,SANDSTONE:0)
Block(-1,9,6,SANDSTONE:0)
Block(-1,9,7,SANDSTONE:0)
Block(-1,9,8,SANDSTONE:0)
Block(-1,10,-7,SANDSTONE:0)
Block(-1,10,-6,SANDSTONE:0)
Block(-1,10,-5,SANDSTONE:0)
Block(-1,10,-4,SANDSTONE:0)
Block(-1,10,-3,SANDSTONE:0)
Block(-1,10,-2,SANDSTONE:0)
Block(-1,10,-1,SANDSTONE:0)
Block(-1,10,0,SANDSTONE:0)
Block(-1,10,1,SANDSTONE:0)
Block(-1,10,2,SANDSTONE:0)
Block(-1,10,3,SANDSTONE:0)
Block(-1,10,4,SANDSTONE:0)
Block(-1,10,5,SANDSTONE:0)
Block(-1,10,6,SANDSTONE:0)
Block(-1,10,7,SANDSTONE:0)
Block(-1,10,8,SANDSTONE:0)
RandomBlock(-1,11,-7,SAND:0,50,SANDSTONE:0,100)
Block(-1,11,-6,SANDSTONE:0)
Block(-1,11,-5,SANDSTONE:0)
Block(-1,11,-4,SANDSTONE:0)
Block(-1,11,-3,SANDSTONE:0)
Block(-1,11,-2,SANDSTONE:0)
Block(-1,11,-1,SANDSTONE:0)
Block(-1,11,0,SANDSTONE:0)
Block(-1,11,1,SANDSTONE:0)
Block(-1,11,2,SANDSTONE:0)
Block(-1,11,3,SANDSTONE:0)
Block(-1,11,4,SANDSTONE:0)
Block(-1,11,5,SANDSTONE:0)
Block(-1,11,6,SANDSTONE:0)
Block(-1,11,7,SANDSTONE:0)
Block(-1,11,8,SANDSTONE:0)
RandomBlock(-1,12,-7,SAND:0,50,SANDSTONE:0,100)
RandomBlock(-1,12,-6,SAND:0,50,SANDSTONE:0,100)
Block(-1,12,-5,SANDSTONE:0)
Block(-1,12,-4,SANDSTONE:0)
Block(-1,12,-3,SANDSTONE:0)
Block(-1,12,-2,SANDSTONE:0)
Block(-1,12,-1,SANDSTONE:0)
Block(-1,12,0,SANDSTONE:0)
Block(-1,12,1,SANDSTONE:0)
Block(-1,12,2,SANDSTONE:0)
Block(-1,12,3,SANDSTONE:0)
Block(-1,12,4,SANDSTONE:0)
Block(-1,12,5,SANDSTONE:0)
Block(-1,12,6,SANDSTONE:0)
Block(-1,12,7,SANDSTONE:0)
Block(-1,12,8,SANDSTONE:0)
RandomBlock(-1,13,-7,SAND:0,50,SANDSTONE:0,100)
RandomBlock(-1,13,-6,SAND:0,50,SANDSTONE:0,100)
RandomBlock(-1,13,-5,SAND:0,50,SANDSTONE:0,100)
Block(-1,13,-4,SANDSTONE:0)
Block(-1,13,-3,SANDSTONE:0)
Block(-1,13,-2,SANDSTONE:0)
Block(-1,13,-1,SANDSTONE:0)
Block(-1,13,0,SANDSTONE:0)
Block(-1,13,1,SANDSTONE:0)
Block(-1,13,2,SANDSTONE:0)
Block(-1,13,3,SANDSTONE:0)
Block(-1,13,4,SANDSTONE:0)
Block(-1,13,5,SANDSTONE:0)
Block(-1,13,6,SANDSTONE:0)
Block(-1,13,7,SANDSTONE:0)
Block(-1,13,8,SANDSTONE:0)
RandomBlock(-1,14,-7,SAND:0,50,SANDSTONE:0,100)
RandomBlock(-1,14,-6,SAND:0,50,SANDSTONE:0,100)
RandomBlock(-1,14,-5,SAND:0,50,SANDSTONE:0,100)
RandomBlock(-1,14,-4,SAND:0,50,SANDSTONE:0,100)
Block(-1,14,-3,SANDSTONE:0)
Block(-1,14,-2,SANDSTONE:0)
Block(-1,14,-1,SANDSTONE:0)
Block(-1,14,0,SANDSTONE:0)
Block(-1,14,1,SANDSTONE:0)
Block(-1,14,2,SANDSTONE:0)
Block(-1,14,3,SANDSTONE:0)
Block(-1,14,4,SANDSTONE:0)
Block(-1,14,5,SANDSTONE:0)
Block(-1,14,6,SANDSTONE:0)
Block(-1,14,7,SANDSTONE:0)
Block(-1,14,8,SANDSTONE:0)
RandomBlock(-1,15,-6,SAND:0,50,SANDSTONE:0,100)
RandomBlock(-1,15,-5,SAND:0,50,SANDSTONE:0,100)
RandomBlock(-1,15,-4,SAND:0,50,SANDSTONE:0,100)
RandomBlock(-1,15,-3,SAND:0,50,SANDSTONE:0,100)
RandomBlock(-1,15,-2,SAND:0,50,SANDSTONE:0,100)
Block(-1,15,-1,SANDSTONE:0)
Block(-1,15,0,SANDSTONE:0)
Block(-1,15,1,SANDSTONE:0)
Block(-1,15,2,SANDSTONE:0)
Block(-1,15,3,SANDSTONE:0)
Block(-1,15,4,SANDSTONE:0)
Block(-1,15,5,SANDSTONE:0)
Block(-1,15,6,SANDSTONE:0)
Block(-1,15,7,SANDSTONE:0)
Block(-1,15,8,SANDSTONE:0)
RandomBlock(-1,16,-6,SAND:0,50,SANDSTONE:0,100)
RandomBlock(-1,16,-5,SAND:0,50,SANDSTONE:0,100)
RandomBlock(-1,16,-4,SAND:0,50,SANDSTONE:0,100)
RandomBlock(-1,16,-3,SAND:0,50,SANDSTONE:0,100)
RandomBlock(-1,16,-2,SAND:0,50,SANDSTONE:0,100)
Block(-1,16,-1,SANDSTONE:0)
Block(-1,16,0,SANDSTONE:0)
Block(-1,16,1,SANDSTONE:0)
Block(-1,16,2,SANDSTONE:0)
Block(-1,16,3,SANDSTONE:0)
Block(-1,16,4,SANDSTONE:0)
Block(-1,16,5,SANDSTONE:0)
Block(-1,16,6,SANDSTONE:0)
Block(-1,16,7,SANDSTONE:0)
Block(-1,16,8,SANDSTONE:0)
RandomBlock(-1,17,-5,SAND:0,50,SANDSTONE:0,100)
RandomBlock(-1,17,-4,SAND:0,50,SANDSTONE:0,100)
RandomBlock(-1,17,-3,SAND:0,50,SANDSTONE:0,100)
RandomBlock(-1,17,-2,SAND:0,50,SANDSTONE:0,100)
RandomBlock(-1,17,-1,SAND:0,50,SANDSTONE:0,100)
Block(-1,17,0,SANDSTONE:0)
Block(-1,17,1,SANDSTONE:0)
Block(-1,17,2,SANDSTONE:0)
Block(-1,17,3,SANDSTONE:0)
Block(-1,17,4,SANDSTONE:0)
Block(-1,17,5,SANDSTONE:0)
Block(-1,17,6,SANDSTONE:0)
Block(-1,17,7,SANDSTONE:0)
Block(-1,17,8,SANDSTONE:0)
RandomBlock(-1,18,-2,SAND:0,50,SANDSTONE:0,100)
RandomBlock(-1,18,-1,SAND:0,50,SANDSTONE:0,100)
Block(-1,18,0,SANDSTONE:0)
Block(-1,18,1,SANDSTONE:0)
Block(-1,18,2,SANDSTONE:0)
Block(-1,18,3,SANDSTONE:0)
Block(-1,18,4,SANDSTONE:0)
Block(-1,18,5,SANDSTONE:0)
Block(-1,18,6,SANDSTONE:0)
Block(-1,18,7,SANDSTONE:0)
Block(-1,18,8,SANDSTONE:0)
RandomBlock(-1,19,-2,SAND:0,50,SANDSTONE:0,100)
RandomBlock(-1,19,-1,SAND:0,50,SANDSTONE:0,100)
RandomBlock(-1,19,0,SAND:0,50,SANDSTONE:0,100)
RandomBlock(-1,19,1,SAND:0,50,SANDSTONE:0,100)
Block(-1,19,2,SANDSTONE:0)
Block(-1,19,3,SANDSTONE:0)
Block(-1,19,4,SANDSTONE:0)
Block(-1,19,5,SANDSTONE:0)
Block(-1,19,6,SANDSTONE:0)
Block(-1,19,7,SANDSTONE:0)
Block(-1,19,8,SANDSTONE:0)
RandomBlock(-1,20,-1,SAND:0,50,SANDSTONE:0,100)
RandomBlock(-1,20,0,SAND:0,50,SANDSTONE:0,100)
RandomBlock(-1,20,1,SAND:0,50,SANDSTONE:0,100)
RandomBlock(-1,20,2,SAND:0,50,SANDSTONE:0,100)
Block(-1,20,3,SANDSTONE:0)
Block(-1,20,4,SANDSTONE:0)
Block(-1,20,5,SANDSTONE:0)
Block(-1,20,6,SANDSTONE:0)
Block(-1,20,7,SANDSTONE:0)
Block(-1,20,8,SANDSTONE:0)
RandomBlock(-1,21,0,SAND:0,50,SANDSTONE:0,100)
RandomBlock(-1,21,1,SAND:0,50,SANDSTONE:0,100)
RandomBlock(-1,21,2,SAND:0,50,SANDSTONE:0,100)
RandomBlock(-1,21,3,SAND:0,50,SANDSTONE:0,100)
Block(-1,21,4,SANDSTONE:0)
Block(-1,21,5,SANDSTONE:0)
Block(-1,21,6,SANDSTONE:0)
Block(-1,21,7,SANDSTONE:0)
Block(-1,21,8,SANDSTONE:0)
RandomBlock(-1,22,1,SAND:0,50,SANDSTONE:0,100)
RandomBlock(-1,22,2,SAND:0,50,SANDSTONE:0,100)
RandomBlock(-1,22,3,SAND:0,50,SANDSTONE:0,100)
RandomBlock(-1,22,4,SAND:0,50,SANDSTONE:0,100)
RandomBlock(-1,22,5,SAND:0,50,SANDSTONE:0,100)
RandomBlock(-1,22,6,SAND:0,50,SANDSTONE:0,100)
Block(-1,22,7,SANDSTONE:0)
Block(-1,22,8,SANDSTONE:0)
RandomBlock(-1,23,1,SAND:0,50,SANDSTONE:0,100)
RandomBlock(-1,23,2,SAND:0,50,SANDSTONE:0,100)
RandomBlock(-1,23,3,SAND:0,50,SANDSTONE:0,100)
RandomBlock(-1,23,4,SAND:0,50,SANDSTONE:0,100)
RandomBlock(-1,23,5,SAND:0,50,SANDSTONE:0,100)
RandomBlock(-1,23,6,SAND:0,50,SANDSTONE:0,100)
RandomBlock(-1,23,7,SAND:0,50,SANDSTONE:0,100)
RandomBlock(-1,23,8,SAND:0,50,SANDSTONE:0,100)
RandomBlock(-1,24,2,SAND:0,50,SANDSTONE:0,100)
RandomBlock(-1,24,3,SAND:0,50,SANDSTONE:0,100)
RandomBlock(-1,24,4,SAND:0,50,SANDSTONE:0,100)
RandomBlock(-1,24,5,SAND:0,50,SANDSTONE:0,100)
RandomBlock(-1,24,6,SAND:0,50,SANDSTONE:0,100)
RandomBlock(-1,24,7,SAND:0,50,SANDSTONE:0,100)
RandomBlock(-1,24,8,SAND:0,50,SANDSTONE:0,100)
RandomBlock(-1,25,3,SAND:0,50,SANDSTONE:0,100)
RandomBlock(-1,25,4,SAND:0,50,SANDSTONE:0,100)
RandomBlock(-1,25,5,SAND:0,50,SANDSTONE:0,100)
RandomBlock(-1,25,6,SAND:0,50,SANDSTONE:0,100)
RandomBlock(-1,25,7,SAND:0,50,SANDSTONE:0,100)
RandomBlock(-1,25,8,SAND:0,50,SANDSTONE:0,100)
RandomBlock(-1,26,4,SAND:0,50,SANDSTONE:0,100)
RandomBlock(-1,26,5,SAND:0,50,SANDSTONE:0,100)
RandomBlock(-1,26,6,SAND:0,50,SANDSTONE:0,100)
RandomBlock(-1,26,7,SAND:0,50,SANDSTONE:0,100)
RandomBlock(-1,26,8,SAND:0,50,SANDSTONE:0,100)
RandomBlock(-1,27,4,SAND:0,50,SANDSTONE:0,100)
RandomBlock(-1,27,5,SAND:0,50,SANDSTONE:0,100)
RandomBlock(-1,27,6,SAND:0,50,SANDSTONE:0,100)
RandomBlock(-1,27,7,SAND:0,50,SANDSTONE:0,100)
RandomBlock(-1,27,8,SAND:0,50,SANDSTONE:0,100)
RandomBlock(-1,28,5,SAND:0,50,SANDSTONE:0,100)
RandomBlock(-1,28,6,SAND:0,50,SANDSTONE:0,100)
RandomBlock(-1,28,7,SAND:0,50,SANDSTONE:0,100)
RandomBlock(-1,28,8,SAND:0,50,SANDSTONE:0,100)
RandomBlock(-1,29,6,SAND:0,50,SANDSTONE:0,100)
RandomBlock(-1,29,7,SAND:0,50,SANDSTONE:0,100)
RandomBlock(-1,29,8,SAND:0,50,SANDSTONE:0,100)
RandomBlock(-1,30,8,SAND:0,50,SANDSTONE:0,100)
Block(0,0,-7,SANDSTONE:0)
Block(0,0,-6,SANDSTONE:0)
Block(0,0,-5,SANDSTONE:0)
Block(0,0,-4,SANDSTONE:0)
Block(0,0,-3,SANDSTONE:0)
Block(0,0,-2,SANDSTONE:0)
Block(0,0,-1,SANDSTONE:0)
Block(0,0,0,SANDSTONE:0)
Block(0,0,1,SANDSTONE:0)
Block(0,0,2,SANDSTONE:0)
Block(0,0,3,SANDSTONE:0)
Block(0,0,4,SANDSTONE:0)
Block(0,0,5,SANDSTONE:0)
Block(0,0,6,SANDSTONE:0)
Block(0,0,7,SANDSTONE:0)
Block(0,0,8,SANDSTONE:0)
Block(0,1,-7,SANDSTONE:0)
Block(0,1,-6,SANDSTONE:0)
Block(0,1,-5,SANDSTONE:0)
Block(0,1,-4,SANDSTONE:0)
Block(0,1,-3,SANDSTONE:0)
Block(0,1,-2,SANDSTONE:0)
Block(0,1,-1,SANDSTONE:0)
Block(0,1,0,SANDSTONE:0)
Block(0,1,1,SANDSTONE:0)
Block(0,1,2,SANDSTONE:0)
Block(0,1,3,SANDSTONE:0)
Block(0,1,4,SANDSTONE:0)
Block(0,1,5,SANDSTONE:0)
Block(0,1,6,SANDSTONE:0)
Block(0,1,7,SANDSTONE:0)
Block(0,1,8,SANDSTONE:0)
Block(0,2,-7,SANDSTONE:0)
Block(0,2,-6,SANDSTONE:0)
Block(0,2,-5,SANDSTONE:0)
Block(0,2,-4,SANDSTONE:0)
Block(0,2,-3,SANDSTONE:0)
Block(0,2,-2,SANDSTONE:0)
Block(0,2,-1,SANDSTONE:0)
Block(0,2,0,SANDSTONE:0)
Block(0,2,1,SANDSTONE:0)
Block(0,2,2,SANDSTONE:0)
Block(0,2,3,SANDSTONE:0)
Block(0,2,4,SANDSTONE:0)
Block(0,2,5,SANDSTONE:0)
Block(0,2,6,SANDSTONE:0)
Block(0,2,7,SANDSTONE:0)
Block(0,2,8,SANDSTONE:0)
Block(0,3,-7,SANDSTONE:0)
Block(0,3,-6,SANDSTONE:0)
Block(0,3,-5,SANDSTONE:0)
Block(0,3,-4,SANDSTONE:0)
Block(0,3,-3,SANDSTONE:0)
Block(0,3,-2,SANDSTONE:0)
Block(0,3,-1,SANDSTONE:0)
Block(0,3,0,SANDSTONE:0)
Block(0,3,1,SANDSTONE:0)
Block(0,3,2,SANDSTONE:0)
Block(0,3,3,SANDSTONE:0)
Block(0,3,4,SANDSTONE:0)
Block(0,3,5,SANDSTONE:0)
Block(0,3,6,SANDSTONE:0)
Block(0,3,7,SANDSTONE:0)
Block(0,3,8,SANDSTONE:0)
Block(0,4,-7,SANDSTONE:0)
Block(0,4,-6,SANDSTONE:0)
Block(0,4,-5,SANDSTONE:0)
Block(0,4,-4,SANDSTONE:0)
Block(0,4,-3,SANDSTONE:0)
Block(0,4,-2,SANDSTONE:0)
Block(0,4,-1,SANDSTONE:0)
Block(0,4,0,SANDSTONE:0)
Block(0,4,1,SANDSTONE:0)
Block(0,4,2,SANDSTONE:0)
Block(0,4,3,SANDSTONE:0)
Block(0,4,4,SANDSTONE:0)
Block(0,4,5,SANDSTONE:0)
Block(0,4,6,SANDSTONE:0)
Block(0,4,7,SANDSTONE:0)
Block(0,4,8,SANDSTONE:0)
Block(0,5,-7,SANDSTONE:0)
Block(0,5,-6,SANDSTONE:0)
