
#######################################################################
# +-----------------------------------------------------------------+ #
# |                            BO3 object                           | #
# +-----------------------------------------------------------------+ #
#######################################################################

Author: NLBlackHeavenNL

Description: No description given

Version: 3

SettingsMode: WriteWithoutComments


#######################################################################
# +-----------------------------------------------------------------+ #
# |                          Main settings                          | #
# +-----------------------------------------------------------------+ #
#######################################################################

Tree: true

Frequency: 1

Rarity: 100.0

RotateRandomly: false

SpawnHeight: highestSolidBlock

SpawnHeightOffset: -1

SpawnHeightVariance: 0

##############################
# Height Limits for the BO3. #
##############################

MinHeight: 0

MaxHeight: 255

######################
# Extrusion settings #
######################

ExtrudeMode: None

ExtrudeThroughBlocks: AIR

MaxBranchDepth: 10

ExcludedBiomes: All


#######################################################################
# +-----------------------------------------------------------------+ #
# |                      Source block settings                      | #
# +-----------------------------------------------------------------+ #
#######################################################################

SourceBlocks: AIR,GRASS,DIRT,biomesoplenty:dirt

MaxPercentageOutsideSourceBlock: 0

OutsideSourceBlock: placeAnyway

DoReplaceBlocks: true

IsOTGPlus: false


#######################################################################
# +-----------------------------------------------------------------+ #
# |                              Blocks                             | #
# +-----------------------------------------------------------------+ #
#######################################################################

Block(-6,3,4,dynamictrees:leaves0:0)
Block(-6,3,5,dynamictrees:leaves0:0)
Block(-6,4,4,dynamictrees:leaves0:0)
Block(-6,4,5,dynamictrees:leaves0:0)
Block(-6,5,-1,dynamictrees:leaves0:0)
Block(-6,5,0,dynamictrees:leaves0:0)
Block(-6,5,1,dynamictrees:leaves0:0)
Block(-6,6,-1,dynamictrees:leaves0:0)
Block(-6,6,0,dynamictrees:leaves0:0)
Block(-6,6,1,dynamictrees:leaves0:0)
Block(-6,6,2,dynamictrees:leaves0:0)
Block(-6,7,-1,dynamictrees:leaves0:0)
Block(-6,7,0,dynamictrees:leaves0:0)
Block(-6,7,1,dynamictrees:leaves0:0)
Block(-5,2,4,dynamictrees:leaves0:0)
Block(-5,2,5,dynamictrees:leaves0:0)
Block(-5,3,3,dynamictrees:leaves0:0)
Block(-5,3,4,dynamictrees:leaves0:3)
Block(-5,3,5,dynamictrees:leaves0:2)
Block(-5,3,6,dynamictrees:leaves0:0)
Block(-5,4,3,dynamictrees:leaves0:0)
Block(-5,4,4,dynamictrees:leaves0:2)
Block(-5,4,5,dynamictrees:leaves0:1)
Block(-5,4,6,dynamictrees:leaves0:0)
Block(-5,5,-2,dynamictrees:leaves0:0)
Block(-5,5,-1,dynamictrees:leaves0:1)
Block(-5,5,0,dynamictrees:leaves0:2)
Block(-5,5,1,dynamictrees:leaves0:1)
Block(-5,5,2,dynamictrees:leaves0:0)
Block(-5,5,4,dynamictrees:leaves0:0)
Block(-5,5,5,dynamictrees:leaves0:0)
Block(-5,6,-2,dynamictrees:leaves0:0)
Block(-5,6,-1,dynamictrees:leaves0:2)
Block(-5,6,0,dynamictrees:leaves0:3)
Block(-5,6,1,dynamictrees:leaves0:2)
Block(-5,6,2,dynamictrees:leaves0:1)
Block(-5,6,3,dynamictrees:leaves0:0)
Block(-5,7,-2,dynamictrees:leaves0:0)
Block(-5,7,-1,dynamictrees:leaves0:1)
Block(-5,7,0,dynamictrees:leaves0:2)
Block(-5,7,1,dynamictrees:leaves0:1)
Block(-5,7,2,dynamictrees:leaves0:0)
Block(-5,8,-1,dynamictrees:leaves0:0)
Block(-5,8,0,dynamictrees:leaves0:0)
Block(-5,8,1,dynamictrees:leaves0:0)
Block(-4,2,5,dynamictrees:leaves0:0)
Block(-4,3,0,dynamictrees:oakbranch:1)
Block(-4,3,4,dynamictrees:oakbranch:0)
Block(-4,3,5,dynamictrees:leaves0:3)
Block(-4,3,6,dynamictrees:leaves0:0)
Block(-4,4,0,dynamictrees:oakbranch:0)
Block(-4,4,3,dynamictrees:leaves0:0)
Block(-4,4,4,dynamictrees:leaves0:3)
Block(-4,4,5,dynamictrees:leaves0:2)
Block(-4,4,6,dynamictrees:leaves0:0)
Block(-4,5,-2,dynamictrees:leaves0:0)
Block(-4,5,-1,dynamictrees:leaves0:2)
Block(-4,5,0,dynamictrees:leaves0:3)
Block(-4,5,4,dynamictrees:leaves0:0)
Block(-4,5,5,dynamictrees:leaves0:0)
Block(-4,6,-2,dynamictrees:leaves0:0)
Block(-4,6,-1,dynamictrees:leaves0:3)
Block(-4,6,0,dynamictrees:oakbranch:0)
Block(-4,6,1,dynamictrees:leaves0:3)
Block(-4,6,2,dynamictrees:leaves0:2)
Block(-4,6,3,dynamictrees:leaves0:0)
Block(-4,7,-2,dynamictrees:leaves0:0)
Block(-4,7,-1,dynamictrees:leaves0:2)
Block(-4,7,0,dynamictrees:leaves0:3)
Block(-4,7,1,dynamictrees:leaves0:2)
Block(-4,7,2,dynamictrees:leaves0:1)
Block(-4,7,3,dynamictrees:leaves0:0)
Block(-4,8,-1,dynamictrees:leaves0:0)
Block(-4,8,0,dynamictrees:leaves0:0)
Block(-4,8,1,dynamictrees:leaves0:1)
Block(-4,8,2,dynamictrees:leaves0:0)
Block(-4,8,3,dynamictrees:leaves0:0)
Block(-4,8,4,dynamictrees:leaves0:0)
Block(-4,9,1,dynamictrees:leaves0:0)
Block(-4,9,2,dynamictrees:leaves0:0)
Block(-4,9,3,dynamictrees:leaves0:0)
Block(-3,3,0,dynamictrees:oakbranch:1)
Block(-3,3,1,dynamictrees:oakbranch:1)
Block(-3,3,4,dynamictrees:oakbranch:1)
Block(-3,3,5,dynamictrees:leaves0:0)
Block(-3,4,4,dynamictrees:leaves0:0)
Block(-3,4,5,dynamictrees:leaves0:0)
Block(-3,5,1,dynamictrees:oakbranch:1)
Block(-3,5,2,dynamictrees:oakbranch:0)
Block(-3,6,0,dynamictrees:oakbranch:1)
Block(-3,6,2,dynamictrees:leaves0:3)
Block(-3,7,-1,dynamictrees:leaves0:0)
Block(-3,7,0,dynamictrees:leaves0:0)
Block(-3,7,1,dynamictrees:leaves0:1)
Block(-3,7,2,dynamictrees:leaves0:2)
Block(-3,7,3,dynamictrees:leaves0:1)
Block(-3,7,4,dynamictrees:leaves0:0)
Block(-3,8,-2,dynamictrees:leaves0:0)
Block(-3,8,-1,dynamictrees:leaves0:0)
Block(-3,8,0,dynamictrees:leaves0:1)
Block(-3,8,1,dynamictrees:leaves0:2)
Block(-3,8,2,dynamictrees:leaves0:3)
Block(-3,8,3,dynamictrees:leaves0:2)
Block(-3,8,4,dynamictrees:leaves0:1)
Block(-3,8,5,dynamictrees:leaves0:0)
Block(-3,9,-2,dynamictrees:leaves0:0)
Block(-3,9,-1,dynamictrees:leaves0:0)
Block(-3,9,0,dynamictrees:leaves0:0)
Block(-3,9,1,dynamictrees:leaves0:1)
Block(-3,9,2,dynamictrees:leaves0:2)
Block(-3,9,3,dynamictrees:leaves0:1)
Block(-3,9,4,dynamictrees:leaves0:0)
Block(-3,10,-1,dynamictrees:leaves0:0)
Block(-3,10,1,dynamictrees:leaves0:0)
Block(-3,10,2,dynamictrees:leaves0:0)
Block(-3,10,3,dynamictrees:leaves0:0)
Block(-2,3,1,dynamictrees:oakbranch:4)
Block(-2,3,4,dynamictrees:oakbranch:1)
Block(-2,4,-4,dynamictrees:leaves0:0)
Block(-2,4,-3,dynamictrees:leaves0:0)
Block(-2,4,0,dynamictrees:oakbranch:0)
Block(-2,4,1,dynamictrees:oakbranch:3)
Block(-2,5,-4,dynamictrees:leaves0:0)
Block(-2,5,-3,dynamictrees:leaves0:0)
Block(-2,5,0,dynamictrees:leaves0:3)
Block(-2,5,1,dynamictrees:oakbranch:3)
Block(-2,5,6,dynamictrees:leaves0:0)
Block(-2,5,7,dynamictrees:leaves0:0)
Block(-2,6,0,dynamictrees:oakbranch:1)
Block(-2,6,1,dynamictrees:oakbranch:2)
Block(-2,6,2,dynamictrees:oakbranch:1)
Block(-2,6,5,dynamictrees:leaves0:0)
Block(-2,6,6,dynamictrees:leaves0:0)
Block(-2,6,7,dynamictrees:leaves0:0)
Block(-2,7,-2,dynamictrees:leaves0:0)
Block(-2,7,2,dynamictrees:oakbranch:1)
Block(-2,7,3,dynamictrees:leaves0:0)
Block(-2,7,4,dynamictrees:leaves0:0)
Block(-2,7,6,dynamictrees:leaves0:0)
Block(-2,7,7,dynamictrees:leaves0:0)
Block(-2,8,-3,dynamictrees:leaves0:0)
Block(-2,8,-2,dynamictrees:leaves0:2)
Block(-2,8,-1,dynamictrees:leaves0:3)
Block(-2,8,0,dynamictrees:leaves0:2)
Block(-2,8,1,dynamictrees:leaves0:3)
Block(-2,8,2,dynamictrees:oakbranch:0)
Block(-2,8,3,dynamictrees:leaves0:3)
Block(-2,8,4,dynamictrees:leaves0:2)
Block(-2,8,5,dynamictrees:leaves0:0)
Block(-2,9,-3,dynamictrees:leaves0:0)
Block(-2,9,-2,dynamictrees:leaves0:1)
Block(-2,9,-1,dynamictrees:leaves0:2)
Block(-2,9,0,dynamictrees:leaves0:1)
Block(-2,9,1,dynamictrees:leaves0:2)
Block(-2,9,2,dynamictrees:leaves0:3)
Block(-2,9,3,dynamictrees:leaves0:2)
Block(-2,9,4,dynamictrees:leaves0:1)
Block(-2,9,5,dynamictrees:leaves0:0)
Block(-2,10,-2,dynamictrees:leaves0:0)
Block(-2,10,-1,dynamictrees:leaves0:1)
Block(-2,10,0,dynamictrees:leaves0:0)
Block(-2,10,1,dynamictrees:leaves0:1)
Block(-2,10,2,dynamictrees:leaves0:0)
Block(-2,10,3,dynamictrees:leaves0:1)
Block(-2,10,4,dynamictrees:leaves0:0)
Block(-2,11,-1,dynamictrees:leaves0:0)
Block(-2,11,0,dynamictrees:leaves0:0)
Block(-2,11,1,dynamictrees:leaves0:0)
Block(-2,11,3,dynamictrees:leaves0:0)
Block(-1,3,-4,dynamictrees:leaves0:0)
Block(-1,3,-3,dynamictrees:leaves0:0)
Block(-1,3,1,dynamictrees:oakbranch:4)
Block(-1,3,4,dynamictrees:oakbranch:2)
Block(-1,4,-5,dynamictrees:leaves0:0)
Block(-1,4,-4,dynamictrees:leaves0:2)
Block(-1,4,-3,dynamictrees:leaves0:3)
Block(-1,4,-1,dynamictrees:oakbranch:0)
Block(-1,4,4,dynamictrees:oakbranch:1)
Block(-1,4,5,dynamictrees:oakbranch:1)
Block(-1,5,-5,dynamictrees:leaves0:0)
Block(-1,5,-4,dynamictrees:leaves0:1)
Block(-1,5,-3,dynamictrees:leaves0:2)
Block(-1,5,-1,dynamictrees:leaves0:3)
Block(-1,5,5,dynamictrees:oakbranch:0)
Block(-1,5,6,dynamictrees:leaves0:3)
Block(-1,5,7,dynamictrees:leaves0:1)
Block(-1,5,8,dynamictrees:leaves0:0)
Block(-1,6,-4,dynamictrees:leaves0:0)
Block(-1,6,-3,dynamictrees:leaves0:0)
Block(-1,6,5,dynamictrees:leaves0:3)
Block(-1,6,6,dynamictrees:leaves0:3)
Block(-1,6,7,dynamictrees:leaves0:2)
Block(-1,6,8,dynamictrees:leaves0:0)
Block(-1,7,5,dynamictrees:leaves0:0)
Block(-1,7,6,dynamictrees:leaves0:2)
Block(-1,7,7,dynamictrees:leaves0:1)
Block(-1,7,8,dynamictrees:leaves0:0)
Block(-1,8,-3,dynamictrees:leaves0:0)
Block(-1,8,-2,dynamictrees:leaves0:3)
Block(-1,8,-1,dynamictrees:oakbranch:0)
Block(-1,8,2,dynamictrees:leaves0:3)
Block(-1,8,3,dynamictrees:oakbranch:0)
Block(-1,8,4,dynamictrees:leaves0:3)
Block(-1,8,5,dynamictrees:leaves0:0)
Block(-1,8,6,dynamictrees:leaves0:0)
Block(-1,8,7,dynamictrees:leaves0:0)
Block(-1,9,-3,dynamictrees:leaves0:0)
Block(-1,9,-2,dynamictrees:leaves0:2)
Block(-1,9,-1,dynamictrees:leaves0:3)
Block(-1,9,0,dynamictrees:leaves0:2)
Block(-1,9,1,dynamictrees:leaves0:1)
Block(-1,9,2,dynamictrees:leaves0:2)
Block(-1,9,3,dynamictrees:leaves0:3)
Block(-1,9,4,dynamictrees:leaves0:2)
Block(-1,9,5,dynamictrees:leaves0:0)
Block(-1,10,-3,dynamictrees:leaves0:0)
Block(-1,10,-2,dynamictrees:leaves0:1)
Block(-1,10,-1,dynamictrees:leaves0:2)
Block(-1,10,0,dynamictrees:leaves0:3)
Block(-1,10,1,dynamictrees:leaves0:2)
Block(-1,10,2,dynamictrees:leaves0:1)
Block(-1,10,3,dynamictrees:leaves0:2)
Block(-1,10,4,dynamictrees:leaves0:1)
Block(-1,10,5,dynamictrees:leaves0:0)
Block(-1,11,-2,dynamictrees:leaves0:0)
Block(-1,11,-1,dynamictrees:leaves0:1)
Block(-1,11,0,dynamictrees:leaves0:2)
Block(-1,11,1,dynamictrees:leaves0:1)
Block(-1,11,2,dynamictrees:leaves0:0)
Block(-1,11,3,dynamictrees:leaves0:0)
Block(-1,11,4,dynamictrees:leaves0:0)
Block(-1,12,-1,dynamictrees:leaves0:0)
Block(-1,12,0,dynamictrees:leaves0:0)
Block(-1,12,1,dynamictrees:leaves0:0)
Block(0,0,1,dynamictrees:rootydirt:0)
Block(0,1,1,dynamictrees:oakbranch:7)
Block(0,2,1,dynamictrees:oakbranch:7)
Block(0,3,-4,dynamictrees:leaves0:0)
Block(0,3,1,dynamictrees:oakbranch:7)
Block(0,3,2,dynamictrees:oakbranch:4)
Block(0,3,3,dynamictrees:oakbranch:4)
Block(0,3,4,dynamictrees:oakbranch:3)
Block(0,4,-5,dynamictrees:leaves0:0)
Block(0,4,-4,dynamictrees:leaves0:3)
Block(0,4,-3,dynamictrees:oakbranch:0)
Block(0,4,-2,dynamictrees:oakbranch:1)
Block(0,4,-1,dynamictrees:oakbranch:2)
Block(0,4,0,dynamictrees:oakbranch:2)
Block(0,4,1,dynamictrees:oakbranch:7)
Block(0,4,3,dynamictrees:oakbranch:2)
Block(0,5,-5,dynamictrees:leaves0:0)
Block(0,5,-4,dynamictrees:leaves0:2)
Block(0,5,-3,dynamictrees:leaves0:3)
Block(0,5,-1,dynamictrees:oakbranch:1)
Block(0,5,1,dynamictrees:oakbranch:6)
Block(0,5,3,dynamictrees:oakbranch:2)
Block(0,5,4,dynamictrees:oakbranch:1)
Block(0,5,6,dynamictrees:leaves0:3)
Block(0,5,7,dynamictrees:leaves0:2)
Block(0,5,8,dynamictrees:leaves0:0)
Block(0,6,-4,dynamictrees:leaves0:0)
Block(0,6,-3,dynamictrees:leaves0:0)
Block(0,6,0,dynamictrees:oakbranch:0)
Block(0,6,1,dynamictrees:oakbranch:5)
Block(0,6,4,dynamictrees:oakbranch:1)
Block(0,6,5,dynamictrees:oakbranch:1)
Block(0,6,6,dynamictrees:oakbranch:0)
Block(0,6,7,dynamictrees:leaves0:3)
Block(0,6,8,dynamictrees:leaves0:0)
Block(0,7,0,dynamictrees:leaves0:3)
Block(0,7,1,dynamictrees:oakbranch:4)
Block(0,7,2,dynamictrees:oakbranch:1)
Block(0,7,3,dynamictrees:oakbranch:1)
Block(0,7,5,dynamictrees:leaves0:0)
Block(0,7,6,dynamictrees:leaves0:3)
Block(0,7,7,dynamictrees:leaves0:2)
Block(0,7,8,dynamictrees:leaves0:0)
Block(0,8,-2,dynamictrees:leaves0:0)
Block(0,8,-1,dynamictrees:oakbranch:1)
Block(0,8,0,dynamictrees:oakbranch:2)
Block(0,8,1,dynamictrees:oakbranch:3)
Block(0,8,2,dynamictrees:leaves0:2)
Block(0,8,3,dynamictrees:oakbranch:1)
Block(0,8,4,dynamictrees:leaves0:2)
Block(0,8,5,dynamictrees:leaves0:0)
Block(0,8,6,dynamictrees:leaves0:0)
Block(0,8,7,dynamictrees:leaves0:0)
Block(0,9,-3,dynamictrees:leaves0:0)
Block(0,9,-2,dynamictrees:leaves0:1)
Block(0,9,-1,dynamictrees:leaves0:2)
Block(0,9,0,dynamictrees:oakbranch:1)
Block(0,9,1,dynamictrees:leaves0:2)
Block(0,9,2,dynamictrees:leaves0:3)
Block(0,9,3,dynamictrees:oakbranch:0)
Block(0,9,4,dynamictrees:leaves0:3)
Block(0,9,5,dynamictrees:leaves0:0)
Block(0,10,-2,dynamictrees:leaves0:0)
Block(0,10,-1,dynamictrees:leaves0:3)
Block(0,10,0,dynamictrees:oakbranch:0)
Block(0,10,1,dynamictrees:leaves0:3)
Block(0,10,2,dynamictrees:leaves0:2)
Block(0,10,3,dynamictrees:leaves0:3)
Block(0,10,4,dynamictrees:leaves0:2)
Block(0,10,5,dynamictrees:leaves0:0)
Block(0,11,-2,dynamictrees:leaves0:0)
Block(0,11,-1,dynamictrees:leaves0:2)
Block(0,11,0,dynamictrees:leaves0:3)
Block(0,11,1,dynamictrees:leaves0:2)
Block(0,11,2,dynamictrees:leaves0:1)
Block(0,11,3,dynamictrees:leaves0:0)
Block(0,11,4,dynamictrees:leaves0:0)
Block(0,12,-1,dynamictrees:leaves0:0)
Block(0,12,0,dynamictrees:leaves0:0)
Block(0,12,1,dynamictrees:leaves0:0)
Block(0,12,2,dynamictrees:leaves0:0)
Block(1,4,-4,dynamictrees:leaves0:0)
Block(1,4,-3,dynamictrees:leaves0:3)
Block(1,4,-2,dynamictrees:oakbranch:0)
Block(1,4,1,dynamictrees:oakbranch:3)
Block(1,5,-5,dynamictrees:leaves0:0)
Block(1,5,-4,dynamictrees:leaves0:1)
Block(1,5,-3,dynamictrees:leaves0:2)
Block(1,5,-2,dynamictrees:leaves0:3)
Block(1,5,-1,dynamictrees:oakbranch:1)
Block(1,5,4,dynamictrees:oakbranch:0)
Block(1,5,6,dynamictrees:leaves0:2)
Block(1,5,7,dynamictrees:leaves0:1)
Block(1,5,8,dynamictrees:leaves0:0)
Block(1,6,-4,dynamictrees:leaves0:0)
Block(1,6,-3,dynamictrees:leaves0:0)
Block(1,6,-1,dynamictrees:oakbranch:1)
Block(1,6,1,dynamictrees:oakbranch:2)
Block(1,6,4,dynamictrees:leaves0:3)
Block(1,6,6,dynamictrees:leaves0:3)
Block(1,6,7,dynamictrees:leaves0:2)
Block(1,6,8,dynamictrees:leaves0:0)
Block(1,7,-1,dynamictrees:oakbranch:0)
Block(1,7,4,dynamictrees:leaves0:0)
Block(1,7,5,dynamictrees:leaves0:0)
Block(1,7,6,dynamictrees:leaves0:2)
Block(1,7,7,dynamictrees:leaves0:1)
Block(1,7,8,dynamictrees:leaves0:0)
Block(1,8,-2,dynamictrees:leaves0:0)
Block(1,8,-1,dynamictrees:leaves0:3)
Block(1,8,1,dynamictrees:oakbranch:1)
Block(1,8,2,dynamictrees:oakbranch:1)
Block(1,8,3,dynamictrees:leaves0:0)
Block(1,8,4,dynamictrees:leaves0:1)
Block(1,8,5,dynamictrees:leaves0:0)
Block(1,8,6,dynamictrees:leaves0:0)
Block(1,8,7,dynamictrees:leaves0:0)
Block(1,9,-2,dynamictrees:leaves0:0)
Block(1,9,-1,dynamictrees:leaves0:3)
Block(1,9,0,dynamictrees:oakbranch:0)
Block(1,9,1,dynamictrees:leaves0:3)
Block(1,9,2,dynamictrees:oakbranch:0)
Block(1,9,3,dynamictrees:leaves0:3)
Block(1,9,4,dynamictrees:leaves0:2)
Block(1,9,5,dynamictrees:leaves0:0)
Block(1,10,-2,dynamictrees:leaves0:0)
Block(1,10,-1,dynamictrees:leaves0:2)
Block(1,10,0,dynamictrees:leaves0:3)
Block(1,10,1,dynamictrees:leaves0:2)
Block(1,10,2,dynamictrees:leaves0:3)
Block(1,10,3,dynamictrees:leaves0:2)
Block(1,10,4,dynamictrees:leaves0:1)
Block(1,10,5,dynamictrees:leaves0:0)
Block(1,11,-2,dynamictrees:leaves0:0)
Block(1,11,-1,dynamictrees:leaves0:1)
Block(1,11,0,dynamictrees:leaves0:2)
Block(1,11,1,dynamictrees:leaves0:1)
Block(1,11,2,dynamictrees:leaves0:0)
Block(1,11,3,dynamictrees:leaves0:0)
Block(1,11,4,dynamictrees:leaves0:0)
Block(1,12,-1,dynamictrees:leaves0:0)
Block(1,12,0,dynamictrees:leaves0:0)
Block(1,12,1,dynamictrees:leaves0:0)
Block(2,4,0,dynamictrees:oakbranch:1)
Block(2,4,1,dynamictrees:oakbranch:2)
Block(2,4,2,dynamictrees:oakbranch:1)
Block(2,4,4,dynamictrees:leaves0:0)
Block(2,5,-4,dynamictrees:leaves0:0)
Block(2,5,-3,dynamictrees:leaves0:0)
Block(2,5,-2,dynamictrees:leaves0:0)
Block(2,5,0,dynamictrees:oakbranch:0)
Block(2,5,2,dynamictrees:oakbranch:1)
Block(2,5,4,dynamictrees:leaves0:3)
Block(2,5,5,dynamictrees:leaves0:0)
Block(2,5,6,dynamictrees:leaves0:0)
Block(2,5,7,dynamictrees:leaves0:0)
Block(2,6,0,dynamictrees:leaves0:3)
Block(2,6,1,dynamictrees:oakbranch:2)
Block(2,6,4,dynamictrees:leaves0:2)
Block(2,6,5,dynamictrees:leaves0:0)
Block(2,6,6,dynamictrees:leaves0:0)
Block(2,6,7,dynamictrees:leaves0:0)
Block(2,7,0,dynamictrees:oakbranch:0)
Block(2,7,1,dynamictrees:oakbranch:1)
Block(2,7,4,dynamictrees:leaves0:0)
Block(2,7,6,dynamictrees:leaves0:0)
Block(2,7,7,dynamictrees:leaves0:0)
Block(2,8,-2,dynamictrees:leaves0:0)
Block(2,8,-1,dynamictrees:leaves0:2)
Block(2,8,0,dynamictrees:leaves0:3)
Block(2,8,1,dynamictrees:leaves0:0)
Block(2,8,2,dynamictrees:leaves0:0)
Block(2,8,3,dynamictrees:leaves0:0)
Block(2,8,4,dynamictrees:leaves0:0)
Block(2,9,-2,dynamictrees:leaves0:0)
Block(2,9,-1,dynamictrees:leaves0:2)
Block(2,9,0,dynamictrees:leaves0:3)
Block(2,9,1,dynamictrees:leaves0:2)
Block(2,9,2,dynamictrees:leaves0:3)
Block(2,9,3,dynamictrees:leaves0:2)
Block(2,9,4,dynamictrees:leaves0:1)
Block(2,9,5,dynamictrees:leaves0:0)
Block(2,10,-2,dynamictrees:leaves0:0)
Block(2,10,-1,dynamictrees:leaves0:1)
Block(2,10,0,dynamictrees:leaves0:2)
Block(2,10,1,dynamictrees:leaves0:1)
Block(2,10,2,dynamictrees:leaves0:2)
Block(2,10,3,dynamictrees:leaves0:1)
Block(2,10,4,dynamictrees:leaves0:0)
Block(2,11,-1,dynamictrees:leaves0:0)
Block(2,11,0,dynamictrees:leaves0:1)
Block(2,11,1,dynamictrees:leaves0:0)
Block(2,11,2,dynamictrees:leaves0:0)
Block(2,11,3,dynamictrees:leaves0:0)
Block(2,12,0,dynamictrees:leaves0:0)
Block(3,4,4,dynamictrees:leaves0:0)
Block(3,5,2,dynamictrees:oakbranch:1)
Block(3,5,3,dynamictrees:oakbranch:0)
Block(3,5,4,dynamictrees:leaves0:3)
Block(3,5,5,dynamictrees:leaves0:0)
Block(3,6,1,dynamictrees:oakbranch:1)
Block(3,6,3,dynamictrees:leaves0:3)
Block(3,6,4,dynamictrees:leaves0:2)
Block(3,6,5,dynamictrees:leaves0:0)
Block(3,7,-1,dynamictrees:leaves0:0)
Block(3,7,0,dynamictrees:leaves0:3)
Block(3,7,1,dynamictrees:leaves0:2)
Block(3,7,2,dynamictrees:leaves0:1)
Block(3,7,3,dynamictrees:leaves0:0)
Block(3,7,4,dynamictrees:leaves0:0)
Block(3,8,-2,dynamictrees:leaves0:0)
Block(3,8,-1,dynamictrees:leaves0:1)
Block(3,8,0,dynamictrees:leaves0:2)
Block(3,8,1,dynamictrees:leaves0:1)
Block(3,8,2,dynamictrees:leaves0:0)
Block(3,9,-1,dynamictrees:leaves0:0)
Block(3,9,0,dynamictrees:leaves0:0)
Block(3,9,1,dynamictrees:leaves0:0)
Block(3,9,2,dynamictrees:leaves0:0)
Block(3,9,3,dynamictrees:leaves0:0)
Block(3,9,4,dynamictrees:leaves0:0)
Block(3,10,-1,dynamictrees:leaves0:0)
Block(3,10,0,dynamictrees:leaves0:0)
Block(3,10,1,dynamictrees:leaves0:0)
Block(3,10,2,dynamictrees:leaves0:0)
Block(3,10,3,dynamictrees:leaves0:0)
Block(3,11,0,dynamictrees:leaves0:0)
Block(4,4,3,dynamictrees:leaves0:0)
Block(4,4,4,dynamictrees:leaves0:0)
Block(4,5,1,dynamictrees:leaves0:3)
Block(4,5,2,dynamictrees:leaves0:2)
Block(4,5,3,dynamictrees:leaves0:3)
Block(4,5,4,dynamictrees:leaves0:2)
Block(4,5,5,dynamictrees:leaves0:0)
Block(4,6,-1,dynamictrees:leaves0:0)
Block(4,6,0,dynamictrees:leaves0:3)
Block(4,6,1,dynamictrees:oakbranch:0)
Block(4,6,2,dynamictrees:leaves0:3)
Block(4,6,3,dynamictrees:leaves0:2)
Block(4,6,4,dynamictrees:leaves0:1)
Block(4,6,5,dynamictrees:leaves0:0)
Block(4,7,-1,dynamictrees:leaves0:0)
Block(4,7,0,dynamictrees:leaves0:2)
Block(4,7,1,dynamictrees:leaves0:3)
Block(4,7,2,dynamictrees:leaves0:2)
Block(4,7,3,dynamictrees:leaves0:1)
Block(4,7,4,dynamictrees:leaves0:0)
Block(4,8,-1,dynamictrees:leaves0:0)
Block(4,8,0,dynamictrees:leaves0:1)
Block(4,8,1,dynamictrees:leaves0:0)
Block(4,8,2,dynamictrees:leaves0:0)
Block(4,8,3,dynamictrees:leaves0:0)
Block(4,9,0,dynamictrees:leaves0:0)
Block(5,5,-1,dynamictrees:leaves0:0)
Block(5,5,0,dynamictrees:leaves0:1)
Block(5,5,1,dynamictrees:leaves0:2)
Block(5,5,2,dynamictrees:leaves0:1)
Block(5,5,3,dynamictrees:leaves0:0)
Block(5,5,4,dynamictrees:leaves0:0)
Block(5,6,-1,dynamictrees:leaves0:0)
Block(5,6,0,dynamictrees:leaves0:2)
Block(5,6,1,dynamictrees:leaves0:3)
Block(5,6,2,dynamictrees:leaves0:2)
Block(5,6,3,dynamictrees:leaves0:1)
Block(5,6,4,dynamictrees:leaves0:0)
Block(5,7,-1,dynamictrees:leaves0:0)
Block(5,7,0,dynamictrees:leaves0:1)
Block(5,7,1,dynamictrees:leaves0:2)
Block(5,7,2,dynamictrees:leaves0:1)
Block(5,7,3,dynamictrees:leaves0:0)
Block(5,8,0,dynamictrees:leaves0:0)
Block(5,8,1,dynamictrees:leaves0:0)
Block(5,8,2,dynamictrees:leaves0:0)
Block(6,5,0,dynamictrees:leaves0:0)
Block(6,5,1,dynamictrees:leaves0:0)
Block(6,5,2,dynamictrees:leaves0:0)
Block(6,6,0,dynamictrees:leaves0:0)
Block(6,6,1,dynamictrees:leaves0:0)
Block(6,6,2,dynamictrees:leaves0:0)
Block(6,6,3,dynamictrees:leaves0:0)
Block(6,7,0,dynamictrees:leaves0:0)
Block(6,7,1,dynamictrees:leaves0:0)
Block(6,7,2,dynamictrees:leaves0:0)

#######################################################################
# +-----------------------------------------------------------------+ #
# |                            BO3 checks                           | #
# +-----------------------------------------------------------------+ #
#######################################################################

BlockCheck(0,-1,1,GRASS,DIRT,biomesoplenty:grass,biomesoplenty:dirt)

#######################################################################
# +-----------------------------------------------------------------+ #
# |                             Branches                            | #
# +-----------------------------------------------------------------+ #
#######################################################################


#######################################################################
# +-----------------------------------------------------------------+ #
# |                             Entities                            | #
# +-----------------------------------------------------------------+ #
#######################################################################


#######################################################################
# +-----------------------------------------------------------------+ #
# |                            Particles                            | #
# +-----------------------------------------------------------------+ #
#######################################################################


#######################################################################
# +-----------------------------------------------------------------+ #
# |                             Spawners                            | #
# +-----------------------------------------------------------------+ #
#######################################################################


#######################################################################
# +-----------------------------------------------------------------+ #
# |                             ModData                             | #
# +-----------------------------------------------------------------+ #
#######################################################################

