
#######################################################################
# +-----------------------------------------------------------------+ #
# |                            BO3 object                           | #
# +-----------------------------------------------------------------+ #
#######################################################################

Author: NLBlackHeavenNL

Description: No description given

Version: 3

SettingsMode: WriteWithoutComments


#######################################################################
# +-----------------------------------------------------------------+ #
# |                          Main settings                          | #
# +-----------------------------------------------------------------+ #
#######################################################################

Tree: true

Frequency: 1

Rarity: 100.0

RotateRandomly: false

SpawnHeight: highestSolidBlock

SpawnHeightOffset: -1

SpawnHeightVariance: 0

##############################
# Height Limits for the BO3. #
##############################

MinHeight: 0

MaxHeight: 255

######################
# Extrusion settings #
######################

ExtrudeMode: None

ExtrudeThroughBlocks: AIR

MaxBranchDepth: 10

ExcludedBiomes: All


#######################################################################
# +-----------------------------------------------------------------+ #
# |                      Source block settings                      | #
# +-----------------------------------------------------------------+ #
#######################################################################

SourceBlocks: AIR,GRASS,DIRT,biomesoplenty:dirt

MaxPercentageOutsideSourceBlock: 0

OutsideSourceBlock: placeAnyway

DoReplaceBlocks: true

IsOTGPlus: false


#######################################################################
# +-----------------------------------------------------------------+ #
# |                              Blocks                             | #
# +-----------------------------------------------------------------+ #
#######################################################################

Block(-6,7,-1,dynamictreesquark:leaves0:0)
Block(-6,7,0,dynamictreesquark:leaves0:0)
Block(-6,7,1,dynamictreesquark:leaves0:0)
Block(-6,7,2,dynamictreesquark:leaves0:0)
Block(-6,8,0,dynamictreesquark:leaves0:0)
Block(-6,8,1,dynamictreesquark:leaves0:0)
Block(-6,8,2,dynamictreesquark:leaves0:0)
Block(-5,6,-1,dynamictreesquark:leaves0:0)
Block(-5,6,0,dynamictreesquark:leaves0:0)
Block(-5,6,1,dynamictreesquark:leaves0:0)
Block(-5,6,2,dynamictreesquark:leaves0:0)
Block(-5,7,-2,dynamictreesquark:leaves0:0)
Block(-5,7,-1,dynamictreesquark:leaves0:1)
Block(-5,7,0,dynamictreesquark:leaves0:2)
Block(-5,7,1,dynamictreesquark:leaves0:3)
Block(-5,7,2,dynamictreesquark:leaves0:2)
Block(-5,7,3,dynamictreesquark:leaves0:0)
Block(-5,8,-1,dynamictreesquark:leaves0:0)
Block(-5,8,0,dynamictreesquark:leaves0:1)
Block(-5,8,1,dynamictreesquark:leaves0:2)
Block(-5,8,2,dynamictreesquark:leaves0:1)
Block(-5,8,3,dynamictreesquark:leaves0:0)
Block(-5,9,0,dynamictreesquark:leaves0:0)
Block(-5,9,1,dynamictreesquark:leaves0:0)
Block(-5,9,2,dynamictreesquark:leaves0:0)
Block(-4,6,-1,dynamictreesquark:leaves0:0)
Block(-4,6,0,dynamictreesquark:leaves0:0)
Block(-4,6,2,dynamictreesquark:leaves0:0)
Block(-4,7,-2,dynamictreesquark:leaves0:0)
Block(-4,7,-1,dynamictreesquark:leaves0:2)
Block(-4,7,0,dynamictreesquark:leaves0:3)
Block(-4,7,1,dynamictreesquark:blossomingbranch:0)
Block(-4,7,2,dynamictreesquark:leaves0:3)
Block(-4,7,3,dynamictreesquark:leaves0:0)
Block(-4,8,-2,dynamictreesquark:leaves0:0)
Block(-4,8,-1,dynamictreesquark:leaves0:1)
Block(-4,8,0,dynamictreesquark:leaves0:2)
Block(-4,8,1,dynamictreesquark:leaves0:3)
Block(-4,8,2,dynamictreesquark:leaves0:2)
Block(-4,8,3,dynamictreesquark:leaves0:0)
Block(-4,9,-1,dynamictreesquark:leaves0:0)
Block(-4,9,0,dynamictreesquark:leaves0:0)
Block(-4,9,1,dynamictreesquark:leaves0:0)
Block(-4,9,2,dynamictreesquark:leaves0:0)
Block(-4,10,1,dynamictreesquark:leaves0:0)
Block(-3,6,-1,dynamictreesquark:leaves0:0)
Block(-3,6,3,dynamictreesquark:leaves0:0)
Block(-3,7,-2,dynamictreesquark:leaves0:0)
Block(-3,7,-1,dynamictreesquark:leaves0:3)
Block(-3,7,0,dynamictreesquark:blossomingbranch:0)
Block(-3,7,1,dynamictreesquark:blossomingbranch:1)
Block(-3,7,2,dynamictreesquark:leaves0:3)
Block(-3,7,3,dynamictreesquark:leaves0:2)
Block(-3,7,4,dynamictreesquark:leaves0:0)
Block(-3,8,-2,dynamictreesquark:leaves0:0)
Block(-3,8,-1,dynamictreesquark:leaves0:2)
Block(-3,8,0,dynamictreesquark:leaves0:3)
Block(-3,8,1,dynamictreesquark:leaves0:3)
Block(-3,8,2,dynamictreesquark:leaves0:2)
Block(-3,8,3,dynamictreesquark:leaves0:1)
Block(-3,8,4,dynamictreesquark:leaves0:0)
Block(-3,9,-1,dynamictreesquark:leaves0:0)
Block(-3,9,0,dynamictreesquark:leaves0:1)
Block(-3,9,1,dynamictreesquark:leaves0:2)
Block(-3,9,2,dynamictreesquark:leaves0:1)
Block(-3,9,3,dynamictreesquark:leaves0:0)
Block(-3,10,0,dynamictreesquark:leaves0:0)
Block(-3,10,1,dynamictreesquark:leaves0:1)
Block(-3,10,2,dynamictreesquark:leaves0:0)
Block(-3,11,1,dynamictreesquark:leaves0:0)
Block(-2,5,1,dynamictreesquark:blossomingbranch:2)
Block(-2,6,1,dynamictreesquark:blossomingbranch:2)
Block(-2,7,-3,dynamictreesquark:leaves0:0)
Block(-2,7,-2,dynamictreesquark:leaves0:0)
Block(-2,7,-1,dynamictreesquark:leaves0:0)
Block(-2,7,1,dynamictreesquark:blossomingbranch:2)
Block(-2,7,2,dynamictreesquark:blossomingbranch:0)
Block(-2,8,-3,dynamictreesquark:leaves0:0)
Block(-2,8,-2,dynamictreesquark:leaves0:0)
Block(-2,8,-1,dynamictreesquark:leaves0:0)
Block(-2,8,1,dynamictreesquark:blossomingbranch:0)
Block(-2,8,3,dynamictreesquark:leaves0:0)
Block(-2,9,-3,dynamictreesquark:leaves0:0)
Block(-2,9,-2,dynamictreesquark:leaves0:0)
Block(-2,9,-1,dynamictreesquark:leaves0:0)
Block(-2,9,0,dynamictreesquark:leaves0:2)
Block(-2,9,1,dynamictreesquark:leaves0:3)
Block(-2,9,2,dynamictreesquark:leaves0:2)
Block(-2,9,3,dynamictreesquark:leaves0:0)
Block(-2,9,4,dynamictreesquark:leaves0:0)
Block(-2,10,-1,dynamictreesquark:leaves0:0)
Block(-2,10,0,dynamictreesquark:leaves0:1)
Block(-2,10,1,dynamictreesquark:leaves0:2)
Block(-2,10,2,dynamictreesquark:leaves0:1)
Block(-2,10,3,dynamictreesquark:leaves0:0)
Block(-2,10,4,dynamictreesquark:leaves0:0)
Block(-2,11,0,dynamictreesquark:leaves0:0)
Block(-2,11,1,dynamictreesquark:leaves0:0)
Block(-2,11,2,dynamictreesquark:leaves0:0)
Block(-2,11,3,dynamictreesquark:leaves0:0)
Block(-2,12,0,dynamictreesquark:leaves0:0)
Block(-2,12,1,dynamictreesquark:leaves0:0)
Block(-2,12,2,dynamictreesquark:leaves0:0)
Block(-1,5,1,dynamictreesquark:blossomingbranch:3)
Block(-1,5,2,dynamictreesquark:blossomingbranch:0)
Block(-1,6,0,dynamictreesquark:blossomingbranch:0)
Block(-1,6,2,dynamictreesquark:leaves0:3)
Block(-1,7,-4,dynamictreesquark:leaves0:0)
Block(-1,7,-3,dynamictreesquark:leaves0:1)
Block(-1,7,-2,dynamictreesquark:leaves0:2)
Block(-1,7,2,dynamictreesquark:leaves0:3)
Block(-1,8,-4,dynamictreesquark:leaves0:0)
Block(-1,8,-3,dynamictreesquark:leaves0:2)
Block(-1,8,-2,dynamictreesquark:leaves0:3)
Block(-1,8,0,dynamictreesquark:blossomingbranch:0)
Block(-1,8,2,dynamictreesquark:blossomingbranch:0)
Block(-1,8,4,dynamictreesquark:leaves0:0)
Block(-1,9,-4,dynamictreesquark:leaves0:0)
Block(-1,9,-3,dynamictreesquark:leaves0:1)
Block(-1,9,-2,dynamictreesquark:leaves0:2)
Block(-1,9,-1,dynamictreesquark:leaves0:0)
Block(-1,9,0,dynamictreesquark:leaves0:3)
Block(-1,9,1,dynamictreesquark:blossomingbranch:0)
Block(-1,9,2,dynamictreesquark:leaves0:3)
Block(-1,9,3,dynamictreesquark:leaves0:3)
Block(-1,9,4,dynamictreesquark:leaves0:2)
Block(-1,9,5,dynamictreesquark:leaves0:0)
Block(-1,10,-3,dynamictreesquark:leaves0:0)
Block(-1,10,-2,dynamictreesquark:leaves0:0)
Block(-1,10,-1,dynamictreesquark:leaves0:0)
Block(-1,10,0,dynamictreesquark:leaves0:2)
Block(-1,10,1,dynamictreesquark:leaves0:3)
Block(-1,10,2,dynamictreesquark:leaves0:2)
Block(-1,10,3,dynamictreesquark:leaves0:2)
Block(-1,10,4,dynamictreesquark:leaves0:1)
Block(-1,10,5,dynamictreesquark:leaves0:0)
Block(-1,11,-1,dynamictreesquark:leaves0:0)
Block(-1,11,0,dynamictreesquark:leaves0:2)
Block(-1,11,1,dynamictreesquark:leaves0:3)
Block(-1,11,2,dynamictreesquark:leaves0:2)
Block(-1,11,3,dynamictreesquark:leaves0:1)
Block(-1,11,4,dynamictreesquark:leaves0:0)
Block(-1,12,-1,dynamictreesquark:leaves0:0)
Block(-1,12,0,dynamictreesquark:leaves0:1)
Block(-1,12,1,dynamictreesquark:leaves0:2)
Block(-1,12,2,dynamictreesquark:leaves0:1)
Block(-1,12,3,dynamictreesquark:leaves0:0)
Block(-1,13,0,dynamictreesquark:leaves0:0)
Block(-1,13,1,dynamictreesquark:leaves0:0)
Block(-1,13,2,dynamictreesquark:leaves0:0)
Block(0,0,1,dynamictrees:rootydirt:15)
Block(0,1,1,dynamictreesquark:blossomingbranch:7)
Block(0,2,1,dynamictreesquark:blossomingbranch:7)
Block(0,3,1,dynamictreesquark:blossomingbranch:7)
Block(0,4,1,dynamictreesquark:blossomingbranch:7)
Block(0,5,1,dynamictreesquark:blossomingbranch:7)
Block(0,6,0,dynamictreesquark:blossomingbranch:1)
Block(0,6,1,dynamictreesquark:blossomingbranch:5)
Block(0,6,2,dynamictreesquark:blossomingbranch:0)
Block(0,7,-4,dynamictreesquark:leaves0:0)
Block(0,7,-3,dynamictreesquark:leaves0:2)
Block(0,7,-2,dynamictreesquark:leaves0:3)
Block(0,7,1,dynamictreesquark:blossomingbranch:5)
Block(0,7,2,dynamictreesquark:leaves0:3)
Block(0,8,-4,dynamictreesquark:leaves0:0)
Block(0,8,-3,dynamictreesquark:leaves0:3)
Block(0,8,-2,dynamictreesquark:blossomingbranch:0)
Block(0,8,-1,dynamictreesquark:blossomingbranch:1)
Block(0,8,0,dynamictreesquark:blossomingbranch:1)
Block(0,8,1,dynamictreesquark:blossomingbranch:4)
Block(0,8,2,dynamictreesquark:blossomingbranch:2)
Block(0,8,3,dynamictreesquark:blossomingbranch:1)
Block(0,9,-4,dynamictreesquark:leaves0:0)
Block(0,9,-3,dynamictreesquark:leaves0:2)
Block(0,9,-2,dynamictreesquark:leaves0:3)
Block(0,9,-1,dynamictreesquark:leaves0:0)
Block(0,9,1,dynamictreesquark:blossomingbranch:2)
Block(0,9,3,dynamictreesquark:blossomingbranch:0)
Block(0,9,4,dynamictreesquark:leaves0:3)
Block(0,9,5,dynamictreesquark:leaves0:0)
Block(0,10,-3,dynamictreesquark:leaves0:0)
Block(0,10,-2,dynamictreesquark:leaves0:0)
Block(0,10,-1,dynamictreesquark:leaves0:0)
Block(0,10,0,dynamictreesquark:leaves0:2)
Block(0,10,1,dynamictreesquark:blossomingbranch:1)
Block(0,10,2,dynamictreesquark:leaves0:2)
Block(0,10,3,dynamictreesquark:leaves0:3)
Block(0,10,4,dynamictreesquark:leaves0:2)
Block(0,10,5,dynamictreesquark:leaves0:0)
Block(0,11,-1,dynamictreesquark:leaves0:0)
Block(0,11,0,dynamictreesquark:leaves0:3)
Block(0,11,1,dynamictreesquark:blossomingbranch:0)
Block(0,11,2,dynamictreesquark:leaves0:3)
Block(0,11,3,dynamictreesquark:leaves0:2)
Block(0,11,4,dynamictreesquark:leaves0:1)
Block(0,11,5,dynamictreesquark:leaves0:0)
Block(0,12,-1,dynamictreesquark:leaves0:0)
Block(0,12,0,dynamictreesquark:leaves0:2)
Block(0,12,1,dynamictreesquark:leaves0:3)
Block(0,12,2,dynamictreesquark:leaves0:2)
Block(0,12,3,dynamictreesquark:leaves0:1)
Block(0,12,4,dynamictreesquark:leaves0:0)
Block(0,13,0,dynamictreesquark:leaves0:0)
Block(0,13,1,dynamictreesquark:leaves0:0)
Block(0,13,2,dynamictreesquark:leaves0:0)
Block(0,13,3,dynamictreesquark:leaves0:0)
Block(1,3,1,dynamictreesquark:blossomingbranch:5)
Block(1,5,1,dynamictreesquark:blossomingbranch:0)
Block(1,7,-4,dynamictreesquark:leaves0:0)
Block(1,7,-3,dynamictreesquark:leaves0:1)
Block(1,7,-2,dynamictreesquark:leaves0:2)
Block(1,7,1,dynamictreesquark:blossomingbranch:1)
Block(1,8,-4,dynamictreesquark:leaves0:0)
Block(1,8,-3,dynamictreesquark:leaves0:2)
Block(1,8,-2,dynamictreesquark:leaves0:3)
Block(1,8,4,dynamictreesquark:leaves0:0)
Block(1,9,-4,dynamictreesquark:leaves0:0)
Block(1,9,-3,dynamictreesquark:leaves0:1)
Block(1,9,-2,dynamictreesquark:leaves0:2)
Block(1,9,-1,dynamictreesquark:leaves0:0)
Block(1,9,3,dynamictreesquark:leaves0:3)
Block(1,9,4,dynamictreesquark:leaves0:2)
Block(1,9,5,dynamictreesquark:leaves0:0)
Block(1,10,-3,dynamictreesquark:leaves0:0)
Block(1,10,-2,dynamictreesquark:leaves0:0)
Block(1,10,-1,dynamictreesquark:leaves0:0)
Block(1,10,0,dynamictreesquark:leaves0:3)
Block(1,10,1,dynamictreesquark:blossomingbranch:0)
Block(1,10,2,dynamictreesquark:leaves0:3)
Block(1,10,3,dynamictreesquark:leaves0:2)
Block(1,10,4,dynamictreesquark:leaves0:1)
Block(1,10,5,dynamictreesquark:leaves0:0)
Block(1,11,-1,dynamictreesquark:leaves0:0)
Block(1,11,0,dynamictreesquark:leaves0:2)
Block(1,11,1,dynamictreesquark:leaves0:3)
Block(1,11,2,dynamictreesquark:leaves0:2)
Block(1,11,3,dynamictreesquark:leaves0:1)
Block(1,11,4,dynamictreesquark:leaves0:0)
Block(1,12,-1,dynamictreesquark:leaves0:0)
Block(1,12,0,dynamictreesquark:leaves0:1)
Block(1,12,1,dynamictreesquark:leaves0:2)
Block(1,12,2,dynamictreesquark:leaves0:1)
Block(1,12,3,dynamictreesquark:leaves0:0)
Block(1,13,0,dynamictreesquark:leaves0:0)
Block(1,13,1,dynamictreesquark:leaves0:0)
Block(1,13,2,dynamictreesquark:leaves0:0)
Block(2,2,0,dynamictreesquark:blossomingbranch:0)
Block(2,3,0,dynamictreesquark:blossomingbranch:2)
Block(2,3,1,dynamictreesquark:blossomingbranch:5)
Block(2,3,2,dynamictreesquark:blossomingbranch:2)
Block(2,3,3,dynamictreesquark:blossomingbranch:0)
Block(2,4,0,dynamictreesquark:blossomingbranch:2)
Block(2,4,2,dynamictreesquark:blossomingbranch:1)
Block(2,4,3,dynamictreesquark:leaves0:3)
Block(2,5,0,dynamictreesquark:blossomingbranch:1)
Block(2,5,2,dynamictreesquark:blossomingbranch:1)
Block(2,5,3,dynamictreesquark:leaves0:3)
Block(2,6,-4,dynamictreesquark:leaves0:0)
Block(2,6,-3,dynamictreesquark:leaves0:3)
Block(2,6,-2,dynamictreesquark:blossomingbranch:0)
Block(2,6,-1,dynamictreesquark:blossomingbranch:1)
Block(2,6,0,dynamictreesquark:blossomingbranch:1)
Block(2,6,2,dynamictreesquark:blossomingbranch:1)
Block(2,6,3,dynamictreesquark:blossomingbranch:0)
Block(2,7,-4,dynamictreesquark:leaves0:0)
Block(2,7,-3,dynamictreesquark:leaves0:2)
Block(2,7,-2,dynamictreesquark:leaves0:3)
Block(2,7,1,dynamictreesquark:blossomingbranch:1)
Block(2,7,3,dynamictreesquark:leaves0:3)
Block(2,7,4,dynamictreesquark:leaves0:0)
Block(2,8,-4,dynamictreesquark:leaves0:0)
Block(2,8,-3,dynamictreesquark:leaves0:1)
Block(2,8,-2,dynamictreesquark:leaves0:2)
Block(2,8,-1,dynamictreesquark:leaves0:0)
Block(2,8,1,dynamictreesquark:blossomingbranch:0)
Block(2,8,3,dynamictreesquark:leaves0:0)
Block(2,9,-3,dynamictreesquark:leaves0:0)
Block(2,9,-2,dynamictreesquark:leaves0:1)
Block(2,9,-1,dynamictreesquark:leaves0:0)
Block(2,9,0,dynamictreesquark:leaves0:0)
Block(2,9,1,dynamictreesquark:leaves0:3)
Block(2,9,2,dynamictreesquark:leaves0:0)
Block(2,9,3,dynamictreesquark:leaves0:0)
Block(2,9,4,dynamictreesquark:leaves0:0)
Block(2,10,-2,dynamictreesquark:leaves0:0)
Block(2,10,-1,dynamictreesquark:leaves0:0)
Block(2,10,0,dynamictreesquark:leaves0:2)
Block(2,10,1,dynamictreesquark:leaves0:3)
Block(2,10,2,dynamictreesquark:leaves0:2)
Block(2,10,3,dynamictreesquark:leaves0:1)
Block(2,10,4,dynamictreesquark:leaves0:0)
Block(2,11,-1,dynamictreesquark:leaves0:0)
Block(2,11,0,dynamictreesquark:leaves0:1)
Block(2,11,1,dynamictreesquark:leaves0:2)
Block(2,11,2,dynamictreesquark:leaves0:1)
Block(2,11,3,dynamictreesquark:leaves0:0)
Block(2,12,0,dynamictreesquark:leaves0:0)
Block(2,12,1,dynamictreesquark:leaves0:1)
Block(2,12,2,dynamictreesquark:leaves0:0)
Block(2,13,1,dynamictreesquark:leaves0:0)
Block(3,1,0,dynamictreesquark:leaves0:0)
Block(3,2,-1,dynamictreesquark:leaves0:0)
Block(3,2,0,dynamictreesquark:leaves0:3)
Block(3,3,0,dynamictreesquark:leaves0:0)
Block(3,3,1,dynamictreesquark:blossomingbranch:3)
Block(3,4,1,dynamictreesquark:blossomingbranch:2)
Block(3,5,-3,dynamictreesquark:leaves0:0)
Block(3,5,1,dynamictreesquark:blossomingbranch:1)
Block(3,5,3,dynamictreesquark:leaves0:2)
Block(3,5,4,dynamictreesquark:leaves0:0)
Block(3,6,-4,dynamictreesquark:leaves0:0)
Block(3,6,-3,dynamictreesquark:leaves0:2)
Block(3,6,-2,dynamictreesquark:leaves0:3)
Block(3,6,-1,dynamictreesquark:leaves0:0)
Block(3,6,1,dynamictreesquark:blossomingbranch:1)
Block(3,6,3,dynamictreesquark:leaves0:3)
Block(3,6,4,dynamictreesquark:leaves0:0)
Block(3,7,-4,dynamictreesquark:leaves0:0)
Block(3,7,-3,dynamictreesquark:leaves0:1)
Block(3,7,-2,dynamictreesquark:leaves0:2)
Block(3,7,-1,dynamictreesquark:leaves0:0)
Block(3,7,3,dynamictreesquark:leaves0:2)
Block(3,7,4,dynamictreesquark:leaves0:0)
Block(3,8,-3,dynamictreesquark:leaves0:0)
Block(3,8,-2,dynamictreesquark:leaves0:1)
Block(3,8,-1,dynamictreesquark:leaves0:0)
Block(3,8,3,dynamictreesquark:leaves0:0)
Block(3,9,-2,dynamictreesquark:leaves0:0)
Block(3,9,1,dynamictreesquark:leaves0:0)
Block(3,10,0,dynamictreesquark:leaves0:0)
Block(3,10,1,dynamictreesquark:leaves0:0)
Block(3,10,2,dynamictreesquark:leaves0:0)
Block(3,10,3,dynamictreesquark:leaves0:0)
Block(3,11,0,dynamictreesquark:leaves0:0)
Block(3,11,1,dynamictreesquark:leaves0:0)
Block(3,11,2,dynamictreesquark:leaves0:0)
Block(3,12,1,dynamictreesquark:leaves0:0)
Block(4,2,0,dynamictreesquark:leaves0:0)
Block(4,4,1,dynamictreesquark:blossomingbranch:1)
Block(4,4,2,dynamictreesquark:blossomingbranch:0)
Block(4,5,1,dynamictreesquark:leaves0:0)
Block(4,5,2,dynamictreesquark:leaves0:3)
Block(4,5,3,dynamictreesquark:leaves0:2)
Block(4,5,4,dynamictreesquark:leaves0:0)
Block(4,6,-3,dynamictreesquark:leaves0:0)
Block(4,6,-2,dynamictreesquark:leaves0:0)
Block(4,6,1,dynamictreesquark:blossomingbranch:1)
Block(4,6,2,dynamictreesquark:blossomingbranch:0)
Block(4,6,3,dynamictreesquark:leaves0:3)
Block(4,6,4,dynamictreesquark:leaves0:0)
Block(4,7,-3,dynamictreesquark:leaves0:0)
Block(4,7,-2,dynamictreesquark:leaves0:0)
Block(4,7,1,dynamictreesquark:leaves0:0)
Block(4,7,2,dynamictreesquark:leaves0:3)
Block(4,7,3,dynamictreesquark:leaves0:2)
Block(4,7,4,dynamictreesquark:leaves0:0)
Block(4,8,-2,dynamictreesquark:leaves0:0)
Block(4,8,2,dynamictreesquark:leaves0:0)
Block(4,8,3,dynamictreesquark:leaves0:0)
Block(5,5,1,dynamictreesquark:leaves0:0)
Block(5,5,2,dynamictreesquark:leaves0:2)
Block(5,5,3,dynamictreesquark:leaves0:1)
Block(5,5,4,dynamictreesquark:leaves0:0)
Block(5,6,1,dynamictreesquark:leaves0:0)
Block(5,6,2,dynamictreesquark:leaves0:3)
Block(5,6,3,dynamictreesquark:leaves0:2)
Block(5,6,4,dynamictreesquark:leaves0:0)
Block(5,7,1,dynamictreesquark:leaves0:0)
Block(5,7,2,dynamictreesquark:leaves0:2)
Block(5,7,3,dynamictreesquark:leaves0:1)
Block(5,7,4,dynamictreesquark:leaves0:0)
Block(5,8,2,dynamictreesquark:leaves0:0)
Block(5,8,3,dynamictreesquark:leaves0:0)
Block(6,5,2,dynamictreesquark:leaves0:0)
Block(6,5,3,dynamictreesquark:leaves0:0)
Block(6,6,2,dynamictreesquark:leaves0:0)
Block(6,6,3,dynamictreesquark:leaves0:0)
Block(6,7,2,dynamictreesquark:leaves0:0)
Block(6,7,3,dynamictreesquark:leaves0:0)

#######################################################################
# +-----------------------------------------------------------------+ #
# |                            BO3 checks                           | #
# +-----------------------------------------------------------------+ #
#######################################################################

BlockCheck(0,-1,1,GRASS,DIRT,biomesoplenty:grass,biomesoplenty:dirt)

#######################################################################
# +-----------------------------------------------------------------+ #
# |                             Branches                            | #
# +-----------------------------------------------------------------+ #
#######################################################################


#######################################################################
# +-----------------------------------------------------------------+ #
# |                             Entities                            | #
# +-----------------------------------------------------------------+ #
#######################################################################


#######################################################################
# +-----------------------------------------------------------------+ #
# |                            Particles                            | #
# +-----------------------------------------------------------------+ #
#######################################################################


#######################################################################
# +-----------------------------------------------------------------+ #
# |                             Spawners                            | #
# +-----------------------------------------------------------------+ #
#######################################################################


#######################################################################
# +-----------------------------------------------------------------+ #
# |                             ModData                             | #
# +-----------------------------------------------------------------+ #
#######################################################################

