
#######################################################################
# +-----------------------------------------------------------------+ #
# |                            BO4 object                           | #
# +-----------------------------------------------------------------+ #
#######################################################################

Author: NLBlackEagle

Description: No description given

SettingsMode: WriteWithoutComments


#######################################################################
# +-----------------------------------------------------------------+ #
# |                          Main settings                          | #
# +-----------------------------------------------------------------+ #
#######################################################################

FixedRotation: 

Frequency: 0

SpawnHeight: randomY

UseCenterForHighestBlock: true

##############################
# Height Limits for the BO4. #
##############################

MinHeight: 78

MaxHeight: 78

InheritBO3: 

InheritBO3Rotation: NORTH

OverrideChildSettings: true

OverrideParentHeight: false

CanOverride: true

BranchFrequency: 0

BranchFrequencyGroup: 

MustBeBelowOther: false

MustBeInside: 

CannotBeInside: 

ReplacesBO3: 

MustBeInsideWorldBorders: false

CanSpawnOnWater: true

SpawnOnWaterOnly: false

SpawnUnderWater: false

SpawnAtWaterLevel: false

HeightOffset: 0

RemoveAir: false

ReplaceAbove: 

ReplaceBelow: 

ReplaceWithBiomeBlocks: true

ReplaceWithSurfaceBlock: GRASS

ReplaceWithGroundBlock: DIRT

ReplaceWithStoneBlock: STONE

SmoothRadius: 0

SmoothHeightOffset: 0

SmoothStartTop: false

SmoothStartWood: false

SmoothingSurfaceBlock: 

SmoothingGroundBlock: 

BO3Group: 

IsSpawnPoint: false

DoReplaceBlocks: false


#######################################################################
# +-----------------------------------------------------------------+ #
# |                              Blocks                             | #
# +-----------------------------------------------------------------+ #
#######################################################################

Block(-8,0,2,quark:limestone:0)
Block(-8,0,3,quark:limestone:0)
Block(-8,0,4,quark:limestone:0)
Block(-8,0,5,quark:limestone:0)
Block(-8,0,6,quark:limestone:0)
Block(-8,0,7,quark:limestone:0)
Block(-8,0,8,quark:limestone:0)
Block(-8,1,2,COBBLESTONE_STAIRS:2)
Block(-8,1,3,quark:limestone:0)
Block(-8,1,4,srparasites:deadblood:1)
Block(-8,1,5,srparasites:deadblood:1)
Block(-8,1,6,srparasites:deadblood:1)
Block(-8,1,7,quark:limestone:0)
Block(-8,1,8,COBBLESTONE_STAIRS:3)
Block(-8,2,3,quark:limestone:0)
Block(-8,2,4,srparasites:deadblood:0)
Block(-8,2,5,srparasites:deadblood:1)
Block(-8,2,6,srparasites:deadblood:0)
Block(-8,2,7,quark:limestone:0)
Block(-8,3,3,quark:limestone:0)
Block(-8,3,4,AIR:0)
Block(-8,3,5,AIR:0)
Block(-8,3,6,AIR:0)
Block(-8,3,7,quark:limestone:0)
Block(-8,4,-6,COBBLESTONE_STAIRS:6)
RandomBlock(-8,4,-5,quark:iron_plate:1,70,STAINED_CLAY:15,30,STAINED_CLAY:7,30,quark:iron_plate:1,100)
RandomBlock(-8,4,-4,quark:iron_plate:1,70,STAINED_CLAY:15,30,STAINED_CLAY:7,30,quark:iron_plate:1,100)
RandomBlock(-8,4,-3,quark:iron_plate:1,70,STAINED_CLAY:15,30,STAINED_CLAY:7,30,quark:iron_plate:1,100)
RandomBlock(-8,4,-2,quark:iron_plate:1,70,STAINED_CLAY:15,30,STAINED_CLAY:7,30,quark:iron_plate:1,100)
RandomBlock(-8,4,-1,rustic:iron_lattice:1,30,rustic:iron_lattice:1,30,biomesoplenty:leaves_2:7,30,quark:iron_plate_stairs:6,10,quark:iron_plate_stairs:0,10,quark:iron_plate_stairs:5,10,quark:iron_plate_stairs:3,10,quark:iron_plate_slab:8,10,quark:iron_plate_stairs:7,10,quark:iron_plate_stairs:1,10,quark:iron_plate_slab:0,10,quark:iron_plate_stairs:4,10,quark:iron_plate_stairs:2,10,rustic:iron_lattice:1,50,rustic:iron_lattice:1,50,biomesoplenty:leaves_2:7,100)
RandomBlock(-8,4,0,rustic:iron_lattice:1,30,rustic:iron_lattice:1,30,biomesoplenty:leaves_2:7,30,quark:iron_plate_stairs:6,10,quark:iron_plate_stairs:0,10,quark:iron_plate_stairs:5,10,quark:iron_plate_stairs:3,10,quark:iron_plate_slab:8,10,quark:iron_plate_stairs:7,10,quark:iron_plate_stairs:1,10,quark:iron_plate_slab:0,10,quark:iron_plate_stairs:4,10,quark:iron_plate_stairs:2,10,rustic:iron_lattice:1,50,rustic:iron_lattice:1,50,biomesoplenty:leaves_2:7,100)
RandomBlock(-8,4,1,quark:iron_plate:1,70,STAINED_CLAY:15,30,STAINED_CLAY:7,30,quark:iron_plate:1,100)
RandomBlock(-8,4,2,quark:iron_plate:1,70,STAINED_CLAY:15,30,STAINED_CLAY:7,30,quark:iron_plate:1,100)
RandomBlock(-8,4,3,quark:iron_plate:1,70,STAINED_CLAY:15,30,STAINED_CLAY:7,30,quark:iron_plate:1,100)
Block(-8,4,4,AIR:0)
Block(-8,4,5,AIR:0)
Block(-8,4,6,AIR:0)
Block(-8,4,7,quark:limestone:0)
RandomBlock(-8,5,-6,quark:iron_plate:1,70,STAINED_CLAY:15,30,STAINED_CLAY:7,30,quark:iron_plate:1,100)
Block(-8,5,-5,AIR:0)
Block(-8,5,-4,AIR:0)
Block(-8,5,-3,AIR:0)
Block(-8,5,-2,AIR:0)
Block(-8,5,-1,AIR:0)
Block(-8,5,0,AIR:0)
Block(-8,5,1,AIR:0)
Block(-8,5,2,AIR:0)
Block(-8,5,3,AIR:0)
Block(-8,5,4,AIR:0)
Block(-8,5,5,AIR:0)
Block(-8,5,6,AIR:0)
Block(-8,5,7,quark:limestone:0)
RandomBlock(-8,6,-6,rustic:iron_lattice:1,30,rustic:iron_lattice:1,30,biomesoplenty:leaves_2:7,30,quark:iron_plate_stairs:6,10,quark:iron_plate_stairs:0,10,quark:iron_plate_stairs:5,10,quark:iron_plate_stairs:3,10,quark:iron_plate_slab:8,10,quark:iron_plate_stairs:7,10,quark:iron_plate_stairs:1,10,quark:iron_plate_slab:0,10,quark:iron_plate_stairs:4,10,quark:iron_plate_stairs:2,10,rustic:iron_lattice:1,50,rustic:iron_lattice:1,50,biomesoplenty:leaves_2:7,100)
Block(-8,6,-5,AIR:0)
Block(-8,6,-4,AIR:0)
Block(-8,6,-3,AIR:0)
Block(-8,6,-2,AIR:0)
Block(-8,6,-1,AIR:0)
Block(-8,6,0,AIR:0)
Block(-8,6,1,AIR:0)
Block(-8,6,2,AIR:0)
Block(-8,6,3,AIR:0)
Block(-8,6,4,AIR:0)
Block(-8,6,5,AIR:0)
Block(-8,6,6,AIR:0)
Block(-8,6,7,quark:limestone:0)
Block(-8,7,-6,COBBLESTONE_STAIRS:2)
RandomBlock(-8,7,-5,rustic:iron_lattice:1,30,rustic:iron_lattice:1,30,biomesoplenty:leaves_2:7,30,quark:iron_plate_stairs:6,10,quark:iron_plate_stairs:0,10,quark:iron_plate_stairs:5,10,quark:iron_plate_stairs:3,10,quark:iron_plate_slab:8,10,quark:iron_plate_stairs:7,10,quark:iron_plate_stairs:1,10,quark:iron_plate_slab:0,10,quark:iron_plate_stairs:4,10,quark:iron_plate_stairs:2,10,rustic:iron_lattice:1,50,rustic:iron_lattice:1,50,biomesoplenty:leaves_2:7,100)
RandomBlock(-8,7,-4,rustic:iron_lattice:1,30,rustic:iron_lattice:1,30,biomesoplenty:leaves_2:7,30,quark:iron_plate_stairs:6,10,quark:iron_plate_stairs:0,10,quark:iron_plate_stairs:5,10,quark:iron_plate_stairs:3,10,quark:iron_plate_slab:8,10,quark:iron_plate_stairs:7,10,quark:iron_plate_stairs:1,10,quark:iron_plate_slab:0,10,quark:iron_plate_stairs:4,10,quark:iron_plate_stairs:2,10,rustic:iron_lattice:1,50,rustic:iron_lattice:1,50,biomesoplenty:leaves_2:7,100)
RandomBlock(-8,7,-3,rustic:iron_lattice:1,30,rustic:iron_lattice:1,30,biomesoplenty:leaves_2:7,30,quark:iron_plate_stairs:6,10,quark:iron_plate_stairs:0,10,quark:iron_plate_stairs:5,10,quark:iron_plate_stairs:3,10,quark:iron_plate_slab:8,10,quark:iron_plate_stairs:7,10,quark:iron_plate_stairs:1,10,quark:iron_plate_slab:0,10,quark:iron_plate_stairs:4,10,quark:iron_plate_stairs:2,10,rustic:iron_lattice:1,50,rustic:iron_lattice:1,50,biomesoplenty:leaves_2:7,100)
RandomBlock(-8,7,-2,quark:iron_plate:1,70,STAINED_CLAY:15,30,STAINED_CLAY:7,30,quark:iron_plate:1,100)
RandomBlock(-8,7,-1,quark:iron_plate:1,70,STAINED_CLAY:15,30,STAINED_CLAY:7,30,quark:iron_plate:1,100)
RandomBlock(-8,7,0,quark:iron_plate:1,70,STAINED_CLAY:15,30,STAINED_CLAY:7,30,quark:iron_plate:1,100)
RandomBlock(-8,7,1,quark:iron_plate:1,70,STAINED_CLAY:15,30,STAINED_CLAY:7,30,quark:iron_plate:1,100)
RandomBlock(-8,7,2,quark:iron_plate:1,70,STAINED_CLAY:15,30,STAINED_CLAY:7,30,quark:iron_plate:1,100)
RandomBlock(-8,7,3,quark:iron_plate:1,70,STAINED_CLAY:15,30,STAINED_CLAY:7,30,quark:iron_plate:1,100)
Block(-8,7,4,AIR:0)
Block(-8,7,5,AIR:0)
Block(-8,7,6,AIR:0)
Block(-8,7,7,quark:limestone:0)
Block(-8,8,3,quark:limestone:0)
Block(-8,8,4,COBBLESTONE_STAIRS:7)
Block(-8,8,5,AIR:0)
Block(-8,8,6,COBBLESTONE_STAIRS:6)
Block(-8,8,7,quark:limestone:0)
RandomBlock(-8,9,3,quark:iron_plate:1,70,STAINED_CLAY:15,30,STAINED_CLAY:7,30,quark:iron_plate:1,100)
Block(-8,9,4,COBBLESTONE_STAIRS:3)
RandomBlock(-8,9,5,quark:iron_plate:1,70,STAINED_CLAY:15,30,STAINED_CLAY:7,30,quark:iron_plate:1,100)
Block(-8,9,6,COBBLESTONE_STAIRS:2)
RandomBlock(-8,9,7,quark:iron_plate:1,70,STAINED_CLAY:15,30,STAINED_CLAY:7,30,quark:iron_plate:1,100)
Block(-8,10,3,rustic:iron_lattice:0)
Block(-8,10,7,rustic:iron_lattice:0)
Block(-7,0,2,quark:limestone:0)
Block(-7,0,3,quark:limestone:0)
Block(-7,0,4,quark:limestone:0)
Block(-7,0,5,quark:limestone:0)
Block(-7,0,6,quark:limestone:0)
Block(-7,0,7,quark:limestone:0)
Block(-7,0,8,quark:limestone:0)
Block(-7,1,2,COBBLESTONE_STAIRS:2)
Block(-7,1,3,quark:limestone:0)
Block(-7,1,4,srparasites:deadblood:1)
Block(-7,1,5,srparasites:deadblood:1)
Block(-7,1,6,srparasites:deadblood:0)
Block(-7,1,7,quark:limestone:0)
Block(-7,1,8,COBBLESTONE_STAIRS:3)
Block(-7,2,3,quark:limestone:0)
Block(-7,2,4,srparasites:deadblood:0)
Block(-7,2,5,srparasites:deadblood:1)
Block(-7,2,6,srparasites:deadblood:0)
Block(-7,2,7,quark:limestone:0)
Block(-7,3,3,quark:limestone:0)
Block(-7,3,4,AIR:0)
Block(-7,3,5,AIR:0)
Block(-7,3,6,AIR:0)
Block(-7,3,7,quark:limestone:0)
Block(-7,4,-6,COBBLESTONE_STAIRS:6)
RandomBlock(-7,4,-5,quark:iron_plate:1,70,STAINED_CLAY:15,30,STAINED_CLAY:7,30,quark:iron_plate:1,100)
RandomBlock(-7,4,-4,quark:iron_plate:1,70,STAINED_CLAY:15,30,STAINED_CLAY:7,30,quark:iron_plate:1,100)
RandomBlock(-7,4,-3,quark:iron_plate:1,70,STAINED_CLAY:15,30,STAINED_CLAY:7,30,quark:iron_plate:1,100)
RandomBlock(-7,4,-2,rustic:iron_lattice:1,30,rustic:iron_lattice:1,30,biomesoplenty:leaves_2:7,30,quark:iron_plate_stairs:6,10,quark:iron_plate_stairs:0,10,quark:iron_plate_stairs:5,10,quark:iron_plate_stairs:3,10,quark:iron_plate_slab:8,10,quark:iron_plate_stairs:7,10,quark:iron_plate_stairs:1,10,quark:iron_plate_slab:0,10,quark:iron_plate_stairs:4,10,quark:iron_plate_stairs:2,10,rustic:iron_lattice:1,50,rustic:iron_lattice:1,50,biomesoplenty:leaves_2:7,100)
RandomBlock(-7,4,-1,rustic:iron_lattice:1,30,rustic:iron_lattice:1,30,biomesoplenty:leaves_2:7,30,quark:iron_plate_stairs:6,10,quark:iron_plate_stairs:0,10,quark:iron_plate_stairs:5,10,quark:iron_plate_stairs:3,10,quark:iron_plate_slab:8,10,quark:iron_plate_stairs:7,10,quark:iron_plate_stairs:1,10,quark:iron_plate_slab:0,10,quark:iron_plate_stairs:4,10,quark:iron_plate_stairs:2,10,rustic:iron_lattice:1,50,rustic:iron_lattice:1,50,biomesoplenty:leaves_2:7,100)
RandomBlock(-7,4,0,rustic:iron_lattice:1,30,rustic:iron_lattice:1,30,biomesoplenty:leaves_2:7,30,quark:iron_plate_stairs:6,10,quark:iron_plate_stairs:0,10,quark:iron_plate_stairs:5,10,quark:iron_plate_stairs:3,10,quark:iron_plate_slab:8,10,quark:iron_plate_stairs:7,10,quark:iron_plate_stairs:1,10,quark:iron_plate_slab:0,10,quark:iron_plate_stairs:4,10,quark:iron_plate_stairs:2,10,rustic:iron_lattice:1,50,rustic:iron_lattice:1,50,biomesoplenty:leaves_2:7,100)
RandomBlock(-7,4,1,quark:iron_plate:1,70,STAINED_CLAY:15,30,STAINED_CLAY:7,30,quark:iron_plate:1,100)
RandomBlock(-7,4,2,quark:iron_plate:1,70,STAINED_CLAY:15,30,STAINED_CLAY:7,30,quark:iron_plate:1,100)
RandomBlock(-7,4,3,quark:iron_plate:1,70,STAINED_CLAY:15,30,STAINED_CLAY:7,30,quark:iron_plate:1,100)
Block(-7,4,4,AIR:0)
Block(-7,4,5,AIR:0)
Block(-7,4,6,AIR:0)
Block(-7,4,7,quark:limestone:0)
RandomBlock(-7,5,-6,quark:iron_plate:1,70,STAINED_CLAY:15,30,STAINED_CLAY:7,30,quark:iron_plate:1,100)
Block(-7,5,-5,AIR:0)
Block(-7,5,-4,AIR:0)
Block(-7,5,-3,AIR:0)
Block(-7,5,-2,AIR:0)
Block(-7,5,-1,AIR:0)
Block(-7,5,0,AIR:0)
Block(-7,5,1,AIR:0)
Block(-7,5,2,AIR:0)
Block(-7,5,3,AIR:0)
Block(-7,5,4,AIR:0)
Block(-7,5,5,AIR:0)
Block(-7,5,6,AIR:0)
Block(-7,5,7,quark:limestone:0)
RandomBlock(-7,6,-6,rustic:iron_lattice:1,30,rustic:iron_lattice:1,30,biomesoplenty:leaves_2:7,30,quark:iron_plate_stairs:6,10,quark:iron_plate_stairs:0,10,quark:iron_plate_stairs:5,10,quark:iron_plate_stairs:3,10,quark:iron_plate_slab:8,10,quark:iron_plate_stairs:7,10,quark:iron_plate_stairs:1,10,quark:iron_plate_slab:0,10,quark:iron_plate_stairs:4,10,quark:iron_plate_stairs:2,10,rustic:iron_lattice:1,50,rustic:iron_lattice:1,50,biomesoplenty:leaves_2:7,100)
Block(-7,6,-5,AIR:0)
Block(-7,6,-4,AIR:0)
Block(-7,6,-3,AIR:0)
Block(-7,6,-2,AIR:0)
Block(-7,6,-1,AIR:0)
Block(-7,6,0,AIR:0)
Block(-7,6,1,AIR:0)
Block(-7,6,2,AIR:0)
Block(-7,6,3,AIR:0)
Block(-7,6,4,AIR:0)
Block(-7,6,5,AIR:0)
Block(-7,6,6,AIR:0)
Block(-7,6,7,quark:limestone:0)
Block(-7,7,-6,COBBLESTONE_STAIRS:2)
RandomBlock(-7,7,-5,rustic:iron_lattice:1,30,rustic:iron_lattice:1,30,biomesoplenty:leaves_2:7,30,quark:iron_plate_stairs:6,10,quark:iron_plate_stairs:0,10,quark:iron_plate_stairs:5,10,quark:iron_plate_stairs:3,10,quark:iron_plate_slab:8,10,quark:iron_plate_stairs:7,10,quark:iron_plate_stairs:1,10,quark:iron_plate_slab:0,10,quark:iron_plate_stairs:4,10,quark:iron_plate_stairs:2,10,rustic:iron_lattice:1,50,rustic:iron_lattice:1,50,biomesoplenty:leaves_2:7,100)
RandomBlock(-7,7,-4,rustic:iron_lattice:1,30,rustic:iron_lattice:1,30,biomesoplenty:leaves_2:7,30,quark:iron_plate_stairs:6,10,quark:iron_plate_stairs:0,10,quark:iron_plate_stairs:5,10,quark:iron_plate_stairs:3,10,quark:iron_plate_slab:8,10,quark:iron_plate_stairs:7,10,quark:iron_plate_stairs:1,10,quark:iron_plate_slab:0,10,quark:iron_plate_stairs:4,10,quark:iron_plate_stairs:2,10,rustic:iron_lattice:1,50,rustic:iron_lattice:1,50,biomesoplenty:leaves_2:7,100)
RandomBlock(-7,7,-3,rustic:iron_lattice:1,30,rustic:iron_lattice:1,30,biomesoplenty:leaves_2:7,30,quark:iron_plate_stairs:6,10,quark:iron_plate_stairs:0,10,quark:iron_plate_stairs:5,10,quark:iron_plate_stairs:3,10,quark:iron_plate_slab:8,10,quark:iron_plate_stairs:7,10,quark:iron_plate_stairs:1,10,quark:iron_plate_slab:0,10,quark:iron_plate_stairs:4,10,quark:iron_plate_stairs:2,10,rustic:iron_lattice:1,50,rustic:iron_lattice:1,50,biomesoplenty:leaves_2:7,100)
RandomBlock(-7,7,-2,quark:iron_plate:1,70,STAINED_CLAY:15,30,STAINED_CLAY:7,30,quark:iron_plate:1,100)
RandomBlock(-7,7,-1,quark:iron_plate:1,70,STAINED_CLAY:15,30,STAINED_CLAY:7,30,quark:iron_plate:1,100)
RandomBlock(-7,7,0,quark:iron_plate:1,70,STAINED_CLAY:15,30,STAINED_CLAY:7,30,quark:iron_plate:1,100)
RandomBlock(-7,7,1,quark:iron_plate:1,70,STAINED_CLAY:15,30,STAINED_CLAY:7,30,quark:iron_plate:1,100)
RandomBlock(-7,7,2,quark:iron_plate:1,70,STAINED_CLAY:15,30,STAINED_CLAY:7,30,quark:iron_plate:1,100)
RandomBlock(-7,7,3,quark:iron_plate:1,70,STAINED_CLAY:15,30,STAINED_CLAY:7,30,quark:iron_plate:1,100)
Block(-7,7,4,AIR:0)
Block(-7,7,5,AIR:0)
Block(-7,7,6,AIR:0)
Block(-7,7,7,quark:limestone:0)
Block(-7,8,3,quark:limestone:0)
Block(-7,8,4,COBBLESTONE_STAIRS:7)
Block(-7,8,5,AIR:0)
Block(-7,8,6,COBBLESTONE_STAIRS:6)
Block(-7,8,7,quark:limestone:0)
RandomBlock(-7,9,3,quark:iron_plate:1,70,STAINED_CLAY:15,30,STAINED_CLAY:7,30,quark:iron_plate:1,100)
Block(-7,9,4,COBBLESTONE_STAIRS:3)
RandomBlock(-7,9,5,quark:iron_plate:1,70,STAINED_CLAY:15,30,STAINED_CLAY:7,30,quark:iron_plate:1,100)
Block(-7,9,6,COBBLESTONE_STAIRS:2)
RandomBlock(-7,9,7,quark:iron_plate:1,70,STAINED_CLAY:15,30,STAINED_CLAY:7,30,quark:iron_plate:1,100)
Block(-7,10,3,rustic:iron_lattice:0)
Block(-7,10,7,rustic:iron_lattice:0)
Block(-6,0,-5,quark:limestone:0)
Block(-6,0,-4,quark:limestone:0)
Block(-6,0,2,quark:limestone:0)
Block(-6,0,3,quark:limestone:0)
Block(-6,0,4,quark:limestone:0)
Block(-6,0,5,quark:limestone:0)
Block(-6,0,6,quark:limestone:0)
Block(-6,0,7,quark:limestone:0)
Block(-6,0,8,quark:limestone:0)
Block(-6,1,-5,quark:basalt_wall:0)
Block(-6,1,-4,quark:basalt_wall:0)
Block(-6,1,2,COBBLESTONE_STAIRS:2)
Block(-6,1,3,quark:limestone:0)
Block(-6,1,4,srparasites:deadblood:1)
Block(-6,1,5,srparasites:deadblood:1)
Block(-6,1,6,srparasites:deadblood:1)
Block(-6,1,7,quark:limestone:0)
Block(-6,1,8,COBBLESTONE_STAIRS:3)
Block(-6,2,-5,quark:basalt_wall:0)
Block(-6,2,-4,quark:basalt_wall:0)
Block(-6,2,3,quark:limestone:0)
Block(-6,2,4,srparasites:deadblood:0)
Block(-6,2,5,srparasites:deadblood:0)
Block(-6,2,6,srparasites:deadblood:0)
Block(-6,2,7,quark:limestone:0)
Block(-6,3,-5,quark:basalt_wall:0)
Block(-6,3,-4,quark:basalt_wall:0)
Block(-6,3,3,quark:limestone:0)
Block(-6,3,4,AIR:0)
Block(-6,3,5,AIR:0)
Block(-6,3,6,AIR:0)
Block(-6,3,7,quark:limestone:0)
Block(-6,4,-6,COBBLESTONE_STAIRS:6)
RandomBlock(-6,4,-5,quark:iron_plate:1,70,STAINED_CLAY:15,30,STAINED_CLAY:7,30,quark:iron_plate:1,100)
RandomBlock(-6,4,-4,quark:iron_plate:1,70,STAINED_CLAY:15,30,STAINED_CLAY:7,30,quark:iron_plate:1,100)
Block(-6,4,-3,COBBLESTONE_STAIRS:7)
Block(-6,4,-2,COBBLESTONE_STAIRS:5)
Block(-6,4,-1,COBBLESTONE_STAIRS:5)
Block(-6,4,0,COBBLESTONE_STAIRS:5)
Block(-6,4,1,COBBLESTONE_STAIRS:5)
Block(-6,4,2,COBBLESTONE_STAIRS:5)
RandomBlock(-6,4,3,quark:iron_plate:1,70,STAINED_CLAY:15,30,STAINED_CLAY:7,30,quark:iron_plate:1,100)
Block(-6,4,4,AIR:0)
Block(-6,4,5,AIR:0)
Block(-6,4,6,AIR:0)
Block(-6,4,7,quark:limestone:0)
RandomBlock(-6,5,-6,rustic:iron_lattice:1,30,rustic:iron_lattice:1,30,biomesoplenty:leaves_2:7,30,quark:iron_plate_stairs:6,10,quark:iron_plate_stairs:0,10,quark:iron_plate_stairs:5,10,quark:iron_plate_stairs:3,10,quark:iron_plate_slab:8,10,quark:iron_plate_stairs:7,10,quark:iron_plate_stairs:1,10,quark:iron_plate_slab:0,10,quark:iron_plate_stairs:4,10,quark:iron_plate_stairs:2,10,rustic:iron_lattice:1,50,rustic:iron_lattice:1,50,biomesoplenty:leaves_2:7,100)
Block(-6,5,-5,AIR:0)
Block(-6,5,-4,AIR:0)
RandomBlock(-6,5,-3,quark:iron_plate:1,70,STAINED_CLAY:15,30,STAINED_CLAY:7,30,quark:iron_plate:1,100)
RandomBlock(-6,5,-2,quark:iron_plate:1,70,STAINED_CLAY:15,30,STAINED_CLAY:7,30,quark:iron_plate:1,100)
RandomBlock(-6,5,-1,quark:iron_plate:1,70,STAINED_CLAY:15,30,STAINED_CLAY:7,30,quark:iron_plate:1,100)
RandomBlock(-6,5,0,quark:iron_plate:1,70,STAINED_CLAY:15,30,STAINED_CLAY:7,30,quark:iron_plate:1,100)
RandomBlock(-6,5,1,quark:iron_plate:1,70,STAINED_CLAY:15,30,STAINED_CLAY:7,30,quark:iron_plate:1,100)
RandomBlock(-6,5,2,quark:iron_plate:1,70,STAINED_CLAY:15,30,STAINED_CLAY:7,30,quark:iron_plate:1,100)
RandomBlock(-6,5,3,quark:iron_plate:1,70,STAINED_CLAY:15,30,STAINED_CLAY:7,30,quark:iron_plate:1,100)
Block(-6,5,4,AIR:0)
Block(-6,5,5,AIR:0)
Block(-6,5,6,AIR:0)
Block(-6,5,7,quark:limestone:0)
RandomBlock(-6,6,-6,rustic:iron_lattice:1,30,rustic:iron_lattice:1,30,biomesoplenty:leaves_2:7,30,quark:iron_plate_stairs:6,10,quark:iron_plate_stairs:0,10,quark:iron_plate_stairs:5,10,quark:iron_plate_stairs:3,10,quark:iron_plate_slab:8,10,quark:iron_plate_stairs:7,10,quark:iron_plate_stairs:1,10,quark:iron_plate_slab:0,10,quark:iron_plate_stairs:4,10,quark:iron_plate_stairs:2,10,rustic:iron_lattice:1,50,rustic:iron_lattice:1,50,biomesoplenty:leaves_2:7,100)
Block(-6,6,-5,AIR:0)
Block(-6,6,-4,AIR:0)
RandomBlock(-6,6,-3,quark:iron_plate:1,70,STAINED_CLAY:15,30,STAINED_CLAY:7,30,quark:iron_plate:1,100)
RandomBlock(-6,6,-2,quark:iron_plate:1,70,STAINED_CLAY:15,30,STAINED_CLAY:7,30,quark:iron_plate:1,100)
RandomBlock(-6,6,-1,quark:iron_plate:1,70,STAINED_CLAY:15,30,STAINED_CLAY:7,30,quark:iron_plate:1,100)
RandomBlock(-6,6,0,quark:iron_plate:1,70,STAINED_CLAY:15,30,STAINED_CLAY:7,30,quark:iron_plate:1,100)
RandomBlock(-6,6,1,quark:iron_plate:1,70,STAINED_CLAY:15,30,STAINED_CLAY:7,30,quark:iron_plate:1,100)
RandomBlock(-6,6,2,quark:iron_plate:1,70,STAINED_CLAY:15,30,STAINED_CLAY:7,30,quark:iron_plate:1,100)
RandomBlock(-6,6,3,quark:iron_plate:1,70,STAINED_CLAY:15,30,STAINED_CLAY:7,30,quark:iron_plate:1,100)
Block(-6,6,4,AIR:0)
Block(-6,6,5,AIR:0)
Block(-6,6,6,AIR:0)
Block(-6,6,7,quark:limestone:0)
Block(-6,7,-6,COBBLESTONE_STAIRS:2)
RandomBlock(-6,7,-5,rustic:iron_lattice:1,30,rustic:iron_lattice:1,30,biomesoplenty:leaves_2:7,30,quark:iron_plate_stairs:6,10,quark:iron_plate_stairs:0,10,quark:iron_plate_stairs:5,10,quark:iron_plate_stairs:3,10,quark:iron_plate_slab:8,10,quark:iron_plate_stairs:7,10,quark:iron_plate_stairs:1,10,quark:iron_plate_slab:0,10,quark:iron_plate_stairs:4,10,quark:iron_plate_stairs:2,10,rustic:iron_lattice:1,50,rustic:iron_lattice:1,50,biomesoplenty:leaves_2:7,100)
RandomBlock(-6,7,-4,rustic:iron_lattice:1,30,rustic:iron_lattice:1,30,biomesoplenty:leaves_2:7,30,quark:iron_plate_stairs:6,10,quark:iron_plate_stairs:0,10,quark:iron_plate_stairs:5,10,quark:iron_plate_stairs:3,10,quark:iron_plate_slab:8,10,quark:iron_plate_stairs:7,10,quark:iron_plate_stairs:1,10,quark:iron_plate_slab:0,10,quark:iron_plate_stairs:4,10,quark:iron_plate_stairs:2,10,rustic:iron_lattice:1,50,rustic:iron_lattice:1,50,biomesoplenty:leaves_2:7,100)
Block(-6,7,-3,COBBLESTONE_STAIRS:3)
Block(-6,7,-2,COBBLESTONE_STAIRS:1)
Block(-6,7,-1,COBBLESTONE_STAIRS:1)
Block(-6,7,0,COBBLESTONE_STAIRS:1)
Block(-6,7,1,COBBLESTONE_STAIRS:1)
Block(-6,7,2,COBBLESTONE_STAIRS:1)
RandomBlock(-6,7,3,quark:iron_plate:1,70,STAINED_CLAY:15,30,STAINED_CLAY:7,30,quark:iron_plate:1,100)
Block(-6,7,4,AIR:0)
Block(-6,7,5,AIR:0)
Block(-6,7,6,AIR:0)
Block(-6,7,7,quark:limestone:0)
Block(-6,8,3,quark:limestone:0)
Block(-6,8,4,COBBLESTONE_STAIRS:4)
Block(-6,8,5,COBBLESTONE_STAIRS:4)
Block(-6,8,6,COBBLESTONE_STAIRS:4)
Block(-6,8,7,quark:limestone:0)
RandomBlock(-6,9,3,quark:iron_plate:1,70,STAINED_CLAY:15,30,STAINED_CLAY:7,30,quark:iron_plate:1,100)
Block(-6,9,4,COBBLESTONE_STAIRS:0)
Block(-6,9,5,COBBLESTONE_STAIRS:0)
Block(-6,9,6,COBBLESTONE_STAIRS:2)
RandomBlock(-6,9,7,quark:iron_plate:1,70,STAINED_CLAY:15,30,STAINED_CLAY:7,30,quark:iron_plate:1,100)
Block(-6,10,3,rustic:iron_lattice:0)
Block(-6,10,7,rustic:iron_lattice:0)
Block(-5,0,2,quark:limestone:0)
RandomBlock(-5,0,3,quark:iron_plate:1,70,STAINED_CLAY:15,30,STAINED_CLAY:7,30,quark:iron_plate:1,100)
Block(-5,0,4,quark:limestone:0)
Block(-5,0,5,quark:limestone:0)
Block(-5,0,6,quark:limestone:0)
RandomBlock(-5,0,7,quark:iron_plate:1,70,STAINED_CLAY:15,30,STAINED_CLAY:7,30,quark:iron_plate:1,100)
Block(-5,0,8,quark:limestone:0)
Block(-5,1,2,COBBLESTONE_STAIRS:2)
RandomBlock(-5,1,3,quark:iron_plate:1,70,STAINED_CLAY:15,30,STAINED_CLAY:7,30,quark:iron_plate:1,100)
Block(-5,1,4,quark:limestone:0)
Block(-5,1,5,quark:limestone:0)
Block(-5,1,6,quark:limestone:0)
RandomBlock(-5,1,7,quark:iron_plate:1,70,STAINED_CLAY:15,30,STAINED_CLAY:7,30,quark:iron_plate:1,100)
Block(-5,1,8,COBBLESTONE_STAIRS:3)
RandomBlock(-5,2,3,quark:iron_plate:1,70,STAINED_CLAY:15,30,STAINED_CLAY:7,30,quark:iron_plate:1,100)
Block(-5,2,4,quark:limestone:0)
Block(-5,2,5,quark:limestone:0)
Block(-5,2,6,quark:limestone:0)
RandomBlock(-5,2,7,quark:iron_plate:1,70,STAINED_CLAY:15,30,STAINED_CLAY:7,30,quark:iron_plate:1,100)
RandomBlock(-5,3,3,quark:iron_plate:1,70,STAINED_CLAY:15,30,STAINED_CLAY:7,30,quark:iron_plate:1,100)
Block(-5,3,4,quark:limestone:0)
Block(-5,3,5,quark:limestone:0)
Block(-5,3,6,quark:limestone:0)
RandomBlock(-5,3,7,quark:iron_plate:1,70,STAINED_CLAY:15,30,STAINED_CLAY:7,30,quark:iron_plate:1,100)
Block(-5,4,-6,COBBLESTONE_STAIRS:6)
RandomBlock(-5,4,-5,quark:iron_plate:1,70,STAINED_CLAY:15,30,STAINED_CLAY:7,30,quark:iron_plate:1,100)
RandomBlock(-5,4,-4,quark:iron_plate:1,70,STAINED_CLAY:15,30,STAINED_CLAY:7,30,quark:iron_plate:1,100)
Block(-5,4,-3,COBBLESTONE_STAIRS:7)
RandomBlock(-5,4,3,quark:iron_plate:1,70,STAINED_CLAY:15,30,STAINED_CLAY:7,30,quark:iron_plate:1,100)
Block(-5,4,4,quark:limestone:0)
Block(-5,4,5,quark:limestone:0)
Block(-5,4,6,quark:limestone:0)
RandomBlock(-5,4,7,quark:iron_plate:1,70,STAINED_CLAY:15,30,STAINED_CLAY:7,30,quark:iron_plate:1,100)
RandomBlock(-5,5,-6,quark:iron_plate:1,70,STAINED_CLAY:15,30,STAINED_CLAY:7,30,quark:iron_plate:1,100)
Block(-5,5,-5,AIR:0)
Block(-5,5,-4,AIR:0)
RandomBlock(-5,5,-3,quark:iron_plate:1,70,STAINED_CLAY:15,30,STAINED_CLAY:7,30,quark:iron_plate:1,100)
RandomBlock(-5,5,3,quark:iron_plate:1,70,STAINED_CLAY:15,30,STAINED_CLAY:7,30,quark:iron_plate:1,100)
Block(-5,5,4,quark:limestone:0)
Block(-5,5,5,quark:limestone:0)
Block(-5,5,6,quark:limestone:0)
RandomBlock(-5,5,7,quark:iron_plate:1,70,STAINED_CLAY:15,30,STAINED_CLAY:7,30,quark:iron_plate:1,100)
RandomBlock(-5,6,-6,quark:iron_plate:1,70,STAINED_CLAY:15,30,STAINED_CLAY:7,30,quark:iron_plate:1,100)
Block(-5,6,-5,AIR:0)
Block(-5,6,-4,AIR:0)
RandomBlock(-5,6,-3,quark:iron_plate:1,70,STAINED_CLAY:15,30,STAINED_CLAY:7,30,quark:iron_plate:1,100)
RandomBlock(-5,6,3,quark:iron_plate:1,70,STAINED_CLAY:15,30,STAINED_CLAY:7,30,quark:iron_plate:1,100)
Block(-5,6,4,quark:limestone:0)
Block(-5,6,5,quark:limestone:0)
Block(-5,6,6,quark:limestone:0)
RandomBlock(-5,6,7,quark:iron_plate:1,70,STAINED_CLAY:15,30,STAINED_CLAY:7,30,quark:iron_plate:1,100)
Block(-5,7,-6,COBBLESTONE_STAIRS:2)
RandomBlock(-5,7,-5,rustic:iron_lattice:1,30,rustic:iron_lattice:1,30,biomesoplenty:leaves_2:7,30,quark:iron_plate_stairs:6,10,quark:iron_plate_stairs:0,10,quark:iron_plate_stairs:5,10,quark:iron_plate_stairs:3,10,quark:iron_plate_slab:8,10,quark:iron_plate_stairs:7,10,quark:iron_plate_stairs:1,10,quark:iron_plate_slab:0,10,quark:iron_plate_stairs:4,10,quark:iron_plate_stairs:2,10,rustic:iron_lattice:1,50,rustic:iron_lattice:1,50,biomesoplenty:leaves_2:7,100)
RandomBlock(-5,7,-4,quark:iron_plate:1,70,STAINED_CLAY:15,30,STAINED_CLAY:7,30,quark:iron_plate:1,100)
Block(-5,7,-3,COBBLESTONE_STAIRS:3)
RandomBlock(-5,7,3,quark:iron_plate:1,70,STAINED_CLAY:15,30,STAINED_CLAY:7,30,quark:iron_plate:1,100)
Block(-5,7,4,quark:limestone:0)
Block(-5,7,5,quark:limestone:0)
Block(-5,7,6,quark:limestone:0)
RandomBlock(-5,7,7,quark:iron_plate:1,70,STAINED_CLAY:15,30,STAINED_CLAY:7,30,quark:iron_plate:1,100)
RandomBlock(-5,8,3,quark:iron_plate:1,70,STAINED_CLAY:15,30,STAINED_CLAY:7,30,quark:iron_plate:1,100)
Block(-5,8,4,quark:limestone:0)
Block(-5,8,5,quark:limestone:0)
Block(-5,8,6,quark:limestone:0)
RandomBlock(-5,8,7,quark:iron_plate:1,70,STAINED_CLAY:15,30,STAINED_CLAY:7,30,quark:iron_plate:1,100)
RandomBlock(-5,9,3,quark:iron_plate:1,70,STAINED_CLAY:15,30,STAINED_CLAY:7,30,quark:iron_plate:1,100)
RandomBlock(-5,9,4,quark:iron_plate:1,70,STAINED_CLAY:15,30,STAINED_CLAY:7,30,quark:iron_plate:1,100)
RandomBlock(-5,9,5,quark:iron_plate:1,70,STAINED_CLAY:15,30,STAINED_CLAY:7,30,quark:iron_plate:1,100)
RandomBlock(-5,9,6,quark:iron_plate:1,70,STAINED_CLAY:15,30,STAINED_CLAY:7,30,quark:iron_plate:1,100)
RandomBlock(-5,9,7,quark:iron_plate:1,70,STAINED_CLAY:15,30,STAINED_CLAY:7,30,quark:iron_plate:1,100)
Block(-5,10,3,rustic:iron_lattice:0)
Block(-5,10,4,rustic:iron_lattice:0)
Block(-5,10,5,rustic:iron_lattice:0)
Block(-5,10,6,rustic:iron_lattice:0)
Block(-5,10,7,rustic:iron_lattice:0)
Block(-4,0,2,quark:limestone:0)
Block(-4,0,3,quark:limestone:0)
Block(-4,0,4,quark:limestone:0)
Block(-4,0,5,quark:limestone:0)
Block(-4,0,6,quark:limestone:0)
Block(-4,0,7,quark:limestone:0)
Block(-4,0,8,quark:limestone:0)
Block(-4,1,2,COBBLESTONE_STAIRS:2)
Block(-4,1,3,COBBLESTONE_STAIRS:1)
Block(-4,1,4,quark:limestone:0)
Block(-4,1,5,COBBLESTONE_STAIRS:3)
Block(-4,1,6,COBBLESTONE_STAIRS:1)
Block(-4,1,7,COBBLESTONE_STAIRS:1)
Block(-4,1,8,COBBLESTONE_STAIRS:1)
Block(-4,4,-6,COBBLESTONE_STAIRS:6)
RandomBlock(-4,4,-5,quark:iron_plate:1,70,STAINED_CLAY:15,30,STAINED_CLAY:7,30,quark:iron_plate:1,100)
RandomBlock(-4,4,-4,quark:iron_plate:1,70,STAINED_CLAY:15,30,STAINED_CLAY:7,30,quark:iron_plate:1,100)
Block(-4,4,-3,COBBLESTONE_STAIRS:7)
RandomBlock(-4,5,-6,rustic:iron_lattice:1,30,rustic:iron_lattice:1,30,biomesoplenty:leaves_2:7,30,quark:iron_plate_stairs:6,10,quark:iron_plate_stairs:0,10,quark:iron_plate_stairs:5,10,quark:iron_plate_stairs:3,10,quark:iron_plate_slab:8,10,quark:iron_plate_stairs:7,10,quark:iron_plate_stairs:1,10,quark:iron_plate_slab:0,10,quark:iron_plate_stairs:4,10,quark:iron_plate_stairs:2,10,rustic:iron_lattice:1,50,rustic:iron_lattice:1,50,biomesoplenty:leaves_2:7,100)
Block(-4,5,-5,AIR:0)
Block(-4,5,-4,AIR:0)
RandomBlock(-4,5,-3,quark:iron_plate:1,70,STAINED_CLAY:15,30,STAINED_CLAY:7,30,quark:iron_plate:1,100)
RandomBlock(-4,5,4,quark:iron_plate:1,70,STAINED_CLAY:15,30,STAINED_CLAY:7,30,quark:iron_plate:1,100)
RandomBlock(-4,6,-6,quark:iron_plate:1,70,STAINED_CLAY:15,30,STAINED_CLAY:7,30,quark:iron_plate:1,100)
Block(-4,6,-5,AIR:0)
Block(-4,6,-4,AIR:0)
RandomBlock(-4,6,-3,quark:iron_plate:1,70,STAINED_CLAY:15,30,STAINED_CLAY:7,30,quark:iron_plate:1,100)
Block(-4,7,-6,COBBLESTONE_STAIRS:2)
RandomBlock(-4,7,-5,rustic:iron_lattice:1,30,rustic:iron_lattice:1,30,biomesoplenty:leaves_2:7,30,quark:iron_plate_stairs:6,10,quark:iron_plate_stairs:0,10,quark:iron_plate_stairs:5,10,quark:iron_plate_stairs:3,10,quark:iron_plate_slab:8,10,quark:iron_plate_stairs:7,10,quark:iron_plate_stairs:1,10,quark:iron_plate_slab:0,10,quark:iron_plate_stairs:4,10,quark:iron_plate_stairs:2,10,rustic:iron_lattice:1,50,rustic:iron_lattice:1,50,biomesoplenty:leaves_2:7,100)
RandomBlock(-4,7,-4,quark:iron_plate:1,70,STAINED_CLAY:15,30,STAINED_CLAY:7,30,quark:iron_plate:1,100)
Block(-4,7,-3,COBBLESTONE_STAIRS:3)
Block(-3,0,3,quark:limestone:0)
RandomBlock(-3,0,4,quark:iron_plate:1,70,STAINED_CLAY:15,30,STAINED_CLAY:7,30,quark:iron_plate:1,100)
Block(-3,0,5,quark:limestone:0)
Block(-3,1,3,COBBLESTONE_STAIRS:2)
RandomBlock(-3,1,4,quark:iron_plate:1,70,STAINED_CLAY:15,30,STAINED_CLAY:7,30,quark:iron_plate:1,100)
Block(-3,1,5,COBBLESTONE_STAIRS:3)
RandomBlock(-3,2,4,quark:iron_plate:1,70,STAINED_CLAY:15,30,STAINED_CLAY:7,30,quark:iron_plate:1,100)
RandomBlock(-3,3,4,quark:iron_plate:1,70,STAINED_CLAY:15,30,STAINED_CLAY:7,30,quark:iron_plate:1,100)
Block(-3,4,-6,COBBLESTONE_STAIRS:6)
RandomBlock(-3,4,-5,quark:iron_plate:1,70,STAINED_CLAY:15,30,STAINED_CLAY:7,30,quark:iron_plate:1,100)
RandomBlock(-3,4,-4,quark:iron_plate:1,70,STAINED_CLAY:15,30,STAINED_CLAY:7,30,quark:iron_plate:1,100)
Block(-3,4,-3,COBBLESTONE_STAIRS:7)
RandomBlock(-3,4,4,quark:iron_plate:1,70,STAINED_CLAY:15,30,STAINED_CLAY:7,30,quark:iron_plate:1,100)
RandomBlock(-3,5,-6,rustic:iron_lattice:1,30,rustic:iron_lattice:1,30,biomesoplenty:leaves_2:7,30,quark:iron_plate_stairs:6,10,quark:iron_plate_stairs:0,10,quark:iron_plate_stairs:5,10,quark:iron_plate_stairs:3,10,quark:iron_plate_slab:8,10,quark:iron_plate_stairs:7,10,quark:iron_plate_stairs:1,10,quark:iron_plate_slab:0,10,quark:iron_plate_stairs:4,10,quark:iron_plate_stairs:2,10,rustic:iron_lattice:1,50,rustic:iron_lattice:1,50,biomesoplenty:leaves_2:7,100)
Block(-3,5,-5,AIR:0)
Block(-3,5,-4,AIR:0)
RandomBlock(-3,5,-3,quark:iron_plate:1,70,STAINED_CLAY:15,30,STAINED_CLAY:7,30,quark:iron_plate:1,100)
RandomBlock(-3,5,4,quark:iron_plate:1,70,STAINED_CLAY:15,30,STAINED_CLAY:7,30,quark:iron_plate:1,100)
RandomBlock(-3,6,-6,rustic:iron_lattice:1,30,rustic:iron_lattice:1,30,biomesoplenty:leaves_2:7,30,quark:iron_plate_stairs:6,10,quark:iron_plate_stairs:0,10,quark:iron_plate_stairs:5,10,quark:iron_plate_stairs:3,10,quark:iron_plate_slab:8,10,quark:iron_plate_stairs:7,10,quark:iron_plate_stairs:1,10,quark:iron_plate_slab:0,10,quark:iron_plate_stairs:4,10,quark:iron_plate_stairs:2,10,rustic:iron_lattice:1,50,rustic:iron_lattice:1,50,biomesoplenty:leaves_2:7,100)
Block(-3,6,-5,AIR:0)
Block(-3,6,-4,AIR:0)
RandomBlock(-3,6,-3,quark:iron_plate:1,70,STAINED_CLAY:15,30,STAINED_CLAY:7,30,quark:iron_plate:1,100)
Block(-3,7,-6,COBBLESTONE_STAIRS:2)
RandomBlock(-3,7,-5,quark:iron_plate:1,70,STAINED_CLAY:15,30,STAINED_CLAY:7,30,quark:iron_plate:1,100)
RandomBlock(-3,7,-4,quark:iron_plate:1,70,STAINED_CLAY:15,30,STAINED_CLAY:7,30,quark:iron_plate:1,100)
Block(-3,7,-3,COBBLESTONE_STAIRS:3)
Block(-2,0,3,quark:limestone:0)
Block(-2,0,4,quark:limestone:0)
Block(-2,0,5,quark:limestone:0)
Block(-2,1,3,COBBLESTONE_STAIRS:2)
Block(-2,1,4,COBBLESTONE_STAIRS:1)
Block(-2,1,5,COBBLESTONE_STAIRS:1)
Block(-2,4,-6,COBBLESTONE_STAIRS:6)
RandomBlock(-2,4,-5,quark:iron_plate:1,70,STAINED_CLAY:15,30,STAINED_CLAY:7,30,quark:iron_plate:1,100)
RandomBlock(-2,4,-4,quark:iron_plate:1,70,STAINED_CLAY:15,30,STAINED_CLAY:7,30,quark:iron_plate:1,100)
Block(-2,4,-3,COBBLESTONE_STAIRS:7)
RandomBlock(-2,5,-6,rustic:iron_lattice:1,30,rustic:iron_lattice:1,30,biomesoplenty:leaves_2:7,30,quark:iron_plate_stairs:6,10,quark:iron_plate_stairs:0,10,quark:iron_plate_stairs:5,10,quark:iron_plate_stairs:3,10,quark:iron_plate_slab:8,10,quark:iron_plate_stairs:7,10,quark:iron_plate_stairs:1,10,quark:iron_plate_slab:0,10,quark:iron_plate_stairs:4,10,quark:iron_plate_stairs:2,10,rustic:iron_lattice:1,50,rustic:iron_lattice:1,50,biomesoplenty:leaves_2:7,100)
Block(-2,5,-5,AIR:0)
Block(-2,5,-4,AIR:0)
RandomBlock(-2,5,-3,quark:iron_plate:1,70,STAINED_CLAY:15,30,STAINED_CLAY:7,30,quark:iron_plate:1,100)
RandomBlock(-2,6,-6,rustic:iron_lattice:1,30,rustic:iron_lattice:1,30,biomesoplenty:leaves_2:7,30,quark:iron_plate_stairs:6,10,quark:iron_plate_stairs:0,10,quark:iron_plate_stairs:5,10,quark:iron_plate_stairs:3,10,quark:iron_plate_slab:8,10,quark:iron_plate_stairs:7,10,quark:iron_plate_stairs:1,10,quark:iron_plate_slab:0,10,quark:iron_plate_stairs:4,10,quark:iron_plate_stairs:2,10,rustic:iron_lattice:1,50,rustic:iron_lattice:1,50,biomesoplenty:leaves_2:7,100)
Block(-2,6,-5,AIR:0)
Block(-2,6,-4,AIR:0)
RandomBlock(-2,6,-3,quark:iron_plate:1,70,STAINED_CLAY:15,30,STAINED_CLAY:7,30,quark:iron_plate:1,100)
Block(-2,7,-6,COBBLESTONE_STAIRS:2)
RandomBlock(-2,7,-5,quark:iron_plate:1,70,STAINED_CLAY:15,30,STAINED_CLAY:7,30,quark:iron_plate:1,100)
RandomBlock(-2,7,-4,quark:iron_plate:1,70,STAINED_CLAY:15,30,STAINED_CLAY:7,30,quark:iron_plate:1,100)
Block(-2,7,-3,COBBLESTONE_STAIRS:3)
Block(-1,4,-6,COBBLESTONE_STAIRS:6)
RandomBlock(-1,4,-5,quark:iron_plate:1,70,STAINED_CLAY:15,30,STAINED_CLAY:7,30,quark:iron_plate:1,100)
RandomBlock(-1,4,-4,quark:iron_plate:1,70,STAINED_CLAY:15,30,STAINED_CLAY:7,30,quark:iron_plate:1,100)
Block(-1,4,-3,COBBLESTONE_STAIRS:7)
RandomBlock(-1,5,-6,quark:iron_plate:1,70,STAINED_CLAY:15,30,STAINED_CLAY:7,30,quark:iron_plate:1,100)
Block(-1,5,-5,AIR:0)
Block(-1,5,-4,AIR:0)
RandomBlock(-1,5,-3,quark:iron_plate:1,70,STAINED_CLAY:15,30,STAINED_CLAY:7,30,quark:iron_plate:1,100)
RandomBlock(-1,6,-6,rustic:iron_lattice:1,30,rustic:iron_lattice:1,30,biomesoplenty:leaves_2:7,30,quark:iron_plate_stairs:6,10,quark:iron_plate_stairs:0,10,quark:iron_plate_stairs:5,10,quark:iron_plate_stairs:3,10,quark:iron_plate_slab:8,10,quark:iron_plate_stairs:7,10,quark:iron_plate_stairs:1,10,quark:iron_plate_slab:0,10,quark:iron_plate_stairs:4,10,quark:iron_plate_stairs:2,10,rustic:iron_lattice:1,50,rustic:iron_lattice:1,50,biomesoplenty:leaves_2:7,100)
Block(-1,6,-5,AIR:0)
Block(-1,6,-4,AIR:0)
RandomBlock(-1,6,-3,quark:iron_plate:1,70,STAINED_CLAY:15,30,STAINED_CLAY:7,30,quark:iron_plate:1,100)
Block(-1,7,-6,COBBLESTONE_STAIRS:2)
RandomBlock(-1,7,-5,quark:iron_plate:1,70,STAINED_CLAY:15,30,STAINED_CLAY:7,30,quark:iron_plate:1,100)
RandomBlock(-1,7,-4,quark:iron_plate:1,70,STAINED_CLAY:15,30,STAINED_CLAY:7,30,quark:iron_plate:1,100)
Block(-1,7,-3,COBBLESTONE_STAIRS:3)
Block(0,4,-6,COBBLESTONE_STAIRS:6)
RandomBlock(0,4,-5,quark:iron_plate:1,70,STAINED_CLAY:15,30,STAINED_CLAY:7,30,quark:iron_plate:1,100)
RandomBlock(0,4,-4,quark:iron_plate:1,70,STAINED_CLAY:15,30,STAINED_CLAY:7,30,quark:iron_plate:1,100)
Block(0,4,-3,COBBLESTONE_STAIRS:7)
RandomBlock(0,5,-6,quark:iron_plate:1,70,STAINED_CLAY:15,30,STAINED_CLAY:7,30,quark:iron_plate:1,100)
Block(0,5,-5,AIR:0)
Block(0,5,-4,AIR:0)
RandomBlock(0,5,-3,quark:iron_plate:1,70,STAINED_CLAY:15,30,STAINED_CLAY:7,30,quark:iron_plate:1,100)
RandomBlock(0,6,-6,rustic:iron_lattice:1,30,rustic:iron_lattice:1,30,biomesoplenty:leaves_2:7,30,quark:iron_plate_stairs:6,10,quark:iron_plate_stairs:0,10,quark:iron_plate_stairs:5,10,quark:iron_plate_stairs:3,10,quark:iron_plate_slab:8,10,quark:iron_plate_stairs:7,10,quark:iron_plate_stairs:1,10,quark:iron_plate_slab:0,10,quark:iron_plate_stairs:4,10,quark:iron_plate_stairs:2,10,rustic:iron_lattice:1,50,rustic:iron_lattice:1,50,biomesoplenty:leaves_2:7,100)
Block(0,6,-5,AIR:0)
Block(0,6,-4,AIR:0)
RandomBlock(0,6,-3,quark:iron_plate:1,70,STAINED_CLAY:15,30,STAINED_CLAY:7,30,quark:iron_plate:1,100)
Block(0,7,-6,COBBLESTONE_STAIRS:2)
RandomBlock(0,7,-5,quark:iron_plate:1,70,STAINED_CLAY:15,30,STAINED_CLAY:7,30,quark:iron_plate:1,100)
RandomBlock(0,7,-4,quark:iron_plate:1,70,STAINED_CLAY:15,30,STAINED_CLAY:7,30,quark:iron_plate:1,100)
Block(0,7,-3,COBBLESTONE_STAIRS:3)
Block(1,4,-6,COBBLESTONE_STAIRS:6)
RandomBlock(1,4,-5,quark:iron_plate:1,70,STAINED_CLAY:15,30,STAINED_CLAY:7,30,quark:iron_plate:1,100)
RandomBlock(1,4,-4,rustic:iron_lattice:1,30,rustic:iron_lattice:1,30,biomesoplenty:leaves_2:7,30,quark:iron_plate_stairs:6,10,quark:iron_plate_stairs:0,10,quark:iron_plate_stairs:5,10,quark:iron_plate_stairs:3,10,quark:iron_plate_slab:8,10,quark:iron_plate_stairs:7,10,quark:iron_plate_stairs:1,10,quark:iron_plate_slab:0,10,quark:iron_plate_stairs:4,10,quark:iron_plate_stairs:2,10,rustic:iron_lattice:1,50,rustic:iron_lattice:1,50,biomesoplenty:leaves_2:7,100)
Block(1,4,-3,COBBLESTONE_STAIRS:7)
RandomBlock(1,5,-6,quark:iron_plate:1,70,STAINED_CLAY:15,30,STAINED_CLAY:7,30,quark:iron_plate:1,100)
Block(1,5,-5,AIR:0)
Block(1,5,-4,AIR:0)
RandomBlock(1,5,-3,quark:iron_plate:1,70,STAINED_CLAY:15,30,STAINED_CLAY:7,30,quark:iron_plate:1,100)
RandomBlock(1,6,-6,quark:iron_plate:1,70,STAINED_CLAY:15,30,STAINED_CLAY:7,30,quark:iron_plate:1,100)
Block(1,6,-5,AIR:0)
Block(1,6,-4,AIR:0)
RandomBlock(1,6,-3,quark:iron_plate:1,70,STAINED_CLAY:15,30,STAINED_CLAY:7,30,quark:iron_plate:1,100)
Block(1,7,-6,COBBLESTONE_STAIRS:2)
RandomBlock(1,7,-5,quark:iron_plate:1,70,STAINED_CLAY:15,30,STAINED_CLAY:7,30,quark:iron_plate:1,100)
RandomBlock(1,7,-4,quark:iron_plate:1,70,STAINED_CLAY:15,30,STAINED_CLAY:7,30,quark:iron_plate:1,100)
Block(1,7,-3,COBBLESTONE_STAIRS:3)
Block(2,0,-5,quark:limestone:0)
Block(2,0,-4,quark:limestone:0)
Block(2,1,-5,quark:basalt_wall:0)
Block(2,1,-4,quark:basalt_wall:0)
Block(2,2,-5,quark:basalt_wall:0)
Block(2,2,-4,quark:basalt_wall:0)
Block(2,3,-5,quark:basalt_wall:0)
Block(2,3,-4,quark:basalt_wall:0)
Block(2,4,-6,COBBLESTONE_STAIRS:6)
RandomBlock(2,4,-5,rustic:iron_lattice:1,30,rustic:iron_lattice:1,30,biomesoplenty:leaves_2:7,30,quark:iron_plate_stairs:6,10,quark:iron_plate_stairs:0,10,quark:iron_plate_stairs:5,10,quark:iron_plate_stairs:3,10,quark:iron_plate_slab:8,10,quark:iron_plate_stairs:7,10,quark:iron_plate_stairs:1,10,quark:iron_plate_slab:0,10,quark:iron_plate_stairs:4,10,quark:iron_plate_stairs:2,10,rustic:iron_lattice:1,50,rustic:iron_lattice:1,50,biomesoplenty:leaves_2:7,100)
RandomBlock(2,4,-4,rustic:iron_lattice:1,30,rustic:iron_lattice:1,30,biomesoplenty:leaves_2:7,30,quark:iron_plate_stairs:6,10,quark:iron_plate_stairs:0,10,quark:iron_plate_stairs:5,10,quark:iron_plate_stairs:3,10,quark:iron_plate_slab:8,10,quark:iron_plate_stairs:7,10,quark:iron_plate_stairs:1,10,quark:iron_plate_slab:0,10,quark:iron_plate_stairs:4,10,quark:iron_plate_stairs:2,10,rustic:iron_lattice:1,50,rustic:iron_lattice:1,50,biomesoplenty:leaves_2:7,100)
Block(2,4,-3,COBBLESTONE_STAIRS:7)
RandomBlock(2,5,-6,rustic:iron_lattice:1,30,rustic:iron_lattice:1,30,biomesoplenty:leaves_2:7,30,quark:iron_plate_stairs:6,10,quark:iron_plate_stairs:0,10,quark:iron_plate_stairs:5,10,quark:iron_plate_stairs:3,10,quark:iron_plate_slab:8,10,quark:iron_plate_stairs:7,10,quark:iron_plate_stairs:1,10,quark:iron_plate_slab:0,10,quark:iron_plate_stairs:4,10,quark:iron_plate_stairs:2,10,rustic:iron_lattice:1,50,rustic:iron_lattice:1,50,biomesoplenty:leaves_2:7,100)
Block(2,5,-5,AIR:0)
Block(2,5,-4,AIR:0)
RandomBlock(2,5,-3,quark:iron_plate:1,70,STAINED_CLAY:15,30,STAINED_CLAY:7,30,quark:iron_plate:1,100)
RandomBlock(2,6,-6,quark:iron_plate:1,70,STAINED_CLAY:15,30,STAINED_CLAY:7,30,quark:iron_plate:1,100)
Block(2,6,-5,AIR:0)
Block(2,6,-4,AIR:0)
RandomBlock(2,6,-3,quark:iron_plate:1,70,STAINED_CLAY:15,30,STAINED_CLAY:7,30,quark:iron_plate:1,100)
Block(2,7,-6,COBBLESTONE_STAIRS:2)
RandomBlock(2,7,-5,quark:iron_plate:1,70,STAINED_CLAY:15,30,STAINED_CLAY:7,30,quark:iron_plate:1,100)
RandomBlock(2,7,-4,quark:iron_plate:1,70,STAINED_CLAY:15,30,STAINED_CLAY:7,30,quark:iron_plate:1,100)
Block(2,7,-3,COBBLESTONE_STAIRS:3)
Block(3,4,-6,COBBLESTONE_STAIRS:6)
RandomBlock(3,4,-5,rustic:iron_lattice:1,30,rustic:iron_lattice:1,30,biomesoplenty:leaves_2:7,30,quark:iron_plate_stairs:6,10,quark:iron_plate_stairs:0,10,quark:iron_plate_stairs:5,10,quark:iron_plate_stairs:3,10,quark:iron_plate_slab:8,10,quark:iron_plate_stairs:7,10,quark:iron_plate_stairs:1,10,quark:iron_plate_slab:0,10,quark:iron_plate_stairs:4,10,quark:iron_plate_stairs:2,10,rustic:iron_lattice:1,50,rustic:iron_lattice:1,50,biomesoplenty:leaves_2:7,100)
RandomBlock(3,4,-4,quark:iron_plate:1,70,STAINED_CLAY:15,30,STAINED_CLAY:7,30,quark:iron_plate:1,100)
Block(3,4,-3,COBBLESTONE_STAIRS:7)
RandomBlock(3,5,-6,rustic:iron_lattice:1,30,rustic:iron_lattice:1,30,biomesoplenty:leaves_2:7,30,quark:iron_plate_stairs:6,10,quark:iron_plate_stairs:0,10,quark:iron_plate_stairs:5,10,quark:iron_plate_stairs:3,10,quark:iron_plate_slab:8,10,quark:iron_plate_stairs:7,10,quark:iron_plate_stairs:1,10,quark:iron_plate_slab:0,10,quark:iron_plate_stairs:4,10,quark:iron_plate_stairs:2,10,rustic:iron_lattice:1,50,rustic:iron_lattice:1,50,biomesoplenty:leaves_2:7,100)
Block(3,5,-5,AIR:0)
Block(3,5,-4,AIR:0)
RandomBlock(3,5,-3,quark:iron_plate:1,70,STAINED_CLAY:15,30,STAINED_CLAY:7,30,quark:iron_plate:1,100)
RandomBlock(3,6,-6,rustic:iron_lattice:1,30,rustic:iron_lattice:1,30,biomesoplenty:leaves_2:7,30,quark:iron_plate_stairs:6,10,quark:iron_plate_stairs:0,10,quark:iron_plate_stairs:5,10,quark:iron_plate_stairs:3,10,quark:iron_plate_slab:8,10,quark:iron_plate_stairs:7,10,quark:iron_plate_stairs:1,10,quark:iron_plate_slab:0,10,quark:iron_plate_stairs:4,10,quark:iron_plate_stairs:2,10,rustic:iron_lattice:1,50,rustic:iron_lattice:1,50,biomesoplenty:leaves_2:7,100)
Block(3,6,-5,AIR:0)
Block(3,6,-4,AIR:0)
RandomBlock(3,6,-3,quark:iron_plate:1,70,STAINED_CLAY:15,30,STAINED_CLAY:7,30,quark:iron_plate:1,100)
Block(3,7,-6,COBBLESTONE_STAIRS:2)
RandomBlock(3,7,-5,quark:iron_plate:1,70,STAINED_CLAY:15,30,STAINED_CLAY:7,30,quark:iron_plate:1,100)
RandomBlock(3,7,-4,quark:iron_plate:1,70,STAINED_CLAY:15,30,STAINED_CLAY:7,30,quark:iron_plate:1,100)
Block(3,7,-3,COBBLESTONE_STAIRS:3)
Block(4,4,-6,COBBLESTONE_STAIRS:6)
RandomBlock(4,4,-5,quark:iron_plate:1,70,STAINED_CLAY:15,30,STAINED_CLAY:7,30,quark:iron_plate:1,100)
RandomBlock(4,4,-4,rustic:iron_lattice:1,30,rustic:iron_lattice:1,30,biomesoplenty:leaves_2:7,30,quark:iron_plate_stairs:6,10,quark:iron_plate_stairs:0,10,quark:iron_plate_stairs:5,10,quark:iron_plate_stairs:3,10,quark:iron_plate_slab:8,10,quark:iron_plate_stairs:7,10,quark:iron_plate_stairs:1,10,quark:iron_plate_slab:0,10,quark:iron_plate_stairs:4,10,quark:iron_plate_stairs:2,10,rustic:iron_lattice:1,50,rustic:iron_lattice:1,50,biomesoplenty:leaves_2:7,100)
Block(4,4,-3,COBBLESTONE_STAIRS:7)
RandomBlock(4,5,-6,rustic:iron_lattice:1,30,rustic:iron_lattice:1,30,biomesoplenty:leaves_2:7,30,quark:iron_plate_stairs:6,10,quark:iron_plate_stairs:0,10,quark:iron_plate_stairs:5,10,quark:iron_plate_stairs:3,10,quark:iron_plate_slab:8,10,quark:iron_plate_stairs:7,10,quark:iron_plate_stairs:1,10,quark:iron_plate_slab:0,10,quark:iron_plate_stairs:4,10,quark:iron_plate_stairs:2,10,rustic:iron_lattice:1,50,rustic:iron_lattice:1,50,biomesoplenty:leaves_2:7,100)
Block(4,5,-5,AIR:0)
Block(4,5,-4,AIR:0)
RandomBlock(4,5,-3,quark:iron_plate:1,70,STAINED_CLAY:15,30,STAINED_CLAY:7,30,quark:iron_plate:1,100)
RandomBlock(4,6,-6,rustic:iron_lattice:1,30,rustic:iron_lattice:1,30,biomesoplenty:leaves_2:7,30,quark:iron_plate_stairs:6,10,quark:iron_plate_stairs:0,10,quark:iron_plate_stairs:5,10,quark:iron_plate_stairs:3,10,quark:iron_plate_slab:8,10,quark:iron_plate_stairs:7,10,quark:iron_plate_stairs:1,10,quark:iron_plate_slab:0,10,quark:iron_plate_stairs:4,10,quark:iron_plate_stairs:2,10,rustic:iron_lattice:1,50,rustic:iron_lattice:1,50,biomesoplenty:leaves_2:7,100)
Block(4,6,-5,AIR:0)
Block(4,6,-4,AIR:0)
RandomBlock(4,6,-3,quark:iron_plate:1,70,STAINED_CLAY:15,30,STAINED_CLAY:7,30,quark:iron_plate:1,100)
Block(4,7,-6,COBBLESTONE_STAIRS:2)
RandomBlock(4,7,-5,quark:iron_plate:1,70,STAINED_CLAY:15,30,STAINED_CLAY:7,30,quark:iron_plate:1,100)
RandomBlock(4,7,-4,quark:iron_plate:1,70,STAINED_CLAY:15,30,STAINED_CLAY:7,30,quark:iron_plate:1,100)
Block(4,7,-3,COBBLESTONE_STAIRS:3)
Block(5,4,-6,COBBLESTONE_STAIRS:6)
RandomBlock(5,4,-5,rustic:iron_lattice:1,30,rustic:iron_lattice:1,30,biomesoplenty:leaves_2:7,30,quark:iron_plate_stairs:6,10,quark:iron_plate_stairs:0,10,quark:iron_plate_stairs:5,10,quark:iron_plate_stairs:3,10,quark:iron_plate_slab:8,10,quark:iron_plate_stairs:7,10,quark:iron_plate_stairs:1,10,quark:iron_plate_slab:0,10,quark:iron_plate_stairs:4,10,quark:iron_plate_stairs:2,10,rustic:iron_lattice:1,50,rustic:iron_lattice:1,50,biomesoplenty:leaves_2:7,100)
RandomBlock(5,4,-4,quark:iron_plate:1,70,STAINED_CLAY:15,30,STAINED_CLAY:7,30,quark:iron_plate:1,100)
Block(5,4,-3,COBBLESTONE_STAIRS:4)
Block(5,4,-2,COBBLESTONE_STAIRS:4)
Block(5,4,-1,COBBLESTONE_STAIRS:7)
RandomBlock(5,5,-6,quark:iron_plate:1,70,STAINED_CLAY:15,30,STAINED_CLAY:7,30,quark:iron_plate:1,100)
Block(5,5,-5,SMOOTH_STAIRS:3)
Block(5,5,-4,SMOOTH_STAIRS:2)
RandomBlock(5,5,-3,quark:iron_plate:1,70,STAINED_CLAY:15,30,STAINED_CLAY:7,30,quark:iron_plate:1,100)
RandomBlock(5,5,-2,quark:iron_plate:1,70,STAINED_CLAY:15,30,STAINED_CLAY:7,30,quark:iron_plate:1,100)
RandomBlock(5,5,-1,quark:iron_plate:1,70,STAINED_CLAY:15,30,STAINED_CLAY:7,30,quark:iron_plate:1,100)
RandomBlock(5,6,-6,quark:iron_plate:1,70,STAINED_CLAY:15,30,STAINED_CLAY:7,30,quark:iron_plate:1,100)
Block(5,6,-5,SMOOTH_STAIRS:7)
Block(5,6,-4,SMOOTH_STAIRS:6)
RandomBlock(5,6,-3,quark:iron_plate:1,70,STAINED_CLAY:15,30,STAINED_CLAY:7,30,quark:iron_plate:1,100)
RandomBlock(5,6,-2,quark:iron_plate:1,70,STAINED_CLAY:15,30,STAINED_CLAY:7,30,quark:iron_plate:1,100)
RandomBlock(5,6,-1,quark:iron_plate:1,70,STAINED_CLAY:15,30,STAINED_CLAY:7,30,quark:iron_plate:1,100)
Block(5,7,-6,COBBLESTONE_STAIRS:2)
RandomBlock(5,7,-5,quark:iron_plate:1,70,STAINED_CLAY:15,30,STAINED_CLAY:7,30,quark:iron_plate:1,100)
RandomBlock(5,7,-4,quark:iron_plate:1,70,STAINED_CLAY:15,30,STAINED_CLAY:7,30,quark:iron_plate:1,100)
RandomBlock(5,7,-3,quark:iron_plate:1,70,STAINED_CLAY:15,30,STAINED_CLAY:7,30,quark:iron_plate:1,100)
RandomBlock(5,7,-2,quark:iron_plate:1,70,STAINED_CLAY:15,30,STAINED_CLAY:7,30,quark:iron_plate:1,100)
RandomBlock(5,7,-1,quark:iron_plate:1,70,STAINED_CLAY:15,30,STAINED_CLAY:7,30,quark:iron_plate:1,100)
Block(5,8,-3,COBBLESTONE_STAIRS:2)
Block(5,8,-2,COBBLESTONE_STAIRS:0)
Block(5,8,-1,COBBLESTONE_STAIRS:3)
Block(5,9,-3,rustic:iron_lattice:0)
Block(5,9,-2,rustic:iron_lattice:0)
Block(5,9,-1,rustic:iron_lattice:0)
Block(6,4,-6,COBBLESTONE_STAIRS:6)
RandomBlock(6,4,-5,quark:iron_plate:1,70,STAINED_CLAY:15,30,STAINED_CLAY:7,30,quark:iron_plate:1,100)
RandomBlock(6,4,-4,quark:iron_plate:1,70,STAINED_CLAY:15,30,STAINED_CLAY:7,30,quark:iron_plate:1,100)
RandomBlock(6,4,-3,quark:iron_plate:1,70,STAINED_CLAY:15,30,STAINED_CLAY:7,30,quark:iron_plate:1,100)
RandomBlock(6,4,-2,quark:iron_plate:1,70,STAINED_CLAY:15,30,STAINED_CLAY:7,30,quark:iron_plate:1,100)
Block(6,4,-1,COBBLESTONE_STAIRS:7)
RandomBlock(6,5,-6,quark:iron_plate:1,70,STAINED_CLAY:15,30,STAINED_CLAY:7,30,quark:iron_plate:1,100)
Block(6,5,-4,quark:polished_stone:0)
Block(6,5,-3,PISTON_BASE:2)
Block(6,5,-2,PISTON_BASE:2)
RandomBlock(6,5,-1,quark:iron_plate:1,70,STAINED_CLAY:15,30,STAINED_CLAY:7,30,quark:iron_plate:1,100)
RandomBlock(6,6,-6,quark:iron_plate:1,70,STAINED_CLAY:15,30,STAINED_CLAY:7,30,quark:iron_plate:1,100)
Block(6,6,-4,quark:polished_stone:0)
Block(6,6,-3,PISTON_BASE:2)
Block(6,6,-2,PISTON_BASE:2)
RandomBlock(6,6,-1,quark:iron_plate:1,70,STAINED_CLAY:15,30,STAINED_CLAY:7,30,quark:iron_plate:1,100)
Block(6,7,-6,COBBLESTONE_STAIRS:2)
RandomBlock(6,7,-5,quark:iron_plate:1,70,STAINED_CLAY:15,30,STAINED_CLAY:7,30,quark:iron_plate:1,100)
RandomBlock(6,7,-4,quark:iron_plate:1,70,STAINED_CLAY:15,30,STAINED_CLAY:7,30,quark:iron_plate:1,100)
RandomBlock(6,7,-3,quark:iron_plate:1,70,STAINED_CLAY:15,30,STAINED_CLAY:7,30,quark:iron_plate:1,100)
RandomBlock(6,7,-1,quark:iron_plate:1,70,STAINED_CLAY:15,30,STAINED_CLAY:7,30,quark:iron_plate:1,100)
Block(6,8,-3,COBBLESTONE_STAIRS:2)
Block(6,8,-2,quark:polished_stone:0)
Block(6,8,-1,COBBLESTONE_STAIRS:3)
Block(6,9,-3,rustic:iron_lattice:0)
Block(6,9,-2,rustic:iron_lattice:0)
Block(6,9,-1,rustic:iron_lattice:0)
Block(7,4,-6,COBBLESTONE_STAIRS:6)
RandomBlock(7,4,-5,quark:iron_plate:1,70,STAINED_CLAY:15,30,STAINED_CLAY:7,30,quark:iron_plate:1,100)
RandomBlock(7,4,-4,quark:iron_plate:1,70,STAINED_CLAY:15,30,STAINED_CLAY:7,30,quark:iron_plate:1,100)
Block(7,4,-3,COBBLESTONE_STAIRS:5)
Block(7,4,-2,COBBLESTONE_STAIRS:5)
Block(7,4,-1,COBBLESTONE_STAIRS:5)
RandomBlock(7,5,-6,quark:iron_plate:1,70,STAINED_CLAY:15,30,STAINED_CLAY:7,30,quark:iron_plate:1,100)
Block(7,5,-5,SMOOTH_STAIRS:3)
Block(7,5,-4,SMOOTH_STAIRS:2)
RandomBlock(7,5,-3,quark:iron_plate:1,70,STAINED_CLAY:15,30,STAINED_CLAY:7,30,quark:iron_plate:1,100)
RandomBlock(7,5,-2,quark:iron_plate:1,70,STAINED_CLAY:15,30,STAINED_CLAY:7,30,quark:iron_plate:1,100)
RandomBlock(7,5,-1,quark:iron_plate:1,70,STAINED_CLAY:15,30,STAINED_CLAY:7,30,quark:iron_plate:1,100)
RandomBlock(7,6,-6,quark:iron_plate:1,70,STAINED_CLAY:15,30,STAINED_CLAY:7,30,quark:iron_plate:1,100)
Block(7,6,-5,SMOOTH_STAIRS:7)
Block(7,6,-4,SMOOTH_STAIRS:6)
RandomBlock(7,6,-3,quark:iron_plate:1,70,STAINED_CLAY:15,30,STAINED_CLAY:7,30,quark:iron_plate:1,100)
RandomBlock(7,6,-2,quark:iron_plate:1,70,STAINED_CLAY:15,30,STAINED_CLAY:7,30,quark:iron_plate:1,100)
RandomBlock(7,6,-1,quark:iron_plate:1,70,STAINED_CLAY:15,30,STAINED_CLAY:7,30,quark:iron_plate:1,100)
Block(7,7,-6,COBBLESTONE_STAIRS:2)
RandomBlock(7,7,-5,quark:iron_plate:1,70,STAINED_CLAY:15,30,STAINED_CLAY:7,30,quark:iron_plate:1,100)
RandomBlock(7,7,-4,quark:iron_plate:1,70,STAINED_CLAY:15,30,STAINED_CLAY:7,30,quark:iron_plate:1,100)
RandomBlock(7,7,-3,quark:iron_plate:1,70,STAINED_CLAY:15,30,STAINED_CLAY:7,30,quark:iron_plate:1,100)
RandomBlock(7,7,-2,quark:iron_plate:1,70,STAINED_CLAY:15,30,STAINED_CLAY:7,30,quark:iron_plate:1,100)
RandomBlock(7,7,-1,quark:iron_plate:1,70,STAINED_CLAY:15,30,STAINED_CLAY:7,30,quark:iron_plate:1,100)
Block(7,8,-3,COBBLESTONE_STAIRS:1)
Block(7,8,-2,COBBLESTONE_STAIRS:1)
Block(7,8,-1,COBBLESTONE_STAIRS:1)
Block(7,9,-3,rustic:iron_lattice:0)
Block(7,9,-2,rustic:iron_lattice:0)
Block(7,9,-1,rustic:iron_lattice:0)

#######################################################################
# +-----------------------------------------------------------------+ #
# |                             Branches                            | #
# +-----------------------------------------------------------------+ #
#######################################################################

Branch(16,0,0,true,brutal_pipebig_05C2R0,NORTH,100.0,0)

#######################################################################
# +-----------------------------------------------------------------+ #
# |                             Entities                            | #
# +-----------------------------------------------------------------+ #
#######################################################################


#######################################################################
# +-----------------------------------------------------------------+ #
# |                            Particles                            | #
# +-----------------------------------------------------------------+ #
#######################################################################


#######################################################################
# +-----------------------------------------------------------------+ #
# |                             Spawners                            | #
# +-----------------------------------------------------------------+ #
#######################################################################


#######################################################################
# +-----------------------------------------------------------------+ #
# |                             ModData                             | #
# +-----------------------------------------------------------------+ #
#######################################################################

